Qubicle Exchange Format
Version 0.2
www.minddesk.com
8 8 8
24
0.062745 0.062745 0.062745
0.164706 0.109804 0.000000
0.164706 0.113725 0.000000
0.239216 0.164706 0.000000
0.243137 0.164706 0.000000
0.243137 0.168627 0.000000
0.247059 0.168627 0.000000
0.250980 0.172549 0.000000
0.254902 0.176471 0.003922
0.254902 0.180392 0.007843
0.258824 0.184314 0.011765
0.262745 0.184314 0.015686
0.266667 0.188235 0.019608
0.266667 0.192157 0.023529
0.270588 0.196078 0.027451
0.274510 0.200000 0.031373
0.862745 0.658824 0.623529
0.882353 0.678431 0.639216
0.890196 0.670588 0.627451
0.933333 0.933333 0.933333
0.937255 0.666667 0.243137
0.937255 0.666667 0.247059
0.964706 0.737255 0.694118
1.000000 1.000000 1.000000
1 2 1 6 116
1 2 6 9 116
1 3 1 4 68
1 3 2 14 20
1 3 3 1 20
1 3 4 2 20
1 3 5 4 20
1 3 6 10 36
1 4 1 13 68
1 4 2 8 4
1 4 3 0 4
1 4 4 0 4
1 4 5 11 4
1 4 6 13 36
1 5 1 19 68
1 5 2 21 4
1 5 3 14 4
1 5 4 9 4
1 5 5 20 4
1 5 6 14 36
1 6 1 19 76
1 6 2 19 12
1 6 3 4 12
1 6 4 6 12
1 6 5 8 12
1 6 6 6 44
2 2 1 7 80
2 2 2 23 20
2 2 3 23 20
2 2 4 23 20
2 2 5 23 20
2 2 6 10 48
2 3 1 4 64
2 3 2 4 0
2 3 3 7 0
2 3 4 11 0
2 3 5 17 0
2 3 6 8 32
2 4 1 7 64
2 4 2 4 0
2 4 3 13 0
2 4 4 11 0
2 4 5 4 0
2 4 6 9 32
2 5 1 19 64
2 5 2 7 0
2 5 3 15 0
2 5 4 6 0
2 5 5 3 0
2 5 6 6 32
2 6 1 19 72
2 6 2 19 8
2 6 3 14 8
2 6 4 6 8
2 6 5 4 8
2 6 6 9 40
3 0 2 11 116
3 0 5 14 116
3 1 2 11 100
3 1 5 6 100
3 2 0 7 84
3 2 1 23 16
3 2 2 23 0
3 2 3 6 16
3 2 4 16 16
3 2 5 23 0
3 2 6 23 16
3 2 7 19 52
3 3 0 6 68
3 3 1 7 0
3 3 2 15 0
3 3 3 4 0
3 3 4 18 0
3 3 5 5 0
3 3 6 4 0
3 3 7 19 36
3 4 0 4 68
3 4 1 14 0
3 4 2 6 0
3 4 3 6 0
3 4 4 6 0
3 4 5 9 0
3 4 6 14 0
3 4 7 5 36
3 5 0 3 68
3 5 1 6 0
3 5 2 14 0
3 5 3 8 0
3 5 4 4 0
3 5 5 5 0
3 5 6 11 0
3 5 7 8 36
3 6 0 14 76
3 6 1 3 8
3 6 2 4 8
3 6 3 3 8
3 6 4 19 8
3 6 5 19 8
3 6 6 19 8
3 6 7 19 44
4 0 2 13 114
4 0 5 7 114
4 1 2 15 98
4 1 5 6 98
4 2 0 7 82
4 2 1 23 18
4 2 2 23 0
4 2 3 14 16
4 2 4 22 16
4 2 5 23 0
4 2 6 23 18
4 2 7 19 50
4 3 0 6 66
4 3 1 14 0
4 3 2 10 0
4 3 3 4 0
4 3 4 4 0
4 3 5 7 0
4 3 6 11 0
4 3 7 13 34
4 4 0 5 66
4 4 1 4 0
4 4 2 6 0
4 4 3 15 0
4 4 4 9 0
4 4 5 13 0
4 4 6 6 0
4 4 7 12 34
4 5 0 3 66
4 5 1 12 0
4 5 2 14 0
4 5 3 4 0
4 5 4 6 0
4 5 5 9 0
4 5 6 6 0
4 5 7 9 34
4 6 0 6 74
4 6 1 4 8
4 6 2 4 8
4 6 3 9 8
4 6 4 19 8
4 6 5 19 8
4 6 6 19 8
4 6 7 19 42
5 2 2 23 82
5 2 3 23 18
5 2 4 23 18
5 2 5 23 50
5 3 1 4 80
5 3 2 4 0
5 3 3 14 0
5 3 4 13 0
5 3 5 6 0
5 3 6 3 48
5 4 1 3 64
5 4 2 15 0
5 4 3 4 0
5 4 4 9 0
5 4 5 13 0
5 4 6 6 32
5 5 1 4 64
5 5 2 6 0
5 5 3 9 0
5 5 4 3 0
5 5 5 9 0
5 5 6 12 32
5 6 1 13 72
5 6 2 12 8
5 6 3 5 8
5 6 4 6 8
5 6 5 19 8
5 6 6 19 40
6 3 1 19 82
6 3 2 19 18
6 3 3 19 18
6 3 4 4 18
6 3 5 4 18
6 3 6 7 50
6 4 1 19 66
6 4 2 19 2
6 4 3 19 2
6 4 4 9 2
6 4 5 6 2
6 4 6 6 34
6 5 1 19 66
6 5 2 10 2
6 5 3 4 2
6 5 4 3 2
6 5 5 6 2
6 5 6 6 34
6 6 1 8 74
6 6 2 4 10
6 6 3 6 10
6 6 4 9 10
6 6 5 8 10
6 6 6 10 42
