Qubicle Exchange Format
Version 0.2
www.minddesk.com
8 8 8
10
0.066667 0.066667 0.066667
0.172549 0.117647 0.000000
0.250980 0.172549 0.000000
0.894118 0.666667 0.623529
0.898039 0.686275 0.647059
0.898039 0.690196 0.650980
0.933333 0.933333 0.933333
0.941176 0.666667 0.235294
0.968627 0.737255 0.694118
1.000000 1.000000 1.000000
1 2 1 2 116
1 2 6 2 116
1 3 1 2 68
1 3 2 2 20
1 3 3 1 20
1 3 4 1 20
1 3 5 2 20
1 3 6 2 36
1 4 1 2 68
1 4 2 2 4
1 4 3 0 4
1 4 4 0 4
1 4 5 2 4
1 4 6 2 36
1 5 1 6 68
1 5 2 7 4
1 5 3 2 4
1 5 4 2 4
1 5 5 7 4
1 5 6 2 36
1 6 1 6 76
1 6 2 6 12
1 6 3 2 12
1 6 4 2 12
1 6 5 2 12
1 6 6 2 44
2 2 1 2 80
2 2 2 9 20
2 2 3 9 20
2 2 4 9 20
2 2 5 9 20
2 2 6 2 48
2 3 1 2 64
2 3 2 2 0
2 3 3 2 0
2 3 4 2 0
2 3 5 5 0
2 3 6 2 32
2 4 1 2 64
2 4 2 2 0
2 4 3 2 0
2 4 4 2 0
2 4 5 2 0
2 4 6 2 32
2 5 1 6 64
2 5 2 2 0
2 5 3 2 0
2 5 4 2 0
2 5 5 2 0
2 5 6 2 32
2 6 1 6 72
2 6 2 6 8
2 6 3 2 8
2 6 4 2 8
2 6 5 2 8
2 6 6 2 40
3 0 2 2 116
3 0 5 2 116
3 1 2 2 100
3 1 5 2 100
3 2 0 2 84
3 2 1 9 16
3 2 2 9 0
3 2 3 2 16
3 2 4 4 16
3 2 5 9 0
3 2 6 9 16
3 2 7 2 52
3 3 0 2 68
3 3 1 2 0
3 3 2 2 0
3 3 3 2 0
3 3 4 3 0
3 3 5 2 0
3 3 6 2 0
3 3 7 2 36
3 4 0 2 68
3 4 1 2 0
3 4 2 2 0
3 4 3 2 0
3 4 4 2 0
3 4 5 2 0
3 4 6 2 0
3 4 7 2 36
3 5 0 2 68
3 5 1 2 0
3 5 2 2 0
3 5 3 2 0
3 5 4 2 0
3 5 5 2 0
3 5 6 2 0
3 5 7 2 36
3 6 0 2 76
3 6 1 2 8
3 6 2 2 8
3 6 3 2 8
3 6 4 2 8
3 6 5 2 8
3 6 6 2 8
3 6 7 2 44
4 0 2 2 114
4 0 5 6 114
4 1 2 2 98
4 1 5 6 98
4 2 0 2 82
4 2 1 9 18
4 2 2 9 0
4 2 3 2 16
4 2 4 8 16
4 2 5 9 0
4 2 6 9 18
4 2 7 2 50
4 3 0 2 66
4 3 1 2 0
4 3 2 2 0
4 3 3 2 0
4 3 4 2 0
4 3 5 2 0
4 3 6 2 0
4 3 7 2 34
4 4 0 2 66
4 4 1 2 0
4 4 2 2 0
4 4 3 2 0
4 4 4 2 0
4 4 5 2 0
4 4 6 2 0
4 4 7 2 34
4 5 0 2 66
4 5 1 2 0
4 5 2 2 0
4 5 3 2 0
4 5 4 2 0
4 5 5 2 0
4 5 6 2 0
4 5 7 6 34
4 6 0 2 74
4 6 1 2 8
4 6 2 2 8
4 6 3 6 8
4 6 4 6 8
4 6 5 6 8
4 6 6 6 8
4 6 7 6 42
5 2 2 9 82
5 2 3 9 18
5 2 4 9 18
5 2 5 9 50
5 3 1 2 80
5 3 2 2 0
5 3 3 2 0
5 3 4 2 0
5 3 5 2 0
5 3 6 2 48
5 4 1 2 64
5 4 2 2 0
5 4 3 2 0
5 4 4 2 0
5 4 5 2 0
5 4 6 2 32
5 5 1 2 64
5 5 2 2 0
5 5 3 2 0
5 5 4 2 0
5 5 5 2 0
5 5 6 2 32
5 6 1 2 72
5 6 2 6 8
5 6 3 6 8
5 6 4 2 8
5 6 5 2 8
5 6 6 2 40
6 3 1 2 82
6 3 2 2 18
6 3 3 2 18
6 3 4 2 18
6 3 5 2 18
6 3 6 2 50
6 4 1 6 66
6 4 2 6 2
6 4 3 2 2
6 4 4 2 2
6 4 5 2 2
6 4 6 2 34
6 5 1 6 66
6 5 2 6 2
6 5 3 6 2
6 5 4 2 2
6 5 5 2 2
6 5 6 2 34
6 6 1 2 74
6 6 2 6 10
6 6 3 6 10
6 6 4 2 10
6 6 5 2 10
6 6 6 2 42
