Qubicle Exchange Format
Version 0.2
www.minddesk.com
8 8 8
14
0.066667 0.066667 0.066667
0.172549 0.117647 0.000000
0.250980 0.172549 0.000000
0.890196 0.890196 0.890196
0.894118 0.666667 0.623529
0.898039 0.686275 0.647059
0.898039 0.690196 0.650980
0.933333 0.933333 0.933333
0.941176 0.666667 0.235294
0.949020 0.713726 0.666667
0.960784 0.737255 0.694118
0.968627 0.737255 0.694118
0.992157 0.992157 0.992157
1.000000 1.000000 1.000000
1 2 1 2 124
1 2 6 2 124
1 4 1 2 84
1 4 2 2 20
1 4 3 1 126
1 4 4 1 126
1 4 5 2 20
1 4 6 2 52
1 5 1 2 68
1 5 2 2 126
1 5 3 0 126
1 5 4 0 126
1 5 5 2 126
1 5 6 2 36
1 6 1 7 126
1 6 2 8 126
1 6 3 2 12
1 6 4 2 12
1 6 5 8 126
1 6 6 2 44
1 7 1 7 126
1 7 2 7 126
1 7 3 2 126
1 7 4 2 126
1 7 5 2 126
1 7 6 2 126
2 2 1 2 88
2 2 2 13 20
2 2 3 13 20
2 2 4 13 20
2 2 5 13 20
2 2 6 2 56
2 3 2 13 68
2 3 3 13 4
2 3 4 13 4
2 3 5 13 36
2 4 1 2 80
2 4 2 2 0
2 4 3 2 0
2 4 4 2 0
2 4 5 6 0
2 4 6 2 48
2 5 1 2 64
2 5 2 2 0
2 5 3 2 0
2 5 4 2 0
2 5 5 2 0
2 5 6 2 32
2 6 1 7 126
2 6 2 2 8
2 6 3 2 8
2 6 4 2 8
2 6 5 2 8
2 6 6 2 40
2 7 1 7 126
2 7 2 7 126
2 7 3 2 126
2 7 4 2 126
2 7 5 2 126
2 7 6 2 126
3 0 2 2 116
3 0 5 2 116
3 1 2 2 100
3 1 5 2 100
3 2 1 13 88
3 2 2 3 0
3 2 3 13 16
3 2 4 13 16
3 2 5 10 0
3 2 6 13 56
3 3 0 2 126
3 3 2 13 64
3 3 3 2 0
3 3 4 5 0
3 3 5 13 32
3 3 7 2 126
3 4 0 2 126
3 4 1 2 80
3 4 2 2 0
3 4 3 2 0
3 4 4 4 0
3 4 5 2 0
3 4 6 2 48
3 4 7 2 126
3 5 0 2 126
3 5 1 2 64
3 5 2 2 0
3 5 3 2 0
3 5 4 2 0
3 5 5 2 0
3 5 6 2 32
3 5 7 2 126
3 6 0 2 126
3 6 1 2 72
3 6 2 2 8
3 6 3 2 8
3 6 4 2 8
3 6 5 2 8
3 6 6 2 40
3 6 7 2 126
3 7 0 2 126
3 7 1 2 126
3 7 2 2 126
3 7 3 2 126
3 7 4 2 126
3 7 5 2 126
3 7 6 2 126
3 7 7 2 126
4 0 2 2 114
4 0 5 7 126
4 1 2 2 98
4 1 5 7 126
4 2 1 13 90
4 2 2 12 0
4 2 3 13 16
4 2 4 13 16
4 2 5 9 0
4 2 6 13 58
4 3 0 2 126
4 3 2 13 64
4 3 3 2 0
4 3 4 11 0
4 3 5 13 32
4 3 7 2 126
4 4 0 2 126
4 4 1 2 80
4 4 2 2 0
4 4 3 2 0
4 4 4 2 0
4 4 5 2 0
4 4 6 2 48
4 4 7 2 126
4 5 0 2 126
4 5 1 2 64
4 5 2 2 0
4 5 3 2 0
4 5 4 2 0
4 5 5 2 0
4 5 6 2 32
4 5 7 2 126
4 6 0 2 126
4 6 1 2 72
4 6 2 2 8
4 6 3 2 8
4 6 4 2 8
4 6 5 2 8
4 6 6 2 40
4 6 7 7 126
4 7 0 2 126
4 7 1 2 126
4 7 2 2 126
4 7 3 7 126
4 7 4 7 126
4 7 5 7 126
4 7 6 7 126
4 7 7 7 126
5 2 2 13 82
5 2 3 13 18
5 2 4 13 18
5 2 5 13 50
5 3 2 13 126
5 3 3 13 126
5 3 4 13 126
5 3 5 13 34
5 4 1 2 80
5 4 2 2 0
5 4 3 2 0
5 4 4 2 0
5 4 5 2 0
5 4 6 2 48
5 5 1 2 64
5 5 2 2 0
5 5 3 2 0
5 5 4 2 0
5 5 5 2 0
5 5 6 2 32
5 6 1 2 72
5 6 2 2 8
5 6 3 2 8
5 6 4 2 8
5 6 5 2 8
5 6 6 2 40
5 7 1 2 126
5 7 2 7 126
5 7 3 7 126
5 7 4 2 126
5 7 5 2 126
5 7 6 2 126
6 4 1 2 82
6 4 2 2 18
6 4 3 2 18
6 4 4 2 18
6 4 5 2 18
6 4 6 2 50
6 5 1 7 126
6 5 2 7 126
6 5 3 2 2
6 5 4 2 2
6 5 5 2 2
6 5 6 2 34
6 6 1 7 126
6 6 2 7 126
6 6 3 7 126
6 6 4 2 10
6 6 5 2 10
6 6 6 2 42
6 7 1 2 126
6 7 2 7 126
6 7 3 7 126
6 7 4 2 126
6 7 5 2 126
6 7 6 2 126
