Qubicle Exchange Format
Version 0.2
www.minddesk.com
8 8 8
13
0.066667 0.066667 0.066667
0.172549 0.117647 0.000000
0.250980 0.172549 0.000000
0.890196 0.890196 0.890196
0.894118 0.666667 0.623529
0.898039 0.686275 0.647059
0.898039 0.690196 0.650980
0.933333 0.933333 0.933333
0.941176 0.666667 0.235294
0.949020 0.713726 0.666667
0.960784 0.737255 0.694118
0.968627 0.737255 0.694118
1.000000 1.000000 1.000000
0 2 1 2 124
1 2 1 2 120
1 2 6 2 124
1 4 1 2 84
1 4 2 2 20
1 4 3 1 20
1 4 4 1 20
1 4 5 2 20
1 4 6 2 52
1 5 1 2 68
1 5 2 2 4
1 5 3 0 4
1 5 4 0 4
1 5 5 2 4
1 5 6 2 36
1 6 1 7 68
1 6 2 8 4
1 6 3 2 4
1 6 4 2 4
1 6 5 8 4
1 6 6 2 36
1 7 1 7 76
1 7 2 7 12
1 7 3 2 12
1 7 4 2 12
1 7 5 2 12
1 7 6 2 44
2 0 2 2 116
2 1 2 2 100
2 2 1 12 88
2 2 2 12 4
2 2 3 12 20
2 2 4 12 20
2 2 5 12 20
2 2 6 2 56
2 3 2 12 68
2 3 3 12 4
2 3 4 12 4
2 3 5 12 36
2 4 1 2 80
2 4 2 2 0
2 4 3 2 0
2 4 4 2 0
2 4 5 6 0
2 4 6 2 48
2 5 1 2 64
2 5 2 2 0
2 5 3 2 0
2 5 4 2 0
2 5 5 2 0
2 5 6 2 32
2 6 1 7 64
2 6 2 2 0
2 6 3 2 0
2 6 4 2 0
2 6 5 2 0
2 6 6 2 32
2 7 1 7 72
2 7 2 7 8
2 7 3 2 8
2 7 4 2 8
2 7 5 2 8
2 7 6 2 40
3 0 2 2 114
3 0 5 2 116
3 1 2 2 98
3 1 5 2 100
3 2 1 12 90
3 2 2 3 0
3 2 3 12 16
3 2 4 12 16
3 2 5 10 0
3 2 6 12 56
3 3 0 2 116
3 3 2 12 64
3 3 3 2 0
3 3 4 5 0
3 3 5 12 32
3 3 7 2 116
3 4 0 2 68
3 4 1 2 16
3 4 2 2 0
3 4 3 2 0
3 4 4 4 0
3 4 5 2 0
3 4 6 2 16
3 4 7 2 36
3 5 0 2 68
3 5 1 2 0
3 5 2 2 0
3 5 3 2 0
3 5 4 2 0
3 5 5 2 0
3 5 6 2 0
3 5 7 2 36
3 6 0 2 68
3 6 1 2 0
3 6 2 2 0
3 6 3 2 0
3 6 4 2 0
3 6 5 2 0
3 6 6 2 0
3 6 7 2 36
3 7 0 2 76
3 7 1 2 8
3 7 2 2 8
3 7 3 2 8
3 7 4 2 8
3 7 5 2 8
3 7 6 2 8
3 7 7 2 44
4 0 5 7 114
4 1 5 7 98
4 2 2 12 126
4 2 3 12 16
4 2 4 12 16
4 2 5 9 0
4 2 6 12 58
4 3 0 2 114
4 3 2 12 64
4 3 3 2 0
4 3 4 11 0
4 3 5 12 32
4 3 7 2 114
4 4 0 2 66
4 4 1 2 16
4 4 2 2 0
4 4 3 2 0
4 4 4 2 0
4 4 5 2 0
4 4 6 2 16
4 4 7 2 34
4 5 0 2 66
4 5 1 2 0
4 5 2 2 0
4 5 3 2 0
4 5 4 2 0
4 5 5 2 0
4 5 6 2 0
4 5 7 2 34
4 6 0 2 66
4 6 1 2 0
4 6 2 2 0
4 6 3 2 0
4 6 4 2 0
4 6 5 2 0
4 6 6 2 0
4 6 7 7 34
4 7 0 2 74
4 7 1 2 8
4 7 2 2 8
4 7 3 7 8
4 7 4 7 8
4 7 5 7 8
4 7 6 7 8
4 7 7 7 42
5 2 2 12 82
5 2 3 12 18
5 2 4 12 18
5 2 5 12 50
5 3 2 12 66
5 3 3 12 2
5 3 4 12 2
5 3 5 12 34
5 4 1 2 80
5 4 2 2 0
5 4 3 2 0
5 4 4 2 0
5 4 5 2 0
5 4 6 2 48
5 5 1 2 64
5 5 2 2 0
5 5 3 2 0
5 5 4 2 0
5 5 5 2 0
5 5 6 2 32
5 6 1 2 64
5 6 2 2 0
5 6 3 2 0
5 6 4 2 0
5 6 5 2 0
5 6 6 2 32
5 7 1 2 72
5 7 2 7 8
5 7 3 7 8
5 7 4 2 8
5 7 5 2 8
5 7 6 2 40
6 4 1 2 82
6 4 2 2 18
6 4 3 2 18
6 4 4 2 18
6 4 5 2 18
6 4 6 2 50
6 5 1 7 66
6 5 2 7 2
6 5 3 2 2
6 5 4 2 2
6 5 5 2 2
6 5 6 2 34
6 6 1 7 66
6 6 2 7 2
6 6 3 7 2
6 6 4 2 2
6 6 5 2 2
6 6 6 2 34
6 7 1 2 74
6 7 2 7 10
6 7 3 7 10
6 7 4 2 10
6 7 5 2 10
6 7 6 2 42
