Qubicle Exchange Format
Version 0.2
www.minddesk.com
8 8 8
5
0.250980 0.172549 0.000000
0.933333 0.933333 0.933333
0.941176 0.666667 0.235294
1.000000 0.403922 0.094118
1.000000 1.000000 1.000000
1 0 6 4 116
1 1 6 4 100
1 2 6 4 100
1 3 6 4 100
1 4 6 1 100
1 5 6 1 100
1 6 6 1 100
1 7 3 1 92
1 7 4 1 28
1 7 5 1 28
1 7 6 1 44
2 0 2 3 84
2 0 3 3 20
2 0 4 3 20
2 0 5 4 20
2 0 6 4 48
2 1 2 3 68
2 1 3 3 4
2 1 4 4 4
2 1 5 4 4
2 1 6 4 32
2 2 2 3 68
2 2 3 4 4
2 2 4 4 4
2 2 5 4 4
2 2 6 4 32
2 3 2 4 68
2 3 3 4 4
2 3 4 4 4
2 3 5 4 4
2 3 6 4 32
2 4 2 4 68
2 4 3 4 4
2 4 4 4 4
2 4 5 4 4
2 4 6 1 32
2 5 2 4 68
2 5 3 4 4
2 5 4 4 4
2 5 5 1 4
2 5 6 1 32
2 6 2 4 68
2 6 3 4 4
2 6 4 1 4
2 6 5 1 4
2 6 6 1 32
2 7 2 4 76
2 7 3 1 8
2 7 4 1 8
2 7 5 1 8
2 7 6 1 8
2 7 7 1 60
3 0 1 3 84
3 0 2 3 16
3 0 3 3 16
3 0 4 3 16
3 0 5 4 16
3 0 6 4 48
3 1 1 3 68
3 1 2 0 0
3 1 3 0 0
3 1 4 0 0
3 1 5 0 0
3 1 6 4 32
3 2 1 3 68
3 2 2 0 0
3 2 3 0 0
3 2 4 0 0
3 2 5 0 0
3 2 6 4 32
3 3 1 3 68
3 3 2 0 0
3 3 3 0 0
3 3 4 0 0
3 3 5 0 0
3 3 6 4 32
3 4 1 4 68
3 4 2 0 0
3 4 3 0 0
3 4 4 0 0
3 4 5 0 0
3 4 6 1 32
3 5 1 4 68
3 5 2 0 0
3 5 3 0 0
3 5 4 0 0
3 5 5 0 0
3 5 6 1 32
3 6 1 4 68
3 6 2 0 0
3 6 3 0 0
3 6 4 0 0
3 6 5 0 0
3 6 6 1 32
3 7 1 4 76
3 7 2 2 8
3 7 3 2 8
3 7 4 2 8
3 7 5 2 8
3 7 6 1 8
3 7 7 1 58
4 0 1 3 80
4 0 2 3 16
4 0 3 3 16
4 0 4 3 16
4 0 5 4 16
4 0 6 4 50
4 1 1 3 64
4 1 2 0 0
4 1 3 0 0
4 1 4 0 0
4 1 5 0 0
4 1 6 4 34
4 2 1 3 64
4 2 2 0 0
4 2 3 0 0
4 2 4 0 0
4 2 5 0 0
4 2 6 4 34
4 3 1 3 64
4 3 2 0 0
4 3 3 0 0
4 3 4 0 0
4 3 5 0 0
4 3 6 4 34
4 4 1 4 64
4 4 2 0 0
4 4 3 0 0
4 4 4 0 0
4 4 5 0 0
4 4 6 1 34
4 5 1 4 64
4 5 2 0 0
4 5 3 0 0
4 5 4 0 0
4 5 5 0 0
4 5 6 1 34
4 6 1 4 64
4 6 2 0 0
4 6 3 0 0
4 6 4 0 0
4 6 5 0 0
4 6 6 1 34
4 7 0 4 92
4 7 1 4 8
4 7 2 2 8
4 7 3 2 8
4 7 4 2 8
4 7 5 2 8
4 7 6 1 42
5 0 1 3 80
5 0 2 3 18
5 0 3 3 18
5 0 4 3 18
5 0 5 4 50
5 1 1 3 64
5 1 2 3 2
5 1 3 3 2
5 1 4 4 2
5 1 5 4 34
5 2 1 3 64
5 2 2 3 2
5 2 3 4 2
5 2 4 4 2
5 2 5 4 34
5 3 1 3 64
5 3 2 4 2
5 3 3 4 2
5 3 4 4 2
5 3 5 4 34
5 4 1 4 64
5 4 2 4 2
5 4 3 4 2
5 4 4 4 2
5 4 5 4 34
5 5 1 4 64
5 5 2 4 2
5 5 3 4 2
5 5 4 4 2
5 5 5 1 34
5 6 1 4 64
5 6 2 4 2
5 6 3 4 2
5 6 4 1 2
5 6 5 1 34
5 7 0 4 90
5 7 1 4 8
5 7 2 4 8
5 7 3 1 8
5 7 4 1 8
5 7 5 1 42
6 0 1 3 114
6 1 1 3 98
6 2 1 3 98
6 3 1 3 98
6 4 1 4 98
6 5 1 4 98
6 6 1 4 98
6 7 1 4 74
6 7 2 4 26
6 7 3 1 26
6 7 4 1 58
