Qubicle Exchange Format
Version 0.2
www.minddesk.com
8 8 8
5
0.250980 0.172549 0.000000
0.933333 0.933333 0.933333
0.941176 0.666667 0.235294
1.000000 0.403922 0.094118
1.000000 1.000000 1.000000
1 0 1 3 116
1 1 1 3 100
1 2 1 3 100
1 3 1 3 100
1 4 1 4 100
1 5 1 4 100
1 6 1 4 100
1 7 1 4 76
1 7 2 1 28
1 7 3 1 28
1 7 4 1 60
2 0 1 3 80
2 0 2 3 20
2 0 3 3 20
2 0 4 3 20
2 0 5 4 52
2 1 1 3 64
2 1 2 3 4
2 1 3 3 4
2 1 4 4 4
2 1 5 4 36
2 2 1 3 64
2 2 2 3 4
2 2 3 4 4
2 2 4 4 4
2 2 5 4 36
2 3 1 3 64
2 3 2 4 4
2 3 3 4 4
2 3 4 4 4
2 3 5 4 36
2 4 1 4 64
2 4 2 4 4
2 4 3 4 4
2 4 4 4 4
2 4 5 4 36
2 5 1 4 64
2 5 2 4 4
2 5 3 4 4
2 5 4 4 4
2 5 5 1 36
2 6 1 4 64
2 6 2 4 4
2 6 3 4 4
2 6 4 1 4
2 6 5 1 36
2 7 0 4 92
2 7 1 4 8
2 7 2 4 8
2 7 3 1 8
2 7 4 1 8
2 7 5 1 44
3 0 1 3 80
3 0 2 3 16
3 0 3 3 16
3 0 4 3 16
3 0 5 4 16
3 0 6 4 52
3 1 1 3 64
3 1 2 0 0
3 1 3 0 0
3 1 4 0 0
3 1 5 0 0
3 1 6 4 36
3 2 1 3 64
3 2 2 0 0
3 2 3 0 0
3 2 4 0 0
3 2 5 0 0
3 2 6 4 36
3 3 1 3 64
3 3 2 0 0
3 3 3 0 0
3 3 4 0 0
3 3 5 0 0
3 3 6 4 36
3 4 1 4 64
3 4 2 0 0
3 4 3 0 0
3 4 4 0 0
3 4 5 0 0
3 4 6 1 36
3 5 1 4 64
3 5 2 0 0
3 5 3 0 0
3 5 4 0 0
3 5 5 0 0
3 5 6 1 36
3 6 1 4 64
3 6 2 0 0
3 6 3 0 0
3 6 4 0 0
3 6 5 0 0
3 6 6 1 36
3 7 0 4 90
3 7 1 4 8
3 7 2 2 8
3 7 3 2 8
3 7 4 2 8
3 7 5 2 8
3 7 6 1 44
4 0 1 3 82
4 0 2 3 16
4 0 3 3 16
4 0 4 3 16
4 0 5 4 16
4 0 6 4 48
4 1 1 3 66
4 1 2 0 0
4 1 3 0 0
4 1 4 0 0
4 1 5 0 0
4 1 6 4 32
4 2 1 3 66
4 2 2 0 0
4 2 3 0 0
4 2 4 0 0
4 2 5 0 0
4 2 6 4 32
4 3 1 3 66
4 3 2 0 0
4 3 3 0 0
4 3 4 0 0
4 3 5 0 0
4 3 6 4 32
4 4 1 4 66
4 4 2 0 0
4 4 3 0 0
4 4 4 0 0
4 4 5 0 0
4 4 6 1 32
4 5 1 4 66
4 5 2 0 0
4 5 3 0 0
4 5 4 0 0
4 5 5 0 0
4 5 6 1 32
4 6 1 4 66
4 6 2 0 0
4 6 3 0 0
4 6 4 0 0
4 6 5 0 0
4 6 6 1 32
4 7 1 4 74
4 7 2 2 8
4 7 3 2 8
4 7 4 2 8
4 7 5 2 8
4 7 6 1 8
4 7 7 1 60
5 0 2 3 82
5 0 3 3 18
5 0 4 3 18
5 0 5 4 18
5 0 6 4 48
5 1 2 3 66
5 1 3 3 2
5 1 4 4 2
5 1 5 4 2
5 1 6 4 32
5 2 2 3 66
5 2 3 4 2
5 2 4 4 2
5 2 5 4 2
5 2 6 4 32
5 3 2 4 66
5 3 3 4 2
5 3 4 4 2
5 3 5 4 2
5 3 6 4 32
5 4 2 4 66
5 4 3 4 2
5 4 4 4 2
5 4 5 4 2
5 4 6 1 32
5 5 2 4 66
5 5 3 4 2
5 5 4 4 2
5 5 5 1 2
5 5 6 1 32
5 6 2 4 66
5 6 3 4 2
5 6 4 1 2
5 6 5 1 2
5 6 6 1 32
5 7 2 4 74
5 7 3 1 8
5 7 4 1 8
5 7 5 1 8
5 7 6 1 8
5 7 7 1 58
6 0 6 4 114
6 1 6 4 98
6 2 6 4 98
6 3 6 4 98
6 4 6 1 98
6 5 6 1 98
6 6 6 1 98
6 7 3 1 90
6 7 4 1 26
6 7 5 1 26
6 7 6 1 42
