Qubicle Exchange Format
Version 0.2
www.minddesk.com
8 8 8
5
0.250980 0.172549 0.000000
0.933333 0.933333 0.933333
0.941176 0.666667 0.235294
1.000000 0.403922 0.094118
1.000000 1.000000 1.000000
1 4 1 4 92
1 4 2 4 28
1 4 3 4 28
1 4 4 4 28
1 4 5 4 28
1 4 6 1 60
1 6 2 1 92
1 6 3 1 28
1 6 4 1 28
1 6 5 1 60
2 0 1 3 84
2 0 2 3 20
2 0 3 3 20
2 0 4 3 20
2 0 5 4 20
2 0 6 4 52
2 1 1 3 68
2 1 2 3 4
2 1 3 3 4
2 1 4 4 4
2 1 5 4 4
2 1 6 4 36
2 2 1 3 68
2 2 2 3 4
2 2 3 4 4
2 2 4 4 4
2 2 5 4 4
2 2 6 4 36
2 3 1 3 68
2 3 2 4 4
2 3 3 4 4
2 3 4 4 4
2 3 5 4 4
2 3 6 4 36
2 4 0 4 92
2 4 1 4 0
2 4 2 4 0
2 4 3 4 0
2 4 4 4 0
2 4 5 1 0
2 4 6 1 0
2 4 7 1 60
2 5 1 4 68
2 5 2 4 4
2 5 3 4 4
2 5 4 1 4
2 5 5 1 4
2 5 6 1 36
2 6 1 4 76
2 6 2 4 8
2 6 3 1 8
2 6 4 1 8
2 6 5 1 8
2 6 6 1 44
3 0 1 3 80
3 0 2 3 16
3 0 3 3 16
3 0 4 3 16
3 0 5 4 16
3 0 6 4 48
3 1 1 3 64
3 1 2 0 0
3 1 3 0 0
3 1 4 0 0
3 1 5 0 0
3 1 6 4 32
3 2 1 3 64
3 2 2 0 0
3 2 3 0 0
3 2 4 0 0
3 2 5 0 0
3 2 6 4 32
3 3 1 3 64
3 3 2 0 0
3 3 3 0 0
3 3 4 0 0
3 3 5 0 0
3 3 6 4 32
3 4 0 4 88
3 4 1 4 0
3 4 2 0 0
3 4 3 0 0
3 4 4 0 0
3 4 5 0 0
3 4 6 1 0
3 4 7 1 56
3 5 1 4 64
3 5 2 0 0
3 5 3 0 0
3 5 4 0 0
3 5 5 0 0
3 5 6 1 32
3 6 0 4 92
3 6 1 4 8
3 6 2 2 8
3 6 3 2 8
3 6 4 2 8
3 6 5 2 8
3 6 6 1 8
3 6 7 1 60
4 0 1 3 80
4 0 2 3 16
4 0 3 3 16
4 0 4 3 16
4 0 5 4 16
4 0 6 4 48
4 1 1 3 64
4 1 2 0 0
4 1 3 0 0
4 1 4 0 0
4 1 5 0 0
4 1 6 4 32
4 2 1 3 64
4 2 2 0 0
4 2 3 0 0
4 2 4 0 0
4 2 5 0 0
4 2 6 4 32
4 3 1 3 64
4 3 2 0 0
4 3 3 0 0
4 3 4 0 0
4 3 5 0 0
4 3 6 4 32
4 4 0 4 88
4 4 1 4 0
4 4 2 0 0
4 4 3 0 0
4 4 4 0 0
4 4 5 0 0
4 4 6 1 0
4 4 7 1 56
4 5 1 4 64
4 5 2 0 0
4 5 3 0 0
4 5 4 0 0
4 5 5 0 0
4 5 6 1 32
4 6 0 4 90
4 6 1 4 8
4 6 2 2 8
4 6 3 2 8
4 6 4 2 8
4 6 5 2 8
4 6 6 1 8
4 6 7 1 58
5 0 1 3 82
5 0 2 3 18
5 0 3 3 18
5 0 4 3 18
5 0 5 4 18
5 0 6 4 50
5 1 1 3 66
5 1 2 3 2
5 1 3 3 2
5 1 4 4 2
5 1 5 4 2
5 1 6 4 34
5 2 1 3 66
5 2 2 3 2
5 2 3 4 2
5 2 4 4 2
5 2 5 4 2
5 2 6 4 34
5 3 1 3 66
5 3 2 4 2
5 3 3 4 2
5 3 4 4 2
5 3 5 4 2
5 3 6 4 34
5 4 0 4 90
5 4 1 4 0
5 4 2 4 0
5 4 3 4 0
5 4 4 4 0
5 4 5 1 0
5 4 6 1 0
5 4 7 1 58
5 5 1 4 66
5 5 2 4 2
5 5 3 4 2
5 5 4 1 2
5 5 5 1 2
5 5 6 1 34
5 6 1 4 74
5 6 2 4 8
5 6 3 1 8
5 6 4 1 8
5 6 5 1 8
5 6 6 1 42
6 4 1 4 90
6 4 2 4 26
6 4 3 4 26
6 4 4 4 26
6 4 5 4 26
6 4 6 1 58
6 6 2 4 90
6 6 3 1 26
6 6 4 1 26
6 6 5 1 58
