Qubicle Exchange Format
Version 0.2
www.minddesk.com
8 8 8
5
0.250980 0.172549 0.000000
0.933333 0.933333 0.933333
0.941176 0.666667 0.235294
1.000000 0.403922 0.094118
1.000000 1.000000 1.000000
1 7 2 1 126
1 7 3 1 126
1 7 4 1 126
1 7 5 1 126
2 0 1 3 126
2 0 2 3 126
2 0 3 3 126
2 0 4 3 126
2 0 5 4 126
2 0 6 4 126
2 1 1 3 126
2 1 2 3 126
2 1 3 3 126
2 1 4 4 126
2 1 5 4 126
2 1 6 4 126
2 2 1 3 126
2 2 2 3 126
2 2 3 4 126
2 2 4 4 126
2 2 5 4 126
2 2 6 4 126
2 3 1 3 126
2 3 2 4 126
2 3 3 4 126
2 3 4 4 126
2 3 5 4 126
2 3 6 4 126
2 4 1 4 126
2 4 2 4 126
2 4 3 4 126
2 4 4 4 126
2 4 5 4 126
2 4 6 1 126
2 5 1 4 126
2 5 2 4 126
2 5 3 4 126
2 5 4 4 126
2 5 5 1 126
2 5 6 1 126
2 6 1 4 126
2 6 2 4 126
2 6 3 4 126
2 6 4 1 126
2 6 5 1 126
2 6 6 1 126
2 7 1 4 126
2 7 2 4 126
2 7 3 1 126
2 7 4 1 126
2 7 5 1 126
2 7 6 1 126
3 0 1 3 126
3 0 2 3 126
3 0 3 3 126
3 0 4 3 126
3 0 5 4 126
3 0 6 4 126
3 1 1 3 126
3 1 2 0 100
3 1 3 0 126
3 1 4 0 126
3 1 5 0 100
3 1 6 4 126
3 2 1 3 126
3 2 2 0 64
3 2 3 0 16
3 2 4 0 16
3 2 5 0 32
3 2 6 4 126
3 3 1 3 126
3 3 2 0 68
3 3 3 0 0
3 3 4 0 0
3 3 5 0 32
3 3 6 4 126
3 4 1 4 126
3 4 2 0 0
3 4 3 0 0
3 4 4 0 0
3 4 5 0 0
3 4 6 1 126
3 5 1 4 126
3 5 2 0 0
3 5 3 0 0
3 5 4 0 0
3 5 5 0 0
3 5 6 1 126
3 6 1 4 126
3 6 2 0 0
3 6 3 0 0
3 6 4 0 0
3 6 5 0 0
3 6 6 1 126
3 7 0 4 126
3 7 1 4 126
3 7 2 2 126
3 7 3 2 126
3 7 4 2 126
3 7 5 2 126
3 7 6 1 126
3 7 7 1 126
4 0 1 3 126
4 0 2 3 126
4 0 3 3 126
4 0 4 3 126
4 0 5 4 126
4 0 6 4 126
4 1 1 3 126
4 1 2 0 98
4 1 3 0 126
4 1 4 0 126
4 1 5 0 98
4 1 6 4 126
4 2 1 3 126
4 2 2 0 64
4 2 3 0 16
4 2 4 0 16
4 2 5 0 32
4 2 6 4 126
4 3 1 3 126
4 3 2 0 64
4 3 3 0 0
4 3 4 0 0
4 3 5 0 32
4 3 6 4 126
4 4 1 4 126
4 4 2 0 0
4 4 3 0 0
4 4 4 0 0
4 4 5 0 0
4 4 6 1 126
4 5 1 4 126
4 5 2 0 0
4 5 3 0 0
4 5 4 0 0
4 5 5 0 0
4 5 6 1 126
4 6 1 4 126
4 6 2 0 0
4 6 3 0 0
4 6 4 0 0
4 6 5 0 0
4 6 6 1 126
4 7 0 4 126
4 7 1 4 126
4 7 2 2 126
4 7 3 2 126
4 7 4 2 126
4 7 5 2 126
4 7 6 1 126
4 7 7 1 126
5 0 1 3 126
5 0 2 3 126
5 0 3 3 126
5 0 4 3 126
5 0 5 4 126
5 0 6 4 126
5 1 1 3 126
5 1 2 3 126
5 1 3 3 126
5 1 4 4 126
5 1 5 4 126
5 1 6 4 126
5 2 1 3 126
5 2 2 3 126
5 2 3 4 126
5 2 4 4 126
5 2 5 4 126
5 2 6 4 126
5 3 1 3 126
5 3 2 4 126
5 3 3 4 126
5 3 4 4 126
5 3 5 4 126
5 3 6 4 126
5 4 1 4 126
5 4 2 4 126
5 4 3 4 126
5 4 4 4 126
5 4 5 4 126
5 4 6 1 126
5 5 1 4 126
5 5 2 4 126
5 5 3 4 126
5 5 4 4 126
5 5 5 1 126
5 5 6 1 126
5 6 1 4 126
5 6 2 4 126
5 6 3 4 126
5 6 4 1 126
5 6 5 1 126
5 6 6 1 126
5 7 1 4 126
5 7 2 4 126
5 7 3 1 126
5 7 4 1 126
5 7 5 1 126
5 7 6 1 126
6 7 2 4 126
6 7 3 1 126
6 7 4 1 126
6 7 5 1 126
