Qubicle Exchange Format
Version 0.2
www.minddesk.com
16 16 16
699
0.000000 0.000000 0.000000
0.000000 0.168627 0.054902
0.000000 0.172549 0.054902
0.000000 0.176471 0.054902
0.000000 0.176471 0.058824
0.000000 0.180392 0.054902
0.000000 0.180392 0.058824
0.000000 0.184314 0.054902
0.000000 0.184314 0.058824
0.000000 0.188235 0.058824
0.000000 0.188235 0.062745
0.000000 0.192157 0.058824
0.000000 0.192157 0.062745
0.000000 0.196078 0.058824
0.000000 0.196078 0.062745
0.000000 0.200000 0.058824
0.000000 0.200000 0.062745
0.000000 0.200000 0.066667
0.000000 0.203922 0.062745
0.000000 0.203922 0.066667
0.000000 0.203922 0.070588
0.000000 0.207843 0.062745
0.000000 0.207843 0.066667
0.000000 0.207843 0.070588
0.000000 0.211765 0.062745
0.000000 0.211765 0.066667
0.000000 0.211765 0.070588
0.000000 0.215686 0.066667
0.000000 0.215686 0.070588
0.000000 0.219608 0.066667
0.000000 0.219608 0.070588
0.000000 0.219608 0.074510
0.000000 0.223529 0.066667
0.000000 0.223529 0.070588
0.000000 0.223529 0.074510
0.000000 0.227451 0.070588
0.000000 0.227451 0.078431
0.000000 0.231373 0.074510
0.003922 0.200000 0.070588
0.003922 0.203922 0.070588
0.003922 0.207843 0.066667
0.003922 0.207843 0.070588
0.003922 0.211765 0.070588
0.003922 0.211765 0.074510
0.003922 0.215686 0.078431
0.003922 0.219608 0.074510
0.003922 0.219608 0.078431
0.003922 0.223529 0.074510
0.003922 0.223529 0.078431
0.003922 0.223529 0.082353
0.003922 0.227451 0.074510
0.003922 0.227451 0.078431
0.003922 0.231373 0.082353
0.003922 0.235294 0.078431
0.003922 0.235294 0.082353
0.007843 0.196078 0.070588
0.007843 0.207843 0.070588
0.007843 0.211765 0.070588
0.007843 0.211765 0.078431
0.007843 0.215686 0.074510
0.007843 0.215686 0.078431
0.007843 0.219608 0.074510
0.007843 0.219608 0.078431
0.007843 0.219608 0.082353
0.007843 0.223529 0.086275
0.007843 0.227451 0.078431
0.007843 0.227451 0.082353
0.007843 0.227451 0.086275
0.007843 0.231373 0.078431
0.011765 0.200000 0.078431
0.011765 0.203922 0.078431
0.011765 0.207843 0.074510
0.011765 0.207843 0.078431
0.011765 0.211765 0.078431
0.011765 0.219608 0.078431
0.011765 0.219608 0.082353
0.011765 0.223529 0.082353
0.011765 0.227451 0.082353
0.011765 0.231373 0.082353
0.011765 0.231373 0.086275
0.011765 0.235294 0.086275
0.011765 0.243137 0.090196
0.015686 0.207843 0.078431
0.015686 0.215686 0.082353
0.015686 0.215686 0.086275
0.015686 0.219608 0.082353
0.015686 0.219608 0.086275
0.015686 0.223529 0.086275
0.015686 0.223529 0.090196
0.015686 0.227451 0.082353
0.015686 0.227451 0.086275
0.015686 0.227451 0.090196
0.015686 0.231373 0.086275
0.015686 0.231373 0.090196
0.015686 0.239216 0.090196
0.015686 0.239216 0.094118
0.015686 0.243137 0.094118
0.015686 0.247059 0.094118
0.019608 0.215686 0.082353
0.019608 0.215686 0.086275
0.019608 0.223529 0.090196
0.019608 0.227451 0.090196
0.019608 0.231373 0.090196
0.019608 0.235294 0.090196
0.019608 0.235294 0.094118
0.019608 0.243137 0.090196
0.019608 0.243137 0.094118
0.019608 0.247059 0.094118
0.019608 0.247059 0.098039
0.019608 0.250980 0.098039
0.023529 0.211765 0.086275
0.023529 0.215686 0.090196
0.023529 0.219608 0.086275
0.023529 0.219608 0.090196
0.023529 0.219608 0.094118
0.023529 0.227451 0.090196
0.023529 0.231373 0.094118
0.023529 0.235294 0.090196
0.023529 0.235294 0.098039
0.023529 0.239216 0.098039
0.023529 0.243137 0.098039
0.023529 0.247059 0.098039
0.023529 0.250980 0.098039
0.023529 0.250980 0.101961
0.027451 0.215686 0.090196
0.027451 0.219608 0.090196
0.027451 0.223529 0.090196
0.027451 0.227451 0.094118
0.027451 0.231373 0.094118
0.027451 0.231373 0.098039
0.027451 0.235294 0.094118
0.027451 0.235294 0.098039
0.027451 0.243137 0.101961
0.027451 0.258824 0.105882
0.031373 0.215686 0.094118
0.031373 0.223529 0.094118
0.031373 0.223529 0.098039
0.031373 0.227451 0.094118
0.031373 0.227451 0.098039
0.031373 0.227451 0.101961
0.031373 0.231373 0.098039
0.031373 0.235294 0.098039
0.031373 0.235294 0.101961
0.031373 0.239216 0.101961
0.031373 0.243137 0.101961
0.031373 0.243137 0.105882
0.031373 0.247059 0.101961
0.031373 0.247059 0.105882
0.031373 0.250980 0.101961
0.031373 0.250980 0.105882
0.031373 0.254902 0.105882
0.031373 0.254902 0.109804
0.035294 0.219608 0.098039
0.035294 0.223529 0.098039
0.035294 0.227451 0.098039
0.035294 0.227451 0.101961
0.035294 0.231373 0.098039
0.035294 0.231373 0.101961
0.035294 0.235294 0.101961
0.035294 0.239216 0.101961
0.035294 0.243137 0.105882
0.035294 0.247059 0.105882
0.035294 0.247059 0.109804
0.035294 0.250980 0.109804
0.035294 0.254902 0.105882
0.035294 0.254902 0.109804
0.035294 0.262745 0.113725
0.039216 0.223529 0.098039
0.039216 0.231373 0.105882
0.039216 0.235294 0.101961
0.039216 0.235294 0.105882
0.039216 0.239216 0.105882
0.039216 0.243137 0.105882
0.039216 0.243137 0.109804
0.039216 0.247059 0.105882
0.039216 0.247059 0.109804
0.039216 0.250980 0.109804
0.039216 0.254902 0.109804
0.039216 0.254902 0.113725
0.039216 0.258824 0.109804
0.039216 0.258824 0.113725
0.039216 0.258824 0.117647
0.039216 0.262745 0.113725
0.039216 0.262745 0.117647
0.043137 0.223529 0.105882
0.043137 0.227451 0.105882
0.043137 0.227451 0.109804
0.043137 0.231373 0.105882
0.043137 0.231373 0.109804
0.043137 0.235294 0.105882
0.043137 0.235294 0.109804
0.043137 0.239216 0.105882
0.043137 0.239216 0.109804
0.043137 0.243137 0.109804
0.043137 0.247059 0.109804
0.043137 0.247059 0.113725
0.043137 0.250980 0.109804
0.043137 0.250980 0.113725
0.043137 0.254902 0.113725
0.043137 0.254902 0.117647
0.043137 0.258824 0.113725
0.043137 0.262745 0.117647
0.043137 0.262745 0.121569
0.043137 0.266667 0.121569
0.047059 0.227451 0.105882
0.047059 0.231373 0.109804
0.047059 0.239216 0.109804
0.047059 0.243137 0.109804
0.047059 0.243137 0.113725
0.047059 0.247059 0.109804
0.047059 0.247059 0.113725
0.047059 0.247059 0.117647
0.047059 0.250980 0.113725
0.047059 0.250980 0.117647
0.047059 0.254902 0.113725
0.047059 0.254902 0.117647
0.047059 0.254902 0.121569
0.047059 0.258824 0.117647
0.047059 0.262745 0.121569
0.047059 0.266667 0.121569
0.047059 0.270588 0.125490
0.050980 0.239216 0.113725
0.050980 0.243137 0.113725
0.050980 0.247059 0.113725
0.050980 0.247059 0.117647
0.050980 0.250980 0.121569
0.050980 0.254902 0.113725
0.050980 0.254902 0.117647
0.050980 0.254902 0.121569
0.050980 0.258824 0.117647
0.050980 0.258824 0.121569
0.050980 0.266667 0.121569
0.050980 0.266667 0.125490
0.050980 0.270588 0.121569
0.050980 0.270588 0.125490
0.050980 0.274510 0.125490
0.054902 0.239216 0.113725
0.054902 0.239216 0.117647
0.054902 0.243137 0.113725
0.054902 0.243137 0.117647
0.054902 0.247059 0.113725
0.054902 0.247059 0.117647
0.054902 0.247059 0.121569
0.054902 0.250980 0.117647
0.054902 0.250980 0.121569
0.054902 0.254902 0.121569
0.054902 0.254902 0.125490
0.054902 0.262745 0.125490
0.054902 0.266667 0.121569
0.054902 0.266667 0.129412
0.054902 0.270588 0.125490
0.054902 0.270588 0.129412
0.054902 0.274510 0.129412
0.054902 0.274510 0.133333
0.058824 0.243137 0.121569
0.058824 0.247059 0.117647
0.058824 0.247059 0.121569
0.058824 0.250980 0.121569
0.058824 0.258824 0.125490
0.058824 0.258824 0.129412
0.058824 0.262745 0.125490
0.058824 0.262745 0.129412
0.058824 0.266667 0.125490
0.058824 0.266667 0.129412
0.058824 0.270588 0.129412
0.058824 0.274510 0.133333
0.058824 0.278431 0.129412
0.058824 0.278431 0.133333
0.058824 0.278431 0.137255
0.062745 0.243137 0.121569
0.062745 0.243137 0.125490
0.062745 0.247059 0.121569
0.062745 0.247059 0.125490
0.062745 0.247059 0.129412
0.062745 0.250980 0.121569
0.062745 0.250980 0.125490
0.062745 0.254902 0.125490
0.062745 0.258824 0.125490
0.062745 0.258824 0.129412
0.062745 0.262745 0.125490
0.062745 0.262745 0.129412
0.062745 0.262745 0.133333
0.062745 0.266667 0.125490
0.062745 0.266667 0.129412
0.062745 0.266667 0.133333
0.062745 0.270588 0.133333
0.062745 0.274510 0.133333
0.062745 0.274510 0.137255
0.062745 0.278431 0.133333
0.062745 0.278431 0.137255
0.062745 0.282353 0.137255
0.062745 0.286275 0.137255
0.066667 0.247059 0.125490
0.066667 0.254902 0.129412
0.066667 0.258824 0.129412
0.066667 0.258824 0.133333
0.066667 0.262745 0.129412
0.066667 0.262745 0.133333
0.066667 0.262745 0.137255
0.066667 0.266667 0.133333
0.066667 0.266667 0.137255
0.066667 0.270588 0.133333
0.066667 0.270588 0.137255
0.066667 0.278431 0.137255
0.066667 0.282353 0.137255
0.066667 0.282353 0.141176
0.066667 0.286275 0.141176
0.070588 0.247059 0.129412
0.070588 0.250980 0.133333
0.070588 0.254902 0.133333
0.070588 0.258824 0.129412
0.070588 0.262745 0.133333
0.070588 0.262745 0.137255
0.070588 0.266667 0.133333
0.070588 0.266667 0.137255
0.070588 0.270588 0.133333
0.070588 0.270588 0.137255
0.070588 0.270588 0.141176
0.070588 0.274510 0.137255
0.070588 0.274510 0.141176
0.070588 0.278431 0.137255
0.070588 0.278431 0.141176
0.070588 0.282353 0.141176
0.070588 0.286275 0.141176
0.070588 0.286275 0.145098
0.070588 0.290196 0.145098
0.074510 0.250980 0.129412
0.074510 0.254902 0.129412
0.074510 0.258824 0.137255
0.074510 0.262745 0.137255
0.074510 0.266667 0.137255
0.074510 0.266667 0.141176
0.074510 0.270588 0.137255
0.074510 0.270588 0.141176
0.074510 0.270588 0.145098
0.074510 0.274510 0.141176
0.074510 0.278431 0.141176
0.074510 0.278431 0.145098
0.074510 0.282353 0.145098
0.074510 0.282353 0.149020
0.074510 0.290196 0.145098
0.074510 0.290196 0.149020
0.078431 0.254902 0.141176
0.078431 0.258824 0.137255
0.078431 0.266667 0.141176
0.078431 0.270588 0.137255
0.078431 0.270588 0.141176
0.078431 0.270588 0.145098
0.078431 0.274510 0.141176
0.078431 0.274510 0.145098
0.078431 0.278431 0.141176
0.078431 0.278431 0.145098
0.078431 0.278431 0.149020
0.078431 0.282353 0.145098
0.078431 0.286275 0.145098
0.078431 0.286275 0.149020
0.078431 0.290196 0.149020
0.078431 0.290196 0.152941
0.078431 0.294118 0.152941
0.082353 0.258824 0.141176
0.082353 0.258824 0.145098
0.082353 0.262745 0.141176
0.082353 0.266667 0.141176
0.082353 0.266667 0.145098
0.082353 0.270588 0.145098
0.082353 0.270588 0.149020
0.082353 0.274510 0.145098
0.082353 0.274510 0.149020
0.082353 0.278431 0.145098
0.082353 0.278431 0.149020
0.082353 0.282353 0.149020
0.082353 0.286275 0.149020
0.082353 0.286275 0.152941
0.082353 0.290196 0.152941
0.082353 0.294118 0.156863
0.082353 0.298039 0.156863
0.086275 0.266667 0.145098
0.086275 0.270588 0.149020
0.086275 0.274510 0.149020
0.086275 0.278431 0.149020
0.086275 0.278431 0.152941
0.086275 0.282353 0.149020
0.086275 0.282353 0.152941
0.086275 0.282353 0.156863
0.086275 0.286275 0.152941
0.086275 0.286275 0.156863
0.086275 0.290196 0.152941
0.086275 0.290196 0.156863
0.086275 0.294118 0.152941
0.086275 0.294118 0.156863
0.086275 0.298039 0.156863
0.086275 0.301961 0.156863
0.086275 0.301961 0.160784
0.090196 0.270588 0.149020
0.090196 0.274510 0.152941
0.090196 0.282353 0.152941
0.090196 0.282353 0.156863
0.090196 0.286275 0.152941
0.090196 0.286275 0.156863
0.090196 0.290196 0.156863
0.090196 0.290196 0.160784
0.090196 0.294118 0.156863
0.090196 0.294118 0.160784
0.090196 0.298039 0.160784
0.090196 0.298039 0.164706
0.090196 0.301961 0.164706
0.094118 0.286275 0.156863
0.094118 0.286275 0.160784
0.094118 0.290196 0.156863
0.094118 0.290196 0.160784
0.094118 0.294118 0.160784
0.094118 0.298039 0.160784
0.094118 0.301961 0.160784
0.094118 0.301961 0.164706
0.094118 0.305882 0.164706
0.098039 0.286275 0.160784
0.098039 0.286275 0.164706
0.098039 0.294118 0.160784
0.098039 0.294118 0.164706
0.098039 0.298039 0.164706
0.098039 0.301961 0.164706
0.098039 0.305882 0.168627
0.098039 0.305882 0.172549
0.098039 0.309804 0.168627
0.101961 0.290196 0.164706
0.101961 0.294118 0.164706
0.101961 0.298039 0.164706
0.101961 0.298039 0.168627
0.101961 0.301961 0.168627
0.101961 0.301961 0.172549
0.101961 0.305882 0.168627
0.101961 0.305882 0.172549
0.101961 0.309804 0.172549
0.101961 0.313726 0.172549
0.101961 0.313726 0.176471
0.105882 0.294118 0.168627
0.105882 0.298039 0.168627
0.105882 0.298039 0.172549
0.105882 0.301961 0.168627
0.105882 0.301961 0.172549
0.105882 0.305882 0.172549
0.105882 0.305882 0.176471
0.105882 0.309804 0.172549
0.105882 0.309804 0.176471
0.105882 0.313726 0.172549
0.105882 0.313726 0.176471
0.109804 0.294118 0.172549
0.109804 0.294118 0.176471
0.109804 0.298039 0.172549
0.109804 0.301961 0.172549
0.109804 0.301961 0.176471
0.109804 0.305882 0.176471
0.109804 0.309804 0.180392
0.109804 0.313726 0.176471
0.109804 0.313726 0.180392
0.109804 0.317647 0.176471
0.109804 0.317647 0.180392
0.113725 0.298039 0.176471
0.113725 0.298039 0.180392
0.113725 0.301961 0.172549
0.113725 0.301961 0.176471
0.113725 0.305882 0.176471
0.113725 0.305882 0.180392
0.113725 0.309804 0.176471
0.113725 0.309804 0.180392
0.113725 0.313726 0.180392
0.113725 0.313726 0.184314
0.113725 0.317647 0.180392
0.113725 0.317647 0.184314
0.113725 0.321569 0.180392
0.113725 0.321569 0.184314
0.117647 0.298039 0.180392
0.117647 0.301961 0.180392
0.117647 0.305882 0.184314
0.117647 0.309804 0.180392
0.117647 0.309804 0.184314
0.117647 0.313726 0.184314
0.117647 0.317647 0.184314
0.117647 0.321569 0.184314
0.117647 0.321569 0.188235
0.117647 0.325490 0.188235
0.121569 0.305882 0.184314
0.121569 0.309804 0.184314
0.121569 0.313726 0.184314
0.121569 0.313726 0.188235
0.121569 0.317647 0.188235
0.121569 0.321569 0.188235
0.121569 0.321569 0.192157
0.121569 0.325490 0.188235
0.121569 0.325490 0.192157
0.121569 0.329412 0.192157
0.125490 0.305882 0.188235
0.125490 0.309804 0.188235
0.125490 0.313726 0.188235
0.125490 0.317647 0.188235
0.125490 0.317647 0.192157
0.125490 0.321569 0.188235
0.125490 0.321569 0.192157
0.125490 0.325490 0.192157
0.125490 0.325490 0.196078
0.125490 0.329412 0.192157
0.125490 0.329412 0.196078
0.125490 0.333333 0.200000
0.129412 0.309804 0.192157
0.129412 0.317647 0.192157
0.129412 0.317647 0.196078
0.129412 0.321569 0.196078
0.129412 0.325490 0.196078
0.129412 0.325490 0.200000
0.129412 0.329412 0.192157
0.129412 0.329412 0.196078
0.129412 0.329412 0.200000
0.129412 0.333333 0.196078
0.129412 0.333333 0.200000
0.133333 0.313726 0.196078
0.133333 0.317647 0.196078
0.133333 0.321569 0.196078
0.133333 0.321569 0.200000
0.133333 0.325490 0.203922
0.133333 0.329412 0.200000
0.133333 0.333333 0.200000
0.133333 0.333333 0.203922
0.133333 0.337255 0.200000
0.133333 0.337255 0.203922
0.137255 0.325490 0.200000
0.137255 0.325490 0.203922
0.137255 0.337255 0.203922
0.137255 0.337255 0.207843
0.137255 0.341176 0.203922
0.141176 0.321569 0.200000
0.141176 0.325490 0.203922
0.141176 0.329412 0.203922
0.141176 0.333333 0.203922
0.141176 0.333333 0.207843
0.141176 0.341176 0.207843
0.141176 0.345098 0.207843
0.145098 0.325490 0.203922
0.145098 0.329412 0.203922
0.145098 0.329412 0.207843
0.145098 0.333333 0.207843
0.145098 0.341176 0.211765
0.145098 0.345098 0.211765
0.145098 0.345098 0.215686
0.149020 0.329412 0.203922
0.149020 0.329412 0.211765
0.149020 0.333333 0.211765
0.149020 0.337255 0.207843
0.149020 0.345098 0.211765
0.149020 0.345098 0.215686
0.149020 0.345098 0.219608
0.149020 0.349020 0.215686
0.152941 0.333333 0.211765
0.152941 0.349020 0.215686
0.152941 0.349020 0.219608
0.152941 0.349020 0.223529
0.152941 0.352941 0.215686
0.152941 0.352941 0.219608
0.156863 0.345098 0.219608
0.156863 0.349020 0.219608
0.156863 0.349020 0.223529
0.156863 0.352941 0.219608
0.156863 0.352941 0.223529
0.160784 0.337255 0.219608
0.160784 0.337255 0.223529
0.160784 0.341176 0.223529
0.160784 0.345098 0.223529
0.160784 0.352941 0.227451
0.160784 0.356863 0.223529
0.160784 0.356863 0.227451
0.160784 0.356863 0.231373
0.164706 0.356863 0.227451
0.164706 0.356863 0.231373
0.164706 0.360784 0.231373
0.164706 0.360784 0.235294
0.168627 0.356863 0.231373
0.168627 0.360784 0.235294
0.168627 0.364706 0.235294
0.168627 0.364706 0.239216
0.172549 0.364706 0.235294
0.172549 0.364706 0.239216
0.172549 0.368627 0.239216
0.176471 0.368627 0.239216
0.176471 0.368627 0.243137
0.184314 0.372549 0.247059
0.184314 0.372549 0.250980
0.184314 0.376471 0.247059
0.184314 0.376471 0.250980
0.188235 0.376471 0.250980
0.188235 0.376471 0.254902
0.192157 0.380392 0.254902
0.192157 0.384314 0.254902
0.196078 0.380392 0.258824
0.196078 0.384314 0.258824
0.203922 0.388235 0.262745
0.203922 0.388235 0.266667
0.207843 0.392157 0.266667
0.207843 0.392157 0.270588
0.211765 0.392157 0.274510
0.211765 0.396078 0.274510
0.215686 0.396078 0.274510
0.215686 0.396078 0.278431
0.305882 0.215686 0.015686
0.309804 0.215686 0.015686
0.313726 0.219608 0.015686
0.317647 0.219608 0.015686
0.317647 0.223529 0.015686
0.321569 0.223529 0.015686
0.321569 0.227451 0.015686
0.325490 0.227451 0.015686
0.329412 0.231373 0.015686
0.333333 0.231373 0.015686
0.333333 0.235294 0.015686
0.337255 0.235294 0.015686
0.341176 0.239216 0.019608
0.341176 0.243137 0.023529
0.345098 0.247059 0.027451
0.349020 0.247059 0.031373
0.349020 0.250980 0.035294
0.352941 0.254902 0.039216
0.356863 0.258824 0.043137
0.356863 0.258824 0.047059
0.360784 0.262745 0.050980
0.364706 0.266667 0.054902
0.368627 0.270588 0.062745
0.372549 0.274510 0.066667
0.372549 0.278431 0.070588
0.376471 0.282353 0.074510
0.380392 0.019608 0.000000
0.380392 0.282353 0.078431
0.380392 0.286275 0.082353
0.384314 0.290196 0.086275
0.388235 0.294118 0.090196
0.388235 0.294118 0.094118
0.392157 0.298039 0.098039
0.396078 0.301961 0.101961
0.396078 0.305882 0.105882
0.400000 0.305882 0.109804
0.407843 0.023529 0.000000
0.411765 0.019608 0.000000
0.415686 0.027451 0.000000
0.423529 0.019608 0.000000
0.427451 0.019608 0.000000
0.427451 0.023529 0.000000
0.431373 0.023529 0.000000
0.435294 0.031373 0.000000
0.439216 0.023529 0.000000
0.439216 0.078431 0.054902
0.443137 0.023529 0.000000
0.443137 0.058824 0.035294
0.447059 0.019608 0.000000
0.447059 0.023529 0.000000
0.450980 0.023529 0.000000
0.450980 0.043137 0.015686
0.454902 0.023529 0.000000
0.454902 0.058824 0.031373
0.458824 0.023529 0.000000
0.458824 0.035294 0.003922
0.458824 0.070588 0.043137
0.462745 0.043137 0.015686
0.466667 0.023529 0.000000
0.466667 0.082353 0.054902
0.474510 0.082353 0.050980
0.482353 0.043137 0.015686
0.482353 0.058824 0.031373
0.482353 0.098039 0.066667
0.482353 0.109804 0.082353
0.486275 0.066667 0.039216
0.486275 0.094118 0.062745
0.490196 0.043137 0.011765
0.490196 0.047059 0.015686
0.494118 0.070588 0.039216
0.498039 0.058824 0.027451
0.498039 0.109804 0.082353
0.501961 0.062745 0.031373
0.501961 0.078431 0.047059
0.501961 0.113725 0.086275
0.505882 0.074510 0.043137
0.509804 0.082353 0.050980
0.509804 0.101961 0.074510
0.513726 0.090196 0.058824
0.513726 0.094118 0.062745
0.525490 0.117647 0.086275
0.525490 0.133333 0.101961
0.529412 0.125490 0.094118
0.529412 0.145098 0.113725
0.533333 0.121569 0.094118
0.537255 0.133333 0.105882
0.537255 0.137255 0.109804
0.549020 0.160784 0.137255
0.576471 0.211765 0.188235
0.611765 0.050980 0.105882
0.623529 0.050980 0.105882
0.643137 0.050980 0.105882
0.654902 0.011765 0.074510
0.658824 0.105882 0.156863
0.674510 0.090196 0.149020
0.674510 0.094118 0.149020
0.678431 0.082353 0.141176
0.996078 0.000000 0.000000
2 4 6 603 84
2 4 7 609 20
2 4 8 631 20
2 4 9 610 20
2 4 10 119 20
2 4 11 22 20
2 4 12 481 60
2 5 6 617 76
2 5 7 602 12
2 5 8 635 12
2 5 9 608 12
2 5 10 349 12
2 5 11 25 44
2 8 2 217 84
2 8 3 358 20
2 8 4 688 126
2 8 5 688 126
2 8 6 688 126
2 8 7 688 126
2 8 8 51 20
2 8 9 65 20
2 8 10 295 20
2 8 11 6 20
2 8 12 406 20
2 8 13 182 52
2 9 2 31 68
2 9 3 291 4
2 9 4 320 126
2 9 5 489 4
2 9 6 429 4
2 9 7 14 4
2 9 8 476 4
2 9 9 145 4
2 9 10 163 4
2 9 11 210 4
2 9 12 428 4
2 9 13 358 36
2 10 2 63 68
2 10 3 189 4
2 10 4 320 126
2 10 5 320 126
2 10 6 153 4
2 10 7 116 4
2 10 8 38 4
2 10 9 576 4
2 10 10 141 4
2 10 11 145 4
2 10 12 494 4
2 10 13 14 36
2 11 2 382 68
2 11 3 51 4
2 11 4 320 126
2 11 5 320 126
2 11 6 18 4
2 11 7 1 4
2 11 8 374 4
2 11 9 375 4
2 11 10 336 4
2 11 11 50 4
2 11 12 239 4
2 11 13 161 36
2 12 2 27 68
2 12 3 506 4
2 12 4 396 4
2 12 5 320 126
2 12 6 560 4
2 12 7 476 4
2 12 8 568 4
2 12 9 27 4
2 12 10 251 4
2 12 11 221 4
2 12 12 22 4
2 12 13 11 36
2 13 2 22 68
2 13 3 263 4
2 13 4 432 4
2 13 5 416 4
2 13 6 247 4
2 13 7 588 4
2 13 8 282 4
2 13 9 356 12
2 13 10 472 12
2 13 11 289 12
2 13 12 22 12
2 13 13 27 44
2 14 2 309 68
2 14 3 398 4
2 14 4 12 4
2 14 5 221 4
2 14 6 496 4
2 14 7 329 4
2 14 8 393 36
2 15 2 155 76
2 15 3 210 12
2 15 4 688 126
2 15 5 688 126
2 15 6 590 12
2 15 7 426 12
2 15 8 193 44
3 4 6 634 80
3 4 7 612 16
3 4 8 603 16
3 4 9 620 16
3 4 10 557 16
3 4 11 485 16
3 4 12 172 18
3 4 13 442 62
3 5 6 609 72
3 5 7 629 8
3 5 8 608 8
3 5 9 609 8
3 5 10 12 8
3 5 11 9 8
3 5 12 158 46
3 8 2 325 80
3 8 3 132 16
3 8 4 389 16
3 8 5 461 16
3 8 6 131 16
3 8 7 283 16
3 8 8 161 16
3 8 9 66 16
3 8 10 333 16
3 8 11 247 16
3 8 12 167 16
3 8 13 335 48
3 9 2 26 64
3 9 3 143 0
3 9 4 538 0
3 9 5 516 0
3 9 6 131 0
3 9 7 210 0
3 9 8 22 0
3 9 9 22 0
3 9 10 6 0
3 9 11 565 0
3 9 12 267 0
3 9 13 318 32
3 10 2 229 66
3 10 3 249 0
3 10 4 627 0
3 10 5 648 0
3 10 6 116 0
3 10 7 366 0
3 10 8 39 0
3 10 9 534 0
3 10 10 232 0
3 10 11 61 0
3 10 12 238 0
3 10 13 85 32
3 11 2 258 64
3 11 3 214 0
3 11 4 638 0
3 11 5 640 0
3 11 6 173 0
3 11 7 4 0
3 11 8 414 0
3 11 9 60 0
3 11 10 16 0
3 11 11 12 0
3 11 12 335 0
3 11 13 347 32
3 12 2 66 64
3 12 3 22 0
3 12 4 568 0
3 12 5 404 0
3 12 6 244 0
3 12 7 289 0
3 12 8 122 0
3 12 9 22 0
3 12 10 395 0
3 12 11 437 0
3 12 12 501 0
3 12 13 18 32
3 13 2 102 64
3 13 3 19 0
3 13 4 437 0
3 13 5 202 0
3 13 6 472 0
3 13 7 258 0
3 13 8 30 0
3 13 9 37 0
3 13 10 540 0
3 13 11 384 0
3 13 12 371 0
3 13 13 266 32
3 14 2 115 64
3 14 3 17 0
3 14 4 58 0
3 14 5 11 0
3 14 6 595 0
3 14 7 371 0
3 14 8 171 0
3 14 9 206 12
3 14 10 507 12
3 14 11 242 12
3 14 12 117 12
3 14 13 0 126
3 15 2 177 72
3 15 3 16 8
3 15 4 688 126
3 15 5 9 10
3 15 6 438 10
3 15 7 537 8
3 15 8 280 40
4 0 6 520 84
4 0 7 486 20
4 0 8 458 20
4 0 9 298 52
4 1 6 465 68
4 1 7 453 4
4 1 8 437 4
4 1 9 570 36
4 2 6 3 68
4 2 7 366 4
4 2 8 432 4
4 2 9 455 36
4 3 6 417 68
4 3 7 9 4
4 3 8 578 4
4 3 9 567 36
4 4 4 603 84
4 4 5 626 20
4 4 6 267 0
4 4 7 431 0
4 4 8 27 0
4 4 9 11 0
4 4 10 610 16
4 4 11 630 48
4 5 4 605 68
4 5 5 601 4
4 5 6 324 0
4 5 7 251 0
4 5 8 11 0
4 5 9 198 0
4 5 10 637 0
4 5 11 612 32
4 6 4 623 68
4 6 5 622 4
4 6 6 616 4
4 6 7 606 4
4 6 8 633 4
4 6 9 603 4
4 6 10 619 4
4 6 11 618 36
4 7 4 635 68
4 7 5 603 4
4 7 6 605 4
4 7 7 609 4
4 7 8 602 4
4 7 9 609 4
4 7 10 635 4
4 7 11 602 36
4 8 2 26 80
4 8 3 23 16
4 8 4 8 0
4 8 5 21 0
4 8 6 271 0
4 8 7 5 0
4 8 8 423 0
4 8 9 31 0
4 8 10 10 0
4 8 11 192 0
4 8 12 285 16
4 8 13 294 48
4 9 2 123 72
4 9 3 132 0
4 9 4 465 0
4 9 5 29 0
4 9 6 379 0
4 9 7 18 0
4 9 8 390 0
4 9 9 278 0
4 9 10 160 0
4 9 11 31 0
4 9 12 328 0
4 9 13 14 32
4 10 2 391 66
4 10 3 433 64
4 10 4 492 0
4 10 5 331 0
4 10 6 14 0
4 10 7 453 0
4 10 8 509 0
4 10 9 156 0
4 10 10 18 0
4 10 11 25 0
4 10 12 49 0
4 10 13 397 32
4 11 2 327 80
4 11 3 474 0
4 11 4 2 0
4 11 5 152 0
4 11 6 28 0
4 11 7 18 0
4 11 8 340 0
4 11 9 497 0
4 11 10 442 0
4 11 11 288 0
4 11 12 44 0
4 11 13 305 32
4 12 2 103 64
4 12 3 140 0
4 12 4 235 0
4 12 5 370 0
4 12 6 346 0
4 12 7 447 0
4 12 8 11 0
4 12 9 342 0
4 12 10 483 0
4 12 11 487 0
4 12 12 690 0
4 12 13 698 126
4 13 2 182 64
4 13 3 233 0
4 13 4 398 0
4 13 5 432 0
4 13 6 160 0
4 13 7 396 0
4 13 8 222 0
4 13 9 362 0
4 13 10 468 0
4 13 11 154 0
4 13 12 696 0
4 13 13 698 126
4 14 2 88 64
4 14 3 93 0
4 14 4 11 0
4 14 5 453 8
4 14 6 641 8
4 14 7 646 0
4 14 8 419 0
4 14 9 181 0
4 14 10 11 0
4 14 11 187 0
4 14 12 534 0
4 14 13 0 126
4 15 2 423 72
4 15 3 86 8
4 15 4 510 40
4 15 5 15 42
4 15 6 320 126
4 15 7 320 126
4 15 8 579 8
4 15 9 462 12
4 15 10 6 12
4 15 11 342 12
4 15 12 556 12
4 15 13 569 44
5 0 6 460 82
5 0 7 409 18
5 0 8 319 18
5 0 9 319 50
5 1 6 521 66
5 1 7 188 2
5 1 8 374 2
5 1 9 300 34
5 2 6 3 66
5 2 7 189 2
5 2 8 585 2
5 2 9 391 34
5 3 6 8 66
5 3 7 279 2
5 3 8 375 2
5 3 9 212 34
5 4 4 629 80
5 4 5 616 16
5 4 6 358 0
5 4 7 252 0
5 4 8 35 0
5 4 9 179 0
5 4 10 635 16
5 4 11 632 48
5 5 4 621 64
5 5 5 647 0
5 5 6 587 0
5 5 7 371 0
5 5 8 47 0
5 5 9 21 0
5 5 10 669 0
5 5 11 619 32
5 6 4 611 64
5 6 5 651 0
5 6 6 642 0
5 6 7 681 0
5 6 8 643 0
5 6 9 670 0
5 6 10 645 0
5 6 11 619 32
5 7 4 625 64
5 7 5 654 0
5 7 6 667 0
5 7 7 666 0
5 7 8 678 0
5 7 9 647 0
5 7 10 671 0
5 7 11 616 32
5 8 2 26 80
5 8 3 162 16
5 8 4 277 0
5 8 5 102 0
5 8 6 482 0
5 8 7 210 0
5 8 8 247 0
5 8 9 410 0
5 8 10 336 0
5 8 11 377 0
5 8 12 20 16
5 8 13 157 48
5 9 2 324 72
5 9 3 81 0
5 9 4 130 0
5 9 5 198 0
5 9 6 170 0
5 9 7 504 0
5 9 8 306 0
5 9 9 31 0
5 9 10 58 0
5 9 11 353 0
5 9 12 256 0
5 9 13 195 32
5 10 2 349 64
5 10 3 308 64
5 10 4 297 0
5 10 5 168 0
5 10 6 294 0
5 10 7 14 0
5 10 8 159 0
5 10 9 356 0
5 10 10 14 0
5 10 11 397 0
5 10 12 44 0
5 10 13 352 32
5 11 2 345 80
5 11 3 596 0
5 11 4 10 0
5 11 5 4 0
5 11 6 485 0
5 11 7 106 0
5 11 8 386 0
5 11 9 180 0
5 11 10 276 0
5 11 11 25 0
5 11 12 52 0
5 11 13 43 32
5 12 2 121 64
5 12 3 303 0
5 12 4 267 0
5 12 5 202 0
5 12 6 409 0
5 12 7 157 0
5 12 8 6 0
5 12 9 115 0
5 12 10 171 0
5 12 11 169 0
5 12 12 694 0
5 12 13 698 126
5 13 2 16 64
5 13 3 194 0
5 13 4 324 0
5 13 5 526 0
5 13 6 348 0
5 13 7 173 0
5 13 8 13 0
5 13 9 75 0
5 13 10 176 0
5 13 11 152 0
5 13 12 691 0
5 13 13 698 126
5 14 2 542 64
5 14 3 216 0
5 14 4 76 0
5 14 5 277 8
5 14 6 639 8
5 14 7 649 8
5 14 8 540 0
5 14 9 123 0
5 14 10 70 0
5 14 11 14 0
5 14 12 473 32
5 14 13 0 126
5 15 2 85 72
5 15 3 86 8
5 15 4 26 40
5 15 5 193 40
5 15 6 320 126
5 15 7 320 126
5 15 8 118 72
5 15 9 114 8
5 15 10 6 8
5 15 11 314 8
5 15 12 533 8
5 15 13 584 56
6 4 4 634 80
6 4 5 604 16
6 4 6 611 16
6 4 7 610 16
6 4 8 605 16
6 4 9 629 16
6 4 10 601 16
6 4 11 621 48
6 5 4 626 64
6 5 5 644 0
6 5 6 439 0
6 5 7 16 0
6 5 8 338 0
6 5 9 119 0
6 5 10 296 0
6 5 11 603 32
6 6 4 628 64
6 6 5 657 0
6 6 6 413 0
6 6 7 552 0
6 6 8 531 0
6 6 9 258 0
6 6 10 685 0
6 6 11 605 32
6 7 4 611 64
6 7 5 687 0
6 7 6 197 0
6 7 7 373 0
6 7 8 553 0
6 7 9 583 0
6 7 10 676 0
6 7 11 604 32
6 8 2 584 80
6 8 3 245 16
6 8 4 36 0
6 8 5 265 0
6 8 6 331 0
6 8 7 300 0
6 8 8 277 0
6 8 9 21 0
6 8 10 485 0
6 8 11 552 0
6 8 12 12 16
6 8 13 8 48
6 9 2 369 72
6 9 3 520 0
6 9 4 133 0
6 9 5 217 0
6 9 6 517 0
6 9 7 378 0
6 9 8 488 0
6 9 9 94 0
6 9 10 495 0
6 9 11 425 0
6 9 12 344 0
6 9 13 457 32
6 10 2 306 70
6 10 3 488 64
6 10 4 19 0
6 10 5 381 0
6 10 6 176 0
6 10 7 449 0
6 10 8 499 0
6 10 9 529 0
6 10 10 143 0
6 10 11 147 0
6 10 12 272 0
6 10 13 8 32
6 11 2 371 80
6 11 3 263 0
6 11 4 484 0
6 11 5 40 0
6 11 6 310 0
6 11 7 140 0
6 11 8 584 0
6 11 9 597 0
6 11 10 367 0
6 11 11 573 0
6 11 12 152 0
6 11 13 225 32
6 12 2 579 64
6 12 3 561 0
6 12 4 536 0
6 12 5 432 0
6 12 6 418 0
6 12 7 302 0
6 12 8 254 0
6 12 9 284 0
6 12 10 148 0
6 12 11 87 0
6 12 12 14 0
6 12 13 318 32
6 13 2 574 64
6 13 3 357 0
6 13 4 585 0
6 13 5 454 0
6 13 6 413 0
6 13 7 253 0
6 13 8 465 0
6 13 9 272 0
6 13 10 301 0
6 13 11 27 0
6 13 12 387 0
6 13 13 0 126
6 14 2 470 64
6 14 3 120 0
6 14 4 547 0
6 14 5 464 0
6 14 6 366 0
6 14 7 146 8
6 14 8 120 0
6 14 9 161 0
6 14 10 514 0
6 14 11 8 0
6 14 12 172 0
6 14 13 56 36
6 15 2 91 72
6 15 3 108 8
6 15 4 480 8
6 15 5 264 12
6 15 6 65 44
6 15 7 320 126
6 15 8 470 72
6 15 9 258 8
6 15 10 407 8
6 15 11 257 8
6 15 12 18 8
6 15 13 144 40
7 4 4 611 80
7 4 5 608 16
7 4 6 605 16
7 4 7 628 16
7 4 8 614 16
7 4 9 624 16
7 4 10 629 16
7 4 11 611 48
7 5 4 636 64
7 5 5 661 0
7 5 6 12 0
7 5 7 19 0
7 5 8 62 0
7 5 9 440 0
7 5 10 353 0
7 5 11 601 32
7 6 4 618 64
7 6 5 662 0
7 6 6 366 0
7 6 7 389 0
7 6 8 261 0
7 6 9 423 0
7 6 10 660 0
7 6 11 602 32
7 7 4 611 64
7 7 5 673 0
7 7 6 172 0
7 7 7 192 0
7 7 8 517 0
7 7 9 432 0
7 7 10 650 0
7 7 11 605 32
7 8 2 306 80
7 8 3 205 16
7 8 4 180 0
7 8 5 381 0
7 8 6 265 0
7 8 7 265 0
7 8 8 231 0
7 8 9 234 0
7 8 10 398 0
7 8 11 466 0
7 8 12 193 16
7 8 13 225 48
7 9 2 241 72
7 9 3 247 0
7 9 4 322 0
7 9 5 560 0
7 9 6 600 0
7 9 7 490 0
7 9 8 53 0
7 9 9 304 0
7 9 10 435 0
7 9 11 478 0
7 9 12 297 0
7 9 13 529 32
7 10 2 553 64
7 10 3 450 64
7 10 4 21 0
7 10 5 282 0
7 10 6 11 0
7 10 7 14 0
7 10 8 434 0
7 10 9 577 0
7 10 10 385 0
7 10 11 249 0
7 10 12 41 0
7 10 13 55 32
7 11 2 367 80
7 11 3 464 0
7 11 4 126 0
7 11 5 28 0
7 11 6 226 0
7 11 7 316 0
7 11 8 292 0
7 11 9 428 0
7 11 10 305 0
7 11 11 136 0
7 11 12 9 0
7 11 13 83 32
7 12 2 479 64
7 12 3 562 0
7 12 4 541 0
7 12 5 257 0
7 12 6 263 0
7 12 7 335 0
7 12 8 535 0
7 12 9 593 0
7 12 10 209 0
7 12 11 248 0
7 12 12 351 0
7 12 13 83 32
7 13 2 328 64
7 13 3 518 0
7 13 4 406 0
7 13 5 586 0
7 13 6 151 0
7 13 7 470 0
7 13 8 382 0
7 13 9 410 0
7 13 10 149 0
7 13 11 390 0
7 13 12 356 0
7 13 13 25 32
7 14 2 412 64
7 14 3 541 0
7 14 4 575 0
7 14 5 284 0
7 14 6 210 0
7 14 7 366 0
7 14 8 338 0
7 14 9 14 0
7 14 10 14 0
7 14 11 360 0
7 14 12 8 0
7 14 13 515 32
7 15 2 211 72
7 15 3 162 8
7 15 4 572 8
7 15 5 476 8
7 15 6 189 8
7 15 7 362 12
7 15 8 179 8
7 15 9 301 8
7 15 10 246 8
7 15 11 257 8
7 15 12 59 8
7 15 13 314 40
8 4 4 614 80
8 4 5 608 16
8 4 6 608 16
8 4 7 625 16
8 4 8 625 16
8 4 9 611 16
8 4 10 608 16
8 4 11 618 48
8 5 4 619 64
8 5 5 665 0
8 5 6 225 0
8 5 7 581 0
8 5 8 244 0
8 5 9 581 0
8 5 10 659 0
8 5 11 603 32
8 6 4 606 64
8 6 5 83 0
8 6 6 467 0
8 6 7 411 0
8 6 8 129 0
8 6 9 346 0
8 6 10 653 0
8 6 11 610 32
8 7 4 616 64
8 7 5 378 0
8 7 6 87 0
8 7 7 430 0
8 7 8 11 0
8 7 9 18 0
8 7 10 668 0
8 7 11 630 32
8 8 2 262 80
8 8 3 262 16
8 8 4 545 0
8 8 5 295 0
8 8 6 333 0
8 8 7 427 0
8 8 8 575 0
8 8 9 138 0
8 8 10 332 0
8 8 11 543 0
8 8 12 158 16
8 8 13 413 48
8 9 2 154 72
8 9 3 330 0
8 9 4 566 0
8 9 5 525 0
8 9 6 190 0
8 9 7 321 0
8 9 8 178 0
8 9 9 142 0
8 9 10 532 0
8 9 11 351 0
8 9 12 289 0
8 9 13 554 32
8 10 2 334 70
8 10 3 48 64
8 10 4 27 0
8 10 5 431 0
8 10 6 83 0
8 10 7 185 0
8 10 8 8 0
8 10 9 16 0
8 10 10 16 0
8 10 11 11 0
8 10 12 539 0
8 10 13 559 32
8 11 2 76 82
8 11 3 203 0
8 11 4 402 0
8 11 5 485 0
8 11 6 189 0
8 11 7 333 0
8 11 8 7 0
8 11 9 143 0
8 11 10 563 0
8 11 11 82 0
8 11 12 295 0
8 11 13 566 32
8 12 2 158 64
8 12 3 200 0
8 12 4 250 0
8 12 5 89 0
8 12 6 16 0
8 12 7 386 0
8 12 8 165 0
8 12 9 134 0
8 12 10 594 0
8 12 11 401 0
8 12 12 598 0
8 12 13 497 32
8 13 2 519 64
8 13 3 25 0
8 13 4 390 0
8 13 5 161 0
8 13 6 27 0
8 13 7 27 0
8 13 8 489 0
8 13 9 400 0
8 13 10 504 0
8 13 11 456 0
8 13 12 322 0
8 13 13 319 32
8 14 2 338 64
8 14 3 96 0
8 14 4 56 0
8 14 5 11 0
8 14 6 497 0
8 14 7 16 0
8 14 8 453 0
8 14 9 358 0
8 14 10 517 0
8 14 11 284 0
8 14 12 375 0
8 14 13 437 32
8 15 2 215 72
8 15 3 17 8
8 15 4 21 8
8 15 5 5 8
8 15 6 78 8
8 15 7 320 8
8 15 8 213 8
8 15 9 413 8
8 15 10 470 8
8 15 11 409 8
8 15 12 599 8
8 15 13 244 40
9 4 4 612 80
9 4 5 601 16
9 4 6 624 16
9 4 7 614 16
9 4 8 617 16
9 4 9 603 16
9 4 10 615 16
9 4 11 601 48
9 5 4 617 64
9 5 5 658 0
9 5 6 317 0
9 5 7 432 0
9 5 8 561 0
9 5 9 341 0
9 5 10 674 0
9 5 11 604 32
9 6 4 630 64
9 6 5 13 0
9 6 6 13 0
9 6 7 207 0
9 6 8 361 0
9 6 9 361 0
9 6 10 679 0
9 6 11 632 32
9 7 4 636 64
9 7 5 155 0
9 7 6 193 0
9 7 7 420 0
9 7 8 16 0
9 7 9 8 0
9 7 10 672 0
9 7 11 604 32
9 8 2 546 80
9 8 3 257 16
9 8 4 341 0
9 8 5 525 0
9 8 6 72 0
9 8 7 372 0
9 8 8 479 0
9 8 9 380 0
9 8 10 326 0
9 8 11 307 0
9 8 12 153 16
9 8 13 446 48
9 9 2 311 72
9 9 3 9 0
9 9 4 319 0
9 9 5 319 0
9 9 6 369 0
9 9 7 370 0
9 9 8 405 0
9 9 9 549 0
9 9 10 587 0
9 9 11 370 0
9 9 12 318 0
9 9 13 443 32
9 10 3 527 64
9 10 4 286 0
9 10 5 248 0
9 10 6 85 0
9 10 7 280 0
9 10 8 171 0
9 10 9 21 0
9 10 10 12 0
9 10 11 314 0
9 10 12 273 0
9 10 13 452 32
9 11 3 245 64
9 11 4 314 0
9 11 5 14 0
9 11 6 22 0
9 11 7 110 0
9 11 8 5 0
9 11 9 564 0
9 11 10 9 0
9 11 11 101 0
9 11 12 295 0
9 11 13 352 32
9 12 2 121 80
9 12 3 14 0
9 12 4 16 0
9 12 5 27 0
9 12 6 558 0
9 12 7 354 0
9 12 8 566 0
9 12 9 290 0
9 12 10 580 0
9 12 11 522 0
9 12 12 280 0
9 12 13 575 32
9 13 2 214 64
9 13 3 16 0
9 13 4 18 0
9 13 5 226 0
9 13 6 16 0
9 13 7 501 0
9 13 8 134 0
9 13 9 390 0
9 13 10 413 0
9 13 11 208 0
9 13 12 410 0
9 13 13 0 126
9 14 2 392 64
9 14 3 287 0
9 14 4 236 0
9 14 5 13 0
9 14 6 85 0
9 14 7 87 0
9 14 8 500 0
9 14 9 512 0
9 14 10 528 0
9 14 11 503 0
9 14 12 470 0
9 14 13 386 32
9 15 2 28 72
9 15 3 28 8
9 15 4 196 8
9 15 5 494 8
9 15 6 16 8
9 15 7 331 8
9 15 8 315 8
9 15 9 340 8
9 15 10 451 8
9 15 11 299 8
9 15 12 489 8
9 15 13 481 40
10 0 6 230 84
10 0 7 463 20
10 0 8 381 20
10 0 9 77 52
10 1 6 415 68
10 1 7 389 4
10 1 8 32 4
10 1 9 469 36
10 2 6 166 68
10 2 7 54 4
10 2 8 240 4
10 2 9 21 36
10 3 6 19 68
10 3 7 30 4
10 3 8 156 4
10 3 9 318 36
10 4 4 613 80
10 4 5 609 16
10 4 6 245 0
10 4 7 370 0
10 4 8 60 0
10 4 9 62 0
10 4 10 615 16
10 4 11 602 48
10 5 4 606 64
10 5 5 663 0
10 5 6 382 0
10 5 7 224 0
10 5 8 337 0
10 5 9 64 0
10 5 10 664 0
10 5 11 603 32
10 6 4 612 64
10 6 5 683 0
10 6 6 680 0
10 6 7 677 0
10 6 8 653 0
10 6 9 652 0
10 6 10 449 0
10 6 11 635 32
10 7 4 616 64
10 7 5 642 0
10 7 6 676 0
10 7 7 686 0
10 7 8 656 0
10 7 9 675 0
10 7 10 71 0
10 7 11 618 32
10 8 2 139 80
10 8 3 135 16
10 8 4 22 0
10 8 5 573 0
10 8 6 505 0
10 8 7 548 0
10 8 8 571 0
10 8 9 445 0
10 8 10 540 0
10 8 11 340 0
10 8 12 190 16
10 8 13 111 48
10 9 2 479 74
10 9 3 355 0
10 9 4 28 0
10 9 5 34 0
10 9 6 582 0
10 9 7 482 0
10 9 8 349 0
10 9 9 524 0
10 9 10 423 0
10 9 11 375 0
10 9 12 125 0
10 9 13 237 32
10 10 3 515 64
10 10 4 19 0
10 10 5 247 0
10 10 6 387 0
10 10 7 312 0
10 10 8 80 0
10 10 9 380 0
10 10 10 191 0
10 10 11 255 0
10 10 12 18 0
10 10 13 11 32
10 11 3 471 64
10 11 4 17 0
10 11 5 22 0
10 11 6 99 0
10 11 7 199 0
10 11 8 339 0
10 11 9 373 0
10 11 10 274 0
10 11 11 140 0
10 11 12 408 0
10 11 13 83 32
10 12 2 370 80
10 12 3 283 0
10 12 4 380 0
10 12 5 359 0
10 12 6 379 0
10 12 7 421 0
10 12 8 449 0
10 12 9 11 0
10 12 10 243 0
10 12 11 365 0
10 12 12 695 0
10 12 13 698 126
10 13 2 201 64
10 13 3 35 0
10 13 4 14 0
10 13 5 11 0
10 13 6 524 0
10 13 7 281 0
10 13 8 16 0
10 13 9 243 0
10 13 10 363 0
10 13 11 115 0
10 13 12 693 0
10 13 13 698 126
10 14 2 331 64
10 14 3 46 0
10 14 4 87 0
10 14 5 170 0
10 14 6 71 0
10 14 7 10 0
10 14 8 32 0
10 14 9 59 0
10 14 10 164 0
10 14 11 132 0
10 14 12 229 0
10 14 13 0 126
10 15 2 688 126
10 15 3 46 8
10 15 4 364 8
10 15 5 157 8
10 15 6 75 8
10 15 7 39 8
10 15 8 304 8
10 15 9 107 8
10 15 10 412 8
10 15 11 9 8
10 15 12 379 8
10 15 13 561 40
11 0 6 399 82
11 0 7 222 18
11 0 8 520 18
11 0 9 128 50
11 1 6 507 66
11 1 7 508 2
11 1 8 27 2
11 1 9 16 34
11 2 6 27 66
11 2 7 388 2
11 2 8 7 2
11 2 9 394 34
11 3 6 25 66
11 3 7 403 2
11 3 8 212 2
11 3 9 112 34
11 4 4 602 82
11 4 5 628 18
11 4 6 247 0
11 4 7 558 0
11 4 8 267 0
11 4 9 67 0
11 4 10 636 16
11 4 11 636 48
11 5 4 618 66
11 5 5 614 2
11 5 6 468 0
11 5 7 204 0
11 5 8 227 0
11 5 9 513 0
11 5 10 655 2
11 5 11 611 32
11 6 4 601 66
11 6 5 616 2
11 6 6 608 2
11 6 7 618 2
11 6 8 623 2
11 6 9 602 2
11 6 10 618 2
11 6 11 628 34
11 7 4 630 66
11 7 5 606 2
11 7 6 631 2
11 7 7 609 2
11 7 8 634 2
11 7 9 625 2
11 7 10 607 2
11 7 11 605 34
11 8 2 321 88
11 8 3 143 16
11 8 4 405 0
11 8 5 548 0
11 8 6 442 0
11 8 7 350 0
11 8 8 263 0
11 8 9 524 0
11 8 10 195 0
11 8 11 219 0
11 8 12 100 16
11 8 13 446 48
11 9 3 502 64
11 9 4 444 0
11 9 5 48 0
11 9 6 370 0
11 9 7 523 0
11 9 8 526 0
11 9 9 415 0
11 9 10 581 0
11 9 11 592 0
11 9 12 407 0
11 9 13 113 32
11 10 2 441 92
11 10 3 515 66
11 10 4 429 0
11 10 5 193 0
11 10 6 521 0
11 10 7 218 0
11 10 8 575 0
11 10 9 80 0
11 10 10 370 0
11 10 11 14 0
11 10 12 189 0
11 10 13 353 32
11 11 3 589 64
11 11 4 65 0
11 11 5 25 0
11 11 6 102 0
11 11 7 511 0
11 11 8 104 0
11 11 9 72 0
11 11 10 551 0
11 11 11 259 0
11 11 12 222 0
11 11 13 436 32
11 12 2 13 82
11 12 3 34 0
11 12 4 492 0
11 12 5 237 0
11 12 6 453 0
11 12 7 211 0
11 12 8 313 0
11 12 9 74 0
11 12 10 428 0
11 12 11 6 0
11 12 12 692 0
11 12 13 698 126
11 13 2 179 64
11 13 3 323 0
11 13 4 11 0
11 13 5 184 0
11 13 6 186 0
11 13 7 228 0
11 13 8 395 0
11 13 9 368 0
11 13 10 174 0
11 13 11 79 0
11 13 12 697 0
11 13 13 698 126
11 14 2 387 64
11 14 3 228 0
11 14 4 152 0
11 14 5 82 0
11 14 6 8 0
11 14 7 4 0
11 14 8 478 0
11 14 9 18 0
11 14 10 121 0
11 14 11 68 0
11 14 12 568 0
11 14 13 0 126
11 15 2 688 126
11 15 3 219 8
11 15 4 9 8
11 15 5 320 126
11 15 6 69 8
11 15 7 8 8
11 15 8 159 8
11 15 9 61 8
11 15 10 105 8
11 15 11 442 8
11 15 12 526 8
11 15 13 425 40
12 4 6 630 80
12 4 7 635 16
12 4 8 513 16
12 4 9 366 16
12 4 10 81 24
12 4 11 35 16
12 4 12 106 20
12 4 13 25 52
12 5 6 603 72
12 5 7 631 8
12 5 8 242 8
12 5 9 462 42
12 5 10 51 10
12 5 11 22 72
12 5 12 29 12
12 5 13 14 44
12 8 2 113 88
12 8 3 306 16
12 8 4 520 16
12 8 5 506 16
12 8 6 16 16
12 8 7 100 16
12 8 8 236 16
12 8 9 84 16
12 8 10 312 16
12 8 11 498 16
12 8 12 269 16
12 8 13 493 48
12 9 3 268 74
12 9 4 261 0
12 9 5 524 0
12 9 6 129 0
12 9 7 309 0
12 9 8 347 0
12 9 9 17 0
12 9 10 596 0
12 9 11 475 0
12 9 12 192 0
12 9 13 115 32
12 10 2 478 126
12 10 4 172 64
12 10 5 198 0
12 10 6 230 0
12 10 7 137 0
12 10 8 491 0
12 10 9 550 0
12 10 10 257 0
12 10 11 22 0
12 10 12 223 0
12 10 13 176 32
12 11 3 520 82
12 11 4 555 2
12 11 5 147 0
12 11 6 22 0
12 11 7 350 0
12 11 8 230 0
12 11 9 194 0
12 11 10 57 0
12 11 11 13 0
12 11 12 343 0
12 11 13 11 32
12 12 2 223 82
12 12 3 25 66
12 12 4 408 2
12 12 5 45 0
12 12 6 192 0
12 12 7 68 0
12 12 8 448 0
12 12 9 390 0
12 12 10 229 0
12 12 11 92 0
12 12 12 214 0
12 12 13 158 32
12 13 2 25 80
12 13 3 297 0
12 13 4 398 0
12 13 5 330 0
12 13 6 316 0
12 13 7 50 0
12 13 8 280 0
12 13 9 229 2
12 13 10 8 0
12 13 11 494 0
12 13 12 507 0
12 13 13 389 32
12 14 2 226 64
12 14 3 333 0
12 14 4 682 0
12 14 5 689 0
12 14 6 183 0
12 14 7 151 0
12 14 8 244 2
12 14 9 14 2
12 14 10 21 2
12 14 11 18 0
12 14 12 285 0
12 14 13 0 126
12 15 2 688 126
12 15 3 283 8
12 15 4 320 126
12 15 5 320 126
12 15 6 97 8
12 15 7 87 8
12 15 8 239 10
12 15 9 424 10
12 15 10 13 10
12 15 11 8 10
12 15 12 329 10
12 15 13 193 40
13 4 6 610 82
13 4 7 602 18
13 4 8 280 18
13 4 9 591 26
13 4 10 97 26
13 4 11 109 18
13 4 12 212 18
13 4 13 507 50
13 5 6 635 74
13 5 7 602 10
13 5 8 489 42
13 5 11 523 74
13 5 12 25 10
13 5 13 18 42
13 8 2 143 90
13 8 3 383 26
13 8 4 275 18
13 8 5 306 18
13 8 6 124 18
13 8 7 293 18
13 8 8 8 18
13 8 9 131 18
13 8 10 548 18
13 8 11 422 18
13 8 12 395 18
13 8 13 6 50
13 9 4 261 66
13 9 5 515 2
13 9 6 270 2
13 9 7 8 2
13 9 8 184 2
13 9 9 8 2
13 9 10 585 2
13 9 11 518 2
13 9 12 73 2
13 9 13 544 34
13 10 4 220 74
13 10 5 16 2
13 10 6 260 2
13 10 7 98 2
13 10 8 209 2
13 10 9 459 2
13 10 10 11 2
13 10 11 112 2
13 10 12 159 2
13 10 13 24 34
13 11 4 33 66
13 11 5 358 66
13 11 6 102 2
13 11 7 127 2
13 11 8 212 2
13 11 9 229 2
13 11 10 16 2
13 11 11 18 2
13 11 12 171 2
13 11 13 530 34
13 12 4 308 82
13 12 5 175 66
13 12 6 369 2
13 12 7 477 2
13 12 8 469 2
13 12 9 83 10
13 12 10 128 2
13 12 11 11 2
13 12 12 25 2
13 12 13 25 34
13 13 2 12 82
13 13 3 243 18
13 13 4 210 18
13 13 5 376 2
13 13 6 25 2
13 13 7 354 2
13 13 8 513 42
13 13 10 15 74
13 13 11 42 2
13 13 12 9 2
13 13 13 150 34
13 14 2 229 66
13 14 3 22 2
13 14 4 684 2
13 14 5 688 2
13 14 6 95 2
13 14 7 90 34
13 14 11 18 74
13 14 12 92 10
13 14 13 198 34
13 15 2 13 74
13 15 3 144 10
13 15 4 320 126
13 15 5 320 126
13 15 6 178 10
13 15 7 409 42
13 15 13 14 106
