Qubicle Exchange Format
Version 0.2
www.minddesk.com
16 16 16
699
0.000000 0.000000 0.000000
0.000000 0.168627 0.054902
0.000000 0.172549 0.054902
0.000000 0.176471 0.054902
0.000000 0.176471 0.058824
0.000000 0.180392 0.054902
0.000000 0.180392 0.058824
0.000000 0.184314 0.054902
0.000000 0.184314 0.058824
0.000000 0.188235 0.058824
0.000000 0.188235 0.062745
0.000000 0.192157 0.058824
0.000000 0.192157 0.062745
0.000000 0.196078 0.058824
0.000000 0.196078 0.062745
0.000000 0.200000 0.058824
0.000000 0.200000 0.062745
0.000000 0.200000 0.066667
0.000000 0.203922 0.062745
0.000000 0.203922 0.066667
0.000000 0.203922 0.070588
0.000000 0.207843 0.062745
0.000000 0.207843 0.066667
0.000000 0.207843 0.070588
0.000000 0.211765 0.062745
0.000000 0.211765 0.066667
0.000000 0.211765 0.070588
0.000000 0.215686 0.066667
0.000000 0.215686 0.070588
0.000000 0.219608 0.066667
0.000000 0.219608 0.070588
0.000000 0.219608 0.074510
0.000000 0.223529 0.066667
0.000000 0.223529 0.070588
0.000000 0.223529 0.074510
0.000000 0.227451 0.070588
0.000000 0.227451 0.078431
0.000000 0.231373 0.074510
0.003922 0.200000 0.070588
0.003922 0.203922 0.070588
0.003922 0.207843 0.066667
0.003922 0.207843 0.070588
0.003922 0.211765 0.070588
0.003922 0.211765 0.074510
0.003922 0.215686 0.078431
0.003922 0.219608 0.074510
0.003922 0.219608 0.078431
0.003922 0.223529 0.074510
0.003922 0.223529 0.078431
0.003922 0.223529 0.082353
0.003922 0.227451 0.074510
0.003922 0.227451 0.078431
0.003922 0.231373 0.082353
0.003922 0.235294 0.078431
0.003922 0.235294 0.082353
0.007843 0.196078 0.070588
0.007843 0.207843 0.070588
0.007843 0.211765 0.070588
0.007843 0.211765 0.078431
0.007843 0.215686 0.074510
0.007843 0.215686 0.078431
0.007843 0.219608 0.074510
0.007843 0.219608 0.078431
0.007843 0.219608 0.082353
0.007843 0.223529 0.086275
0.007843 0.227451 0.078431
0.007843 0.227451 0.082353
0.007843 0.227451 0.086275
0.007843 0.231373 0.078431
0.011765 0.200000 0.078431
0.011765 0.203922 0.078431
0.011765 0.207843 0.074510
0.011765 0.207843 0.078431
0.011765 0.211765 0.078431
0.011765 0.219608 0.078431
0.011765 0.219608 0.082353
0.011765 0.223529 0.082353
0.011765 0.227451 0.082353
0.011765 0.231373 0.082353
0.011765 0.231373 0.086275
0.011765 0.235294 0.086275
0.011765 0.243137 0.090196
0.015686 0.207843 0.078431
0.015686 0.215686 0.082353
0.015686 0.215686 0.086275
0.015686 0.219608 0.082353
0.015686 0.219608 0.086275
0.015686 0.223529 0.086275
0.015686 0.223529 0.090196
0.015686 0.227451 0.082353
0.015686 0.227451 0.086275
0.015686 0.227451 0.090196
0.015686 0.231373 0.086275
0.015686 0.231373 0.090196
0.015686 0.239216 0.090196
0.015686 0.239216 0.094118
0.015686 0.243137 0.094118
0.015686 0.247059 0.094118
0.019608 0.215686 0.082353
0.019608 0.215686 0.086275
0.019608 0.223529 0.090196
0.019608 0.227451 0.090196
0.019608 0.231373 0.090196
0.019608 0.235294 0.090196
0.019608 0.235294 0.094118
0.019608 0.243137 0.090196
0.019608 0.243137 0.094118
0.019608 0.247059 0.094118
0.019608 0.247059 0.098039
0.019608 0.250980 0.098039
0.023529 0.211765 0.086275
0.023529 0.215686 0.090196
0.023529 0.219608 0.086275
0.023529 0.219608 0.090196
0.023529 0.219608 0.094118
0.023529 0.227451 0.090196
0.023529 0.231373 0.094118
0.023529 0.235294 0.090196
0.023529 0.235294 0.098039
0.023529 0.239216 0.098039
0.023529 0.243137 0.098039
0.023529 0.247059 0.098039
0.023529 0.250980 0.098039
0.023529 0.250980 0.101961
0.027451 0.215686 0.090196
0.027451 0.219608 0.090196
0.027451 0.223529 0.090196
0.027451 0.227451 0.094118
0.027451 0.231373 0.094118
0.027451 0.231373 0.098039
0.027451 0.235294 0.094118
0.027451 0.235294 0.098039
0.027451 0.243137 0.101961
0.027451 0.258824 0.105882
0.031373 0.215686 0.094118
0.031373 0.223529 0.094118
0.031373 0.223529 0.098039
0.031373 0.227451 0.094118
0.031373 0.227451 0.098039
0.031373 0.227451 0.101961
0.031373 0.231373 0.098039
0.031373 0.235294 0.098039
0.031373 0.235294 0.101961
0.031373 0.239216 0.101961
0.031373 0.243137 0.101961
0.031373 0.243137 0.105882
0.031373 0.247059 0.101961
0.031373 0.247059 0.105882
0.031373 0.250980 0.101961
0.031373 0.250980 0.105882
0.031373 0.254902 0.105882
0.031373 0.254902 0.109804
0.035294 0.219608 0.098039
0.035294 0.223529 0.098039
0.035294 0.227451 0.098039
0.035294 0.227451 0.101961
0.035294 0.231373 0.098039
0.035294 0.231373 0.101961
0.035294 0.235294 0.101961
0.035294 0.239216 0.101961
0.035294 0.243137 0.105882
0.035294 0.247059 0.105882
0.035294 0.247059 0.109804
0.035294 0.250980 0.109804
0.035294 0.254902 0.105882
0.035294 0.254902 0.109804
0.035294 0.262745 0.113725
0.039216 0.223529 0.098039
0.039216 0.231373 0.105882
0.039216 0.235294 0.101961
0.039216 0.235294 0.105882
0.039216 0.239216 0.105882
0.039216 0.243137 0.105882
0.039216 0.243137 0.109804
0.039216 0.247059 0.105882
0.039216 0.247059 0.109804
0.039216 0.250980 0.109804
0.039216 0.254902 0.109804
0.039216 0.254902 0.113725
0.039216 0.258824 0.109804
0.039216 0.258824 0.113725
0.039216 0.258824 0.117647
0.039216 0.262745 0.113725
0.039216 0.262745 0.117647
0.043137 0.223529 0.105882
0.043137 0.227451 0.105882
0.043137 0.227451 0.109804
0.043137 0.231373 0.105882
0.043137 0.231373 0.109804
0.043137 0.235294 0.105882
0.043137 0.235294 0.109804
0.043137 0.239216 0.105882
0.043137 0.239216 0.109804
0.043137 0.243137 0.109804
0.043137 0.247059 0.109804
0.043137 0.247059 0.113725
0.043137 0.250980 0.109804
0.043137 0.250980 0.113725
0.043137 0.254902 0.113725
0.043137 0.254902 0.117647
0.043137 0.258824 0.113725
0.043137 0.262745 0.117647
0.043137 0.262745 0.121569
0.043137 0.266667 0.121569
0.047059 0.227451 0.105882
0.047059 0.231373 0.109804
0.047059 0.239216 0.109804
0.047059 0.243137 0.109804
0.047059 0.243137 0.113725
0.047059 0.247059 0.109804
0.047059 0.247059 0.113725
0.047059 0.247059 0.117647
0.047059 0.250980 0.113725
0.047059 0.250980 0.117647
0.047059 0.254902 0.113725
0.047059 0.254902 0.117647
0.047059 0.254902 0.121569
0.047059 0.258824 0.117647
0.047059 0.262745 0.121569
0.047059 0.266667 0.121569
0.047059 0.270588 0.125490
0.050980 0.239216 0.113725
0.050980 0.243137 0.113725
0.050980 0.247059 0.113725
0.050980 0.247059 0.117647
0.050980 0.250980 0.121569
0.050980 0.254902 0.113725
0.050980 0.254902 0.117647
0.050980 0.254902 0.121569
0.050980 0.258824 0.117647
0.050980 0.258824 0.121569
0.050980 0.266667 0.121569
0.050980 0.266667 0.125490
0.050980 0.270588 0.121569
0.050980 0.270588 0.125490
0.050980 0.274510 0.125490
0.054902 0.239216 0.113725
0.054902 0.239216 0.117647
0.054902 0.243137 0.113725
0.054902 0.243137 0.117647
0.054902 0.247059 0.113725
0.054902 0.247059 0.117647
0.054902 0.247059 0.121569
0.054902 0.250980 0.117647
0.054902 0.250980 0.121569
0.054902 0.254902 0.121569
0.054902 0.254902 0.125490
0.054902 0.262745 0.125490
0.054902 0.266667 0.121569
0.054902 0.266667 0.129412
0.054902 0.270588 0.125490
0.054902 0.270588 0.129412
0.054902 0.274510 0.129412
0.054902 0.274510 0.133333
0.058824 0.243137 0.121569
0.058824 0.247059 0.117647
0.058824 0.247059 0.121569
0.058824 0.250980 0.121569
0.058824 0.258824 0.125490
0.058824 0.258824 0.129412
0.058824 0.262745 0.125490
0.058824 0.262745 0.129412
0.058824 0.266667 0.125490
0.058824 0.266667 0.129412
0.058824 0.270588 0.129412
0.058824 0.274510 0.133333
0.058824 0.278431 0.129412
0.058824 0.278431 0.133333
0.058824 0.278431 0.137255
0.062745 0.243137 0.121569
0.062745 0.243137 0.125490
0.062745 0.247059 0.121569
0.062745 0.247059 0.125490
0.062745 0.247059 0.129412
0.062745 0.250980 0.121569
0.062745 0.250980 0.125490
0.062745 0.254902 0.125490
0.062745 0.258824 0.125490
0.062745 0.258824 0.129412
0.062745 0.262745 0.125490
0.062745 0.262745 0.129412
0.062745 0.262745 0.133333
0.062745 0.266667 0.125490
0.062745 0.266667 0.129412
0.062745 0.266667 0.133333
0.062745 0.270588 0.133333
0.062745 0.274510 0.133333
0.062745 0.274510 0.137255
0.062745 0.278431 0.133333
0.062745 0.278431 0.137255
0.062745 0.282353 0.137255
0.062745 0.286275 0.137255
0.066667 0.247059 0.125490
0.066667 0.254902 0.129412
0.066667 0.258824 0.129412
0.066667 0.258824 0.133333
0.066667 0.262745 0.129412
0.066667 0.262745 0.133333
0.066667 0.262745 0.137255
0.066667 0.266667 0.133333
0.066667 0.266667 0.137255
0.066667 0.270588 0.133333
0.066667 0.270588 0.137255
0.066667 0.278431 0.137255
0.066667 0.282353 0.137255
0.066667 0.282353 0.141176
0.066667 0.286275 0.141176
0.070588 0.247059 0.129412
0.070588 0.250980 0.133333
0.070588 0.254902 0.133333
0.070588 0.258824 0.129412
0.070588 0.262745 0.133333
0.070588 0.262745 0.137255
0.070588 0.266667 0.133333
0.070588 0.266667 0.137255
0.070588 0.270588 0.133333
0.070588 0.270588 0.137255
0.070588 0.270588 0.141176
0.070588 0.274510 0.137255
0.070588 0.274510 0.141176
0.070588 0.278431 0.137255
0.070588 0.278431 0.141176
0.070588 0.282353 0.141176
0.070588 0.286275 0.141176
0.070588 0.286275 0.145098
0.070588 0.290196 0.145098
0.074510 0.250980 0.129412
0.074510 0.254902 0.129412
0.074510 0.258824 0.137255
0.074510 0.262745 0.137255
0.074510 0.266667 0.137255
0.074510 0.266667 0.141176
0.074510 0.270588 0.137255
0.074510 0.270588 0.141176
0.074510 0.270588 0.145098
0.074510 0.274510 0.141176
0.074510 0.278431 0.141176
0.074510 0.278431 0.145098
0.074510 0.282353 0.145098
0.074510 0.282353 0.149020
0.074510 0.290196 0.145098
0.074510 0.290196 0.149020
0.078431 0.254902 0.141176
0.078431 0.258824 0.137255
0.078431 0.266667 0.141176
0.078431 0.270588 0.137255
0.078431 0.270588 0.141176
0.078431 0.270588 0.145098
0.078431 0.274510 0.141176
0.078431 0.274510 0.145098
0.078431 0.278431 0.141176
0.078431 0.278431 0.145098
0.078431 0.278431 0.149020
0.078431 0.282353 0.145098
0.078431 0.286275 0.145098
0.078431 0.286275 0.149020
0.078431 0.290196 0.149020
0.078431 0.290196 0.152941
0.078431 0.294118 0.152941
0.082353 0.258824 0.141176
0.082353 0.258824 0.145098
0.082353 0.262745 0.141176
0.082353 0.266667 0.141176
0.082353 0.266667 0.145098
0.082353 0.270588 0.145098
0.082353 0.270588 0.149020
0.082353 0.274510 0.145098
0.082353 0.274510 0.149020
0.082353 0.278431 0.145098
0.082353 0.278431 0.149020
0.082353 0.282353 0.149020
0.082353 0.286275 0.149020
0.082353 0.286275 0.152941
0.082353 0.290196 0.152941
0.082353 0.294118 0.156863
0.082353 0.298039 0.156863
0.086275 0.266667 0.145098
0.086275 0.270588 0.149020
0.086275 0.274510 0.149020
0.086275 0.278431 0.149020
0.086275 0.278431 0.152941
0.086275 0.282353 0.149020
0.086275 0.282353 0.152941
0.086275 0.282353 0.156863
0.086275 0.286275 0.152941
0.086275 0.286275 0.156863
0.086275 0.290196 0.152941
0.086275 0.290196 0.156863
0.086275 0.294118 0.152941
0.086275 0.294118 0.156863
0.086275 0.298039 0.156863
0.086275 0.301961 0.156863
0.086275 0.301961 0.160784
0.090196 0.270588 0.149020
0.090196 0.274510 0.152941
0.090196 0.282353 0.152941
0.090196 0.282353 0.156863
0.090196 0.286275 0.152941
0.090196 0.286275 0.156863
0.090196 0.290196 0.156863
0.090196 0.290196 0.160784
0.090196 0.294118 0.156863
0.090196 0.294118 0.160784
0.090196 0.298039 0.160784
0.090196 0.298039 0.164706
0.090196 0.301961 0.164706
0.094118 0.286275 0.156863
0.094118 0.286275 0.160784
0.094118 0.290196 0.156863
0.094118 0.290196 0.160784
0.094118 0.294118 0.160784
0.094118 0.298039 0.160784
0.094118 0.301961 0.160784
0.094118 0.301961 0.164706
0.094118 0.305882 0.164706
0.098039 0.286275 0.160784
0.098039 0.286275 0.164706
0.098039 0.294118 0.160784
0.098039 0.294118 0.164706
0.098039 0.298039 0.164706
0.098039 0.301961 0.164706
0.098039 0.305882 0.168627
0.098039 0.305882 0.172549
0.098039 0.309804 0.168627
0.101961 0.290196 0.164706
0.101961 0.294118 0.164706
0.101961 0.298039 0.164706
0.101961 0.298039 0.168627
0.101961 0.301961 0.168627
0.101961 0.301961 0.172549
0.101961 0.305882 0.168627
0.101961 0.305882 0.172549
0.101961 0.309804 0.172549
0.101961 0.313726 0.172549
0.101961 0.313726 0.176471
0.105882 0.294118 0.168627
0.105882 0.298039 0.168627
0.105882 0.298039 0.172549
0.105882 0.301961 0.168627
0.105882 0.301961 0.172549
0.105882 0.305882 0.172549
0.105882 0.305882 0.176471
0.105882 0.309804 0.172549
0.105882 0.309804 0.176471
0.105882 0.313726 0.172549
0.105882 0.313726 0.176471
0.109804 0.294118 0.172549
0.109804 0.294118 0.176471
0.109804 0.298039 0.172549
0.109804 0.301961 0.172549
0.109804 0.301961 0.176471
0.109804 0.305882 0.176471
0.109804 0.309804 0.180392
0.109804 0.313726 0.176471
0.109804 0.313726 0.180392
0.109804 0.317647 0.176471
0.109804 0.317647 0.180392
0.113725 0.298039 0.176471
0.113725 0.298039 0.180392
0.113725 0.301961 0.172549
0.113725 0.301961 0.176471
0.113725 0.305882 0.176471
0.113725 0.305882 0.180392
0.113725 0.309804 0.176471
0.113725 0.309804 0.180392
0.113725 0.313726 0.180392
0.113725 0.313726 0.184314
0.113725 0.317647 0.180392
0.113725 0.317647 0.184314
0.113725 0.321569 0.180392
0.113725 0.321569 0.184314
0.117647 0.298039 0.180392
0.117647 0.301961 0.180392
0.117647 0.305882 0.184314
0.117647 0.309804 0.180392
0.117647 0.309804 0.184314
0.117647 0.313726 0.184314
0.117647 0.317647 0.184314
0.117647 0.321569 0.184314
0.117647 0.321569 0.188235
0.117647 0.325490 0.188235
0.121569 0.305882 0.184314
0.121569 0.309804 0.184314
0.121569 0.313726 0.184314
0.121569 0.313726 0.188235
0.121569 0.317647 0.188235
0.121569 0.321569 0.188235
0.121569 0.321569 0.192157
0.121569 0.325490 0.188235
0.121569 0.325490 0.192157
0.121569 0.329412 0.192157
0.125490 0.305882 0.188235
0.125490 0.309804 0.188235
0.125490 0.313726 0.188235
0.125490 0.317647 0.188235
0.125490 0.317647 0.192157
0.125490 0.321569 0.188235
0.125490 0.321569 0.192157
0.125490 0.325490 0.192157
0.125490 0.325490 0.196078
0.125490 0.329412 0.192157
0.125490 0.329412 0.196078
0.125490 0.333333 0.200000
0.129412 0.309804 0.192157
0.129412 0.317647 0.192157
0.129412 0.317647 0.196078
0.129412 0.321569 0.196078
0.129412 0.325490 0.196078
0.129412 0.325490 0.200000
0.129412 0.329412 0.192157
0.129412 0.329412 0.196078
0.129412 0.329412 0.200000
0.129412 0.333333 0.196078
0.129412 0.333333 0.200000
0.133333 0.313726 0.196078
0.133333 0.317647 0.196078
0.133333 0.321569 0.196078
0.133333 0.321569 0.200000
0.133333 0.325490 0.203922
0.133333 0.329412 0.200000
0.133333 0.333333 0.200000
0.133333 0.333333 0.203922
0.133333 0.337255 0.200000
0.133333 0.337255 0.203922
0.137255 0.325490 0.200000
0.137255 0.325490 0.203922
0.137255 0.337255 0.203922
0.137255 0.337255 0.207843
0.137255 0.341176 0.203922
0.141176 0.321569 0.200000
0.141176 0.325490 0.203922
0.141176 0.329412 0.203922
0.141176 0.333333 0.203922
0.141176 0.333333 0.207843
0.141176 0.341176 0.207843
0.141176 0.345098 0.207843
0.145098 0.325490 0.203922
0.145098 0.329412 0.203922
0.145098 0.329412 0.207843
0.145098 0.333333 0.207843
0.145098 0.341176 0.211765
0.145098 0.345098 0.211765
0.145098 0.345098 0.215686
0.149020 0.329412 0.203922
0.149020 0.329412 0.211765
0.149020 0.333333 0.211765
0.149020 0.337255 0.207843
0.149020 0.345098 0.211765
0.149020 0.345098 0.215686
0.149020 0.345098 0.219608
0.149020 0.349020 0.215686
0.152941 0.333333 0.211765
0.152941 0.349020 0.215686
0.152941 0.349020 0.219608
0.152941 0.349020 0.223529
0.152941 0.352941 0.215686
0.152941 0.352941 0.219608
0.156863 0.345098 0.219608
0.156863 0.349020 0.219608
0.156863 0.349020 0.223529
0.156863 0.352941 0.219608
0.156863 0.352941 0.223529
0.160784 0.337255 0.219608
0.160784 0.337255 0.223529
0.160784 0.341176 0.223529
0.160784 0.345098 0.223529
0.160784 0.352941 0.227451
0.160784 0.356863 0.223529
0.160784 0.356863 0.227451
0.160784 0.356863 0.231373
0.164706 0.356863 0.227451
0.164706 0.356863 0.231373
0.164706 0.360784 0.231373
0.164706 0.360784 0.235294
0.168627 0.356863 0.231373
0.168627 0.360784 0.235294
0.168627 0.364706 0.235294
0.168627 0.364706 0.239216
0.172549 0.364706 0.235294
0.172549 0.364706 0.239216
0.172549 0.368627 0.239216
0.176471 0.368627 0.239216
0.176471 0.368627 0.243137
0.184314 0.372549 0.247059
0.184314 0.372549 0.250980
0.184314 0.376471 0.247059
0.184314 0.376471 0.250980
0.188235 0.376471 0.250980
0.188235 0.376471 0.254902
0.192157 0.380392 0.254902
0.192157 0.384314 0.254902
0.196078 0.380392 0.258824
0.196078 0.384314 0.258824
0.203922 0.388235 0.262745
0.203922 0.388235 0.266667
0.207843 0.392157 0.266667
0.207843 0.392157 0.270588
0.211765 0.392157 0.274510
0.211765 0.396078 0.274510
0.215686 0.396078 0.274510
0.215686 0.396078 0.278431
0.305882 0.215686 0.015686
0.309804 0.215686 0.015686
0.313726 0.219608 0.015686
0.317647 0.219608 0.015686
0.317647 0.223529 0.015686
0.321569 0.223529 0.015686
0.321569 0.227451 0.015686
0.325490 0.227451 0.015686
0.329412 0.231373 0.015686
0.333333 0.231373 0.015686
0.333333 0.235294 0.015686
0.337255 0.235294 0.015686
0.341176 0.239216 0.019608
0.341176 0.243137 0.023529
0.345098 0.247059 0.027451
0.349020 0.247059 0.031373
0.349020 0.250980 0.035294
0.352941 0.254902 0.039216
0.356863 0.258824 0.043137
0.356863 0.258824 0.047059
0.360784 0.262745 0.050980
0.364706 0.266667 0.054902
0.368627 0.270588 0.062745
0.372549 0.274510 0.066667
0.372549 0.278431 0.070588
0.376471 0.282353 0.074510
0.380392 0.019608 0.000000
0.380392 0.282353 0.078431
0.380392 0.286275 0.082353
0.384314 0.290196 0.086275
0.388235 0.294118 0.090196
0.388235 0.294118 0.094118
0.392157 0.298039 0.098039
0.396078 0.301961 0.101961
0.396078 0.305882 0.105882
0.400000 0.305882 0.109804
0.407843 0.023529 0.000000
0.411765 0.019608 0.000000
0.415686 0.027451 0.000000
0.423529 0.019608 0.000000
0.427451 0.019608 0.000000
0.427451 0.023529 0.000000
0.431373 0.023529 0.000000
0.435294 0.031373 0.000000
0.439216 0.023529 0.000000
0.439216 0.078431 0.054902
0.443137 0.023529 0.000000
0.443137 0.058824 0.035294
0.447059 0.019608 0.000000
0.447059 0.023529 0.000000
0.450980 0.023529 0.000000
0.450980 0.043137 0.015686
0.454902 0.023529 0.000000
0.454902 0.058824 0.031373
0.458824 0.023529 0.000000
0.458824 0.035294 0.003922
0.458824 0.070588 0.043137
0.462745 0.043137 0.015686
0.466667 0.023529 0.000000
0.466667 0.082353 0.054902
0.474510 0.082353 0.050980
0.482353 0.043137 0.015686
0.482353 0.058824 0.031373
0.482353 0.098039 0.066667
0.482353 0.109804 0.082353
0.486275 0.066667 0.039216
0.486275 0.094118 0.062745
0.490196 0.043137 0.011765
0.490196 0.047059 0.015686
0.494118 0.070588 0.039216
0.498039 0.058824 0.027451
0.498039 0.109804 0.082353
0.501961 0.062745 0.031373
0.501961 0.078431 0.047059
0.501961 0.113725 0.086275
0.505882 0.074510 0.043137
0.509804 0.082353 0.050980
0.509804 0.101961 0.074510
0.513726 0.090196 0.058824
0.513726 0.094118 0.062745
0.525490 0.117647 0.086275
0.525490 0.133333 0.101961
0.529412 0.125490 0.094118
0.529412 0.145098 0.113725
0.533333 0.121569 0.094118
0.537255 0.133333 0.105882
0.537255 0.137255 0.109804
0.549020 0.160784 0.137255
0.576471 0.211765 0.188235
0.611765 0.050980 0.105882
0.623529 0.050980 0.105882
0.643137 0.050980 0.105882
0.654902 0.011765 0.074510
0.658824 0.105882 0.156863
0.674510 0.090196 0.149020
0.674510 0.094118 0.149020
0.678431 0.082353 0.141176
0.996078 0.000000 0.000000
0 4 3 442 124
1 4 2 481 92
1 4 3 172 48
1 5 3 158 108
2 4 2 22 80
2 4 3 485 48
2 4 12 25 84
2 4 13 507 52
2 5 2 25 76
2 5 3 9 40
2 5 12 14 76
2 5 13 18 44
2 8 2 182 84
2 8 3 335 20
2 8 4 294 20
2 8 5 157 20
2 8 6 8 20
2 8 7 225 20
2 8 8 413 20
2 8 9 446 20
2 8 10 111 20
2 8 11 446 20
2 8 12 493 20
2 8 13 6 52
2 9 2 358 68
2 9 3 318 4
2 9 4 14 4
2 9 5 195 4
2 9 6 457 4
2 9 7 529 4
2 9 8 554 4
2 9 9 443 4
2 9 10 237 4
2 9 11 113 4
2 9 12 115 4
2 9 13 544 36
2 10 2 14 68
2 10 3 85 4
2 10 4 397 4
2 10 5 352 4
2 10 6 8 4
2 10 7 55 4
2 10 8 559 4
2 10 9 452 4
2 10 10 11 4
2 10 11 353 4
2 10 12 176 4
2 10 13 24 36
2 11 2 161 68
2 11 3 347 4
2 11 4 305 4
2 11 5 43 4
2 11 6 225 4
2 11 7 83 4
2 11 8 566 4
2 11 9 352 4
2 11 10 83 4
2 11 11 436 4
2 11 12 11 4
2 11 13 530 36
2 12 2 11 68
2 12 3 18 4
2 12 4 698 4
2 12 5 698 4
2 12 6 318 4
2 12 7 83 4
2 12 8 497 4
2 12 9 575 4
2 12 10 698 4
2 12 11 698 4
2 12 12 158 4
2 12 13 25 36
2 13 2 27 76
2 13 3 266 4
2 13 4 698 4
2 13 5 698 4
2 13 6 0 4
2 13 7 25 4
2 13 8 319 4
2 13 9 0 4
2 13 10 698 4
2 13 11 698 4
2 13 12 389 4
2 13 13 150 36
2 14 3 0 76
2 14 4 0 4
2 14 5 0 4
2 14 6 56 4
2 14 7 515 4
2 14 8 437 4
2 14 9 386 4
2 14 10 0 4
2 14 11 0 4
2 14 12 0 4
2 14 13 198 36
2 15 4 569 76
2 15 5 584 12
2 15 6 144 12
2 15 7 314 12
2 15 8 244 12
2 15 9 481 12
2 15 10 561 12
2 15 11 425 12
2 15 12 193 12
2 15 13 14 46
3 4 2 119 80
3 4 3 557 48
3 4 12 106 80
3 4 13 212 48
3 5 2 349 72
3 5 3 12 40
3 5 12 29 72
3 5 13 25 40
3 8 2 406 80
3 8 3 167 16
3 8 4 285 16
3 8 5 20 16
3 8 6 12 16
3 8 7 193 16
3 8 8 158 16
3 8 9 153 16
3 8 10 190 16
3 8 11 100 16
3 8 12 269 16
3 8 13 395 48
3 9 2 428 64
3 9 3 267 0
3 9 4 328 0
3 9 5 256 0
3 9 6 344 0
3 9 7 297 0
3 9 8 289 0
3 9 9 318 0
3 9 10 125 0
3 9 11 407 0
3 9 12 192 0
3 9 13 73 32
3 10 2 494 64
3 10 3 238 0
3 10 4 49 0
3 10 5 44 0
3 10 6 272 0
3 10 7 41 0
3 10 8 539 0
3 10 9 273 0
3 10 10 18 0
3 10 11 189 0
3 10 12 223 0
3 10 13 159 32
3 11 2 239 64
3 11 3 335 0
3 11 4 44 0
3 11 5 52 0
3 11 6 152 0
3 11 7 9 0
3 11 8 295 0
3 11 9 295 0
3 11 10 408 0
3 11 11 222 0
3 11 12 343 0
3 11 13 171 32
3 12 2 22 64
3 12 3 501 0
3 12 4 690 0
3 12 5 694 0
3 12 6 14 0
3 12 7 351 0
3 12 8 598 0
3 12 9 280 0
3 12 10 695 0
3 12 11 692 0
3 12 12 214 0
3 12 13 25 32
3 13 2 22 72
3 13 3 371 0
3 13 4 696 0
3 13 5 691 0
3 13 6 387 0
3 13 7 356 0
3 13 8 322 0
3 13 9 410 0
3 13 10 693 0
3 13 11 697 0
3 13 12 507 0
3 13 13 9 32
3 14 3 117 72
3 14 4 534 0
3 14 5 473 0
3 14 6 172 0
3 14 7 8 0
3 14 8 375 0
3 14 9 470 0
3 14 10 229 0
3 14 11 568 0
3 14 12 285 0
3 14 13 92 40
3 15 4 556 72
3 15 5 533 8
3 15 6 18 8
3 15 7 59 8
3 15 8 599 8
3 15 9 489 8
3 15 10 379 8
3 15 11 526 8
3 15 12 329 40
4 0 4 298 84
4 0 5 319 52
4 1 4 570 76
4 1 5 300 44
4 4 2 610 80
4 4 3 620 16
4 4 4 630 20
4 4 5 632 20
4 4 6 621 20
4 4 7 611 20
4 4 8 618 20
4 4 9 601 20
4 4 10 602 20
4 4 11 636 20
4 4 12 35 16
4 4 13 109 48
4 5 2 608 72
4 5 3 609 8
4 5 4 612 4
4 5 5 619 4
4 5 6 603 4
4 5 7 601 4
4 5 8 603 4
4 5 9 604 4
4 5 10 603 4
4 5 11 611 4
4 5 12 22 8
4 5 13 523 42
4 6 4 618 68
4 6 5 619 4
4 6 6 605 4
4 6 7 602 4
4 6 8 610 4
4 6 9 632 4
4 6 10 635 4
4 6 11 628 36
4 7 4 602 68
4 7 5 616 4
4 7 6 604 4
4 7 7 605 4
4 7 8 630 4
4 7 9 604 4
4 7 10 618 4
4 7 11 605 36
4 8 2 6 80
4 8 3 247 16
4 8 4 192 0
4 8 5 377 0
4 8 6 552 0
4 8 7 466 0
4 8 8 543 0
4 8 9 307 0
4 8 10 340 0
4 8 11 219 0
4 8 12 498 16
4 8 13 422 48
4 9 2 210 64
4 9 3 565 0
4 9 4 31 0
4 9 5 353 0
4 9 6 425 0
4 9 7 478 0
4 9 8 351 0
4 9 9 370 0
4 9 10 375 0
4 9 11 592 0
4 9 12 475 0
4 9 13 518 32
4 10 2 145 64
4 10 3 61 0
4 10 4 25 0
4 10 5 397 0
4 10 6 147 0
4 10 7 249 0
4 10 8 11 0
4 10 9 314 0
4 10 10 255 0
4 10 11 14 0
4 10 12 22 0
4 10 13 112 32
4 11 2 50 64
4 11 3 12 0
4 11 4 288 0
4 11 5 25 0
4 11 6 573 0
4 11 7 136 0
4 11 8 82 0
4 11 9 101 0
4 11 10 140 0
4 11 11 259 0
4 11 12 13 0
4 11 13 18 32
4 12 2 221 64
4 12 3 437 0
4 12 4 487 0
4 12 5 169 0
4 12 6 87 0
4 12 7 248 0
4 12 8 401 0
4 12 9 522 0
4 12 10 365 0
4 12 11 6 0
4 12 12 92 0
4 12 13 11 32
4 13 2 289 72
4 13 3 384 0
4 13 4 154 0
4 13 5 152 0
4 13 6 27 0
4 13 7 390 0
4 13 8 456 0
4 13 9 208 0
4 13 10 115 0
4 13 11 79 0
4 13 12 494 0
4 13 13 42 32
4 14 3 242 72
4 14 4 187 0
4 14 5 14 0
4 14 6 8 0
4 14 7 360 0
4 14 8 284 0
4 14 9 503 0
4 14 10 132 0
4 14 11 68 0
4 14 12 18 0
4 14 13 18 42
4 15 4 342 72
4 15 5 314 8
4 15 6 257 8
4 15 7 257 8
4 15 8 409 8
4 15 9 299 8
4 15 10 9 8
4 15 11 442 8
4 15 12 8 40
5 0 4 458 80
5 0 5 319 48
5 1 4 437 72
5 1 5 374 40
5 4 2 631 80
5 4 3 603 16
5 4 4 610 16
5 4 5 635 16
5 4 6 601 16
5 4 7 629 16
5 4 8 608 16
5 4 9 615 16
5 4 10 615 16
5 4 11 636 16
5 4 12 81 16
5 4 13 97 56
5 5 2 635 72
5 5 3 608 8
5 5 4 637 0
5 5 5 669 0
5 5 6 296 0
5 5 7 353 0
5 5 8 659 0
5 5 9 674 0
5 5 10 664 0
5 5 11 655 0
5 5 12 51 40
5 6 4 619 64
5 6 5 645 0
5 6 6 685 0
5 6 7 660 0
5 6 8 653 0
5 6 9 679 0
5 6 10 449 0
5 6 11 618 32
5 7 4 635 64
5 7 5 671 0
5 7 6 676 0
5 7 7 650 0
5 7 8 668 0
5 7 9 672 0
5 7 10 71 0
5 7 11 607 32
5 8 2 295 80
5 8 3 333 16
5 8 4 10 0
5 8 5 336 0
5 8 6 485 0
5 8 7 398 0
5 8 8 332 0
5 8 9 326 0
5 8 10 540 0
5 8 11 195 0
5 8 12 312 16
5 8 13 548 48
5 9 2 163 64
5 9 3 6 0
5 9 4 160 0
5 9 5 58 0
5 9 6 495 0
5 9 7 435 0
5 9 8 532 0
5 9 9 587 0
5 9 10 423 0
5 9 11 581 0
5 9 12 596 0
5 9 13 585 32
5 10 2 141 64
5 10 3 232 0
5 10 4 18 0
5 10 5 14 0
5 10 6 143 0
5 10 7 385 0
5 10 8 16 0
5 10 9 12 0
5 10 10 191 0
5 10 11 370 0
5 10 12 257 0
5 10 13 11 32
5 11 2 336 64
5 11 3 16 0
5 11 4 442 0
5 11 5 276 0
5 11 6 367 0
5 11 7 305 0
5 11 8 563 0
5 11 9 9 0
5 11 10 274 0
5 11 11 551 0
5 11 12 57 0
5 11 13 16 32
5 12 2 251 64
5 12 3 395 0
5 12 4 483 0
5 12 5 171 0
5 12 6 148 0
5 12 7 209 0
5 12 8 594 0
5 12 9 580 0
5 12 10 243 0
5 12 11 428 0
5 12 12 229 0
5 12 13 128 32
5 13 2 472 72
5 13 3 540 0
5 13 4 468 0
5 13 5 176 0
5 13 6 301 0
5 13 7 149 0
5 13 8 504 0
5 13 9 413 0
5 13 10 363 0
5 13 11 174 0
5 13 12 8 0
5 13 13 15 42
5 14 3 507 72
5 14 4 11 0
5 14 5 70 0
5 14 6 514 0
5 14 7 14 0
5 14 8 517 0
5 14 9 528 0
5 14 10 164 0
5 14 11 121 0
5 14 12 21 32
5 15 4 6 72
5 15 5 6 8
5 15 6 407 8
5 15 7 246 8
5 15 8 470 8
5 15 9 451 8
5 15 10 412 8
5 15 11 105 8
5 15 12 13 40
6 0 4 486 80
6 0 5 409 48
6 0 10 77 84
6 0 11 128 52
6 1 4 453 64
6 1 5 188 32
6 1 10 469 68
6 1 11 16 36
6 2 4 455 68
6 2 5 391 36
6 2 10 21 68
6 2 11 394 36
6 3 4 567 68
6 3 5 212 36
6 3 10 318 68
6 3 11 112 36
6 4 2 609 80
6 4 3 612 16
6 4 4 11 0
6 4 5 179 0
6 4 6 629 16
6 4 7 624 16
6 4 8 611 16
6 4 9 603 16
6 4 10 62 0
6 4 11 67 0
6 4 12 366 16
6 4 13 591 56
6 5 2 602 72
6 5 3 629 8
6 5 4 198 0
6 5 5 21 0
6 5 6 119 0
6 5 7 440 0
6 5 8 581 0
6 5 9 341 0
6 5 10 64 0
6 5 11 513 0
6 5 12 462 40
6 6 4 603 64
6 6 5 670 0
6 6 6 258 0
6 6 7 423 0
6 6 8 346 0
6 6 9 361 0
6 6 10 652 0
6 6 11 602 32
6 7 4 609 64
6 7 5 647 0
6 7 6 583 0
6 7 7 432 0
6 7 8 18 0
6 7 9 8 0
6 7 10 675 0
6 7 11 625 32
6 8 2 65 80
6 8 3 66 16
6 8 4 31 0
6 8 5 410 0
6 8 6 21 0
6 8 7 234 0
6 8 8 138 0
6 8 9 380 0
6 8 10 445 0
6 8 11 524 0
6 8 12 84 16
6 8 13 131 48
6 9 2 145 64
6 9 3 22 0
6 9 4 278 0
6 9 5 31 0
6 9 6 94 0
6 9 7 304 0
6 9 8 142 0
6 9 9 549 0
6 9 10 524 0
6 9 11 415 0
6 9 12 17 0
6 9 13 8 32
6 10 2 576 64
6 10 3 534 0
6 10 4 156 0
6 10 5 356 0
6 10 6 529 0
6 10 7 577 0
6 10 8 16 0
6 10 9 21 0
6 10 10 380 0
6 10 11 80 0
6 10 12 550 0
6 10 13 459 32
6 11 2 375 64
6 11 3 60 0
6 11 4 497 0
6 11 5 180 0
6 11 6 597 0
6 11 7 428 0
6 11 8 143 0
6 11 9 564 0
6 11 10 373 0
6 11 11 72 0
6 11 12 194 0
6 11 13 229 32
6 12 2 27 64
6 12 3 22 0
6 12 4 342 0
6 12 5 115 0
6 12 6 284 0
6 12 7 593 0
6 12 8 134 0
6 12 9 290 0
6 12 10 11 0
6 12 11 74 0
6 12 12 390 0
6 12 13 83 40
6 13 2 356 72
6 13 3 37 0
6 13 4 362 0
6 13 5 75 0
6 13 6 272 0
6 13 7 410 0
6 13 8 400 0
6 13 9 390 0
6 13 10 243 0
6 13 11 368 0
6 13 12 229 32
6 14 3 206 72
6 14 4 181 0
6 14 5 123 0
6 14 6 161 0
6 14 7 14 0
6 14 8 358 0
6 14 9 512 0
6 14 10 59 0
6 14 11 18 0
6 14 12 14 32
6 15 4 462 72
6 15 5 114 8
6 15 6 258 8
6 15 7 301 8
6 15 8 413 8
6 15 9 340 8
6 15 10 107 8
6 15 11 61 8
6 15 12 424 40
7 0 4 520 82
7 0 5 460 50
7 0 10 381 80
7 0 11 520 48
7 1 4 465 64
7 1 5 521 32
7 1 10 32 64
7 1 11 27 32
7 2 4 432 64
7 2 5 585 32
7 2 10 240 64
7 2 11 7 32
7 3 4 578 64
7 3 5 375 32
7 3 10 156 64
7 3 11 212 32
7 4 2 603 82
7 4 3 634 18
7 4 4 27 0
7 4 5 35 0
7 4 6 605 16
7 4 7 614 16
7 4 8 625 16
7 4 9 617 16
7 4 10 60 0
7 4 11 267 0
7 4 12 513 16
7 4 13 280 48
7 5 2 617 74
7 5 3 609 10
7 5 4 11 0
7 5 5 47 0
7 5 6 338 0
7 5 7 62 0
7 5 8 244 0
7 5 9 561 0
7 5 10 337 0
7 5 11 227 0
7 5 12 242 8
7 5 13 489 44
7 6 4 633 64
7 6 5 643 0
7 6 6 531 0
7 6 7 261 0
7 6 8 129 0
7 6 9 361 0
7 6 10 653 0
7 6 11 623 32
7 7 4 602 64
7 7 5 678 0
7 7 6 553 0
7 7 7 517 0
7 7 8 11 0
7 7 9 16 0
7 7 10 656 0
7 7 11 634 32
7 8 2 51 80
7 8 3 161 16
7 8 4 423 0
7 8 5 247 0
7 8 6 277 0
7 8 7 231 0
7 8 8 575 0
7 8 9 479 0
7 8 10 571 0
7 8 11 263 0
7 8 12 236 16
7 8 13 8 48
7 9 2 476 64
7 9 3 22 0
7 9 4 390 0
7 9 5 306 0
7 9 6 488 0
7 9 7 53 0
7 9 8 178 0
7 9 9 405 0
7 9 10 349 0
7 9 11 526 0
7 9 12 347 0
7 9 13 184 32
7 10 2 38 64
7 10 3 39 0
7 10 4 509 0
7 10 5 159 0
7 10 6 499 0
7 10 7 434 0
7 10 8 8 0
7 10 9 171 0
7 10 10 80 0
7 10 11 575 0
7 10 12 491 0
7 10 13 209 32
7 11 2 374 64
7 11 3 414 0
7 11 4 340 0
7 11 5 386 0
7 11 6 584 0
7 11 7 292 0
7 11 8 7 0
7 11 9 5 0
7 11 10 339 0
7 11 11 104 0
7 11 12 230 0
7 11 13 212 32
7 12 2 568 64
7 12 3 122 0
7 12 4 11 0
7 12 5 6 0
7 12 6 254 0
7 12 7 535 0
7 12 8 165 0
7 12 9 566 0
7 12 10 449 0
7 12 11 313 0
7 12 12 448 0
7 12 13 469 32
7 13 2 282 64
7 13 3 30 0
7 13 4 222 0
7 13 5 13 0
7 13 6 465 0
7 13 7 382 0
7 13 8 489 0
7 13 9 134 0
7 13 10 16 0
7 13 11 395 0
7 13 12 280 0
7 13 13 513 44
7 14 2 393 68
7 14 3 171 0
7 14 4 419 0
7 14 5 540 0
7 14 6 120 0
7 14 7 338 0
7 14 8 453 0
7 14 9 500 0
7 14 10 32 0
7 14 11 478 0
7 14 12 244 32
7 15 2 193 76
7 15 3 280 12
7 15 4 579 8
7 15 5 118 8
7 15 6 470 8
7 15 7 179 8
7 15 8 213 8
7 15 9 315 8
7 15 10 304 8
7 15 11 159 8
7 15 12 239 40
8 0 10 463 80
8 0 11 222 48
8 1 4 455 82
8 1 5 455 50
8 1 10 389 64
8 1 11 508 32
8 2 4 366 64
8 2 5 189 32
8 2 10 54 64
8 2 11 388 32
8 3 4 9 64
8 3 5 279 32
8 3 10 30 64
8 3 11 403 32
8 4 4 623 126
8 4 5 252 0
8 4 6 610 16
8 4 7 628 16
8 4 8 625 16
8 4 9 614 16
8 4 10 370 0
8 4 11 558 0
8 4 12 635 16
8 4 13 602 48
8 5 4 623 126
8 5 5 371 0
8 5 6 16 0
8 5 7 19 0
8 5 8 581 0
8 5 9 432 0
8 5 10 224 0
8 5 11 204 0
8 5 12 631 8
8 5 13 602 40
8 6 4 606 64
8 6 5 681 0
8 6 6 552 0
8 6 7 389 0
8 6 8 411 0
8 6 9 207 0
8 6 10 677 0
8 6 11 618 32
8 7 4 609 64
8 7 5 666 0
8 7 6 373 0
8 7 7 192 0
8 7 8 430 0
8 7 9 420 0
8 7 10 686 0
8 7 11 609 32
8 8 2 688 80
8 8 3 283 16
8 8 4 5 0
8 8 5 210 0
8 8 6 300 0
8 8 7 265 0
8 8 8 427 0
8 8 9 372 0
8 8 10 548 0
8 8 11 350 0
8 8 12 100 16
8 8 13 293 48
8 9 2 14 64
8 9 3 210 0
8 9 4 18 0
8 9 5 504 0
8 9 6 378 0
8 9 7 490 0
8 9 8 321 0
8 9 9 370 0
8 9 10 482 0
8 9 11 523 0
8 9 12 309 0
8 9 13 8 32
8 10 2 116 64
8 10 3 366 0
8 10 4 453 0
8 10 5 14 0
8 10 6 449 0
8 10 7 14 0
8 10 8 185 0
8 10 9 280 0
8 10 10 312 0
8 10 11 218 0
8 10 12 137 0
8 10 13 98 32
8 11 2 1 64
8 11 3 4 0
8 11 4 18 0
8 11 5 106 0
8 11 6 140 0
8 11 7 316 0
8 11 8 333 0
8 11 9 110 0
8 11 10 199 0
8 11 11 511 0
8 11 12 350 0
8 11 13 127 32
8 12 2 476 64
8 12 3 289 0
8 12 4 447 0
8 12 5 157 0
8 12 6 302 0
8 12 7 335 0
8 12 8 386 0
8 12 9 354 0
8 12 10 421 0
8 12 11 211 0
8 12 12 68 0
8 12 13 477 32
8 13 2 588 64
8 13 3 258 0
8 13 4 396 0
8 13 5 173 0
8 13 6 253 0
8 13 7 470 0
8 13 8 27 0
8 13 9 501 0
8 13 10 281 0
8 13 11 228 0
8 13 12 50 0
8 13 13 354 32
8 14 2 329 64
8 14 3 371 0
8 14 4 646 0
8 14 5 649 0
8 14 6 146 0
8 14 7 366 0
8 14 8 16 0
8 14 9 87 0
8 14 10 10 0
8 14 11 4 0
8 14 12 151 0
8 14 13 90 36
8 15 2 426 72
8 15 3 537 8
8 15 4 320 8
8 15 5 320 8
8 15 6 320 8
8 15 7 362 8
8 15 8 320 8
8 15 9 331 8
8 15 10 39 8
8 15 11 8 8
8 15 12 87 8
8 15 13 409 44
9 0 10 230 82
9 0 11 399 50
9 1 10 415 66
9 1 11 507 34
9 2 4 3 82
9 2 5 3 50
9 2 10 166 66
9 2 11 27 34
9 3 4 417 66
9 3 5 8 34
9 3 10 19 66
9 3 11 25 34
9 4 4 623 64
9 4 5 358 0
9 4 6 611 16
9 4 7 605 16
9 4 8 608 16
9 4 9 624 16
9 4 10 245 0
9 4 11 247 0
9 4 12 630 18
9 4 13 610 50
9 5 4 623 64
9 5 5 587 0
9 5 6 439 0
9 5 7 12 0
9 5 8 225 0
9 5 9 317 0
9 5 10 382 0
9 5 11 468 0
9 5 12 603 10
9 5 13 635 42
9 6 4 616 64
9 6 5 642 0
9 6 6 413 0
9 6 7 366 0
9 6 8 467 0
9 6 9 13 0
9 6 10 680 0
9 6 11 608 32
9 7 4 605 64
9 7 5 667 0
9 7 6 197 0
9 7 7 172 0
9 7 8 87 0
9 7 9 193 0
9 7 10 676 0
9 7 11 631 32
9 8 2 688 80
9 8 3 131 16
9 8 4 271 0
9 8 5 482 0
9 8 6 331 0
9 8 7 265 0
9 8 8 333 0
9 8 9 72 0
9 8 10 505 0
9 8 11 442 0
9 8 12 16 16
9 8 13 124 48
9 9 2 429 64
9 9 3 131 0
9 9 4 379 0
9 9 5 170 0
9 9 6 517 0
9 9 7 600 0
9 9 8 190 0
9 9 9 369 0
9 9 10 582 0
9 9 11 370 0
9 9 12 129 0
9 9 13 270 32
9 10 2 153 64
9 10 3 116 0
9 10 4 14 0
9 10 5 294 0
9 10 6 176 0
9 10 7 11 0
9 10 8 83 0
9 10 9 85 0
9 10 10 387 0
9 10 11 521 0
9 10 12 230 0
9 10 13 260 32
9 11 2 18 64
9 11 3 173 0
9 11 4 28 0
9 11 5 485 0
9 11 6 310 0
9 11 7 226 0
9 11 8 189 0
9 11 9 22 0
9 11 10 99 0
9 11 11 102 0
9 11 12 22 0
9 11 13 102 32
9 12 2 560 64
9 12 3 244 0
9 12 4 346 0
9 12 5 409 0
9 12 6 418 0
9 12 7 263 0
9 12 8 16 0
9 12 9 558 0
9 12 10 379 0
9 12 11 453 0
9 12 12 192 0
9 12 13 369 32
9 13 2 247 64
9 13 3 472 0
9 13 4 160 0
9 13 5 348 0
9 13 6 413 0
9 13 7 151 0
9 13 8 27 0
9 13 9 16 0
9 13 10 524 0
9 13 11 186 0
9 13 12 316 0
9 13 13 25 32
9 14 2 496 64
9 14 3 595 0
9 14 4 641 0
9 14 5 639 0
9 14 6 366 0
9 14 7 210 0
9 14 8 497 0
9 14 9 85 0
9 14 10 71 0
9 14 11 8 0
9 14 12 183 0
9 14 13 95 32
9 15 2 590 72
9 15 3 438 8
9 15 4 320 8
9 15 5 320 8
9 15 6 65 8
9 15 7 189 8
9 15 8 78 8
9 15 9 16 8
9 15 10 75 8
9 15 11 69 8
9 15 12 97 8
9 15 13 178 40
10 4 4 626 80
10 4 5 616 16
10 4 6 604 16
10 4 7 608 16
10 4 8 608 16
10 4 9 601 16
10 4 10 609 16
10 4 11 628 48
10 5 4 601 64
10 5 5 647 0
10 5 6 644 0
10 5 7 661 0
10 5 8 665 0
10 5 9 658 0
10 5 10 663 0
10 5 11 614 32
10 6 4 622 64
10 6 5 651 0
10 6 6 657 0
10 6 7 662 0
10 6 8 83 0
10 6 9 13 0
10 6 10 683 0
10 6 11 616 32
10 7 4 603 64
10 7 5 654 0
10 7 6 687 0
10 7 7 673 0
10 7 8 378 0
10 7 9 155 0
10 7 10 642 0
10 7 11 606 32
10 8 2 688 80
10 8 3 461 16
10 8 4 21 0
10 8 5 102 0
10 8 6 265 0
10 8 7 381 0
10 8 8 295 0
10 8 9 525 0
10 8 10 573 0
10 8 11 548 0
10 8 12 506 16
10 8 13 306 48
10 9 2 489 64
10 9 3 516 0
10 9 4 29 0
10 9 5 198 0
10 9 6 217 0
10 9 7 560 0
10 9 8 525 0
10 9 9 319 0
10 9 10 34 0
10 9 11 48 0
10 9 12 524 0
10 9 13 515 32
10 10 2 320 64
10 10 3 648 0
10 10 4 331 0
10 10 5 168 0
10 10 6 381 0
10 10 7 282 0
10 10 8 431 0
10 10 9 248 0
10 10 10 247 0
10 10 11 193 0
10 10 12 198 0
10 10 13 16 32
10 11 2 320 64
10 11 3 640 0
10 11 4 152 0
10 11 5 4 0
10 11 6 40 0
10 11 7 28 0
10 11 8 485 0
10 11 9 14 0
10 11 10 22 0
10 11 11 25 0
10 11 12 147 0
10 11 13 358 32
10 12 2 320 64
10 12 3 404 0
10 12 4 370 0
10 12 5 202 0
10 12 6 432 0
10 12 7 257 0
10 12 8 89 0
10 12 9 27 0
10 12 10 359 0
10 12 11 237 0
10 12 12 45 0
10 12 13 175 32
10 13 2 416 64
10 13 3 202 0
10 13 4 432 0
10 13 5 526 0
10 13 6 454 0
10 13 7 586 0
10 13 8 161 0
10 13 9 226 0
10 13 10 11 0
10 13 11 184 0
10 13 12 330 0
10 13 13 376 32
10 14 2 221 64
10 14 3 11 0
10 14 4 453 0
10 14 5 277 0
10 14 6 464 0
10 14 7 284 0
10 14 8 11 0
10 14 9 13 0
10 14 10 170 0
10 14 11 82 0
10 14 12 689 0
10 14 13 688 32
10 15 2 688 72
10 15 3 9 8
10 15 4 15 8
10 15 5 193 8
10 15 6 264 8
10 15 7 476 8
10 15 8 5 8
10 15 9 494 8
10 15 10 157 8
10 15 11 320 8
10 15 12 320 8
10 15 13 320 40
11 4 4 603 82
11 4 5 629 18
11 4 6 634 18
11 4 7 611 18
11 4 8 614 18
11 4 9 612 18
11 4 10 613 18
11 4 11 602 50
11 5 4 605 66
11 5 5 621 2
11 5 6 626 2
11 5 7 636 2
11 5 8 619 2
11 5 9 617 2
11 5 10 606 2
11 5 11 618 34
11 6 4 623 66
11 6 5 611 2
11 6 6 628 2
11 6 7 618 2
11 6 8 606 2
11 6 9 630 2
11 6 10 612 2
11 6 11 601 34
11 7 4 635 66
11 7 5 625 2
11 7 6 611 2
11 7 7 611 2
11 7 8 616 2
11 7 9 636 2
11 7 10 616 2
11 7 11 630 34
11 8 2 688 80
11 8 3 389 16
11 8 4 8 0
11 8 5 277 0
11 8 6 36 0
11 8 7 180 0
11 8 8 545 0
11 8 9 341 0
11 8 10 22 0
11 8 11 405 0
11 8 12 520 16
11 8 13 275 48
11 9 2 320 64
11 9 3 538 0
11 9 4 465 0
11 9 5 130 0
11 9 6 133 0
11 9 7 322 0
11 9 8 566 0
11 9 9 319 0
11 9 10 28 0
11 9 11 444 0
11 9 12 261 0
11 9 13 261 34
11 10 2 320 64
11 10 3 627 0
11 10 4 492 0
11 10 5 297 0
11 10 6 19 0
11 10 7 21 0
11 10 8 27 0
11 10 9 286 0
11 10 10 19 0
11 10 11 429 0
11 10 12 172 2
11 10 13 220 34
11 11 2 320 64
11 11 3 638 0
11 11 4 2 0
11 11 5 10 0
11 11 6 484 0
11 11 7 126 0
11 11 8 402 0
11 11 9 314 0
11 11 10 17 0
11 11 11 65 0
11 11 12 555 0
11 11 13 33 34
11 12 2 396 64
11 12 3 568 0
11 12 4 235 0
11 12 5 267 0
11 12 6 536 0
11 12 7 541 0
11 12 8 250 0
11 12 9 16 0
11 12 10 380 0
11 12 11 492 0
11 12 12 408 0
11 12 13 308 34
11 13 2 432 64
11 13 3 437 0
11 13 4 398 0
11 13 5 324 0
11 13 6 585 0
11 13 7 406 0
11 13 8 390 0
11 13 9 18 0
11 13 10 14 0
11 13 11 11 0
11 13 12 398 0
11 13 13 210 32
11 14 2 12 64
11 14 3 58 0
11 14 4 11 0
11 14 5 76 0
11 14 6 547 0
11 14 7 575 0
11 14 8 56 0
11 14 9 236 0
11 14 10 87 0
11 14 11 152 0
11 14 12 682 0
11 14 13 684 32
11 15 2 688 72
11 15 3 688 8
11 15 4 510 8
11 15 5 26 8
11 15 6 480 8
11 15 7 572 8
11 15 8 21 8
11 15 9 196 8
11 15 10 364 8
11 15 11 9 8
11 15 12 320 8
11 15 13 320 40
12 8 2 358 80
12 8 3 132 16
12 8 4 23 16
12 8 5 162 16
12 8 6 245 16
12 8 7 205 16
12 8 8 262 16
12 8 9 257 16
12 8 10 135 16
12 8 11 143 16
12 8 12 306 16
12 8 13 383 56
12 9 2 291 64
12 9 3 143 0
12 9 4 132 0
12 9 5 81 0
12 9 6 520 0
12 9 7 247 0
12 9 8 330 0
12 9 9 9 0
12 9 10 355 0
12 9 11 502 2
12 9 12 268 42
12 10 2 189 64
12 10 3 249 0
12 10 4 433 0
12 10 5 308 0
12 10 6 488 0
12 10 7 450 0
12 10 8 48 0
12 10 9 527 2
12 10 10 515 2
12 10 11 515 32
12 11 2 51 64
12 11 3 214 0
12 11 4 474 0
12 11 5 596 0
12 11 6 263 0
12 11 7 464 0
12 11 8 203 0
12 11 9 245 2
12 11 10 471 2
12 11 11 589 2
12 11 12 520 50
12 12 2 506 64
12 12 3 22 0
12 12 4 140 0
12 12 5 303 0
12 12 6 561 0
12 12 7 562 0
12 12 8 200 0
12 12 9 14 0
12 12 10 283 0
12 12 11 34 0
12 12 12 25 32
12 13 2 263 64
12 13 3 19 0
12 13 4 233 0
12 13 5 194 0
12 13 6 357 0
12 13 7 518 0
12 13 8 25 0
12 13 9 16 0
12 13 10 35 0
12 13 11 323 0
12 13 12 297 0
12 13 13 243 48
12 14 2 398 64
12 14 3 17 0
12 14 4 93 0
12 14 5 216 0
12 14 6 120 0
12 14 7 541 0
12 14 8 96 0
12 14 9 287 0
12 14 10 46 0
12 14 11 228 0
12 14 12 333 0
12 14 13 22 32
12 15 2 210 72
12 15 3 16 8
12 15 4 86 8
12 15 5 86 8
12 15 6 108 8
12 15 7 162 8
12 15 8 17 8
12 15 9 28 8
12 15 10 46 8
12 15 11 219 8
12 15 12 283 8
12 15 13 144 40
13 8 2 217 82
13 8 3 325 18
13 8 4 26 18
13 8 5 26 18
13 8 6 584 18
13 8 7 306 18
13 8 8 262 18
13 8 9 546 18
13 8 10 139 18
13 8 11 321 26
13 8 12 113 26
13 8 13 143 58
13 9 2 31 66
13 9 3 26 2
13 9 4 123 2
13 9 5 324 2
13 9 6 369 2
13 9 7 241 2
13 9 8 154 2
13 9 9 311 10
13 9 10 479 42
13 10 2 63 66
13 10 3 229 2
13 10 4 391 2
13 10 5 349 2
13 10 6 306 2
13 10 7 553 2
13 10 8 334 34
13 10 11 441 90
13 10 12 478 62
13 11 2 382 66
13 11 3 258 2
13 11 4 327 2
13 11 5 345 2
13 11 6 371 2
13 11 7 367 2
13 11 8 76 34
13 12 2 27 66
13 12 3 66 2
13 12 4 103 2
13 12 5 121 2
13 12 6 579 2
13 12 7 479 2
13 12 8 158 2
13 12 9 121 18
13 12 10 370 18
13 12 11 13 18
13 12 12 223 50
13 13 2 22 66
13 13 3 102 2
13 13 4 182 2
13 13 5 16 2
13 13 6 574 2
13 13 7 328 2
13 13 8 519 2
13 13 9 214 2
13 13 10 201 2
13 13 11 179 2
13 13 12 25 2
13 13 13 12 50
13 14 2 309 66
13 14 3 115 2
13 14 4 88 2
13 14 5 542 2
13 14 6 470 2
13 14 7 412 2
13 14 8 338 2
13 14 9 392 2
13 14 10 331 2
13 14 11 387 2
13 14 12 226 2
13 14 13 229 34
13 15 2 155 74
13 15 3 177 10
13 15 4 423 10
13 15 5 85 10
13 15 6 91 10
13 15 7 211 10
13 15 8 215 10
13 15 9 28 10
13 15 10 688 10
13 15 11 688 10
13 15 12 688 10
13 15 13 13 42
