Qubicle Exchange Format
Version 0.2
www.minddesk.com
8 8 8
129
0.000000 0.192157 0.062745
0.000000 0.200000 0.066667
0.000000 0.203922 0.062745
0.000000 0.203922 0.066667
0.000000 0.207843 0.066667
0.000000 0.211765 0.066667
0.000000 0.211765 0.070588
0.000000 0.215686 0.066667
0.000000 0.215686 0.070588
0.000000 0.219608 0.070588
0.000000 0.223529 0.070588
0.000000 0.223529 0.074510
0.000000 0.227451 0.070588
0.000000 0.231373 0.078431
0.003922 0.219608 0.074510
0.003922 0.231373 0.082353
0.007843 0.231373 0.082353
0.007843 0.231373 0.086275
0.007843 0.235294 0.082353
0.011765 0.223529 0.082353
0.011765 0.235294 0.086275
0.015686 0.227451 0.086275
0.015686 0.243137 0.094118
0.015686 0.247059 0.094118
0.019608 0.227451 0.090196
0.019608 0.235294 0.090196
0.019608 0.239216 0.094118
0.027451 0.243137 0.098039
0.027451 0.243137 0.101961
0.027451 0.247059 0.101961
0.027451 0.258824 0.105882
0.031373 0.239216 0.101961
0.031373 0.258824 0.109804
0.035294 0.239216 0.105882
0.035294 0.258824 0.113725
0.043137 0.247059 0.113725
0.043137 0.266667 0.117647
0.047059 0.258824 0.117647
0.047059 0.270588 0.121569
0.050980 0.250980 0.117647
0.050980 0.254902 0.121569
0.050980 0.258824 0.117647
0.050980 0.274510 0.125490
0.054902 0.258824 0.121569
0.054902 0.270588 0.129412
0.058824 0.058824 0.058824
0.058824 0.262745 0.129412
0.058824 0.266667 0.129412
0.058824 0.274510 0.133333
0.062745 0.262745 0.129412
0.062745 0.266667 0.129412
0.062745 0.270588 0.133333
0.062745 0.278431 0.133333
0.066667 0.270588 0.133333
0.066667 0.278431 0.137255
0.070588 0.266667 0.137255
0.070588 0.278431 0.141176
0.070588 0.286275 0.145098
0.070588 0.290196 0.145098
0.074510 0.274510 0.141176
0.074510 0.290196 0.149020
0.078431 0.282353 0.145098
0.078431 0.294118 0.149020
0.078431 0.294118 0.152941
0.082353 0.294118 0.156863
0.082353 0.298039 0.156863
0.086275 0.298039 0.156863
0.086275 0.298039 0.160784
0.090196 0.294118 0.160784
0.090196 0.298039 0.160784
0.090196 0.301961 0.164706
0.098039 0.309804 0.168627
0.101961 0.309804 0.172549
0.105882 0.313726 0.172549
0.109804 0.317647 0.176471
0.109804 0.317647 0.180392
0.113725 0.113725 0.113725
0.113725 0.317647 0.184314
0.117647 0.321569 0.188235
0.121569 0.325490 0.192157
0.125490 0.329412 0.196078
0.125490 0.333333 0.196078
0.133333 0.337255 0.200000
0.133333 0.337255 0.203922
0.145098 0.145098 0.145098
0.164706 0.360784 0.231373
0.164706 0.360784 0.235294
0.419608 0.023529 0.000000
0.478431 0.396078 0.000000
0.482353 0.396078 0.000000
0.486275 0.400000 0.000000
0.490196 0.086275 0.058824
0.490196 0.403922 0.000000
0.494118 0.094118 0.066667
0.494118 0.407843 0.000000
0.498039 0.411765 0.000000
0.501961 0.411765 0.000000
0.505882 0.415686 0.000000
0.509804 0.419608 0.000000
0.513726 0.423529 0.000000
0.517647 0.423529 0.000000
0.517647 0.427451 0.000000
0.521569 0.427451 0.000000
0.521569 0.431373 0.000000
0.525490 0.431373 0.000000
0.525490 0.435294 0.000000
0.529412 0.435294 0.000000
0.529412 0.439216 0.000000
0.533333 0.439216 0.003922
0.537255 0.443137 0.011765
0.537255 0.447059 0.015686
0.541176 0.447059 0.019608
0.541176 0.450980 0.023529
0.545098 0.454902 0.031373
0.549020 0.458824 0.035294
0.549020 0.458824 0.039216
0.552941 0.462745 0.043137
0.552941 0.462745 0.047059
0.552941 0.466667 0.050980
0.556863 0.466667 0.054902
0.556863 0.470588 0.058824
0.560784 0.474510 0.066667
0.564706 0.478431 0.070588
0.564706 0.478431 0.074510
0.568627 0.482353 0.082353
0.572549 0.486275 0.086275
0.572549 0.486275 0.090196
0.992157 0.000000 0.000000
0.992157 0.058824 0.058824
0 6 1 119 84
0 6 2 106 20
0 6 3 120 20
0 6 4 94 20
0 6 5 109 20
0 6 6 103 52
0 7 1 107 76
0 7 2 125 12
0 7 3 89 12
0 7 4 108 12
0 7 5 115 12
0 7 6 125 44
1 2 3 112 92
1 2 4 111 28
1 2 5 8 28
1 2 6 45 54
1 3 6 84 70
1 3 7 76 62
1 4 1 13 84
1 4 2 81 20
1 4 3 3 20
1 4 4 9 20
1 4 5 51 20
1 4 6 91 36
1 5 1 16 68
1 5 2 87 4
1 5 3 24 4
1 5 4 17 4
1 5 5 5 4
1 5 6 7 36
1 6 0 119 84
1 6 1 9 0
1 6 2 63 0
1 6 3 58 0
1 6 4 4 0
1 6 5 47 0
1 6 6 5 32
1 7 0 101 76
1 7 1 109 8
1 7 2 103 8
1 7 3 126 8
1 7 4 99 8
1 7 5 111 8
1 7 6 99 8
1 7 7 110 60
2 0 3 44 86
2 0 4 67 54
2 1 3 96 70
2 1 4 88 38
2 2 2 90 84
2 2 3 40 0
2 2 4 10 0
2 2 5 122 48
2 3 2 39 68
2 3 3 116 4
2 3 4 106 4
2 3 5 106 36
2 4 1 30 80
2 4 2 54 0
2 4 3 53 0
2 4 4 14 0
2 4 5 3 0
2 4 6 6 48
2 5 1 85 64
2 5 2 55 0
2 5 3 5 0
2 5 4 36 0
2 5 5 12 0
2 5 6 57 32
2 6 0 126 80
2 6 1 12 0
2 6 2 19 0
2 6 3 80 0
2 6 4 31 0
2 6 5 42 0
2 6 6 127 32
2 7 0 90 72
2 7 1 94 8
2 7 2 101 8
2 7 3 113 8
2 7 4 105 8
2 7 5 101 8
2 7 6 90 8
2 7 7 92 56
3 2 2 99 80
3 2 3 124 16
3 2 4 119 16
3 2 5 3 48
3 3 2 120 64
3 3 3 102 0
3 3 4 98 0
3 3 5 123 32
3 4 1 47 80
3 4 2 15 0
3 4 3 46 0
3 4 4 4 0
3 4 5 74 0
3 4 6 1 48
3 5 1 75 64
3 5 2 4 0
3 5 3 61 0
3 5 4 59 0
3 5 5 34 0
3 5 6 0 32
3 6 0 107 80
3 6 1 64 0
3 6 2 83 0
3 6 3 22 0
3 6 4 56 0
3 6 5 52 0
3 6 6 4 32
3 7 0 94 72
3 7 1 106 8
3 7 2 104 8
3 7 3 88 8
3 7 4 115 8
3 7 5 115 8
3 7 6 94 8
3 7 7 96 56
4 2 2 112 80
4 2 3 108 16
4 2 4 106 16
4 2 5 99 48
4 3 2 112 64
4 3 3 107 0
4 3 4 98 0
4 3 5 94 32
4 4 1 25 80
4 4 2 60 0
4 4 3 28 0
4 4 4 70 0
4 4 5 71 0
4 4 6 66 48
4 5 1 17 64
4 5 2 18 0
4 5 3 3 0
4 5 4 8 0
4 5 5 6 0
4 5 6 77 32
4 6 0 97 80
4 6 1 29 0
4 6 2 4 0
4 6 3 12 0
4 6 4 73 0
4 6 5 62 0
4 6 6 49 32
4 7 0 96 72
4 7 1 110 8
4 7 2 124 8
4 7 3 100 8
4 7 4 94 8
4 7 5 96 8
4 7 6 97 8
4 7 7 89 56
5 0 3 57 86
5 0 4 12 54
5 1 3 100 70
5 1 4 95 38
5 2 2 112 82
5 2 3 48 0
5 2 4 20 0
5 2 5 118 48
5 3 2 0 66
5 3 3 110 2
5 3 4 126 2
5 3 5 106 34
5 4 1 79 80
5 4 2 11 0
5 4 3 41 0
5 4 4 65 0
5 4 5 82 0
5 4 6 35 48
5 5 1 43 64
5 5 2 68 0
5 5 3 60 0
5 5 4 21 0
5 5 5 3 0
5 5 6 50 32
5 6 0 88 80
5 6 1 9 0
5 6 2 33 0
5 6 3 78 0
5 6 4 61 0
5 6 5 37 0
5 6 6 128 32
5 7 0 97 72
5 7 1 102 8
5 7 2 98 8
5 7 3 116 8
5 7 4 112 8
5 7 5 109 8
5 7 6 105 8
5 7 7 125 56
6 2 3 125 90
6 2 4 104 26
6 2 5 32 26
6 2 6 3 62
6 4 1 72 82
6 4 2 93 18
6 4 3 4 18
6 4 4 4 18
6 4 5 86 18
6 4 6 1 50
6 5 1 38 66
6 5 2 23 2
6 5 3 5 2
6 5 4 82 2
6 5 5 4 2
6 5 6 27 34
6 6 0 109 82
6 6 1 10 0
6 6 2 4 0
6 6 3 69 0
6 6 4 26 0
6 6 5 2 0
6 6 6 9 32
6 7 0 114 74
6 7 1 113 8
6 7 2 117 8
6 7 3 115 8
6 7 4 102 8
6 7 5 106 8
6 7 6 117 8
6 7 7 97 58
7 6 1 92 82
7 6 2 121 18
7 6 3 101 18
7 6 4 97 18
7 6 5 92 18
7 6 6 110 50
7 7 1 106 74
7 7 2 106 10
7 7 3 107 10
7 7 4 92 10
7 7 5 102 10
7 7 6 95 42
