Qubicle Exchange Format
Version 0.2
www.minddesk.com
8 8 8
127
0.000000 0.192157 0.062745
0.000000 0.200000 0.066667
0.000000 0.203922 0.062745
0.000000 0.203922 0.066667
0.000000 0.207843 0.066667
0.000000 0.211765 0.066667
0.000000 0.211765 0.070588
0.000000 0.215686 0.066667
0.000000 0.215686 0.070588
0.000000 0.219608 0.070588
0.000000 0.223529 0.070588
0.000000 0.223529 0.074510
0.000000 0.227451 0.070588
0.000000 0.231373 0.078431
0.003922 0.219608 0.074510
0.003922 0.231373 0.082353
0.007843 0.231373 0.082353
0.007843 0.231373 0.086275
0.007843 0.235294 0.082353
0.011765 0.223529 0.082353
0.011765 0.235294 0.086275
0.015686 0.227451 0.086275
0.015686 0.243137 0.094118
0.015686 0.247059 0.094118
0.019608 0.227451 0.090196
0.019608 0.235294 0.090196
0.019608 0.239216 0.094118
0.027451 0.243137 0.098039
0.027451 0.243137 0.101961
0.027451 0.247059 0.101961
0.027451 0.258824 0.105882
0.031373 0.239216 0.101961
0.031373 0.258824 0.109804
0.035294 0.239216 0.105882
0.035294 0.258824 0.113725
0.043137 0.247059 0.113725
0.043137 0.266667 0.117647
0.047059 0.258824 0.117647
0.047059 0.270588 0.121569
0.050980 0.250980 0.117647
0.050980 0.254902 0.121569
0.050980 0.258824 0.117647
0.050980 0.274510 0.125490
0.054902 0.258824 0.121569
0.054902 0.270588 0.129412
0.058824 0.058824 0.058824
0.058824 0.262745 0.129412
0.058824 0.266667 0.129412
0.062745 0.262745 0.129412
0.062745 0.266667 0.129412
0.062745 0.270588 0.133333
0.062745 0.278431 0.133333
0.066667 0.270588 0.133333
0.066667 0.278431 0.137255
0.070588 0.266667 0.137255
0.070588 0.278431 0.141176
0.070588 0.286275 0.145098
0.070588 0.290196 0.145098
0.074510 0.274510 0.141176
0.074510 0.290196 0.149020
0.078431 0.282353 0.145098
0.078431 0.294118 0.149020
0.078431 0.294118 0.152941
0.082353 0.294118 0.156863
0.082353 0.298039 0.156863
0.086275 0.298039 0.156863
0.086275 0.298039 0.160784
0.090196 0.294118 0.160784
0.090196 0.298039 0.160784
0.090196 0.301961 0.164706
0.098039 0.309804 0.168627
0.101961 0.309804 0.172549
0.105882 0.313726 0.172549
0.109804 0.317647 0.176471
0.109804 0.317647 0.180392
0.113725 0.113725 0.113725
0.113725 0.317647 0.184314
0.117647 0.321569 0.188235
0.121569 0.325490 0.192157
0.125490 0.329412 0.196078
0.125490 0.333333 0.196078
0.133333 0.337255 0.200000
0.133333 0.337255 0.203922
0.145098 0.145098 0.145098
0.164706 0.360784 0.231373
0.164706 0.360784 0.235294
0.419608 0.023529 0.000000
0.478431 0.396078 0.000000
0.482353 0.396078 0.000000
0.486275 0.400000 0.000000
0.490196 0.086275 0.058824
0.490196 0.403922 0.000000
0.494118 0.094118 0.066667
0.494118 0.407843 0.000000
0.498039 0.411765 0.000000
0.501961 0.411765 0.000000
0.505882 0.415686 0.000000
0.509804 0.419608 0.000000
0.513726 0.423529 0.000000
0.517647 0.423529 0.000000
0.517647 0.427451 0.000000
0.521569 0.427451 0.000000
0.521569 0.431373 0.000000
0.525490 0.431373 0.000000
0.525490 0.435294 0.000000
0.529412 0.435294 0.000000
0.529412 0.439216 0.000000
0.533333 0.439216 0.003922
0.537255 0.443137 0.011765
0.537255 0.447059 0.015686
0.541176 0.447059 0.019608
0.541176 0.450980 0.023529
0.545098 0.454902 0.031373
0.549020 0.458824 0.035294
0.549020 0.458824 0.039216
0.552941 0.462745 0.043137
0.552941 0.462745 0.047059
0.552941 0.466667 0.050980
0.556863 0.466667 0.054902
0.556863 0.470588 0.058824
0.560784 0.474510 0.066667
0.564706 0.478431 0.070588
0.564706 0.478431 0.074510
0.568627 0.482353 0.082353
0.572549 0.486275 0.086275
0.572549 0.486275 0.090196
1.000000 0.000000 0.000000
0 2 6 3 124
0 3 1 75 124
0 7 1 109 92
0 7 2 91 28
0 7 3 95 28
0 7 4 88 28
0 7 5 124 28
0 7 6 96 60
1 2 1 45 116
1 2 6 32 120
1 3 1 83 98
1 4 1 90 68
1 4 2 6 20
1 4 3 1 20
1 4 4 65 20
1 4 5 35 20
1 4 6 1 52
1 5 1 7 68
1 5 2 56 4
1 5 3 0 4
1 5 4 76 4
1 5 5 49 4
1 5 6 27 36
1 6 0 102 84
1 6 1 5 4
1 6 2 126 4
1 6 3 4 4
1 6 4 48 4
1 6 5 126 4
1 6 6 9 4
1 6 7 109 52
1 7 0 124 76
1 7 1 98 8
1 7 2 89 8
1 7 3 93 8
1 7 4 96 8
1 7 5 104 8
1 7 6 116 8
1 7 7 94 44
2 0 5 12 124
2 2 1 8 88
2 2 2 121 20
2 2 3 3 20
2 2 4 98 20
2 2 5 117 20
2 2 6 103 56
2 3 2 105 68
2 3 3 122 4
2 3 4 93 4
2 3 5 105 36
2 4 1 50 80
2 4 2 3 0
2 4 3 73 0
2 4 4 70 0
2 4 5 81 0
2 4 6 85 48
2 5 1 5 64
2 5 2 12 0
2 5 3 34 0
2 5 4 6 0
2 5 5 3 0
2 5 6 4 32
2 6 0 108 80
2 6 1 47 0
2 6 2 42 0
2 6 3 51 0
2 6 4 61 0
2 6 5 37 0
2 6 6 2 0
2 6 7 91 48
2 7 0 114 72
2 7 1 110 8
2 7 2 100 8
2 7 3 114 8
2 7 4 95 8
2 7 5 108 8
2 7 6 105 8
2 7 7 101 40
3 0 2 66 116
3 0 5 56 114
3 1 2 87 100
3 1 5 94 100
3 2 1 110 88
3 2 2 10 0
3 2 3 118 16
3 2 4 105 16
3 2 5 20 0
3 2 6 111 126
3 3 2 105 64
3 3 3 97 0
3 3 4 97 0
3 3 5 125 32
3 4 1 9 80
3 4 2 14 0
3 4 3 4 0
3 4 4 69 0
3 4 5 64 0
3 4 6 4 48
3 5 1 17 64
3 5 2 36 0
3 5 3 58 0
3 5 4 8 0
3 5 5 21 0
3 5 6 81 32
3 6 0 93 80
3 6 1 4 0
3 6 2 31 0
3 6 3 55 0
3 6 4 72 0
3 6 5 60 0
3 6 6 26 0
3 6 7 96 48
3 7 0 107 72
3 7 1 98 8
3 7 2 104 8
3 7 3 114 8
3 7 4 93 8
3 7 5 111 8
3 7 6 101 8
3 7 7 91 40
4 0 2 44 114
4 1 2 95 98
4 1 5 99 114
4 2 1 111 90
4 2 2 40 0
4 2 3 123 16
4 2 4 107 16
4 2 5 111 126
4 3 2 115 64
4 3 3 101 0
4 3 4 106 0
4 3 5 109 32
4 4 1 3 80
4 4 2 52 0
4 4 3 46 0
4 4 4 28 0
4 4 5 41 0
4 4 6 4 48
4 5 1 24 64
4 5 2 5 0
4 5 3 60 0
4 5 4 3 0
4 5 5 59 0
4 5 6 5 32
4 6 0 119 80
4 6 1 57 0
4 6 2 79 0
4 6 3 22 0
4 6 4 12 0
4 6 5 77 0
4 6 6 68 0
4 6 7 100 48
4 7 0 88 72
4 7 1 125 8
4 7 2 112 8
4 7 3 87 8
4 7 4 99 8
4 7 5 115 8
4 7 6 114 8
4 7 7 106 40
5 2 2 89 82
5 2 3 98 18
5 2 4 111 18
5 2 5 111 126
5 3 2 39 66
5 3 3 119 2
5 3 4 111 2
5 3 5 0 34
5 4 1 80 80
5 4 2 53 0
5 4 3 15 0
5 4 4 59 0
5 4 5 11 0
5 4 6 92 48
5 5 1 86 64
5 5 2 54 0
5 5 3 4 0
5 5 4 18 0
5 5 5 67 0
5 5 6 23 32
5 6 0 105 80
5 6 1 62 0
5 6 2 19 0
5 6 3 82 0
5 6 4 4 0
5 6 5 33 0
5 6 6 4 0
5 6 7 120 48
5 7 0 124 72
5 7 1 102 8
5 7 2 100 8
5 7 3 103 8
5 7 4 123 8
5 7 5 97 8
5 7 6 116 8
5 7 7 105 40
6 4 1 13 82
6 4 2 30 18
6 4 3 47 18
6 4 4 25 18
6 4 5 78 18
6 4 6 71 50
6 5 1 16 66
6 5 2 84 2
6 5 3 74 2
6 5 4 17 2
6 5 5 43 2
6 5 6 38 34
6 6 0 118 82
6 6 1 9 0
6 6 2 12 0
6 6 3 63 0
6 6 4 29 0
6 6 5 9 0
6 6 6 10 0
6 6 7 91 50
6 7 0 106 74
6 7 1 108 8
6 7 2 93 8
6 7 3 105 8
6 7 4 109 8
6 7 5 101 8
6 7 6 112 8
6 7 7 105 42
7 6 1 118 82
7 6 2 125 18
7 6 3 106 18
7 6 4 96 18
7 6 5 87 18
7 6 6 108 50
7 7 1 100 74
7 7 2 89 10
7 7 3 93 10
7 7 4 95 10
7 7 5 96 10
7 7 6 113 42
