Qubicle Exchange Format
Version 0.2
www.minddesk.com
16 32 16
2
0.000000 0.000000 0.000000
0.000000 0.658824 0.000000
4 5 6 0 124
4 9 9 0 124
4 16 6 0 124
5 0 5 1 84
5 0 6 1 20
5 0 7 1 20
5 0 8 1 20
5 0 9 1 20
5 0 10 1 52
5 1 5 1 68
5 1 6 1 4
5 1 7 1 4
5 1 8 1 4
5 1 9 1 4
5 1 10 1 36
5 2 5 1 68
5 2 6 1 4
5 2 7 1 4
5 2 8 1 4
5 2 9 1 4
5 2 10 1 36
5 3 5 1 68
5 3 6 1 4
5 3 7 1 4
5 3 8 1 4
5 3 9 1 4
5 3 10 1 36
5 4 5 1 68
5 4 6 1 4
5 4 7 1 4
5 4 8 1 4
5 4 9 1 4
5 4 10 1 36
5 5 5 1 68
5 5 6 1 0
5 5 7 1 4
5 5 8 1 4
5 5 9 1 4
5 5 10 1 36
5 6 5 1 68
5 6 6 1 4
5 6 7 1 4
5 6 8 1 4
5 6 9 1 4
5 6 10 1 36
5 7 5 1 68
5 7 6 1 4
5 7 7 1 4
5 7 8 1 4
5 7 9 1 4
5 7 10 1 36
5 8 5 1 68
5 8 6 1 4
5 8 7 1 4
5 8 8 1 4
5 8 9 1 4
5 8 10 1 36
5 9 5 1 68
5 9 6 1 4
5 9 7 1 4
5 9 8 1 4
5 9 9 1 0
5 9 10 1 36
5 10 5 1 68
5 10 6 1 4
5 10 7 1 4
5 10 8 1 4
5 10 9 1 4
5 10 10 1 36
5 11 5 1 68
5 11 6 1 4
5 11 7 1 4
5 11 8 1 4
5 11 9 1 4
5 11 10 1 36
5 12 5 1 68
5 12 6 1 4
5 12 7 1 4
5 12 8 1 4
5 12 9 1 4
5 12 10 1 36
5 13 5 1 68
5 13 6 1 4
5 13 7 1 4
5 13 8 1 4
5 13 9 1 4
5 13 10 1 36
5 14 5 1 68
5 14 6 1 4
5 14 7 1 4
5 14 8 1 4
5 14 9 1 4
5 14 10 1 36
5 15 5 1 68
5 15 6 1 4
5 15 7 1 4
5 15 8 1 4
5 15 9 1 4
5 15 10 1 36
5 16 5 1 68
5 16 6 1 0
5 16 7 1 4
5 16 8 1 4
5 16 9 1 4
5 16 10 1 36
5 17 5 1 68
5 17 6 1 4
5 17 7 1 4
5 17 8 1 4
5 17 9 1 4
5 17 10 1 36
5 18 5 1 68
5 18 6 1 4
5 18 7 1 4
5 18 8 1 4
5 18 9 1 4
5 18 10 1 36
5 19 5 1 76
5 19 6 1 12
5 19 7 1 12
5 19 8 1 12
5 19 9 1 12
5 19 10 1 44
5 20 9 0 126
6 0 5 1 80
6 0 6 1 16
6 0 7 1 16
6 0 8 1 16
6 0 9 1 16
6 0 10 1 48
6 1 5 1 64
6 1 6 1 0
6 1 7 1 0
6 1 8 1 0
6 1 9 1 0
6 1 10 1 32
6 2 5 1 64
6 2 6 1 0
6 2 7 1 0
6 2 8 1 0
6 2 9 1 0
6 2 10 1 32
6 3 5 1 64
6 3 6 1 0
6 3 7 1 0
6 3 8 1 0
6 3 9 1 0
6 3 10 1 32
6 4 5 1 64
6 4 6 1 0
6 4 7 1 0
6 4 8 1 0
6 4 9 1 0
6 4 10 1 32
6 5 5 1 64
6 5 6 1 0
6 5 7 1 0
6 5 8 1 0
6 5 9 1 0
6 5 10 1 32
6 6 5 1 64
6 6 6 1 0
6 6 7 1 0
6 6 8 1 0
6 6 9 1 0
6 6 10 1 32
6 7 5 1 64
6 7 6 1 0
6 7 7 1 0
6 7 8 1 0
6 7 9 1 0
6 7 10 1 32
6 8 5 1 64
6 8 6 1 0
6 8 7 1 0
6 8 8 1 0
6 8 9 1 0
6 8 10 1 0
6 8 11 1 20
6 8 12 1 20
6 8 13 1 20
6 8 14 1 52
6 9 5 1 64
6 9 6 1 0
6 9 7 1 0
6 9 8 1 0
6 9 9 1 0
6 9 10 1 0
6 9 11 1 4
6 9 12 1 4
6 9 13 1 4
6 9 14 1 36
6 10 4 0 94
6 10 5 1 0
6 10 6 1 0
6 10 7 1 0
6 10 8 1 0
6 10 9 1 0
6 10 10 1 0
6 10 11 1 4
6 10 12 1 4
6 10 13 1 4
6 10 14 1 36
6 11 5 1 64
6 11 6 1 0
6 11 7 1 0
6 11 8 1 0
6 11 9 1 0
6 11 10 1 0
6 11 11 1 12
6 11 12 1 12
6 11 13 1 4
6 11 14 1 36
6 12 5 1 64
6 12 6 1 0
6 12 7 1 0
6 12 8 1 0
6 12 9 1 0
6 12 10 1 32
6 12 13 1 68
6 12 14 1 36
6 12 15 0 126
6 13 5 1 64
6 13 6 1 0
6 13 7 1 0
6 13 8 1 0
6 13 9 1 0
6 13 10 1 32
6 13 13 1 76
6 13 14 1 44
6 14 5 1 64
6 14 6 1 0
6 14 7 1 0
6 14 8 1 0
6 14 9 1 0
6 14 10 1 32
6 15 5 1 64
6 15 6 1 0
6 15 7 1 0
6 15 8 1 0
6 15 9 1 0
6 15 10 1 0
6 15 11 0 62
6 16 4 0 126
6 16 5 1 64
6 16 6 1 0
6 16 7 1 0
6 16 8 1 0
6 16 9 1 0
6 16 10 1 32
6 17 5 1 64
6 17 6 1 0
6 17 7 1 0
6 17 8 1 0
6 17 9 1 0
6 17 10 1 32
6 18 5 1 64
6 18 6 1 0
6 18 7 1 0
6 18 8 1 0
6 18 9 1 0
6 18 10 1 32
6 19 5 1 72
6 19 6 1 8
6 19 7 1 8
6 19 8 1 8
6 19 9 1 8
6 19 10 1 40
6 20 6 0 126
7 0 5 1 80
7 0 6 1 16
7 0 7 1 16
7 0 8 1 16
7 0 9 1 16
7 0 10 1 48
7 1 5 1 64
7 1 6 1 0
7 1 7 1 0
7 1 8 1 0
7 1 9 1 0
7 1 10 1 32
7 2 5 1 64
7 2 6 1 0
7 2 7 1 0
7 2 8 1 0
7 2 9 1 0
7 2 10 1 32
7 3 5 1 64
7 3 6 1 0
7 3 7 1 0
7 3 8 1 0
7 3 9 1 0
7 3 10 1 32
7 4 5 1 64
7 4 6 1 0
7 4 7 1 0
7 4 8 1 0
7 4 9 1 0
7 4 10 1 32
7 5 5 1 64
7 5 6 1 0
7 5 7 1 0
7 5 8 1 0
7 5 9 1 0
7 5 10 1 32
7 6 5 1 64
7 6 6 1 0
7 6 7 1 0
7 6 8 1 0
7 6 9 1 0
7 6 10 1 32
7 7 5 1 64
7 7 6 1 0
7 7 7 1 0
7 7 8 1 0
7 7 9 1 0
7 7 10 1 0
7 7 11 0 54
7 8 5 1 64
7 8 6 1 0
7 8 7 1 0
7 8 8 1 0
7 8 9 1 0
7 8 10 1 0
7 8 11 1 0
7 8 12 1 16
7 8 13 1 16
7 8 14 1 48
7 9 5 1 64
7 9 6 1 0
7 9 7 1 0
7 9 8 1 0
7 9 9 1 0
7 9 10 1 0
7 9 11 1 0
7 9 12 1 0
7 9 13 1 0
7 9 14 1 32
7 10 5 1 64
7 10 6 1 0
7 10 7 1 0
7 10 8 1 0
7 10 9 1 0
7 10 10 1 0
7 10 11 1 0
7 10 12 1 0
7 10 13 1 0
7 10 14 1 32
7 11 5 1 64
7 11 6 1 0
7 11 7 1 0
7 11 8 1 0
7 11 9 1 0
7 11 10 1 0
7 11 11 1 8
7 11 12 1 8
7 11 13 1 0
7 11 14 1 32
7 12 5 1 64
7 12 6 1 0
7 12 7 1 0
7 12 8 1 0
7 12 9 1 0
7 12 10 1 32
7 12 13 1 64
7 12 14 1 32
7 13 1 1 84
7 13 2 1 20
7 13 3 1 20
7 13 4 1 20
7 13 5 1 0
7 13 6 1 0
7 13 7 1 0
7 13 8 1 0
7 13 9 1 0
7 13 10 1 32
7 13 13 1 72
7 13 14 1 40
7 14 1 1 68
7 14 2 1 4
7 14 3 1 4
7 14 4 1 4
7 14 5 1 0
7 14 6 1 0
7 14 7 1 0
7 14 8 1 0
7 14 9 1 0
7 14 10 1 32
7 15 1 1 68
7 15 2 1 4
7 15 3 1 12
7 15 4 1 12
7 15 5 1 0
7 15 6 1 0
7 15 7 1 0
7 15 8 1 0
7 15 9 1 0
7 15 10 1 32
7 16 1 1 68
7 16 2 1 36
7 16 5 1 64
7 16 6 1 0
7 16 7 1 0
7 16 8 1 0
7 16 9 1 0
7 16 10 1 32
7 17 1 1 68
7 17 2 1 36
7 17 5 1 64
7 17 6 1 0
7 17 7 1 0
7 17 8 1 0
7 17 9 1 0
7 17 10 1 32
7 18 1 1 76
7 18 2 1 44
7 18 5 1 64
7 18 6 1 0
7 18 7 1 0
7 18 8 1 0
7 18 9 1 0
7 18 10 1 32
7 19 5 1 72
7 19 6 1 8
7 19 7 1 8
7 19 8 1 8
7 19 9 1 8
7 19 10 1 40
8 0 5 1 80
8 0 6 1 16
8 0 7 1 16
8 0 8 1 16
8 0 9 1 16
8 0 10 1 48
8 1 5 1 64
8 1 6 1 0
8 1 7 1 0
8 1 8 1 0
8 1 9 1 0
8 1 10 1 32
8 2 5 1 64
8 2 6 1 0
8 2 7 1 0
8 2 8 1 0
8 2 9 1 0
8 2 10 1 32
8 3 4 0 94
8 3 5 1 0
8 3 6 1 0
8 3 7 1 0
8 3 8 1 0
8 3 9 1 0
8 3 10 1 32
8 4 5 1 64
8 4 6 1 0
8 4 7 1 0
8 4 8 1 0
8 4 9 1 0
8 4 10 1 32
8 5 5 1 64
8 5 6 1 0
8 5 7 1 0
8 5 8 1 0
8 5 9 1 0
8 5 10 1 32
8 6 5 1 64
8 6 6 1 0
8 6 7 1 0
8 6 8 1 0
8 6 9 1 0
8 6 10 1 32
8 7 5 1 64
8 7 6 1 0
8 7 7 1 0
8 7 8 1 0
8 7 9 1 0
8 7 10 1 32
8 8 5 1 64
8 8 6 1 0
8 8 7 1 0
8 8 8 1 0
8 8 9 1 0
8 8 10 1 0
8 8 11 1 18
8 8 12 1 18
8 8 13 1 18
8 8 14 1 50
8 9 5 1 64
8 9 6 1 0
8 9 7 1 0
8 9 8 1 0
8 9 9 1 0
8 9 10 1 0
8 9 11 1 2
8 9 12 1 2
8 9 13 1 2
8 9 14 1 34
8 9 15 0 126
8 10 5 1 64
8 10 6 1 0
8 10 7 1 0
8 10 8 1 0
8 10 9 1 0
8 10 10 1 0
8 10 11 1 2
8 10 12 1 2
8 10 13 1 2
8 10 14 1 34
8 11 5 1 64
8 11 6 1 0
8 11 7 1 0
8 11 8 1 0
8 11 9 1 0
8 11 10 1 0
8 11 11 1 10
8 11 12 1 10
8 11 13 1 2
8 11 14 1 34
8 12 5 1 64
8 12 6 1 0
8 12 7 1 0
8 12 8 1 0
8 12 9 1 0
8 12 10 1 32
8 12 13 1 66
8 12 14 1 34
8 13 1 1 80
8 13 2 1 16
8 13 3 1 16
8 13 4 1 16
8 13 5 1 0
8 13 6 1 0
8 13 7 1 0
8 13 8 1 0
8 13 9 1 0
8 13 10 1 32
8 13 13 1 74
8 13 14 1 42
8 14 1 1 64
8 14 2 1 0
8 14 3 1 0
8 14 4 1 0
8 14 5 1 0
8 14 6 1 0
8 14 7 1 0
8 14 8 1 0
8 14 9 1 0
8 14 10 1 32
8 15 0 0 126
8 15 1 1 64
8 15 2 1 0
8 15 3 1 8
8 15 4 1 8
8 15 5 1 0
8 15 6 1 0
8 15 7 1 0
8 15 8 1 0
8 15 9 1 0
8 15 10 1 32
8 16 1 1 64
8 16 2 1 32
8 16 5 1 64
8 16 6 1 0
8 16 7 1 0
8 16 8 1 0
8 16 9 1 0
8 16 10 1 32
8 17 1 1 64
8 17 2 1 32
8 17 5 1 64
8 17 6 1 0
8 17 7 1 0
8 17 8 1 0
8 17 9 1 0
8 17 10 1 32
8 18 1 1 72
8 18 2 1 40
8 18 5 1 64
8 18 6 1 0
8 18 7 1 0
8 18 8 1 0
8 18 9 1 0
8 18 10 1 32
8 19 5 1 72
8 19 6 1 8
8 19 7 1 8
8 19 8 1 8
8 19 9 1 8
8 19 10 1 40
9 0 5 1 80
9 0 6 1 16
9 0 7 1 16
9 0 8 1 16
9 0 9 1 16
9 0 10 1 48
9 1 5 1 64
9 1 6 1 0
9 1 7 1 0
9 1 8 1 0
9 1 9 1 0
9 1 10 1 32
9 2 5 1 64
9 2 6 1 0
9 2 7 1 0
9 2 8 1 0
9 2 9 1 0
9 2 10 1 32
9 3 5 1 64
9 3 6 1 0
9 3 7 1 0
9 3 8 1 0
9 3 9 1 0
9 3 10 1 32
9 4 5 1 64
9 4 6 1 0
9 4 7 1 0
9 4 8 1 0
9 4 9 1 0
9 4 10 1 32
9 5 5 1 64
9 5 6 1 0
9 5 7 1 0
9 5 8 1 0
9 5 9 1 0
9 5 10 1 32
9 6 5 1 64
9 6 6 1 0
9 6 7 1 0
9 6 8 1 0
9 6 9 1 0
9 6 10 1 32
9 7 5 1 64
9 7 6 1 0
9 7 7 1 0
9 7 8 1 0
9 7 9 1 0
9 7 10 1 32
9 8 5 1 64
9 8 6 1 0
9 8 7 1 0
9 8 8 1 0
9 8 9 1 0
9 8 10 1 32
9 9 5 1 64
9 9 6 1 0
9 9 7 1 0
9 9 8 1 0
9 9 9 1 0
9 9 10 1 32
9 10 5 1 64
9 10 6 1 0
9 10 7 1 0
9 10 8 1 0
9 10 9 1 0
9 10 10 1 32
9 11 5 1 64
9 11 6 1 0
9 11 7 1 0
9 11 8 1 0
9 11 9 1 0
9 11 10 1 32
9 12 5 1 64
9 12 6 1 0
9 12 7 1 0
9 12 8 1 0
9 12 9 1 0
9 12 10 1 32
9 13 1 1 82
9 13 2 1 18
9 13 3 1 18
9 13 4 1 18
9 13 5 1 0
9 13 6 1 0
9 13 7 1 0
9 13 8 1 0
9 13 9 1 0
9 13 10 1 32
9 14 1 1 66
9 14 2 1 2
9 14 3 1 2
9 14 4 1 2
9 14 5 1 0
9 14 6 1 0
9 14 7 1 0
9 14 8 1 0
9 14 9 1 0
9 14 10 1 0
9 14 11 0 62
9 15 1 1 66
9 15 2 1 2
9 15 3 1 10
9 15 4 1 2
9 15 5 1 0
9 15 6 1 0
9 15 7 1 0
9 15 8 1 0
9 15 9 1 0
9 15 10 1 32
9 16 1 1 66
9 16 2 1 34
9 16 4 0 78
9 16 5 1 0
9 16 6 1 0
9 16 7 1 0
9 16 8 1 0
9 16 9 1 0
9 16 10 1 32
9 17 1 1 66
9 17 2 1 34
9 17 5 1 64
9 17 6 1 0
9 17 7 1 0
9 17 8 1 0
9 17 9 1 0
9 17 10 1 32
9 18 1 1 74
9 18 2 1 42
9 18 5 1 64
9 18 6 1 0
9 18 7 1 0
9 18 8 1 0
9 18 9 1 0
9 18 10 1 32
9 19 5 1 72
9 19 6 1 8
9 19 7 1 8
9 19 8 1 8
9 19 9 1 8
9 19 10 1 40
9 20 8 0 126
10 0 5 1 82
10 0 6 1 18
10 0 7 1 18
10 0 8 1 18
10 0 9 1 18
10 0 10 1 50
10 1 5 1 66
10 1 6 1 2
10 1 7 1 2
10 1 8 1 2
10 1 9 1 2
10 1 10 1 34
10 2 5 1 66
10 2 6 1 2
10 2 7 1 2
10 2 8 1 2
10 2 9 1 2
10 2 10 1 34
10 3 5 1 66
10 3 6 1 2
10 3 7 1 2
10 3 8 1 2
10 3 9 1 2
10 3 10 1 34
10 4 5 1 66
10 4 6 1 2
10 4 7 1 2
10 4 8 1 2
10 4 9 1 2
10 4 10 1 34
10 5 5 1 66
10 5 6 1 2
10 5 7 1 0
10 5 8 1 2
10 5 9 1 2
10 5 10 1 34
10 6 5 1 66
10 6 6 1 2
10 6 7 1 2
10 6 8 1 2
10 6 9 1 2
10 6 10 1 34
10 7 5 1 66
10 7 6 1 2
10 7 7 1 2
10 7 8 1 2
10 7 9 1 2
10 7 10 1 34
10 8 5 1 66
10 8 6 1 2
10 8 7 1 2
10 8 8 1 2
10 8 9 1 2
10 8 10 1 34
10 9 5 1 66
10 9 6 1 2
10 9 7 1 2
10 9 8 1 2
10 9 9 1 2
10 9 10 1 34
10 10 5 1 66
10 10 6 1 2
10 10 7 1 2
10 10 8 1 2
10 10 9 1 0
10 10 10 1 34
10 11 5 1 66
10 11 6 1 2
10 11 7 1 2
10 11 8 1 2
10 11 9 1 2
10 11 10 1 34
10 12 5 1 66
10 12 6 1 2
10 12 7 1 2
10 12 8 1 2
10 12 9 1 2
10 12 10 1 34
10 13 5 1 66
10 13 6 1 2
10 13 7 1 2
10 13 8 1 2
10 13 9 1 2
10 13 10 1 34
10 14 5 1 66
10 14 6 1 2
10 14 7 1 0
10 14 8 1 2
10 14 9 1 2
10 14 10 1 34
10 15 3 0 126
10 15 5 1 66
10 15 6 1 2
10 15 7 1 2
10 15 8 1 2
10 15 9 1 2
10 15 10 1 34
10 16 5 1 66
10 16 6 1 2
10 16 7 1 2
10 16 8 1 2
10 16 9 1 2
10 16 10 1 34
10 17 5 1 66
10 17 6 1 2
10 17 7 1 2
10 17 8 1 2
10 17 9 1 2
10 17 10 1 34
10 18 5 1 66
10 18 6 1 2
10 18 7 1 2
10 18 8 1 2
10 18 9 1 0
10 18 10 1 34
10 19 5 1 74
10 19 6 1 10
10 19 7 1 10
10 19 8 1 10
10 19 9 1 10
10 19 10 1 42
11 5 7 0 122
11 10 9 0 122
11 14 7 0 122
11 18 9 0 122
