Qubicle Exchange Format
Version 0.2
www.minddesk.com
16 32 16
3
0.000000 0.000000 0.000000
0.000000 0.658824 0.000000
0.956863 0.470588 0.988235
3 1 8 0 126
3 4 9 0 126
3 5 5 0 126
4 0 4 1 126
4 0 5 1 126
4 0 6 1 126
4 0 7 1 126
4 0 8 1 126
4 0 9 1 126
4 0 10 1 126
4 0 11 1 126
4 1 4 1 126
4 1 5 1 126
4 1 6 1 126
4 1 7 1 126
4 1 8 1 126
4 1 9 1 126
4 1 10 1 126
4 1 11 1 126
4 2 4 1 126
4 2 5 1 126
4 2 6 1 126
4 2 7 1 126
4 2 8 1 126
4 2 9 1 126
4 2 10 1 126
4 2 11 1 126
4 3 4 1 126
4 3 5 1 126
4 3 6 1 126
4 3 7 1 126
4 3 8 1 126
4 3 9 1 126
4 3 10 1 126
4 3 11 1 126
4 4 4 1 84
4 4 5 1 20
4 4 6 1 20
4 4 7 1 20
4 4 8 1 20
4 4 9 1 20
4 4 10 1 20
4 4 11 1 52
4 5 4 1 68
4 5 5 1 4
4 5 6 1 4
4 5 7 1 4
4 5 8 1 4
4 5 9 1 4
4 5 10 1 4
4 5 11 1 36
4 6 4 1 76
4 6 5 1 12
4 6 6 1 12
4 6 7 1 12
4 6 8 1 12
4 6 9 1 12
4 6 10 1 12
4 6 11 1 44
5 0 4 1 126
5 0 5 1 126
5 0 6 1 126
5 0 7 1 126
5 0 8 1 126
5 0 9 1 126
5 0 10 1 126
5 0 11 1 126
5 1 4 1 126
5 1 5 1 126
5 1 6 1 126
5 1 7 1 126
5 1 8 1 126
5 1 9 1 126
5 1 10 1 126
5 1 11 1 126
5 2 4 1 126
5 2 5 1 126
5 2 6 1 126
5 2 7 1 126
5 2 8 1 126
5 2 9 1 126
5 2 10 1 126
5 2 11 1 126
5 3 4 1 126
5 3 5 1 126
5 3 6 1 126
5 3 7 1 126
5 3 8 1 126
5 3 9 1 126
5 3 10 1 126
5 3 11 1 126
5 4 4 1 80
5 4 5 1 0
5 4 6 1 0
5 4 7 1 0
5 4 8 1 0
5 4 9 1 0
5 4 10 1 0
5 4 11 1 48
5 5 4 1 64
5 5 5 1 0
5 5 6 1 0
5 5 7 1 0
5 5 8 1 0
5 5 9 1 0
5 5 10 1 0
5 5 11 1 32
5 6 4 1 72
5 6 5 1 0
5 6 6 1 0
5 6 7 1 0
5 6 8 1 0
5 6 9 1 0
5 6 10 1 0
5 6 11 1 40
5 7 5 1 76
5 7 6 1 12
5 7 7 1 12
5 7 8 1 12
5 7 9 1 12
5 7 10 1 44
6 0 4 1 126
6 0 5 1 126
6 0 6 1 16
6 0 7 1 16
6 0 8 1 16
6 0 9 1 16
6 0 10 1 126
6 0 11 1 126
6 1 4 1 126
6 1 5 1 126
6 1 6 1 0
6 1 7 1 0
6 1 8 1 0
6 1 9 1 0
6 1 10 1 126
6 1 11 1 126
6 2 3 0 126
6 2 4 1 126
6 2 5 1 126
6 2 6 1 0
6 2 7 1 0
6 2 8 1 0
6 2 9 1 0
6 2 10 1 126
6 2 11 1 126
6 3 4 1 126
6 3 5 1 126
6 3 6 1 126
6 3 7 1 126
6 3 8 1 126
6 3 9 1 126
6 3 10 1 126
6 3 11 1 126
6 4 4 1 80
6 4 5 1 0
6 4 6 1 0
6 4 7 1 0
6 4 8 1 0
6 4 9 1 0
6 4 10 1 0
6 4 11 1 48
6 5 4 1 64
6 5 5 1 0
6 5 6 1 0
6 5 7 1 0
6 5 8 1 0
6 5 9 1 0
6 5 10 1 0
6 5 11 1 32
6 5 12 0 126
6 6 4 1 72
6 6 5 1 0
6 6 6 1 0
6 6 7 1 0
6 6 8 1 0
6 6 9 1 0
6 6 10 1 0
6 6 11 1 40
6 7 5 1 72
6 7 6 1 0
6 7 7 1 0
6 7 8 1 0
6 7 9 1 0
6 7 10 1 40
6 8 6 1 68
6 8 7 1 4
6 8 8 1 4
6 8 9 1 36
6 9 6 2 68
6 9 7 2 12
6 9 8 2 12
6 9 9 2 36
6 10 6 2 110
6 10 9 2 110
7 0 4 1 126
7 0 5 1 126
7 0 6 1 16
7 0 7 1 16
7 0 8 1 16
7 0 9 1 16
7 0 10 1 126
7 0 11 1 126
7 1 4 1 126
7 1 5 1 126
7 1 6 1 0
7 1 7 1 0
7 1 8 1 0
7 1 9 1 0
7 1 10 1 126
7 1 11 1 126
7 2 4 1 126
7 2 5 1 126
7 2 6 1 0
7 2 7 1 0
7 2 8 1 0
7 2 9 1 0
7 2 10 1 126
7 2 11 1 126
7 3 4 1 126
7 3 5 1 126
7 3 6 1 126
7 3 7 1 126
7 3 8 1 126
7 3 9 1 126
7 3 10 1 126
7 3 11 1 126
7 4 4 1 80
7 4 5 1 0
7 4 6 1 0
7 4 7 1 0
7 4 8 1 0
7 4 9 1 0
7 4 10 1 0
7 4 11 1 48
7 5 4 1 64
7 5 5 1 0
7 5 6 1 0
7 5 7 1 0
7 5 8 1 0
7 5 9 1 0
7 5 10 1 0
7 5 11 1 32
7 6 4 1 72
7 6 5 1 0
7 6 6 1 0
7 6 7 1 0
7 6 8 1 0
7 6 9 1 0
7 6 10 1 0
7 6 11 1 40
7 7 5 1 72
7 7 6 1 0
7 7 7 1 0
7 7 8 1 0
7 7 9 1 0
7 7 10 1 40
7 8 6 1 64
7 8 7 1 0
7 8 8 1 0
7 8 9 1 32
7 9 6 2 72
7 9 7 2 8
7 9 8 2 8
7 9 9 2 40
8 0 4 1 126
8 0 5 1 126
8 0 6 1 16
8 0 7 1 16
8 0 8 1 16
8 0 9 1 16
8 0 10 1 126
8 0 11 1 126
8 1 4 1 126
8 1 5 1 126
8 1 6 1 0
8 1 7 1 0
8 1 8 1 0
8 1 9 1 0
8 1 10 1 126
8 1 11 1 126
8 2 4 1 126
8 2 5 1 126
8 2 6 1 0
8 2 7 1 0
8 2 8 1 0
8 2 9 1 0
8 2 10 1 126
8 2 11 1 126
8 3 4 1 126
8 3 5 1 126
8 3 6 1 126
8 3 7 1 126
8 3 8 1 126
8 3 9 1 126
8 3 10 1 126
8 3 11 1 126
8 4 4 1 80
8 4 5 1 0
8 4 6 1 0
8 4 7 1 0
8 4 8 1 0
8 4 9 1 0
8 4 10 1 0
8 4 11 1 48
8 5 3 0 126
8 5 4 1 64
8 5 5 1 0
8 5 6 1 0
8 5 7 1 0
8 5 8 1 0
8 5 9 1 0
8 5 10 1 0
8 5 11 1 32
8 6 4 1 72
8 6 5 1 0
8 6 6 1 0
8 6 7 1 0
8 6 8 1 0
8 6 9 1 0
8 6 10 1 0
8 6 11 1 40
8 7 5 1 72
8 7 6 1 0
8 7 7 1 0
8 7 8 1 0
8 7 9 1 0
8 7 10 1 40
8 8 6 1 64
8 8 7 1 0
8 8 8 1 0
8 8 9 1 32
8 9 6 2 72
8 9 7 2 8
8 9 8 2 8
8 9 9 2 40
9 0 4 1 126
9 0 5 1 126
9 0 6 1 16
9 0 7 1 16
9 0 8 1 16
9 0 9 1 16
9 0 10 1 126
9 0 11 1 126
9 1 4 1 126
9 1 5 1 126
9 1 6 1 0
9 1 7 1 0
9 1 8 1 0
9 1 9 1 0
9 1 10 1 126
9 1 11 1 126
9 1 12 0 126
9 2 4 1 126
9 2 5 1 126
9 2 6 1 0
9 2 7 1 0
9 2 8 1 0
9 2 9 1 0
9 2 10 1 126
9 2 11 1 126
9 3 4 1 126
9 3 5 1 126
9 3 6 1 126
9 3 7 1 126
9 3 8 1 126
9 3 9 1 126
9 3 10 1 126
9 3 11 1 126
9 4 4 1 80
9 4 5 1 0
9 4 6 1 0
9 4 7 1 0
9 4 8 1 0
9 4 9 1 0
9 4 10 1 0
9 4 11 1 48
9 5 4 1 64
9 5 5 1 0
9 5 6 1 0
9 5 7 1 0
9 5 8 1 0
9 5 9 1 0
9 5 10 1 0
9 5 11 1 32
9 6 4 1 72
9 6 5 1 0
9 6 6 1 0
9 6 7 1 0
9 6 8 1 0
9 6 9 1 0
9 6 10 1 0
9 6 11 1 40
9 7 5 1 72
9 7 6 1 0
9 7 7 1 0
9 7 8 1 0
9 7 9 1 0
9 7 10 1 40
9 8 6 1 66
9 8 7 1 2
9 8 8 1 2
9 8 9 1 34
9 9 6 2 66
9 9 7 2 10
9 9 8 2 10
9 9 9 2 34
9 10 6 2 110
9 10 9 2 110
10 0 4 1 126
10 0 5 1 126
10 0 6 1 126
10 0 7 1 126
10 0 8 1 126
10 0 9 1 126
10 0 10 1 126
10 0 11 1 126
10 1 4 1 126
10 1 5 1 126
10 1 6 1 126
10 1 7 1 126
10 1 8 1 126
10 1 9 1 126
10 1 10 1 126
10 1 11 1 126
10 2 4 1 126
10 2 5 1 126
10 2 6 1 126
10 2 7 1 126
10 2 8 1 126
10 2 9 1 126
10 2 10 1 126
10 2 11 1 126
10 3 4 1 126
10 3 5 1 126
10 3 6 1 126
10 3 7 1 126
10 3 8 1 126
10 3 9 1 126
10 3 10 1 126
10 3 11 1 126
10 4 4 1 80
10 4 5 1 0
10 4 6 1 0
10 4 7 1 0
10 4 8 1 0
10 4 9 1 0
10 4 10 1 0
10 4 11 1 48
10 5 4 1 64
10 5 5 1 0
10 5 6 1 0
10 5 7 1 0
10 5 8 1 0
10 5 9 1 0
10 5 10 1 0
10 5 11 1 32
10 6 4 1 72
10 6 5 1 0
10 6 6 1 0
10 6 7 1 0
10 6 8 1 0
10 6 9 1 0
10 6 10 1 0
10 6 11 1 40
10 7 5 1 74
10 7 6 1 10
10 7 7 1 10
10 7 8 1 10
10 7 9 1 10
10 7 10 1 42
11 0 4 1 126
11 0 5 1 126
11 0 6 1 126
11 0 7 1 126
11 0 8 1 126
11 0 9 1 126
11 0 10 1 126
11 0 11 1 126
11 1 4 1 126
11 1 5 1 126
11 1 6 1 126
11 1 7 1 126
11 1 8 1 126
11 1 9 1 126
11 1 10 1 126
11 1 11 1 126
11 2 4 1 126
11 2 5 1 126
11 2 6 1 126
11 2 7 1 126
11 2 8 1 126
11 2 9 1 126
11 2 10 1 126
11 2 11 1 126
11 3 4 1 126
11 3 5 1 126
11 3 6 1 126
11 3 7 1 126
11 3 8 1 126
11 3 9 1 126
11 3 10 1 126
11 3 11 1 126
11 4 4 1 82
11 4 5 1 18
11 4 6 1 18
11 4 7 1 18
11 4 8 1 18
11 4 9 1 18
11 4 10 1 18
11 4 11 1 50
11 5 4 1 66
11 5 5 1 2
11 5 6 1 2
11 5 7 1 2
11 5 8 1 2
11 5 9 1 2
11 5 10 1 2
11 5 11 1 34
11 6 4 1 74
11 6 5 1 10
11 6 6 1 10
11 6 7 1 10
11 6 8 1 10
11 6 9 1 10
11 6 10 1 10
11 6 11 1 42
12 1 5 0 126
12 2 8 0 126
12 5 5 0 126
12 5 10 0 126
