Qubicle Exchange Format
Version 0.2
www.minddesk.com
16 32 16
3
0.000000 0.000000 0.000000
0.000000 0.658824 0.000000
0.956863 0.470588 0.988235
4 3 4 0 126
4 10 3 0 126
5 0 2 1 84
5 0 3 1 20
5 0 4 1 20
5 0 5 1 20
5 0 6 1 52
5 1 2 1 68
5 1 3 1 4
5 1 4 1 4
5 1 5 1 4
5 1 6 1 36
5 2 2 1 68
5 2 3 1 4
5 2 4 1 4
5 2 5 1 4
5 2 6 1 36
5 3 2 1 68
5 3 3 1 4
5 3 4 1 4
5 3 5 1 4
5 3 6 1 36
5 4 2 1 68
5 4 3 1 4
5 4 4 1 4
5 4 5 1 4
5 4 6 1 36
5 5 2 1 68
5 5 3 1 4
5 5 4 1 4
5 5 5 1 4
5 5 6 1 36
5 6 2 1 68
5 6 3 1 4
5 6 4 1 4
5 6 5 1 4
5 6 6 1 36
5 7 2 1 68
5 7 3 1 4
5 7 4 1 4
5 7 5 1 4
5 7 6 1 36
5 8 2 1 68
5 8 3 1 4
5 8 4 1 4
5 8 5 1 4
5 8 6 1 36
5 8 10 0 126
5 9 2 1 68
5 9 3 1 4
5 9 4 1 4
5 9 5 1 4
5 9 6 1 36
5 10 2 1 68
5 10 3 1 4
5 10 4 1 4
5 10 5 1 4
5 10 6 1 36
5 11 2 1 68
5 11 3 1 4
5 11 4 1 4
5 11 5 1 4
5 11 6 1 36
5 12 2 1 76
5 12 3 1 12
5 12 4 1 12
5 12 5 1 12
5 12 6 1 44
5 14 11 0 126
6 0 2 1 80
6 0 3 1 16
6 0 4 1 16
6 0 5 1 16
6 0 6 1 48
6 1 2 1 64
6 1 3 1 0
6 1 4 1 0
6 1 5 1 0
6 1 6 1 32
6 2 2 1 64
6 2 3 1 0
6 2 4 1 0
6 2 5 1 0
6 2 6 1 32
6 3 2 1 64
6 3 3 1 0
6 3 4 1 0
6 3 5 1 0
6 3 6 1 32
6 4 2 1 64
6 4 3 1 0
6 4 4 1 0
6 4 5 1 0
6 4 6 1 32
6 5 2 1 64
6 5 3 1 0
6 5 4 1 0
6 5 5 1 0
6 5 6 1 32
6 6 2 1 64
6 6 3 1 0
6 6 4 1 0
6 6 5 1 0
6 6 6 1 0
6 6 7 1 20
6 6 8 1 20
6 6 9 1 20
6 6 10 1 20
6 6 11 1 20
6 6 12 1 52
6 7 2 1 64
6 7 3 1 0
6 7 4 1 0
6 7 5 1 0
6 7 6 1 0
6 7 7 1 4
6 7 8 1 4
6 7 9 1 4
6 7 10 1 4
6 7 11 1 4
6 7 12 1 36
6 8 2 1 64
6 8 3 1 0
6 8 4 1 0
6 8 5 1 0
6 8 6 1 0
6 8 7 1 4
6 8 8 1 4
6 8 9 1 4
6 8 10 1 4
6 8 11 1 4
6 8 12 1 36
6 9 2 1 64
6 9 3 1 0
6 9 4 1 0
6 9 5 1 0
6 9 6 1 0
6 9 7 1 4
6 9 8 1 4
6 9 9 1 4
6 9 10 1 4
6 9 11 1 4
6 9 12 1 36
6 10 2 1 64
6 10 3 1 0
6 10 4 1 0
6 10 5 1 0
6 10 6 1 0
6 10 7 1 12
6 10 8 1 12
6 10 9 1 4
6 10 10 1 4
6 10 11 1 4
6 10 12 1 36
6 11 2 1 64
6 11 3 1 0
6 11 4 1 0
6 11 5 1 0
6 11 6 1 32
6 11 9 1 68
6 11 10 1 4
6 11 11 1 4
6 11 12 1 36
6 12 2 1 72
6 12 3 1 8
6 12 4 1 8
6 12 5 1 8
6 12 6 1 40
6 12 9 1 68
6 12 10 1 4
6 12 11 1 4
6 12 12 1 36
6 13 3 2 126
6 13 4 2 126
6 13 5 2 126
6 13 9 1 68
6 13 10 1 4
6 13 11 1 4
6 13 12 1 36
6 14 3 2 126
6 14 5 2 126
6 14 9 1 68
6 14 10 1 4
6 14 11 1 4
6 14 12 1 36
6 15 9 1 68
6 15 10 1 4
6 15 11 1 4
6 15 12 1 36
6 16 9 1 68
6 16 10 1 4
6 16 11 1 4
6 16 12 1 36
6 17 9 1 76
6 17 10 1 12
6 17 11 1 12
6 17 12 1 44
7 0 2 1 80
7 0 3 1 16
7 0 4 1 16
7 0 5 1 16
7 0 6 1 48
7 1 2 1 64
7 1 3 1 0
7 1 4 1 0
7 1 5 1 0
7 1 6 1 32
7 2 2 1 64
7 2 3 1 0
7 2 4 1 0
7 2 5 1 0
7 2 6 1 32
7 3 2 1 64
7 3 3 1 0
7 3 4 1 0
7 3 5 1 0
7 3 6 1 32
7 4 2 1 64
7 4 3 1 0
7 4 4 1 0
7 4 5 1 0
7 4 6 1 32
7 5 2 1 64
7 5 3 1 0
7 5 4 1 0
7 5 5 1 0
7 5 6 1 32
7 6 2 1 64
7 6 3 1 0
7 6 4 1 0
7 6 5 1 0
7 6 6 1 0
7 6 7 1 16
7 6 8 1 16
7 6 9 1 16
7 6 10 1 16
7 6 11 1 16
7 6 12 1 48
7 7 1 0 126
7 7 2 1 64
7 7 3 1 0
7 7 4 1 0
7 7 5 1 0
7 7 6 1 0
7 7 7 1 0
7 7 8 1 0
7 7 9 1 0
7 7 10 1 0
7 7 11 1 0
7 7 12 1 32
7 8 2 1 64
7 8 3 1 0
7 8 4 1 0
7 8 5 1 0
7 8 6 1 0
7 8 7 1 0
7 8 8 1 0
7 8 9 1 0
7 8 10 1 0
7 8 11 1 0
7 8 12 1 32
7 9 2 1 64
7 9 3 1 0
7 9 4 1 0
7 9 5 1 0
7 9 6 1 0
7 9 7 1 0
7 9 8 1 0
7 9 9 1 0
7 9 10 1 0
7 9 11 1 0
7 9 12 1 32
7 10 2 1 64
7 10 3 1 0
7 10 4 1 0
7 10 5 1 0
7 10 6 1 0
7 10 7 1 8
7 10 8 1 8
7 10 9 1 0
7 10 10 1 0
7 10 11 1 0
7 10 12 1 32
7 11 2 1 64
7 11 3 1 0
7 11 4 1 0
7 11 5 1 0
7 11 6 1 32
7 11 9 1 64
7 11 10 1 0
7 11 11 1 0
7 11 12 1 32
7 12 2 1 72
7 12 3 1 8
7 12 4 1 8
7 12 5 1 8
7 12 6 1 40
7 12 9 1 64
7 12 10 1 0
7 12 11 1 0
7 12 12 1 32
7 13 3 2 126
7 13 4 2 126
7 13 5 2 126
7 13 9 1 64
7 13 10 1 0
7 13 11 1 0
7 13 12 1 32
7 14 9 1 64
7 14 10 1 0
7 14 11 1 0
7 14 12 1 32
7 14 13 0 126
7 15 9 1 64
7 15 10 1 0
7 15 11 1 0
7 15 12 1 32
7 16 9 1 64
7 16 10 1 0
7 16 11 1 0
7 16 12 1 32
7 17 9 1 72
7 17 10 1 8
7 17 11 1 8
7 17 12 1 40
8 0 2 1 80
8 0 3 1 16
8 0 4 1 16
8 0 5 1 16
8 0 6 1 48
8 1 2 1 64
8 1 3 1 0
8 1 4 1 0
8 1 5 1 0
8 1 6 1 32
8 2 2 1 64
8 2 3 1 0
8 2 4 1 0
8 2 5 1 0
8 2 6 1 32
8 3 1 0 126
8 3 2 1 64
8 3 3 1 0
8 3 4 1 0
8 3 5 1 0
8 3 6 1 32
8 4 2 1 64
8 4 3 1 0
8 4 4 1 0
8 4 5 1 0
8 4 6 1 32
8 5 2 1 64
8 5 3 1 0
8 5 4 1 0
8 5 5 1 0
8 5 6 1 32
8 6 2 1 64
8 6 3 1 0
8 6 4 1 0
8 6 5 1 0
8 6 6 1 0
8 6 7 1 16
8 6 8 1 16
8 6 9 1 16
8 6 10 1 16
8 6 11 1 16
8 6 12 1 48
8 7 2 1 64
8 7 3 1 0
8 7 4 1 0
8 7 5 1 0
8 7 6 1 0
8 7 7 1 0
8 7 8 1 0
8 7 9 1 0
8 7 10 1 0
8 7 11 1 0
8 7 12 1 32
8 8 2 1 64
8 8 3 1 0
8 8 4 1 0
8 8 5 1 0
8 8 6 1 0
8 8 7 1 0
8 8 8 1 0
8 8 9 1 0
8 8 10 1 0
8 8 11 1 0
8 8 12 1 32
8 8 13 0 126
8 9 2 1 64
8 9 3 1 0
8 9 4 1 0
8 9 5 1 0
8 9 6 1 0
8 9 7 1 0
8 9 8 1 0
8 9 9 1 0
8 9 10 1 0
8 9 11 1 0
8 9 12 1 32
8 10 2 1 64
8 10 3 1 0
8 10 4 1 0
8 10 5 1 0
8 10 6 1 0
8 10 7 1 8
8 10 8 1 8
8 10 9 1 0
8 10 10 1 0
8 10 11 1 0
8 10 12 1 32
8 11 2 1 64
8 11 3 1 0
8 11 4 1 0
8 11 5 1 0
8 11 6 1 32
8 11 9 1 64
8 11 10 1 0
8 11 11 1 0
8 11 12 1 32
8 12 2 1 72
8 12 3 1 8
8 12 4 1 8
8 12 5 1 8
8 12 6 1 40
8 12 9 1 64
8 12 10 1 0
8 12 11 1 0
8 12 12 1 32
8 13 3 2 126
8 13 4 2 126
8 13 5 2 126
8 13 9 1 64
8 13 10 1 0
8 13 11 1 0
8 13 12 1 32
8 14 9 1 64
8 14 10 1 0
8 14 11 1 0
8 14 12 1 32
8 15 9 1 64
8 15 10 1 0
8 15 11 1 0
8 15 12 1 32
8 16 9 1 64
8 16 10 1 0
8 16 11 1 0
8 16 12 1 32
8 17 9 1 72
8 17 10 1 8
8 17 11 1 8
8 17 12 1 40
8 18 10 0 126
9 0 2 1 80
9 0 3 1 16
9 0 4 1 16
9 0 5 1 16
9 0 6 1 48
9 1 2 1 64
9 1 3 1 0
9 1 4 1 0
9 1 5 1 0
9 1 6 1 32
9 2 2 1 64
9 2 3 1 0
9 2 4 1 0
9 2 5 1 0
9 2 6 1 32
9 3 2 1 64
9 3 3 1 0
9 3 4 1 0
9 3 5 1 0
9 3 6 1 32
9 4 2 1 64
9 4 3 1 0
9 4 4 1 0
9 4 5 1 0
9 4 6 1 32
9 5 2 1 64
9 5 3 1 0
9 5 4 1 0
9 5 5 1 0
9 5 6 1 32
9 6 2 1 64
9 6 3 1 0
9 6 4 1 0
9 6 5 1 0
9 6 6 1 0
9 6 7 1 18
9 6 8 1 18
9 6 9 1 18
9 6 10 1 18
9 6 11 1 18
9 6 12 1 50
9 7 2 1 64
9 7 3 1 0
9 7 4 1 0
9 7 5 1 0
9 7 6 1 0
9 7 7 1 2
9 7 8 1 2
9 7 9 1 2
9 7 10 1 2
9 7 11 1 2
9 7 12 1 34
9 8 2 1 64
9 8 3 1 0
9 8 4 1 0
9 8 5 1 0
9 8 6 1 0
9 8 7 1 2
9 8 8 1 2
9 8 9 1 2
9 8 10 1 2
9 8 11 1 2
9 8 12 1 34
9 9 2 1 64
9 9 3 1 0
9 9 4 1 0
9 9 5 1 0
9 9 6 1 0
9 9 7 1 2
9 9 8 1 2
9 9 9 1 2
9 9 10 1 2
9 9 11 1 2
9 9 12 1 34
9 10 2 1 64
9 10 3 1 0
9 10 4 1 0
9 10 5 1 0
9 10 6 1 0
9 10 7 1 10
9 10 8 1 10
9 10 9 1 2
9 10 10 1 2
9 10 11 1 2
9 10 12 1 34
9 11 2 1 64
9 11 3 1 0
9 11 4 1 0
9 11 5 1 0
9 11 6 1 32
9 11 9 1 66
9 11 10 1 2
9 11 11 1 2
9 11 12 1 34
9 12 2 1 72
9 12 3 1 8
9 12 4 1 8
9 12 5 1 8
9 12 6 1 40
9 12 9 1 66
9 12 10 1 2
9 12 11 1 2
9 12 12 1 34
9 13 3 2 126
9 13 4 2 126
9 13 5 2 126
9 13 9 1 66
9 13 10 1 2
9 13 11 1 2
9 13 12 1 34
9 14 3 2 126
9 14 5 2 126
9 14 9 1 66
9 14 10 1 2
9 14 11 1 2
9 14 12 1 34
9 15 9 1 66
9 15 10 1 2
9 15 11 1 2
9 15 12 1 34
9 16 9 1 66
9 16 10 1 2
9 16 11 1 2
9 16 12 1 34
9 17 9 1 74
9 17 10 1 10
9 17 11 1 10
9 17 12 1 42
10 0 2 1 82
10 0 3 1 18
10 0 4 1 18
10 0 5 1 18
10 0 6 1 50
10 1 2 1 66
10 1 3 1 2
10 1 4 1 2
10 1 5 1 2
10 1 6 1 34
10 2 2 1 66
10 2 3 1 2
10 2 4 1 2
10 2 5 1 2
10 2 6 1 34
10 3 2 1 66
10 3 3 1 2
10 3 4 1 2
10 3 5 1 2
10 3 6 1 34
10 4 2 1 66
10 4 3 1 2
10 4 4 1 2
10 4 5 1 2
10 4 6 1 34
10 5 2 1 66
10 5 3 1 2
10 5 4 1 2
10 5 5 1 2
10 5 6 1 34
10 6 2 1 66
10 6 3 1 2
10 6 4 1 2
10 6 5 1 2
10 6 6 1 34
10 7 2 1 66
10 7 3 1 2
10 7 4 1 2
10 7 5 1 2
10 7 6 1 34
10 8 2 1 66
10 8 3 1 2
10 8 4 1 2
10 8 5 1 2
10 8 6 1 34
10 8 7 0 126
10 9 2 1 66
10 9 3 1 2
10 9 4 1 2
10 9 5 1 2
10 9 6 1 34
10 10 2 1 66
10 10 3 1 2
10 10 4 1 2
10 10 5 1 2
10 10 6 1 34
10 11 2 1 66
10 11 3 1 2
10 11 4 1 2
10 11 5 1 2
10 11 6 1 34
10 12 2 1 74
10 12 3 1 10
10 12 4 1 10
10 12 5 1 10
10 12 6 1 42
11 4 5 0 126
11 8 2 0 126
