Qubicle Exchange Format
Version 0.2
www.minddesk.com
16 32 16
41
0.423529 0.290196 0.003922
0.423529 0.294118 0.003922
0.427451 0.294118 0.003922
0.431373 0.298039 0.003922
0.435294 0.298039 0.003922
0.435294 0.301961 0.003922
0.439216 0.301961 0.003922
0.439216 0.305882 0.003922
0.443137 0.305882 0.003922
0.447059 0.309804 0.003922
0.450980 0.309804 0.003922
0.450980 0.313726 0.003922
0.454902 0.313726 0.003922
0.458824 0.317647 0.003922
0.462745 0.317647 0.003922
0.462745 0.321569 0.003922
0.466667 0.321569 0.003922
0.470588 0.325490 0.007843
0.470588 0.329412 0.011765
0.474510 0.329412 0.015686
0.474510 0.333333 0.019608
0.478431 0.337255 0.023529
0.478431 0.337255 0.027451
0.482353 0.341176 0.031373
0.482353 0.345098 0.035294
0.486275 0.345098 0.039216
0.486275 0.349020 0.043137
0.490196 0.352941 0.047059
0.490196 0.352941 0.050980
0.494118 0.356863 0.054902
0.494118 0.360784 0.058824
0.498039 0.360784 0.062745
0.498039 0.364706 0.066667
0.501961 0.368627 0.070588
0.505882 0.368627 0.074510
0.505882 0.372549 0.078431
0.509804 0.376471 0.082353
0.509804 0.376471 0.086275
0.513726 0.380392 0.090196
0.513726 0.384314 0.094118
0.517647 0.384314 0.098039
4 0 4 16 84
4 0 5 32 28
4 0 6 2 20
4 0 7 28 20
4 0 8 2 52
4 1 4 34 100
4 1 6 12 76
4 1 7 4 12
4 1 8 6 44
4 2 4 3 108
4 2 10 21 116
4 3 8 7 116
4 3 10 30 108
4 4 8 27 100
4 5 8 0 110
5 0 3 21 84
5 0 4 6 16
5 0 5 5 16
5 0 6 12 16
5 0 7 22 16
5 0 8 9 16
5 0 9 4 28
5 0 10 12 20
5 0 11 14 52
5 1 3 5 68
5 1 4 13 0
5 1 5 21 12
5 1 6 2 8
5 1 7 17 8
5 1 8 11 32
5 1 10 26 68
5 1 11 12 44
5 2 3 6 68
5 2 4 20 32
5 2 8 2 100
5 2 10 7 96
5 3 3 4 76
5 3 4 30 4
5 3 5 17 20
5 3 6 22 22
5 3 7 4 20
5 3 8 12 32
5 3 10 8 96
5 4 4 38 68
5 4 5 18 4
5 4 6 36 14
5 4 7 36 14
5 4 8 21 42
5 4 10 5 108
5 5 4 3 78
5 5 5 12 46
6 0 3 6 80
6 0 4 9 16
6 0 5 16 16
6 0 6 17 16
6 0 7 20 18
6 0 8 20 16
6 0 9 26 16
6 0 10 26 16
6 0 11 16 48
6 1 3 16 66
6 1 4 17 2
6 1 5 31 0
6 1 6 24 0
6 1 7 4 2
6 1 8 26 0
6 1 9 27 4
6 1 10 37 0
6 1 11 35 32
6 2 3 14 66
6 2 4 3 0
6 2 5 22 4
6 2 6 1 12
6 2 7 36 6
6 2 8 26 0
6 2 9 28 6
6 2 10 0 0
6 2 11 12 36
6 3 3 21 66
6 3 4 6 0
6 3 5 14 32
6 3 7 34 74
6 3 8 13 8
6 3 9 11 6
6 3 10 0 0
6 3 11 16 36
6 4 3 6 70
6 4 4 37 10
6 4 5 29 40
6 4 9 5 78
6 4 10 4 0
6 4 11 20 36
6 5 3 37 110
6 5 10 25 76
6 5 11 33 44
7 0 3 0 88
7 0 4 33 24
7 0 5 16 16
7 0 6 33 48
7 0 8 9 80
7 0 9 21 16
7 0 10 13 16
7 0 11 2 16
7 0 12 28 60
7 1 5 26 64
7 1 6 32 32
7 1 8 35 64
7 1 9 2 8
7 1 10 39 0
7 1 11 1 32
7 2 4 40 80
7 2 5 16 0
7 2 6 16 32
7 2 8 27 96
7 2 10 16 64
7 2 11 16 32
7 3 4 8 72
7 3 5 39 0
7 3 6 39 44
7 3 8 22 96
7 3 10 26 64
7 3 11 23 32
7 4 5 17 104
7 4 8 25 110
7 4 10 6 66
7 4 11 14 32
7 5 10 16 74
7 5 11 2 42
8 0 3 2 88
8 0 4 24 16
8 0 5 7 16
8 0 6 8 16
8 0 7 12 20
8 0 8 32 16
8 0 9 5 16
8 0 10 19 16
8 0 11 31 16
8 0 12 3 48
8 1 4 6 68
8 1 5 15 0
8 1 6 16 0
8 1 7 16 4
8 1 8 8 0
8 1 9 26 0
8 1 10 37 0
8 1 11 30 2
8 1 12 2 38
8 2 4 19 64
8 2 5 14 2
8 2 6 16 0
8 2 7 16 4
8 2 8 12 0
8 2 9 13 6
8 2 10 3 0
8 2 11 10 2
8 2 12 35 46
8 3 4 32 72
8 3 5 26 2
8 3 6 19 10
8 3 7 29 14
8 3 8 30 8
8 3 9 13 14
8 3 10 37 8
8 3 11 23 32
8 4 5 21 106
8 4 11 9 104
9 0 3 18 80
9 0 4 19 16
9 0 5 22 16
9 0 6 2 16
9 0 7 3 16
9 0 8 5 16
9 0 9 34 16
9 0 10 35 16
9 0 11 13 24
9 0 12 39 56
9 1 3 5 68
9 1 4 19 0
9 1 5 4 8
9 1 6 6 0
9 1 7 29 0
9 1 8 9 0
9 1 9 15 8
9 1 10 3 32
9 2 3 2 70
9 2 4 19 32
9 2 6 23 72
9 2 7 2 10
9 2 8 2 32
9 2 10 39 96
9 3 3 34 70
9 3 4 7 32
9 3 8 6 96
9 3 10 20 64
9 3 11 9 50
9 4 3 0 70
9 4 4 30 36
9 4 8 15 108
9 4 10 10 70
9 4 11 15 34
9 5 3 24 78
9 5 4 25 46
9 5 10 9 78
9 5 11 6 46
10 0 3 25 80
10 0 4 0 16
10 0 5 17 16
10 0 6 31 16
10 0 7 29 16
10 0 8 27 18
10 0 9 24 16
10 0 10 15 16
10 0 11 7 24
10 0 12 18 56
10 1 3 34 72
10 1 4 28 0
10 1 5 16 0
10 1 6 40 0
10 1 7 9 8
10 1 8 3 2
10 1 9 39 0
10 1 10 3 32
10 2 4 20 66
10 2 5 15 4
10 2 6 2 40
10 2 8 14 66
10 2 9 27 4
10 2 10 17 32
10 3 4 34 66
10 3 5 35 36
10 3 7 31 86
10 3 8 8 2
10 3 9 17 14
10 3 10 20 40
10 4 4 27 74
10 4 5 8 14
10 4 6 37 22
10 4 7 13 6
10 4 8 3 42
10 5 6 23 78
10 5 7 35 46
11 0 3 35 80
11 0 4 36 16
11 0 5 23 16
11 0 6 4 16
11 0 7 2 48
11 0 9 20 80
11 0 10 32 16
11 0 11 18 16
11 0 12 21 50
11 1 3 10 72
11 1 4 9 10
11 1 5 0 0
11 1 6 25 2
11 1 7 16 42
11 1 9 17 66
11 1 10 36 2
11 1 11 13 6
11 1 12 2 38
11 2 5 26 64
11 2 6 31 34
11 2 9 5 74
11 2 10 11 2
11 2 11 11 14
11 2 12 24 46
11 3 5 23 74
11 3 6 22 46
11 3 10 32 106
12 0 3 38 82
12 0 4 32 26
12 0 5 40 18
12 0 6 31 26
12 0 7 19 26
12 0 8 13 30
12 0 9 31 26
12 0 10 6 26
12 0 11 25 58
12 1 3 38 98
12 1 5 31 98
12 2 3 1 102
12 2 5 32 106
12 3 3 23 102
12 4 3 7 102
12 4 6 16 118
12 5 3 34 110
12 5 6 23 110
