Qubicle Exchange Format
Version 0.2
www.minddesk.com
16 32 16
1
0.250980 0.172549 0.000000
4 9 7 0 126
4 11 7 0 126
5 9 7 0 126
5 9 8 0 126
5 10 7 0 126
5 10 8 0 126
5 11 7 0 126
5 11 8 0 126
6 0 6 0 86
6 0 7 0 22
6 0 8 0 20
6 0 9 0 52
6 1 6 0 70
6 1 7 0 4
6 1 8 0 4
6 1 9 0 36
6 2 6 0 70
6 2 7 0 4
6 2 8 0 4
6 2 9 0 36
6 3 6 0 70
6 3 7 0 4
6 3 8 0 4
6 3 9 0 36
6 4 6 0 70
6 4 7 0 4
6 4 8 0 4
6 4 9 0 36
6 5 6 0 70
6 5 7 0 4
6 5 8 0 4
6 5 9 0 36
6 6 6 0 70
6 6 7 0 4
6 6 8 0 4
6 6 9 0 36
6 7 6 0 70
6 7 7 0 4
6 7 8 0 4
6 7 9 0 36
6 8 6 0 70
6 8 7 0 4
6 8 8 0 4
6 8 9 0 36
6 9 6 0 70
6 9 7 0 4
6 9 8 0 4
6 9 9 0 36
6 10 6 0 70
6 10 7 0 4
6 10 8 0 4
6 10 9 0 36
6 11 6 0 70
6 11 7 0 4
6 11 8 0 4
6 11 9 0 36
6 12 6 0 68
6 12 7 0 4
6 12 8 0 4
6 12 9 0 36
6 13 6 0 68
6 13 7 0 4
6 13 8 0 4
6 13 9 0 36
6 14 6 0 68
6 14 7 0 4
6 14 8 0 4
6 14 9 0 36
6 15 6 0 68
6 15 7 0 4
6 15 8 0 4
6 15 9 0 4
6 15 10 0 20
6 15 11 0 20
6 15 12 0 52
6 16 0 0 126
6 16 1 0 126
6 16 2 0 126
6 16 3 0 126
6 16 4 0 126
6 16 5 0 126
6 16 6 0 68
6 16 7 0 4
6 16 8 0 4
6 16 9 0 4
6 16 10 0 4
6 16 11 0 4
6 16 12 0 36
6 17 1 0 126
6 17 2 0 126
6 17 3 0 126
6 17 4 0 126
6 17 5 0 126
6 17 6 0 68
6 17 7 0 4
6 17 8 0 4
6 17 9 0 4
6 17 10 0 4
6 17 11 0 4
6 17 12 0 36
6 18 6 0 68
6 18 7 0 4
6 18 8 0 4
6 18 9 0 4
6 18 10 0 12
6 18 11 0 12
6 18 12 0 44
6 19 6 0 76
6 19 7 0 4
6 19 8 0 4
6 19 9 0 44
6 20 7 0 76
6 20 8 0 44
6 20 14 0 126
6 21 15 0 126
6 22 15 0 126
7 0 8 0 82
7 0 9 0 50
7 1 7 0 80
7 1 8 0 0
7 1 9 0 32
7 2 7 0 64
7 2 8 0 0
7 2 9 0 32
7 3 7 0 64
7 3 8 0 0
7 3 9 0 32
7 4 7 0 64
7 4 8 0 0
7 4 9 0 32
7 5 7 0 64
7 5 8 0 0
7 5 9 0 32
7 6 7 0 64
7 6 8 0 0
7 6 9 0 32
7 7 7 0 64
7 7 8 0 0
7 7 9 0 32
7 8 7 0 64
7 8 8 0 0
7 8 9 0 32
7 9 7 0 64
7 9 8 0 0
7 9 9 0 32
7 10 7 0 64
7 10 8 0 0
7 10 9 0 32
7 11 7 0 64
7 11 8 0 0
7 11 9 0 32
7 12 6 0 80
7 12 7 0 0
7 12 8 0 0
7 12 9 0 32
7 13 6 0 64
7 13 7 0 0
7 13 8 0 0
7 13 9 0 32
7 14 6 0 64
7 14 7 0 0
7 14 8 0 0
7 14 9 0 32
7 15 6 0 64
7 15 7 0 0
7 15 8 0 0
7 15 9 0 0
7 15 10 0 16
7 15 11 0 16
7 15 12 0 48
7 16 1 0 126
7 16 2 0 126
7 16 3 0 126
7 16 4 0 126
7 16 5 0 126
7 16 6 0 64
7 16 7 0 0
7 16 8 0 0
7 16 9 0 0
7 16 10 0 0
7 16 11 0 0
7 16 12 0 32
7 17 3 0 126
7 17 4 0 126
7 17 5 0 126
7 17 6 0 64
7 17 7 0 0
7 17 8 0 0
7 17 9 0 0
7 17 10 0 0
7 17 11 0 0
7 17 12 0 32
7 18 6 0 64
7 18 7 0 0
7 18 8 0 0
7 18 9 0 0
7 18 10 0 8
7 18 11 0 8
7 18 12 0 40
7 18 13 0 126
7 18 14 0 126
7 18 15 0 126
7 19 6 0 72
7 19 7 0 0
7 19 8 0 0
7 19 9 0 40
7 19 12 0 126
7 19 13 0 126
7 19 14 0 126
7 19 15 0 126
7 20 7 0 72
7 20 8 0 40
7 20 14 0 126
7 20 15 0 126
7 21 14 0 126
7 21 15 0 126
7 22 15 0 126
8 0 6 0 84
8 0 7 0 52
8 1 6 0 68
8 1 7 0 0
8 1 8 0 16
8 1 9 0 50
8 2 6 0 68
8 2 7 0 0
8 2 8 0 0
8 2 9 0 34
8 3 6 0 68
8 3 7 0 0
8 3 8 0 0
8 3 9 0 34
8 4 6 0 68
8 4 7 0 0
8 4 8 0 0
8 4 9 0 34
8 5 6 0 68
8 5 7 0 0
8 5 8 0 0
8 5 9 0 34
8 6 6 0 68
8 6 7 0 0
8 6 8 0 0
8 6 9 0 34
8 7 6 0 68
8 7 7 0 0
8 7 8 0 0
8 7 9 0 34
8 8 6 0 68
8 8 7 0 0
8 8 8 0 0
8 8 9 0 34
8 9 6 0 68
8 9 7 0 0
8 9 8 0 0
8 9 9 0 34
8 10 6 0 68
8 10 7 0 0
8 10 8 0 0
8 10 9 0 34
8 11 6 0 68
8 11 7 0 0
8 11 8 0 0
8 11 9 0 34
8 12 6 0 64
8 12 7 0 0
8 12 8 0 0
8 12 9 0 32
8 13 6 0 64
8 13 7 0 0
8 13 8 0 0
8 13 9 0 32
8 14 6 0 64
8 14 7 0 0
8 14 8 0 0
8 14 9 0 32
8 15 6 0 64
8 15 7 0 0
8 15 8 0 0
8 15 9 0 0
8 15 10 0 18
8 15 11 0 18
8 15 12 0 50
8 16 6 0 64
8 16 7 0 0
8 16 8 0 0
8 16 9 0 0
8 16 10 0 2
8 16 11 0 2
8 16 12 0 34
8 17 6 0 64
8 17 7 0 0
8 17 8 0 0
8 17 9 0 0
8 17 10 0 2
8 17 11 0 2
8 17 12 0 34
8 18 6 0 64
8 18 7 0 0
8 18 8 0 0
8 18 9 0 0
8 18 10 0 10
8 18 11 0 10
8 18 12 0 42
8 18 13 0 126
8 18 14 0 126
8 18 15 0 126
8 19 6 0 72
8 19 7 0 0
8 19 8 0 0
8 19 9 0 32
8 19 12 0 126
8 19 13 0 126
8 19 14 0 126
8 19 15 0 126
8 20 7 0 72
8 20 8 0 8
8 20 9 0 46
8 20 14 0 126
8 20 15 0 126
8 21 14 0 126
9 0 6 0 82
9 0 7 0 18
9 0 8 0 54
9 1 6 0 66
9 1 7 0 2
9 1 8 0 34
9 2 6 0 66
9 2 7 0 2
9 2 8 0 34
9 3 6 0 66
9 3 7 0 2
9 3 8 0 34
9 4 6 0 66
9 4 7 0 2
9 4 8 0 34
9 5 6 0 66
9 5 7 0 2
9 5 8 0 34
9 6 6 0 66
9 6 7 0 2
9 6 8 0 34
9 7 6 0 66
9 7 7 0 2
9 7 8 0 34
9 8 6 0 66
9 8 7 0 2
9 8 8 0 34
9 9 6 0 66
9 9 7 0 2
9 9 8 0 34
9 10 6 0 66
9 10 7 0 2
9 10 8 0 34
9 11 6 0 66
9 11 7 0 2
9 11 8 0 34
9 12 6 0 66
9 12 7 0 2
9 12 8 0 2
9 12 9 0 50
9 13 6 0 66
9 13 7 0 2
9 13 8 0 2
9 13 9 0 34
9 14 6 0 66
9 14 7 0 2
9 14 8 0 2
9 14 9 0 34
9 15 6 0 66
9 15 7 0 2
9 15 8 0 2
9 15 9 0 34
9 16 6 0 66
9 16 7 0 2
9 16 8 0 2
9 16 9 0 34
9 17 6 0 66
9 17 7 0 2
9 17 8 0 2
9 17 9 0 34
9 18 6 0 66
9 18 7 0 2
9 18 8 0 2
9 18 9 0 34
9 19 6 0 74
9 19 7 0 2
9 19 8 0 2
9 19 9 0 42
9 20 7 0 74
9 20 8 0 42
10 14 6 0 126
10 14 7 0 126
10 14 8 0 126
10 15 6 0 126
10 15 7 0 126
10 15 8 0 126
11 14 7 0 126
11 14 8 0 126
11 15 7 0 126
11 15 8 0 126
12 14 7 0 126
12 15 7 0 126
12 15 8 0 126
13 15 7 0 126
13 15 8 0 126
13 16 7 0 126
13 16 8 0 126
14 15 7 0 126
14 15 8 0 126
14 15 9 0 126
14 15 10 0 126
14 15 11 0 126
14 15 12 0 126
14 15 13 0 126
14 15 14 0 126
14 16 7 0 126
14 16 8 0 126
14 16 9 0 126
14 16 10 0 126
14 16 11 0 126
14 16 12 0 126
14 16 13 0 126
14 17 7 0 126
14 17 8 0 126
14 17 11 0 126
14 18 7 0 126
14 18 8 0 126
14 19 7 0 126
14 20 7 0 126
