Qubicle Exchange Format
Version 0.2
www.minddesk.com
8 8 8
5
0.000000 0.000000 0.000000
0.733333 0.733333 0.733333
0.988235 0.454902 0.705882
0.988235 0.780392 0.741176
1.000000 1.000000 1.000000
1 2 1 3 116
1 2 6 3 116
1 3 1 3 68
1 3 2 3 20
1 3 3 3 20
1 3 4 3 20
1 3 5 3 20
1 3 6 3 36
1 4 1 3 68
1 4 2 0 4
1 4 3 3 4
1 4 4 3 4
1 4 5 0 4
1 4 6 3 36
1 5 1 1 76
1 5 2 3 4
1 5 3 3 4
1 5 4 3 4
1 5 5 3 4
1 5 6 1 44
1 6 2 1 76
1 6 3 1 12
1 6 4 1 12
1 6 5 1 44
2 2 1 3 80
2 2 2 4 20
2 2 3 4 20
2 2 4 4 20
2 2 5 4 20
2 2 6 3 48
2 3 1 3 64
2 3 2 3 0
2 3 3 3 0
2 3 4 3 0
2 3 5 3 0
2 3 6 3 32
2 4 1 3 64
2 4 2 3 0
2 4 3 3 0
2 4 4 3 0
2 4 5 3 0
2 4 6 3 32
2 5 1 1 72
2 5 2 3 0
2 5 3 3 0
2 5 4 3 0
2 5 5 3 0
2 5 6 1 40
2 6 2 1 72
2 6 3 1 8
2 6 4 1 8
2 6 5 1 40
3 0 2 3 116
3 0 5 3 116
3 1 2 2 126
3 1 5 2 126
3 2 1 4 80
3 2 2 4 0
3 2 3 4 16
3 2 4 4 16
3 2 5 3 0
3 2 6 4 48
3 3 1 3 64
3 3 2 3 0
3 3 3 3 0
3 3 4 3 0
3 3 5 3 0
3 3 6 3 32
3 4 1 3 64
3 4 2 3 0
3 4 3 3 0
3 4 4 3 0
3 4 5 3 0
3 4 6 3 32
3 5 1 1 72
3 5 2 3 0
3 5 3 3 0
3 5 4 3 0
3 5 5 3 0
3 5 6 1 40
3 6 2 1 72
3 6 3 1 8
3 6 4 1 8
3 6 5 1 40
4 0 2 3 114
4 0 5 3 114
4 1 2 2 126
4 1 5 2 126
4 2 1 4 82
4 2 2 4 0
4 2 3 4 16
4 2 4 4 16
4 2 5 3 0
4 2 6 4 50
4 3 1 3 64
4 3 2 3 0
4 3 3 3 0
4 3 4 3 0
4 3 5 3 0
4 3 6 3 32
4 4 1 3 64
4 4 2 3 0
4 4 3 3 0
4 4 4 3 0
4 4 5 3 0
4 4 6 3 32
4 5 1 1 72
4 5 2 3 0
4 5 3 3 0
4 5 4 3 0
4 5 5 3 0
4 5 6 1 40
4 6 2 1 72
4 6 3 1 8
4 6 4 1 8
4 6 5 1 40
5 2 2 4 82
5 2 3 4 18
5 2 4 4 18
5 2 5 4 50
5 3 1 3 80
5 3 2 3 0
5 3 3 3 0
5 3 4 3 0
5 3 5 3 0
5 3 6 3 48
5 4 1 3 64
5 4 2 3 0
5 4 3 3 0
5 4 4 3 0
5 4 5 3 0
5 4 6 3 32
5 5 1 1 72
5 5 2 3 0
5 5 3 3 0
5 5 4 3 0
5 5 5 3 0
5 5 6 1 40
5 6 2 1 74
5 6 3 1 10
5 6 4 1 10
5 6 5 1 42
6 3 1 3 82
6 3 2 3 18
6 3 3 3 18
6 3 4 3 18
6 3 5 3 18
6 3 6 3 50
6 4 1 3 66
6 4 2 1 2
6 4 3 3 0
6 4 4 1 0
6 4 5 1 2
6 4 6 3 34
6 5 1 1 74
6 5 2 1 10
6 5 3 1 8
6 5 4 1 8
6 5 5 1 10
6 5 6 1 42
7 4 3 1 82
7 4 4 1 50
7 5 3 1 74
7 5 4 1 42
