Qubicle Exchange Format
Version 0.2
www.minddesk.com
8 8 8
5
0.000000 0.000000 0.000000
0.733333 0.733333 0.733333
0.988235 0.454902 0.705882
0.988235 0.780392 0.741176
1.000000 1.000000 1.000000
1 2 1 3 126
1 2 6 3 126
1 4 1 3 126
1 4 2 3 126
1 4 3 3 126
1 4 4 3 126
1 4 5 3 126
1 4 6 3 126
1 5 1 3 126
1 5 2 0 126
1 5 3 3 126
1 5 4 3 126
1 5 5 0 126
1 5 6 3 126
1 6 1 1 126
1 6 2 3 126
1 6 3 3 126
1 6 4 3 126
1 6 5 3 126
1 6 6 1 126
1 7 2 1 126
1 7 3 1 126
1 7 4 1 126
1 7 5 1 126
2 2 1 3 126
2 2 2 4 20
2 2 3 4 20
2 2 4 4 20
2 2 5 4 20
2 2 6 3 126
2 3 2 4 68
2 3 3 4 4
2 3 4 4 4
2 3 5 4 36
2 4 1 3 126
2 4 2 3 126
2 4 3 3 126
2 4 4 3 126
2 4 5 3 126
2 4 6 3 126
2 5 1 3 126
2 5 2 3 126
2 5 3 3 126
2 5 4 3 126
2 5 5 3 126
2 5 6 3 126
2 6 1 1 126
2 6 2 3 126
2 6 3 3 126
2 6 4 3 126
2 6 5 3 126
2 6 6 1 126
2 7 2 1 126
2 7 3 1 126
2 7 4 1 126
2 7 5 1 126
3 0 2 3 126
3 0 5 3 126
3 1 2 2 126
3 1 5 2 126
3 2 1 4 88
3 2 2 4 0
3 2 3 4 16
3 2 4 4 16
3 2 5 3 126
3 2 6 4 56
3 3 2 4 64
3 3 3 4 0
3 3 4 3 126
3 3 5 4 32
3 4 1 3 126
3 4 2 3 126
3 4 3 3 126
3 4 4 3 126
3 4 5 3 126
3 4 6 3 126
3 5 1 3 126
3 5 2 3 126
3 5 3 3 126
3 5 4 3 126
3 5 5 3 126
3 5 6 3 126
3 6 1 1 126
3 6 2 3 126
3 6 3 3 126
3 6 4 3 126
3 6 5 3 126
3 6 6 1 126
3 7 2 1 126
3 7 3 1 126
3 7 4 1 126
3 7 5 1 126
4 0 2 3 126
4 0 5 3 126
4 1 2 2 126
4 1 5 2 126
4 2 1 4 90
4 2 2 4 0
4 2 3 4 16
4 2 4 4 16
4 2 5 3 126
4 2 6 4 58
4 3 2 4 64
4 3 3 4 0
4 3 4 3 126
4 3 5 4 32
4 4 1 3 126
4 4 2 3 126
4 4 3 3 126
4 4 4 3 126
4 4 5 3 126
4 4 6 3 126
4 5 1 3 126
4 5 2 3 126
4 5 3 3 126
4 5 4 3 126
4 5 5 3 126
4 5 6 3 126
4 6 1 1 126
4 6 2 3 126
4 6 3 3 126
4 6 4 3 126
4 6 5 3 126
4 6 6 1 126
4 7 2 1 126
4 7 3 1 126
4 7 4 1 126
4 7 5 1 126
5 2 2 4 82
5 2 3 4 18
5 2 4 4 18
5 2 5 4 50
5 3 2 4 66
5 3 3 4 2
5 3 4 4 2
5 3 5 4 34
5 4 1 3 126
5 4 2 3 126
5 4 3 3 126
5 4 4 3 126
5 4 5 3 126
5 4 6 3 126
5 5 1 3 126
5 5 2 3 126
5 5 3 3 126
5 5 4 3 126
5 5 5 3 126
5 5 6 3 126
5 6 1 1 126
5 6 2 3 126
5 6 3 3 126
5 6 4 3 126
5 6 5 3 126
5 6 6 1 126
5 7 2 1 126
5 7 3 1 126
5 7 4 1 126
5 7 5 1 126
6 4 1 3 126
6 4 2 3 126
6 4 3 3 126
6 4 4 3 126
6 4 5 3 126
6 4 6 3 126
6 5 1 3 126
6 5 2 1 126
6 5 3 3 126
6 5 4 1 126
6 5 5 1 126
6 5 6 3 126
6 6 1 1 126
6 6 2 1 126
6 6 3 1 126
6 6 4 1 126
6 6 5 1 126
6 6 6 1 126
7 5 3 1 126
7 5 4 1 126
7 6 3 1 126
7 6 4 1 126
