Qubicle Exchange Format
Version 0.2
www.minddesk.com
32 16 16
4
0.250980 0.172549 0.000000
0.658824 0.894118 0.988235
0.941176 0.898039 0.235294
0.988235 0.894118 0.627451
0 8 0 0 92
0 8 1 0 30
0 8 2 0 30
0 8 3 0 30
0 8 4 0 30
0 8 5 0 30
0 8 6 0 30
0 8 7 0 30
0 8 8 0 30
0 8 9 0 30
0 8 10 0 30
0 8 11 0 30
0 8 12 0 30
0 8 13 0 30
0 8 14 0 30
0 8 15 0 60
1 0 1 3 84
1 0 2 3 20
1 0 3 3 20
1 0 4 3 20
1 0 5 3 20
1 0 6 3 20
1 0 7 3 20
1 0 8 3 20
1 0 9 3 20
1 0 10 3 20
1 0 11 3 20
1 0 12 3 20
1 0 13 3 20
1 0 14 3 52
1 1 1 3 68
1 1 2 3 6
1 1 3 3 6
1 1 4 3 6
1 1 5 3 6
1 1 6 3 6
1 1 7 3 6
1 1 8 3 6
1 1 9 3 6
1 1 10 3 6
1 1 11 3 6
1 1 12 3 6
1 1 13 3 6
1 1 14 3 36
1 2 1 3 68
1 2 2 3 6
1 2 3 3 6
1 2 4 3 6
1 2 5 3 6
1 2 6 3 6
1 2 7 3 6
1 2 8 3 6
1 2 9 3 6
1 2 10 3 6
1 2 11 3 6
1 2 12 3 6
1 2 13 3 6
1 2 14 3 36
1 3 1 3 68
1 3 2 3 6
1 3 3 3 6
1 3 4 3 6
1 3 5 3 6
1 3 6 3 6
1 3 7 3 6
1 3 8 3 6
1 3 9 3 6
1 3 10 3 6
1 3 11 3 6
1 3 12 3 6
1 3 13 3 6
1 3 14 3 36
1 4 1 3 68
1 4 2 3 6
1 4 3 3 6
1 4 4 3 6
1 4 5 3 6
1 4 6 3 6
1 4 7 3 6
1 4 8 3 6
1 4 9 3 6
1 4 10 3 6
1 4 11 3 6
1 4 12 3 6
1 4 13 3 6
1 4 14 3 36
1 5 1 3 68
1 5 2 3 6
1 5 3 3 6
1 5 4 3 6
1 5 5 3 6
1 5 6 3 6
1 5 7 3 6
1 5 8 3 6
1 5 9 3 6
1 5 10 3 6
1 5 11 3 6
1 5 12 3 6
1 5 13 3 6
1 5 14 3 36
1 6 1 3 68
1 6 2 3 6
1 6 3 3 6
1 6 4 3 6
1 6 5 3 6
1 6 6 3 6
1 6 7 3 6
1 6 8 3 6
1 6 9 3 6
1 6 10 3 6
1 6 11 3 6
1 6 12 3 6
1 6 13 3 6
1 6 14 3 36
1 7 1 3 76
1 7 2 3 14
1 7 3 3 14
1 7 4 3 14
1 7 5 3 14
1 7 6 3 14
1 7 7 3 14
1 7 8 3 14
1 7 9 3 14
1 7 10 3 14
1 7 11 3 14
1 7 12 3 14
1 7 13 3 14
1 7 14 3 44
1 8 0 0 112
1 8 15 0 120
1 9 0 0 76
1 9 1 0 30
1 9 2 0 30
1 9 3 0 30
1 9 4 0 30
1 9 5 0 30
1 9 6 0 30
1 9 7 0 30
1 9 8 0 30
1 9 9 0 30
1 9 10 0 30
1 9 11 0 30
1 9 12 0 30
1 9 13 0 30
1 9 14 0 60
2 0 1 3 80
2 0 2 3 24
2 0 3 3 24
2 0 4 3 24
2 0 5 3 24
2 0 6 3 24
2 0 7 3 24
2 0 8 3 24
2 0 9 3 24
2 0 10 3 24
2 0 11 3 24
2 0 12 3 24
2 0 13 3 24
2 0 14 3 48
2 1 1 3 98
2 1 14 3 96
2 2 1 3 98
2 2 14 3 96
2 3 1 3 98
2 3 14 3 96
2 4 1 3 98
2 4 14 3 96
2 5 1 3 98
2 5 14 3 96
2 6 1 3 96
2 6 14 3 96
2 7 1 3 104
2 7 14 3 104
2 8 0 0 114
2 8 15 0 120
2 9 0 0 96
2 9 14 0 120
2 10 0 0 76
2 10 1 0 30
2 10 2 0 30
2 10 3 0 30
2 10 4 0 30
2 10 5 0 30
2 10 6 0 30
2 10 7 0 30
2 10 8 0 30
2 10 9 0 30
2 10 10 0 30
2 10 11 0 30
2 10 12 0 30
2 10 13 0 60
3 0 1 3 88
3 0 2 3 24
3 0 3 3 24
3 0 4 3 24
3 0 5 3 24
3 0 6 3 24
3 0 7 3 24
3 0 8 3 24
3 0 9 3 24
3 0 10 3 24
3 0 11 3 24
3 0 12 3 24
3 0 13 3 24
3 0 14 3 48
3 1 0 0 116
3 1 14 3 96
3 2 0 0 102
3 2 14 3 96
3 3 0 0 100
3 3 14 3 96
3 4 0 0 102
3 4 14 3 96
3 5 0 0 108
3 5 14 3 96
3 6 1 3 112
3 6 14 3 96
3 7 1 3 96
3 7 14 3 104
3 8 1 3 108
3 8 15 0 120
3 9 0 0 114
3 9 14 0 120
3 10 0 0 96
3 10 13 0 120
3 11 0 0 76
3 11 1 0 30
3 11 2 0 30
3 11 3 0 30
3 11 4 0 30
3 11 5 0 30
3 11 6 0 30
3 11 7 0 30
3 11 8 0 30
3 11 9 0 30
3 11 10 0 30
3 11 11 0 30
3 11 12 0 60
4 0 1 3 88
4 0 2 3 24
4 0 3 3 24
4 0 4 3 24
4 0 5 3 24
4 0 6 3 24
4 0 7 3 24
4 0 8 3 24
4 0 9 3 24
4 0 10 3 24
4 0 11 3 24
4 0 12 3 24
4 0 13 3 24
4 0 14 3 48
4 1 0 0 120
4 1 14 3 96
4 2 1 1 126
4 2 14 3 96
4 3 0 0 120
4 3 14 3 96
4 4 1 1 126
4 4 14 3 96
4 5 0 0 120
4 5 14 3 96
4 6 1 3 112
4 6 14 3 96
4 7 1 3 96
4 7 14 3 104
4 8 1 3 96
4 8 15 0 120
4 9 1 3 108
4 9 14 0 120
4 10 0 0 114
4 10 13 0 120
4 11 0 0 96
4 11 12 0 120
4 12 0 0 76
4 12 1 0 30
4 12 2 0 30
4 12 3 0 30
4 12 4 0 30
4 12 5 0 30
4 12 6 0 30
4 12 7 0 30
4 12 8 0 30
4 12 9 0 30
4 12 10 0 30
4 12 11 0 60
5 0 1 3 88
5 0 2 3 24
5 0 3 3 24
5 0 4 3 24
5 0 5 3 24
5 0 6 3 24
5 0 7 3 24
5 0 8 3 24
5 0 9 3 24
5 0 10 3 24
5 0 11 3 24
5 0 12 3 24
5 0 13 3 24
5 0 14 3 48
5 1 0 0 112
5 1 14 3 96
5 2 0 0 102
5 2 14 3 96
5 3 0 0 96
5 3 14 3 96
5 4 0 0 102
5 4 14 3 96
5 5 0 0 104
5 5 14 3 96
5 6 1 3 112
5 6 14 3 96
5 7 1 3 96
5 7 14 3 104
5 8 1 3 96
5 8 15 0 120
5 9 1 3 96
5 9 14 0 120
5 10 1 3 108
5 10 13 0 120
5 11 0 0 114
5 11 12 0 120
5 12 0 0 96
5 12 11 0 120
5 13 0 0 76
5 13 1 0 28
5 13 2 0 28
5 13 3 0 28
5 13 4 0 28
5 13 5 0 28
5 13 6 0 28
5 13 7 0 28
5 13 8 0 28
5 13 9 0 28
5 13 10 0 60
6 0 1 3 88
6 0 2 3 24
6 0 3 3 24
6 0 4 3 24
6 0 5 3 24
6 0 6 3 24
6 0 7 3 24
6 0 8 3 24
6 0 9 3 24
6 0 10 3 24
6 0 11 3 24
6 0 12 3 24
6 0 13 3 24
6 0 14 3 48
6 1 0 0 120
6 1 14 3 96
6 2 1 1 126
6 2 14 3 96
6 3 0 0 120
6 3 14 3 96
6 4 1 1 126
6 4 14 3 96
6 5 0 0 120
6 5 14 3 96
6 6 1 3 112
6 6 14 3 96
6 7 1 3 96
6 7 14 3 104
6 8 1 3 96
6 8 15 0 120
6 9 1 3 96
6 9 14 0 120
6 10 1 3 96
6 10 13 0 120
6 11 1 3 108
6 11 12 0 120
6 12 0 0 112
6 12 11 0 120
6 13 0 0 72
6 13 1 0 24
6 13 2 0 24
6 13 3 0 24
6 13 4 0 24
6 13 5 0 24
6 13 6 0 24
6 13 7 0 24
6 13 8 0 24
6 13 9 0 24
6 13 10 0 56
7 0 1 3 88
7 0 2 3 24
7 0 3 3 24
7 0 4 3 24
7 0 5 3 24
7 0 6 3 24
7 0 7 3 24
7 0 8 3 24
7 0 9 3 24
7 0 10 3 24
7 0 11 3 24
7 0 12 3 24
7 0 13 3 24
7 0 14 3 48
7 1 0 0 114
7 1 14 3 96
7 2 0 0 102
7 2 14 3 96
7 3 0 0 98
7 3 14 3 96
7 4 0 0 102
7 4 14 3 96
7 5 0 0 106
7 5 14 3 96
7 6 1 3 112
7 6 14 3 96
7 7 1 3 96
7 7 14 3 104
7 8 1 3 96
7 8 15 0 120
7 9 1 3 96
7 9 14 0 120
7 10 1 3 96
7 10 13 0 120
7 11 1 3 104
7 11 12 0 120
7 12 0 0 112
7 12 11 0 120
7 13 0 0 72
7 13 1 0 24
7 13 2 0 24
7 13 3 0 24
7 13 4 0 24
7 13 5 0 24
7 13 6 0 24
7 13 7 0 24
7 13 8 0 24
7 13 9 0 24
7 13 10 0 56
8 0 1 3 80
8 0 2 3 24
8 0 3 3 24
8 0 4 3 24
8 0 5 3 24
8 0 6 3 24
8 0 7 3 24
8 0 8 3 24
8 0 9 3 24
8 0 10 3 24
8 0 11 3 24
8 0 12 3 24
8 0 13 3 24
8 0 14 3 48
8 1 1 3 100
8 1 14 3 96
8 2 1 3 100
8 2 14 3 96
8 3 1 3 100
8 3 14 3 96
8 4 1 3 100
8 4 14 3 96
8 5 1 3 100
8 5 14 3 96
8 6 1 3 96
8 6 14 3 96
8 7 1 3 96
8 7 14 3 104
8 8 1 3 96
8 8 15 0 120
8 9 1 3 96
8 9 14 0 120
8 10 1 3 96
8 10 13 0 120
8 11 1 3 104
8 11 12 0 120
8 12 0 0 112
8 12 11 0 120
8 13 0 0 72
8 13 1 0 24
8 13 2 0 24
8 13 3 0 24
8 13 4 0 24
8 13 5 0 24
8 13 6 0 24
8 13 7 0 24
8 13 8 0 24
8 13 9 0 24
8 13 10 0 56
9 0 1 3 80
9 0 2 3 24
9 0 3 3 24
9 0 4 3 24
9 0 5 3 24
9 0 6 3 24
9 0 7 3 24
9 0 8 3 24
9 0 9 3 24
9 0 10 3 24
9 0 11 3 24
9 0 12 3 24
9 0 13 3 24
9 0 14 3 48
9 1 1 3 96
9 1 14 3 96
9 2 1 3 96
9 2 14 3 96
9 3 1 3 96
9 3 14 3 96
9 4 1 3 96
9 4 14 3 96
9 5 1 3 96
9 5 14 3 96
9 6 1 3 96
9 6 14 3 96
9 7 1 3 96
9 7 14 3 104
9 8 1 3 96
9 8 15 0 120
9 9 1 3 96
9 9 14 0 120
9 10 1 3 96
9 10 13 0 120
9 11 1 3 104
9 11 12 0 120
9 12 0 0 112
9 12 11 0 120
9 13 0 0 72
9 13 1 0 24
9 13 2 0 24
9 13 3 0 24
9 13 4 0 24
9 13 5 0 24
9 13 6 0 24
9 13 7 0 24
9 13 8 0 24
9 13 9 0 24
9 13 10 0 56
10 0 1 3 80
10 0 2 3 24
10 0 3 3 24
10 0 4 3 24
10 0 5 3 24
10 0 6 3 24
10 0 7 3 24
10 0 8 3 24
10 0 9 3 24
10 0 10 3 24
10 0 11 3 24
10 0 12 3 24
10 0 13 3 24
10 0 14 3 48
10 1 1 3 96
10 1 14 3 96
10 2 1 3 96
10 2 14 3 96
10 3 1 3 96
10 3 14 3 96
10 4 1 3 96
10 4 14 3 96
10 5 1 3 96
10 5 14 3 96
10 6 1 3 96
10 6 14 3 96
10 7 1 3 96
10 7 14 3 104
10 8 1 3 96
10 8 15 0 120
10 9 1 3 96
10 9 14 0 120
10 10 1 3 96
10 10 13 0 120
10 11 1 3 104
10 11 12 0 120
10 12 0 0 112
10 12 11 0 120
10 13 0 0 72
10 13 1 0 24
10 13 2 0 24
10 13 3 0 24
10 13 4 0 24
10 13 5 0 24
10 13 6 0 24
10 13 7 0 24
10 13 8 0 24
10 13 9 0 24
10 13 10 0 56
11 0 1 3 80
11 0 2 3 24
11 0 3 3 24
11 0 4 3 24
11 0 5 3 24
11 0 6 3 24
11 0 7 3 24
11 0 8 3 24
11 0 9 3 24
11 0 10 3 24
11 0 11 3 24
11 0 12 3 24
11 0 13 3 24
11 0 14 3 48
11 1 1 3 96
11 1 14 3 96
11 2 1 3 96
11 2 14 3 96
11 3 1 3 96
11 3 14 3 96
11 4 1 3 96
11 4 14 3 96
11 5 1 3 96
11 5 14 3 96
11 6 1 3 96
11 6 14 3 96
11 7 1 3 96
11 7 14 3 104
11 8 1 3 96
11 8 15 0 120
11 9 1 3 96
11 9 14 0 120
11 10 1 3 96
11 10 13 0 120
11 11 1 3 104
11 11 12 0 120
11 12 0 0 112
11 12 11 0 120
11 13 0 0 72
11 13 1 0 24
11 13 2 0 24
11 13 3 0 24
11 13 4 0 24
11 13 5 0 24
11 13 6 0 24
11 13 7 0 24
11 13 8 0 24
11 13 9 0 24
11 13 10 0 56
12 0 1 3 80
12 0 2 3 24
12 0 3 3 24
12 0 4 3 24
12 0 5 3 24
12 0 6 3 24
12 0 7 3 24
12 0 8 3 24
12 0 9 3 24
12 0 10 3 24
12 0 11 3 24
12 0 12 3 24
12 0 13 3 24
12 0 14 3 48
12 1 1 3 96
12 1 14 3 96
12 2 1 3 96
12 2 14 3 96
12 3 1 3 96
12 3 14 3 96
12 4 1 3 96
12 4 14 3 96
12 5 1 3 96
12 5 14 3 96
12 6 1 3 96
12 6 14 3 96
12 7 1 3 96
12 7 14 3 104
12 8 1 3 96
12 8 15 0 120
12 9 1 3 96
12 9 14 0 120
12 10 1 3 96
12 10 13 0 120
12 11 1 3 104
12 11 12 0 120
12 12 0 0 112
12 12 11 0 120
12 13 0 0 72
12 13 1 0 24
12 13 2 0 24
12 13 3 0 24
12 13 4 0 24
12 13 5 0 24
12 13 6 0 24
12 13 7 0 24
12 13 8 0 24
12 13 9 0 24
12 13 10 0 56
13 0 1 3 80
13 0 2 3 24
13 0 3 3 24
13 0 4 3 24
13 0 5 3 24
13 0 6 3 24
13 0 7 3 24
13 0 8 3 24
13 0 9 3 24
13 0 10 3 24
13 0 11 3 24
13 0 12 3 24
13 0 13 3 24
13 0 14 3 48
13 1 1 3 98
13 1 14 3 96
13 2 1 3 98
13 2 14 3 96
13 3 1 3 98
13 3 14 3 96
13 4 1 3 98
13 4 14 3 96
13 5 1 3 98
13 5 14 3 96
13 6 1 3 98
13 6 14 3 96
13 7 1 3 98
13 7 14 3 104
13 8 1 3 96
13 8 15 0 120
13 9 1 3 96
13 9 14 0 120
13 10 1 3 96
13 10 13 0 120
13 11 1 3 104
13 11 12 0 120
13 12 0 0 112
13 12 11 0 120
13 13 0 0 72
13 13 1 0 24
13 13 2 0 24
13 13 3 0 24
13 13 4 0 24
13 13 5 0 24
13 13 6 0 24
13 13 7 0 24
13 13 8 0 24
13 13 9 0 24
13 13 10 0 56
14 0 0 0 84
14 0 1 3 24
14 0 2 3 24
14 0 3 3 24
14 0 4 3 24
14 0 5 3 24
14 0 6 3 24
14 0 7 3 24
14 0 8 3 24
14 0 9 3 24
14 0 10 3 24
14 0 11 3 24
14 0 12 3 24
14 0 13 3 24
14 0 14 3 48
14 1 0 0 100
14 1 14 3 96
14 2 0 0 100
14 2 14 3 96
14 3 0 0 100
14 3 14 3 96
14 4 0 0 100
14 4 14 3 96
14 5 0 0 100
14 5 14 3 96
14 6 0 0 100
14 6 14 3 96
14 7 0 0 108
14 7 14 3 104
14 8 1 3 112
14 8 15 0 120
14 9 1 3 96
14 9 14 0 120
14 10 1 3 96
14 10 13 0 120
14 11 1 3 104
14 11 12 0 120
14 12 0 0 112
14 12 11 0 120
14 13 0 0 72
14 13 1 0 24
14 13 2 0 24
14 13 3 0 24
14 13 4 0 24
14 13 5 0 24
14 13 6 0 24
14 13 7 0 24
14 13 8 0 24
14 13 9 0 24
14 13 10 0 56
15 0 0 0 80
15 0 1 3 24
15 0 2 3 24
15 0 3 3 24
15 0 4 3 24
15 0 5 3 24
15 0 6 3 24
15 0 7 3 24
15 0 8 3 24
15 0 9 3 24
15 0 10 3 24
15 0 11 3 24
15 0 12 3 24
15 0 13 3 24
15 0 14 3 48
15 1 0 0 96
15 1 14 3 96
15 2 0 0 96
15 2 14 3 96
15 3 0 0 96
15 3 14 3 96
15 4 0 0 96
15 4 14 3 96
15 5 0 0 96
15 5 14 3 96
15 6 0 0 96
15 6 14 3 96
15 7 0 0 104
15 7 14 3 104
15 8 1 3 112
15 8 15 0 120
15 9 1 3 96
15 9 14 0 120
15 10 1 3 96
15 10 13 0 120
15 11 1 3 104
15 11 12 0 120
15 12 0 0 112
15 12 11 0 120
15 13 0 0 72
15 13 1 0 24
15 13 2 0 24
15 13 3 0 24
15 13 4 0 24
15 13 5 0 24
15 13 6 0 24
15 13 7 0 24
15 13 8 0 24
15 13 9 0 24
15 13 10 0 56
16 0 0 0 80
16 0 1 3 24
16 0 2 3 24
16 0 3 3 24
16 0 4 3 24
16 0 5 3 24
16 0 6 3 24
16 0 7 3 24
16 0 8 3 24
16 0 9 3 24
16 0 10 3 24
16 0 11 3 24
16 0 12 3 24
16 0 13 3 24
16 0 14 3 48
16 1 0 0 96
16 1 14 3 96
16 2 0 0 96
16 2 14 3 96
16 3 0 0 96
16 3 14 3 96
16 4 0 0 96
16 4 14 3 96
16 5 0 0 96
16 5 14 3 96
16 6 0 0 96
16 6 14 3 96
16 7 0 0 104
16 7 14 3 104
16 8 1 3 112
16 8 15 0 120
16 9 1 3 96
16 9 14 0 120
16 10 1 3 96
16 10 13 0 120
16 11 1 3 104
16 11 12 0 120
16 12 0 0 112
16 12 11 0 120
16 13 0 0 72
16 13 1 0 24
16 13 2 0 24
16 13 3 0 24
16 13 4 0 24
16 13 5 0 24
16 13 6 0 24
16 13 7 0 24
16 13 8 0 24
16 13 9 0 24
16 13 10 0 56
17 0 0 0 82
17 0 1 3 24
17 0 2 3 24
17 0 3 3 24
17 0 4 3 24
17 0 5 3 24
17 0 6 3 24
17 0 7 3 24
17 0 8 3 24
17 0 9 3 24
17 0 10 3 24
17 0 11 3 24
17 0 12 3 24
17 0 13 3 24
17 0 14 3 48
17 1 0 0 98
17 1 14 3 96
17 2 0 0 98
17 2 14 3 96
17 3 0 2 98
17 3 14 3 96
17 4 0 0 98
17 4 14 3 96
17 5 0 0 98
17 5 14 3 96
17 6 0 0 98
17 6 14 3 96
17 7 0 0 106
17 7 14 3 104
17 8 1 3 112
17 8 15 0 120
17 9 1 3 96
17 9 14 0 120
17 10 1 3 96
17 10 13 0 120
17 11 1 3 104
17 11 12 0 120
17 12 0 0 112
17 12 11 0 120
17 13 0 0 72
17 13 1 0 24
17 13 2 0 24
17 13 3 0 24
17 13 4 0 24
17 13 5 0 24
17 13 6 0 24
17 13 7 0 24
17 13 8 0 24
17 13 9 0 24
17 13 10 0 56
18 0 1 3 80
18 0 2 3 24
18 0 3 3 24
18 0 4 3 24
18 0 5 3 24
18 0 6 3 24
18 0 7 3 24
18 0 8 3 24
18 0 9 3 24
18 0 10 3 24
18 0 11 3 24
18 0 12 3 24
18 0 13 3 24
18 0 14 3 48
18 1 1 3 100
18 1 14 3 96
18 2 1 3 100
18 2 14 3 96
18 3 1 3 100
18 3 14 3 96
18 4 1 3 100
18 4 14 3 96
18 5 1 3 100
18 5 14 3 96
18 6 1 3 100
18 6 14 3 96
18 7 1 3 100
18 7 14 3 104
18 8 1 3 96
18 8 15 0 120
18 9 1 3 96
18 9 14 0 120
18 10 1 3 96
18 10 13 0 120
18 11 1 3 104
18 11 12 0 120
18 12 0 0 112
18 12 11 0 120
18 13 0 0 72
18 13 1 0 24
18 13 2 0 24
18 13 3 0 24
18 13 4 0 24
18 13 5 0 24
18 13 6 0 24
18 13 7 0 24
18 13 8 0 24
18 13 9 0 24
18 13 10 0 56
19 0 1 3 80
19 0 2 3 24
19 0 3 3 24
19 0 4 3 24
19 0 5 3 24
19 0 6 3 24
19 0 7 3 24
19 0 8 3 24
19 0 9 3 24
19 0 10 3 24
19 0 11 3 24
19 0 12 3 24
19 0 13 3 24
19 0 14 3 48
19 1 1 3 96
19 1 14 3 96
19 2 1 3 96
19 2 14 3 96
19 3 1 3 96
19 3 14 3 96
19 4 1 3 96
19 4 14 3 96
19 5 1 3 96
19 5 14 3 96
19 6 1 3 96
19 6 14 3 96
19 7 1 3 96
19 7 14 3 104
19 8 1 3 96
19 8 15 0 120
19 9 1 3 96
19 9 14 0 120
19 10 1 3 96
19 10 13 0 120
19 11 1 3 104
19 11 12 0 120
19 12 0 0 112
19 12 11 0 120
19 13 0 0 72
19 13 1 0 24
19 13 2 0 24
19 13 3 0 24
19 13 4 0 24
19 13 5 0 24
19 13 6 0 24
19 13 7 0 24
19 13 8 0 24
19 13 9 0 24
19 13 10 0 56
20 0 1 3 80
20 0 2 3 24
20 0 3 3 24
20 0 4 3 24
20 0 5 3 24
20 0 6 3 24
20 0 7 3 24
20 0 8 3 24
20 0 9 3 24
20 0 10 3 24
20 0 11 3 24
20 0 12 3 24
20 0 13 3 24
20 0 14 3 48
20 1 1 3 96
20 1 14 3 96
20 2 1 3 96
20 2 14 3 96
20 3 1 3 96
20 3 14 3 96
20 4 1 3 96
20 4 14 3 96
20 5 1 3 96
20 5 14 3 96
20 6 1 3 96
20 6 14 3 96
20 7 1 3 96
20 7 14 3 104
20 8 1 3 96
20 8 15 0 120
20 9 1 3 96
20 9 14 0 120
20 10 1 3 96
20 10 13 0 120
20 11 1 3 104
20 11 12 0 120
20 12 0 0 112
20 12 11 0 120
20 13 0 0 72
20 13 1 0 24
20 13 2 0 24
20 13 3 0 24
20 13 4 0 24
20 13 5 0 24
20 13 6 0 24
20 13 7 0 24
20 13 8 0 24
20 13 9 0 24
20 13 10 0 56
21 0 1 3 80
21 0 2 3 24
21 0 3 3 24
21 0 4 3 24
21 0 5 3 24
21 0 6 3 24
21 0 7 3 24
21 0 8 3 24
21 0 9 3 24
21 0 10 3 24
21 0 11 3 24
21 0 12 3 24
21 0 13 3 24
21 0 14 3 48
21 1 1 3 96
21 1 14 3 96
21 2 1 3 96
21 2 14 3 96
21 3 1 3 96
21 3 14 3 96
21 4 1 3 96
21 4 14 3 96
21 5 1 3 96
21 5 14 3 96
21 6 1 3 96
21 6 14 3 96
21 7 1 3 96
21 7 14 3 104
21 8 1 3 96
21 8 15 0 120
21 9 1 3 96
21 9 14 0 120
21 10 1 3 96
21 10 13 0 120
21 11 1 3 104
21 11 12 0 120
21 12 0 0 112
21 12 11 0 120
21 13 0 0 72
21 13 1 0 24
21 13 2 0 24
21 13 3 0 24
21 13 4 0 24
21 13 5 0 24
21 13 6 0 24
21 13 7 0 24
21 13 8 0 24
21 13 9 0 24
21 13 10 0 56
22 0 1 3 80
22 0 2 3 24
22 0 3 3 24
22 0 4 3 24
22 0 5 3 24
22 0 6 3 24
22 0 7 3 24
22 0 8 3 24
22 0 9 3 24
22 0 10 3 24
22 0 11 3 24
22 0 12 3 24
22 0 13 3 24
22 0 14 3 48
22 1 1 3 96
22 1 14 3 96
22 2 1 3 96
22 2 14 3 96
22 3 1 3 96
22 3 14 3 96
22 4 1 3 96
22 4 14 3 96
22 5 1 3 96
22 5 14 3 96
22 6 1 3 96
22 6 14 3 96
22 7 1 3 96
22 7 14 3 104
22 8 1 3 96
22 8 15 0 120
22 9 1 3 96
22 9 14 0 120
22 10 1 3 96
22 10 13 0 120
22 11 1 3 104
22 11 12 0 120
22 12 0 0 112
22 12 11 0 120
22 13 0 0 72
22 13 1 0 24
22 13 2 0 24
22 13 3 0 24
22 13 4 0 24
22 13 5 0 24
22 13 6 0 24
22 13 7 0 24
22 13 8 0 24
22 13 9 0 24
22 13 10 0 56
23 0 1 3 80
23 0 2 3 24
23 0 3 3 24
23 0 4 3 24
23 0 5 3 24
23 0 6 3 24
23 0 7 3 24
23 0 8 3 24
23 0 9 3 24
23 0 10 3 24
23 0 11 3 24
23 0 12 3 24
23 0 13 3 24
23 0 14 3 48
23 1 1 3 98
23 1 14 3 96
23 2 1 3 98
23 2 14 3 96
23 3 1 3 98
23 3 14 3 96
23 4 1 3 98
23 4 14 3 96
23 5 1 3 98
23 5 14 3 96
23 6 1 3 96
23 6 14 3 96
23 7 1 3 96
23 7 14 3 104
23 8 1 3 96
23 8 15 0 120
23 9 1 3 96
23 9 14 0 120
23 10 1 3 96
23 10 13 0 120
23 11 1 3 104
23 11 12 0 120
23 12 0 0 112
23 12 11 0 120
23 13 0 0 72
23 13 1 0 24
23 13 2 0 24
23 13 3 0 24
23 13 4 0 24
23 13 5 0 24
23 13 6 0 24
23 13 7 0 24
23 13 8 0 24
23 13 9 0 24
23 13 10 0 56
24 0 1 3 88
24 0 2 3 24
24 0 3 3 24
24 0 4 3 24
24 0 5 3 24
24 0 6 3 24
24 0 7 3 24
24 0 8 3 24
24 0 9 3 24
24 0 10 3 24
24 0 11 3 24
24 0 12 3 24
24 0 13 3 24
24 0 14 3 48
24 1 0 0 116
24 1 14 3 96
24 2 0 0 102
24 2 14 3 96
24 3 0 0 100
24 3 14 3 96
24 4 0 0 102
24 4 14 3 96
24 5 0 0 108
24 5 14 3 96
24 6 1 3 112
24 6 14 3 96
24 7 1 3 96
24 7 14 3 104
24 8 1 3 96
24 8 15 0 120
24 9 1 3 96
24 9 14 0 120
24 10 1 3 96
24 10 13 0 120
24 11 1 3 104
24 11 12 0 120
24 12 0 0 112
24 12 11 0 120
24 13 0 0 72
24 13 1 0 24
24 13 2 0 24
24 13 3 0 24
24 13 4 0 24
24 13 5 0 24
24 13 6 0 24
24 13 7 0 24
24 13 8 0 24
24 13 9 0 24
24 13 10 0 56
25 0 1 3 88
25 0 2 3 24
25 0 3 3 24
25 0 4 3 24
25 0 5 3 24
25 0 6 3 24
25 0 7 3 24
25 0 8 3 24
25 0 9 3 24
25 0 10 3 24
25 0 11 3 24
25 0 12 3 24
25 0 13 3 24
25 0 14 3 48
25 1 0 0 120
25 1 14 3 96
25 2 1 1 126
25 2 14 3 96
25 3 0 0 120
25 3 14 3 96
25 4 1 1 126
25 4 14 3 96
25 5 0 0 120
25 5 14 3 96
25 6 1 3 112
25 6 14 3 96
25 7 1 3 96
25 7 14 3 104
25 8 1 3 96
25 8 15 0 120
25 9 1 3 96
25 9 14 0 120
25 10 1 3 96
25 10 13 0 120
25 11 1 3 106
25 11 12 0 120
25 12 0 0 112
25 12 11 0 120
25 13 0 0 72
25 13 1 0 24
25 13 2 0 24
25 13 3 0 24
25 13 4 0 24
25 13 5 0 24
25 13 6 0 24
25 13 7 0 24
25 13 8 0 24
25 13 9 0 24
25 13 10 0 56
26 0 1 3 88
26 0 2 3 24
26 0 3 3 24
26 0 4 3 24
26 0 5 3 24
26 0 6 3 24
26 0 7 3 24
26 0 8 3 24
26 0 9 3 24
26 0 10 3 24
26 0 11 3 24
26 0 12 3 24
26 0 13 3 24
26 0 14 3 48
26 1 0 0 112
26 1 14 3 96
26 2 0 0 102
26 2 14 3 96
26 3 0 0 96
26 3 14 3 96
26 4 0 0 102
26 4 14 3 96
26 5 0 0 104
26 5 14 3 96
26 6 1 3 112
26 6 14 3 96
26 7 1 3 96
26 7 14 3 104
26 8 1 3 96
26 8 15 0 120
26 9 1 3 96
26 9 14 0 120
26 10 1 3 106
26 10 13 0 120
26 11 0 0 116
26 11 12 0 120
26 12 0 0 96
26 12 11 0 120
26 13 0 0 74
26 13 1 0 26
26 13 2 0 26
26 13 3 0 26
26 13 4 0 26
26 13 5 0 26
26 13 6 0 26
26 13 7 0 26
26 13 8 0 26
26 13 9 0 26
26 13 10 0 58
27 0 1 3 88
27 0 2 3 24
27 0 3 3 24
27 0 4 3 24
27 0 5 3 24
27 0 6 3 24
27 0 7 3 24
27 0 8 3 24
27 0 9 3 24
27 0 10 3 24
27 0 11 3 24
27 0 12 3 24
27 0 13 3 24
27 0 14 3 48
27 1 0 0 120
27 1 14 3 96
27 2 1 1 126
27 2 14 3 96
27 3 0 0 120
27 3 14 3 96
27 4 1 1 126
27 4 14 3 96
27 5 0 0 120
27 5 14 3 96
27 6 1 3 112
27 6 14 3 96
27 7 1 3 96
27 7 14 3 104
27 8 1 3 96
27 8 15 0 120
27 9 1 3 106
27 9 14 0 120
27 10 0 0 116
27 10 13 0 120
27 11 0 0 96
27 11 12 0 120
27 12 0 0 74
27 12 1 0 30
27 12 2 0 30
27 12 3 0 30
27 12 4 0 30
27 12 5 0 30
27 12 6 0 30
27 12 7 0 30
27 12 8 0 30
27 12 9 0 30
27 12 10 0 30
27 12 11 0 58
28 0 1 3 88
28 0 2 3 24
28 0 3 3 24
28 0 4 3 24
28 0 5 3 24
28 0 6 3 24
28 0 7 3 24
28 0 8 3 24
28 0 9 3 24
28 0 10 3 24
28 0 11 3 24
28 0 12 3 24
28 0 13 3 24
28 0 14 3 48
28 1 0 0 114
28 1 14 3 96
28 2 0 0 102
28 2 14 3 96
28 3 0 0 98
28 3 14 3 96
28 4 0 0 102
28 4 14 3 96
28 5 0 0 106
28 5 14 3 96
28 6 1 3 112
28 6 14 3 96
28 7 1 3 96
28 7 14 3 104
28 8 1 3 106
28 8 15 0 120
28 9 0 0 116
28 9 14 0 120
28 10 0 0 96
28 10 13 0 120
28 11 0 0 74
28 11 1 0 30
28 11 2 0 30
28 11 3 0 30
28 11 4 0 30
28 11 5 0 30
28 11 6 0 30
28 11 7 0 30
28 11 8 0 30
28 11 9 0 30
28 11 10 0 30
28 11 11 0 30
28 11 12 0 58
29 0 1 3 80
29 0 2 3 24
29 0 3 3 24
29 0 4 3 24
29 0 5 3 24
29 0 6 3 24
29 0 7 3 24
29 0 8 3 24
29 0 9 3 24
29 0 10 3 24
29 0 11 3 24
29 0 12 3 24
29 0 13 3 24
29 0 14 3 48
29 1 1 3 100
29 1 14 3 96
29 2 1 3 100
29 2 14 3 96
29 3 1 3 100
29 3 14 3 96
29 4 1 3 100
29 4 14 3 96
29 5 1 3 100
29 5 14 3 96
29 6 1 3 96
29 6 14 3 96
29 7 1 3 104
29 7 14 3 104
29 8 0 0 116
29 8 15 0 120
29 9 0 0 96
29 9 14 0 120
29 10 0 0 74
29 10 1 0 30
29 10 2 0 30
29 10 3 0 30
29 10 4 0 30
29 10 5 0 30
29 10 6 0 30
29 10 7 0 30
29 10 8 0 30
29 10 9 0 30
29 10 10 0 30
29 10 11 0 30
29 10 12 0 30
29 10 13 0 58
30 0 1 3 82
30 0 2 3 18
30 0 3 3 18
30 0 4 3 18
30 0 5 3 18
30 0 6 3 18
30 0 7 3 18
30 0 8 3 18
30 0 9 3 18
30 0 10 3 18
30 0 11 3 18
30 0 12 3 18
30 0 13 3 18
30 0 14 3 50
30 1 1 3 66
30 1 2 3 6
30 1 3 3 6
30 1 4 3 6
30 1 5 3 6
30 1 6 3 6
30 1 7 3 6
30 1 8 3 6
30 1 9 3 6
30 1 10 3 6
30 1 11 3 6
30 1 12 3 6
30 1 13 3 6
30 1 14 3 34
30 2 1 3 66
30 2 2 3 6
30 2 3 3 6
30 2 4 3 6
30 2 5 3 6
30 2 6 3 6
30 2 7 3 6
30 2 8 3 6
30 2 9 3 6
30 2 10 3 6
30 2 11 3 6
30 2 12 3 6
30 2 13 3 6
30 2 14 3 34
30 3 1 3 66
30 3 2 3 6
30 3 3 3 6
30 3 4 3 6
30 3 5 3 6
30 3 6 3 6
30 3 7 3 6
30 3 8 3 6
30 3 9 3 6
30 3 10 3 6
30 3 11 3 6
30 3 12 3 6
30 3 13 3 6
30 3 14 3 34
30 4 1 3 66
30 4 2 3 6
30 4 3 3 6
30 4 4 3 6
30 4 5 3 6
30 4 6 3 6
30 4 7 3 6
30 4 8 3 6
30 4 9 3 6
30 4 10 3 6
30 4 11 3 6
30 4 12 3 6
30 4 13 3 6
30 4 14 3 34
30 5 1 3 66
30 5 2 3 6
30 5 3 3 6
30 5 4 3 6
30 5 5 3 6
30 5 6 3 6
30 5 7 3 6
30 5 8 3 6
30 5 9 3 6
30 5 10 3 6
30 5 11 3 6
30 5 12 3 6
30 5 13 3 6
30 5 14 3 34
30 6 1 3 66
30 6 2 3 6
30 6 3 3 6
30 6 4 3 6
30 6 5 3 6
30 6 6 3 6
30 6 7 3 6
30 6 8 3 6
30 6 9 3 6
30 6 10 3 6
30 6 11 3 6
30 6 12 3 6
30 6 13 3 6
30 6 14 3 34
30 7 1 3 74
30 7 2 3 14
30 7 3 3 14
30 7 4 3 14
30 7 5 3 14
30 7 6 3 14
30 7 7 3 14
30 7 8 3 14
30 7 9 3 14
30 7 10 3 14
30 7 11 3 14
30 7 12 3 14
30 7 13 3 14
30 7 14 3 42
30 8 0 0 112
30 8 15 0 120
30 9 0 0 74
30 9 1 0 30
30 9 2 0 30
30 9 3 0 30
30 9 4 0 30
30 9 5 0 30
30 9 6 0 30
30 9 7 0 30
30 9 8 0 30
30 9 9 0 30
30 9 10 0 30
30 9 11 0 30
30 9 12 0 30
30 9 13 0 30
30 9 14 0 58
31 8 0 0 90
31 8 1 0 30
31 8 2 0 30
31 8 3 0 30
31 8 4 0 30
31 8 5 0 30
31 8 6 0 30
31 8 7 0 30
31 8 8 0 30
31 8 9 0 30
31 8 10 0 30
31 8 11 0 30
31 8 12 0 30
31 8 13 0 30
31 8 14 0 30
31 8 15 0 58
