Qubicle Exchange Format
Version 0.2
www.minddesk.com
16 32 16
1
0.266667 0.266667 0.266667
5 0 7 0 84
5 0 8 0 20
5 0 9 0 20
5 0 10 0 20
5 0 11 0 20
5 0 12 0 52
5 1 6 0 84
5 1 7 0 4
5 1 8 0 4
5 1 9 0 4
5 1 10 0 4
5 1 11 0 4
5 1 12 0 46
5 2 5 0 84
5 2 6 0 4
5 2 7 0 4
5 2 8 0 4
5 2 9 0 12
5 2 10 0 4
5 2 11 0 36
5 3 5 0 68
5 3 6 0 4
5 3 7 0 4
5 3 8 0 44
5 3 10 0 76
5 3 11 0 44
5 4 5 0 76
5 4 6 0 12
5 4 7 0 44
6 0 6 0 84
6 0 7 0 16
6 0 8 0 16
6 0 9 0 16
6 0 10 0 16
6 0 11 0 16
6 0 12 0 56
6 1 6 0 64
6 1 7 0 0
6 1 8 0 0
6 1 9 0 0
6 1 10 0 0
6 1 11 0 32
6 2 4 0 84
6 2 5 0 16
6 2 6 0 0
6 2 7 0 0
6 2 8 0 0
6 2 9 0 0
6 2 10 0 0
6 2 11 0 0
6 2 12 0 52
6 3 4 0 76
6 3 5 0 0
6 3 6 0 0
6 3 7 0 0
6 3 8 0 0
6 3 9 0 4
6 3 10 0 0
6 3 11 0 0
6 3 12 0 4
6 3 13 0 60
6 4 5 0 72
6 4 6 0 8
6 4 7 0 0
6 4 8 0 4
6 4 9 0 4
6 4 10 0 4
6 4 11 0 4
6 4 12 0 44
6 5 7 0 76
6 5 8 0 4
6 5 9 0 4
6 5 10 0 12
6 5 11 0 44
6 6 8 0 76
6 6 9 0 44
7 0 5 0 84
7 0 6 0 16
7 0 7 0 16
7 0 8 0 16
7 0 9 0 16
7 0 10 0 16
7 0 11 0 16
7 0 12 0 16
7 0 13 0 60
7 1 5 0 70
7 1 6 0 0
7 1 7 0 0
7 1 8 0 0
7 1 9 0 0
7 1 10 0 0
7 1 11 0 0
7 1 12 0 36
7 2 4 0 80
7 2 5 0 0
7 2 6 0 0
7 2 7 0 0
7 2 8 0 0
7 2 9 0 0
7 2 10 0 0
7 2 11 0 0
7 2 12 0 0
7 2 13 0 52
7 3 4 0 64
7 3 5 0 0
7 3 6 0 0
7 3 7 0 0
7 3 8 0 0
7 3 9 0 0
7 3 10 0 0
7 3 11 0 0
7 3 12 0 0
7 3 13 0 40
7 4 4 0 76
7 4 5 0 0
7 4 6 0 0
7 4 7 0 0
7 4 8 0 0
7 4 9 0 0
7 4 10 0 0
7 4 11 0 0
7 4 12 0 40
7 5 5 0 76
7 5 6 0 4
7 5 7 0 0
7 5 8 0 0
7 5 9 0 0
7 5 10 0 0
7 5 11 0 32
7 6 6 0 68
7 6 7 0 12
7 6 8 0 0
7 6 9 0 0
7 6 10 0 4
7 6 11 0 44
7 7 6 0 100
7 7 8 0 76
7 7 9 0 4
7 7 10 0 36
7 8 6 0 108
7 8 9 0 76
7 8 10 0 44
8 0 4 0 92
8 0 5 0 24
8 0 6 0 16
8 0 7 0 16
8 0 8 0 16
8 0 9 0 16
8 0 10 0 16
8 0 11 0 16
8 0 12 0 16
8 0 13 0 48
8 1 6 0 64
8 1 7 0 0
8 1 8 0 0
8 1 9 0 0
8 1 10 0 0
8 1 11 0 0
8 1 12 0 0
8 1 13 0 36
8 2 4 0 80
8 2 5 0 16
8 2 6 0 0
8 2 7 0 0
8 2 8 0 0
8 2 9 0 0
8 2 10 0 0
8 2 11 0 0
8 2 12 0 0
8 2 13 0 32
8 3 4 0 64
8 3 5 0 0
8 3 6 0 0
8 3 7 0 0
8 3 8 0 0
8 3 9 0 0
8 3 10 0 0
8 3 11 0 0
8 3 12 0 0
8 3 13 0 42
8 4 4 0 72
8 4 5 0 0
8 4 6 0 0
8 4 7 0 0
8 4 8 0 0
8 4 9 0 0
8 4 10 0 0
8 4 11 0 0
8 4 12 0 32
8 5 5 0 64
8 5 6 0 0
8 5 7 0 0
8 5 8 0 0
8 5 9 0 0
8 5 10 0 0
8 5 11 0 0
8 5 12 0 38
8 6 5 0 68
8 6 6 0 0
8 6 7 0 0
8 6 8 0 0
8 6 9 0 0
8 6 10 0 0
8 6 11 0 0
8 6 12 0 46
8 7 4 0 92
8 7 5 0 4
8 7 6 0 0
8 7 7 0 4
8 7 8 0 0
8 7 9 0 0
8 7 10 0 0
8 7 11 0 36
8 8 5 0 76
8 8 6 0 0
8 8 7 0 4
8 8 8 0 4
8 8 9 0 0
8 8 10 0 8
8 8 11 0 12
8 8 12 0 60
8 9 6 0 76
8 9 7 0 12
8 9 8 0 12
8 9 9 0 44
9 0 4 0 88
9 0 5 0 16
9 0 6 0 16
9 0 7 0 16
9 0 8 0 16
9 0 9 0 16
9 0 10 0 16
9 0 11 0 16
9 0 12 0 16
9 0 13 0 48
9 1 5 0 68
9 1 6 0 0
9 1 7 0 0
9 1 8 0 0
9 1 9 0 0
9 1 10 0 0
9 1 11 0 0
9 1 12 0 0
9 1 13 0 32
9 2 4 0 80
9 2 5 0 0
9 2 6 0 0
9 2 7 0 0
9 2 8 0 0
9 2 9 0 0
9 2 10 0 0
9 2 11 0 0
9 2 12 0 0
9 2 13 0 40
9 3 4 0 64
9 3 5 0 0
9 3 6 0 0
9 3 7 0 0
9 3 8 0 0
9 3 9 0 0
9 3 10 0 0
9 3 11 0 0
9 3 12 0 32
9 4 4 0 64
9 4 5 0 0
9 4 6 0 0
9 4 7 0 0
9 4 8 0 0
9 4 9 0 0
9 4 10 0 0
9 4 11 0 0
9 4 12 0 40
9 5 4 0 68
9 5 5 0 0
9 5 6 0 0
9 5 7 0 0
9 5 8 0 0
9 5 9 0 0
9 5 10 0 0
9 5 11 0 32
9 6 4 0 68
9 6 5 0 0
9 6 6 0 0
9 6 7 0 0
9 6 8 0 0
9 6 9 0 0
9 6 10 0 0
9 6 11 0 32
9 7 4 0 64
9 7 5 0 0
9 7 6 0 0
9 7 7 0 0
9 7 8 0 0
9 7 9 0 0
9 7 10 0 0
9 7 11 0 0
9 7 12 0 52
9 8 4 0 68
9 8 5 0 0
9 8 6 0 0
9 8 7 0 0
9 8 8 0 0
9 8 9 0 0
9 8 10 0 0
9 8 11 0 0
9 8 12 0 40
9 9 4 0 76
9 9 5 0 4
9 9 6 0 0
9 9 7 0 0
9 9 8 0 8
9 9 9 0 8
9 9 10 0 4
9 9 11 0 44
9 10 5 0 78
9 10 6 0 12
9 10 7 0 44
9 10 10 0 110
10 0 4 0 88
10 0 5 0 16
10 0 6 0 16
10 0 7 0 16
10 0 8 0 16
10 0 9 0 16
10 0 10 0 16
10 0 11 0 16
10 0 12 0 16
10 0 13 0 50
10 1 5 0 64
10 1 6 0 0
10 1 7 0 0
10 1 8 0 0
10 1 9 0 0
10 1 10 0 0
10 1 11 0 0
10 1 12 0 0
10 1 13 0 34
10 2 4 0 80
10 2 5 0 0
10 2 6 0 0
10 2 7 0 0
10 2 8 0 0
10 2 9 0 0
10 2 10 0 0
10 2 11 0 0
10 2 12 0 0
10 2 13 0 34
10 3 4 0 64
10 3 5 0 0
10 3 6 0 0
10 3 7 0 0
10 3 8 0 0
10 3 9 0 0
10 3 10 0 0
10 3 11 0 0
10 3 12 0 0
10 3 13 0 38
10 4 4 0 64
10 4 5 0 0
10 4 6 0 0
10 4 7 0 0
10 4 8 0 0
10 4 9 0 0
10 4 10 0 0
10 4 11 0 0
10 4 12 0 0
10 4 13 0 36
10 5 4 0 64
10 5 5 0 0
10 5 6 0 0
10 5 7 0 0
10 5 8 0 0
10 5 9 0 0
10 5 10 0 0
10 5 11 0 0
10 5 12 0 6
10 5 13 0 46
10 6 4 0 64
10 6 5 0 0
10 6 6 0 0
10 6 7 0 0
10 6 8 0 0
10 6 9 0 0
10 6 10 0 0
10 6 11 0 0
10 6 12 0 36
10 7 4 0 64
10 7 5 0 0
10 7 6 0 0
10 7 7 0 0
10 7 8 0 0
10 7 9 0 0
10 7 10 0 0
10 7 11 0 0
10 7 12 0 32
10 8 4 0 64
10 8 5 0 0
10 8 6 0 0
10 8 7 0 0
10 8 8 0 0
10 8 9 0 0
10 8 10 0 0
10 8 11 0 0
10 8 12 0 42
10 9 4 0 74
10 9 5 0 8
10 9 6 0 0
10 9 7 0 0
10 9 8 0 0
10 9 9 0 0
10 9 10 0 8
10 9 11 0 42
10 10 6 0 74
10 10 7 0 10
10 10 8 0 14
10 10 9 0 46
11 0 4 0 80
11 0 5 0 16
11 0 6 0 16
11 0 7 0 16
11 0 8 0 16
11 0 9 0 16
11 0 10 0 16
11 0 11 0 16
11 0 12 0 48
11 1 4 0 68
11 1 5 0 0
11 1 6 0 0
11 1 7 0 0
11 1 8 0 0
11 1 9 0 0
11 1 10 0 2
11 1 11 0 2
11 1 12 0 32
11 2 4 0 64
11 2 5 0 0
11 2 6 0 0
11 2 7 0 0
11 2 8 0 0
11 2 9 0 0
11 2 10 0 0
11 2 11 0 0
11 2 12 0 32
11 3 4 0 64
11 3 5 0 0
11 3 6 0 0
11 3 7 0 0
11 3 8 0 0
11 3 9 0 0
11 3 10 0 0
11 3 11 0 0
11 3 12 0 32
11 4 4 0 64
11 4 5 0 0
11 4 6 0 0
11 4 7 0 0
11 4 8 0 0
11 4 9 0 0
11 4 10 0 0
11 4 11 0 0
11 4 12 0 8
11 4 13 0 58
11 5 4 0 64
11 5 5 0 0
11 5 6 0 0
11 5 7 0 0
11 5 8 0 0
11 5 9 0 0
11 5 10 0 0
11 5 11 0 32
11 6 4 0 64
11 6 5 0 0
11 6 6 0 0
11 6 7 0 0
11 6 8 0 0
11 6 9 0 0
11 6 10 0 0
11 6 11 0 0
11 6 12 0 48
11 7 4 0 64
11 7 5 0 0
11 7 6 0 0
11 7 7 0 0
11 7 8 0 0
11 7 9 0 0
11 7 10 0 0
11 7 11 0 0
11 7 12 0 42
11 8 4 0 74
11 8 5 0 0
11 8 6 0 0
11 8 7 0 0
11 8 8 0 0
11 8 9 0 0
11 8 10 0 0
11 8 11 0 42
11 9 5 0 74
11 9 6 0 10
11 9 7 0 8
11 9 8 0 8
11 9 9 0 10
11 9 10 0 42
12 0 4 0 80
12 0 5 0 16
12 0 6 0 16
12 0 7 0 16
12 0 8 0 16
12 0 9 0 16
12 0 10 0 24
12 0 11 0 24
12 0 12 0 50
12 1 4 0 64
12 1 5 0 0
12 1 6 0 0
12 1 7 0 0
12 1 8 0 0
12 1 9 0 32
12 1 12 0 66
12 1 13 0 62
12 2 4 0 64
12 2 5 0 0
12 2 6 0 0
12 2 7 0 0
12 2 8 0 0
12 2 9 0 0
12 2 10 0 18
12 2 11 0 18
12 2 12 0 34
12 3 4 0 64
12 3 5 0 0
12 3 6 0 0
12 3 7 0 0
12 3 8 0 0
12 3 9 0 0
12 3 10 0 0
12 3 11 0 0
12 3 12 0 34
12 4 4 0 66
12 4 5 0 0
12 4 6 0 0
12 4 7 0 0
12 4 8 0 0
12 4 9 0 0
12 4 10 0 0
12 4 11 0 2
12 4 12 0 42
12 5 4 0 66
12 5 5 0 0
12 5 6 0 0
12 5 7 0 0
12 5 8 0 0
12 5 9 0 0
12 5 10 0 0
12 5 11 0 34
12 6 4 0 64
12 6 5 0 0
12 6 6 0 0
12 6 7 0 0
12 6 8 0 0
12 6 9 0 0
12 6 10 0 0
12 6 11 0 0
12 6 12 0 58
12 7 4 0 74
12 7 5 0 0
12 7 6 0 0
12 7 7 0 0
12 7 8 0 0
12 7 9 0 0
12 7 10 0 0
12 7 11 0 42
12 8 5 0 74
12 8 6 0 10
12 8 7 0 0
12 8 8 0 0
12 8 9 0 10
12 8 10 0 42
12 9 7 0 74
12 9 8 0 42
13 0 4 0 82
13 0 5 0 18
13 0 6 0 18
13 0 7 0 18
13 0 8 0 18
13 0 9 0 18
13 0 10 0 26
13 0 11 0 58
13 1 4 0 66
13 1 5 0 2
13 1 6 0 2
13 1 7 0 2
13 1 8 0 2
13 1 9 0 34
13 2 4 0 66
13 2 5 0 2
13 2 6 0 2
13 2 7 0 2
13 2 8 0 2
13 2 9 0 34
13 3 4 0 74
13 3 5 0 2
13 3 6 0 2
13 3 7 0 2
13 3 8 0 2
13 3 9 0 2
13 3 10 0 18
13 3 11 0 58
13 4 5 0 66
13 4 6 0 2
13 4 7 0 2
13 4 8 0 2
13 4 9 0 2
13 4 10 0 34
13 5 5 0 66
13 5 6 0 2
13 5 7 0 2
13 5 8 0 2
13 5 9 0 2
13 5 10 0 34
13 6 4 0 90
13 6 5 0 2
13 6 6 0 2
13 6 7 0 2
13 6 8 0 2
13 6 9 0 2
13 6 10 0 2
13 6 11 0 58
13 7 5 0 74
13 7 6 0 10
13 7 7 0 2
13 7 8 0 2
13 7 9 0 10
13 7 10 0 42
13 8 7 0 74
13 8 8 0 42
