Qubicle Exchange Format
Version 0.2
www.minddesk.com
16 32 16
25
0.239216 0.239216 0.239216
0.243137 0.243137 0.243137
0.247059 0.247059 0.247059
0.250980 0.250980 0.250980
0.254902 0.254902 0.254902
0.258824 0.258824 0.258824
0.262745 0.262745 0.262745
0.266667 0.266667 0.266667
0.270588 0.270588 0.270588
0.274510 0.274510 0.274510
0.278431 0.278431 0.278431
0.282353 0.282353 0.282353
0.286275 0.286275 0.286275
0.290196 0.290196 0.290196
0.294118 0.294118 0.294118
0.298039 0.298039 0.298039
0.301961 0.301961 0.301961
0.305882 0.305882 0.305882
0.309804 0.309804 0.309804
0.313726 0.313726 0.313726
0.317647 0.317647 0.317647
0.321569 0.321569 0.321569
0.325490 0.325490 0.325490
0.329412 0.329412 0.329412
0.333333 0.333333 0.333333
5 0 7 4 84
5 0 8 3 20
5 0 9 5 20
5 0 10 10 20
5 0 11 6 20
5 0 12 1 52
5 1 6 16 84
5 1 7 13 4
5 1 8 19 4
5 1 9 4 4
5 1 10 4 4
5 1 11 7 4
5 1 12 2 46
5 2 5 0 92
5 2 6 6 12
5 2 7 4 12
5 2 8 0 12
5 2 9 23 12
5 2 10 6 12
5 2 11 0 36
5 3 11 12 110
6 0 6 12 84
6 0 7 6 16
6 0 8 24 16
6 0 9 5 16
6 0 10 19 16
6 0 11 16 16
6 0 12 2 56
6 1 6 4 64
6 1 7 7 0
6 1 8 6 0
6 1 9 10 0
6 1 10 3 0
6 1 11 5 32
6 2 5 14 88
6 2 6 6 0
6 2 7 3 0
6 2 8 22 0
6 2 9 6 8
6 2 10 19 0
6 2 11 16 8
6 2 12 5 60
6 3 6 22 76
6 3 7 21 12
6 3 8 9 44
6 3 10 2 108
7 0 5 1 84
7 0 6 6 16
7 0 7 3 16
7 0 8 0 16
7 0 9 14 16
7 0 10 9 16
7 0 11 10 16
7 0 12 24 16
7 0 13 14 60
7 1 5 4 70
7 1 6 11 0
7 1 7 12 0
7 1 8 24 0
7 1 9 12 0
7 1 10 1 0
7 1 11 11 0
7 1 12 20 36
7 2 4 16 92
7 2 5 22 8
7 2 6 12 0
7 2 7 16 0
7 2 8 0 0
7 2 9 2 0
7 2 10 5 0
7 2 11 13 8
7 2 12 4 8
7 2 13 4 62
7 3 6 7 64
7 3 7 6 0
7 3 8 19 0
7 3 9 8 4
7 3 10 5 40
7 4 6 4 78
7 4 7 16 6
7 4 8 1 12
7 4 9 6 44
7 5 7 5 108
8 0 4 15 92
8 0 5 6 24
8 0 6 23 16
8 0 7 9 16
8 0 8 1 16
8 0 9 6 16
8 0 10 19 16
8 0 11 1 16
8 0 12 24 16
8 0 13 6 48
8 1 6 5 64
8 1 7 18 0
8 1 8 15 0
8 1 9 7 0
8 1 10 20 0
8 1 11 13 0
8 1 12 8 0
8 1 13 0 44
8 2 4 4 90
8 2 5 17 24
8 2 6 6 0
8 2 7 0 0
8 2 8 14 0
8 2 9 4 0
8 2 10 23 0
8 2 11 2 8
8 2 12 12 40
8 3 6 2 72
8 3 7 4 8
8 3 8 2 0
8 3 9 12 0
8 3 10 8 40
8 4 8 17 64
8 4 9 21 32
8 5 7 17 88
8 5 8 4 12
8 5 9 6 12
8 5 10 18 62
9 0 4 2 88
9 0 5 13 16
9 0 6 3 16
9 0 7 14 16
9 0 8 19 16
9 0 9 3 16
9 0 10 1 16
9 0 11 7 16
9 0 12 9 16
9 0 13 16 48
9 1 5 8 68
9 1 6 9 0
9 1 7 2 0
9 1 8 14 0
9 1 9 11 0
9 1 10 16 0
9 1 11 6 0
9 1 12 0 0
9 1 13 15 40
9 2 5 17 72
9 2 6 11 0
9 2 7 8 0
9 2 8 2 0
9 2 9 24 0
9 2 10 5 0
9 2 11 0 8
9 2 12 11 40
9 3 6 20 64
9 3 7 9 0
9 3 8 15 0
9 3 9 13 0
9 3 10 5 32
9 4 6 20 76
9 4 7 5 4
9 4 8 0 0
9 4 9 10 0
9 4 10 3 44
9 5 7 19 72
9 5 8 13 8
9 5 9 7 40
10 0 4 5 88
10 0 5 19 16
10 0 6 22 16
10 0 7 16 16
10 0 8 11 16
10 0 9 1 16
10 0 10 19 16
10 0 11 1 16
10 0 12 22 16
10 0 13 3 50
10 1 5 2 64
10 1 6 22 0
10 1 7 7 0
10 1 8 9 0
10 1 9 24 0
10 1 10 3 0
10 1 11 7 0
10 1 12 5 0
10 1 13 22 42
10 2 5 22 72
10 2 6 2 0
10 2 7 5 0
10 2 8 3 0
10 2 9 23 0
10 2 10 10 0
10 2 11 2 0
10 2 12 1 34
10 3 6 0 64
10 3 7 4 0
10 3 8 14 0
10 3 9 6 0
10 3 10 6 0
10 3 11 1 12
10 3 12 6 46
10 4 6 5 72
10 4 7 1 0
10 4 8 3 0
10 4 9 17 0
10 4 10 6 42
10 5 7 21 72
10 5 8 3 8
10 5 9 10 40
11 0 4 17 80
11 0 5 14 16
11 0 6 1 16
11 0 7 14 16
11 0 8 22 16
11 0 9 3 16
11 0 10 2 16
11 0 11 5 16
11 0 12 14 48
11 1 4 22 68
11 1 5 2 0
11 1 6 19 0
11 1 7 2 0
11 1 8 3 0
11 1 9 24 0
11 1 10 6 2
11 1 11 8 2
11 1 12 4 40
11 2 4 4 76
11 2 5 22 0
11 2 6 5 0
11 2 7 1 0
11 2 8 24 0
11 2 9 22 0
11 2 10 4 0
11 2 11 0 32
11 3 5 8 78
11 3 6 15 0
11 3 7 3 0
11 3 8 21 0
11 3 9 9 0
11 3 10 20 10
11 3 11 11 42
11 4 6 5 74
11 4 7 6 0
11 4 8 2 0
11 4 9 11 32
11 5 7 21 74
11 5 8 5 10
11 5 9 1 42
12 0 4 7 80
12 0 5 0 16
12 0 6 16 16
12 0 7 23 16
12 0 8 14 16
12 0 9 5 16
12 0 10 1 24
12 0 11 18 24
12 0 12 6 50
12 1 4 24 64
12 1 5 22 0
12 1 6 12 0
12 1 7 23 0
12 1 8 19 0
12 1 9 5 32
12 1 12 1 66
12 1 13 22 62
12 2 4 3 72
12 2 5 22 8
12 2 6 19 0
12 2 7 3 0
12 2 8 0 0
12 2 9 9 0
12 2 10 3 26
12 2 11 0 26
12 2 12 11 46
12 3 6 4 74
12 3 7 13 2
12 3 8 1 2
12 3 9 1 34
12 4 7 10 74
12 4 8 4 10
12 4 9 15 42
13 0 4 16 82
13 0 5 16 18
13 0 6 1 18
13 0 7 20 18
13 0 8 19 18
13 0 9 2 18
13 0 10 12 26
13 0 11 4 58
13 1 4 4 66
13 1 5 22 2
13 1 6 2 2
13 1 7 19 2
13 1 8 6 2
13 1 9 6 34
13 2 4 11 74
13 2 5 24 10
13 2 6 10 10
13 2 7 7 10
13 2 8 6 10
13 2 9 0 42
