Qubicle Exchange Format
Version 0.2
www.minddesk.com
16 32 16
65
0.000000 0.239216 0.000000
0.000000 0.243137 0.000000
0.000000 0.247059 0.000000
0.000000 0.250980 0.000000
0.000000 0.254902 0.000000
0.000000 0.258824 0.000000
0.000000 0.262745 0.000000
0.000000 0.266667 0.000000
0.003922 0.270588 0.003922
0.007843 0.270588 0.007843
0.011765 0.274510 0.011765
0.015686 0.278431 0.015686
0.019608 0.282353 0.019608
0.023529 0.282353 0.023529
0.027451 0.286275 0.027451
0.031373 0.290196 0.031373
0.035294 0.294118 0.035294
0.039216 0.294118 0.039216
0.043137 0.298039 0.043137
0.047059 0.301961 0.047059
0.050980 0.301961 0.050980
0.054902 0.305882 0.054902
0.058824 0.309804 0.058824
0.062745 0.313726 0.062745
0.066667 0.313726 0.066667
0.070588 0.317647 0.070588
0.074510 0.321569 0.074510
0.078431 0.325490 0.078431
0.082353 0.325490 0.082353
0.086275 0.329412 0.086275
0.090196 0.333333 0.090196
0.223529 0.152941 0.000000
0.227451 0.152941 0.000000
0.227451 0.156863 0.000000
0.231373 0.156863 0.000000
0.231373 0.160784 0.000000
0.235294 0.160784 0.000000
0.239216 0.160784 0.000000
0.239216 0.164706 0.000000
0.243137 0.164706 0.000000
0.243137 0.168627 0.000000
0.247059 0.168627 0.000000
0.250980 0.172549 0.000000
0.254902 0.176471 0.003922
0.254902 0.180392 0.007843
0.258824 0.184314 0.011765
0.262745 0.184314 0.015686
0.266667 0.188235 0.019608
0.266667 0.192157 0.023529
0.270588 0.196078 0.027451
0.274510 0.200000 0.031373
0.278431 0.203922 0.035294
0.278431 0.203922 0.039216
0.282353 0.207843 0.043137
0.286275 0.211765 0.047059
0.290196 0.215686 0.050980
0.290196 0.219608 0.054902
0.294118 0.223529 0.058824
0.298039 0.223529 0.062745
0.301961 0.231373 0.070588
0.305882 0.235294 0.074510
0.309804 0.239216 0.078431
0.313726 0.239216 0.082353
0.313726 0.243137 0.086275
0.317647 0.247059 0.090196
0 12 5 10 84
0 12 6 4 20
0 12 7 27 20
0 12 8 28 20
0 12 9 24 20
0 12 10 3 52
0 13 5 26 76
0 13 6 22 12
0 13 7 0 12
0 13 8 1 12
0 13 9 13 12
0 13 10 15 44
1 12 3 2 84
1 12 4 27 20
1 12 5 1 16
1 12 6 13 16
1 12 7 4 16
1 12 8 19 16
1 12 9 3 16
1 12 10 17 16
1 12 11 4 20
1 12 12 6 52
1 13 3 0 76
1 13 4 24 12
1 13 5 5 0
1 13 6 1 0
1 13 7 1 0
1 13 8 7 0
1 13 9 14 0
1 13 10 16 0
1 13 11 21 12
1 13 12 3 44
1 14 5 0 68
1 14 6 20 4
1 14 7 24 4
1 14 8 1 4
1 14 9 1 4
1 14 10 13 36
1 15 5 24 68
1 15 6 4 4
1 15 7 16 4
1 15 8 4 4
1 15 9 5 4
1 15 10 1 36
1 16 5 5 76
1 16 6 30 12
1 16 7 18 12
1 16 8 6 12
1 16 9 5 12
1 16 10 4 44
2 12 2 25 84
2 12 3 29 16
2 12 4 13 16
2 12 5 9 16
2 12 6 5 16
2 12 7 5 16
2 12 8 1 16
2 12 9 15 16
2 12 10 5 16
2 12 11 2 16
2 12 12 5 16
2 12 13 6 52
2 13 2 13 76
2 13 3 18 0
2 13 4 11 0
2 13 5 2 0
2 13 6 15 0
2 13 7 23 0
2 13 8 10 0
2 13 9 5 0
2 13 10 9 0
2 13 11 22 0
2 13 12 5 0
2 13 13 6 44
2 14 3 1 76
2 14 4 13 4
2 14 5 4 0
2 14 6 4 0
2 14 7 10 0
2 14 8 6 0
2 14 9 5 0
2 14 10 20 0
2 14 11 28 4
2 14 12 4 44
2 15 4 27 68
2 15 5 7 0
2 15 6 3 0
2 15 7 5 0
2 15 8 13 0
2 15 9 20 0
2 15 10 21 0
2 15 11 4 36
2 16 4 0 76
2 16 5 0 8
2 16 6 4 0
2 16 7 29 0
2 16 8 19 0
2 16 9 1 0
2 16 10 9 8
2 16 11 5 44
2 17 6 7 68
2 17 7 0 4
2 17 8 6 4
2 17 9 26 36
2 18 6 1 76
2 18 7 2 12
2 18 8 13 12
2 18 9 6 44
3 12 1 8 84
3 12 2 5 16
3 12 3 26 16
3 12 4 0 16
3 12 5 16 16
3 12 6 8 16
3 12 7 27 16
3 12 8 29 16
3 12 9 3 16
3 12 10 4 16
3 12 11 3 16
3 12 12 18 16
3 12 13 5 16
3 12 14 19 52
3 13 1 3 76
3 13 2 5 0
3 13 3 2 0
3 13 4 2 0
3 13 5 4 0
3 13 6 5 0
3 13 7 15 0
3 13 8 6 0
3 13 9 6 0
3 13 10 27 0
3 13 11 15 0
3 13 12 4 0
3 13 13 11 0
3 13 14 3 44
3 14 2 12 76
3 14 3 1 0
3 14 4 13 0
3 14 5 3 0
3 14 6 9 0
3 14 7 30 0
3 14 8 3 0
3 14 9 26 0
3 14 10 2 0
3 14 11 17 0
3 14 12 0 0
3 14 13 21 44
3 15 3 3 68
3 15 4 14 0
3 15 5 18 0
3 15 6 12 0
3 15 7 1 0
3 15 8 4 0
3 15 9 23 0
3 15 10 8 0
3 15 11 30 0
3 15 12 17 36
3 16 3 4 68
3 16 4 15 0
3 16 5 22 0
3 16 6 0 0
3 16 7 1 0
3 16 8 9 0
3 16 9 1 0
3 16 10 0 0
3 16 11 28 0
3 16 12 11 36
3 17 3 14 76
3 17 4 3 4
3 17 5 27 4
3 17 6 19 0
3 17 7 20 0
3 17 8 1 0
3 17 9 3 0
3 17 10 3 4
3 17 11 4 4
3 17 12 25 44
3 18 4 5 68
3 18 5 3 4
3 18 6 2 0
3 18 7 2 0
3 18 8 3 0
3 18 9 5 0
3 18 10 3 4
3 18 11 3 36
3 19 4 1 76
3 19 5 5 12
3 19 6 5 4
3 19 7 25 4
3 19 8 3 4
3 19 9 28 4
3 19 10 17 12
3 19 11 30 44
3 20 6 3 68
3 20 7 4 4
3 20 8 5 4
3 20 9 8 36
3 21 6 2 76
3 21 7 5 12
3 21 8 29 12
3 21 9 3 44
4 12 1 28 80
4 12 2 1 16
4 12 3 1 16
4 12 4 8 16
4 12 5 5 16
4 12 6 4 16
4 12 7 6 16
4 12 8 1 16
4 12 9 24 16
4 12 10 5 16
4 12 11 4 16
4 12 12 1 16
4 12 13 16 16
4 12 14 11 48
4 13 1 20 72
4 13 2 20 0
4 13 3 1 0
4 13 4 27 0
4 13 5 4 0
4 13 6 4 0
4 13 7 18 0
4 13 8 15 0
4 13 9 23 0
4 13 10 13 0
4 13 11 19 0
4 13 12 2 0
4 13 13 27 0
4 13 14 4 40
4 14 2 29 64
4 14 3 23 0
4 14 4 8 0
4 14 5 2 0
4 14 6 4 0
4 14 7 16 0
4 14 8 5 0
4 14 9 24 0
4 14 10 14 0
4 14 11 20 0
4 14 12 4 0
4 14 13 5 32
4 15 2 20 68
4 15 3 3 0
4 15 4 4 0
4 15 5 4 0
4 15 6 1 0
4 15 7 3 0
4 15 8 5 0
4 15 9 28 0
4 15 10 8 0
4 15 11 3 0
4 15 12 6 0
4 15 13 1 36
4 16 2 24 76
4 16 3 5 0
4 16 4 4 0
4 16 5 6 0
4 16 6 29 0
4 16 7 5 0
4 16 8 21 0
4 16 9 7 0
4 16 10 23 0
4 16 11 3 0
4 16 12 18 0
4 16 13 0 44
4 17 3 4 64
4 17 4 4 0
4 17 5 24 0
4 17 6 28 0
4 17 7 6 0
4 17 8 16 0
4 17 9 16 0
4 17 10 17 0
4 17 11 3 0
4 17 12 3 32
4 18 3 0 68
4 18 4 3 0
4 18 5 2 0
4 18 6 20 0
4 18 7 6 0
4 18 8 6 0
4 18 9 6 0
4 18 10 0 0
4 18 11 11 0
4 18 12 0 36
4 19 3 5 76
4 19 4 7 0
4 19 5 15 0
4 19 6 5 0
4 19 7 3 0
4 19 8 5 0
4 19 9 13 0
4 19 10 2 0
4 19 11 4 0
4 19 12 1 44
4 20 4 17 68
4 20 5 1 4
4 20 6 22 0
4 20 7 6 0
4 20 8 3 0
4 20 9 6 0
4 20 10 7 4
4 20 11 11 36
4 21 4 18 76
4 21 5 3 4
4 21 6 20 0
4 21 7 6 0
4 21 8 3 0
4 21 9 5 0
4 21 10 3 4
4 21 11 4 44
4 22 5 4 68
4 22 6 2 4
4 22 7 5 4
4 22 8 11 4
4 22 9 10 4
4 22 10 12 36
4 23 5 28 76
4 23 6 6 4
4 23 7 6 4
4 23 8 6 4
4 23 9 12 4
4 23 10 2 44
4 24 6 19 76
4 24 7 19 12
4 24 8 18 12
4 24 9 18 44
5 12 0 13 84
5 12 1 0 16
5 12 2 11 16
5 12 3 8 16
5 12 4 24 16
5 12 5 30 16
5 12 6 11 16
5 12 7 13 16
5 12 8 2 16
5 12 9 1 16
5 12 10 0 16
5 12 11 7 16
5 12 12 4 16
5 12 13 2 16
5 12 14 2 16
5 12 15 2 52
5 13 0 0 76
5 13 1 29 0
5 13 2 3 0
5 13 3 11 0
5 13 4 11 0
5 13 5 4 0
5 13 6 6 0
5 13 7 5 0
5 13 8 6 0
5 13 9 3 0
5 13 10 23 0
5 13 11 7 0
5 13 12 0 0
5 13 13 23 0
5 13 14 10 0
5 13 15 1 44
5 14 1 7 68
5 14 2 12 0
5 14 3 2 0
5 14 4 3 0
5 14 5 3 0
5 14 6 26 0
5 14 7 7 0
5 14 8 9 0
5 14 9 6 0
5 14 10 2 0
5 14 11 20 0
5 14 12 12 0
5 14 13 10 0
5 14 14 1 36
5 15 1 8 68
5 15 2 30 0
5 15 3 25 0
5 15 4 5 0
5 15 5 1 0
5 15 6 1 0
5 15 7 1 0
5 15 8 0 0
5 15 9 28 0
5 15 10 8 0
5 15 11 1 0
5 15 12 9 0
5 15 13 9 0
5 15 14 11 36
5 16 1 9 76
5 16 2 7 8
5 16 3 14 0
5 16 4 24 0
5 16 5 6 0
5 16 6 5 0
5 16 7 1 0
5 16 8 11 0
5 16 9 5 0
5 16 10 21 0
5 16 11 13 0
5 16 12 5 0
5 16 13 4 8
5 16 14 0 44
5 17 3 21 64
5 17 4 15 0
5 17 5 12 0
5 17 6 4 0
5 17 7 1 0
5 17 8 11 0
5 17 9 15 0
5 17 10 1 0
5 17 11 0 0
5 17 12 26 32
5 18 3 6 64
5 18 4 5 0
5 18 5 17 0
5 18 6 3 0
5 18 7 25 0
5 18 8 0 0
5 18 9 5 0
5 18 10 6 0
5 18 11 30 0
5 18 12 21 32
5 19 3 0 72
5 19 4 0 0
5 19 5 1 0
5 19 6 22 0
5 19 7 22 0
5 19 8 1 0
5 19 9 16 0
5 19 10 1 0
5 19 11 5 0
5 19 12 7 40
5 20 4 15 64
5 20 5 28 0
5 20 6 0 0
5 20 7 6 0
5 20 8 22 0
5 20 9 11 0
5 20 10 29 0
5 20 11 4 32
5 21 4 12 64
5 21 5 3 0
5 21 6 30 0
5 21 7 20 0
5 21 8 15 0
5 21 9 18 0
5 21 10 22 0
5 21 11 3 32
5 22 4 13 68
5 22 5 30 0
5 22 6 17 0
5 22 7 18 0
5 22 8 2 0
5 22 9 4 0
5 22 10 29 0
5 22 11 12 36
5 23 4 17 76
5 23 5 5 0
5 23 6 5 0
5 23 7 12 0
5 23 8 30 0
5 23 9 2 0
5 23 10 9 0
5 23 11 25 44
5 24 5 7 68
5 24 6 26 0
5 24 7 3 0
5 24 8 14 0
5 24 9 30 0
5 24 10 6 36
5 25 5 5 76
5 25 6 27 4
5 25 7 6 4
5 25 8 5 4
5 25 9 8 4
5 25 10 28 44
5 26 6 3 76
5 26 7 26 12
5 26 8 13 12
5 26 9 25 44
6 0 6 33 84
6 0 7 51 20
6 0 8 63 20
6 0 9 41 52
6 1 6 61 68
6 1 7 34 4
6 1 8 62 4
6 1 9 33 36
6 2 6 34 68
6 2 7 41 4
6 2 8 58 4
6 2 9 34 36
6 3 6 41 68
6 3 7 36 4
6 3 8 42 4
6 3 9 45 36
6 4 6 41 68
6 4 7 41 4
6 4 8 45 4
6 4 9 38 36
6 5 6 34 68
6 5 7 33 4
6 5 8 41 4
6 5 9 36 36
6 6 6 33 68
6 6 7 55 4
6 6 8 61 4
6 6 9 36 36
6 7 6 48 68
6 7 7 34 4
6 7 8 53 4
6 7 9 38 36
6 8 6 34 68
6 8 7 35 4
6 8 8 52 4
6 8 9 41 36
6 9 6 40 68
6 9 7 38 4
6 9 8 53 4
6 9 9 36 36
6 10 6 41 68
6 10 7 41 4
6 10 8 48 4
6 10 9 31 36
6 11 6 41 68
6 11 7 33 4
6 11 8 40 4
6 11 9 36 36
6 12 0 21 80
6 12 1 21 16
6 12 2 22 16
6 12 3 0 16
6 12 4 13 16
6 12 5 3 16
6 12 6 9 0
6 12 7 12 0
6 12 8 2 0
6 12 9 9 0
6 12 10 15 16
6 12 11 18 16
6 12 12 4 16
6 12 13 1 16
6 12 14 5 16
6 12 15 13 48
6 13 0 4 72
6 13 1 4 0
6 13 2 26 0
6 13 3 10 0
6 13 4 15 0
6 13 5 24 0
6 13 6 6 0
6 13 7 24 0
6 13 8 9 0
6 13 9 1 0
6 13 10 19 0
6 13 11 4 0
6 13 12 0 0
6 13 13 5 0
6 13 14 25 0
6 13 15 0 40
6 14 1 2 64
6 14 2 7 0
6 14 3 23 0
6 14 4 30 0
6 14 5 3 0
6 14 6 27 0
6 14 7 13 0
6 14 8 3 0
6 14 9 2 0
6 14 10 4 0
6 14 11 6 0
6 14 12 5 0
6 14 13 19 0
6 14 14 25 32
6 15 1 18 64
6 15 2 3 0
6 15 3 2 0
6 15 4 4 0
6 15 5 0 0
6 15 6 11 0
6 15 7 4 0
6 15 8 6 0
6 15 9 4 0
6 15 10 4 0
6 15 11 5 0
6 15 12 4 0
6 15 13 0 0
6 15 14 3 32
6 16 1 29 72
6 16 2 14 0
6 16 3 5 0
6 16 4 23 0
6 16 5 2 0
6 16 6 2 0
6 16 7 3 0
6 16 8 3 0
6 16 9 4 0
6 16 10 0 0
6 16 11 29 0
6 16 12 2 0
6 16 13 19 0
6 16 14 0 40
6 17 2 4 68
6 17 3 4 0
6 17 4 5 0
6 17 5 3 0
6 17 6 11 0
6 17 7 17 0
6 17 8 26 0
6 17 9 12 0
6 17 10 21 0
6 17 11 19 0
6 17 12 9 0
6 17 13 22 36
6 18 2 1 76
6 18 3 0 0
6 18 4 13 0
6 18 5 6 0
6 18 6 16 0
6 18 7 16 0
6 18 8 25 0
6 18 9 5 0
6 18 10 25 0
6 18 11 6 0
6 18 12 6 0
6 18 13 22 44
6 19 3 2 64
6 19 4 7 0
6 19 5 2 0
6 19 6 23 0
6 19 7 1 0
6 19 8 0 0
6 19 9 2 0
6 19 10 0 0
6 19 11 6 0
6 19 12 28 32
6 20 3 19 68
6 20 4 9 0
6 20 5 21 0
6 20 6 4 0
6 20 7 15 0
6 20 8 4 0
6 20 9 8 0
6 20 10 3 0
6 20 11 30 0
6 20 12 15 36
6 21 3 19 76
6 21 4 5 0
6 21 5 3 0
6 21 6 6 0
6 21 7 1 0
6 21 8 28 0
6 21 9 5 0
6 21 10 13 0
6 21 11 3 0
6 21 12 22 44
6 22 4 27 64
6 22 5 3 0
6 22 6 0 0
6 22 7 25 0
6 22 8 13 0
6 22 9 3 0
6 22 10 18 0
6 22 11 5 32
6 23 4 0 64
6 23 5 28 0
6 23 6 5 0
6 23 7 15 0
6 23 8 9 0
6 23 9 14 0
6 23 10 13 0
6 23 11 3 32
6 24 4 30 76
6 24 5 3 0
6 24 6 29 0
6 24 7 25 0
6 24 8 11 0
6 24 9 29 0
6 24 10 3 0
6 24 11 1 44
6 25 5 11 64
6 25 6 1 0
6 25 7 19 0
6 25 8 6 0
6 25 9 25 0
6 25 10 1 32
6 26 5 12 76
6 26 6 19 0
6 26 7 28 0
6 26 8 5 0
6 26 9 28 0
6 26 10 23 44
6 27 6 22 68
6 27 7 4 4
6 27 8 0 4
6 27 9 3 36
6 28 6 15 68
6 28 7 5 4
6 28 8 21 4
6 28 9 4 36
6 29 6 21 76
6 29 7 24 12
6 29 8 3 12
6 29 9 15 44
7 0 6 34 80
7 0 7 34 16
7 0 8 63 16
7 0 9 41 48
7 1 6 63 64
7 1 7 51 0
7 1 8 55 0
7 1 9 41 32
7 2 6 55 64
7 2 7 38 0
7 2 8 43 0
7 2 9 34 32
7 3 6 34 64
7 3 7 33 0
7 3 8 62 0
7 3 9 56 32
7 4 6 58 64
7 4 7 49 0
7 4 8 44 0
7 4 9 53 32
7 5 6 41 64
7 5 7 45 0
7 5 8 34 0
7 5 9 33 32
7 6 6 34 64
7 6 7 44 0
7 6 8 39 0
7 6 9 41 32
7 7 6 39 64
7 7 7 41 0
7 7 8 52 0
7 7 9 58 32
7 8 6 45 64
7 8 7 51 0
7 8 8 46 0
7 8 9 40 32
7 9 6 60 64
7 9 7 33 0
7 9 8 37 0
7 9 9 32 32
7 10 6 48 64
7 10 7 39 0
7 10 8 41 0
7 10 9 49 32
7 11 6 64 64
7 11 7 36 0
7 11 8 41 0
7 11 9 37 32
7 12 0 4 80
7 12 1 3 16
7 12 2 4 16
7 12 3 1 16
7 12 4 4 16
7 12 5 26 16
7 12 6 3 0
7 12 7 10 0
7 12 8 0 0
7 12 9 12 0
7 12 10 11 16
7 12 11 23 16
7 12 12 11 16
7 12 13 10 16
7 12 14 6 16
7 12 15 5 48
7 13 0 2 72
7 13 1 18 0
7 13 2 3 0
7 13 3 18 0
7 13 4 23 0
7 13 5 5 0
7 13 6 1 0
7 13 7 29 0
7 13 8 1 0
7 13 9 21 0
7 13 10 5 0
7 13 11 6 0
7 13 12 3 0
7 13 13 8 0
7 13 14 1 0
7 13 15 11 40
7 14 1 8 64
7 14 2 11 0
7 14 3 2 0
7 14 4 4 0
7 14 5 14 0
7 14 6 3 0
7 14 7 16 0
7 14 8 5 0
7 14 9 21 0
7 14 10 5 0
7 14 11 9 0
7 14 12 0 0
7 14 13 6 0
7 14 14 3 32
7 15 1 1 64
7 15 2 17 0
7 15 3 30 0
7 15 4 4 0
7 15 5 6 0
7 15 6 6 0
7 15 7 2 0
7 15 8 17 0
7 15 9 29 0
7 15 10 13 0
7 15 11 0 0
7 15 12 19 0
7 15 13 2 0
7 15 14 25 32
7 16 1 16 72
7 16 2 2 0
7 16 3 5 0
7 16 4 7 0
7 16 5 1 0
7 16 6 6 0
7 16 7 28 0
7 16 8 2 0
7 16 9 0 0
7 16 10 3 0
7 16 11 7 0
7 16 12 14 0
7 16 13 28 0
7 16 14 15 40
7 17 2 3 64
7 17 3 20 0
7 17 4 9 0
7 17 5 15 0
7 17 6 0 0
7 17 7 18 0
7 17 8 15 0
7 17 9 6 0
7 17 10 21 0
7 17 11 16 0
7 17 12 3 0
7 17 13 23 32
7 18 2 9 72
7 18 3 3 0
7 18 4 6 0
7 18 5 1 0
7 18 6 25 0
7 18 7 6 0
7 18 8 10 0
7 18 9 10 0
7 18 10 5 0
7 18 11 6 0
7 18 12 28 0
7 18 13 20 40
7 19 3 30 64
7 19 4 9 0
7 19 5 21 0
7 19 6 4 0
7 19 7 3 0
7 19 8 3 0
7 19 9 24 0
7 19 10 14 0
7 19 11 5 0
7 19 12 0 32
7 20 3 22 64
7 20 4 2 0
7 20 5 25 0
7 20 6 19 0
7 20 7 12 0
7 20 8 6 0
7 20 9 23 0
7 20 10 18 0
7 20 11 26 0
7 20 12 20 32
7 21 3 12 72
7 21 4 11 0
7 21 5 6 0
7 21 6 5 0
7 21 7 1 0
7 21 8 21 0
7 21 9 2 0
7 21 10 5 0
7 21 11 1 0
7 21 12 29 40
7 22 4 3 64
7 22 5 5 0
7 22 6 14 0
7 22 7 15 0
7 22 8 13 0
7 22 9 4 0
7 22 10 3 0
7 22 11 25 32
7 23 4 30 64
7 23 5 0 0
7 23 6 13 0
7 23 7 4 0
7 23 8 15 0
7 23 9 2 0
7 23 10 12 0
7 23 11 15 32
7 24 4 5 72
7 24 5 19 0
7 24 6 3 0
7 24 7 30 0
7 24 8 5 0
7 24 9 5 0
7 24 10 4 0
7 24 11 11 40
7 25 5 4 64
7 25 6 4 0
7 25 7 4 0
7 25 8 18 0
7 25 9 24 0
7 25 10 0 32
7 26 5 16 72
7 26 6 1 0
7 26 7 24 0
7 26 8 6 0
7 26 9 15 0
7 26 10 1 40
7 27 6 19 64
7 27 7 2 0
7 27 8 3 0
7 27 9 29 32
7 28 6 18 64
7 28 7 15 0
7 28 8 6 0
7 28 9 21 32
7 29 6 17 72
7 29 7 6 0
7 29 8 1 0
7 29 9 1 40
7 30 7 0 68
7 30 8 11 36
7 31 7 5 76
7 31 8 18 44
8 0 6 37 80
8 0 7 34 16
8 0 8 64 16
8 0 9 39 48
8 1 6 62 64
8 1 7 59 0
8 1 8 54 0
8 1 9 47 32
8 2 6 59 64
8 2 7 47 0
8 2 8 47 0
8 2 9 41 32
8 3 6 47 64
8 3 7 38 0
8 3 8 39 0
8 3 9 56 32
8 4 6 50 64
8 4 7 57 0
8 4 8 41 0
8 4 9 32 32
8 5 6 37 64
8 5 7 43 0
8 5 8 55 0
8 5 9 46 32
8 6 6 41 64
8 6 7 41 0
8 6 8 44 0
8 6 9 46 32
8 7 6 63 64
8 7 7 41 0
8 7 8 63 0
8 7 9 34 32
8 8 6 55 64
8 8 7 62 0
8 8 8 61 0
8 8 9 40 32
8 9 6 52 64
8 9 7 60 0
8 9 8 41 0
8 9 9 34 32
8 10 6 34 64
8 10 7 58 0
8 10 8 36 0
8 10 9 59 32
8 11 6 54 64
8 11 7 45 0
8 11 8 56 0
8 11 9 50 32
8 12 0 4 80
8 12 1 18 16
8 12 2 5 16
8 12 3 0 16
8 12 4 2 16
8 12 5 4 16
8 12 6 4 0
8 12 7 4 0
8 12 8 8 0
8 12 9 30 0
8 12 10 4 16
8 12 11 1 16
8 12 12 27 16
8 12 13 30 16
8 12 14 4 16
8 12 15 10 48
8 13 0 16 72
8 13 1 6 0
8 13 2 30 0
8 13 3 5 0
8 13 4 3 0
8 13 5 6 0
8 13 6 6 0
8 13 7 3 0
8 13 8 3 0
8 13 9 19 0
8 13 10 7 0
8 13 11 19 0
8 13 12 8 0
8 13 13 11 0
8 13 14 2 0
8 13 15 21 40
8 14 1 5 64
8 14 2 1 0
8 14 3 2 0
8 14 4 13 0
8 14 5 3 0
8 14 6 2 0
8 14 7 2 0
8 14 8 8 0
8 14 9 16 0
8 14 10 8 0
8 14 11 14 0
8 14 12 6 0
8 14 13 13 0
8 14 14 6 32
8 15 1 2 64
8 15 2 12 0
8 15 3 24 0
8 15 4 29 0
8 15 5 18 0
8 15 6 2 0
8 15 7 27 0
8 15 8 3 0
8 15 9 18 0
8 15 10 4 0
8 15 11 6 0
8 15 12 0 0
8 15 13 25 0
8 15 14 23 32
8 16 1 14 72
8 16 2 22 0
8 16 3 24 0
8 16 4 22 0
8 16 5 25 0
8 16 6 6 0
8 16 7 0 0
8 16 8 9 0
8 16 9 2 0
8 16 10 3 0
8 16 11 20 0
8 16 12 13 0
8 16 13 3 0
8 16 14 0 40
8 17 2 5 64
8 17 3 4 0
8 17 4 11 0
8 17 5 0 0
8 17 6 11 0
8 17 7 4 0
8 17 8 5 0
8 17 9 4 0
8 17 10 2 0
8 17 11 30 0
8 17 12 12 0
8 17 13 1 32
8 18 2 26 72
8 18 3 17 0
8 18 4 27 0
8 18 5 6 0
8 18 6 3 0
8 18 7 24 0
8 18 8 28 0
8 18 9 14 0
8 18 10 8 0
8 18 11 1 0
8 18 12 11 0
8 18 13 18 40
8 19 3 5 64
8 19 4 3 0
8 19 5 3 0
8 19 6 29 0
8 19 7 0 0
8 19 8 13 0
8 19 9 3 0
8 19 10 25 0
8 19 11 4 0
8 19 12 20 32
8 20 3 30 64
8 20 4 2 0
8 20 5 1 0
8 20 6 1 0
8 20 7 4 0
8 20 8 5 0
8 20 9 1 0
8 20 10 5 0
8 20 11 0 0
8 20 12 0 32
8 21 3 1 72
8 21 4 12 0
8 21 5 6 0
8 21 6 3 0
8 21 7 3 0
8 21 8 1 0
8 21 9 5 0
8 21 10 2 0
8 21 11 27 0
8 21 12 30 40
8 22 4 8 64
8 22 5 27 0
8 22 6 1 0
8 22 7 12 0
8 22 8 4 0
8 22 9 1 0
8 22 10 3 0
8 22 11 0 32
8 23 4 26 64
8 23 5 23 0
8 23 6 6 0
8 23 7 4 0
8 23 8 10 0
8 23 9 21 0
8 23 10 3 0
8 23 11 19 32
8 24 4 4 72
8 24 5 18 0
8 24 6 19 0
8 24 7 2 0
8 24 8 24 0
8 24 9 3 0
8 24 10 15 0
8 24 11 5 40
8 25 5 14 64
8 25 6 19 0
8 25 7 1 0
8 25 8 6 0
8 25 9 1 0
8 25 10 12 32
8 26 5 24 72
8 26 6 25 0
8 26 7 3 0
8 26 8 28 0
8 26 9 2 0
8 26 10 6 40
8 27 6 2 64
8 27 7 7 0
8 27 8 26 0
8 27 9 19 32
8 28 6 2 64
8 28 7 4 0
8 28 8 3 0
8 28 9 4 32
8 29 6 0 72
8 29 7 9 0
8 29 8 15 0
8 29 9 3 40
8 30 7 0 66
8 30 8 12 34
8 31 7 30 74
8 31 8 27 42
9 0 6 34 82
9 0 7 41 18
9 0 8 36 18
9 0 9 39 50
9 1 6 47 66
9 1 7 63 2
9 1 8 55 2
9 1 9 58 34
9 2 6 36 66
9 2 7 57 2
9 2 8 50 2
9 2 9 32 34
9 3 6 36 66
9 3 7 50 2
9 3 8 41 2
9 3 9 32 34
9 4 6 36 66
9 4 7 49 2
9 4 8 33 2
9 4 9 53 34
9 5 6 38 66
9 5 7 58 2
9 5 8 38 2
9 5 9 41 34
9 6 6 41 66
9 6 7 64 2
9 6 8 57 2
9 6 9 61 34
9 7 6 58 66
9 7 7 34 2
9 7 8 41 2
9 7 9 60 34
9 8 6 51 66
9 8 7 34 2
9 8 8 49 2
9 8 9 55 34
9 9 6 34 66
9 9 7 53 2
9 9 8 63 2
9 9 9 46 34
9 10 6 54 66
9 10 7 58 2
9 10 8 61 2
9 10 9 41 34
9 11 6 33 66
9 11 7 33 2
9 11 8 64 2
9 11 9 49 34
9 12 0 5 80
9 12 1 4 16
9 12 2 22 16
9 12 3 2 16
9 12 4 2 16
9 12 5 6 16
9 12 6 15 0
9 12 7 24 0
9 12 8 3 0
9 12 9 30 0
9 12 10 29 16
9 12 11 3 16
9 12 12 28 16
9 12 13 21 16
9 12 14 11 16
9 12 15 24 48
9 13 0 0 72
9 13 1 25 0
9 13 2 1 0
9 13 3 0 0
9 13 4 25 0
9 13 5 2 0
9 13 6 4 0
9 13 7 6 0
9 13 8 2 0
9 13 9 29 0
9 13 10 0 0
9 13 11 2 0
9 13 12 3 0
9 13 13 10 0
9 13 14 1 0
9 13 15 15 40
9 14 1 2 64
9 14 2 2 0
9 14 3 3 0
9 14 4 14 0
9 14 5 1 0
9 14 6 16 0
9 14 7 10 0
9 14 8 2 0
9 14 9 10 0
9 14 10 0 0
9 14 11 13 0
9 14 12 15 0
9 14 13 25 0
9 14 14 1 32
9 15 1 3 64
9 15 2 6 0
9 15 3 5 0
9 15 4 0 0
9 15 5 6 0
9 15 6 8 0
9 15 7 0 0
9 15 8 29 0
9 15 9 0 0
9 15 10 30 0
9 15 11 24 0
9 15 12 1 0
9 15 13 5 0
9 15 14 1 32
9 16 1 0 72
9 16 2 4 0
9 16 3 6 0
9 16 4 4 0
9 16 5 24 0
9 16 6 6 0
9 16 7 19 0
9 16 8 7 0
9 16 9 3 0
9 16 10 4 0
9 16 11 21 0
9 16 12 4 0
9 16 13 2 0
9 16 14 5 40
9 17 2 19 66
9 17 3 1 0
9 17 4 5 0
9 17 5 0 0
9 17 6 4 0
9 17 7 6 0
9 17 8 4 0
9 17 9 2 0
9 17 10 2 0
9 17 11 4 0
9 17 12 6 0
9 17 13 7 34
9 18 2 3 74
9 18 3 28 0
9 18 4 5 0
9 18 5 24 0
9 18 6 16 0
9 18 7 3 0
9 18 8 5 0
9 18 9 3 0
9 18 10 5 0
9 18 11 5 0
9 18 12 9 0
9 18 13 4 42
9 19 3 1 64
9 19 4 21 0
9 19 5 23 0
9 19 6 3 0
9 19 7 21 0
9 19 8 4 0
9 19 9 16 0
9 19 10 6 0
9 19 11 28 0
9 19 12 18 32
9 20 3 3 66
9 20 4 15 0
9 20 5 1 0
9 20 6 18 0
9 20 7 1 0
9 20 8 4 0
9 20 9 6 0
9 20 10 9 0
9 20 11 4 0
9 20 12 21 34
9 21 3 11 74
9 21 4 24 0
9 21 5 2 0
9 21 6 0 0
9 21 7 0 0
9 21 8 5 0
9 21 9 5 0
9 21 10 4 0
9 21 11 0 0
9 21 12 6 42
9 22 4 16 64
9 22 5 21 0
9 22 6 27 0
9 22 7 9 0
9 22 8 3 0
9 22 9 12 0
9 22 10 4 0
9 22 11 3 32
9 23 4 4 64
9 23 5 6 0
9 23 6 4 0
9 23 7 11 0
9 23 8 2 0
9 23 9 28 0
9 23 10 27 0
9 23 11 1 32
9 24 4 25 74
9 24 5 4 0
9 24 6 3 0
9 24 7 0 0
9 24 8 13 0
9 24 9 5 0
9 24 10 23 0
9 24 11 3 42
9 25 5 6 64
9 25 6 25 0
9 25 7 3 0
9 25 8 1 0
9 25 9 5 0
9 25 10 18 32
9 26 5 10 74
9 26 6 24 0
9 26 7 12 0
9 26 8 24 0
9 26 9 21 0
9 26 10 28 42
9 27 6 6 66
9 27 7 6 2
9 27 8 0 2
9 27 9 30 34
9 28 6 13 66
9 28 7 3 2
9 28 8 5 2
9 28 9 28 34
9 29 6 21 74
9 29 7 5 10
9 29 8 24 10
9 29 9 23 42
10 12 0 3 82
10 12 1 6 16
10 12 2 2 16
10 12 3 19 16
10 12 4 27 16
10 12 5 4 16
10 12 6 18 16
10 12 7 10 16
10 12 8 29 16
10 12 9 13 16
10 12 10 29 16
10 12 11 14 16
10 12 12 6 16
10 12 13 6 16
10 12 14 14 16
10 12 15 6 50
10 13 0 6 74
10 13 1 1 0
10 13 2 11 0
10 13 3 27 0
10 13 4 3 0
10 13 5 2 0
10 13 6 4 0
10 13 7 5 0
10 13 8 2 0
10 13 9 30 0
10 13 10 3 0
10 13 11 4 0
10 13 12 3 0
10 13 13 6 0
10 13 14 4 0
10 13 15 13 42
10 14 1 3 66
10 14 2 4 0
10 14 3 22 0
10 14 4 10 0
10 14 5 1 0
10 14 6 4 0
10 14 7 1 0
10 14 8 27 0
10 14 9 1 0
10 14 10 2 0
10 14 11 6 0
10 14 12 14 0
10 14 13 3 0
10 14 14 28 34
10 15 1 6 66
10 15 2 17 0
10 15 3 0 0
10 15 4 9 0
10 15 5 19 0
10 15 6 0 0
10 15 7 4 0
10 15 8 25 0
10 15 9 5 0
10 15 10 4 0
10 15 11 4 0
10 15 12 23 0
10 15 13 14 0
10 15 14 6 34
10 16 1 4 74
10 16 2 0 8
10 16 3 1 0
10 16 4 5 0
10 16 5 12 0
10 16 6 20 0
10 16 7 1 0
10 16 8 0 0
10 16 9 6 0
10 16 10 13 0
10 16 11 25 0
10 16 12 8 0
10 16 13 27 8
10 16 14 4 42
10 17 3 3 64
10 17 4 19 0
10 17 5 6 0
10 17 6 17 0
10 17 7 28 0
10 17 8 5 0
10 17 9 5 0
10 17 10 0 0
10 17 11 22 0
10 17 12 6 32
10 18 3 1 64
10 18 4 28 0
10 18 5 2 0
10 18 6 1 0
10 18 7 30 0
10 18 8 18 0
10 18 9 2 0
10 18 10 4 0
10 18 11 0 0
10 18 12 16 32
10 19 3 5 72
10 19 4 2 0
10 19 5 11 0
10 19 6 22 0
10 19 7 22 0
10 19 8 3 0
10 19 9 5 0
10 19 10 3 0
10 19 11 6 0
10 19 12 3 40
10 20 4 27 64
10 20 5 0 0
10 20 6 6 0
10 20 7 10 0
10 20 8 15 0
10 20 9 23 0
10 20 10 22 0
10 20 11 6 32
10 21 4 3 64
10 21 5 24 0
10 21 6 3 0
10 21 7 29 0
10 21 8 2 0
10 21 9 20 0
10 21 10 29 0
10 21 11 18 32
10 22 4 19 66
10 22 5 3 0
10 22 6 20 0
10 22 7 1 0
10 22 8 19 0
10 22 9 13 0
10 22 10 4 0
10 22 11 25 34
10 23 4 1 74
10 23 5 18 0
10 23 6 24 0
10 23 7 3 0
10 23 8 5 0
10 23 9 20 0
10 23 10 3 0
10 23 11 22 42
10 24 5 1 66
10 24 6 27 0
10 24 7 0 0
10 24 8 4 0
10 24 9 10 0
10 24 10 12 34
10 25 5 4 74
10 25 6 26 2
10 25 7 4 2
10 25 8 4 2
10 25 9 0 2
10 25 10 30 42
10 26 6 4 74
10 26 7 21 10
10 26 8 3 10
10 26 9 1 42
11 12 1 27 80
11 12 2 22 16
11 12 3 18 16
11 12 4 2 16
11 12 5 20 16
11 12 6 13 16
11 12 7 4 16
11 12 8 27 16
11 12 9 1 16
11 12 10 11 16
11 12 11 24 16
11 12 12 19 16
11 12 13 27 16
11 12 14 3 48
11 13 1 19 72
11 13 2 24 0
11 13 3 6 0
11 13 4 3 0
11 13 5 8 0
11 13 6 7 0
11 13 7 6 0
11 13 8 14 0
11 13 9 4 0
11 13 10 10 0
11 13 11 16 0
11 13 12 1 0
11 13 13 20 0
11 13 14 4 40
11 14 2 0 64
11 14 3 6 0
11 14 4 6 0
11 14 5 22 0
11 14 6 2 0
11 14 7 2 0
11 14 8 4 0
11 14 9 2 0
11 14 10 2 0
11 14 11 3 0
11 14 12 2 0
11 14 13 15 32
11 15 2 26 66
11 15 3 5 0
11 15 4 14 0
11 15 5 27 0
11 15 6 2 0
11 15 7 3 0
11 15 8 0 0
11 15 9 8 0
11 15 10 20 0
11 15 11 3 0
11 15 12 27 0
11 15 13 1 34
11 16 2 20 74
11 16 3 0 0
11 16 4 15 0
11 16 5 2 0
11 16 6 11 0
11 16 7 3 0
11 16 8 2 0
11 16 9 15 0
11 16 10 21 0
11 16 11 26 0
11 16 12 25 0
11 16 13 2 42
11 17 3 13 64
11 17 4 3 0
11 17 5 26 0
11 17 6 30 0
11 17 7 4 0
11 17 8 4 0
11 17 9 6 0
11 17 10 11 0
11 17 11 1 0
11 17 12 23 32
11 18 3 4 66
11 18 4 22 0
11 18 5 2 0
11 18 6 6 0
11 18 7 23 0
11 18 8 16 0
11 18 9 3 0
11 18 10 28 0
11 18 11 6 0
11 18 12 0 34
11 19 3 6 74
11 19 4 18 0
11 19 5 4 0
11 19 6 0 0
11 19 7 8 0
11 19 8 25 0
11 19 9 23 0
11 19 10 0 0
11 19 11 27 0
11 19 12 30 42
11 20 4 8 66
11 20 5 15 2
11 20 6 15 0
11 20 7 2 0
11 20 8 1 0
11 20 9 14 0
11 20 10 15 2
11 20 11 2 34
11 21 4 1 74
11 21 5 6 2
11 21 6 6 0
11 21 7 2 0
11 21 8 1 0
11 21 9 6 0
11 21 10 3 2
11 21 11 20 42
11 22 5 6 66
11 22 6 1 2
11 22 7 4 2
11 22 8 30 2
11 22 9 5 2
11 22 10 19 34
11 23 5 27 74
11 23 6 2 2
11 23 7 18 2
11 23 8 5 2
11 23 9 25 2
11 23 10 19 42
11 24 6 5 74
11 24 7 6 10
11 24 8 4 10
11 24 9 21 42
12 12 1 5 82
12 12 2 16 16
12 12 3 3 16
12 12 4 12 16
12 12 5 6 16
12 12 6 14 16
12 12 7 5 16
12 12 8 26 16
12 12 9 4 16
12 12 10 0 16
12 12 11 1 16
12 12 12 1 16
12 12 13 19 16
12 12 14 6 50
12 13 1 5 74
12 13 2 4 0
12 13 3 16 0
12 13 4 5 0
12 13 5 6 0
12 13 6 7 0
12 13 7 2 0
12 13 8 4 0
12 13 9 2 0
12 13 10 30 0
12 13 11 1 0
12 13 12 27 0
12 13 13 5 0
12 13 14 24 42
12 14 2 9 74
12 14 3 10 0
12 14 4 6 0
12 14 5 6 0
12 14 6 6 0
12 14 7 24 0
12 14 8 6 0
12 14 9 7 0
12 14 10 1 0
12 14 11 0 0
12 14 12 27 0
12 14 13 1 42
12 15 3 1 66
12 15 4 3 0
12 15 5 7 0
12 15 6 1 0
12 15 7 6 0
12 15 8 30 0
12 15 9 1 0
12 15 10 1 0
12 15 11 3 0
12 15 12 17 34
12 16 3 2 66
12 16 4 2 0
12 16 5 9 0
12 16 6 4 0
12 16 7 15 0
12 16 8 29 0
12 16 9 6 0
12 16 10 1 0
12 16 11 5 0
12 16 12 22 34
12 17 3 29 74
12 17 4 25 2
12 17 5 5 2
12 17 6 0 0
12 17 7 21 0
12 17 8 2 0
12 17 9 6 0
12 17 10 19 2
12 17 11 0 2
12 17 12 20 42
12 18 4 22 66
12 18 5 22 2
12 18 6 6 0
12 18 7 11 0
12 18 8 13 0
12 18 9 4 0
12 18 10 6 2
12 18 11 22 34
12 19 4 8 74
12 19 5 6 10
12 19 6 8 2
12 19 7 12 2
12 19 8 6 2
12 19 9 25 2
12 19 10 4 10
12 19 11 4 42
12 20 6 24 66
12 20 7 1 2
12 20 8 0 2
12 20 9 15 34
12 21 6 14 74
12 21 7 6 10
12 21 8 26 10
12 21 9 2 42
13 12 2 9 82
13 12 3 4 16
13 12 4 0 16
13 12 5 28 16
13 12 6 4 16
13 12 7 2 16
13 12 8 8 16
13 12 9 1 16
13 12 10 2 16
13 12 11 2 16
13 12 12 16 16
13 12 13 16 50
13 13 2 5 74
13 13 3 5 0
13 13 4 5 0
13 13 5 5 0
13 13 6 6 0
13 13 7 9 0
13 13 8 6 0
13 13 9 3 0
13 13 10 8 0
13 13 11 5 0
13 13 12 21 0
13 13 13 5 42
13 14 3 5 74
13 14 4 2 2
13 14 5 6 0
13 14 6 1 0
13 14 7 17 0
13 14 8 29 0
13 14 9 5 0
13 14 10 19 0
13 14 11 2 2
13 14 12 1 42
13 15 4 6 66
13 15 5 14 0
13 15 6 6 0
13 15 7 8 0
13 15 8 11 0
13 15 9 14 0
13 15 10 28 0
13 15 11 16 34
13 16 4 28 74
13 16 5 1 8
13 16 6 2 0
13 16 7 7 0
13 16 8 12 0
13 16 9 17 0
13 16 10 10 8
13 16 11 20 42
13 17 6 6 66
13 17 7 27 2
13 17 8 3 2
13 17 9 0 34
13 18 6 19 74
13 18 7 28 10
13 18 8 30 10
13 18 9 7 42
14 12 3 15 82
14 12 4 9 18
14 12 5 4 16
14 12 6 6 16
14 12 7 3 16
14 12 8 5 16
14 12 9 30 16
14 12 10 0 16
14 12 11 3 18
14 12 12 1 50
14 13 3 4 74
14 13 4 22 10
14 13 5 0 0
14 13 6 28 0
14 13 7 0 0
14 13 8 2 0
14 13 9 22 0
14 13 10 29 0
14 13 11 4 10
14 13 12 13 42
14 14 5 1 66
14 14 6 12 2
14 14 7 6 2
14 14 8 1 2
14 14 9 17 2
14 14 10 5 34
14 15 5 6 66
14 15 6 24 2
14 15 7 3 2
14 15 8 30 2
14 15 9 1 2
14 15 10 2 34
14 16 5 5 74
14 16 6 20 10
14 16 7 29 10
14 16 8 7 10
14 16 9 16 10
14 16 10 6 42
15 12 5 16 82
15 12 6 24 18
15 12 7 12 18
15 12 8 3 18
15 12 9 5 18
15 12 10 14 50
15 13 5 18 74
15 13 6 5 10
15 13 7 19 10
15 13 8 18 10
15 13 9 13 10
15 13 10 4 42
