Qubicle Exchange Format
Version 0.2
www.minddesk.com
16 32 16
32
0.000000 0.239216 0.000000
0.000000 0.243137 0.000000
0.000000 0.247059 0.000000
0.000000 0.250980 0.000000
0.000000 0.254902 0.000000
0.000000 0.258824 0.000000
0.000000 0.262745 0.000000
0.000000 0.266667 0.000000
0.003922 0.270588 0.003922
0.007843 0.270588 0.007843
0.011765 0.274510 0.011765
0.015686 0.278431 0.015686
0.019608 0.282353 0.019608
0.023529 0.282353 0.023529
0.027451 0.286275 0.027451
0.031373 0.290196 0.031373
0.035294 0.294118 0.035294
0.039216 0.294118 0.039216
0.043137 0.298039 0.043137
0.047059 0.301961 0.047059
0.050980 0.301961 0.050980
0.054902 0.305882 0.054902
0.058824 0.309804 0.058824
0.062745 0.313726 0.062745
0.066667 0.313726 0.066667
0.070588 0.317647 0.070588
0.074510 0.321569 0.074510
0.078431 0.325490 0.078431
0.082353 0.325490 0.082353
0.086275 0.329412 0.086275
0.090196 0.333333 0.090196
0.250980 0.172549 0.000000
0 19 7 6 124
0 20 10 4 116
0 21 9 3 92
0 21 10 0 44
0 22 7 17 124
0 23 11 25 124
0 25 7 3 116
0 25 9 2 84
0 25 10 1 60
0 26 6 6 92
0 26 7 4 12
0 26 8 27 28
0 26 9 8 44
1 18 5 19 124
1 19 7 11 80
1 19 8 2 60
1 20 3 4 124
1 20 6 4 84
1 20 7 6 44
1 20 10 7 80
1 20 11 2 52
1 21 4 3 84
1 21 5 14 20
1 21 6 23 36
1 21 9 12 80
1 21 10 22 0
1 21 11 4 4
1 21 12 4 52
1 22 4 3 76
1 22 5 23 12
1 22 6 1 4
1 22 7 10 24
1 22 8 4 20
1 22 9 20 4
1 22 10 3 4
1 22 11 6 4
1 22 12 1 36
1 23 6 19 108
1 23 8 3 76
1 23 9 14 4
1 23 10 3 4
1 23 11 3 0
1 23 12 12 36
1 24 5 25 124
1 24 9 9 68
1 24 10 0 4
1 24 11 9 12
1 24 12 4 44
1 25 7 2 80
1 25 8 22 20
1 25 9 22 0
1 25 10 8 40
1 26 6 8 80
1 26 7 3 8
1 26 8 5 8
1 26 9 4 40
1 27 5 5 92
1 27 6 13 44
2 17 5 9 84
2 17 6 30 20
2 17 7 14 52
2 17 10 6 124
2 18 3 27 116
2 18 5 25 64
2 18 6 0 4
2 18 7 12 4
2 18 8 2 20
2 18 9 27 52
2 18 12 14 124
2 19 3 29 68
2 19 4 2 20
2 19 5 0 4
2 19 6 24 4
2 19 7 8 0
2 19 8 2 0
2 19 9 15 36
2 20 2 21 84
2 20 3 20 0
2 20 4 3 4
2 20 5 29 4
2 20 6 12 0
2 20 7 9 0
2 20 8 6 4
2 20 9 2 4
2 20 10 14 16
2 20 11 2 16
2 20 12 25 52
2 21 2 5 76
2 21 3 24 12
2 21 4 1 0
2 21 5 26 0
2 21 6 15 0
2 21 7 23 4
2 21 8 8 4
2 21 9 19 0
2 21 10 9 0
2 21 11 14 0
2 21 12 2 0
2 21 13 24 52
2 22 4 13 72
2 22 5 4 0
2 22 6 18 0
2 22 7 13 0
2 22 8 9 0
2 22 9 6 0
2 22 10 17 0
2 22 11 5 0
2 22 12 6 0
2 22 13 16 44
2 23 5 2 68
2 23 6 5 0
2 23 7 1 4
2 23 8 4 0
2 23 9 19 0
2 23 10 0 0
2 23 11 23 0
2 23 12 2 32
2 24 4 3 84
2 24 5 10 0
2 24 6 27 4
2 24 7 2 4
2 24 8 16 4
2 24 9 22 0
2 24 10 1 0
2 24 11 15 0
2 24 12 17 40
2 25 3 15 92
2 25 4 0 4
2 25 5 5 4
2 25 6 5 4
2 25 7 12 0
2 25 8 2 0
2 25 9 5 0
2 25 10 9 0
2 25 11 3 44
2 26 4 4 76
2 26 5 5 4
2 26 6 3 0
2 26 7 11 0
2 26 8 9 0
2 26 9 6 0
2 26 10 6 36
2 27 5 3 64
2 27 6 18 0
2 27 7 6 12
2 27 8 0 4
2 27 9 17 4
2 27 10 1 4
2 27 11 5 60
2 28 5 10 76
2 28 6 14 44
2 28 8 4 76
2 28 9 28 12
2 28 10 27 44
3 16 5 9 84
3 16 6 22 20
3 16 7 4 20
3 16 8 7 20
3 16 9 18 20
3 16 10 5 52
3 17 4 1 84
3 17 5 4 0
3 17 6 9 0
3 17 7 12 0
3 17 8 4 4
3 17 9 3 4
3 17 10 28 0
3 17 11 29 20
3 17 12 7 52
3 18 2 6 84
3 18 3 6 16
3 18 4 1 4
3 18 5 22 0
3 18 6 5 0
3 18 7 3 0
3 18 8 6 0
3 18 9 3 0
3 18 10 3 12
3 18 11 5 4
3 18 12 0 0
3 18 13 6 52
3 19 2 19 68
3 19 3 3 0
3 19 4 30 0
3 19 5 5 0
3 19 6 27 0
3 19 7 3 0
3 19 8 5 0
3 19 9 5 32
3 19 11 2 68
3 19 12 12 4
3 19 13 29 36
3 20 1 3 84
3 20 2 3 0
3 20 3 12 0
3 20 4 4 0
3 20 5 30 0
3 20 6 18 0
3 20 7 11 0
3 20 8 16 0
3 20 9 5 0
3 20 10 6 16
3 20 11 1 0
3 20 12 22 0
3 20 13 24 4
3 20 14 20 60
3 21 1 1 68
3 21 2 4 0
3 21 3 21 0
3 21 4 5 0
3 21 5 2 0
3 21 6 0 0
3 21 7 17 0
3 21 8 6 0
3 21 9 2 0
3 21 10 28 0
3 21 11 7 0
3 21 12 13 0
3 21 13 7 32
3 22 1 3 78
3 22 2 29 14
3 22 3 1 12
3 22 4 1 8
3 22 5 6 0
3 22 6 19 0
3 22 7 5 0
3 22 8 3 0
3 22 9 11 0
3 22 10 16 0
3 22 11 6 0
3 22 12 4 0
3 22 13 3 32
3 23 5 3 64
3 23 6 23 0
3 23 7 3 0
3 23 8 8 0
3 23 9 27 0
3 23 10 3 0
3 23 11 2 0
3 23 12 30 0
3 23 13 3 36
3 24 4 14 80
3 24 5 9 0
3 24 6 15 0
3 24 7 6 0
3 24 8 12 0
3 24 9 3 0
3 24 10 5 0
3 24 11 5 0
3 24 12 3 0
3 24 13 11 4
3 24 14 1 60
3 25 2 19 92
3 25 3 1 16
3 25 4 5 0
3 25 5 30 0
3 25 6 1 0
3 25 7 6 0
3 25 8 8 0
3 25 9 1 0
3 25 10 1 0
3 25 11 17 0
3 25 12 27 12
3 25 13 2 44
3 26 3 30 68
3 26 4 13 0
3 26 5 22 0
3 26 6 11 0
3 26 7 22 0
3 26 8 24 0
3 26 9 30 0
3 26 10 2 0
3 26 11 21 36
3 27 3 1 76
3 27 4 6 4
3 27 5 7 0
3 27 6 18 0
3 27 7 5 0
3 27 8 0 0
3 27 9 29 0
3 27 10 5 0
3 27 11 1 32
3 28 4 5 76
3 28 5 12 0
3 28 6 22 0
3 28 7 30 4
3 28 8 18 0
3 28 9 5 0
3 28 10 13 0
3 28 11 19 12
3 28 12 16 60
3 29 5 1 76
3 29 6 18 12
3 29 7 9 12
3 29 8 5 12
3 29 9 4 12
3 29 10 5 44
4 15 6 21 84
4 15 7 3 20
4 15 8 0 20
4 15 9 8 52
4 16 4 15 84
4 16 5 1 16
4 16 6 5 0
4 16 7 17 0
4 16 8 26 0
4 16 9 2 0
4 16 10 9 16
4 16 11 1 52
4 17 4 19 64
4 17 5 28 0
4 17 6 20 0
4 17 7 20 0
4 17 8 2 0
4 17 9 2 0
4 17 10 5 0
4 17 11 25 0
4 17 12 6 48
4 18 2 15 80
4 18 3 9 16
4 18 4 17 0
4 18 5 6 0
4 18 6 0 0
4 18 7 3 0
4 18 8 5 0
4 18 9 13 0
4 18 10 3 0
4 18 11 6 0
4 18 12 5 0
4 18 13 4 50
4 19 1 5 84
4 19 2 1 0
4 19 3 13 0
4 19 4 6 0
4 19 5 6 0
4 19 6 3 0
4 19 7 11 0
4 19 8 20 0
4 19 9 23 0
4 19 10 10 4
4 19 11 6 0
4 19 12 20 0
4 19 13 3 2
4 19 14 26 54
4 20 1 21 64
4 20 2 29 0
4 20 3 1 0
4 20 4 19 0
4 20 5 6 0
4 20 6 9 0
4 20 7 15 0
4 20 8 24 0
4 20 9 12 0
4 20 10 4 0
4 20 11 7 0
4 20 12 5 0
4 20 13 29 0
4 20 14 8 40
4 21 0 28 92
4 21 1 25 8
4 21 2 7 8
4 21 3 30 0
4 21 4 20 0
4 21 5 22 0
4 21 6 24 0
4 21 7 5 0
4 21 8 30 0
4 21 9 22 0
4 21 10 5 0
4 21 11 1 0
4 21 12 12 0
4 21 13 17 32
4 22 3 5 72
4 22 4 4 0
4 22 5 5 0
4 22 6 4 0
4 22 7 28 0
4 22 8 5 0
4 22 9 1 0
4 22 10 3 0
4 22 11 4 0
4 22 12 3 0
4 22 13 1 32
4 23 4 0 68
4 23 5 19 0
4 23 6 2 0
4 23 7 1 0
4 23 8 23 0
4 23 9 0 0
4 23 10 5 0
4 23 11 2 0
4 23 12 5 0
4 23 13 7 0
4 23 14 25 20
4 23 15 1 52
4 24 2 22 84
4 24 3 8 20
4 24 4 1 0
4 24 5 2 0
4 24 6 2 0
4 24 7 6 0
4 24 8 23 0
4 24 9 8 0
4 24 10 13 0
4 24 11 3 0
4 24 12 20 0
4 24 13 1 0
4 24 14 6 8
4 24 15 11 46
4 25 2 1 64
4 25 3 24 0
4 25 4 1 0
4 25 5 1 0
4 25 6 1 0
4 25 7 4 0
4 25 8 6 0
4 25 9 5 0
4 25 10 16 0
4 25 11 7 0
4 25 12 25 0
4 25 13 16 32
4 26 1 5 94
4 26 2 1 12
4 26 3 4 0
4 26 4 25 0
4 26 5 6 0
4 26 6 17 0
4 26 7 6 0
4 26 8 17 0
4 26 9 2 0
4 26 10 23 0
4 26 11 2 0
4 26 12 15 4
4 26 13 15 12
4 26 14 27 60
4 27 3 3 64
4 27 4 28 0
4 27 5 4 0
4 27 6 8 0
4 27 7 5 0
4 27 8 10 0
4 27 9 1 0
4 27 10 6 0
4 27 11 4 0
4 27 12 7 36
4 28 3 29 76
4 28 4 23 0
4 28 5 1 0
4 28 6 5 0
4 28 7 26 0
4 28 8 5 0
4 28 9 30 0
4 28 10 24 0
4 28 11 6 0
4 28 12 3 40
4 29 4 10 76
4 29 5 29 8
4 29 6 1 8
4 29 7 11 0
4 29 8 1 0
4 29 9 2 0
4 29 10 5 8
4 29 11 3 44
4 30 7 20 78
4 30 8 5 12
4 30 9 5 44
5 15 5 6 84
5 15 6 10 16
5 15 7 2 16
5 15 8 1 16
5 15 9 25 16
5 15 10 0 52
5 16 4 5 80
5 16 5 28 0
5 16 6 22 0
5 16 7 4 0
5 16 8 20 0
5 16 9 22 0
5 16 10 1 0
5 16 11 15 16
5 16 12 30 52
5 17 2 4 84
5 17 3 24 20
5 17 4 3 0
5 17 5 0 0
5 17 6 5 0
5 17 7 0 0
5 17 8 26 0
5 17 9 4 0
5 17 10 20 0
5 17 11 10 0
5 17 12 17 0
5 17 13 4 62
5 18 1 0 84
5 18 2 30 0
5 18 3 19 0
5 18 4 0 0
5 18 5 10 0
5 18 6 8 0
5 18 7 5 0
5 18 8 0 0
5 18 9 19 0
5 18 10 1 0
5 18 11 19 0
5 18 12 3 32
5 19 1 22 64
5 19 2 16 0
5 19 3 6 0
5 19 4 17 0
5 19 5 7 0
5 19 6 6 0
5 19 7 22 0
5 19 8 2 0
5 19 9 1 0
5 19 10 6 0
5 19 11 16 0
5 19 12 25 32
5 20 0 2 84
5 20 1 5 0
5 20 2 23 0
5 20 3 6 0
5 20 4 2 0
5 20 5 2 0
5 20 6 28 0
5 20 7 11 0
5 20 8 30 0
5 20 9 0 0
5 20 10 4 0
5 20 11 10 0
5 20 12 25 0
5 20 13 6 16
5 20 14 6 48
5 21 0 4 74
5 21 1 19 8
5 21 2 16 0
5 21 3 25 0
5 21 4 5 0
5 21 5 25 0
5 21 6 2 0
5 21 7 17 0
5 21 8 3 0
5 21 9 2 0
5 21 10 20 0
5 21 11 20 0
5 21 12 4 0
5 21 13 3 0
5 21 14 28 36
5 22 2 9 76
5 22 3 0 0
5 22 4 25 0
5 22 5 26 0
5 22 6 6 0
5 22 7 6 0
5 22 8 4 0
5 22 9 15 0
5 22 10 29 0
5 22 11 24 0
5 22 12 0 0
5 22 13 3 0
5 22 14 4 36
5 23 0 4 94
5 23 1 8 52
5 23 3 3 68
5 23 4 18 0
5 23 5 0 0
5 23 6 4 0
5 23 7 23 0
5 23 8 26 0
5 23 9 5 0
5 23 10 0 0
5 23 11 1 0
5 23 12 22 0
5 23 13 6 0
5 23 14 5 0
5 23 15 9 58
5 24 1 5 76
5 24 2 0 16
5 24 3 4 0
5 24 4 22 0
5 24 5 3 0
5 24 6 4 0
5 24 7 10 0
5 24 8 5 0
5 24 9 4 0
5 24 10 25 0
5 24 11 3 0
5 24 12 4 0
5 24 13 4 0
5 24 14 16 32
5 25 2 11 64
5 25 3 6 0
5 25 4 3 0
5 25 5 20 0
5 25 6 0 0
5 25 7 5 0
5 25 8 7 0
5 25 9 1 0
5 25 10 3 0
5 25 11 10 0
5 25 12 6 0
5 25 13 12 0
5 25 14 30 36
5 26 2 8 64
5 26 3 4 0
5 26 4 18 0
5 26 5 26 0
5 26 6 4 0
5 26 7 21 0
5 26 8 2 0
5 26 9 4 0
5 26 10 6 0
5 26 11 27 0
5 26 12 27 0
5 26 13 30 0
5 26 14 0 32
5 27 2 11 76
5 27 3 20 0
5 27 4 15 0
5 27 5 6 0
5 27 6 0 0
5 27 7 5 0
5 27 8 0 0
5 27 9 5 0
5 27 10 1 0
5 27 11 1 0
5 27 12 12 0
5 27 13 13 12
5 27 14 14 44
5 28 3 5 66
5 28 4 17 0
5 28 5 1 0
5 28 6 4 0
5 28 7 2 0
5 28 8 5 0
5 28 9 4 0
5 28 10 1 0
5 28 11 5 0
5 28 12 2 32
5 29 3 2 76
5 29 4 1 8
5 29 5 20 0
5 29 6 17 8
5 29 7 2 8
5 29 8 4 0
5 29 9 21 0
5 29 10 4 0
5 29 11 16 8
5 29 12 13 44
5 30 5 1 108
5 30 8 3 74
5 30 9 28 8
5 30 10 27 44
6 0 6 31 84
6 0 7 31 20
6 0 8 31 20
6 0 9 31 52
6 1 6 31 68
6 1 7 31 4
6 1 8 31 4
6 1 9 31 36
6 2 6 31 68
6 2 7 31 4
6 2 8 31 4
6 2 9 31 36
6 3 6 31 70
6 3 7 31 4
6 3 8 31 4
6 3 9 31 36
6 4 6 31 70
6 4 7 31 4
6 4 8 31 4
6 4 9 31 38
6 5 6 31 70
6 5 7 31 4
6 5 8 31 4
6 5 9 31 38
6 6 6 31 68
6 6 7 31 4
6 6 8 31 4
6 6 9 31 46
6 7 6 31 68
6 7 7 31 4
6 7 8 31 44
6 7 9 31 46
6 8 6 31 76
6 8 7 31 44
6 8 8 31 36
6 8 9 31 100
6 9 6 31 76
6 9 7 31 68
6 9 8 31 116
6 9 9 31 52
6 10 6 31 76
6 10 7 31 84
6 10 8 31 36
6 10 9 31 52
6 11 6 31 70
6 11 7 31 68
6 11 8 31 36
6 11 9 31 52
6 12 6 31 84
6 12 7 31 4
6 12 8 31 4
6 12 9 31 54
6 13 6 31 68
6 13 7 31 4
6 13 8 31 4
6 13 9 31 36
6 14 6 31 68
6 14 7 31 4
6 14 8 31 4
6 14 9 31 36
6 15 4 0 86
6 15 5 3 16
6 15 6 5 0
6 15 7 30 0
6 15 8 1 0
6 15 9 3 0
6 15 10 14 16
6 15 11 5 52
6 16 4 9 64
6 16 5 0 0
6 16 6 6 0
6 16 7 2 0
6 16 8 6 0
6 16 9 11 0
6 16 10 13 0
6 16 11 30 0
6 16 12 4 48
6 17 2 13 80
6 17 3 7 16
6 17 4 3 0
6 17 5 0 0
6 17 6 24 0
6 17 7 9 0
6 17 8 13 0
6 17 9 6 0
6 17 10 5 0
6 17 11 0 0
6 17 12 5 32
6 18 1 27 80
6 18 2 29 0
6 18 3 29 0
6 18 4 11 0
6 18 5 4 0
6 18 6 2 0
6 18 7 6 0
6 18 8 26 0
6 18 9 13 0
6 18 10 7 0
6 18 11 1 0
6 18 12 4 32
6 19 0 30 84
6 19 1 25 0
6 19 2 2 0
6 19 3 3 0
6 19 4 13 0
6 19 5 19 0
6 19 6 4 0
6 19 7 30 0
6 19 8 30 0
6 19 9 2 0
6 19 10 19 0
6 19 11 6 0
6 19 12 5 0
6 19 13 19 52
6 20 0 6 74
6 20 1 21 0
6 20 2 3 0
6 20 3 2 0
6 20 4 4 0
6 20 5 27 0
6 20 6 6 0
6 20 7 0 0
6 20 8 7 0
6 20 9 6 0
6 20 10 22 0
6 20 11 6 0
6 20 12 26 0
6 20 13 19 0
6 20 14 6 16
6 20 15 6 54
6 21 1 27 72
6 21 2 1 0
6 21 3 12 0
6 21 4 22 0
6 21 5 24 0
6 21 6 20 0
6 21 7 6 0
6 21 8 2 0
6 21 9 3 0
6 21 10 24 0
6 21 11 5 0
6 21 12 22 0
6 21 13 23 0
6 21 14 3 0
6 21 15 30 46
6 22 2 3 64
6 22 3 8 0
6 22 4 16 0
6 22 5 0 0
6 22 6 6 0
6 22 7 3 0
6 22 8 1 0
6 22 9 7 0
6 22 10 0 0
6 22 11 29 0
6 22 12 6 0
6 22 13 11 0
6 22 14 23 32
6 23 1 14 80
6 23 2 1 4
6 23 3 23 0
6 23 4 9 0
6 23 5 27 0
6 23 6 3 0
6 23 7 4 0
6 23 8 19 0
6 23 9 4 0
6 23 10 5 0
6 23 11 4 0
6 23 12 6 0
6 23 13 5 0
6 23 14 16 32
6 24 1 10 72
6 24 2 3 0
6 24 3 1 0
6 24 4 4 0
6 24 5 30 0
6 24 6 27 0
6 24 7 18 0
6 24 8 1 0
6 24 9 1 0
6 24 10 21 0
6 24 11 6 0
6 24 12 28 0
6 24 13 21 0
6 24 14 6 32
6 25 2 24 64
6 25 3 22 0
6 25 4 15 0
6 25 5 4 0
6 25 6 18 0
6 25 7 5 0
6 25 8 26 0
6 25 9 12 0
6 25 10 14 0
6 25 11 19 0
6 25 12 3 0
6 25 13 7 0
6 25 14 2 0
6 25 15 24 52
6 26 1 15 92
6 26 2 9 0
6 26 3 0 0
6 26 4 13 0
6 26 5 2 0
6 26 6 27 0
6 26 7 3 0
6 26 8 0 0
6 26 9 8 0
6 26 10 2 0
6 26 11 23 0
6 26 12 5 0
6 26 13 1 0
6 26 14 4 0
6 26 15 10 44
6 27 2 3 72
6 27 3 0 8
6 27 4 1 0
6 27 5 2 0
6 27 6 8 0
6 27 7 13 0
6 27 8 29 0
6 27 9 5 0
6 27 10 0 0
6 27 11 10 0
6 27 12 5 0
6 27 13 4 8
6 27 14 6 40
6 28 4 19 64
6 28 5 18 0
6 28 6 6 0
6 28 7 6 0
6 28 8 2 0
6 28 9 2 0
6 28 10 2 0
6 28 11 14 0
6 28 12 25 32
6 29 3 30 88
6 29 4 2 0
6 29 5 1 0
6 29 6 4 0
6 29 7 5 8
6 29 8 3 8
6 29 9 3 0
6 29 10 8 0
6 29 11 29 8
6 29 12 10 40
6 30 4 14 76
6 30 5 27 8
6 30 6 25 44
6 30 9 0 74
6 30 10 22 40
7 0 6 31 80
7 0 7 31 16
7 0 8 31 16
7 0 9 31 48
7 1 6 31 64
7 1 7 31 0
7 1 8 31 0
7 1 9 31 32
7 2 6 31 72
7 2 7 31 0
7 2 8 31 0
7 2 9 31 32
7 3 6 31 64
7 3 7 31 64
7 3 8 31 0
7 3 9 31 42
7 4 6 31 80
7 4 7 31 64
7 4 8 31 32
7 4 9 31 42
7 5 6 31 80
7 5 7 31 64
7 5 8 31 32
7 5 9 31 34
7 6 6 31 82
7 6 7 31 0
7 6 8 31 32
7 6 9 31 50
7 7 6 31 64
7 7 7 31 0
7 7 8 31 32
7 7 9 31 50
7 8 6 31 64
7 8 7 31 0
7 8 8 31 4
7 8 9 31 54
7 9 6 31 68
7 9 7 31 4
7 9 8 31 0
7 9 9 31 38
7 10 6 31 76
7 10 7 31 0
7 10 8 31 0
7 10 9 31 46
7 11 6 31 64
7 11 7 31 64
7 11 8 31 32
7 11 9 31 46
7 12 6 31 80
7 12 7 31 0
7 12 8 31 32
7 12 9 31 48
7 13 6 31 64
7 13 7 31 0
7 13 8 31 0
7 13 9 31 48
7 14 6 31 64
7 14 7 31 0
7 14 8 31 0
7 14 9 31 32
7 15 5 8 80
7 15 6 17 0
7 15 7 14 0
7 15 8 4 0
7 15 9 23 0
7 15 10 8 16
7 15 11 29 48
7 16 4 21 82
7 16 5 17 0
7 16 6 21 0
7 16 7 22 0
7 16 8 19 0
7 16 9 22 0
7 16 10 1 0
7 16 11 6 0
7 16 12 25 50
7 17 2 4 80
7 17 3 12 16
7 17 4 25 0
7 17 5 8 0
7 17 6 4 0
7 17 7 29 0
7 17 8 6 0
7 17 9 23 0
7 17 10 3 0
7 17 11 6 0
7 17 12 0 32
7 18 1 6 82
7 18 2 19 0
7 18 3 0 0
7 18 4 13 0
7 18 5 3 0
7 18 6 6 0
7 18 7 11 0
7 18 8 14 0
7 18 9 0 0
7 18 10 2 0
7 18 11 13 0
7 18 12 20 0
7 18 13 0 20
7 18 14 17 52
7 19 0 2 88
7 19 1 1 0
7 19 2 4 0
7 19 3 12 0
7 19 4 2 0
7 19 5 6 0
7 19 6 4 0
7 19 7 1 0
7 19 8 3 0
7 19 9 13 0
7 19 10 26 0
7 19 11 28 0
7 19 12 0 0
7 19 13 8 0
7 19 14 2 4
7 19 15 23 60
7 20 1 1 66
7 20 2 4 0
7 20 3 27 0
7 20 4 3 0
7 20 5 2 0
7 20 6 4 0
7 20 7 11 0
7 20 8 26 0
7 20 9 3 0
7 20 10 2 0
7 20 11 4 0
7 20 12 6 0
7 20 13 3 0
7 20 14 0 32
7 21 1 3 72
7 21 2 1 0
7 21 3 29 0
7 21 4 1 0
7 21 5 25 0
7 21 6 30 0
7 21 7 22 0
7 21 8 15 0
7 21 9 0 0
7 21 10 3 0
7 21 11 14 0
7 21 12 24 0
7 21 13 6 0
7 21 14 7 32
7 22 2 1 64
7 22 3 17 0
7 22 4 25 0
7 22 5 0 0
7 22 6 6 0
7 22 7 5 0
7 22 8 17 0
7 22 9 5 0
7 22 10 18 0
7 22 11 5 0
7 22 12 9 0
7 22 13 3 0
7 22 14 4 34
7 23 1 15 80
7 23 2 24 0
7 23 3 18 0
7 23 4 5 0
7 23 5 30 0
7 23 6 1 0
7 23 7 0 0
7 23 8 3 0
7 23 9 29 0
7 23 10 12 0
7 23 11 1 0
7 23 12 1 0
7 23 13 8 0
7 23 14 18 34
7 24 0 2 92
7 24 1 8 0
7 24 2 0 0
7 24 3 2 0
7 24 4 20 0
7 24 5 4 0
7 24 6 26 0
7 24 7 2 0
7 24 8 2 0
7 24 9 4 0
7 24 10 5 0
7 24 11 18 0
7 24 12 26 0
7 24 13 24 0
7 24 14 17 0
7 24 15 11 52
7 25 1 18 68
7 25 2 8 0
7 25 3 1 0
7 25 4 4 0
7 25 5 16 0
7 25 6 5 0
7 25 7 23 0
7 25 8 25 0
7 25 9 0 0
7 25 10 21 0
7 25 11 27 0
7 25 12 3 0
7 25 13 1 0
7 25 14 28 0
7 25 15 1 32
7 26 0 1 92
7 26 1 7 8
7 26 2 0 0
7 26 3 5 0
7 26 4 10 0
7 26 5 1 0
7 26 6 21 0
7 26 7 23 0
7 26 8 11 0
7 26 9 3 0
7 26 10 10 0
7 26 11 2 0
7 26 12 2 0
7 26 13 15 0
7 26 14 10 0
7 26 15 8 40
7 27 2 16 72
7 27 3 5 8
7 27 4 5 0
7 27 5 6 0
7 27 6 1 0
7 27 7 2 0
7 27 8 3 0
7 27 9 30 0
7 27 10 27 0
7 27 11 19 0
7 27 12 0 0
7 27 13 2 0
7 27 14 5 40
7 28 4 6 64
7 28 5 8 0
7 28 6 1 0
7 28 7 3 0
7 28 8 4 0
7 28 9 3 0
7 28 10 0 0
7 28 11 19 0
7 28 12 8 0
7 28 13 4 44
7 29 3 5 88
7 29 4 14 0
7 29 5 4 0
7 29 6 27 0
7 29 7 4 0
7 29 8 6 8
7 29 9 27 8
7 29 10 17 0
7 29 11 3 8
7 29 12 6 42
7 30 4 5 72
7 30 5 5 8
7 30 6 2 8
7 30 7 5 44
7 30 10 28 106
8 0 6 31 80
8 0 7 31 16
8 0 8 31 16
8 0 9 31 48
8 1 6 31 64
8 1 7 31 0
8 1 8 31 0
8 1 9 31 32
8 2 6 31 64
8 2 7 31 0
8 2 8 31 0
8 2 9 31 40
8 3 6 31 68
8 3 7 31 0
8 3 8 31 32
8 3 9 31 40
8 4 6 31 76
8 4 7 31 0
8 4 8 31 32
8 4 9 31 56
8 5 6 31 78
8 5 7 31 64
8 5 8 31 34
8 5 9 31 60
8 6 6 31 82
8 6 7 31 66
8 6 8 31 34
8 6 9 31 44
8 7 6 31 82
8 7 7 31 2
8 7 8 31 34
8 7 9 31 44
8 8 6 31 66
8 8 7 31 2
8 8 8 31 34
8 8 9 31 40
8 9 6 31 66
8 9 7 31 0
8 9 8 31 34
8 9 9 31 40
8 10 6 31 66
8 10 7 31 2
8 10 8 31 34
8 10 9 31 40
8 11 6 31 70
8 11 7 31 2
8 11 8 31 34
8 11 9 31 36
8 12 6 31 64
8 12 7 31 0
8 12 8 31 0
8 12 9 31 52
8 13 6 31 64
8 13 7 31 0
8 13 8 31 0
8 13 9 31 32
8 14 6 31 64
8 14 7 31 0
8 14 8 31 0
8 14 9 31 32
8 15 4 25 92
8 15 5 11 16
8 15 6 3 0
8 15 7 30 0
8 15 8 8 0
8 15 9 11 0
8 15 10 1 16
8 15 11 4 50
8 16 5 5 64
8 16 6 2 0
8 16 7 25 0
8 16 8 1 0
8 16 9 28 0
8 16 10 30 0
8 16 11 5 32
8 17 2 24 82
8 17 3 1 16
8 17 4 26 16
8 17 5 1 0
8 17 6 1 0
8 17 7 29 0
8 17 8 28 0
8 17 9 4 0
8 17 10 14 0
8 17 11 5 0
8 17 12 9 16
8 17 13 14 52
8 18 2 15 64
8 18 3 2 0
8 18 4 1 0
8 18 5 10 0
8 18 6 18 0
8 18 7 22 0
8 18 8 25 0
8 18 9 6 0
8 18 10 2 0
8 18 11 10 0
8 18 12 20 0
8 18 13 4 0
8 18 14 0 48
8 19 0 6 90
8 19 1 6 26
8 19 2 3 0
8 19 3 22 0
8 19 4 1 0
8 19 5 12 0
8 19 6 25 0
8 19 7 4 0
8 19 8 20 0
8 19 9 3 0
8 19 10 6 0
8 19 11 7 0
8 19 12 9 0
8 19 13 5 0
8 19 14 13 0
8 19 15 1 48
8 20 2 26 64
8 20 3 2 0
8 20 4 4 0
8 20 5 17 0
8 20 6 24 0
8 20 7 5 0
8 20 8 3 0
8 20 9 15 0
8 20 10 3 0
8 20 11 11 0
8 20 12 4 0
8 20 13 2 0
8 20 14 21 0
8 20 15 5 44
8 21 1 3 88
8 21 2 2 0
8 21 3 6 0
8 21 4 6 0
8 21 5 21 0
8 21 6 10 0
8 21 7 1 0
8 21 8 6 0
8 21 9 3 0
8 21 10 0 0
8 21 11 26 0
8 21 12 29 0
8 21 13 11 0
8 21 14 6 40
8 22 2 10 64
8 22 3 18 0
8 22 4 0 0
8 22 5 0 0
8 22 6 3 0
8 22 7 2 0
8 22 8 12 0
8 22 9 2 0
8 22 10 27 0
8 22 11 2 0
8 22 12 3 0
8 22 13 4 32
8 23 0 16 84
8 23 1 22 16
8 23 2 1 0
8 23 3 1 0
8 23 4 1 0
8 23 5 6 0
8 23 6 0 0
8 23 7 5 0
8 23 8 4 0
8 23 9 7 0
8 23 10 10 0
8 23 11 4 0
8 23 12 11 0
8 23 13 29 32
8 24 0 30 72
8 24 1 29 0
8 24 2 21 0
8 24 3 4 0
8 24 4 6 0
8 24 5 21 0
8 24 6 12 0
8 24 7 6 0
8 24 8 13 0
8 24 9 6 0
8 24 10 4 0
8 24 11 0 0
8 24 12 12 0
8 24 13 1 0
8 24 14 18 16
8 24 15 7 50
8 25 1 4 64
8 25 2 2 0
8 25 3 16 0
8 25 4 19 0
8 25 5 27 0
8 25 6 21 0
8 25 7 6 0
8 25 8 6 0
8 25 9 9 0
8 25 10 29 0
8 25 11 3 0
8 25 12 2 0
8 25 13 20 0
8 25 14 13 0
8 25 15 28 32
8 26 0 22 88
8 26 1 0 8
8 26 2 3 0
8 26 3 0 0
8 26 4 11 0
8 26 5 3 0
8 26 6 14 0
8 26 7 0 0
8 26 8 2 0
8 26 9 0 0
8 26 10 3 0
8 26 11 10 0
8 26 12 0 0
8 26 13 21 0
8 26 14 15 0
8 26 15 7 40
8 27 2 24 72
8 27 3 2 8
8 27 4 3 0
8 27 5 1 0
8 27 6 4 0
8 27 7 9 0
8 27 8 27 0
8 27 9 21 0
8 27 10 7 0
8 27 11 4 0
8 27 12 1 0
8 27 13 2 0
8 27 14 2 40
8 28 4 18 64
8 28 5 17 0
8 28 6 25 0
8 28 7 3 0
8 28 8 22 0
8 28 9 6 0
8 28 10 18 0
8 28 11 21 0
8 28 12 9 8
8 28 13 5 40
8 29 3 0 88
8 29 4 18 0
8 29 5 1 0
8 29 6 2 0
8 29 7 6 0
8 29 8 12 0
8 29 9 1 8
8 29 10 2 8
8 29 11 2 40
8 30 4 13 72
8 30 5 4 8
8 30 6 22 8
8 30 7 4 8
8 30 8 17 44
9 0 6 31 82
9 0 7 31 18
9 0 8 31 18
9 0 9 31 50
9 1 6 31 66
9 1 7 31 2
9 1 8 31 2
9 1 9 31 34
9 2 6 31 66
9 2 7 31 2
9 2 8 31 2
9 2 9 31 34
9 3 6 31 66
9 3 7 31 2
9 3 8 31 2
9 3 9 31 38
9 4 6 31 74
9 4 7 31 2
9 4 8 31 10
9 4 9 31 38
9 5 6 31 78
9 5 7 31 106
9 5 8 31 10
9 5 9 31 102
9 6 6 31 78
9 6 7 31 106
9 6 8 31 74
9 6 9 31 102
9 7 6 31 74
9 7 7 31 106
9 7 8 31 74
9 7 9 31 102
9 8 6 31 66
9 8 7 31 98
9 8 8 31 10
9 8 9 31 102
9 9 6 31 90
9 9 7 31 122
9 9 8 31 10
9 9 9 31 102
9 10 6 31 106
9 10 7 31 106
9 10 8 31 90
9 10 9 31 102
9 11 6 31 98
9 11 7 31 98
9 11 8 31 82
9 11 9 31 102
9 12 6 31 82
9 12 7 31 18
9 12 8 31 18
9 12 9 31 34
9 13 6 31 66
9 13 7 31 2
9 13 8 31 2
9 13 9 31 34
9 14 6 31 66
9 14 7 31 2
9 14 8 31 2
9 14 9 31 34
9 15 4 5 82
9 15 5 6 16
9 15 6 5 0
9 15 7 17 0
9 15 8 1 0
9 15 9 9 0
9 15 10 4 48
9 16 4 5 68
9 16 5 19 0
9 16 6 9 0
9 16 7 9 0
9 16 8 6 0
9 16 9 25 0
9 16 10 2 0
9 16 11 13 50
9 17 3 23 80
9 17 4 3 0
9 17 5 27 0
9 17 6 12 0
9 17 7 25 0
9 17 8 5 0
9 17 9 5 0
9 17 10 5 0
9 17 11 15 0
9 17 12 27 16
9 17 13 28 48
9 18 2 18 80
9 18 3 27 0
9 18 4 2 0
9 18 5 0 0
9 18 6 22 0
9 18 7 2 0
9 18 8 10 0
9 18 9 3 0
9 18 10 5 0
9 18 11 26 0
9 18 12 3 0
9 18 13 3 0
9 18 14 4 48
9 19 2 4 64
9 19 3 28 0
9 19 4 4 0
9 19 5 5 0
9 19 6 21 0
9 19 7 3 0
9 19 8 11 0
9 19 9 18 0
9 19 10 23 0
9 19 11 2 0
9 19 12 6 0
9 19 13 6 0
9 19 14 6 0
9 19 15 23 50
9 20 1 2 84
9 20 2 1 0
9 20 3 15 0
9 20 4 1 0
9 20 5 27 0
9 20 6 28 0
9 20 7 21 0
9 20 8 18 0
9 20 9 6 0
9 20 10 22 0
9 20 11 3 0
9 20 12 26 0
9 20 13 26 0
9 20 14 14 2
9 20 15 0 42
9 21 1 0 66
9 21 2 24 0
9 21 3 16 0
9 21 4 20 0
9 21 5 6 0
9 21 6 6 0
9 21 7 0 0
9 21 8 19 0
9 21 9 25 0
9 21 10 6 0
9 21 11 2 0
9 21 12 3 0
9 21 13 15 0
9 21 14 7 42
9 22 1 12 68
9 22 2 2 0
9 22 3 0 0
9 22 4 1 0
9 22 5 8 0
9 22 6 6 0
9 22 7 8 0
9 22 8 18 0
9 22 9 30 0
9 22 10 7 0
9 22 11 25 0
9 22 12 2 0
9 22 13 1 32
9 23 0 22 80
9 23 1 20 0
9 23 2 0 0
9 23 3 4 0
9 23 4 5 0
9 23 5 3 0
9 23 6 23 0
9 23 7 10 0
9 23 8 22 0
9 23 9 25 0
9 23 10 5 0
9 23 11 2 0
9 23 12 27 0
9 23 13 6 32
9 24 0 3 72
9 24 1 5 0
9 24 2 2 0
9 24 3 17 0
9 24 4 6 0
9 24 5 18 0
9 24 6 5 0
9 24 7 5 0
9 24 8 30 0
9 24 9 17 0
9 24 10 1 0
9 24 11 27 0
9 24 12 23 0
9 24 13 8 0
9 24 14 0 48
9 25 1 4 64
9 25 2 14 0
9 25 3 1 0
9 25 4 26 0
9 25 5 6 0
9 25 6 5 0
9 25 7 1 0
9 25 8 3 0
9 25 9 3 0
9 25 10 1 0
9 25 11 5 0
9 25 12 4 0
9 25 13 30 0
9 25 14 7 0
9 25 15 3 50
9 26 0 30 90
9 26 1 6 0
9 26 2 27 0
9 26 3 4 0
9 26 4 0 0
9 26 5 1 0
9 26 6 1 0
9 26 7 6 0
9 26 8 3 0
9 26 9 11 0
9 26 10 19 0
9 26 11 1 0
9 26 12 4 0
9 26 13 2 0
9 26 14 17 0
9 26 15 4 42
9 27 1 4 76
9 27 2 0 8
9 27 3 2 8
9 27 4 26 0
9 27 5 2 0
9 27 6 3 0
9 27 7 26 0
9 27 8 15 0
9 27 9 17 0
9 27 10 0 0
9 27 11 13 0
9 27 12 25 0
9 27 13 5 0
9 27 14 11 42
9 28 4 4 64
9 28 5 3 0
9 28 6 3 0
9 28 7 21 0
9 28 8 11 0
9 28 9 15 0
9 28 10 5 0
9 28 11 19 0
9 28 12 4 10
9 28 13 6 42
9 29 3 0 90
9 29 4 7 0
9 29 5 4 0
9 29 6 1 0
9 29 7 5 0
9 29 8 3 0
9 29 9 14 0
9 29 10 10 8
9 29 11 30 42
9 30 4 9 74
9 30 5 15 8
9 30 6 6 8
9 30 7 4 8
9 30 8 1 8
9 30 9 6 44
10 15 5 8 82
10 15 6 5 16
10 15 7 6 16
10 15 8 3 16
10 15 9 16 16
10 15 10 3 50
10 16 4 4 82
10 16 5 28 0
10 16 6 1 0
10 16 7 30 0
10 16 8 23 0
10 16 9 6 0
10 16 10 26 34
10 16 12 6 118
10 17 3 6 80
10 17 4 4 0
10 17 5 3 0
10 17 6 5 0
10 17 7 7 0
10 17 8 4 0
10 17 9 17 0
10 17 10 10 0
10 17 11 27 16
10 17 12 15 0
10 17 13 30 50
10 18 2 5 82
10 18 3 10 0
10 18 4 4 0
10 18 5 3 0
10 18 6 6 0
10 18 7 2 0
10 18 8 1 0
10 18 9 27 0
10 18 10 15 0
10 18 11 18 0
10 18 12 2 0
10 18 13 1 0
10 18 14 1 50
10 19 2 3 64
10 19 3 3 0
10 19 4 26 0
10 19 5 1 0
10 19 6 5 0
10 19 7 4 0
10 19 8 6 0
10 19 9 12 0
10 19 10 25 0
10 19 11 27 0
10 19 12 0 0
10 19 13 9 0
10 19 14 1 42
10 20 1 1 90
10 20 2 18 0
10 20 3 2 0
10 20 4 22 0
10 20 5 3 0
10 20 6 6 0
10 20 7 16 0
10 20 8 13 0
10 20 9 3 0
10 20 10 3 0
10 20 11 4 0
10 20 12 22 0
10 20 13 1 32
10 21 2 14 64
10 21 3 4 0
10 21 4 26 0
10 21 5 11 0
10 21 6 2 0
10 21 7 1 0
10 21 8 8 0
10 21 9 2 0
10 21 10 17 0
10 21 11 7 0
10 21 12 4 0
10 21 13 5 32
10 22 1 5 82
10 22 2 23 0
10 22 3 5 0
10 22 4 5 0
10 22 5 6 0
10 22 6 2 0
10 22 7 18 0
10 22 8 14 0
10 22 9 9 0
10 22 10 7 0
10 22 11 5 0
10 22 12 10 0
10 22 13 19 0
10 22 14 2 52
10 23 0 0 80
10 23 1 0 0
10 23 2 24 0
10 23 3 10 0
10 23 4 16 0
10 23 5 22 0
10 23 6 14 0
10 23 7 4 0
10 23 8 9 0
10 23 9 1 0
10 23 10 28 0
10 23 11 13 0
10 23 12 6 0
10 23 13 10 0
10 23 14 7 36
10 24 0 4 64
10 24 1 7 0
10 24 2 3 0
10 24 3 30 0
10 24 4 0 0
10 24 5 15 0
10 24 6 4 0
10 24 7 16 0
10 24 8 5 0
10 24 9 19 0
10 24 10 6 0
10 24 11 17 0
10 24 12 2 0
10 24 13 16 0
10 24 14 28 32
10 25 0 1 78
10 25 1 29 0
10 25 2 3 0
10 25 3 26 0
10 25 4 17 0
10 25 5 17 0
10 25 6 0 0
10 25 7 3 0
10 25 8 26 0
10 25 9 24 0
10 25 10 14 0
10 25 11 6 0
10 25 12 12 0
10 25 13 0 0
10 25 14 7 34
10 26 1 21 64
10 26 2 13 0
10 26 3 2 0
10 26 4 5 0
10 26 5 18 0
10 26 6 6 0
10 26 7 2 0
10 26 8 5 0
10 26 9 4 0
10 26 10 3 0
10 26 11 30 0
10 26 12 6 2
10 26 13 5 0
10 26 14 15 42
10 27 1 26 74
10 27 2 2 8
10 27 3 5 0
10 27 4 19 0
10 27 5 6 0
10 27 6 24 0
10 27 7 5 0
10 27 8 18 0
10 27 9 25 0
10 27 10 5 0
10 27 11 1 0
10 27 12 12 8
10 27 13 1 42
10 28 3 11 78
10 28 4 12 0
10 28 5 24 0
10 28 6 3 0
10 28 7 23 0
10 28 8 6 0
10 28 9 5 0
10 28 10 3 0
10 28 11 28 40
10 29 4 0 72
10 29 5 25 0
10 29 6 5 0
10 29 7 3 0
10 29 8 6 0
10 29 9 13 0
10 29 10 4 32
10 30 5 17 74
10 30 6 23 8
10 30 7 21 8
10 30 8 4 8
10 30 9 4 10
10 30 10 1 46
11 15 6 13 82
11 15 7 1 18
11 15 8 13 18
11 15 9 15 50
11 16 5 24 80
11 16 6 5 0
11 16 7 8 0
11 16 8 29 2
11 16 9 15 34
11 17 3 30 80
11 17 4 6 18
11 17 5 0 0
11 17 6 29 0
11 17 7 1 0
11 17 8 1 0
11 17 9 19 0
11 17 10 5 16
11 17 11 8 16
11 17 12 0 48
11 18 3 22 64
11 18 4 0 0
11 18 5 6 0
11 18 6 18 0
11 18 7 26 0
11 18 8 4 0
11 18 9 1 0
11 18 10 17 0
11 18 11 3 0
11 18 12 10 0
11 18 13 9 50
11 19 2 18 82
11 19 3 1 0
11 19 4 2 0
11 19 5 2 0
11 19 6 2 0
11 19 7 28 0
11 19 8 4 0
11 19 9 4 0
11 19 10 30 0
11 19 11 17 0
11 19 12 1 2
11 19 13 8 34
11 20 2 5 64
11 20 3 8 0
11 20 4 29 0
11 20 5 26 0
11 20 6 6 0
11 20 7 5 0
11 20 8 6 0
11 20 9 0 0
11 20 10 1 0
11 20 11 29 0
11 20 12 2 0
11 20 13 1 34
11 21 2 20 64
11 21 3 30 0
11 21 4 19 0
11 21 5 20 0
11 21 6 15 0
11 21 7 1 0
11 21 8 18 0
11 21 9 2 0
11 21 10 1 0
11 21 11 4 0
11 21 12 5 0
11 21 13 18 32
11 21 15 9 118
11 22 2 28 66
11 22 3 5 0
11 22 4 26 0
11 22 5 28 0
11 22 6 5 0
11 22 7 2 0
11 22 8 26 0
11 22 9 23 0
11 22 10 3 0
11 22 11 20 0
11 22 12 6 0
11 22 13 23 2
11 22 14 13 18
11 22 15 20 46
11 23 0 1 82
11 23 1 28 18
11 23 2 4 2
11 23 3 14 0
11 23 4 24 0
11 23 5 28 0
11 23 6 6 0
11 23 7 3 0
11 23 8 26 0
11 23 9 2 0
11 23 10 1 0
11 23 11 14 0
11 23 12 1 0
11 23 13 6 0
11 23 14 13 34
11 24 0 29 74
11 24 1 13 0
11 24 2 1 0
11 24 3 23 0
11 24 4 15 0
11 24 5 6 0
11 24 6 4 0
11 24 7 2 0
11 24 8 3 0
11 24 9 6 0
11 24 10 15 0
11 24 11 19 0
11 24 12 5 0
11 24 13 6 0
11 24 14 3 10
11 24 15 24 62
11 25 1 2 64
11 25 2 24 0
11 25 3 7 0
11 25 4 22 0
11 25 5 4 0
11 25 6 13 0
11 25 7 22 0
11 25 8 27 0
11 25 9 5 0
11 25 10 13 0
11 25 11 1 0
11 25 12 13 10
11 25 13 26 34
11 26 1 20 74
11 26 2 15 0
11 26 3 5 0
11 26 4 16 0
11 26 5 2 0
11 26 6 2 0
11 26 7 2 0
11 26 8 0 0
11 26 9 13 0
11 26 10 4 0
11 26 11 29 32
11 26 13 22 106
11 27 2 3 72
11 27 3 30 8
11 27 4 1 0
11 27 5 26 0
11 27 6 7 0
11 27 7 1 0
11 27 8 2 0
11 27 9 17 0
11 27 10 6 0
11 27 11 3 0
11 27 12 6 50
11 28 4 4 66
11 28 5 5 0
11 28 6 11 0
11 28 7 6 0
11 28 8 6 0
11 28 9 1 0
11 28 10 16 0
11 28 11 21 2
11 28 12 5 46
11 29 4 22 74
11 29 5 3 8
11 29 6 28 0
11 29 7 13 0
11 29 8 19 0
11 29 9 2 8
11 29 10 5 10
11 29 11 1 46
11 30 6 4 74
11 30 7 2 10
11 30 8 5 42
12 16 5 23 82
12 16 6 2 18
12 16 7 16 50
12 17 3 13 114
12 17 5 6 66
12 17 6 20 2
12 17 7 3 2
12 17 8 19 18
12 17 9 2 16
12 17 10 13 16
12 17 11 2 18
12 17 12 12 50
12 18 2 17 94
12 18 3 4 0
12 18 4 1 18
12 18 5 12 2
12 18 6 7 0
12 18 7 23 0
12 18 8 4 2
12 18 9 3 2
12 18 10 6 2
12 18 11 10 2
12 18 12 0 42
12 19 3 3 64
12 19 4 1 0
12 19 5 15 2
12 19 6 6 0
12 19 7 11 0
12 19 8 5 0
12 19 9 14 0
12 19 10 1 0
12 19 11 5 34
12 20 2 24 82
12 20 3 15 0
12 20 4 7 0
12 20 5 6 0
12 20 6 5 0
12 20 7 5 0
12 20 8 0 0
12 20 9 16 0
12 20 10 3 0
12 20 11 3 0
12 20 12 3 48
12 21 2 1 74
12 21 3 3 0
12 21 4 22 0
12 21 5 22 0
12 21 6 0 0
12 21 7 8 0
12 21 8 28 0
12 21 9 25 0
12 21 10 3 0
12 21 11 4 0
12 21 12 11 0
12 21 13 5 56
12 22 3 29 64
12 22 4 5 0
12 22 5 6 0
12 22 6 18 0
12 22 7 23 0
12 22 8 2 0
12 22 9 13 0
12 22 10 29 0
12 22 11 24 0
12 22 12 3 32
12 23 3 1 66
12 23 4 22 0
12 23 5 29 0
12 23 6 17 0
12 23 7 9 0
12 23 8 7 0
12 23 9 6 0
12 23 10 17 0
12 23 11 25 0
12 23 12 6 0
12 23 13 6 50
12 24 1 29 82
12 24 2 3 18
12 24 3 28 0
12 24 4 13 0
12 24 5 2 0
12 24 6 6 0
12 24 7 4 0
12 24 8 11 0
12 24 9 1 0
12 24 10 6 0
12 24 11 26 0
12 24 12 19 8
12 24 13 25 42
12 25 1 7 74
12 25 2 6 0
12 25 3 24 0
12 25 4 20 0
12 25 5 9 2
12 25 6 10 0
12 25 7 24 0
12 25 8 3 0
12 25 9 5 0
12 25 10 1 0
12 25 11 1 32
12 25 14 26 126
12 26 2 12 66
12 26 3 4 0
12 26 4 4 2
12 26 5 6 0
12 26 6 3 0
12 26 7 12 0
12 26 8 29 0
12 26 9 19 0
12 26 10 5 0
12 26 11 5 32
12 27 2 30 74
12 27 3 2 8
12 27 4 11 10
12 27 5 10 0
12 27 6 17 0
12 27 7 0 0
12 27 8 6 0
12 27 9 3 0
12 27 10 3 0
12 27 11 22 40
12 28 5 2 66
12 28 6 6 2
12 28 7 4 0
12 28 8 6 0
12 28 9 12 0
12 28 10 3 40
12 29 5 23 74
12 29 6 0 10
12 29 7 2 10
12 29 8 9 10
12 29 9 24 42
13 17 9 13 90
13 17 10 4 58
13 18 3 4 114
13 18 6 0 82
13 18 7 25 50
13 19 3 26 66
13 19 4 9 50
13 19 6 25 66
13 19 7 22 2
13 19 8 0 18
13 19 9 18 16
13 19 10 1 48
13 20 3 26 64
13 20 4 14 0
13 20 5 4 16
13 20 6 2 0
13 20 7 18 0
13 20 8 26 0
13 20 9 14 0
13 20 10 3 0
13 20 11 27 16
13 20 12 1 16
13 20 13 3 54
13 21 3 6 64
13 21 4 2 0
13 21 5 5 0
13 21 6 5 0
13 21 7 1 2
13 21 8 4 0
13 21 9 1 0
13 21 10 8 0
13 21 11 7 0
13 21 12 4 0
13 21 13 6 42
13 22 3 11 72
13 22 4 0 0
13 22 5 6 0
13 22 6 5 0
13 22 7 10 0
13 22 8 6 0
13 22 9 28 0
13 22 10 20 0
13 22 11 6 0
13 22 12 6 32
13 23 4 2 64
13 23 5 11 0
13 23 6 27 0
13 23 7 1 0
13 23 8 11 0
13 23 9 6 0
13 23 10 27 0
13 23 11 25 0
13 23 12 10 34
13 24 3 5 82
13 24 4 8 0
13 24 5 28 8
13 24 6 22 0
13 24 7 4 0
13 24 8 6 0
13 24 9 3 2
13 24 10 6 2
13 24 11 15 0
13 24 12 1 42
13 25 2 28 90
13 25 3 14 0
13 25 4 6 42
13 25 6 13 64
13 25 7 4 0
13 25 8 6 0
13 25 9 2 0
13 25 10 13 0
13 25 11 18 34
13 26 3 24 98
13 26 5 19 82
13 26 6 4 0
13 26 7 20 0
13 26 8 4 0
13 26 9 4 0
13 26 10 5 0
13 26 11 4 34
13 27 3 5 106
13 27 5 6 72
13 27 6 9 10
13 27 7 5 2
13 27 8 10 0
13 27 9 4 0
13 27 10 19 0
13 27 11 4 42
13 28 7 9 74
13 28 8 28 10
13 28 9 27 10
13 28 10 4 42
14 19 9 18 80
14 19 10 19 18
14 19 11 24 54
14 20 3 23 82
14 20 4 0 18
14 20 5 29 18
14 20 6 3 18
14 20 7 25 26
14 20 8 6 16
14 20 9 16 0
14 20 10 14 0
14 20 11 27 2
14 20 12 16 50
14 21 3 11 66
14 21 4 6 0
14 21 5 4 0
14 21 6 26 34
14 21 8 16 64
14 21 9 1 0
14 21 10 1 0
14 21 11 18 0
14 21 12 2 34
14 22 3 5 74
14 22 4 1 0
14 22 5 4 0
14 22 6 18 2
14 22 7 0 18
14 22 8 10 2
14 22 9 19 0
14 22 10 10 0
14 22 11 15 0
14 22 12 4 42
14 23 4 8 64
14 23 5 8 2
14 23 6 22 2
14 23 7 12 0
14 23 8 18 2
14 23 9 0 10
14 23 10 22 10
14 23 11 4 34
14 24 4 13 74
14 24 5 1 10
14 24 6 6 0
14 24 7 0 2
14 24 8 24 34
14 24 11 3 106
14 25 3 30 122
14 25 6 10 66
14 25 7 18 2
14 25 8 11 0
14 25 9 14 16
14 25 10 5 50
14 25 12 23 126
14 26 6 0 72
14 26 7 19 8
14 26 8 5 0
14 26 9 1 0
14 26 10 5 34
14 27 5 1 122
14 27 8 4 74
14 27 9 29 10
14 27 10 12 42
15 19 6 3 126
15 19 9 7 114
15 20 8 1 82
15 20 9 1 2
15 20 10 11 50
15 21 4 0 82
15 21 5 28 50
15 21 8 2 74
15 21 9 21 2
15 21 10 0 2
15 21 11 30 50
15 22 4 6 66
15 22 5 13 42
15 22 9 12 74
15 22 10 2 10
15 22 11 14 42
15 23 4 6 106
15 23 7 0 122
15 24 6 0 122
15 25 8 21 82
15 25 9 5 50
15 26 6 21 90
15 26 7 14 26
15 26 8 2 10
15 26 9 22 42
