Qubicle Exchange Format
Version 0.2
www.minddesk.com
8 8 8
19
0.000000 0.000000 0.000000
0.000000 0.211765 0.070588
0.000000 0.215686 0.070588
0.000000 0.219608 0.070588
0.000000 0.223529 0.074510
0.000000 0.231373 0.074510
0.000000 0.235294 0.078431
0.007843 0.243137 0.086275
0.019608 0.250980 0.098039
0.043137 0.266667 0.117647
0.054902 0.278431 0.129412
0.074510 0.294118 0.149020
0.078431 0.294118 0.152941
0.082353 0.298039 0.156863
0.847059 0.156863 0.000000
0.933333 0.933333 0.933333
0.941176 0.666667 0.235294
0.988235 0.737255 0.690196
1.000000 1.000000 1.000000
1 5 3 16 92
1 5 4 16 60
2 0 2 16 124
2 0 5 16 124
2 2 2 18 84
2 2 3 18 20
2 2 4 18 20
2 2 5 18 52
2 3 1 15 84
2 3 2 15 4
2 3 3 15 4
2 3 4 15 4
2 3 5 15 4
2 3 6 15 52
2 4 1 15 76
2 4 2 15 4
2 4 3 15 4
2 4 4 15 4
2 4 5 15 4
2 4 6 15 44
2 5 2 15 68
2 5 3 15 0
2 5 4 15 0
2 5 5 15 36
2 6 2 0 76
2 6 3 15 12
2 6 4 15 12
2 6 5 0 44
3 0 2 16 112
3 0 5 16 112
3 1 2 18 100
3 1 5 18 100
3 2 2 18 64
3 2 3 18 16
3 2 4 18 16
3 2 5 18 32
3 3 1 15 80
3 3 2 18 0
3 3 3 18 0
3 3 4 17 0
3 3 5 18 0
3 3 6 15 48
3 4 1 15 72
3 4 2 17 0
3 4 3 17 0
3 4 4 17 0
3 4 5 17 0
3 4 6 15 40
3 5 2 15 64
3 5 3 13 0
3 5 4 2 0
3 5 5 15 32
3 6 2 15 72
3 6 3 11 0
3 6 4 9 0
3 6 5 15 40
3 7 3 14 76
3 7 4 14 44
4 0 2 16 114
4 0 5 16 114
4 1 2 18 98
4 1 5 18 98
4 2 2 18 64
4 2 3 18 16
4 2 4 18 16
4 2 5 18 32
4 3 1 15 80
4 3 2 18 0
4 3 3 18 0
4 3 4 17 0
4 3 5 18 0
4 3 6 15 48
4 4 1 15 72
4 4 2 17 0
4 4 3 17 0
4 4 4 4 0
4 4 5 10 0
4 4 6 15 40
4 5 2 15 64
4 5 3 3 0
4 5 4 1 0
4 5 5 15 32
4 6 2 15 72
4 6 3 8 0
4 6 4 5 0
4 6 5 15 40
4 7 3 14 74
4 7 4 14 42
5 2 2 18 82
5 2 3 18 18
5 2 4 18 18
5 2 5 18 50
5 3 1 15 82
5 3 2 18 0
5 3 3 18 0
5 3 4 18 0
5 3 5 18 0
5 3 6 15 50
5 4 1 15 74
5 4 2 17 0
5 4 3 7 0
5 4 4 12 0
5 4 5 6 0
5 4 6 15 42
5 5 2 15 66
5 5 3 15 2
5 5 4 15 2
5 5 5 15 34
5 6 2 15 74
5 6 3 15 10
5 6 4 15 10
5 6 5 15 42
6 3 2 15 82
6 3 3 15 18
6 3 4 15 18
6 3 5 15 50
6 4 2 15 74
6 4 3 15 10
6 4 4 15 10
6 4 5 15 42
