Qubicle Exchange Format
Version 0.2
www.minddesk.com
8 8 8
17
0.000000 0.239216 0.000000
0.000000 0.243137 0.000000
0.000000 0.247059 0.000000
0.000000 0.250980 0.000000
0.000000 0.254902 0.000000
0.000000 0.258824 0.000000
0.000000 0.262745 0.000000
0.000000 0.266667 0.000000
0.003922 0.270588 0.003922
0.007843 0.270588 0.007843
0.015686 0.278431 0.015686
0.027451 0.286275 0.027451
0.031373 0.290196 0.031373
0.054902 0.305882 0.054902
0.070588 0.317647 0.070588
0.933333 0.933333 0.933333
1.000000 0.070588 0.000000
2 0 3 9 86
2 0 4 9 54
2 1 2 4 126
2 1 3 15 126
2 1 4 15 126
2 1 5 4 126
2 2 2 14 92
2 2 3 10 4
2 2 4 7 4
2 2 5 1 60
2 3 3 12 76
2 3 4 6 44
3 0 1 4 126
3 0 2 4 126
3 0 3 9 126
3 0 4 9 126
3 0 5 9 84
3 0 6 9 60
3 1 2 7 116
3 1 3 9 126
3 1 4 2 80
3 1 5 0 36
3 2 2 8 72
3 2 3 3 16
3 2 4 4 0
3 2 5 10 40
3 3 2 16 126
3 3 3 5 72
3 3 4 0 40
3 3 5 16 126
4 0 1 9 126
4 0 2 9 126
4 0 3 9 94
4 0 4 9 22
4 0 5 3 18
4 0 6 9 58
4 1 2 1 114
4 1 3 9 126
4 1 4 3 66
4 1 5 13 34
4 2 2 0 66
4 2 3 2 18
4 2 4 11 2
4 2 5 8 34
4 3 1 9 126
4 3 2 6 78
4 3 3 4 10
4 3 4 5 10
4 3 5 1 46
4 3 6 9 126
4 4 1 9 126
4 4 2 9 126
4 4 5 9 126
4 4 6 9 126
4 5 1 9 126
4 5 2 9 126
4 5 5 9 126
4 5 6 9 126
5 0 3 9 126
5 0 4 9 126
5 1 3 9 126
5 1 4 9 126
