Qubicle Exchange Format
Version 0.2
www.minddesk.com
8 8 8
30
0.000000 0.239216 0.000000
0.000000 0.243137 0.000000
0.000000 0.247059 0.000000
0.000000 0.250980 0.000000
0.000000 0.254902 0.000000
0.000000 0.258824 0.000000
0.000000 0.262745 0.000000
0.000000 0.266667 0.000000
0.003922 0.270588 0.003922
0.007843 0.270588 0.007843
0.011765 0.274510 0.011765
0.015686 0.278431 0.015686
0.019608 0.282353 0.019608
0.023529 0.282353 0.023529
0.027451 0.286275 0.027451
0.031373 0.290196 0.031373
0.035294 0.294118 0.035294
0.039216 0.294118 0.039216
0.043137 0.298039 0.043137
0.050980 0.301961 0.050980
0.054902 0.305882 0.054902
0.058824 0.309804 0.058824
0.066667 0.313726 0.066667
0.070588 0.317647 0.070588
0.078431 0.325490 0.078431
0.082353 0.325490 0.082353
0.086275 0.329412 0.086275
0.090196 0.333333 0.090196
0.913725 0.000000 0.000000
0.992157 0.019608 0.019608
2 0 1 24 118
2 0 5 22 118
2 1 1 1 68
2 1 2 7 20
2 1 3 3 20
2 1 4 23 20
2 1 5 10 36
2 2 1 0 68
2 2 2 8 4
2 2 3 23 4
2 2 4 6 4
2 2 5 9 36
2 3 1 6 76
2 3 2 21 12
2 3 3 27 12
2 3 4 15 12
2 3 5 3 4
2 3 6 19 20
2 3 7 26 60
2 4 5 4 68
2 4 6 29 44
2 5 5 1 110
3 1 1 25 80
3 1 2 26 16
3 1 3 4 16
3 1 4 6 16
3 1 5 23 48
3 2 1 2 64
3 2 2 3 0
3 2 3 11 0
3 2 4 4 0
3 2 5 6 32
3 3 0 6 92
3 3 1 4 8
3 3 2 5 8
3 3 3 15 8
3 3 4 3 8
3 3 5 13 0
3 3 6 15 16
3 3 7 1 48
3 4 5 25 72
3 4 6 18 8
3 4 7 4 44
4 1 1 3 80
4 1 2 2 16
4 1 3 5 16
4 1 4 5 16
4 1 5 3 48
4 2 1 14 64
4 2 2 4 0
4 2 3 7 0
4 2 4 25 0
4 2 5 4 32
4 3 0 2 90
4 3 1 5 8
4 3 2 0 8
4 3 3 6 8
4 3 4 18 8
4 3 5 1 0
4 3 6 26 16
4 3 7 5 48
4 4 5 4 72
4 4 6 11 8
4 4 7 17 42
5 0 1 3 118
5 0 5 10 118
5 1 1 20 66
5 1 2 0 18
5 1 3 27 18
5 1 4 11 18
5 1 5 16 34
5 2 1 8 66
5 2 2 11 2
5 2 3 1 2
5 2 4 25 2
5 2 5 4 34
5 3 1 1 74
5 3 2 3 10
5 3 3 12 10
5 3 4 5 10
5 3 5 17 2
5 3 6 11 18
5 3 7 21 58
5 4 5 27 66
5 4 6 28 42
5 5 5 4 110
