Qubicle Exchange Format
Version 0.2
www.minddesk.com
8 8 8
25
0.000000 0.000000 0.000000
0.000000 0.211765 0.070588
0.000000 0.215686 0.070588
0.000000 0.219608 0.070588
0.000000 0.223529 0.074510
0.000000 0.227451 0.074510
0.000000 0.231373 0.074510
0.000000 0.235294 0.078431
0.007843 0.243137 0.086275
0.015686 0.247059 0.094118
0.019608 0.250980 0.098039
0.027451 0.254902 0.105882
0.039216 0.266667 0.117647
0.043137 0.266667 0.117647
0.047059 0.270588 0.121569
0.054902 0.278431 0.129412
0.058824 0.278431 0.133333
0.070588 0.290196 0.145098
0.074510 0.294118 0.149020
0.078431 0.294118 0.152941
0.082353 0.298039 0.156863
0.125490 0.219608 0.925490
0.333333 0.333333 0.333333
0.988235 0.737255 0.690196
1.000000 1.000000 1.000000
1 2 1 23 116
1 2 6 23 116
1 3 1 23 68
1 3 2 23 20
1 3 3 23 20
1 3 4 23 20
1 3 5 23 20
1 3 6 23 36
1 4 1 23 68
1 4 2 23 4
1 4 3 23 4
1 4 4 23 4
1 4 5 23 4
1 4 6 23 36
1 5 1 23 68
1 5 2 0 4
1 5 3 23 4
1 5 4 23 4
1 5 5 0 4
1 5 6 23 36
1 6 1 22 76
1 6 2 23 12
1 6 3 23 12
1 6 4 23 12
1 6 5 23 12
1 6 6 22 44
2 2 1 23 80
2 2 2 24 20
2 2 3 24 20
2 2 4 24 20
2 2 5 24 20
2 2 6 23 48
2 3 1 23 64
2 3 2 23 0
2 3 3 23 0
2 3 4 23 0
2 3 5 23 0
2 3 6 23 32
2 4 1 23 64
2 4 2 6 0
2 4 3 12 0
2 4 4 1 0
2 4 5 2 0
2 4 6 23 32
2 5 1 23 64
2 5 2 14 0
2 5 3 6 0
2 5 4 15 0
2 5 5 4 0
2 5 6 23 32
2 6 1 22 72
2 6 2 23 8
2 6 3 23 8
2 6 4 23 8
2 6 5 23 8
2 6 6 22 40
3 0 2 23 116
3 0 5 23 116
3 1 2 21 100
3 1 5 21 100
3 2 1 24 80
3 2 2 24 0
3 2 3 24 16
3 2 4 24 16
3 2 5 23 0
3 2 6 24 48
3 3 1 23 64
3 3 2 23 0
3 3 3 23 0
3 3 4 23 0
3 3 5 23 0
3 3 6 23 32
3 4 1 23 64
3 4 2 13 0
3 4 3 20 0
3 4 4 2 0
3 4 5 10 0
3 4 6 23 32
3 5 1 22 64
3 5 2 2 0
3 5 3 18 0
3 5 4 13 0
3 5 5 3 0
3 5 6 23 32
3 6 1 22 72
3 6 2 23 8
3 6 3 23 8
3 6 4 23 8
3 6 5 23 8
3 6 6 22 40
4 0 2 23 114
4 0 5 23 114
4 1 2 21 98
4 1 5 21 98
4 2 1 24 82
4 2 2 24 0
4 2 3 24 16
4 2 4 24 16
4 2 5 23 0
4 2 6 24 50
4 3 1 23 64
4 3 2 23 0
4 3 3 23 0
4 3 4 4 0
4 3 5 15 0
4 3 6 23 32
4 4 1 23 64
4 4 2 23 0
4 4 3 3 0
4 4 4 1 0
4 4 5 11 0
4 4 6 23 32
4 5 1 22 64
4 5 2 14 0
4 5 3 10 0
4 5 4 6 0
4 5 5 16 0
4 5 6 23 32
4 6 1 22 72
4 6 2 23 8
4 6 3 23 8
4 6 4 23 8
4 6 5 23 8
4 6 6 22 40
5 2 2 24 82
5 2 3 24 18
5 2 4 24 18
5 2 5 24 50
5 3 1 23 80
5 3 2 23 0
5 3 3 8 0
5 3 4 19 0
5 3 5 7 0
5 3 6 23 48
5 4 1 23 64
5 4 2 23 0
5 4 3 3 0
5 4 4 5 0
5 4 5 4 0
5 4 6 23 32
5 5 1 22 64
5 5 2 9 0
5 5 3 17 0
5 5 4 6 0
5 5 5 1 0
5 5 6 22 32
5 6 1 22 72
5 6 2 23 8
5 6 3 23 8
5 6 4 23 8
5 6 5 23 8
5 6 6 22 40
6 3 1 23 82
6 3 2 23 18
6 3 3 23 18
6 3 4 23 18
6 3 5 23 18
6 3 6 23 50
6 4 1 23 66
6 4 2 22 2
6 4 3 22 2
6 4 4 22 2
6 4 5 22 2
6 4 6 23 34
6 5 1 22 66
6 5 2 22 2
6 5 3 22 2
6 5 4 22 2
6 5 5 22 2
6 5 6 22 34
6 6 1 22 74
6 6 2 22 10
6 6 3 22 10
6 6 4 22 10
6 6 5 22 10
6 6 6 22 42
