Qubicle Exchange Format
Version 0.2
www.minddesk.com
16 16 16
26
0.000000 0.000000 0.000000
0.000000 0.211765 0.070588
0.000000 0.215686 0.070588
0.000000 0.219608 0.070588
0.000000 0.223529 0.074510
0.000000 0.227451 0.074510
0.000000 0.231373 0.074510
0.000000 0.235294 0.078431
0.007843 0.243137 0.086275
0.015686 0.247059 0.094118
0.019608 0.250980 0.098039
0.027451 0.254902 0.105882
0.039216 0.266667 0.117647
0.043137 0.266667 0.117647
0.047059 0.270588 0.121569
0.054902 0.278431 0.129412
0.058824 0.278431 0.133333
0.070588 0.290196 0.145098
0.074510 0.294118 0.149020
0.078431 0.294118 0.152941
0.082353 0.298039 0.156863
0.125490 0.219608 0.925490
0.333333 0.333333 0.333333
0.600000 0.600000 0.600000
0.988235 0.737255 0.690196
1.000000 1.000000 1.000000
0 0 0 23 84
0 0 1 23 20
0 0 2 23 20
0 0 3 23 20
0 0 4 23 20
0 0 5 23 20
0 0 6 23 20
0 0 7 23 20
0 0 8 23 20
0 0 9 23 20
0 0 10 23 20
0 0 11 23 20
0 0 12 23 20
0 0 13 23 20
0 0 14 23 20
0 0 15 23 52
0 1 0 23 68
0 1 1 23 4
0 1 2 23 12
0 1 3 23 12
0 1 4 23 12
0 1 5 23 12
0 1 6 23 12
0 1 7 23 12
0 1 8 23 12
0 1 9 23 12
0 1 10 23 12
0 1 11 23 12
0 1 12 23 12
0 1 13 23 12
0 1 14 23 4
0 1 15 23 36
0 2 0 23 68
0 2 1 23 36
0 2 14 23 68
0 2 15 23 36
0 3 0 23 68
0 3 1 23 36
0 3 14 23 68
0 3 15 23 36
0 4 0 23 68
0 4 1 23 36
0 4 14 23 68
0 4 15 23 36
0 5 0 23 68
0 5 1 23 36
0 5 14 23 68
0 5 15 23 36
0 6 0 23 68
0 6 1 23 36
0 6 14 23 68
0 6 15 23 36
0 7 0 23 68
0 7 1 23 36
0 7 14 23 68
0 7 15 23 36
0 8 0 23 68
0 8 1 23 36
0 8 14 23 68
0 8 15 23 36
0 9 0 23 68
0 9 1 23 36
0 9 14 23 68
0 9 15 23 36
0 10 0 23 68
0 10 1 23 36
0 10 14 23 68
0 10 15 23 36
0 11 0 23 68
0 11 1 23 36
0 11 14 23 68
0 11 15 23 36
0 12 0 23 68
0 12 1 23 36
0 12 14 23 68
0 12 15 23 36
0 13 0 23 68
0 13 1 23 36
0 13 14 23 68
0 13 15 23 36
0 14 0 23 68
0 14 1 23 4
0 14 2 23 20
0 14 3 23 20
0 14 4 23 20
0 14 5 23 20
0 14 6 23 20
0 14 7 23 20
0 14 8 23 20
0 14 9 23 20
0 14 10 23 20
0 14 11 23 20
0 14 12 23 20
0 14 13 23 20
0 14 14 23 4
0 14 15 23 36
0 15 0 23 76
0 15 1 23 12
0 15 2 23 12
0 15 3 23 12
0 15 4 23 12
0 15 5 23 12
0 15 6 23 12
0 15 7 23 12
0 15 8 23 12
0 15 9 23 12
0 15 10 23 12
0 15 11 23 12
0 15 12 23 12
0 15 13 23 12
0 15 14 23 12
0 15 15 23 44
1 0 0 23 80
1 0 1 23 16
1 0 2 23 18
1 0 3 23 18
1 0 4 23 18
1 0 5 23 18
1 0 6 23 18
1 0 7 23 18
1 0 8 23 18
1 0 9 23 18
1 0 10 23 18
1 0 11 23 18
1 0 12 23 18
1 0 13 23 18
1 0 14 23 16
1 0 15 23 48
1 1 0 23 64
1 1 1 23 0
1 1 2 23 10
1 1 3 23 10
1 1 4 23 10
1 1 5 23 10
1 1 6 23 10
1 1 7 23 10
1 1 8 23 10
1 1 9 23 10
1 1 10 23 10
1 1 11 23 10
1 1 12 23 10
1 1 13 23 10
1 1 14 23 0
1 1 15 23 32
1 2 0 23 66
1 2 1 23 34
1 2 14 23 66
1 2 15 23 34
1 3 0 23 66
1 3 1 23 34
1 3 14 23 66
1 3 15 23 34
1 4 0 23 66
1 4 1 23 34
1 4 14 23 66
1 4 15 23 34
1 5 0 23 66
1 5 1 23 34
1 5 14 23 66
1 5 15 23 34
1 6 0 23 66
1 6 1 23 34
1 6 14 23 66
1 6 15 23 34
1 7 0 23 66
1 7 1 23 34
1 7 14 23 66
1 7 15 23 34
1 8 0 23 66
1 8 1 23 34
1 8 14 23 66
1 8 15 23 34
1 9 0 23 66
1 9 1 23 34
1 9 14 23 66
1 9 15 23 34
1 10 0 23 66
1 10 1 23 34
1 10 14 23 66
1 10 15 23 34
1 11 0 23 66
1 11 1 23 34
1 11 14 23 66
1 11 15 23 34
1 12 0 23 66
1 12 1 23 34
1 12 14 23 66
1 12 15 23 34
1 13 0 23 66
1 13 1 23 34
1 13 14 23 66
1 13 15 23 34
1 14 0 23 64
1 14 1 23 0
1 14 2 23 16
1 14 3 23 16
1 14 4 23 16
1 14 5 23 16
1 14 6 23 16
1 14 7 23 16
1 14 8 23 16
1 14 9 23 16
1 14 10 23 16
1 14 11 23 16
1 14 12 23 16
1 14 13 23 16
1 14 14 23 0
1 14 15 23 32
1 15 0 23 72
1 15 1 23 8
1 15 2 23 8
1 15 3 23 8
1 15 4 23 8
1 15 5 23 8
1 15 6 23 8
1 15 7 23 8
1 15 8 23 8
1 15 9 23 8
1 15 10 23 8
1 15 11 23 8
1 15 12 23 8
1 15 13 23 8
1 15 14 23 8
1 15 15 23 40
2 0 0 23 80
2 0 1 23 48
2 0 14 23 80
2 0 15 23 48
2 1 0 23 72
2 1 1 23 40
2 1 14 23 72
2 1 15 23 40
2 4 2 24 84
2 4 3 24 20
2 4 4 24 20
2 4 5 24 20
2 4 6 25 20
2 4 7 25 20
2 4 8 25 20
2 4 9 25 52
2 5 2 24 76
2 5 3 24 12
2 5 4 24 12
2 5 5 24 12
2 5 6 25 12
2 5 7 25 12
2 5 8 25 12
2 5 9 25 44
2 8 2 24 84
2 8 3 24 20
2 8 4 24 20
2 8 5 24 20
2 8 6 24 20
2 8 7 24 20
2 8 8 24 20
2 8 9 24 20
2 8 10 24 20
2 8 11 24 20
2 8 12 24 20
2 8 13 24 52
2 9 2 24 68
2 9 3 24 4
2 9 4 24 4
2 9 5 24 4
2 9 6 24 4
2 9 7 24 4
2 9 8 24 4
2 9 9 24 4
2 9 10 24 4
2 9 11 24 4
2 9 12 24 4
2 9 13 24 36
2 10 2 24 68
2 10 3 24 4
2 10 4 24 4
2 10 5 24 4
2 10 6 24 4
2 10 7 24 4
2 10 8 24 4
2 10 9 24 4
2 10 10 24 4
2 10 11 24 4
2 10 12 24 4
2 10 13 24 36
2 11 2 24 68
2 11 3 24 4
2 11 4 24 4
2 11 5 24 4
2 11 6 24 4
2 11 7 24 4
2 11 8 24 4
2 11 9 24 4
2 11 10 24 4
2 11 11 24 4
2 11 12 24 4
2 11 13 24 36
2 12 2 24 68
2 12 3 24 4
2 12 4 24 4
2 12 5 24 4
2 12 6 22 4
2 12 7 22 4
2 12 8 22 4
2 12 9 22 4
2 12 10 22 4
2 12 11 22 4
2 12 12 22 4
2 12 13 22 36
2 13 2 24 68
2 13 3 24 4
2 13 4 24 4
2 13 5 24 4
2 13 6 22 4
2 13 7 22 4
2 13 8 22 4
2 13 9 22 4
2 13 10 22 4
2 13 11 22 4
2 13 12 22 4
2 13 13 22 36
2 14 0 23 80
2 14 1 23 16
2 14 2 22 0
2 14 3 22 0
2 14 4 22 0
2 14 5 22 0
2 14 6 22 0
2 14 7 22 0
2 14 8 22 0
2 14 9 22 0
2 14 10 22 0
2 14 11 22 0
2 14 12 22 0
2 14 13 22 0
2 14 14 23 16
2 14 15 23 48
2 15 0 23 72
2 15 1 23 8
2 15 2 22 8
2 15 3 22 8
2 15 4 22 8
2 15 5 22 8
2 15 6 22 8
2 15 7 22 8
2 15 8 22 8
2 15 9 22 8
2 15 10 22 8
2 15 11 22 8
2 15 12 22 8
2 15 13 22 8
2 15 14 23 8
2 15 15 23 40
3 0 0 23 80
3 0 1 23 48
3 0 14 23 80
3 0 15 23 48
3 1 0 23 72
3 1 1 23 40
3 1 14 23 72
3 1 15 23 40
3 4 2 24 82
3 4 3 24 18
3 4 4 24 16
3 4 5 24 16
3 4 6 25 16
3 4 7 25 16
3 4 8 25 16
3 4 9 25 48
3 5 2 24 74
3 5 3 24 10
3 5 4 24 8
3 5 5 24 8
3 5 6 25 8
3 5 7 25 8
3 5 8 25 8
3 5 9 25 40
3 8 2 24 80
3 8 3 24 16
3 8 4 24 16
3 8 5 24 16
3 8 6 24 16
3 8 7 24 16
3 8 8 24 16
3 8 9 24 16
3 8 10 24 16
3 8 11 24 16
3 8 12 24 16
3 8 13 24 48
3 9 2 24 64
3 9 3 24 0
3 9 4 24 0
3 9 5 24 0
3 9 6 24 0
3 9 7 24 0
3 9 8 24 0
3 9 9 24 0
3 9 10 24 0
3 9 11 24 0
3 9 12 24 0
3 9 13 24 32
3 10 2 24 64
3 10 3 24 0
3 10 4 24 0
3 10 5 24 0
3 10 6 24 0
3 10 7 24 0
3 10 8 24 0
3 10 9 24 0
3 10 10 24 0
3 10 11 24 0
3 10 12 24 0
3 10 13 24 32
3 11 2 24 64
3 11 3 24 0
3 11 4 24 0
3 11 5 24 0
3 11 6 24 0
3 11 7 24 0
3 11 8 24 0
3 11 9 24 0
3 11 10 24 0
3 11 11 24 0
3 11 12 24 0
3 11 13 24 32
3 12 2 24 64
3 12 3 24 0
3 12 4 24 0
3 12 5 24 0
3 12 6 22 0
3 12 7 22 0
3 12 8 22 0
3 12 9 22 0
3 12 10 22 0
3 12 11 22 0
3 12 12 22 0
3 12 13 22 32
3 13 2 24 64
3 13 3 24 0
3 13 4 24 0
3 13 5 24 0
3 13 6 22 0
3 13 7 22 0
3 13 8 22 0
3 13 9 22 0
3 13 10 22 0
3 13 11 22 0
3 13 12 22 0
3 13 13 22 32
3 14 0 23 80
3 14 1 23 16
3 14 2 22 0
3 14 3 22 0
3 14 4 22 0
3 14 5 22 0
3 14 6 22 0
3 14 7 22 0
3 14 8 22 0
3 14 9 22 0
3 14 10 22 0
3 14 11 22 0
3 14 12 22 0
3 14 13 22 0
3 14 14 23 16
3 14 15 23 48
3 15 0 23 72
3 15 1 23 8
3 15 2 22 8
3 15 3 22 8
3 15 4 22 8
3 15 5 22 8
3 15 6 22 8
3 15 7 22 8
3 15 8 22 8
3 15 9 22 8
3 15 10 22 8
3 15 11 22 8
3 15 12 22 8
3 15 13 22 8
3 15 14 23 8
3 15 15 23 40
4 0 0 23 80
4 0 1 23 48
4 0 6 24 84
4 0 7 24 20
4 0 8 24 20
4 0 9 24 52
4 0 14 23 80
4 0 15 23 48
4 1 0 23 72
4 1 1 23 40
4 1 6 24 68
4 1 7 24 4
4 1 8 24 4
4 1 9 24 36
4 1 14 23 72
4 1 15 23 40
4 2 6 21 68
4 2 7 21 4
4 2 8 21 4
4 2 9 21 36
4 3 6 21 68
4 3 7 21 4
4 3 8 21 4
4 3 9 21 36
4 4 4 25 80
4 4 5 25 16
4 4 6 25 0
4 4 7 25 0
4 4 8 25 0
4 4 9 25 0
4 4 10 25 20
4 4 11 25 52
4 5 4 25 64
4 5 5 25 0
4 5 6 25 0
4 5 7 25 0
4 5 8 25 0
4 5 9 25 0
4 5 10 25 4
4 5 11 25 36
4 6 4 25 68
4 6 5 25 4
4 6 6 25 4
4 6 7 25 4
4 6 8 25 4
4 6 9 25 4
4 6 10 25 4
4 6 11 25 36
4 7 4 25 68
4 7 5 25 4
4 7 6 25 4
4 7 7 25 4
4 7 8 25 4
4 7 9 25 4
4 7 10 25 4
4 7 11 25 36
4 8 2 24 80
4 8 3 24 16
4 8 4 24 0
4 8 5 24 0
4 8 6 24 0
4 8 7 24 0
4 8 8 24 0
4 8 9 24 0
4 8 10 24 0
4 8 11 24 0
4 8 12 24 16
4 8 13 24 48
4 9 2 24 64
4 9 3 24 0
4 9 4 24 0
4 9 5 24 0
4 9 6 24 0
4 9 7 24 0
4 9 8 24 0
4 9 9 24 0
4 9 10 24 0
4 9 11 24 0
4 9 12 24 0
4 9 13 24 32
4 10 2 24 64
4 10 3 24 0
4 10 4 6 0
4 10 5 6 0
4 10 6 13 0
4 10 7 13 0
4 10 8 24 0
4 10 9 24 0
4 10 10 24 0
4 10 11 24 0
4 10 12 22 0
4 10 13 22 32
4 11 2 24 64
4 11 3 24 0
4 11 4 6 0
4 11 5 6 0
4 11 6 13 0
4 11 7 13 0
4 11 8 24 0
4 11 9 24 0
4 11 10 24 0
4 11 11 24 0
4 11 12 22 0
4 11 13 22 32
4 12 2 0 64
4 12 3 0 0
4 12 4 14 0
4 12 5 14 0
4 12 6 2 0
4 12 7 2 0
4 12 8 14 0
4 12 9 14 0
4 12 10 9 0
4 12 11 9 0
4 12 12 22 0
4 12 13 22 32
4 13 2 0 64
4 13 3 0 0
4 13 4 14 0
4 13 5 14 0
4 13 6 2 0
4 13 7 2 0
4 13 8 14 0
4 13 9 14 0
4 13 10 9 0
4 13 11 9 0
4 13 12 22 0
4 13 13 22 32
4 14 0 23 80
4 14 1 23 16
4 14 2 24 0
4 14 3 24 0
4 14 4 24 0
4 14 5 24 0
4 14 6 24 0
4 14 7 24 0
4 14 8 24 0
4 14 9 24 0
4 14 10 24 0
4 14 11 24 0
4 14 12 22 0
4 14 13 22 0
4 14 14 23 16
4 14 15 23 48
4 15 0 23 72
4 15 1 23 8
4 15 2 24 8
4 15 3 24 8
4 15 4 24 8
4 15 5 24 8
4 15 6 24 8
4 15 7 24 8
4 15 8 24 8
4 15 9 24 8
4 15 10 24 8
4 15 11 24 8
4 15 12 22 8
4 15 13 22 8
4 15 14 23 8
4 15 15 23 40
5 0 0 23 80
5 0 1 23 48
5 0 6 24 82
5 0 7 24 18
5 0 8 24 18
5 0 9 24 50
5 0 14 23 80
5 0 15 23 48
5 1 0 23 72
5 1 1 23 40
5 1 6 24 66
5 1 7 24 2
5 1 8 24 2
5 1 9 24 34
5 1 14 23 72
5 1 15 23 40
5 2 6 21 66
5 2 7 21 2
5 2 8 21 2
5 2 9 21 34
5 3 6 21 66
5 3 7 21 2
5 3 8 21 2
5 3 9 21 34
5 4 4 25 80
5 4 5 25 16
5 4 6 25 0
5 4 7 25 0
5 4 8 25 0
5 4 9 25 0
5 4 10 25 16
5 4 11 25 48
5 5 4 25 64
5 5 5 25 0
5 5 6 25 0
5 5 7 25 0
5 5 8 25 0
5 5 9 25 0
5 5 10 25 0
5 5 11 25 32
5 6 4 25 64
5 6 5 25 0
5 6 6 25 0
5 6 7 25 0
5 6 8 25 0
5 6 9 25 0
5 6 10 25 0
5 6 11 25 32
5 7 4 25 64
5 7 5 25 0
5 7 6 25 0
5 7 7 25 0
5 7 8 25 0
5 7 9 25 0
5 7 10 25 0
5 7 11 25 32
5 8 2 24 80
5 8 3 24 16
5 8 4 24 0
5 8 5 24 0
5 8 6 24 0
5 8 7 24 0
5 8 8 24 0
5 8 9 24 0
5 8 10 24 0
5 8 11 24 0
5 8 12 24 16
5 8 13 24 48
5 9 2 22 126
5 9 3 24 0
5 9 4 24 0
5 9 5 24 0
5 9 6 24 0
5 9 7 24 0
5 9 8 24 0
5 9 9 24 0
5 9 10 24 0
5 9 11 24 0
5 9 12 24 0
5 9 13 24 32
5 10 2 22 126
5 10 3 24 0
5 10 4 6 0
5 10 5 6 0
5 10 6 13 0
5 10 7 13 0
5 10 8 24 0
5 10 9 24 0
5 10 10 24 0
5 10 11 24 0
5 10 12 22 0
5 10 13 22 32
5 11 2 24 64
5 11 3 24 0
5 11 4 6 0
5 11 5 6 0
5 11 6 13 0
5 11 7 13 0
5 11 8 24 0
5 11 9 24 0
5 11 10 24 0
5 11 11 24 0
5 11 12 22 0
5 11 13 22 32
5 12 2 0 64
5 12 3 0 0
5 12 4 14 0
5 12 5 14 0
5 12 6 2 0
5 12 7 2 0
5 12 8 14 0
5 12 9 14 0
5 12 10 9 0
5 12 11 9 0
5 12 12 22 0
5 12 13 22 32
5 13 2 0 64
5 13 3 0 0
5 13 4 14 0
5 13 5 14 0
5 13 6 2 0
5 13 7 2 0
5 13 8 14 0
5 13 9 14 0
5 13 10 9 0
5 13 11 9 0
5 13 12 22 0
5 13 13 22 32
5 14 0 23 80
5 14 1 23 16
5 14 2 24 0
5 14 3 24 0
5 14 4 24 0
5 14 5 24 0
5 14 6 24 0
5 14 7 24 0
5 14 8 24 0
5 14 9 24 0
5 14 10 24 0
5 14 11 24 0
5 14 12 22 0
5 14 13 22 0
5 14 14 23 16
5 14 15 23 48
5 15 0 23 72
5 15 1 23 8
5 15 2 24 8
5 15 3 24 8
5 15 4 24 8
5 15 5 24 8
5 15 6 24 8
5 15 7 24 8
5 15 8 24 8
5 15 9 24 8
5 15 10 24 8
5 15 11 24 8
5 15 12 22 8
5 15 13 22 8
5 15 14 23 8
5 15 15 23 40
6 0 0 23 80
6 0 1 23 48
6 0 14 23 80
6 0 15 23 48
6 1 0 23 72
6 1 1 23 40
6 1 14 23 72
6 1 15 23 40
6 4 4 25 80
6 4 5 25 16
6 4 6 25 16
6 4 7 25 16
6 4 8 25 16
6 4 9 25 16
6 4 10 25 16
6 4 11 25 48
6 5 4 25 64
6 5 5 25 0
6 5 6 25 0
6 5 7 25 0
6 5 8 25 0
6 5 9 25 0
6 5 10 25 0
6 5 11 25 32
6 6 4 25 64
6 6 5 25 0
6 6 6 25 0
6 6 7 25 0
6 6 8 25 0
6 6 9 25 0
6 6 10 25 0
6 6 11 25 32
6 7 4 25 64
6 7 5 25 0
6 7 6 25 0
6 7 7 25 0
6 7 8 25 0
6 7 9 25 0
6 7 10 25 0
6 7 11 25 32
6 8 2 24 80
6 8 3 24 16
6 8 4 24 0
6 8 5 24 0
6 8 6 24 0
6 8 7 24 0
6 8 8 24 0
6 8 9 24 0
6 8 10 8 0
6 8 11 8 0
6 8 12 24 16
6 8 13 24 48
6 9 2 22 126
6 9 3 24 0
6 9 4 24 0
6 9 5 24 0
6 9 6 24 0
6 9 7 24 0
6 9 8 24 0
6 9 9 24 0
6 9 10 8 0
6 9 11 8 0
6 9 12 24 0
6 9 13 24 32
6 10 2 22 126
6 10 3 24 0
6 10 4 12 0
6 10 5 12 0
6 10 6 20 0
6 10 7 20 0
6 10 8 3 0
6 10 9 3 0
6 10 10 3 0
6 10 11 3 0
6 10 12 22 0
6 10 13 22 32
6 11 2 24 64
6 11 3 24 0
6 11 4 12 0
6 11 5 12 0
6 11 6 20 0
6 11 7 20 0
6 11 8 3 0
6 11 9 3 0
6 11 10 3 0
6 11 11 3 0
6 11 12 22 0
6 11 13 22 32
6 12 2 24 64
6 12 3 24 0
6 12 4 6 0
6 12 5 6 0
6 12 6 18 0
6 12 7 18 0
6 12 8 10 0
6 12 9 10 0
6 12 10 17 0
6 12 11 17 0
6 12 12 22 0
6 12 13 22 32
6 13 2 24 64
6 13 3 24 0
6 13 4 6 0
6 13 5 6 0
6 13 6 18 0
6 13 7 18 0
6 13 8 10 0
6 13 9 10 0
6 13 10 17 0
6 13 11 17 0
6 13 12 22 0
6 13 13 22 32
6 14 0 23 80
6 14 1 23 16
6 14 2 24 0
6 14 3 24 0
6 14 4 24 0
6 14 5 24 0
6 14 6 24 0
6 14 7 24 0
6 14 8 24 0
6 14 9 24 0
6 14 10 24 0
6 14 11 24 0
6 14 12 22 0
6 14 13 22 0
6 14 14 23 16
6 14 15 23 48
6 15 0 23 72
6 15 1 23 8
6 15 2 24 8
6 15 3 24 8
6 15 4 24 8
6 15 5 24 8
6 15 6 24 8
6 15 7 24 8
6 15 8 24 8
6 15 9 24 8
6 15 10 24 8
6 15 11 24 8
6 15 12 22 8
6 15 13 22 8
6 15 14 23 8
6 15 15 23 40
7 0 0 23 80
7 0 1 23 48
7 0 14 23 80
7 0 15 23 48
7 1 0 23 72
7 1 1 23 40
7 1 14 23 72
7 1 15 23 40
7 4 4 25 80
7 4 5 25 16
7 4 6 25 16
7 4 7 25 16
7 4 8 25 16
7 4 9 25 16
7 4 10 25 16
7 4 11 25 48
7 5 4 25 64
7 5 5 25 0
7 5 6 25 0
7 5 7 25 0
7 5 8 25 0
7 5 9 25 0
7 5 10 25 0
7 5 11 25 32
7 6 4 25 64
7 6 5 25 0
7 6 6 25 0
7 6 7 25 0
7 6 8 25 0
7 6 9 25 0
7 6 10 25 0
7 6 11 25 32
7 7 4 25 64
7 7 5 25 0
7 7 6 25 0
7 7 7 25 0
7 7 8 25 0
7 7 9 25 0
7 7 10 25 0
7 7 11 25 32
7 8 2 24 80
7 8 3 24 16
7 8 4 24 0
7 8 5 24 0
7 8 6 24 0
7 8 7 24 0
7 8 8 24 0
7 8 9 24 0
7 8 10 8 0
7 8 11 8 0
7 8 12 24 16
7 8 13 24 48
7 9 2 22 126
7 9 3 24 0
7 9 4 24 0
7 9 5 24 0
7 9 6 24 0
7 9 7 24 0
7 9 8 24 0
7 9 9 24 0
7 9 10 8 0
7 9 11 8 0
7 9 12 24 0
7 9 13 24 32
7 10 2 22 126
7 10 3 24 0
7 10 4 12 0
7 10 5 12 0
7 10 6 20 0
7 10 7 20 0
7 10 8 3 0
7 10 9 3 0
7 10 10 3 0
7 10 11 3 0
7 10 12 22 0
7 10 13 22 32
7 11 2 24 64
7 11 3 24 0
7 11 4 12 0
7 11 5 12 0
7 11 6 20 0
7 11 7 20 0
7 11 8 3 0
7 11 9 3 0
7 11 10 3 0
7 11 11 3 0
7 11 12 22 0
7 11 13 22 32
7 12 2 24 64
7 12 3 24 0
7 12 4 6 0
7 12 5 6 0
7 12 6 18 0
7 12 7 18 0
7 12 8 10 0
7 12 9 10 0
7 12 10 17 0
7 12 11 17 0
7 12 12 22 0
7 12 13 22 32
7 13 2 24 64
7 13 3 24 0
7 13 4 6 0
7 13 5 6 0
7 13 6 18 0
7 13 7 18 0
7 13 8 10 0
7 13 9 10 0
7 13 10 17 0
7 13 11 17 0
7 13 12 22 0
7 13 13 22 32
7 14 0 23 80
7 14 1 23 16
7 14 2 24 0
7 14 3 24 0
7 14 4 24 0
7 14 5 24 0
7 14 6 24 0
7 14 7 24 0
7 14 8 24 0
7 14 9 24 0
7 14 10 24 0
7 14 11 24 0
7 14 12 22 0
7 14 13 22 0
7 14 14 23 16
7 14 15 23 48
7 15 0 23 72
7 15 1 23 8
7 15 2 24 8
7 15 3 24 8
7 15 4 24 8
7 15 5 24 8
7 15 6 24 8
7 15 7 24 8
7 15 8 24 8
7 15 9 24 8
7 15 10 24 8
7 15 11 24 8
7 15 12 22 8
7 15 13 22 8
7 15 14 23 8
7 15 15 23 40
8 0 0 23 80
8 0 1 23 48
8 0 14 23 80
8 0 15 23 48
8 1 0 23 72
8 1 1 23 40
8 1 14 23 72
8 1 15 23 40
8 4 4 25 80
8 4 5 25 16
8 4 6 25 16
8 4 7 25 16
8 4 8 25 16
8 4 9 25 16
8 4 10 25 16
8 4 11 25 48
8 5 4 25 64
8 5 5 25 0
8 5 6 25 0
8 5 7 25 0
8 5 8 25 0
8 5 9 25 0
8 5 10 25 0
8 5 11 25 32
8 6 4 25 64
8 6 5 25 0
8 6 6 24 0
8 6 7 24 0
8 6 8 24 0
8 6 9 24 0
8 6 10 25 0
8 6 11 25 32
8 7 4 25 64
8 7 5 25 0
8 7 6 24 0
8 7 7 24 0
8 7 8 24 0
8 7 9 24 0
8 7 10 25 0
8 7 11 25 32
8 8 2 24 80
8 8 3 24 16
8 8 4 24 0
8 8 5 24 0
8 8 6 24 0
8 8 7 24 0
8 8 8 4 0
8 8 9 4 0
8 8 10 19 0
8 8 11 19 0
8 8 12 24 16
8 8 13 24 48
8 9 2 22 126
8 9 3 24 0
8 9 4 24 0
8 9 5 24 0
8 9 6 24 0
8 9 7 24 0
8 9 8 4 0
8 9 9 4 0
8 9 10 19 0
8 9 11 19 0
8 9 12 24 0
8 9 13 24 32
8 10 2 22 126
8 10 3 24 0
8 10 4 1 0
8 10 5 1 0
8 10 6 2 0
8 10 7 2 0
8 10 8 1 0
8 10 9 1 0
8 10 10 5 0
8 10 11 5 0
8 10 12 22 0
8 10 13 22 32
8 11 2 24 64
8 11 3 24 0
8 11 4 1 0
8 11 5 1 0
8 11 6 2 0
8 11 7 2 0
8 11 8 1 0
8 11 9 1 0
8 11 10 5 0
8 11 11 5 0
8 11 12 22 0
8 11 13 22 32
8 12 2 24 64
8 12 3 24 0
8 12 4 15 0
8 12 5 15 0
8 12 6 13 0
8 12 7 13 0
8 12 8 6 0
8 12 9 6 0
8 12 10 6 0
8 12 11 6 0
8 12 12 22 0
8 12 13 22 32
8 13 2 24 64
8 13 3 24 0
8 13 4 15 0
8 13 5 15 0
8 13 6 13 0
8 13 7 13 0
8 13 8 6 0
8 13 9 6 0
8 13 10 6 0
8 13 11 6 0
8 13 12 22 0
8 13 13 22 32
8 14 0 23 80
8 14 1 23 16
8 14 2 24 0
8 14 3 24 0
8 14 4 24 0
8 14 5 24 0
8 14 6 24 0
8 14 7 24 0
8 14 8 24 0
8 14 9 24 0
8 14 10 24 0
8 14 11 24 0
8 14 12 22 0
8 14 13 22 0
8 14 14 23 16
8 14 15 23 48
8 15 0 23 72
8 15 1 23 8
8 15 2 24 8
8 15 3 24 8
8 15 4 24 8
8 15 5 24 8
8 15 6 24 8
8 15 7 24 8
8 15 8 24 8
8 15 9 24 8
8 15 10 24 8
8 15 11 24 8
8 15 12 22 8
8 15 13 22 8
8 15 14 23 8
8 15 15 23 40
9 0 0 23 80
9 0 1 23 48
9 0 14 23 80
9 0 15 23 48
9 1 0 23 72
9 1 1 23 40
9 1 14 23 72
9 1 15 23 40
9 4 4 25 80
9 4 5 25 16
9 4 6 25 16
9 4 7 25 16
9 4 8 25 16
9 4 9 25 16
9 4 10 25 16
9 4 11 25 48
9 5 4 25 64
9 5 5 25 0
9 5 6 25 0
9 5 7 25 0
9 5 8 25 0
9 5 9 25 0
9 5 10 25 0
9 5 11 25 32
9 6 4 25 64
9 6 5 25 0
9 6 6 24 0
9 6 7 24 0
9 6 8 24 0
9 6 9 24 0
9 6 10 25 0
9 6 11 25 32
9 7 4 25 64
9 7 5 25 0
9 7 6 24 0
9 7 7 24 0
9 7 8 24 0
9 7 9 24 0
9 7 10 25 0
9 7 11 25 32
9 8 2 24 80
9 8 3 24 16
9 8 4 24 0
9 8 5 24 0
9 8 6 24 0
9 8 7 24 0
9 8 8 4 0
9 8 9 4 0
9 8 10 19 0
9 8 11 19 0
9 8 12 24 16
9 8 13 24 48
9 9 2 22 126
9 9 3 24 0
9 9 4 24 0
9 9 5 24 0
9 9 6 24 0
9 9 7 24 0
9 9 8 4 0
9 9 9 4 0
9 9 10 19 0
9 9 11 19 0
9 9 12 24 0
9 9 13 24 32
9 10 2 22 126
9 10 3 24 0
9 10 4 1 0
9 10 5 1 0
9 10 6 2 0
9 10 7 2 0
9 10 8 1 0
9 10 9 1 0
9 10 10 5 0
9 10 11 5 0
9 10 12 22 0
9 10 13 22 32
9 11 2 24 64
9 11 3 24 0
9 11 4 1 0
9 11 5 1 0
9 11 6 2 0
9 11 7 2 0
9 11 8 1 0
9 11 9 1 0
9 11 10 5 0
9 11 11 5 0
9 11 12 22 0
9 11 13 22 32
9 12 2 24 64
9 12 3 24 0
9 12 4 15 0
9 12 5 15 0
9 12 6 13 0
9 12 7 13 0
9 12 8 6 0
9 12 9 6 0
9 12 10 6 0
9 12 11 6 0
9 12 12 22 0
9 12 13 22 32
9 13 2 24 64
9 13 3 24 0
9 13 4 15 0
9 13 5 15 0
9 13 6 13 0
9 13 7 13 0
9 13 8 6 0
9 13 9 6 0
9 13 10 6 0
9 13 11 6 0
9 13 12 22 0
9 13 13 22 32
9 14 0 23 80
9 14 1 23 16
9 14 2 24 0
9 14 3 24 0
9 14 4 24 0
9 14 5 24 0
9 14 6 24 0
9 14 7 24 0
9 14 8 24 0
9 14 9 24 0
9 14 10 24 0
9 14 11 24 0
9 14 12 22 0
9 14 13 22 0
9 14 14 23 16
9 14 15 23 48
9 15 0 23 72
9 15 1 23 8
9 15 2 24 8
9 15 3 24 8
9 15 4 24 8
9 15 5 24 8
9 15 6 24 8
9 15 7 24 8
9 15 8 24 8
9 15 9 24 8
9 15 10 24 8
9 15 11 24 8
9 15 12 22 8
9 15 13 22 8
9 15 14 23 8
9 15 15 23 40
10 0 0 23 80
10 0 1 23 48
10 0 6 24 84
10 0 7 24 20
10 0 8 24 20
10 0 9 24 52
10 0 14 23 80
10 0 15 23 48
10 1 0 23 72
10 1 1 23 40
10 1 6 24 68
10 1 7 24 4
10 1 8 24 4
10 1 9 24 36
10 1 14 23 72
10 1 15 23 40
10 2 6 21 68
10 2 7 21 4
10 2 8 21 4
10 2 9 21 36
10 3 6 21 68
10 3 7 21 4
10 3 8 21 4
10 3 9 21 36
10 4 4 25 80
10 4 5 25 16
10 4 6 24 0
10 4 7 24 0
10 4 8 24 0
10 4 9 24 0
10 4 10 25 16
10 4 11 25 48
10 5 4 25 64
10 5 5 25 0
10 5 6 24 0
10 5 7 24 0
10 5 8 24 0
10 5 9 24 0
10 5 10 25 0
10 5 11 25 32
10 6 4 25 64
10 6 5 25 0
10 6 6 25 0
10 6 7 25 0
10 6 8 25 0
10 6 9 25 0
10 6 10 25 0
10 6 11 25 32
10 7 4 25 64
10 7 5 25 0
10 7 6 25 0
10 7 7 25 0
10 7 8 25 0
10 7 9 25 0
10 7 10 25 0
10 7 11 25 32
10 8 2 24 80
10 8 3 24 16
10 8 4 24 0
10 8 5 24 0
10 8 6 24 0
10 8 7 24 0
10 8 8 15 0
10 8 9 15 0
10 8 10 7 0
10 8 11 7 0
10 8 12 24 16
10 8 13 24 48
10 9 2 22 126
10 9 3 24 0
10 9 4 24 0
10 9 5 24 0
10 9 6 24 0
10 9 7 24 0
10 9 8 15 0
10 9 9 15 0
10 9 10 7 0
10 9 11 7 0
10 9 12 24 0
10 9 13 24 32
10 10 2 22 126
10 10 3 24 0
10 10 4 2 0
10 10 5 2 0
10 10 6 10 0
10 10 7 10 0
10 10 8 11 0
10 10 9 11 0
10 10 10 4 0
10 10 11 4 0
10 10 12 22 0
10 10 13 22 32
10 11 2 24 64
10 11 3 24 0
10 11 4 2 0
10 11 5 2 0
10 11 6 10 0
10 11 7 10 0
10 11 8 11 0
10 11 9 11 0
10 11 10 4 0
10 11 11 4 0
10 11 12 22 0
10 11 13 22 32
10 12 2 0 64
10 12 3 0 0
10 12 4 4 0
10 12 5 4 0
10 12 6 3 0
10 12 7 3 0
10 12 8 16 0
10 12 9 16 0
10 12 10 1 0
10 12 11 1 0
10 12 12 22 0
10 12 13 22 32
10 13 2 0 64
10 13 3 0 0
10 13 4 4 0
10 13 5 4 0
10 13 6 3 0
10 13 7 3 0
10 13 8 16 0
10 13 9 16 0
10 13 10 1 0
10 13 11 1 0
10 13 12 22 0
10 13 13 22 32
10 14 0 23 80
10 14 1 23 16
10 14 2 24 0
10 14 3 24 0
10 14 4 24 0
10 14 5 24 0
10 14 6 24 0
10 14 7 24 0
10 14 8 24 0
10 14 9 24 0
10 14 10 24 0
10 14 11 24 0
10 14 12 22 0
10 14 13 22 0
10 14 14 23 16
10 14 15 23 48
10 15 0 23 72
10 15 1 23 8
10 15 2 24 8
10 15 3 24 8
10 15 4 24 8
10 15 5 24 8
10 15 6 24 8
10 15 7 24 8
10 15 8 24 8
10 15 9 24 8
10 15 10 24 8
10 15 11 24 8
10 15 12 22 8
10 15 13 22 8
10 15 14 23 8
10 15 15 23 40
11 0 0 23 80
11 0 1 23 48
11 0 6 24 82
11 0 7 24 18
11 0 8 24 18
11 0 9 24 50
11 0 14 23 80
11 0 15 23 48
11 1 0 23 72
11 1 1 23 40
11 1 6 24 66
11 1 7 24 2
11 1 8 24 2
11 1 9 24 34
11 1 14 23 72
11 1 15 23 40
11 2 6 21 66
11 2 7 21 2
11 2 8 21 2
11 2 9 21 34
11 3 6 21 66
11 3 7 21 2
11 3 8 21 2
11 3 9 21 34
11 4 4 25 80
11 4 5 25 16
11 4 6 24 0
11 4 7 24 0
11 4 8 24 0
11 4 9 24 0
11 4 10 25 18
11 4 11 25 50
11 5 4 25 64
11 5 5 25 0
11 5 6 24 0
11 5 7 24 0
11 5 8 24 0
11 5 9 24 0
11 5 10 25 2
11 5 11 25 34
11 6 4 25 66
11 6 5 25 2
11 6 6 25 2
11 6 7 25 2
11 6 8 25 2
11 6 9 25 2
11 6 10 25 2
11 6 11 25 34
11 7 4 25 66
11 7 5 25 2
11 7 6 25 2
11 7 7 25 2
11 7 8 25 2
11 7 9 25 2
11 7 10 25 2
11 7 11 25 34
11 8 2 24 80
11 8 3 24 16
11 8 4 24 0
11 8 5 24 0
11 8 6 24 0
11 8 7 24 0
11 8 8 15 0
11 8 9 15 0
11 8 10 7 0
11 8 11 7 0
11 8 12 24 16
11 8 13 24 48
11 9 2 24 64
11 9 3 24 0
11 9 4 24 0
11 9 5 24 0
11 9 6 24 0
11 9 7 24 0
11 9 8 15 0
11 9 9 15 0
11 9 10 7 0
11 9 11 7 0
11 9 12 24 0
11 9 13 24 32
11 10 2 24 64
11 10 3 24 0
11 10 4 2 0
11 10 5 2 0
11 10 6 10 0
11 10 7 10 0
11 10 8 11 0
11 10 9 11 0
11 10 10 4 0
11 10 11 4 0
11 10 12 22 0
11 10 13 22 32
11 11 2 24 64
11 11 3 24 0
11 11 4 2 0
11 11 5 2 0
11 11 6 10 0
11 11 7 10 0
11 11 8 11 0
11 11 9 11 0
11 11 10 4 0
11 11 11 4 0
11 11 12 22 0
11 11 13 22 32
11 12 2 0 64
11 12 3 0 0
11 12 4 4 0
11 12 5 4 0
11 12 6 3 0
11 12 7 3 0
11 12 8 16 0
11 12 9 16 0
11 12 10 1 0
11 12 11 1 0
11 12 12 22 0
11 12 13 22 32
11 13 2 0 64
11 13 3 0 0
11 13 4 4 0
11 13 5 4 0
11 13 6 3 0
11 13 7 3 0
11 13 8 16 0
11 13 9 16 0
11 13 10 1 0
11 13 11 1 0
11 13 12 22 0
11 13 13 22 32
11 14 0 23 80
11 14 1 23 16
11 14 2 24 0
11 14 3 24 0
11 14 4 24 0
11 14 5 24 0
11 14 6 24 0
11 14 7 24 0
11 14 8 24 0
11 14 9 24 0
11 14 10 24 0
11 14 11 24 0
11 14 12 22 0
11 14 13 22 0
11 14 14 23 16
11 14 15 23 48
11 15 0 23 72
11 15 1 23 8
11 15 2 24 8
11 15 3 24 8
11 15 4 24 8
11 15 5 24 8
11 15 6 24 8
11 15 7 24 8
11 15 8 24 8
11 15 9 24 8
11 15 10 24 8
11 15 11 24 8
11 15 12 22 8
11 15 13 22 8
11 15 14 23 8
11 15 15 23 40
12 0 0 23 80
12 0 1 23 48
12 0 14 23 80
12 0 15 23 48
12 1 0 23 72
12 1 1 23 40
12 1 14 23 72
12 1 15 23 40
12 4 2 24 84
12 4 3 24 20
12 4 4 24 16
12 4 5 24 16
12 4 6 25 16
12 4 7 25 16
12 4 8 25 16
12 4 9 25 48
12 5 2 24 76
12 5 3 24 12
12 5 4 24 8
12 5 5 24 8
12 5 6 25 8
12 5 7 25 8
12 5 8 25 8
12 5 9 25 40
12 8 2 24 80
12 8 3 24 16
12 8 4 24 16
12 8 5 24 16
12 8 6 24 16
12 8 7 24 16
12 8 8 24 16
12 8 9 24 16
12 8 10 24 16
12 8 11 24 16
12 8 12 24 16
12 8 13 24 48
12 9 2 24 64
12 9 3 24 0
12 9 4 24 0
12 9 5 24 0
12 9 6 24 0
12 9 7 24 0
12 9 8 24 0
12 9 9 24 0
12 9 10 24 0
12 9 11 24 0
12 9 12 24 0
12 9 13 24 32
12 10 2 24 64
12 10 3 24 0
12 10 4 24 0
12 10 5 24 0
12 10 6 24 0
12 10 7 24 0
12 10 8 24 0
12 10 9 24 0
12 10 10 24 0
12 10 11 24 0
12 10 12 24 0
12 10 13 24 32
12 11 2 24 64
12 11 3 24 0
12 11 4 24 0
12 11 5 24 0
12 11 6 24 0
12 11 7 24 0
12 11 8 24 0
12 11 9 24 0
12 11 10 24 0
12 11 11 24 0
12 11 12 24 0
12 11 13 24 32
12 12 2 24 64
12 12 3 24 0
12 12 4 24 0
12 12 5 24 0
12 12 6 24 0
12 12 7 24 0
12 12 8 24 0
12 12 9 24 0
12 12 10 22 0
12 12 11 22 0
12 12 12 22 0
12 12 13 22 32
12 13 2 24 64
12 13 3 24 0
12 13 4 24 0
12 13 5 24 0
12 13 6 24 0
12 13 7 24 0
12 13 8 24 0
12 13 9 24 0
12 13 10 22 0
12 13 11 22 0
12 13 12 22 0
12 13 13 22 32
12 14 0 23 80
12 14 1 23 16
12 14 2 22 0
12 14 3 22 0
12 14 4 22 0
12 14 5 22 0
12 14 6 22 0
12 14 7 22 0
12 14 8 22 0
12 14 9 22 0
12 14 10 22 0
12 14 11 22 0
12 14 12 22 0
12 14 13 22 0
12 14 14 23 16
12 14 15 23 48
12 15 0 23 72
12 15 1 23 8
12 15 2 22 8
12 15 3 22 8
12 15 4 22 8
12 15 5 22 8
12 15 6 22 8
12 15 7 22 8
12 15 8 22 8
12 15 9 22 8
12 15 10 22 8
12 15 11 22 8
12 15 12 22 8
12 15 13 22 8
12 15 14 23 8
12 15 15 23 40
13 0 0 23 80
13 0 1 23 48
13 0 14 23 80
13 0 15 23 48
13 1 0 23 72
13 1 1 23 40
13 1 14 23 72
13 1 15 23 40
13 4 2 24 82
13 4 3 24 18
13 4 4 24 18
13 4 5 24 18
13 4 6 25 18
13 4 7 25 18
13 4 8 25 18
13 4 9 25 50
13 5 2 24 74
13 5 3 24 10
13 5 4 24 10
13 5 5 24 10
13 5 6 25 10
13 5 7 25 10
13 5 8 25 10
13 5 9 25 42
13 8 2 24 82
13 8 3 24 18
13 8 4 24 18
13 8 5 24 18
13 8 6 24 18
13 8 7 24 18
13 8 8 24 18
13 8 9 24 18
13 8 10 24 18
13 8 11 24 18
13 8 12 24 18
13 8 13 24 50
13 9 2 24 66
13 9 3 24 2
13 9 4 24 2
13 9 5 24 2
13 9 6 24 2
13 9 7 24 2
13 9 8 24 2
13 9 9 24 2
13 9 10 24 2
13 9 11 24 2
13 9 12 24 2
13 9 13 24 34
13 10 2 24 66
13 10 3 24 2
13 10 4 24 2
13 10 5 24 2
13 10 6 24 2
13 10 7 24 2
13 10 8 24 2
13 10 9 24 2
13 10 10 24 2
13 10 11 24 2
13 10 12 24 2
13 10 13 24 34
13 11 2 24 66
13 11 3 24 2
13 11 4 24 2
13 11 5 24 2
13 11 6 24 2
13 11 7 24 2
13 11 8 24 2
13 11 9 24 2
13 11 10 24 2
13 11 11 24 2
13 11 12 24 2
13 11 13 24 34
13 12 2 24 66
13 12 3 24 2
13 12 4 24 2
13 12 5 24 2
13 12 6 24 2
13 12 7 24 2
13 12 8 24 2
13 12 9 24 2
13 12 10 22 2
13 12 11 22 2
13 12 12 22 2
13 12 13 22 34
13 13 2 24 66
13 13 3 24 2
13 13 4 24 2
13 13 5 24 2
13 13 6 24 2
13 13 7 24 2
13 13 8 24 2
13 13 9 24 2
13 13 10 22 2
13 13 11 22 2
13 13 12 22 2
13 13 13 22 34
13 14 0 23 80
13 14 1 23 16
13 14 2 22 0
13 14 3 22 0
13 14 4 22 0
13 14 5 22 0
13 14 6 22 0
13 14 7 22 0
13 14 8 22 0
13 14 9 22 0
13 14 10 22 0
13 14 11 22 0
13 14 12 22 0
13 14 13 22 0
13 14 14 23 16
13 14 15 23 48
13 15 0 23 72
13 15 1 23 8
13 15 2 22 8
13 15 3 22 8
13 15 4 22 8
13 15 5 22 8
13 15 6 22 8
13 15 7 22 8
13 15 8 22 8
13 15 9 22 8
13 15 10 22 8
13 15 11 22 8
13 15 12 22 8
13 15 13 22 8
13 15 14 23 8
13 15 15 23 40
14 0 0 23 80
14 0 1 23 16
14 0 2 23 20
14 0 3 23 20
14 0 4 23 20
14 0 5 23 20
14 0 6 23 20
14 0 7 23 20
14 0 8 23 20
14 0 9 23 20
14 0 10 23 20
14 0 11 23 20
14 0 12 23 20
14 0 13 23 20
14 0 14 23 16
14 0 15 23 48
14 1 0 23 64
14 1 1 23 0
14 1 2 23 12
14 1 3 23 12
14 1 4 23 12
14 1 5 23 12
14 1 6 23 12
14 1 7 23 12
14 1 8 23 12
14 1 9 23 12
14 1 10 23 12
14 1 11 23 12
14 1 12 23 12
14 1 13 23 12
14 1 14 23 0
14 1 15 23 32
14 2 0 23 68
14 2 1 23 36
14 2 14 23 68
14 2 15 23 36
14 3 0 23 68
14 3 1 23 36
14 3 14 23 68
14 3 15 23 36
14 4 0 23 68
14 4 1 23 36
14 4 14 23 68
14 4 15 23 36
14 5 0 23 68
14 5 1 23 36
14 5 14 23 68
14 5 15 23 36
14 6 0 23 68
14 6 1 23 36
14 6 14 23 68
14 6 15 23 36
14 7 0 23 68
14 7 1 23 36
14 7 14 23 68
14 7 15 23 36
14 8 0 23 68
14 8 1 23 36
14 8 14 23 68
14 8 15 23 36
14 9 0 23 68
14 9 1 23 36
14 9 14 23 68
14 9 15 23 36
14 10 0 23 68
14 10 1 23 36
14 10 14 23 68
14 10 15 23 36
14 11 0 23 68
14 11 1 23 36
14 11 14 23 68
14 11 15 23 36
14 12 0 23 68
14 12 1 23 36
14 12 14 23 68
14 12 15 23 36
14 13 0 23 68
14 13 1 23 36
14 13 14 23 68
14 13 15 23 36
14 14 0 23 64
14 14 1 23 0
14 14 2 23 16
14 14 3 23 16
14 14 4 23 16
14 14 5 23 16
14 14 6 23 16
14 14 7 23 16
14 14 8 23 16
14 14 9 23 16
14 14 10 23 16
14 14 11 23 16
14 14 12 23 16
14 14 13 23 16
14 14 14 23 0
14 14 15 23 32
14 15 0 23 72
14 15 1 23 8
14 15 2 23 8
14 15 3 23 8
14 15 4 23 8
14 15 5 23 8
14 15 6 23 8
14 15 7 23 8
14 15 8 23 8
14 15 9 23 8
14 15 10 23 8
14 15 11 23 8
14 15 12 23 8
14 15 13 23 8
14 15 14 23 8
14 15 15 23 40
15 0 0 23 82
15 0 1 23 18
15 0 2 23 18
15 0 3 23 18
15 0 4 23 18
15 0 5 23 18
15 0 6 23 18
15 0 7 23 18
15 0 8 23 18
15 0 9 23 18
15 0 10 23 18
15 0 11 23 18
15 0 12 23 18
15 0 13 23 18
15 0 14 23 18
15 0 15 23 50
15 1 0 23 66
15 1 1 23 2
15 1 2 23 10
15 1 3 23 10
15 1 4 23 10
15 1 5 23 10
15 1 6 23 10
15 1 7 23 10
15 1 8 23 10
15 1 9 23 10
15 1 10 23 10
15 1 11 23 10
15 1 12 23 10
15 1 13 23 10
15 1 14 23 2
15 1 15 23 34
15 2 0 23 66
15 2 1 23 34
15 2 14 23 66
15 2 15 23 34
15 3 0 23 66
15 3 1 23 34
15 3 14 23 66
15 3 15 23 34
15 4 0 23 66
15 4 1 23 34
15 4 14 23 66
15 4 15 23 34
15 5 0 23 66
15 5 1 23 34
15 5 14 23 66
15 5 15 23 34
15 6 0 23 66
15 6 1 23 34
15 6 14 23 66
15 6 15 23 34
15 7 0 23 66
15 7 1 23 34
15 7 14 23 66
15 7 15 23 34
15 8 0 23 66
15 8 1 23 34
15 8 14 23 66
15 8 15 23 34
15 9 0 23 66
15 9 1 23 34
15 9 14 23 66
15 9 15 23 34
15 10 0 23 66
15 10 1 23 34
15 10 14 23 66
15 10 15 23 34
15 11 0 23 66
15 11 1 23 34
15 11 14 23 66
15 11 15 23 34
15 12 0 23 66
15 12 1 23 34
15 12 14 23 66
15 12 15 23 34
15 13 0 23 66
15 13 1 23 34
15 13 14 23 66
15 13 15 23 34
15 14 0 23 66
15 14 1 23 2
15 14 2 23 18
15 14 3 23 18
15 14 4 23 18
15 14 5 23 18
15 14 6 23 18
15 14 7 23 18
15 14 8 23 18
15 14 9 23 18
15 14 10 23 18
15 14 11 23 18
15 14 12 23 18
15 14 13 23 18
15 14 14 23 2
15 14 15 23 34
15 15 0 23 74
15 15 1 23 10
15 15 2 23 10
15 15 3 23 10
15 15 4 23 10
15 15 5 23 10
15 15 6 23 10
15 15 7 23 10
15 15 8 23 10
15 15 9 23 10
15 15 10 23 10
15 15 11 23 10
15 15 12 23 10
15 15 13 23 10
15 15 14 23 10
15 15 15 23 42
