Qubicle Exchange Format
Version 0.2
www.minddesk.com
8 8 8
4
0.466667 0.466667 0.466667
0.501961 0.815686 0.062745
0.866667 0.866667 0.866667
1.000000 0.070588 0.000000
0 3 2 1 126
0 3 3 1 126
0 3 4 1 126
0 3 5 1 126
0 4 2 1 92
0 4 3 1 28
0 4 4 1 28
0 4 5 1 60
1 2 3 3 126
1 2 4 3 126
1 3 1 1 126
1 3 2 1 126
1 3 3 1 126
1 3 4 1 126
1 3 5 1 126
1 3 6 1 126
1 4 1 1 92
1 4 2 1 24
1 4 3 1 16
1 4 4 1 16
1 4 5 1 24
1 4 6 1 60
1 5 3 2 76
1 5 4 2 44
2 2 2 1 92
2 2 3 1 24
2 2 4 1 24
2 2 5 1 60
2 3 0 1 126
2 3 1 1 126
2 3 2 1 126
2 3 3 1 126
2 3 4 1 126
2 3 5 1 126
2 3 6 1 126
2 3 7 1 126
2 4 0 1 92
2 4 1 1 24
2 4 2 1 126
2 4 3 1 126
2 4 4 1 126
2 4 5 1 126
2 4 6 1 24
2 4 7 1 60
2 5 2 2 76
2 5 3 2 0
2 5 4 2 0
2 5 5 2 44
2 6 3 2 76
2 6 4 2 44
3 2 1 3 126
3 2 2 1 24
3 2 3 1 24
3 2 4 1 24
3 2 5 1 24
3 2 6 3 126
3 3 0 1 126
3 3 1 1 126
3 3 2 1 126
3 3 3 1 126
3 3 4 1 126
3 3 5 1 126
3 3 6 1 126
3 3 7 1 126
3 4 0 1 88
3 4 1 1 16
3 4 2 1 126
3 4 3 1 126
3 4 4 1 126
3 4 5 1 126
3 4 6 1 16
3 4 7 1 56
3 5 1 2 76
3 5 2 2 0
3 5 3 0 0
3 5 4 0 0
3 5 5 2 0
3 5 6 2 44
3 6 2 2 76
3 6 3 2 0
3 6 4 2 0
3 6 5 2 44
3 7 3 2 76
3 7 4 2 44
4 2 1 3 126
4 2 2 1 24
4 2 3 1 24
4 2 4 1 24
4 2 5 1 24
4 2 6 3 126
4 3 0 1 126
4 3 1 1 126
4 3 2 1 126
4 3 3 1 126
4 3 4 1 126
4 3 5 1 126
4 3 6 1 126
4 3 7 1 126
4 4 0 1 88
4 4 1 1 16
4 4 2 1 126
4 4 3 1 126
4 4 4 1 126
4 4 5 1 126
4 4 6 1 16
4 4 7 1 56
4 5 1 2 74
4 5 2 2 0
4 5 3 0 0
4 5 4 0 0
4 5 5 2 0
4 5 6 2 42
4 6 2 2 74
4 6 3 2 0
4 6 4 2 0
4 6 5 2 42
4 7 3 2 74
4 7 4 2 42
5 2 2 1 90
5 2 3 1 24
5 2 4 1 24
5 2 5 1 58
5 3 0 1 126
5 3 1 1 126
5 3 2 1 126
5 3 3 1 126
5 3 4 1 126
5 3 5 1 126
5 3 6 1 126
5 3 7 1 126
5 4 0 1 90
5 4 1 1 24
5 4 2 1 126
5 4 3 1 126
5 4 4 1 126
5 4 5 1 126
5 4 6 1 24
5 4 7 1 58
5 5 2 2 74
5 5 3 2 0
5 5 4 2 0
5 5 5 2 42
5 6 3 2 74
5 6 4 2 42
6 2 3 3 126
6 2 4 3 126
6 3 1 1 126
6 3 2 1 126
6 3 3 1 126
6 3 4 1 126
6 3 5 1 126
6 3 6 1 126
6 4 1 1 90
6 4 2 1 24
6 4 3 1 16
6 4 4 1 16
6 4 5 1 24
6 4 6 1 58
6 5 3 2 74
6 5 4 2 42
7 3 2 1 126
7 3 3 1 126
7 3 4 1 126
7 3 5 1 126
7 4 2 1 90
7 4 3 1 26
7 4 4 1 26
7 4 5 1 58
