Qubicle Exchange Format
Version 0.2
www.minddesk.com
16 16 16
10
0.317647 0.317647 0.317647
0.321569 0.321569 0.321569
0.325490 0.325490 0.325490
0.329412 0.329412 0.329412
0.333333 0.333333 0.333333
0.337255 0.337255 0.337255
0.341176 0.341176 0.341176
0.345098 0.345098 0.345098
0.349020 0.349020 0.349020
0.352941 0.352941 0.352941
0 4 7 3 84
0 4 8 3 20
0 4 9 4 52
0 5 7 4 68
0 5 8 8 4
0 5 9 3 4
0 5 10 6 60
0 6 7 6 76
0 6 8 2 12
0 6 9 2 44
0 8 8 1 124
0 10 5 2 124
0 11 7 1 124
1 3 5 4 92
1 3 6 6 20
1 3 7 9 20
1 3 8 8 20
1 3 9 1 20
1 3 10 3 52
1 4 6 4 68
1 4 7 3 0
1 4 8 2 0
1 4 9 6 0
1 4 10 5 36
1 5 5 2 84
1 5 6 6 4
1 5 7 1 0
1 5 8 2 0
1 5 9 6 0
1 5 10 1 32
1 6 4 8 84
1 6 5 1 4
1 6 6 0 4
1 6 7 8 0
1 6 8 2 0
1 6 9 7 0
1 6 10 8 36
1 7 4 3 68
1 7 5 1 12
1 7 6 6 12
1 7 7 8 4
1 7 8 8 4
1 7 9 2 4
1 7 10 8 36
1 8 4 9 100
1 8 7 8 68
1 8 8 3 0
1 8 9 6 4
1 8 10 4 36
1 9 4 3 100
1 9 6 3 84
1 9 7 4 4
1 9 8 3 4
1 9 9 6 4
1 9 10 6 4
1 9 11 6 60
1 10 3 3 92
1 10 4 3 12
1 10 5 5 16
1 10 6 8 4
1 10 7 1 4
1 10 8 1 4
1 10 9 3 4
1 10 10 8 44
1 11 5 1 78
1 11 6 3 12
1 11 7 9 8
1 11 8 0 12
1 11 9 3 44
2 2 5 0 84
2 2 6 1 20
2 2 7 4 20
2 2 8 5 20
2 2 9 4 20
2 2 10 2 52
2 3 4 7 84
2 3 5 4 0
2 3 6 2 0
2 3 7 9 0
2 3 8 1 0
2 3 9 8 0
2 3 10 6 32
2 4 4 3 68
2 4 5 1 4
2 4 6 2 0
2 4 7 4 0
2 4 8 9 0
2 4 9 8 0
2 4 10 6 32
2 5 4 1 68
2 5 5 1 0
2 5 6 2 0
2 5 7 9 0
2 5 8 5 0
2 5 9 3 0
2 5 10 9 32
2 6 3 4 84
2 6 4 8 0
2 6 5 3 0
2 6 6 1 0
2 6 7 3 0
2 6 8 4 0
2 6 9 5 0
2 6 10 8 34
2 7 3 0 68
2 7 4 3 0
2 7 5 3 0
2 7 6 3 0
2 7 7 8 0
2 7 8 2 0
2 7 9 1 0
2 7 10 3 32
2 8 3 6 68
2 8 4 1 0
2 8 5 2 4
2 8 6 0 4
2 8 7 2 0
2 8 8 3 0
2 8 9 1 0
2 8 10 3 32
2 9 2 1 84
2 9 3 8 4
2 9 4 5 0
2 9 5 2 4
2 9 6 4 0
2 9 7 9 0
2 9 8 2 0
2 9 9 4 0
2 9 10 2 0
2 9 11 3 48
2 10 2 6 76
2 10 3 2 8
2 10 4 3 8
2 10 5 6 8
2 10 6 1 0
2 10 7 1 0
2 10 8 1 0
2 10 9 4 0
2 10 10 6 0
2 10 11 2 4
2 10 12 3 60
2 11 6 0 64
2 11 7 3 0
2 11 8 8 8
2 11 9 0 8
2 11 10 3 4
2 11 11 8 44
2 12 6 1 76
2 12 7 8 44
2 12 10 1 108
3 1 5 0 84
3 1 6 2 20
3 1 7 2 52
3 2 4 3 84
3 2 5 2 0
3 2 6 4 0
3 2 7 5 0
3 2 8 3 16
3 2 9 2 16
3 2 10 4 16
3 2 11 8 60
3 3 3 8 84
3 3 4 3 0
3 3 5 1 0
3 3 6 3 0
3 3 7 1 0
3 3 8 6 0
3 3 9 8 0
3 3 10 4 32
3 4 3 2 68
3 4 4 3 0
3 4 5 8 0
3 4 6 4 0
3 4 7 4 0
3 4 8 1 0
3 4 9 7 0
3 4 10 9 32
3 5 3 1 68
3 5 4 3 0
3 5 5 9 0
3 5 6 8 0
3 5 7 7 0
3 5 8 4 0
3 5 9 2 0
3 5 10 9 40
3 6 1 5 84
3 6 2 4 20
3 6 3 3 0
3 6 4 3 0
3 6 5 4 0
3 6 6 1 0
3 6 7 3 0
3 6 8 8 0
3 6 9 1 32
3 7 1 2 68
3 7 2 0 4
3 7 3 3 0
3 7 4 5 0
3 7 5 6 0
3 7 6 3 0
3 7 7 8 0
3 7 8 2 0
3 7 9 9 0
3 7 10 3 48
3 8 1 2 76
3 8 2 5 4
3 8 3 1 0
3 8 4 2 0
3 8 5 6 0
3 8 6 6 0
3 8 7 6 0
3 8 8 7 0
3 8 9 6 0
3 8 10 4 32
3 9 2 5 64
3 9 3 4 0
3 9 4 7 0
3 9 5 6 0
3 9 6 0 0
3 9 7 3 0
3 9 8 6 0
3 9 9 2 0
3 9 10 7 0
3 9 11 2 48
3 10 1 2 92
3 10 2 3 8
3 10 3 2 8
3 10 4 8 8
3 10 5 6 0
3 10 6 5 0
3 10 7 1 0
3 10 8 6 0
3 10 9 9 0
3 10 10 2 0
3 10 11 3 0
3 10 12 2 16
3 10 13 0 28
3 10 14 9 60
3 11 5 6 76
3 11 6 9 0
3 11 7 7 0
3 11 8 2 0
3 11 9 6 0
3 11 10 1 0
3 11 11 2 0
3 11 12 2 36
3 12 6 6 64
3 12 7 3 0
3 12 8 1 12
3 12 9 4 4
3 12 10 5 0
3 12 11 4 12
3 12 12 2 46
3 13 6 2 76
3 13 7 7 44
3 13 9 1 76
3 13 10 5 44
4 0 6 3 84
4 0 7 9 52
4 1 4 2 84
4 1 5 6 16
4 1 6 3 0
4 1 7 4 0
4 1 8 3 20
4 1 9 8 52
4 2 4 4 64
4 2 5 2 0
4 2 6 6 0
4 2 7 2 0
4 2 8 6 0
4 2 9 3 0
4 2 10 2 16
4 2 11 5 56
4 3 3 6 80
4 3 4 5 0
4 3 5 1 0
4 3 6 1 0
4 3 7 2 0
4 3 8 1 0
4 3 9 8 0
4 3 10 4 32
4 4 2 3 84
4 4 3 0 0
4 4 4 9 0
4 4 5 4 0
4 4 6 6 0
4 4 7 5 0
4 4 8 3 0
4 4 9 5 0
4 4 10 8 32
4 5 2 3 68
4 5 3 3 0
4 5 4 2 0
4 5 5 9 0
4 5 6 3 0
4 5 7 6 0
4 5 8 7 0
4 5 9 3 0
4 5 10 0 40
4 6 1 6 80
4 6 2 4 0
4 6 3 6 0
4 6 4 3 0
4 6 5 4 0
4 6 6 6 0
4 6 7 8 0
4 6 8 2 0
4 6 9 3 32
4 7 1 1 64
4 7 2 2 0
4 7 3 1 0
4 7 4 3 0
4 7 5 6 0
4 7 6 7 0
4 7 7 6 0
4 7 8 3 0
4 7 9 2 0
4 7 10 1 48
4 8 1 6 64
4 8 2 6 0
4 8 3 1 0
4 8 4 8 0
4 8 5 8 0
4 8 6 4 0
4 8 7 8 0
4 8 8 3 0
4 8 9 3 0
4 8 10 2 32
4 9 1 4 68
4 9 2 5 0
4 9 3 1 0
4 9 4 4 0
4 9 5 3 0
4 9 6 1 0
4 9 7 4 0
4 9 8 8 0
4 9 9 0 0
4 9 10 1 0
4 9 11 2 48
4 10 1 3 64
4 10 2 1 0
4 10 3 3 8
4 10 4 4 0
4 10 5 1 0
4 10 6 1 0
4 10 7 1 0
4 10 8 4 0
4 10 9 2 0
4 10 10 2 0
4 10 11 2 0
4 10 12 1 16
4 10 13 9 16
4 10 14 3 56
4 11 1 0 76
4 11 2 8 44
4 11 4 2 76
4 11 5 1 8
4 11 6 8 0
4 11 7 6 0
4 11 8 2 0
4 11 9 4 0
4 11 10 4 0
4 11 11 3 0
4 11 12 7 8
4 11 13 1 44
4 12 6 0 64
4 12 7 1 0
4 12 8 5 0
4 12 9 1 0
4 12 10 7 0
4 12 11 6 40
4 13 6 4 72
4 13 7 3 8
4 13 8 5 12
4 13 9 6 8
4 13 10 4 32
4 14 10 3 108
5 0 5 8 84
5 0 6 7 16
5 0 7 1 48
5 1 4 9 80
5 1 5 3 0
5 1 6 6 0
5 1 7 3 0
5 1 8 4 16
5 1 9 6 16
5 1 10 6 52
5 2 3 1 84
5 2 4 2 0
5 2 5 1 0
5 2 6 2 0
5 2 7 6 0
5 2 8 7 0
5 2 9 1 0
5 2 10 1 0
5 2 11 4 56
5 3 2 1 84
5 3 3 3 0
5 3 4 2 0
5 3 5 6 0
5 3 6 4 0
5 3 7 8 0
5 3 8 4 0
5 3 9 1 0
5 3 10 7 32
5 4 2 3 64
5 4 3 0 0
5 4 4 3 0
5 4 5 1 0
5 4 6 0 0
5 4 7 2 0
5 4 8 4 0
5 4 9 8 0
5 4 10 2 32
5 5 1 2 84
5 5 2 4 0
5 5 3 3 0
5 5 4 3 0
5 5 5 1 0
5 5 6 6 0
5 5 7 3 0
5 5 8 5 0
5 5 9 9 0
5 5 10 7 40
5 6 1 5 64
5 6 2 9 0
5 6 3 1 0
5 6 4 3 0
5 6 5 2 0
5 6 6 2 0
5 6 7 3 0
5 6 8 8 0
5 6 9 1 32
5 7 1 7 66
5 7 2 2 0
5 7 3 3 0
5 7 4 2 0
5 7 5 3 0
5 7 6 2 0
5 7 7 2 0
5 7 8 5 0
5 7 9 9 0
5 7 10 7 48
5 8 1 8 64
5 8 2 3 0
5 8 3 8 0
5 8 4 6 0
5 8 5 7 0
5 8 6 3 0
5 8 7 0 0
5 8 8 6 0
5 8 9 2 0
5 8 10 2 32
5 9 1 3 64
5 9 2 5 0
5 9 3 1 0
5 9 4 3 0
5 9 5 7 0
5 9 6 4 0
5 9 7 2 0
5 9 8 0 0
5 9 9 9 0
5 9 10 8 0
5 9 11 1 48
5 10 1 4 64
5 10 2 6 0
5 10 3 3 0
5 10 4 6 0
5 10 5 2 0
5 10 6 6 0
5 10 7 1 0
5 10 8 4 0
5 10 9 2 0
5 10 10 3 0
5 10 11 2 0
5 10 12 6 16
5 10 13 5 16
5 10 14 9 24
5 10 15 7 62
5 11 1 0 64
5 11 2 7 0
5 11 3 4 4
5 11 4 7 0
5 11 5 6 0
5 11 6 6 0
5 11 7 3 0
5 11 8 2 0
5 11 9 1 0
5 11 10 2 0
5 11 11 5 0
5 11 12 2 0
5 11 13 1 40
5 12 1 9 76
5 12 2 0 4
5 12 3 1 4
5 12 4 5 4
5 12 5 8 4
5 12 6 3 0
5 12 7 4 0
5 12 8 4 0
5 12 9 2 0
5 12 10 8 0
5 12 11 2 0
5 12 12 3 46
5 13 2 1 76
5 13 3 3 4
5 13 4 1 4
5 13 5 1 4
5 13 6 6 0
5 13 7 3 0
5 13 8 6 0
5 13 9 1 8
5 13 10 8 0
5 13 11 2 44
5 14 3 9 76
5 14 4 2 12
5 14 5 8 4
5 14 6 1 12
5 14 7 3 12
5 14 8 3 44
5 14 10 0 104
5 15 5 8 108
6 0 4 2 84
6 0 5 7 16
6 0 6 6 16
6 0 7 5 48
6 1 4 3 64
6 1 5 3 0
6 1 6 8 0
6 1 7 6 0
6 1 8 9 16
6 1 9 1 16
6 1 10 4 16
6 1 11 6 52
6 2 3 1 80
6 2 4 3 0
6 2 5 3 0
6 2 6 9 0
6 2 7 2 0
6 2 8 0 0
6 2 9 1 0
6 2 10 5 0
6 2 11 5 0
6 2 12 3 60
6 3 2 1 80
6 3 3 2 0
6 3 4 1 0
6 3 5 2 0
6 3 6 7 0
6 3 7 1 0
6 3 8 3 0
6 3 9 3 0
6 3 10 3 0
6 3 11 0 44
6 4 1 1 84
6 4 2 2 0
6 4 3 7 0
6 4 4 2 0
6 4 5 2 0
6 4 6 6 0
6 4 7 9 0
6 4 8 1 0
6 4 9 3 0
6 4 10 4 32
6 5 1 8 64
6 5 2 3 0
6 5 3 6 0
6 5 4 3 0
6 5 5 7 0
6 5 6 6 0
6 5 7 7 0
6 5 8 8 0
6 5 9 1 0
6 5 10 8 32
6 6 1 4 72
6 6 2 6 0
6 6 3 2 0
6 6 4 0 0
6 6 5 1 0
6 6 6 3 0
6 6 7 8 0
6 6 8 3 0
6 6 9 5 0
6 6 10 0 36
6 7 2 4 64
6 7 3 3 0
6 7 4 2 0
6 7 5 4 0
6 7 6 1 0
6 7 7 6 0
6 7 8 6 0
6 7 9 3 0
6 7 10 1 32
6 8 1 7 80
6 8 2 0 0
6 8 3 4 0
6 8 4 1 0
6 8 5 8 0
6 8 6 6 0
6 8 7 2 0
6 8 8 2 0
6 8 9 3 0
6 8 10 1 0
6 8 11 6 52
6 9 1 9 64
6 9 2 4 0
6 9 3 1 0
6 9 4 3 0
6 9 5 4 0
6 9 6 6 0
6 9 7 2 0
6 9 8 6 0
6 9 9 4 0
6 9 10 3 0
6 9 11 8 0
6 9 12 3 52
6 10 1 1 64
6 10 2 1 0
6 10 3 3 0
6 10 4 4 0
6 10 5 3 0
6 10 6 6 0
6 10 7 3 0
6 10 8 5 0
6 10 9 5 0
6 10 10 4 0
6 10 11 1 0
6 10 12 3 0
6 10 13 1 16
6 10 14 8 58
6 11 1 1 64
6 11 2 8 0
6 11 3 6 0
6 11 4 3 0
6 11 5 7 0
6 11 6 7 0
6 11 7 2 0
6 11 8 3 0
6 11 9 2 0
6 11 10 3 0
6 11 11 2 0
6 11 12 5 10
6 11 13 1 42
6 12 1 2 72
6 12 2 8 0
6 12 3 8 0
6 12 4 1 0
6 12 5 4 0
6 12 6 2 0
6 12 7 1 0
6 12 8 3 0
6 12 9 1 0
6 12 10 4 0
6 12 11 2 34
6 13 2 8 72
6 13 3 5 0
6 13 4 3 0
6 13 5 0 0
6 13 6 0 0
6 13 7 9 0
6 13 8 8 0
6 13 9 3 0
6 13 10 8 0
6 13 11 4 34
6 14 3 7 72
6 14 4 7 0
6 14 5 2 0
6 14 6 5 8
6 14 7 1 8
6 14 8 4 8
6 14 9 2 12
6 14 10 6 0
6 14 11 4 46
6 15 4 2 76
6 15 5 7 42
6 15 10 2 108
7 0 4 6 80
7 0 5 3 16
7 0 6 5 16
7 0 7 3 16
7 0 8 2 52
7 1 4 2 64
7 1 5 3 0
7 1 6 8 0
7 1 7 3 0
7 1 8 2 0
7 1 9 2 16
7 1 10 1 16
7 1 11 9 48
7 2 3 7 80
7 2 4 2 0
7 2 5 5 0
7 2 6 2 0
7 2 7 4 0
7 2 8 2 0
7 2 9 6 0
7 2 10 7 0
7 2 11 4 0
7 2 12 7 16
7 2 13 9 62
7 3 2 2 80
7 3 3 1 0
7 3 4 3 0
7 3 5 3 0
7 3 6 1 0
7 3 7 1 0
7 3 8 3 0
7 3 9 8 0
7 3 10 2 0
7 3 11 8 0
7 3 12 7 44
7 4 1 1 80
7 4 2 3 0
7 4 3 3 0
7 4 4 6 0
7 4 5 7 0
7 4 6 3 0
7 4 7 4 0
7 4 8 2 0
7 4 9 2 0
7 4 10 0 0
7 4 11 6 36
7 5 1 6 64
7 5 2 1 0
7 5 3 1 0
7 5 4 1 0
7 5 5 3 0
7 5 6 6 0
7 5 7 4 0
7 5 8 7 0
7 5 9 7 0
7 5 10 2 0
7 5 11 8 36
7 6 1 0 72
7 6 2 7 0
7 6 3 8 0
7 6 4 3 0
7 6 5 2 0
7 6 6 2 0
7 6 7 5 0
7 6 8 3 0
7 6 9 2 0
7 6 10 4 0
7 6 11 8 36
7 7 2 8 64
7 7 3 6 0
7 7 4 6 0
7 7 5 8 0
7 7 6 3 0
7 7 7 8 0
7 7 8 3 0
7 7 9 3 0
7 7 10 3 0
7 7 11 8 36
7 8 1 1 80
7 8 2 6 0
7 8 3 2 0
7 8 4 8 0
7 8 5 3 0
7 8 6 3 0
7 8 7 1 0
7 8 8 4 0
7 8 9 5 0
7 8 10 3 0
7 8 11 0 0
7 8 12 8 52
7 9 1 3 64
7 9 2 3 0
7 9 3 2 0
7 9 4 2 0
7 9 5 1 0
7 9 6 0 0
7 9 7 0 0
7 9 8 6 0
7 9 9 0 0
7 9 10 3 0
7 9 11 3 0
7 9 12 8 0
7 9 13 3 20
7 9 14 8 28
7 9 15 3 60
7 10 1 3 66
7 10 2 1 0
7 10 3 8 0
7 10 4 4 0
7 10 5 4 0
7 10 6 4 0
7 10 7 2 0
7 10 8 0 0
7 10 9 1 0
7 10 10 7 0
7 10 11 6 0
7 10 12 2 8
7 10 13 3 40
7 11 1 1 64
7 11 2 7 0
7 11 3 6 0
7 11 4 1 0
7 11 5 1 0
7 11 6 0 0
7 11 7 9 0
7 11 8 1 0
7 11 9 4 0
7 11 10 7 0
7 11 11 3 40
7 12 1 1 72
7 12 2 7 0
7 12 3 2 0
7 12 4 6 0
7 12 5 4 0
7 12 6 1 0
7 12 7 3 0
7 12 8 3 0
7 12 9 2 0
7 12 10 3 32
7 13 2 6 72
7 13 3 2 0
7 13 4 3 0
7 13 5 1 0
7 13 6 2 0
7 13 7 3 0
7 13 8 6 0
7 13 9 8 0
7 13 10 8 32
7 14 3 5 72
7 14 4 1 0
7 14 5 1 8
7 14 6 2 8
7 14 7 3 10
7 14 8 3 10
7 14 9 3 8
7 14 10 8 32
7 15 4 7 104
7 15 10 4 106
8 0 4 4 80
8 0 5 2 16
8 0 6 6 16
8 0 7 1 16
8 0 8 0 48
8 1 4 6 64
8 1 5 0 0
8 1 6 3 0
8 1 7 4 0
8 1 8 7 0
8 1 9 3 16
8 1 10 0 16
8 1 11 1 48
8 2 3 2 80
8 2 4 1 0
8 2 5 4 0
8 2 6 5 0
8 2 7 1 0
8 2 8 1 0
8 2 9 5 0
8 2 10 7 0
8 2 11 6 0
8 2 12 2 48
8 3 2 2 80
8 3 3 6 0
8 3 4 4 0
8 3 5 9 0
8 3 6 2 0
8 3 7 4 0
8 3 8 4 0
8 3 9 2 0
8 3 10 7 0
8 3 11 1 0
8 3 12 2 0
8 3 13 4 20
8 3 14 4 52
8 4 1 0 80
8 4 2 0 0
8 4 3 4 0
8 4 4 2 0
8 4 5 8 0
8 4 6 3 0
8 4 7 6 0
8 4 8 9 0
8 4 9 4 0
8 4 10 3 0
8 4 11 3 0
8 4 12 4 4
8 4 13 0 4
8 4 14 9 4
8 4 15 6 52
8 5 1 1 66
8 5 2 8 0
8 5 3 4 0
8 5 4 7 0
8 5 5 8 0
8 5 6 2 0
8 5 7 9 0
8 5 8 2 0
8 5 9 1 0
8 5 10 6 0
8 5 11 6 0
8 5 12 3 4
8 5 13 6 4
8 5 14 1 4
8 5 15 2 36
8 6 1 8 66
8 6 2 1 0
8 6 3 1 0
8 6 4 2 0
8 6 5 4 0
8 6 6 2 0
8 6 7 3 0
8 6 8 3 0
8 6 9 4 0
8 6 10 6 0
8 6 11 3 0
8 6 12 4 4
8 6 13 3 4
8 6 14 1 4
8 6 15 2 36
8 7 1 6 70
8 7 2 2 0
8 7 3 1 0
8 7 4 2 0
8 7 5 1 0
8 7 6 3 0
8 7 7 3 0
8 7 8 4 0
8 7 9 9 0
8 7 10 7 0
8 7 11 3 0
8 7 12 4 4
8 7 13 7 4
8 7 14 3 4
8 7 15 0 36
8 8 1 4 66
8 8 2 2 0
8 8 3 5 0
8 8 4 3 0
8 8 5 6 0
8 8 6 9 0
8 8 7 7 0
8 8 8 1 0
8 8 9 2 0
8 8 10 4 0
8 8 11 2 0
8 8 12 8 0
8 8 13 4 4
8 8 14 2 4
8 8 15 3 36
8 9 1 3 74
8 9 2 1 0
8 9 3 6 0
8 9 4 4 0
8 9 5 4 0
8 9 6 3 0
8 9 7 7 0
8 9 8 4 0
8 9 9 4 0
8 9 10 2 0
8 9 11 4 0
8 9 12 1 0
8 9 13 2 0
8 9 14 4 8
8 9 15 1 40
8 10 2 4 64
8 10 3 1 0
8 10 4 3 0
8 10 5 3 0
8 10 6 8 0
8 10 7 1 0
8 10 8 4 0
8 10 9 3 0
8 10 10 3 0
8 10 11 4 0
8 10 12 2 8
8 10 13 2 40
8 11 1 1 82
8 11 2 0 0
8 11 3 4 0
8 11 4 8 0
8 11 5 3 0
8 11 6 1 0
8 11 7 2 0
8 11 8 3 0
8 11 9 3 0
8 11 10 6 0
8 11 11 3 40
8 12 1 6 74
8 12 2 9 0
8 12 3 3 0
8 12 4 8 0
8 12 5 4 0
8 12 6 2 0
8 12 7 5 0
8 12 8 2 0
8 12 9 8 0
8 12 10 3 32
8 13 2 1 72
8 13 3 8 0
8 13 4 3 0
8 13 5 5 0
8 13 6 4 0
8 13 7 3 8
8 13 8 2 8
8 13 9 9 0
8 13 10 1 32
8 14 3 2 72
8 14 4 3 0
8 14 5 4 0
8 14 6 1 40
8 14 9 3 72
8 14 10 3 40
8 15 4 3 72
8 15 5 4 46
9 0 4 3 82
9 0 5 2 16
9 0 6 2 16
9 0 7 9 16
9 0 8 1 16
9 0 9 1 20
9 0 10 2 52
9 1 3 4 84
9 1 4 3 0
9 1 5 1 0
9 1 6 7 0
9 1 7 1 0
9 1 8 0 0
9 1 9 4 0
9 1 10 2 0
9 1 11 2 18
9 1 12 6 54
9 2 3 9 64
9 2 4 1 0
9 2 5 3 0
9 2 6 3 0
9 2 7 3 0
9 2 8 1 0
9 2 9 3 0
9 2 10 9 0
9 2 11 2 0
9 2 12 3 32
9 3 2 2 80
9 3 3 4 0
9 3 4 4 0
9 3 5 1 0
9 3 6 4 0
9 3 7 9 0
9 3 8 6 0
9 3 9 2 0
9 3 10 4 0
9 3 11 0 0
9 3 12 4 0
9 3 13 4 16
9 3 14 1 48
9 4 1 5 90
9 4 2 9 0
9 4 3 0 0
9 4 4 8 0
9 4 5 6 0
9 4 6 0 0
9 4 7 2 0
9 4 8 1 0
9 4 9 5 0
9 4 10 8 0
9 4 11 8 0
9 4 12 0 0
9 4 13 8 0
9 4 14 6 0
9 4 15 3 50
9 5 2 1 64
9 5 3 6 0
9 5 4 4 0
9 5 5 8 0
9 5 6 0 0
9 5 7 4 0
9 5 8 4 0
9 5 9 8 0
9 5 10 7 0
9 5 11 3 0
9 5 12 3 0
9 5 13 0 0
9 5 14 8 0
9 5 15 1 32
9 6 2 4 64
9 6 3 3 0
9 6 4 1 0
9 6 5 1 0
9 6 6 3 0
9 6 7 1 0
9 6 8 3 0
9 6 9 1 0
9 6 10 2 0
9 6 11 3 0
9 6 12 2 0
9 6 13 4 0
9 6 14 1 0
9 6 15 9 32
9 7 2 4 64
9 7 3 5 0
9 7 4 6 0
9 7 5 8 0
9 7 6 2 0
9 7 7 2 0
9 7 8 7 0
9 7 9 9 0
9 7 10 8 0
9 7 11 9 0
9 7 12 2 0
9 7 13 1 0
9 7 14 8 0
9 7 15 1 34
9 8 2 9 64
9 8 3 2 0
9 8 4 5 0
9 8 5 5 0
9 8 6 3 0
9 8 7 1 0
9 8 8 3 0
9 8 9 7 0
9 8 10 1 0
9 8 11 2 0
9 8 12 8 0
9 8 13 3 0
9 8 14 1 2
9 8 15 1 34
9 9 2 0 64
9 9 3 5 0
9 9 4 4 0
9 9 5 9 0
9 9 6 4 0
9 9 7 6 0
9 9 8 0 0
9 9 9 3 0
9 9 10 3 0
9 9 11 7 0
9 9 12 1 0
9 9 13 3 0
9 9 14 7 8
9 9 15 1 42
9 10 2 6 64
9 10 3 6 0
9 10 4 5 0
9 10 5 2 0
9 10 6 6 0
9 10 7 2 0
9 10 8 6 0
9 10 9 5 0
9 10 10 3 0
9 10 11 3 0
9 10 12 2 0
9 10 13 8 32
9 11 2 9 66
9 11 3 5 0
9 11 4 4 0
9 11 5 3 0
9 11 6 3 0
9 11 7 3 0
9 11 8 2 0
9 11 9 1 0
9 11 10 6 0
9 11 11 1 8
9 11 12 6 12
9 11 13 2 44
9 12 2 4 64
9 12 3 4 0
9 12 4 3 0
9 12 5 9 0
9 12 6 4 0
9 12 7 6 0
9 12 8 3 0
9 12 9 1 0
9 12 10 2 32
9 13 2 3 72
9 13 3 2 2
9 13 4 2 0
9 13 5 3 0
9 13 6 4 0
9 13 7 1 0
9 13 8 8 0
9 13 9 6 0
9 13 10 3 32
9 14 3 5 74
9 14 4 8 2
9 14 5 3 10
9 14 6 8 0
9 14 7 5 6
9 14 8 6 14
9 14 9 3 8
9 14 10 3 40
9 15 4 6 106
9 15 6 6 78
9 15 7 1 46
10 0 5 7 82
10 0 6 2 16
10 0 7 1 16
10 0 8 2 16
10 0 9 3 16
10 0 10 2 50
10 1 3 0 82
10 1 4 2 16
10 1 5 3 0
10 1 6 3 0
10 1 7 2 0
10 1 8 4 0
10 1 9 2 0
10 1 10 8 32
10 2 2 3 86
10 2 3 8 0
10 2 4 2 0
10 2 5 2 0
10 2 6 2 0
10 2 7 6 0
10 2 8 3 0
10 2 9 9 0
10 2 10 3 0
10 2 11 6 16
10 2 12 0 48
10 3 1 8 94
10 3 2 8 0
10 3 3 6 0
10 3 4 8 0
10 3 5 6 0
10 3 6 6 0
10 3 7 1 0
10 3 8 2 0
10 3 9 4 0
10 3 10 4 0
10 3 11 1 0
10 3 12 0 0
10 3 13 0 16
10 3 14 3 50
10 4 2 6 64
10 4 3 3 0
10 4 4 1 0
10 4 5 8 0
10 4 6 3 0
10 4 7 2 0
10 4 8 4 0
10 4 9 9 0
10 4 10 1 0
10 4 11 1 0
10 4 12 0 0
10 4 13 6 0
10 4 14 1 32
10 5 2 3 66
10 5 3 6 0
10 5 4 8 0
10 5 5 8 0
10 5 6 4 0
10 5 7 4 0
10 5 8 3 0
10 5 9 5 0
10 5 10 8 0
10 5 11 4 0
10 5 12 6 0
10 5 13 8 0
10 5 14 1 0
10 5 15 8 50
10 6 2 4 64
10 6 3 8 0
10 6 4 6 0
10 6 5 3 0
10 6 6 9 0
10 6 7 2 0
10 6 8 8 0
10 6 9 7 0
10 6 10 5 0
10 6 11 8 0
10 6 12 2 0
10 6 13 1 0
10 6 14 9 0
10 6 15 6 40
10 7 2 1 64
10 7 3 3 0
10 7 4 0 0
10 7 5 1 0
10 7 6 8 0
10 7 7 1 0
10 7 8 5 0
10 7 9 4 0
10 7 10 8 0
10 7 11 7 0
10 7 12 1 0
10 7 13 5 0
10 7 14 2 40
10 8 2 2 64
10 8 3 4 0
10 8 4 1 0
10 8 5 1 0
10 8 6 6 0
10 8 7 9 0
10 8 8 3 0
10 8 9 1 0
10 8 10 3 0
10 8 11 3 0
10 8 12 2 0
10 8 13 0 32
10 9 2 1 64
10 9 3 4 0
10 9 4 2 0
10 9 5 7 0
10 9 6 2 0
10 9 7 8 0
10 9 8 2 0
10 9 9 2 0
10 9 10 8 0
10 9 11 1 0
10 9 12 6 0
10 9 13 6 0
10 9 14 3 48
10 10 2 0 74
10 10 3 1 0
10 10 4 1 0
10 10 5 2 0
10 10 6 3 0
10 10 7 2 0
10 10 8 8 0
10 10 9 3 0
10 10 10 3 0
10 10 11 6 0
10 10 12 8 0
10 10 13 3 0
10 10 14 8 46
10 11 3 5 64
10 11 4 3 0
10 11 5 1 0
10 11 6 0 0
10 11 7 6 0
10 11 8 1 0
10 11 9 4 0
10 11 10 9 0
10 11 11 5 0
10 11 12 0 0
10 11 13 6 40
10 12 2 3 82
10 12 3 3 8
10 12 4 2 0
10 12 5 6 0
10 12 6 8 0
10 12 7 3 0
10 12 8 6 0
10 12 9 8 0
10 12 10 9 0
10 12 11 6 4
10 12 12 1 46
10 13 2 3 106
10 13 4 2 74
10 13 5 1 10
10 13 6 5 0
10 13 7 1 10
10 13 8 6 8
10 13 9 6 0
10 13 10 5 0
10 13 11 1 46
10 14 6 1 106
10 14 9 4 66
10 14 10 3 42
10 15 9 8 110
11 0 6 4 82
11 0 7 0 18
11 0 8 2 18
11 0 9 4 50
11 1 4 1 82
11 1 5 3 16
11 1 6 2 0
11 1 7 3 0
11 1 8 4 0
11 1 9 3 0
11 1 10 1 16
11 1 11 1 54
11 2 3 3 80
11 2 4 2 0
11 2 5 1 0
11 2 6 6 0
11 2 7 4 0
11 2 8 0 0
11 2 9 4 0
11 2 10 9 0
11 2 11 6 0
11 2 12 2 48
11 3 2 1 80
11 3 3 1 0
11 3 4 8 0
11 3 5 5 0
11 3 6 0 0
11 3 7 9 0
11 3 8 4 0
11 3 9 6 0
11 3 10 2 0
11 3 11 7 0
11 3 12 4 0
11 3 13 4 48
11 4 2 1 74
11 4 3 2 0
11 4 4 3 0
11 4 5 3 0
11 4 6 1 0
11 4 7 3 0
11 4 8 7 0
11 4 9 2 0
11 4 10 3 0
11 4 11 4 0
11 4 12 1 0
11 4 13 3 0
11 4 14 3 50
11 5 3 7 64
11 5 4 5 0
11 5 5 6 0
11 5 6 4 0
11 5 7 6 0
11 5 8 2 0
11 5 9 5 0
11 5 10 3 0
11 5 11 3 0
11 5 12 6 0
11 5 13 8 0
11 5 14 0 32
11 6 2 4 82
11 6 3 4 0
11 6 4 2 0
11 6 5 3 0
11 6 6 6 0
11 6 7 6 0
11 6 8 0 0
11 6 9 1 0
11 6 10 1 0
11 6 11 3 0
11 6 12 1 0
11 6 13 1 0
11 6 14 3 0
11 6 15 4 58
11 7 2 9 66
11 7 3 3 0
11 7 4 7 0
11 7 5 9 0
11 7 6 2 0
11 7 7 2 0
11 7 8 9 0
11 7 9 5 0
11 7 10 1 0
11 7 11 2 0
11 7 12 3 0
11 7 13 2 0
11 7 14 1 34
11 8 2 6 66
11 8 3 1 0
11 8 4 3 0
11 8 5 2 0
11 8 6 2 0
11 8 7 2 0
11 8 8 9 0
11 8 9 6 0
11 8 10 5 0
11 8 11 8 0
11 8 12 2 0
11 8 13 0 0
11 8 14 0 38
11 9 2 6 74
11 9 3 6 0
11 9 4 4 0
11 9 5 8 0
11 9 6 3 0
11 9 7 9 0
11 9 8 0 0
11 9 9 4 0
11 9 10 4 0
11 9 11 3 0
11 9 12 3 0
11 9 13 7 0
11 9 14 1 42
11 10 3 7 64
11 10 4 8 0
11 10 5 3 0
11 10 6 3 0
11 10 7 1 0
11 10 8 7 0
11 10 9 3 0
11 10 10 8 0
11 10 11 2 0
11 10 12 9 0
11 10 13 5 32
11 11 3 8 64
11 11 4 7 0
11 11 5 3 0
11 11 6 8 0
11 11 7 5 0
11 11 8 1 0
11 11 9 9 0
11 11 10 2 0
11 11 11 2 0
11 11 12 1 8
11 11 13 4 42
11 12 3 6 72
11 12 4 2 8
11 12 5 4 8
11 12 6 4 0
11 12 7 1 10
11 12 8 2 0
11 12 9 3 0
11 12 10 3 0
11 12 11 2 40
11 13 6 2 106
11 13 8 1 74
11 13 9 7 10
11 13 10 3 40
12 1 5 3 82
12 1 6 1 18
12 1 7 2 18
12 1 8 2 18
12 1 9 3 18
12 1 10 6 50
12 2 3 3 82
12 2 4 1 18
12 2 5 2 0
12 2 6 3 0
12 2 7 6 0
12 2 8 2 0
12 2 9 2 0
12 2 10 4 0
12 2 11 2 18
12 2 12 3 50
12 3 2 1 90
12 3 3 2 0
12 3 4 3 0
12 3 5 7 0
12 3 6 5 0
12 3 7 3 0
12 3 8 2 0
12 3 9 8 0
12 3 10 8 0
12 3 11 3 0
12 3 12 8 0
12 3 13 2 50
12 4 3 5 64
12 4 4 8 0
12 4 5 3 0
12 4 6 8 0
12 4 7 7 0
12 4 8 6 0
12 4 9 2 0
12 4 10 5 0
12 4 11 5 0
12 4 12 8 0
12 4 13 4 34
12 5 3 6 66
12 5 4 5 0
12 5 5 3 0
12 5 6 9 0
12 5 7 9 0
12 5 8 5 0
12 5 9 3 0
12 5 10 2 0
12 5 11 7 0
12 5 12 1 0
12 5 13 1 0
12 5 14 2 50
12 6 3 2 66
12 6 4 6 0
12 6 5 1 0
12 6 6 5 0
12 6 7 5 0
12 6 8 1 0
12 6 9 7 0
12 6 10 2 0
12 6 11 3 0
12 6 12 4 0
12 6 13 8 0
12 6 14 3 42
12 7 3 8 66
12 7 4 2 0
12 7 5 5 0
12 7 6 8 0
12 7 7 3 0
12 7 8 3 0
12 7 9 6 0
12 7 10 7 0
12 7 11 2 0
12 7 12 4 0
12 7 13 3 32
12 8 3 5 64
12 8 4 9 0
12 8 5 5 0
12 8 6 8 0
12 8 7 1 0
12 8 8 4 0
12 8 9 4 0
12 8 10 4 0
12 8 11 6 0
12 8 12 8 0
12 8 13 1 34
12 9 3 1 64
12 9 4 1 0
12 9 5 3 0
12 9 6 3 0
12 9 7 2 0
12 9 8 5 0
12 9 9 1 0
12 9 10 3 0
12 9 11 1 0
12 9 12 6 2
12 9 13 0 34
12 10 3 2 64
12 10 4 3 0
12 10 5 1 0
12 10 6 8 0
12 10 7 1 0
12 10 8 3 0
12 10 9 1 0
12 10 10 6 0
12 10 11 1 0
12 10 12 0 0
12 10 13 2 42
12 11 3 6 64
12 11 4 1 0
12 11 5 3 0
12 11 6 2 0
12 11 7 1 8
12 11 8 1 0
12 11 9 4 0
12 11 10 9 0
12 11 11 8 0
12 11 12 5 34
12 12 2 3 94
12 12 3 2 0
12 12 4 0 8
12 12 5 8 8
12 12 6 2 40
12 12 8 0 72
12 12 9 0 8
12 12 10 1 0
12 12 11 2 0
12 12 12 3 38
12 13 3 9 110
12 13 10 6 64
12 13 11 2 14
12 13 12 1 46
12 14 10 2 110
13 2 5 7 82
13 2 6 4 18
13 2 7 3 18
13 2 8 8 18
13 2 9 3 18
13 2 10 0 50
13 3 3 9 82
13 3 4 8 18
13 3 5 9 0
13 3 6 4 0
13 3 7 8 0
13 3 8 1 0
13 3 9 2 0
13 3 10 1 0
13 3 11 1 18
13 3 12 0 50
13 4 3 4 74
13 4 4 9 0
13 4 5 3 0
13 4 6 4 0
13 4 7 0 0
13 4 8 6 0
13 4 9 4 0
13 4 10 0 2
13 4 11 5 2
13 4 12 6 34
13 5 4 3 64
13 5 5 3 0
13 5 6 8 0
13 5 7 0 0
13 5 8 2 0
13 5 9 9 0
13 5 10 0 0
13 5 11 4 2
13 5 12 5 2
13 5 13 3 50
13 6 4 2 64
13 6 5 1 0
13 6 6 3 0
13 6 7 3 0
13 6 8 4 0
13 6 9 8 0
13 6 10 9 0
13 6 11 3 0
13 6 12 8 2
13 6 13 2 34
13 7 4 0 64
13 7 5 1 0
13 7 6 3 0
13 7 7 4 0
13 7 8 9 0
13 7 9 6 0
13 7 10 9 0
13 7 11 2 0
13 7 12 8 2
13 7 13 9 42
13 8 3 6 80
13 8 4 5 0
13 8 5 1 0
13 8 6 8 0
13 8 7 4 0
13 8 8 1 0
13 8 9 8 0
13 8 10 5 0
13 8 11 3 0
13 8 12 9 42
13 9 3 2 64
13 9 4 1 0
13 9 5 8 0
13 9 6 3 0
13 9 7 4 0
13 9 8 8 0
13 9 9 6 0
13 9 10 3 0
13 9 11 3 32
13 10 3 6 64
13 10 4 3 0
13 10 5 8 0
13 10 6 8 0
13 10 7 5 0
13 10 8 0 0
13 10 9 9 0
13 10 10 7 0
13 10 11 6 2
13 10 12 2 58
13 11 3 4 66
13 11 4 1 0
13 11 5 8 0
13 11 6 3 0
13 11 7 6 0
13 11 8 3 0
13 11 9 3 0
13 11 10 1 2
13 11 11 0 34
13 12 3 1 74
13 12 4 9 10
13 12 5 3 8
13 12 6 6 8
13 12 7 2 12
13 12 8 1 8
13 12 9 3 10
13 12 10 4 2
13 12 11 1 42
13 13 10 6 106
14 3 5 1 82
14 3 6 3 18
14 3 7 3 18
14 3 8 3 18
14 3 9 1 18
14 3 10 4 58
14 4 4 5 82
14 4 5 8 2
14 4 6 2 0
14 4 7 3 0
14 4 8 3 0
14 4 9 0 32
14 5 3 3 86
14 5 4 3 2
14 5 5 1 0
14 5 6 1 0
14 5 7 3 2
14 5 8 7 2
14 5 9 3 2
14 5 10 2 50
14 6 3 7 70
14 6 4 2 0
14 6 5 6 0
14 6 6 3 2
14 6 7 8 2
14 6 8 1 2
14 6 9 1 2
14 6 10 0 2
14 6 11 1 50
14 7 3 8 70
14 7 4 2 0
14 7 5 4 0
14 7 6 8 2
14 7 7 1 0
14 7 8 4 2
14 7 9 3 2
14 7 10 9 0
14 7 11 2 34
14 8 3 4 66
14 8 4 2 0
14 8 5 4 0
14 8 6 7 2
14 8 7 3 0
14 8 8 8 2
14 8 9 0 2
14 8 10 3 2
14 8 11 6 34
14 9 3 0 66
14 9 4 6 0
14 9 5 6 0
14 9 6 3 2
14 9 7 7 2
14 9 8 2 2
14 9 9 8 2
14 9 10 2 0
14 9 11 3 42
14 10 3 8 74
14 10 4 6 2
14 10 5 1 0
14 10 6 1 0
14 10 7 6 2
14 10 8 7 2
14 10 9 8 2
14 10 10 8 42
14 11 4 4 74
14 11 5 0 2
14 11 6 2 0
14 11 7 2 0
14 11 8 3 2
14 11 9 8 42
14 12 5 1 74
14 12 6 0 10
14 12 7 4 10
14 12 8 8 42
15 4 6 2 82
15 4 7 0 26
15 4 8 7 26
15 4 9 2 58
15 5 5 1 82
15 5 6 4 42
15 6 4 1 82
15 6 5 4 34
15 7 4 9 66
15 7 5 3 34
15 7 7 9 114
15 7 10 6 122
15 8 4 8 66
15 8 5 3 34
15 8 7 7 106
15 9 4 4 74
15 9 5 6 34
15 9 10 8 122
15 10 5 3 74
15 10 6 5 50
15 11 6 8 74
15 11 7 3 58
