Qubicle Exchange Format
Version 0.2
www.minddesk.com
8 8 8
4
0.000000 0.439216 0.925490
0.333333 0.333333 0.333333
0.466667 0.466667 0.466667
1.000000 1.000000 1.000000
1 2 1 1 116
1 2 6 1 116
1 3 1 2 68
1 3 2 2 20
1 3 3 2 20
1 3 4 2 20
1 3 5 2 20
1 3 6 2 36
1 4 1 2 68
1 4 2 0 4
1 4 3 0 4
1 4 4 0 4
1 4 5 0 4
1 4 6 2 36
1 5 1 2 68
1 5 2 0 4
1 5 3 0 4
1 5 4 0 4
1 5 5 0 4
1 5 6 2 36
1 6 1 2 76
1 6 2 2 12
1 6 3 2 12
1 6 4 2 12
1 6 5 2 12
1 6 6 2 44
2 2 1 3 80
2 2 2 3 20
2 2 3 3 20
2 2 4 3 20
2 2 5 3 20
2 2 6 3 48
2 3 1 2 64
2 3 2 1 0
2 3 3 1 0
2 3 4 1 0
2 3 5 1 0
2 3 6 2 32
2 4 1 1 64
2 4 2 1 0
2 4 3 1 0
2 4 4 1 0
2 4 5 1 0
2 4 6 1 32
2 5 1 1 64
2 5 2 1 0
2 5 3 1 0
2 5 4 1 0
2 5 5 1 0
2 5 6 1 32
2 6 1 2 72
2 6 2 1 8
2 6 3 1 8
2 6 4 1 8
2 6 5 1 8
2 6 6 2 40
3 0 2 1 116
3 0 5 1 116
3 1 2 1 100
3 1 5 1 100
3 2 1 3 80
3 2 2 3 0
3 2 3 3 16
3 2 4 3 16
3 2 5 3 0
3 2 6 3 48
3 3 1 2 64
3 3 2 1 0
3 3 3 1 0
3 3 4 1 0
3 3 5 1 0
3 3 6 2 32
3 4 1 1 64
3 4 2 1 0
3 4 3 1 0
3 4 4 1 0
3 4 5 1 0
3 4 6 1 32
3 5 1 1 64
3 5 2 1 0
3 5 3 1 0
3 5 4 1 0
3 5 5 1 0
3 5 6 1 32
3 6 1 2 72
3 6 2 1 8
3 6 3 1 8
3 6 4 1 8
3 6 5 1 8
3 6 6 2 40
4 0 2 1 114
4 0 5 1 114
4 1 2 1 98
4 1 5 1 98
4 2 1 3 82
4 2 2 3 0
4 2 3 3 16
4 2 4 3 16
4 2 5 3 0
4 2 6 3 50
4 3 1 2 64
4 3 2 1 0
4 3 3 1 0
4 3 4 1 0
4 3 5 1 0
4 3 6 2 32
4 4 1 1 64
4 4 2 1 0
4 4 3 1 0
4 4 4 1 0
4 4 5 1 0
4 4 6 1 32
4 5 1 1 64
4 5 2 1 0
4 5 3 1 0
4 5 4 1 0
4 5 5 1 0
4 5 6 1 32
4 6 1 2 72
4 6 2 1 8
4 6 3 1 8
4 6 4 1 8
4 6 5 1 8
4 6 6 2 40
5 2 2 3 82
5 2 3 3 18
5 2 4 3 18
5 2 5 3 50
5 3 1 2 80
5 3 2 1 0
5 3 3 1 0
5 3 4 1 0
5 3 5 1 0
5 3 6 2 48
5 4 1 1 64
5 4 2 1 0
5 4 3 1 0
5 4 4 1 0
5 4 5 1 0
5 4 6 1 32
5 5 1 1 64
5 5 2 1 0
5 5 3 1 0
5 5 4 1 0
5 5 5 1 0
5 5 6 1 32
5 6 1 2 72
5 6 2 1 8
5 6 3 1 8
5 6 4 1 8
5 6 5 1 8
5 6 6 2 40
6 3 1 2 82
6 3 2 2 18
6 3 3 2 18
6 3 4 2 18
6 3 5 2 18
6 3 6 2 50
6 4 1 2 66
6 4 2 1 2
6 4 3 1 2
6 4 4 1 2
6 4 5 1 2
6 4 6 2 34
6 5 1 2 66
6 5 2 1 2
6 5 3 1 2
6 5 4 1 2
6 5 5 1 2
6 5 6 2 34
6 6 1 2 74
6 6 2 2 10
6 6 3 2 10
6 6 4 2 10
6 6 5 2 10
6 6 6 2 42
