Qubicle Exchange Format
Version 0.2
www.minddesk.com
8 8 8
4
0.000000 0.439216 0.925490
0.333333 0.333333 0.333333
0.466667 0.466667 0.466667
1.000000 1.000000 1.000000
0 2 1 1 124
1 2 1 3 120
1 2 6 1 124
1 4 1 2 84
1 4 2 2 20
1 4 3 2 20
1 4 4 2 20
1 4 5 2 20
1 4 6 2 52
1 5 1 2 68
1 5 2 0 4
1 5 3 0 4
1 5 4 0 4
1 5 5 0 4
1 5 6 2 36
1 6 1 2 68
1 6 2 0 4
1 6 3 0 4
1 6 4 0 4
1 6 5 0 4
1 6 6 2 36
1 7 1 2 76
1 7 2 2 12
1 7 3 2 12
1 7 4 2 12
1 7 5 2 12
1 7 6 2 44
2 0 2 1 116
2 1 2 1 100
2 2 1 3 88
2 2 2 3 4
2 2 3 3 20
2 2 4 3 20
2 2 5 3 20
2 2 6 3 56
2 3 2 3 68
2 3 3 3 4
2 3 4 3 4
2 3 5 3 36
2 4 1 2 80
2 4 2 1 0
2 4 3 1 0
2 4 4 1 0
2 4 5 1 0
2 4 6 2 48
2 5 1 1 64
2 5 2 1 0
2 5 3 1 0
2 5 4 1 0
2 5 5 1 0
2 5 6 1 32
2 6 1 1 64
2 6 2 1 0
2 6 3 1 0
2 6 4 1 0
2 6 5 1 0
2 6 6 1 32
2 7 1 2 72
2 7 2 1 8
2 7 3 1 8
2 7 4 1 8
2 7 5 1 8
2 7 6 2 40
3 0 2 1 114
3 0 5 1 116
3 1 2 1 98
3 1 5 1 100
3 2 1 3 90
3 2 2 3 0
3 2 3 3 16
3 2 4 3 16
3 2 5 3 0
3 2 6 3 56
3 3 2 3 64
3 3 3 3 0
3 3 4 3 0
3 3 5 3 32
3 4 1 2 80
3 4 2 1 0
3 4 3 1 0
3 4 4 1 0
3 4 5 1 0
3 4 6 2 48
3 5 1 1 64
3 5 2 1 0
3 5 3 1 0
3 5 4 1 0
3 5 5 1 0
3 5 6 1 32
3 6 1 1 64
3 6 2 1 0
3 6 3 1 0
3 6 4 1 0
3 6 5 1 0
3 6 6 1 32
3 7 1 2 72
3 7 2 1 8
3 7 3 1 8
3 7 4 1 8
3 7 5 1 8
3 7 6 2 40
4 0 5 1 114
4 1 5 1 98
4 2 2 3 80
4 2 3 3 16
4 2 4 3 16
4 2 5 3 0
4 2 6 3 58
4 3 2 3 64
4 3 3 3 0
4 3 4 3 0
4 3 5 3 32
4 4 1 2 80
4 4 2 1 0
4 4 3 1 0
4 4 4 1 0
4 4 5 1 0
4 4 6 2 48
4 5 1 1 64
4 5 2 1 0
4 5 3 1 0
4 5 4 1 0
4 5 5 1 0
4 5 6 1 32
4 6 1 1 64
4 6 2 1 0
4 6 3 1 0
4 6 4 1 0
4 6 5 1 0
4 6 6 1 32
4 7 1 2 72
4 7 2 1 8
4 7 3 1 8
4 7 4 1 8
4 7 5 1 8
4 7 6 2 40
5 2 2 3 82
5 2 3 3 18
5 2 4 3 18
5 2 5 3 50
5 3 2 3 66
5 3 3 3 2
5 3 4 3 2
5 3 5 3 34
5 4 1 2 80
5 4 2 1 0
5 4 3 1 0
5 4 4 1 0
5 4 5 1 0
5 4 6 2 48
5 5 1 1 64
5 5 2 1 0
5 5 3 1 0
5 5 4 1 0
5 5 5 1 0
5 5 6 1 32
5 6 1 1 64
5 6 2 1 0
5 6 3 1 0
5 6 4 1 0
5 6 5 1 0
5 6 6 1 32
5 7 1 2 72
5 7 2 1 8
5 7 3 1 8
5 7 4 1 8
5 7 5 1 8
5 7 6 2 40
6 4 1 2 82
6 4 2 2 18
6 4 3 2 18
6 4 4 2 18
6 4 5 2 18
6 4 6 2 50
6 5 1 2 66
6 5 2 1 2
6 5 3 1 2
6 5 4 1 2
6 5 5 1 2
6 5 6 2 34
6 6 1 2 66
6 6 2 1 2
6 6 3 1 2
6 6 4 1 2
6 6 5 1 2
6 6 6 2 34
6 7 1 2 74
6 7 2 2 10
6 7 3 2 10
6 7 4 2 10
6 7 5 2 10
6 7 6 2 42
