Qubicle Exchange Format
Version 0.2
www.minddesk.com
256 4 256
1
0.000000 0.658824 0.000000
0 0 0 0 84
0 0 1 0 20
0 0 2 0 20
0 0 3 0 20
0 0 4 0 20
0 0 5 0 20
0 0 6 0 20
0 0 7 0 20
0 0 8 0 20
0 0 9 0 20
0 0 10 0 20
0 0 11 0 20
0 0 12 0 20
0 0 13 0 20
0 0 14 0 20
0 0 15 0 20
0 0 16 0 20
0 0 17 0 20
0 0 18 0 20
0 0 19 0 20
0 0 20 0 20
0 0 21 0 20
0 0 22 0 20
0 0 23 0 20
0 0 24 0 20
0 0 25 0 20
0 0 26 0 20
0 0 27 0 20
0 0 28 0 20
0 0 29 0 20
0 0 30 0 20
0 0 31 0 20
0 0 32 0 20
0 0 33 0 20
0 0 34 0 20
0 0 35 0 20
0 0 36 0 20
0 0 37 0 20
0 0 38 0 20
0 0 39 0 20
0 0 40 0 20
0 0 41 0 20
0 0 42 0 20
0 0 43 0 20
0 0 44 0 20
0 0 45 0 20
0 0 46 0 20
0 0 47 0 20
0 0 48 0 20
0 0 49 0 20
0 0 50 0 20
0 0 51 0 20
0 0 52 0 20
0 0 53 0 20
0 0 54 0 20
0 0 55 0 20
0 0 56 0 20
0 0 57 0 20
0 0 58 0 20
0 0 59 0 20
0 0 60 0 20
0 0 61 0 20
0 0 62 0 20
0 0 63 0 20
0 0 64 0 20
0 0 65 0 20
0 0 66 0 20
0 0 67 0 20
0 0 68 0 20
0 0 69 0 20
0 0 70 0 20
0 0 71 0 20
0 0 72 0 20
0 0 73 0 20
0 0 74 0 20
0 0 75 0 20
0 0 76 0 20
0 0 77 0 20
0 0 78 0 20
0 0 79 0 20
0 0 80 0 20
0 0 81 0 20
0 0 82 0 20
0 0 83 0 20
0 0 84 0 20
0 0 85 0 20
0 0 86 0 20
0 0 87 0 20
0 0 88 0 20
0 0 89 0 20
0 0 90 0 20
0 0 91 0 20
0 0 92 0 20
0 0 93 0 20
0 0 94 0 20
0 0 95 0 20
0 0 96 0 20
0 0 97 0 20
0 0 98 0 20
0 0 99 0 20
0 0 100 0 20
0 0 101 0 20
0 0 102 0 20
0 0 103 0 20
0 0 104 0 20
0 0 105 0 20
0 0 106 0 20
0 0 107 0 20
0 0 108 0 20
0 0 109 0 20
0 0 110 0 20
0 0 111 0 20
0 0 112 0 20
0 0 113 0 20
0 0 114 0 20
0 0 115 0 20
0 0 116 0 20
0 0 117 0 20
0 0 118 0 20
0 0 119 0 20
0 0 120 0 20
0 0 121 0 20
0 0 122 0 20
0 0 123 0 20
0 0 124 0 20
0 0 125 0 20
0 0 126 0 20
0 0 127 0 20
0 0 128 0 20
0 0 129 0 20
0 0 130 0 20
0 0 131 0 20
0 0 132 0 20
0 0 133 0 20
0 0 134 0 20
0 0 135 0 20
0 0 136 0 20
0 0 137 0 20
0 0 138 0 20
0 0 139 0 20
0 0 140 0 20
0 0 141 0 20
0 0 142 0 20
0 0 143 0 20
0 0 144 0 20
0 0 145 0 20
0 0 146 0 20
0 0 147 0 20
0 0 148 0 20
0 0 149 0 20
0 0 150 0 20
0 0 151 0 20
0 0 152 0 20
0 0 153 0 20
0 0 154 0 20
0 0 155 0 20
0 0 156 0 20
0 0 157 0 20
0 0 158 0 20
0 0 159 0 20
0 0 160 0 20
0 0 161 0 20
0 0 162 0 20
0 0 163 0 20
0 0 164 0 20
0 0 165 0 20
0 0 166 0 20
0 0 167 0 20
0 0 168 0 20
0 0 169 0 20
0 0 170 0 20
0 0 171 0 20
0 0 172 0 20
0 0 173 0 20
0 0 174 0 20
0 0 175 0 20
0 0 176 0 20
0 0 177 0 20
0 0 178 0 20
0 0 179 0 20
0 0 180 0 20
0 0 181 0 20
0 0 182 0 20
0 0 183 0 20
0 0 184 0 20
0 0 185 0 20
0 0 186 0 20
0 0 187 0 20
0 0 188 0 20
0 0 189 0 20
0 0 190 0 20
0 0 191 0 20
0 0 192 0 20
0 0 193 0 20
0 0 194 0 20
0 0 195 0 20
0 0 196 0 20
0 0 197 0 20
0 0 198 0 20
0 0 199 0 20
0 0 200 0 20
0 0 201 0 20
0 0 202 0 20
0 0 203 0 20
0 0 204 0 20
0 0 205 0 20
0 0 206 0 20
0 0 207 0 20
0 0 208 0 20
0 0 209 0 20
0 0 210 0 20
0 0 211 0 20
0 0 212 0 20
0 0 213 0 20
0 0 214 0 20
0 0 215 0 20
0 0 216 0 20
0 0 217 0 20
0 0 218 0 20
0 0 219 0 20
0 0 220 0 20
0 0 221 0 20
0 0 222 0 20
0 0 223 0 20
0 0 224 0 20
0 0 225 0 20
0 0 226 0 20
0 0 227 0 20
0 0 228 0 20
0 0 229 0 20
0 0 230 0 20
0 0 231 0 20
0 0 232 0 20
0 0 233 0 20
0 0 234 0 20
0 0 235 0 20
0 0 236 0 20
0 0 237 0 20
0 0 238 0 20
0 0 239 0 20
0 0 240 0 20
0 0 241 0 20
0 0 242 0 20
0 0 243 0 20
0 0 244 0 20
0 0 245 0 20
0 0 246 0 20
0 0 247 0 20
0 0 248 0 20
0 0 249 0 20
0 0 250 0 20
0 0 251 0 20
0 0 252 0 20
0 0 253 0 20
0 0 254 0 20
0 0 255 0 52
0 1 0 0 68
0 1 1 0 4
0 1 2 0 4
0 1 3 0 4
0 1 4 0 4
0 1 5 0 4
0 1 6 0 4
0 1 7 0 4
0 1 8 0 4
0 1 9 0 4
0 1 10 0 4
0 1 11 0 4
0 1 12 0 4
0 1 13 0 4
0 1 14 0 4
0 1 15 0 4
0 1 16 0 4
0 1 17 0 4
0 1 18 0 4
0 1 19 0 4
0 1 20 0 4
0 1 21 0 4
0 1 22 0 4
0 1 23 0 4
0 1 24 0 4
0 1 25 0 4
0 1 26 0 4
0 1 27 0 4
0 1 28 0 4
0 1 29 0 4
0 1 30 0 4
0 1 31 0 4
0 1 32 0 4
0 1 33 0 4
0 1 34 0 4
0 1 35 0 4
0 1 36 0 4
0 1 37 0 4
0 1 38 0 4
0 1 39 0 4
0 1 40 0 4
0 1 41 0 4
0 1 42 0 4
0 1 43 0 4
0 1 44 0 4
0 1 45 0 4
0 1 46 0 4
0 1 47 0 4
0 1 48 0 4
0 1 49 0 4
0 1 50 0 4
0 1 51 0 4
0 1 52 0 4
0 1 53 0 4
0 1 54 0 4
0 1 55 0 4
0 1 56 0 4
0 1 57 0 4
0 1 58 0 4
0 1 59 0 4
0 1 60 0 4
0 1 61 0 4
0 1 62 0 4
0 1 63 0 4
0 1 64 0 4
0 1 65 0 4
0 1 66 0 4
0 1 67 0 4
0 1 68 0 4
0 1 69 0 4
0 1 70 0 4
0 1 71 0 4
0 1 72 0 4
0 1 73 0 4
0 1 74 0 4
0 1 75 0 4
0 1 76 0 4
0 1 77 0 4
0 1 78 0 4
0 1 79 0 4
0 1 80 0 4
0 1 81 0 4
0 1 82 0 4
0 1 83 0 4
0 1 84 0 4
0 1 85 0 4
0 1 86 0 4
0 1 87 0 4
0 1 88 0 4
0 1 89 0 4
0 1 90 0 4
0 1 91 0 4
0 1 92 0 4
0 1 93 0 4
0 1 94 0 4
0 1 95 0 4
0 1 96 0 4
0 1 97 0 4
0 1 98 0 4
0 1 99 0 4
0 1 100 0 4
0 1 101 0 4
0 1 102 0 4
0 1 103 0 4
0 1 104 0 4
0 1 105 0 4
0 1 106 0 4
0 1 107 0 4
0 1 108 0 4
0 1 109 0 4
0 1 110 0 4
0 1 111 0 4
0 1 112 0 4
0 1 113 0 4
0 1 114 0 4
0 1 115 0 4
0 1 116 0 4
0 1 117 0 4
0 1 118 0 4
0 1 119 0 4
0 1 120 0 4
0 1 121 0 4
0 1 122 0 4
0 1 123 0 4
0 1 124 0 4
0 1 125 0 4
0 1 126 0 4
0 1 127 0 4
0 1 128 0 4
0 1 129 0 4
0 1 130 0 4
0 1 131 0 4
0 1 132 0 4
0 1 133 0 4
0 1 134 0 4
0 1 135 0 4
0 1 136 0 4
0 1 137 0 4
0 1 138 0 4
0 1 139 0 4
0 1 140 0 4
0 1 141 0 4
0 1 142 0 4
0 1 143 0 4
0 1 144 0 4
0 1 145 0 4
0 1 146 0 4
0 1 147 0 4
0 1 148 0 4
0 1 149 0 4
0 1 150 0 4
0 1 151 0 4
0 1 152 0 4
0 1 153 0 4
0 1 154 0 4
0 1 155 0 4
0 1 156 0 4
0 1 157 0 4
0 1 158 0 4
0 1 159 0 4
0 1 160 0 4
0 1 161 0 4
0 1 162 0 4
0 1 163 0 4
0 1 164 0 4
0 1 165 0 4
0 1 166 0 4
0 1 167 0 4
0 1 168 0 4
0 1 169 0 4
0 1 170 0 4
0 1 171 0 4
0 1 172 0 4
0 1 173 0 4
0 1 174 0 4
0 1 175 0 4
0 1 176 0 4
0 1 177 0 4
0 1 178 0 4
0 1 179 0 4
0 1 180 0 4
0 1 181 0 4
0 1 182 0 4
0 1 183 0 4
0 1 184 0 4
0 1 185 0 4
0 1 186 0 4
0 1 187 0 4
0 1 188 0 4
0 1 189 0 4
0 1 190 0 4
0 1 191 0 4
0 1 192 0 4
0 1 193 0 4
0 1 194 0 4
0 1 195 0 4
0 1 196 0 4
0 1 197 0 4
0 1 198 0 4
0 1 199 0 4
0 1 200 0 4
0 1 201 0 4
0 1 202 0 4
0 1 203 0 4
0 1 204 0 4
0 1 205 0 4
0 1 206 0 4
0 1 207 0 4
0 1 208 0 4
0 1 209 0 4
0 1 210 0 4
0 1 211 0 4
0 1 212 0 4
0 1 213 0 4
0 1 214 0 4
0 1 215 0 4
0 1 216 0 4
0 1 217 0 4
0 1 218 0 4
0 1 219 0 4
0 1 220 0 4
0 1 221 0 4
0 1 222 0 4
0 1 223 0 4
0 1 224 0 4
0 1 225 0 4
0 1 226 0 4
0 1 227 0 4
0 1 228 0 4
0 1 229 0 4
0 1 230 0 4
0 1 231 0 4
0 1 232 0 4
0 1 233 0 4
0 1 234 0 4
0 1 235 0 4
0 1 236 0 4
0 1 237 0 4
0 1 238 0 4
0 1 239 0 4
0 1 240 0 4
0 1 241 0 4
0 1 242 0 4
0 1 243 0 4
0 1 244 0 4
0 1 245 0 4
0 1 246 0 4
0 1 247 0 4
0 1 248 0 4
0 1 249 0 4
0 1 250 0 4
0 1 251 0 4
0 1 252 0 4
0 1 253 0 4
0 1 254 0 4
0 1 255 0 36
0 2 0 0 68
0 2 1 0 4
0 2 2 0 4
0 2 3 0 4
0 2 4 0 4
0 2 5 0 4
0 2 6 0 4
0 2 7 0 4
0 2 8 0 4
0 2 9 0 4
0 2 10 0 4
0 2 11 0 4
0 2 12 0 4
0 2 13 0 4
0 2 14 0 4
0 2 15 0 4
0 2 16 0 4
0 2 17 0 4
0 2 18 0 4
0 2 19 0 4
0 2 20 0 4
0 2 21 0 4
0 2 22 0 4
0 2 23 0 4
0 2 24 0 4
0 2 25 0 4
0 2 26 0 4
0 2 27 0 4
0 2 28 0 4
0 2 29 0 4
0 2 30 0 4
0 2 31 0 4
0 2 32 0 4
0 2 33 0 4
0 2 34 0 4
0 2 35 0 4
0 2 36 0 4
0 2 37 0 4
0 2 38 0 4
0 2 39 0 4
0 2 40 0 4
0 2 41 0 4
0 2 42 0 4
0 2 43 0 4
0 2 44 0 4
0 2 45 0 4
0 2 46 0 4
0 2 47 0 4
0 2 48 0 4
0 2 49 0 4
0 2 50 0 4
0 2 51 0 4
0 2 52 0 4
0 2 53 0 4
0 2 54 0 4
0 2 55 0 4
0 2 56 0 4
0 2 57 0 4
0 2 58 0 4
0 2 59 0 4
0 2 60 0 4
0 2 61 0 4
0 2 62 0 4
0 2 63 0 4
0 2 64 0 4
0 2 65 0 4
0 2 66 0 4
0 2 67 0 4
0 2 68 0 4
0 2 69 0 4
0 2 70 0 4
0 2 71 0 4
0 2 72 0 4
0 2 73 0 4
0 2 74 0 4
0 2 75 0 4
0 2 76 0 4
0 2 77 0 4
0 2 78 0 4
0 2 79 0 4
0 2 80 0 4
0 2 81 0 4
0 2 82 0 4
0 2 83 0 4
0 2 84 0 4
0 2 85 0 4
0 2 86 0 4
0 2 87 0 4
0 2 88 0 4
0 2 89 0 4
0 2 90 0 4
0 2 91 0 4
0 2 92 0 4
0 2 93 0 4
0 2 94 0 4
0 2 95 0 4
0 2 96 0 4
0 2 97 0 4
0 2 98 0 4
0 2 99 0 4
0 2 100 0 4
0 2 101 0 4
0 2 102 0 4
0 2 103 0 4
0 2 104 0 4
0 2 105 0 4
0 2 106 0 4
0 2 107 0 4
0 2 108 0 4
0 2 109 0 4
0 2 110 0 4
0 2 111 0 4
0 2 112 0 4
0 2 113 0 4
0 2 114 0 4
0 2 115 0 4
0 2 116 0 4
0 2 117 0 4
0 2 118 0 4
0 2 119 0 4
0 2 120 0 4
0 2 121 0 4
0 2 122 0 4
0 2 123 0 4
0 2 124 0 4
0 2 125 0 4
0 2 126 0 4
0 2 127 0 4
0 2 128 0 4
0 2 129 0 4
0 2 130 0 4
0 2 131 0 4
0 2 132 0 4
0 2 133 0 4
0 2 134 0 4
0 2 135 0 4
0 2 136 0 4
0 2 137 0 4
0 2 138 0 4
0 2 139 0 4
0 2 140 0 4
0 2 141 0 4
0 2 142 0 4
0 2 143 0 4
0 2 144 0 4
0 2 145 0 4
0 2 146 0 4
0 2 147 0 4
0 2 148 0 4
0 2 149 0 4
0 2 150 0 4
0 2 151 0 4
0 2 152 0 4
0 2 153 0 4
0 2 154 0 4
0 2 155 0 4
0 2 156 0 4
0 2 157 0 4
0 2 158 0 4
0 2 159 0 4
0 2 160 0 4
0 2 161 0 4
0 2 162 0 4
0 2 163 0 4
0 2 164 0 4
0 2 165 0 4
0 2 166 0 4
0 2 167 0 4
0 2 168 0 4
0 2 169 0 4
0 2 170 0 4
0 2 171 0 4
0 2 172 0 4
0 2 173 0 4
0 2 174 0 4
0 2 175 0 4
0 2 176 0 4
0 2 177 0 4
0 2 178 0 4
0 2 179 0 4
0 2 180 0 4
0 2 181 0 4
0 2 182 0 4
0 2 183 0 4
0 2 184 0 4
0 2 185 0 4
0 2 186 0 4
0 2 187 0 4
0 2 188 0 4
0 2 189 0 4
0 2 190 0 4
0 2 191 0 4
0 2 192 0 4
0 2 193 0 4
0 2 194 0 4
0 2 195 0 4
0 2 196 0 4
0 2 197 0 4
0 2 198 0 4
0 2 199 0 4
0 2 200 0 4
0 2 201 0 4
0 2 202 0 4
0 2 203 0 4
0 2 204 0 4
0 2 205 0 4
0 2 206 0 4
0 2 207 0 4
0 2 208 0 4
0 2 209 0 4
0 2 210 0 4
0 2 211 0 4
0 2 212 0 4
0 2 213 0 4
0 2 214 0 4
0 2 215 0 4
0 2 216 0 4
0 2 217 0 4
0 2 218 0 4
0 2 219 0 4
0 2 220 0 4
0 2 221 0 4
0 2 222 0 4
0 2 223 0 4
0 2 224 0 4
0 2 225 0 4
0 2 226 0 4
0 2 227 0 4
0 2 228 0 4
0 2 229 0 4
0 2 230 0 4
0 2 231 0 4
0 2 232 0 4
0 2 233 0 4
0 2 234 0 4
0 2 235 0 4
0 2 236 0 4
0 2 237 0 4
0 2 238 0 4
0 2 239 0 4
0 2 240 0 4
0 2 241 0 4
0 2 242 0 4
0 2 243 0 4
0 2 244 0 4
0 2 245 0 4
0 2 246 0 4
0 2 247 0 4
0 2 248 0 4
0 2 249 0 4
0 2 250 0 4
0 2 251 0 4
0 2 252 0 4
0 2 253 0 4
0 2 254 0 4
0 2 255 0 36
0 3 0 0 76
0 3 1 0 12
0 3 2 0 12
0 3 3 0 12
0 3 4 0 12
0 3 5 0 12
0 3 6 0 12
0 3 7 0 12
0 3 8 0 12
0 3 9 0 12
0 3 10 0 12
0 3 11 0 12
0 3 12 0 12
0 3 13 0 12
0 3 14 0 12
0 3 15 0 12
0 3 16 0 12
0 3 17 0 12
0 3 18 0 12
0 3 19 0 12
0 3 20 0 12
0 3 21 0 12
0 3 22 0 12
0 3 23 0 12
0 3 24 0 12
0 3 25 0 12
0 3 26 0 12
0 3 27 0 12
0 3 28 0 12
0 3 29 0 12
0 3 30 0 12
0 3 31 0 12
0 3 32 0 12
0 3 33 0 12
0 3 34 0 12
0 3 35 0 12
0 3 36 0 12
0 3 37 0 12
0 3 38 0 12
0 3 39 0 12
0 3 40 0 12
0 3 41 0 12
0 3 42 0 12
0 3 43 0 12
0 3 44 0 12
0 3 45 0 12
0 3 46 0 12
0 3 47 0 12
0 3 48 0 12
0 3 49 0 12
0 3 50 0 12
0 3 51 0 12
0 3 52 0 12
0 3 53 0 12
0 3 54 0 12
0 3 55 0 12
0 3 56 0 12
0 3 57 0 12
0 3 58 0 12
0 3 59 0 12
0 3 60 0 12
0 3 61 0 12
0 3 62 0 12
0 3 63 0 12
0 3 64 0 12
0 3 65 0 12
0 3 66 0 12
0 3 67 0 12
0 3 68 0 12
0 3 69 0 12
0 3 70 0 12
0 3 71 0 12
0 3 72 0 12
0 3 73 0 12
0 3 74 0 12
0 3 75 0 12
0 3 76 0 12
0 3 77 0 12
0 3 78 0 12
0 3 79 0 12
0 3 80 0 12
0 3 81 0 12
0 3 82 0 12
0 3 83 0 12
0 3 84 0 12
0 3 85 0 12
0 3 86 0 12
0 3 87 0 12
0 3 88 0 12
0 3 89 0 12
0 3 90 0 12
0 3 91 0 12
0 3 92 0 12
0 3 93 0 12
0 3 94 0 12
0 3 95 0 12
0 3 96 0 12
0 3 97 0 12
0 3 98 0 12
0 3 99 0 12
0 3 100 0 12
0 3 101 0 12
0 3 102 0 12
0 3 103 0 12
0 3 104 0 12
0 3 105 0 12
0 3 106 0 12
0 3 107 0 12
0 3 108 0 12
0 3 109 0 12
0 3 110 0 12
0 3 111 0 12
0 3 112 0 12
0 3 113 0 12
0 3 114 0 12
0 3 115 0 12
0 3 116 0 12
0 3 117 0 12
0 3 118 0 12
0 3 119 0 12
0 3 120 0 12
0 3 121 0 12
0 3 122 0 12
0 3 123 0 12
0 3 124 0 12
0 3 125 0 12
0 3 126 0 12
0 3 127 0 12
0 3 128 0 12
0 3 129 0 12
0 3 130 0 12
0 3 131 0 12
0 3 132 0 12
0 3 133 0 12
0 3 134 0 12
0 3 135 0 12
0 3 136 0 12
0 3 137 0 12
0 3 138 0 12
0 3 139 0 12
0 3 140 0 12
0 3 141 0 12
0 3 142 0 12
0 3 143 0 12
0 3 144 0 12
0 3 145 0 12
0 3 146 0 12
0 3 147 0 12
0 3 148 0 12
0 3 149 0 12
0 3 150 0 12
0 3 151 0 12
0 3 152 0 12
0 3 153 0 12
0 3 154 0 12
0 3 155 0 12
0 3 156 0 12
0 3 157 0 12
0 3 158 0 12
0 3 159 0 12
0 3 160 0 12
0 3 161 0 12
0 3 162 0 12
0 3 163 0 12
0 3 164 0 12
0 3 165 0 12
0 3 166 0 12
0 3 167 0 12
0 3 168 0 12
0 3 169 0 12
0 3 170 0 12
0 3 171 0 12
0 3 172 0 12
0 3 173 0 12
0 3 174 0 12
0 3 175 0 12
0 3 176 0 12
0 3 177 0 12
0 3 178 0 12
0 3 179 0 12
0 3 180 0 12
0 3 181 0 12
0 3 182 0 12
0 3 183 0 12
0 3 184 0 12
0 3 185 0 12
0 3 186 0 12
0 3 187 0 12
0 3 188 0 12
0 3 189 0 12
0 3 190 0 12
0 3 191 0 12
0 3 192 0 12
0 3 193 0 12
0 3 194 0 12
0 3 195 0 12
0 3 196 0 12
0 3 197 0 12
0 3 198 0 12
0 3 199 0 12
0 3 200 0 12
0 3 201 0 12
0 3 202 0 12
0 3 203 0 12
0 3 204 0 12
0 3 205 0 12
0 3 206 0 12
0 3 207 0 12
0 3 208 0 12
0 3 209 0 12
0 3 210 0 12
0 3 211 0 12
0 3 212 0 12
0 3 213 0 12
0 3 214 0 12
0 3 215 0 12
0 3 216 0 12
0 3 217 0 12
0 3 218 0 12
0 3 219 0 12
0 3 220 0 12
0 3 221 0 12
0 3 222 0 12
0 3 223 0 12
0 3 224 0 12
0 3 225 0 12
0 3 226 0 12
0 3 227 0 12
0 3 228 0 12
0 3 229 0 12
0 3 230 0 12
0 3 231 0 12
0 3 232 0 12
0 3 233 0 12
0 3 234 0 12
0 3 235 0 12
0 3 236 0 12
0 3 237 0 12
0 3 238 0 12
0 3 239 0 12
0 3 240 0 12
0 3 241 0 12
0 3 242 0 12
0 3 243 0 12
0 3 244 0 12
0 3 245 0 12
0 3 246 0 12
0 3 247 0 12
0 3 248 0 12
0 3 249 0 12
0 3 250 0 12
0 3 251 0 12
0 3 252 0 12
0 3 253 0 12
0 3 254 0 12
0 3 255 0 44
1 0 0 0 80
1 0 1 0 16
1 0 2 0 16
1 0 3 0 16
1 0 4 0 16
1 0 5 0 16
1 0 6 0 16
1 0 7 0 16
1 0 8 0 16
1 0 9 0 16
1 0 10 0 16
1 0 11 0 16
1 0 12 0 16
1 0 13 0 16
1 0 14 0 16
1 0 15 0 16
1 0 16 0 16
1 0 17 0 16
1 0 18 0 16
1 0 19 0 16
1 0 20 0 16
1 0 21 0 16
1 0 22 0 16
1 0 23 0 16
1 0 24 0 16
1 0 25 0 16
1 0 26 0 16
1 0 27 0 16
1 0 28 0 16
1 0 29 0 16
1 0 30 0 16
1 0 31 0 16
1 0 32 0 16
1 0 33 0 16
1 0 34 0 16
1 0 35 0 16
1 0 36 0 16
1 0 37 0 16
1 0 38 0 16
1 0 39 0 16
1 0 40 0 16
1 0 41 0 16
1 0 42 0 16
1 0 43 0 16
1 0 44 0 16
1 0 45 0 16
1 0 46 0 16
1 0 47 0 16
1 0 48 0 16
1 0 49 0 16
1 0 50 0 16
1 0 51 0 16
1 0 52 0 16
1 0 53 0 16
1 0 54 0 16
1 0 55 0 16
1 0 56 0 16
1 0 57 0 16
1 0 58 0 16
1 0 59 0 16
1 0 60 0 16
1 0 61 0 16
1 0 62 0 16
1 0 63 0 16
1 0 64 0 16
1 0 65 0 16
1 0 66 0 16
1 0 67 0 16
1 0 68 0 16
1 0 69 0 16
1 0 70 0 16
1 0 71 0 16
1 0 72 0 16
1 0 73 0 16
1 0 74 0 16
1 0 75 0 16
1 0 76 0 16
1 0 77 0 16
1 0 78 0 16
1 0 79 0 16
1 0 80 0 16
1 0 81 0 16
1 0 82 0 16
1 0 83 0 16
1 0 84 0 16
1 0 85 0 16
1 0 86 0 16
1 0 87 0 16
1 0 88 0 16
1 0 89 0 16
1 0 90 0 16
1 0 91 0 16
1 0 92 0 16
1 0 93 0 16
1 0 94 0 16
1 0 95 0 16
1 0 96 0 16
1 0 97 0 16
1 0 98 0 16
1 0 99 0 16
1 0 100 0 16
1 0 101 0 16
1 0 102 0 16
1 0 103 0 16
1 0 104 0 16
1 0 105 0 16
1 0 106 0 16
1 0 107 0 16
1 0 108 0 16
1 0 109 0 16
1 0 110 0 16
1 0 111 0 16
1 0 112 0 16
1 0 113 0 16
1 0 114 0 16
1 0 115 0 16
1 0 116 0 16
1 0 117 0 16
1 0 118 0 16
1 0 119 0 16
1 0 120 0 16
1 0 121 0 16
1 0 122 0 16
1 0 123 0 16
1 0 124 0 16
1 0 125 0 16
1 0 126 0 16
1 0 127 0 16
1 0 128 0 16
1 0 129 0 16
1 0 130 0 16
1 0 131 0 16
1 0 132 0 16
1 0 133 0 16
1 0 134 0 16
1 0 135 0 16
1 0 136 0 16
1 0 137 0 16
1 0 138 0 16
1 0 139 0 16
1 0 140 0 16
1 0 141 0 16
1 0 142 0 16
1 0 143 0 16
1 0 144 0 16
1 0 145 0 16
1 0 146 0 16
1 0 147 0 16
1 0 148 0 16
1 0 149 0 16
1 0 150 0 16
1 0 151 0 16
1 0 152 0 16
1 0 153 0 16
1 0 154 0 16
1 0 155 0 16
1 0 156 0 16
1 0 157 0 16
1 0 158 0 16
1 0 159 0 16
1 0 160 0 16
1 0 161 0 16
1 0 162 0 16
1 0 163 0 16
1 0 164 0 16
1 0 165 0 16
1 0 166 0 16
1 0 167 0 16
1 0 168 0 16
1 0 169 0 16
1 0 170 0 16
1 0 171 0 16
1 0 172 0 16
1 0 173 0 16
1 0 174 0 16
1 0 175 0 16
1 0 176 0 16
1 0 177 0 16
1 0 178 0 16
1 0 179 0 16
1 0 180 0 16
1 0 181 0 16
1 0 182 0 16
1 0 183 0 16
1 0 184 0 16
1 0 185 0 16
1 0 186 0 16
1 0 187 0 16
1 0 188 0 16
1 0 189 0 16
1 0 190 0 16
1 0 191 0 16
1 0 192 0 16
1 0 193 0 16
1 0 194 0 16
1 0 195 0 16
1 0 196 0 16
1 0 197 0 16
1 0 198 0 16
1 0 199 0 16
1 0 200 0 16
1 0 201 0 16
1 0 202 0 16
1 0 203 0 16
1 0 204 0 16
1 0 205 0 16
1 0 206 0 16
1 0 207 0 16
1 0 208 0 16
1 0 209 0 16
1 0 210 0 16
1 0 211 0 16
1 0 212 0 16
1 0 213 0 16
1 0 214 0 16
1 0 215 0 16
1 0 216 0 16
1 0 217 0 16
1 0 218 0 16
1 0 219 0 16
1 0 220 0 16
1 0 221 0 16
1 0 222 0 16
1 0 223 0 16
1 0 224 0 16
1 0 225 0 16
1 0 226 0 16
1 0 227 0 16
1 0 228 0 16
1 0 229 0 16
1 0 230 0 16
1 0 231 0 16
1 0 232 0 16
1 0 233 0 16
1 0 234 0 16
1 0 235 0 16
1 0 236 0 16
1 0 237 0 16
1 0 238 0 16
1 0 239 0 16
1 0 240 0 16
1 0 241 0 16
1 0 242 0 16
1 0 243 0 16
1 0 244 0 16
1 0 245 0 16
1 0 246 0 16
1 0 247 0 16
1 0 248 0 16
1 0 249 0 16
1 0 250 0 16
1 0 251 0 16
1 0 252 0 16
1 0 253 0 16
1 0 254 0 16
1 0 255 0 48
1 1 0 0 64
1 1 1 0 0
1 1 2 0 0
1 1 3 0 0
1 1 4 0 0
1 1 5 0 0
1 1 6 0 0
1 1 7 0 0
1 1 8 0 0
1 1 9 0 0
1 1 10 0 0
1 1 11 0 0
1 1 12 0 0
1 1 13 0 0
1 1 14 0 0
1 1 15 0 0
1 1 16 0 0
1 1 17 0 0
1 1 18 0 0
1 1 19 0 0
1 1 20 0 0
1 1 21 0 0
1 1 22 0 0
1 1 23 0 0
1 1 24 0 0
1 1 25 0 0
1 1 26 0 0
1 1 27 0 0
1 1 28 0 0
1 1 29 0 0
1 1 30 0 0
1 1 31 0 0
1 1 32 0 0
1 1 33 0 0
1 1 34 0 0
1 1 35 0 0
1 1 36 0 0
1 1 37 0 0
1 1 38 0 0
1 1 39 0 0
1 1 40 0 0
1 1 41 0 0
1 1 42 0 0
1 1 43 0 0
1 1 44 0 0
1 1 45 0 0
1 1 46 0 0
1 1 47 0 0
1 1 48 0 0
1 1 49 0 0
1 1 50 0 0
1 1 51 0 0
1 1 52 0 0
1 1 53 0 0
1 1 54 0 0
1 1 55 0 0
1 1 56 0 0
1 1 57 0 0
1 1 58 0 0
1 1 59 0 0
1 1 60 0 0
1 1 61 0 0
1 1 62 0 0
1 1 63 0 0
1 1 64 0 0
1 1 65 0 0
1 1 66 0 0
1 1 67 0 0
1 1 68 0 0
1 1 69 0 0
1 1 70 0 0
1 1 71 0 0
1 1 72 0 0
1 1 73 0 0
1 1 74 0 0
1 1 75 0 0
1 1 76 0 0
1 1 77 0 0
1 1 78 0 0
1 1 79 0 0
1 1 80 0 0
1 1 81 0 0
1 1 82 0 0
1 1 83 0 0
1 1 84 0 0
1 1 85 0 0
1 1 86 0 0
1 1 87 0 0
1 1 88 0 0
1 1 89 0 0
1 1 90 0 0
1 1 91 0 0
1 1 92 0 0
1 1 93 0 0
1 1 94 0 0
1 1 95 0 0
1 1 96 0 0
1 1 97 0 0
1 1 98 0 0
1 1 99 0 0
1 1 100 0 0
1 1 101 0 0
1 1 102 0 0
1 1 103 0 0
1 1 104 0 0
1 1 105 0 0
1 1 106 0 0
1 1 107 0 0
1 1 108 0 0
1 1 109 0 0
1 1 110 0 0
1 1 111 0 0
1 1 112 0 0
1 1 113 0 0
1 1 114 0 0
1 1 115 0 0
1 1 116 0 0
1 1 117 0 0
1 1 118 0 0
1 1 119 0 0
1 1 120 0 0
1 1 121 0 0
1 1 122 0 0
1 1 123 0 0
1 1 124 0 0
1 1 125 0 0
1 1 126 0 0
1 1 127 0 0
1 1 128 0 0
1 1 129 0 0
1 1 130 0 0
1 1 131 0 0
1 1 132 0 0
1 1 133 0 0
1 1 134 0 0
1 1 135 0 0
1 1 136 0 0
1 1 137 0 0
1 1 138 0 0
1 1 139 0 0
1 1 140 0 0
1 1 141 0 0
1 1 142 0 0
1 1 143 0 0
1 1 144 0 0
1 1 145 0 0
1 1 146 0 0
1 1 147 0 0
1 1 148 0 0
1 1 149 0 0
1 1 150 0 0
1 1 151 0 0
1 1 152 0 0
1 1 153 0 0
1 1 154 0 0
1 1 155 0 0
1 1 156 0 0
1 1 157 0 0
1 1 158 0 0
1 1 159 0 0
1 1 160 0 0
1 1 161 0 0
1 1 162 0 0
1 1 163 0 0
1 1 164 0 0
1 1 165 0 0
1 1 166 0 0
1 1 167 0 0
1 1 168 0 0
1 1 169 0 0
1 1 170 0 0
1 1 171 0 0
1 1 172 0 0
1 1 173 0 0
1 1 174 0 0
1 1 175 0 0
1 1 176 0 0
1 1 177 0 0
1 1 178 0 0
1 1 179 0 0
1 1 180 0 0
1 1 181 0 0
1 1 182 0 0
1 1 183 0 0
1 1 184 0 0
1 1 185 0 0
1 1 186 0 0
1 1 187 0 0
1 1 188 0 0
1 1 189 0 0
1 1 190 0 0
1 1 191 0 0
1 1 192 0 0
1 1 193 0 0
1 1 194 0 0
1 1 195 0 0
1 1 196 0 0
1 1 197 0 0
1 1 198 0 0
1 1 199 0 0
1 1 200 0 0
1 1 201 0 0
1 1 202 0 0
1 1 203 0 0
1 1 204 0 0
1 1 205 0 0
1 1 206 0 0
1 1 207 0 0
1 1 208 0 0
1 1 209 0 0
1 1 210 0 0
1 1 211 0 0
1 1 212 0 0
1 1 213 0 0
1 1 214 0 0
1 1 215 0 0
1 1 216 0 0
1 1 217 0 0
1 1 218 0 0
1 1 219 0 0
1 1 220 0 0
1 1 221 0 0
1 1 222 0 0
1 1 223 0 0
1 1 224 0 0
1 1 225 0 0
1 1 226 0 0
1 1 227 0 0
1 1 228 0 0
1 1 229 0 0
1 1 230 0 0
1 1 231 0 0
1 1 232 0 0
1 1 233 0 0
1 1 234 0 0
1 1 235 0 0
1 1 236 0 0
1 1 237 0 0
1 1 238 0 0
1 1 239 0 0
1 1 240 0 0
1 1 241 0 0
1 1 242 0 0
1 1 243 0 0
1 1 244 0 0
1 1 245 0 0
1 1 246 0 0
1 1 247 0 0
1 1 248 0 0
1 1 249 0 0
1 1 250 0 0
1 1 251 0 0
1 1 252 0 0
1 1 253 0 0
1 1 254 0 0
1 1 255 0 32
1 2 0 0 64
1 2 1 0 0
1 2 2 0 0
1 2 3 0 0
1 2 4 0 0
1 2 5 0 0
1 2 6 0 0
1 2 7 0 0
1 2 8 0 0
1 2 9 0 0
1 2 10 0 0
1 2 11 0 0
1 2 12 0 0
1 2 13 0 0
1 2 14 0 0
1 2 15 0 0
1 2 16 0 0
1 2 17 0 0
1 2 18 0 0
1 2 19 0 0
1 2 20 0 0
1 2 21 0 0
1 2 22 0 0
1 2 23 0 0
1 2 24 0 0
1 2 25 0 0
1 2 26 0 0
1 2 27 0 0
1 2 28 0 0
1 2 29 0 0
1 2 30 0 0
1 2 31 0 0
1 2 32 0 0
1 2 33 0 0
1 2 34 0 0
1 2 35 0 0
1 2 36 0 0
1 2 37 0 0
1 2 38 0 0
1 2 39 0 0
1 2 40 0 0
1 2 41 0 0
1 2 42 0 0
1 2 43 0 0
1 2 44 0 0
1 2 45 0 0
1 2 46 0 0
1 2 47 0 0
1 2 48 0 0
1 2 49 0 0
1 2 50 0 0
1 2 51 0 0
1 2 52 0 0
1 2 53 0 0
1 2 54 0 0
1 2 55 0 0
1 2 56 0 0
1 2 57 0 0
1 2 58 0 0
1 2 59 0 0
1 2 60 0 0
1 2 61 0 0
1 2 62 0 0
1 2 63 0 0
1 2 64 0 0
1 2 65 0 0
1 2 66 0 0
1 2 67 0 0
1 2 68 0 0
1 2 69 0 0
1 2 70 0 0
1 2 71 0 0
1 2 72 0 0
1 2 73 0 0
1 2 74 0 0
1 2 75 0 0
1 2 76 0 0
1 2 77 0 0
1 2 78 0 0
1 2 79 0 0
1 2 80 0 0
1 2 81 0 0
1 2 82 0 0
1 2 83 0 0
1 2 84 0 0
1 2 85 0 0
1 2 86 0 0
1 2 87 0 0
1 2 88 0 0
1 2 89 0 0
1 2 90 0 0
1 2 91 0 0
1 2 92 0 0
1 2 93 0 0
1 2 94 0 0
1 2 95 0 0
1 2 96 0 0
1 2 97 0 0
1 2 98 0 0
1 2 99 0 0
1 2 100 0 0
1 2 101 0 0
1 2 102 0 0
1 2 103 0 0
1 2 104 0 0
1 2 105 0 0
1 2 106 0 0
1 2 107 0 0
1 2 108 0 0
1 2 109 0 0
1 2 110 0 0
1 2 111 0 0
1 2 112 0 0
1 2 113 0 0
1 2 114 0 0
1 2 115 0 0
1 2 116 0 0
1 2 117 0 0
1 2 118 0 0
1 2 119 0 0
1 2 120 0 0
1 2 121 0 0
1 2 122 0 0
1 2 123 0 0
1 2 124 0 0
1 2 125 0 0
1 2 126 0 0
1 2 127 0 0
1 2 128 0 0
1 2 129 0 0
1 2 130 0 0
1 2 131 0 0
1 2 132 0 0
1 2 133 0 0
1 2 134 0 0
1 2 135 0 0
1 2 136 0 0
1 2 137 0 0
1 2 138 0 0
1 2 139 0 0
1 2 140 0 0
1 2 141 0 0
1 2 142 0 0
1 2 143 0 0
1 2 144 0 0
1 2 145 0 0
1 2 146 0 0
1 2 147 0 0
1 2 148 0 0
1 2 149 0 0
1 2 150 0 0
1 2 151 0 0
1 2 152 0 0
1 2 153 0 0
1 2 154 0 0
1 2 155 0 0
1 2 156 0 0
1 2 157 0 0
1 2 158 0 0
1 2 159 0 0
1 2 160 0 0
1 2 161 0 0
1 2 162 0 0
1 2 163 0 0
1 2 164 0 0
1 2 165 0 0
1 2 166 0 0
1 2 167 0 0
1 2 168 0 0
1 2 169 0 0
1 2 170 0 0
1 2 171 0 0
1 2 172 0 0
1 2 173 0 0
1 2 174 0 0
1 2 175 0 0
1 2 176 0 0
1 2 177 0 0
1 2 178 0 0
1 2 179 0 0
1 2 180 0 0
1 2 181 0 0
1 2 182 0 0
1 2 183 0 0
1 2 184 0 0
1 2 185 0 0
1 2 186 0 0
1 2 187 0 0
1 2 188 0 0
1 2 189 0 0
1 2 190 0 0
1 2 191 0 0
1 2 192 0 0
1 2 193 0 0
1 2 194 0 0
1 2 195 0 0
1 2 196 0 0
1 2 197 0 0
1 2 198 0 0
1 2 199 0 0
1 2 200 0 0
1 2 201 0 0
1 2 202 0 0
1 2 203 0 0
1 2 204 0 0
1 2 205 0 0
1 2 206 0 0
1 2 207 0 0
1 2 208 0 0
1 2 209 0 0
1 2 210 0 0
1 2 211 0 0
1 2 212 0 0
1 2 213 0 0
1 2 214 0 0
1 2 215 0 0
1 2 216 0 0
1 2 217 0 0
1 2 218 0 0
1 2 219 0 0
1 2 220 0 0
1 2 221 0 0
1 2 222 0 0
1 2 223 0 0
1 2 224 0 0
1 2 225 0 0
1 2 226 0 0
1 2 227 0 0
1 2 228 0 0
1 2 229 0 0
1 2 230 0 0
1 2 231 0 0
1 2 232 0 0
1 2 233 0 0
1 2 234 0 0
1 2 235 0 0
1 2 236 0 0
1 2 237 0 0
1 2 238 0 0
1 2 239 0 0
1 2 240 0 0
1 2 241 0 0
1 2 242 0 0
1 2 243 0 0
1 2 244 0 0
1 2 245 0 0
1 2 246 0 0
1 2 247 0 0
1 2 248 0 0
1 2 249 0 0
1 2 250 0 0
1 2 251 0 0
1 2 252 0 0
1 2 253 0 0
1 2 254 0 0
1 2 255 0 32
1 3 0 0 72
1 3 1 0 8
1 3 2 0 8
1 3 3 0 8
1 3 4 0 8
1 3 5 0 8
1 3 6 0 8
1 3 7 0 8
1 3 8 0 8
1 3 9 0 8
1 3 10 0 8
1 3 11 0 8
1 3 12 0 8
1 3 13 0 8
1 3 14 0 8
1 3 15 0 8
1 3 16 0 8
1 3 17 0 8
1 3 18 0 8
1 3 19 0 8
1 3 20 0 8
1 3 21 0 8
1 3 22 0 8
1 3 23 0 8
1 3 24 0 8
1 3 25 0 8
1 3 26 0 8
1 3 27 0 8
1 3 28 0 8
1 3 29 0 8
1 3 30 0 8
1 3 31 0 8
1 3 32 0 8
1 3 33 0 8
1 3 34 0 8
1 3 35 0 8
1 3 36 0 8
1 3 37 0 8
1 3 38 0 8
1 3 39 0 8
1 3 40 0 8
1 3 41 0 8
1 3 42 0 8
1 3 43 0 8
1 3 44 0 8
1 3 45 0 8
1 3 46 0 8
1 3 47 0 8
1 3 48 0 8
1 3 49 0 8
1 3 50 0 8
1 3 51 0 8
1 3 52 0 8
1 3 53 0 8
1 3 54 0 8
1 3 55 0 8
1 3 56 0 8
1 3 57 0 8
1 3 58 0 8
1 3 59 0 8
1 3 60 0 8
1 3 61 0 8
1 3 62 0 8
1 3 63 0 8
1 3 64 0 8
1 3 65 0 8
1 3 66 0 8
1 3 67 0 8
1 3 68 0 8
1 3 69 0 8
1 3 70 0 8
1 3 71 0 8
1 3 72 0 8
1 3 73 0 8
1 3 74 0 8
1 3 75 0 8
1 3 76 0 8
1 3 77 0 8
1 3 78 0 8
1 3 79 0 8
1 3 80 0 8
1 3 81 0 8
1 3 82 0 8
1 3 83 0 8
1 3 84 0 8
1 3 85 0 8
1 3 86 0 8
1 3 87 0 8
1 3 88 0 8
1 3 89 0 8
1 3 90 0 8
1 3 91 0 8
1 3 92 0 8
1 3 93 0 8
1 3 94 0 8
1 3 95 0 8
1 3 96 0 8
1 3 97 0 8
1 3 98 0 8
1 3 99 0 8
1 3 100 0 8
1 3 101 0 8
1 3 102 0 8
1 3 103 0 8
1 3 104 0 8
1 3 105 0 8
1 3 106 0 8
1 3 107 0 8
1 3 108 0 8
1 3 109 0 8
1 3 110 0 8
1 3 111 0 8
1 3 112 0 8
1 3 113 0 8
1 3 114 0 8
1 3 115 0 8
1 3 116 0 8
1 3 117 0 8
1 3 118 0 8
1 3 119 0 8
1 3 120 0 8
1 3 121 0 8
1 3 122 0 8
1 3 123 0 8
1 3 124 0 8
1 3 125 0 8
1 3 126 0 8
1 3 127 0 8
1 3 128 0 8
1 3 129 0 8
1 3 130 0 8
1 3 131 0 8
1 3 132 0 8
1 3 133 0 8
1 3 134 0 8
1 3 135 0 8
1 3 136 0 8
1 3 137 0 8
1 3 138 0 8
1 3 139 0 8
1 3 140 0 8
1 3 141 0 8
1 3 142 0 8
1 3 143 0 8
1 3 144 0 8
1 3 145 0 8
1 3 146 0 8
1 3 147 0 8
1 3 148 0 8
1 3 149 0 8
1 3 150 0 8
1 3 151 0 8
1 3 152 0 8
1 3 153 0 8
1 3 154 0 8
1 3 155 0 8
1 3 156 0 8
1 3 157 0 8
1 3 158 0 8
1 3 159 0 8
1 3 160 0 8
1 3 161 0 8
1 3 162 0 8
1 3 163 0 8
1 3 164 0 8
1 3 165 0 8
1 3 166 0 8
1 3 167 0 8
1 3 168 0 8
1 3 169 0 8
1 3 170 0 8
1 3 171 0 8
1 3 172 0 8
1 3 173 0 8
1 3 174 0 8
1 3 175 0 8
1 3 176 0 8
1 3 177 0 8
1 3 178 0 8
1 3 179 0 8
1 3 180 0 8
1 3 181 0 8
1 3 182 0 8
1 3 183 0 8
1 3 184 0 8
1 3 185 0 8
1 3 186 0 8
1 3 187 0 8
1 3 188 0 8
1 3 189 0 8
1 3 190 0 8
1 3 191 0 8
1 3 192 0 8
1 3 193 0 8
1 3 194 0 8
1 3 195 0 8
1 3 196 0 8
1 3 197 0 8
1 3 198 0 8
1 3 199 0 8
1 3 200 0 8
1 3 201 0 8
1 3 202 0 8
1 3 203 0 8
1 3 204 0 8
1 3 205 0 8
1 3 206 0 8
1 3 207 0 8
1 3 208 0 8
1 3 209 0 8
1 3 210 0 8
1 3 211 0 8
1 3 212 0 8
1 3 213 0 8
1 3 214 0 8
1 3 215 0 8
1 3 216 0 8
1 3 217 0 8
1 3 218 0 8
1 3 219 0 8
1 3 220 0 8
1 3 221 0 8
1 3 222 0 8
1 3 223 0 8
1 3 224 0 8
1 3 225 0 8
1 3 226 0 8
1 3 227 0 8
1 3 228 0 8
1 3 229 0 8
1 3 230 0 8
1 3 231 0 8
1 3 232 0 8
1 3 233 0 8
1 3 234 0 8
1 3 235 0 8
1 3 236 0 8
1 3 237 0 8
1 3 238 0 8
1 3 239 0 8
1 3 240 0 8
1 3 241 0 8
1 3 242 0 8
1 3 243 0 8
1 3 244 0 8
1 3 245 0 8
1 3 246 0 8
1 3 247 0 8
1 3 248 0 8
1 3 249 0 8
1 3 250 0 8
1 3 251 0 8
1 3 252 0 8
1 3 253 0 8
1 3 254 0 8
1 3 255 0 40
2 0 0 0 80
2 0 1 0 16
2 0 2 0 16
2 0 3 0 16
2 0 4 0 16
2 0 5 0 16
2 0 6 0 16
2 0 7 0 16
2 0 8 0 16
2 0 9 0 16
2 0 10 0 16
2 0 11 0 16
2 0 12 0 16
2 0 13 0 16
2 0 14 0 16
2 0 15 0 16
2 0 16 0 16
2 0 17 0 16
2 0 18 0 16
2 0 19 0 16
2 0 20 0 16
2 0 21 0 16
2 0 22 0 16
2 0 23 0 16
2 0 24 0 16
2 0 25 0 16
2 0 26 0 16
2 0 27 0 16
2 0 28 0 16
2 0 29 0 16
2 0 30 0 16
2 0 31 0 16
2 0 32 0 16
2 0 33 0 16
2 0 34 0 16
2 0 35 0 16
2 0 36 0 16
2 0 37 0 16
2 0 38 0 16
2 0 39 0 16
2 0 40 0 16
2 0 41 0 16
2 0 42 0 16
2 0 43 0 16
2 0 44 0 16
2 0 45 0 16
2 0 46 0 16
2 0 47 0 16
2 0 48 0 16
2 0 49 0 16
2 0 50 0 16
2 0 51 0 16
2 0 52 0 16
2 0 53 0 16
2 0 54 0 16
2 0 55 0 16
2 0 56 0 16
2 0 57 0 16
2 0 58 0 16
2 0 59 0 16
2 0 60 0 16
2 0 61 0 16
2 0 62 0 16
2 0 63 0 16
2 0 64 0 16
2 0 65 0 16
2 0 66 0 16
2 0 67 0 16
2 0 68 0 16
2 0 69 0 16
2 0 70 0 16
2 0 71 0 16
2 0 72 0 16
2 0 73 0 16
2 0 74 0 16
2 0 75 0 16
2 0 76 0 16
2 0 77 0 16
2 0 78 0 16
2 0 79 0 16
2 0 80 0 16
2 0 81 0 16
2 0 82 0 16
2 0 83 0 16
2 0 84 0 16
2 0 85 0 16
2 0 86 0 16
2 0 87 0 16
2 0 88 0 16
2 0 89 0 16
2 0 90 0 16
2 0 91 0 16
2 0 92 0 16
2 0 93 0 16
2 0 94 0 16
2 0 95 0 16
2 0 96 0 16
2 0 97 0 16
2 0 98 0 16
2 0 99 0 16
2 0 100 0 16
2 0 101 0 16
2 0 102 0 16
2 0 103 0 16
2 0 104 0 16
2 0 105 0 16
2 0 106 0 16
2 0 107 0 16
2 0 108 0 16
2 0 109 0 16
2 0 110 0 16
2 0 111 0 16
2 0 112 0 16
2 0 113 0 16
2 0 114 0 16
2 0 115 0 16
2 0 116 0 16
2 0 117 0 16
2 0 118 0 16
2 0 119 0 16
2 0 120 0 16
2 0 121 0 16
2 0 122 0 16
2 0 123 0 16
2 0 124 0 16
2 0 125 0 16
2 0 126 0 16
2 0 127 0 16
2 0 128 0 16
2 0 129 0 16
2 0 130 0 16
2 0 131 0 16
2 0 132 0 16
2 0 133 0 16
2 0 134 0 16
2 0 135 0 16
2 0 136 0 16
2 0 137 0 16
2 0 138 0 16
2 0 139 0 16
2 0 140 0 16
2 0 141 0 16
2 0 142 0 16
2 0 143 0 16
2 0 144 0 16
2 0 145 0 16
2 0 146 0 16
2 0 147 0 16
2 0 148 0 16
2 0 149 0 16
2 0 150 0 16
2 0 151 0 16
2 0 152 0 16
2 0 153 0 16
2 0 154 0 16
2 0 155 0 16
2 0 156 0 16
2 0 157 0 16
2 0 158 0 16
2 0 159 0 16
2 0 160 0 16
2 0 161 0 16
2 0 162 0 16
2 0 163 0 16
2 0 164 0 16
2 0 165 0 16
2 0 166 0 16
2 0 167 0 16
2 0 168 0 16
2 0 169 0 16
2 0 170 0 16
2 0 171 0 16
2 0 172 0 16
2 0 173 0 16
2 0 174 0 16
2 0 175 0 16
2 0 176 0 16
2 0 177 0 16
2 0 178 0 16
2 0 179 0 16
2 0 180 0 16
2 0 181 0 16
2 0 182 0 16
2 0 183 0 16
2 0 184 0 16
2 0 185 0 16
2 0 186 0 16
2 0 187 0 16
2 0 188 0 16
2 0 189 0 16
2 0 190 0 16
2 0 191 0 16
2 0 192 0 16
2 0 193 0 16
2 0 194 0 16
2 0 195 0 16
2 0 196 0 16
2 0 197 0 16
2 0 198 0 16
2 0 199 0 16
2 0 200 0 16
2 0 201 0 16
2 0 202 0 16
2 0 203 0 16
2 0 204 0 16
2 0 205 0 16
2 0 206 0 16
2 0 207 0 16
2 0 208 0 16
2 0 209 0 16
2 0 210 0 16
2 0 211 0 16
2 0 212 0 16
2 0 213 0 16
2 0 214 0 16
2 0 215 0 16
2 0 216 0 16
2 0 217 0 16
2 0 218 0 16
2 0 219 0 16
2 0 220 0 16
2 0 221 0 16
2 0 222 0 16
2 0 223 0 16
2 0 224 0 16
2 0 225 0 16
2 0 226 0 16
2 0 227 0 16
2 0 228 0 16
2 0 229 0 16
2 0 230 0 16
2 0 231 0 16
2 0 232 0 16
2 0 233 0 16
2 0 234 0 16
2 0 235 0 16
2 0 236 0 16
2 0 237 0 16
2 0 238 0 16
2 0 239 0 16
2 0 240 0 16
2 0 241 0 16
2 0 242 0 16
2 0 243 0 16
2 0 244 0 16
2 0 245 0 16
2 0 246 0 16
2 0 247 0 16
2 0 248 0 16
2 0 249 0 16
2 0 250 0 16
2 0 251 0 16
2 0 252 0 16
2 0 253 0 16
2 0 254 0 16
2 0 255 0 48
2 1 0 0 64
2 1 1 0 0
2 1 2 0 0
2 1 3 0 0
2 1 4 0 0
2 1 5 0 0
2 1 6 0 0
2 1 7 0 0
2 1 8 0 0
2 1 9 0 0
2 1 10 0 0
2 1 11 0 0
2 1 12 0 0
2 1 13 0 0
2 1 14 0 0
2 1 15 0 0
2 1 16 0 0
2 1 17 0 0
2 1 18 0 0
2 1 19 0 0
2 1 20 0 0
2 1 21 0 0
2 1 22 0 0
2 1 23 0 0
2 1 24 0 0
2 1 25 0 0
2 1 26 0 0
2 1 27 0 0
2 1 28 0 0
2 1 29 0 0
2 1 30 0 0
2 1 31 0 0
2 1 32 0 0
2 1 33 0 0
2 1 34 0 0
2 1 35 0 0
2 1 36 0 0
2 1 37 0 0
2 1 38 0 0
2 1 39 0 0
2 1 40 0 0
2 1 41 0 0
2 1 42 0 0
2 1 43 0 0
2 1 44 0 0
2 1 45 0 0
2 1 46 0 0
2 1 47 0 0
2 1 48 0 0
2 1 49 0 0
2 1 50 0 0
2 1 51 0 0
2 1 52 0 0
2 1 53 0 0
2 1 54 0 0
2 1 55 0 0
2 1 56 0 0
2 1 57 0 0
2 1 58 0 0
2 1 59 0 0
2 1 60 0 0
2 1 61 0 0
2 1 62 0 0
2 1 63 0 0
2 1 64 0 0
2 1 65 0 0
2 1 66 0 0
2 1 67 0 0
2 1 68 0 0
2 1 69 0 0
2 1 70 0 0
2 1 71 0 0
2 1 72 0 0
2 1 73 0 0
2 1 74 0 0
2 1 75 0 0
2 1 76 0 0
2 1 77 0 0
2 1 78 0 0
2 1 79 0 0
2 1 80 0 0
2 1 81 0 0
2 1 82 0 0
2 1 83 0 0
2 1 84 0 0
2 1 85 0 0
2 1 86 0 0
2 1 87 0 0
2 1 88 0 0
2 1 89 0 0
2 1 90 0 0
2 1 91 0 0
2 1 92 0 0
2 1 93 0 0
2 1 94 0 0
2 1 95 0 0
2 1 96 0 0
2 1 97 0 0
2 1 98 0 0
2 1 99 0 0
2 1 100 0 0
2 1 101 0 0
2 1 102 0 0
2 1 103 0 0
2 1 104 0 0
2 1 105 0 0
2 1 106 0 0
2 1 107 0 0
2 1 108 0 0
2 1 109 0 0
2 1 110 0 0
2 1 111 0 0
2 1 112 0 0
2 1 113 0 0
2 1 114 0 0
2 1 115 0 0
2 1 116 0 0
2 1 117 0 0
2 1 118 0 0
2 1 119 0 0
2 1 120 0 0
2 1 121 0 0
2 1 122 0 0
2 1 123 0 0
2 1 124 0 0
2 1 125 0 0
2 1 126 0 0
2 1 127 0 0
2 1 128 0 0
2 1 129 0 0
2 1 130 0 0
2 1 131 0 0
2 1 132 0 0
2 1 133 0 0
2 1 134 0 0
2 1 135 0 0
2 1 136 0 0
2 1 137 0 0
2 1 138 0 0
2 1 139 0 0
2 1 140 0 0
2 1 141 0 0
2 1 142 0 0
2 1 143 0 0
2 1 144 0 0
2 1 145 0 0
2 1 146 0 0
2 1 147 0 0
2 1 148 0 0
2 1 149 0 0
2 1 150 0 0
2 1 151 0 0
2 1 152 0 0
2 1 153 0 0
2 1 154 0 0
2 1 155 0 0
2 1 156 0 0
2 1 157 0 0
2 1 158 0 0
2 1 159 0 0
2 1 160 0 0
2 1 161 0 0
2 1 162 0 0
2 1 163 0 0
2 1 164 0 0
2 1 165 0 0
2 1 166 0 0
2 1 167 0 0
2 1 168 0 0
2 1 169 0 0
2 1 170 0 0
2 1 171 0 0
2 1 172 0 0
2 1 173 0 0
2 1 174 0 0
2 1 175 0 0
2 1 176 0 0
2 1 177 0 0
2 1 178 0 0
2 1 179 0 0
2 1 180 0 0
2 1 181 0 0
2 1 182 0 0
2 1 183 0 0
2 1 184 0 0
2 1 185 0 0
2 1 186 0 0
2 1 187 0 0
2 1 188 0 0
2 1 189 0 0
2 1 190 0 0
2 1 191 0 0
2 1 192 0 0
2 1 193 0 0
2 1 194 0 0
2 1 195 0 0
2 1 196 0 0
2 1 197 0 0
2 1 198 0 0
2 1 199 0 0
2 1 200 0 0
2 1 201 0 0
2 1 202 0 0
2 1 203 0 0
2 1 204 0 0
2 1 205 0 0
2 1 206 0 0
2 1 207 0 0
2 1 208 0 0
2 1 209 0 0
2 1 210 0 0
2 1 211 0 0
2 1 212 0 0
2 1 213 0 0
2 1 214 0 0
2 1 215 0 0
2 1 216 0 0
2 1 217 0 0
2 1 218 0 0
2 1 219 0 0
2 1 220 0 0
2 1 221 0 0
2 1 222 0 0
2 1 223 0 0
2 1 224 0 0
2 1 225 0 0
2 1 226 0 0
2 1 227 0 0
2 1 228 0 0
2 1 229 0 0
2 1 230 0 0
2 1 231 0 0
2 1 232 0 0
2 1 233 0 0
2 1 234 0 0
2 1 235 0 0
2 1 236 0 0
2 1 237 0 0
2 1 238 0 0
2 1 239 0 0
2 1 240 0 0
2 1 241 0 0
2 1 242 0 0
2 1 243 0 0
2 1 244 0 0
2 1 245 0 0
2 1 246 0 0
2 1 247 0 0
2 1 248 0 0
2 1 249 0 0
2 1 250 0 0
2 1 251 0 0
2 1 252 0 0
2 1 253 0 0
2 1 254 0 0
2 1 255 0 32
2 2 0 0 64
2 2 1 0 0
2 2 2 0 0
2 2 3 0 0
2 2 4 0 0
2 2 5 0 0
2 2 6 0 0
2 2 7 0 0
2 2 8 0 0
2 2 9 0 0
2 2 10 0 0
2 2 11 0 0
2 2 12 0 0
2 2 13 0 0
2 2 14 0 0
2 2 15 0 0
2 2 16 0 0
2 2 17 0 0
2 2 18 0 0
2 2 19 0 0
2 2 20 0 0
2 2 21 0 0
2 2 22 0 0
2 2 23 0 0
2 2 24 0 0
2 2 25 0 0
2 2 26 0 0
2 2 27 0 0
2 2 28 0 0
2 2 29 0 0
2 2 30 0 0
2 2 31 0 0
2 2 32 0 0
2 2 33 0 0
2 2 34 0 0
2 2 35 0 0
2 2 36 0 0
2 2 37 0 0
2 2 38 0 0
2 2 39 0 0
2 2 40 0 0
2 2 41 0 0
2 2 42 0 0
2 2 43 0 0
2 2 44 0 0
2 2 45 0 0
2 2 46 0 0
2 2 47 0 0
2 2 48 0 0
2 2 49 0 0
2 2 50 0 0
2 2 51 0 0
2 2 52 0 0
2 2 53 0 0
2 2 54 0 0
2 2 55 0 0
2 2 56 0 0
2 2 57 0 0
2 2 58 0 0
2 2 59 0 0
2 2 60 0 0
2 2 61 0 0
2 2 62 0 0
2 2 63 0 0
2 2 64 0 0
2 2 65 0 0
2 2 66 0 0
2 2 67 0 0
2 2 68 0 0
2 2 69 0 0
2 2 70 0 0
2 2 71 0 0
2 2 72 0 0
2 2 73 0 0
2 2 74 0 0
2 2 75 0 0
2 2 76 0 0
2 2 77 0 0
2 2 78 0 0
2 2 79 0 0
2 2 80 0 0
2 2 81 0 0
2 2 82 0 0
2 2 83 0 0
2 2 84 0 0
2 2 85 0 0
2 2 86 0 0
2 2 87 0 0
2 2 88 0 0
2 2 89 0 0
2 2 90 0 0
2 2 91 0 0
2 2 92 0 0
2 2 93 0 0
2 2 94 0 0
2 2 95 0 0
2 2 96 0 0
2 2 97 0 0
2 2 98 0 0
2 2 99 0 0
2 2 100 0 0
2 2 101 0 0
2 2 102 0 0
2 2 103 0 0
2 2 104 0 0
2 2 105 0 0
2 2 106 0 0
2 2 107 0 0
2 2 108 0 0
2 2 109 0 0
2 2 110 0 0
2 2 111 0 0
2 2 112 0 0
2 2 113 0 0
2 2 114 0 0
2 2 115 0 0
2 2 116 0 0
2 2 117 0 0
2 2 118 0 0
2 2 119 0 0
2 2 120 0 0
2 2 121 0 0
2 2 122 0 0
2 2 123 0 0
2 2 124 0 0
2 2 125 0 0
2 2 126 0 0
2 2 127 0 0
2 2 128 0 0
2 2 129 0 0
2 2 130 0 0
2 2 131 0 0
2 2 132 0 0
2 2 133 0 0
2 2 134 0 0
2 2 135 0 0
2 2 136 0 0
2 2 137 0 0
2 2 138 0 0
2 2 139 0 0
2 2 140 0 0
2 2 141 0 0
2 2 142 0 0
2 2 143 0 0
2 2 144 0 0
2 2 145 0 0
2 2 146 0 0
2 2 147 0 0
2 2 148 0 0
2 2 149 0 0
2 2 150 0 0
2 2 151 0 0
2 2 152 0 0
2 2 153 0 0
2 2 154 0 0
2 2 155 0 0
2 2 156 0 0
2 2 157 0 0
2 2 158 0 0
2 2 159 0 0
2 2 160 0 0
2 2 161 0 0
2 2 162 0 0
2 2 163 0 0
2 2 164 0 0
2 2 165 0 0
2 2 166 0 0
2 2 167 0 0
2 2 168 0 0
2 2 169 0 0
2 2 170 0 0
2 2 171 0 0
2 2 172 0 0
2 2 173 0 0
2 2 174 0 0
2 2 175 0 0
2 2 176 0 0
2 2 177 0 0
2 2 178 0 0
2 2 179 0 0
2 2 180 0 0
2 2 181 0 0
2 2 182 0 0
2 2 183 0 0
2 2 184 0 0
2 2 185 0 0
2 2 186 0 0
2 2 187 0 0
2 2 188 0 0
2 2 189 0 0
2 2 190 0 0
2 2 191 0 0
2 2 192 0 0
2 2 193 0 0
2 2 194 0 0
2 2 195 0 0
2 2 196 0 0
2 2 197 0 0
2 2 198 0 0
2 2 199 0 0
2 2 200 0 0
2 2 201 0 0
2 2 202 0 0
2 2 203 0 0
2 2 204 0 0
2 2 205 0 0
2 2 206 0 0
2 2 207 0 0
2 2 208 0 0
2 2 209 0 0
2 2 210 0 0
2 2 211 0 0
2 2 212 0 0
2 2 213 0 0
2 2 214 0 0
2 2 215 0 0
2 2 216 0 0
2 2 217 0 0
2 2 218 0 0
2 2 219 0 0
2 2 220 0 0
2 2 221 0 0
2 2 222 0 0
2 2 223 0 0
2 2 224 0 0
2 2 225 0 0
2 2 226 0 0
2 2 227 0 0
2 2 228 0 0
2 2 229 0 0
2 2 230 0 0
2 2 231 0 0
2 2 232 0 0
2 2 233 0 0
2 2 234 0 0
2 2 235 0 0
2 2 236 0 0
2 2 237 0 0
2 2 238 0 0
2 2 239 0 0
2 2 240 0 0
2 2 241 0 0
2 2 242 0 0
2 2 243 0 0
2 2 244 0 0
2 2 245 0 0
2 2 246 0 0
2 2 247 0 0
2 2 248 0 0
2 2 249 0 0
2 2 250 0 0
2 2 251 0 0
2 2 252 0 0
2 2 253 0 0
2 2 254 0 0
2 2 255 0 32
2 3 0 0 72
2 3 1 0 8
2 3 2 0 8
2 3 3 0 8
2 3 4 0 8
2 3 5 0 8
2 3 6 0 8
2 3 7 0 8
2 3 8 0 8
2 3 9 0 8
2 3 10 0 8
2 3 11 0 8
2 3 12 0 8
2 3 13 0 8
2 3 14 0 8
2 3 15 0 8
2 3 16 0 8
2 3 17 0 8
2 3 18 0 8
2 3 19 0 8
2 3 20 0 8
2 3 21 0 8
2 3 22 0 8
2 3 23 0 8
2 3 24 0 8
2 3 25 0 8
2 3 26 0 8
2 3 27 0 8
2 3 28 0 8
2 3 29 0 8
2 3 30 0 8
2 3 31 0 8
2 3 32 0 8
2 3 33 0 8
2 3 34 0 8
2 3 35 0 8
2 3 36 0 8
2 3 37 0 8
2 3 38 0 8
2 3 39 0 8
2 3 40 0 8
2 3 41 0 8
2 3 42 0 8
2 3 43 0 8
2 3 44 0 8
2 3 45 0 8
2 3 46 0 8
2 3 47 0 8
2 3 48 0 8
2 3 49 0 8
2 3 50 0 8
2 3 51 0 8
2 3 52 0 8
2 3 53 0 8
2 3 54 0 8
2 3 55 0 8
2 3 56 0 8
2 3 57 0 8
2 3 58 0 8
2 3 59 0 8
2 3 60 0 8
2 3 61 0 8
2 3 62 0 8
2 3 63 0 8
2 3 64 0 8
2 3 65 0 8
2 3 66 0 8
2 3 67 0 8
2 3 68 0 8
2 3 69 0 8
2 3 70 0 8
2 3 71 0 8
2 3 72 0 8
2 3 73 0 8
2 3 74 0 8
2 3 75 0 8
2 3 76 0 8
2 3 77 0 8
2 3 78 0 8
2 3 79 0 8
2 3 80 0 8
2 3 81 0 8
2 3 82 0 8
2 3 83 0 8
2 3 84 0 8
2 3 85 0 8
2 3 86 0 8
2 3 87 0 8
2 3 88 0 8
2 3 89 0 8
2 3 90 0 8
2 3 91 0 8
2 3 92 0 8
2 3 93 0 8
2 3 94 0 8
2 3 95 0 8
2 3 96 0 8
2 3 97 0 8
2 3 98 0 8
2 3 99 0 8
2 3 100 0 8
2 3 101 0 8
2 3 102 0 8
2 3 103 0 8
2 3 104 0 8
2 3 105 0 8
2 3 106 0 8
2 3 107 0 8
2 3 108 0 8
2 3 109 0 8
2 3 110 0 8
2 3 111 0 8
2 3 112 0 8
2 3 113 0 8
2 3 114 0 8
2 3 115 0 8
2 3 116 0 8
2 3 117 0 8
2 3 118 0 8
2 3 119 0 8
2 3 120 0 8
2 3 121 0 8
2 3 122 0 8
2 3 123 0 8
2 3 124 0 8
2 3 125 0 8
2 3 126 0 8
2 3 127 0 8
2 3 128 0 8
2 3 129 0 8
2 3 130 0 8
2 3 131 0 8
2 3 132 0 8
2 3 133 0 8
2 3 134 0 8
2 3 135 0 8
2 3 136 0 8
2 3 137 0 8
2 3 138 0 8
2 3 139 0 8
2 3 140 0 8
2 3 141 0 8
2 3 142 0 8
2 3 143 0 8
2 3 144 0 8
2 3 145 0 8
2 3 146 0 8
2 3 147 0 8
2 3 148 0 8
2 3 149 0 8
2 3 150 0 8
2 3 151 0 8
2 3 152 0 8
2 3 153 0 8
2 3 154 0 8
2 3 155 0 8
2 3 156 0 8
2 3 157 0 8
2 3 158 0 8
2 3 159 0 8
2 3 160 0 8
2 3 161 0 8
2 3 162 0 8
2 3 163 0 8
2 3 164 0 8
2 3 165 0 8
2 3 166 0 8
2 3 167 0 8
2 3 168 0 8
2 3 169 0 8
2 3 170 0 8
2 3 171 0 8
2 3 172 0 8
2 3 173 0 8
2 3 174 0 8
2 3 175 0 8
2 3 176 0 8
2 3 177 0 8
2 3 178 0 8
2 3 179 0 8
2 3 180 0 8
2 3 181 0 8
2 3 182 0 8
2 3 183 0 8
2 3 184 0 8
2 3 185 0 8
2 3 186 0 8
2 3 187 0 8
2 3 188 0 8
2 3 189 0 8
2 3 190 0 8
2 3 191 0 8
2 3 192 0 8
2 3 193 0 8
2 3 194 0 8
2 3 195 0 8
2 3 196 0 8
2 3 197 0 8
2 3 198 0 8
2 3 199 0 8
2 3 200 0 8
2 3 201 0 8
2 3 202 0 8
2 3 203 0 8
2 3 204 0 8
2 3 205 0 8
2 3 206 0 8
2 3 207 0 8
2 3 208 0 8
2 3 209 0 8
2 3 210 0 8
2 3 211 0 8
2 3 212 0 8
2 3 213 0 8
2 3 214 0 8
2 3 215 0 8
2 3 216 0 8
2 3 217 0 8
2 3 218 0 8
2 3 219 0 8
2 3 220 0 8
2 3 221 0 8
2 3 222 0 8
2 3 223 0 8
2 3 224 0 8
2 3 225 0 8
2 3 226 0 8
2 3 227 0 8
2 3 228 0 8
2 3 229 0 8
2 3 230 0 8
2 3 231 0 8
2 3 232 0 8
2 3 233 0 8
2 3 234 0 8
2 3 235 0 8
2 3 236 0 8
2 3 237 0 8
2 3 238 0 8
2 3 239 0 8
2 3 240 0 8
2 3 241 0 8
2 3 242 0 8
2 3 243 0 8
2 3 244 0 8
2 3 245 0 8
2 3 246 0 8
2 3 247 0 8
2 3 248 0 8
2 3 249 0 8
2 3 250 0 8
2 3 251 0 8
2 3 252 0 8
2 3 253 0 8
2 3 254 0 8
2 3 255 0 40
3 0 0 0 80
3 0 1 0 16
3 0 2 0 16
3 0 3 0 16
3 0 4 0 16
3 0 5 0 16
3 0 6 0 16
3 0 7 0 16
3 0 8 0 16
3 0 9 0 16
3 0 10 0 16
3 0 11 0 16
3 0 12 0 16
3 0 13 0 16
3 0 14 0 16
3 0 15 0 16
3 0 16 0 16
3 0 17 0 16
3 0 18 0 16
3 0 19 0 16
3 0 20 0 16
3 0 21 0 16
3 0 22 0 16
3 0 23 0 16
3 0 24 0 16
3 0 25 0 16
3 0 26 0 16
3 0 27 0 16
3 0 28 0 16
3 0 29 0 16
3 0 30 0 16
3 0 31 0 16
3 0 32 0 16
3 0 33 0 16
3 0 34 0 16
3 0 35 0 16
3 0 36 0 16
3 0 37 0 16
3 0 38 0 16
3 0 39 0 16
3 0 40 0 16
3 0 41 0 16
3 0 42 0 16
3 0 43 0 16
3 0 44 0 16
3 0 45 0 16
3 0 46 0 16
3 0 47 0 16
3 0 48 0 16
3 0 49 0 16
3 0 50 0 16
3 0 51 0 16
3 0 52 0 16
3 0 53 0 16
3 0 54 0 16
3 0 55 0 16
3 0 56 0 16
3 0 57 0 16
3 0 58 0 16
3 0 59 0 16
3 0 60 0 16
3 0 61 0 16
3 0 62 0 16
3 0 63 0 16
3 0 64 0 16
3 0 65 0 16
3 0 66 0 16
3 0 67 0 16
3 0 68 0 16
3 0 69 0 16
3 0 70 0 16
3 0 71 0 16
3 0 72 0 16
3 0 73 0 16
3 0 74 0 16
3 0 75 0 16
3 0 76 0 16
3 0 77 0 16
3 0 78 0 16
3 0 79 0 16
3 0 80 0 16
3 0 81 0 16
3 0 82 0 16
3 0 83 0 16
3 0 84 0 16
3 0 85 0 16
3 0 86 0 16
3 0 87 0 16
3 0 88 0 16
3 0 89 0 16
3 0 90 0 16
3 0 91 0 16
3 0 92 0 16
3 0 93 0 16
3 0 94 0 16
3 0 95 0 16
3 0 96 0 16
3 0 97 0 16
3 0 98 0 16
3 0 99 0 16
3 0 100 0 16
3 0 101 0 16
3 0 102 0 16
3 0 103 0 16
3 0 104 0 16
3 0 105 0 16
3 0 106 0 16
3 0 107 0 16
3 0 108 0 16
3 0 109 0 16
3 0 110 0 16
3 0 111 0 16
3 0 112 0 16
3 0 113 0 16
3 0 114 0 16
3 0 115 0 16
3 0 116 0 16
3 0 117 0 16
3 0 118 0 16
3 0 119 0 16
3 0 120 0 16
3 0 121 0 16
3 0 122 0 16
3 0 123 0 16
3 0 124 0 16
3 0 125 0 16
3 0 126 0 16
3 0 127 0 16
3 0 128 0 16
3 0 129 0 16
3 0 130 0 16
3 0 131 0 16
3 0 132 0 16
3 0 133 0 16
3 0 134 0 16
3 0 135 0 16
3 0 136 0 16
3 0 137 0 16
3 0 138 0 16
3 0 139 0 16
3 0 140 0 16
3 0 141 0 16
3 0 142 0 16
3 0 143 0 16
3 0 144 0 16
3 0 145 0 16
3 0 146 0 16
3 0 147 0 16
3 0 148 0 16
3 0 149 0 16
3 0 150 0 16
3 0 151 0 16
3 0 152 0 16
3 0 153 0 16
3 0 154 0 16
3 0 155 0 16
3 0 156 0 16
3 0 157 0 16
3 0 158 0 16
3 0 159 0 16
3 0 160 0 16
3 0 161 0 16
3 0 162 0 16
3 0 163 0 16
3 0 164 0 16
3 0 165 0 16
3 0 166 0 16
3 0 167 0 16
3 0 168 0 16
3 0 169 0 16
3 0 170 0 16
3 0 171 0 16
3 0 172 0 16
3 0 173 0 16
3 0 174 0 16
3 0 175 0 16
3 0 176 0 16
3 0 177 0 16
3 0 178 0 16
3 0 179 0 16
3 0 180 0 16
3 0 181 0 16
3 0 182 0 16
3 0 183 0 16
3 0 184 0 16
3 0 185 0 16
3 0 186 0 16
3 0 187 0 16
3 0 188 0 16
3 0 189 0 16
3 0 190 0 16
3 0 191 0 16
3 0 192 0 16
3 0 193 0 16
3 0 194 0 16
3 0 195 0 16
3 0 196 0 16
3 0 197 0 16
3 0 198 0 16
3 0 199 0 16
3 0 200 0 16
3 0 201 0 16
3 0 202 0 16
3 0 203 0 16
3 0 204 0 16
3 0 205 0 16
3 0 206 0 16
3 0 207 0 16
3 0 208 0 16
3 0 209 0 16
3 0 210 0 16
3 0 211 0 16
3 0 212 0 16
3 0 213 0 16
3 0 214 0 16
3 0 215 0 16
3 0 216 0 16
3 0 217 0 16
3 0 218 0 16
3 0 219 0 16
3 0 220 0 16
3 0 221 0 16
3 0 222 0 16
3 0 223 0 16
3 0 224 0 16
3 0 225 0 16
3 0 226 0 16
3 0 227 0 16
3 0 228 0 16
3 0 229 0 16
3 0 230 0 16
3 0 231 0 16
3 0 232 0 16
3 0 233 0 16
3 0 234 0 16
3 0 235 0 16
3 0 236 0 16
3 0 237 0 16
3 0 238 0 16
3 0 239 0 16
3 0 240 0 16
3 0 241 0 16
3 0 242 0 16
3 0 243 0 16
3 0 244 0 16
3 0 245 0 16
3 0 246 0 16
3 0 247 0 16
3 0 248 0 16
3 0 249 0 16
3 0 250 0 16
3 0 251 0 16
3 0 252 0 16
3 0 253 0 16
3 0 254 0 16
3 0 255 0 48
3 1 0 0 64
3 1 1 0 0
3 1 2 0 0
3 1 3 0 0
3 1 4 0 0
3 1 5 0 0
3 1 6 0 0
3 1 7 0 0
3 1 8 0 0
3 1 9 0 0
3 1 10 0 0
3 1 11 0 0
3 1 12 0 0
3 1 13 0 0
3 1 14 0 0
3 1 15 0 0
3 1 16 0 0
3 1 17 0 0
3 1 18 0 0
3 1 19 0 0
3 1 20 0 0
3 1 21 0 0
3 1 22 0 0
3 1 23 0 0
3 1 24 0 0
3 1 25 0 0
3 1 26 0 0
3 1 27 0 0
3 1 28 0 0
3 1 29 0 0
3 1 30 0 0
3 1 31 0 0
3 1 32 0 0
3 1 33 0 0
3 1 34 0 0
3 1 35 0 0
3 1 36 0 0
3 1 37 0 0
3 1 38 0 0
3 1 39 0 0
3 1 40 0 0
3 1 41 0 0
3 1 42 0 0
3 1 43 0 0
3 1 44 0 0
3 1 45 0 0
3 1 46 0 0
3 1 47 0 0
3 1 48 0 0
3 1 49 0 0
3 1 50 0 0
3 1 51 0 0
3 1 52 0 0
3 1 53 0 0
3 1 54 0 0
3 1 55 0 0
3 1 56 0 0
3 1 57 0 0
3 1 58 0 0
3 1 59 0 0
3 1 60 0 0
3 1 61 0 0
3 1 62 0 0
3 1 63 0 0
3 1 64 0 0
3 1 65 0 0
3 1 66 0 0
3 1 67 0 0
3 1 68 0 0
3 1 69 0 0
3 1 70 0 0
3 1 71 0 0
3 1 72 0 0
3 1 73 0 0
3 1 74 0 0
3 1 75 0 0
3 1 76 0 0
3 1 77 0 0
3 1 78 0 0
3 1 79 0 0
3 1 80 0 0
3 1 81 0 0
3 1 82 0 0
3 1 83 0 0
3 1 84 0 0
3 1 85 0 0
3 1 86 0 0
3 1 87 0 0
3 1 88 0 0
3 1 89 0 0
3 1 90 0 0
3 1 91 0 0
3 1 92 0 0
3 1 93 0 0
3 1 94 0 0
3 1 95 0 0
3 1 96 0 0
3 1 97 0 0
3 1 98 0 0
3 1 99 0 0
3 1 100 0 0
3 1 101 0 0
3 1 102 0 0
3 1 103 0 0
3 1 104 0 0
3 1 105 0 0
3 1 106 0 0
3 1 107 0 0
3 1 108 0 0
3 1 109 0 0
3 1 110 0 0
3 1 111 0 0
3 1 112 0 0
3 1 113 0 0
3 1 114 0 0
3 1 115 0 0
3 1 116 0 0
3 1 117 0 0
3 1 118 0 0
3 1 119 0 0
3 1 120 0 0
3 1 121 0 0
3 1 122 0 0
3 1 123 0 0
3 1 124 0 0
3 1 125 0 0
3 1 126 0 0
3 1 127 0 0
3 1 128 0 0
3 1 129 0 0
3 1 130 0 0
3 1 131 0 0
3 1 132 0 0
3 1 133 0 0
3 1 134 0 0
3 1 135 0 0
3 1 136 0 0
3 1 137 0 0
3 1 138 0 0
3 1 139 0 0
3 1 140 0 0
3 1 141 0 0
3 1 142 0 0
3 1 143 0 0
3 1 144 0 0
3 1 145 0 0
3 1 146 0 0
3 1 147 0 0
3 1 148 0 0
3 1 149 0 0
3 1 150 0 0
3 1 151 0 0
3 1 152 0 0
3 1 153 0 0
3 1 154 0 0
3 1 155 0 0
3 1 156 0 0
3 1 157 0 0
3 1 158 0 0
3 1 159 0 0
3 1 160 0 0
3 1 161 0 0
3 1 162 0 0
3 1 163 0 0
3 1 164 0 0
3 1 165 0 0
3 1 166 0 0
3 1 167 0 0
3 1 168 0 0
3 1 169 0 0
3 1 170 0 0
3 1 171 0 0
3 1 172 0 0
3 1 173 0 0
3 1 174 0 0
3 1 175 0 0
3 1 176 0 0
3 1 177 0 0
3 1 178 0 0
3 1 179 0 0
3 1 180 0 0
3 1 181 0 0
3 1 182 0 0
3 1 183 0 0
3 1 184 0 0
3 1 185 0 0
3 1 186 0 0
3 1 187 0 0
3 1 188 0 0
3 1 189 0 0
3 1 190 0 0
3 1 191 0 0
3 1 192 0 0
3 1 193 0 0
3 1 194 0 0
3 1 195 0 0
3 1 196 0 0
3 1 197 0 0
3 1 198 0 0
3 1 199 0 0
3 1 200 0 0
3 1 201 0 0
3 1 202 0 0
3 1 203 0 0
3 1 204 0 0
3 1 205 0 0
3 1 206 0 0
3 1 207 0 0
3 1 208 0 0
3 1 209 0 0
3 1 210 0 0
3 1 211 0 0
3 1 212 0 0
3 1 213 0 0
3 1 214 0 0
3 1 215 0 0
3 1 216 0 0
3 1 217 0 0
3 1 218 0 0
3 1 219 0 0
3 1 220 0 0
3 1 221 0 0
3 1 222 0 0
3 1 223 0 0
3 1 224 0 0
3 1 225 0 0
3 1 226 0 0
3 1 227 0 0
3 1 228 0 0
3 1 229 0 0
3 1 230 0 0
3 1 231 0 0
3 1 232 0 0
3 1 233 0 0
3 1 234 0 0
3 1 235 0 0
3 1 236 0 0
3 1 237 0 0
3 1 238 0 0
3 1 239 0 0
3 1 240 0 0
3 1 241 0 0
3 1 242 0 0
3 1 243 0 0
3 1 244 0 0
3 1 245 0 0
3 1 246 0 0
3 1 247 0 0
3 1 248 0 0
3 1 249 0 0
3 1 250 0 0
3 1 251 0 0
3 1 252 0 0
3 1 253 0 0
3 1 254 0 0
3 1 255 0 32
3 2 0 0 64
3 2 1 0 0
3 2 2 0 0
3 2 3 0 0
3 2 4 0 0
3 2 5 0 0
3 2 6 0 0
3 2 7 0 0
3 2 8 0 0
3 2 9 0 0
3 2 10 0 0
3 2 11 0 0
3 2 12 0 0
3 2 13 0 0
3 2 14 0 0
3 2 15 0 0
3 2 16 0 0
3 2 17 0 0
3 2 18 0 0
3 2 19 0 0
3 2 20 0 0
3 2 21 0 0
3 2 22 0 0
3 2 23 0 0
3 2 24 0 0
3 2 25 0 0
3 2 26 0 0
3 2 27 0 0
3 2 28 0 0
3 2 29 0 0
3 2 30 0 0
3 2 31 0 0
3 2 32 0 0
3 2 33 0 0
3 2 34 0 0
3 2 35 0 0
3 2 36 0 0
3 2 37 0 0
3 2 38 0 0
3 2 39 0 0
3 2 40 0 0
3 2 41 0 0
3 2 42 0 0
3 2 43 0 0
3 2 44 0 0
3 2 45 0 0
3 2 46 0 0
3 2 47 0 0
3 2 48 0 0
3 2 49 0 0
3 2 50 0 0
3 2 51 0 0
3 2 52 0 0
3 2 53 0 0
3 2 54 0 0
3 2 55 0 0
3 2 56 0 0
3 2 57 0 0
3 2 58 0 0
3 2 59 0 0
3 2 60 0 0
3 2 61 0 0
3 2 62 0 0
3 2 63 0 0
3 2 64 0 0
3 2 65 0 0
3 2 66 0 0
3 2 67 0 0
3 2 68 0 0
3 2 69 0 0
3 2 70 0 0
3 2 71 0 0
3 2 72 0 0
3 2 73 0 0
3 2 74 0 0
3 2 75 0 0
3 2 76 0 0
3 2 77 0 0
3 2 78 0 0
3 2 79 0 0
3 2 80 0 0
3 2 81 0 0
3 2 82 0 0
3 2 83 0 0
3 2 84 0 0
3 2 85 0 0
3 2 86 0 0
3 2 87 0 0
3 2 88 0 0
3 2 89 0 0
3 2 90 0 0
3 2 91 0 0
3 2 92 0 0
3 2 93 0 0
3 2 94 0 0
3 2 95 0 0
3 2 96 0 0
3 2 97 0 0
3 2 98 0 0
3 2 99 0 0
3 2 100 0 0
3 2 101 0 0
3 2 102 0 0
3 2 103 0 0
3 2 104 0 0
3 2 105 0 0
3 2 106 0 0
3 2 107 0 0
3 2 108 0 0
3 2 109 0 0
3 2 110 0 0
3 2 111 0 0
3 2 112 0 0
3 2 113 0 0
3 2 114 0 0
3 2 115 0 0
3 2 116 0 0
3 2 117 0 0
3 2 118 0 0
3 2 119 0 0
3 2 120 0 0
3 2 121 0 0
3 2 122 0 0
3 2 123 0 0
3 2 124 0 0
3 2 125 0 0
3 2 126 0 0
3 2 127 0 0
3 2 128 0 0
3 2 129 0 0
3 2 130 0 0
3 2 131 0 0
3 2 132 0 0
3 2 133 0 0
3 2 134 0 0
3 2 135 0 0
3 2 136 0 0
3 2 137 0 0
3 2 138 0 0
3 2 139 0 0
3 2 140 0 0
3 2 141 0 0
3 2 142 0 0
3 2 143 0 0
3 2 144 0 0
3 2 145 0 0
3 2 146 0 0
3 2 147 0 0
3 2 148 0 0
3 2 149 0 0
3 2 150 0 0
3 2 151 0 0
3 2 152 0 0
3 2 153 0 0
3 2 154 0 0
3 2 155 0 0
3 2 156 0 0
3 2 157 0 0
3 2 158 0 0
3 2 159 0 0
3 2 160 0 0
3 2 161 0 0
3 2 162 0 0
3 2 163 0 0
3 2 164 0 0
3 2 165 0 0
3 2 166 0 0
3 2 167 0 0
3 2 168 0 0
3 2 169 0 0
3 2 170 0 0
3 2 171 0 0
3 2 172 0 0
3 2 173 0 0
3 2 174 0 0
3 2 175 0 0
3 2 176 0 0
3 2 177 0 0
3 2 178 0 0
3 2 179 0 0
3 2 180 0 0
3 2 181 0 0
3 2 182 0 0
3 2 183 0 0
3 2 184 0 0
3 2 185 0 0
3 2 186 0 0
3 2 187 0 0
3 2 188 0 0
3 2 189 0 0
3 2 190 0 0
3 2 191 0 0
3 2 192 0 0
3 2 193 0 0
3 2 194 0 0
3 2 195 0 0
3 2 196 0 0
3 2 197 0 0
3 2 198 0 0
3 2 199 0 0
3 2 200 0 0
3 2 201 0 0
3 2 202 0 0
3 2 203 0 0
3 2 204 0 0
3 2 205 0 0
3 2 206 0 0
3 2 207 0 0
3 2 208 0 0
3 2 209 0 0
3 2 210 0 0
3 2 211 0 0
3 2 212 0 0
3 2 213 0 0
3 2 214 0 0
3 2 215 0 0
3 2 216 0 0
3 2 217 0 0
3 2 218 0 0
3 2 219 0 0
3 2 220 0 0
3 2 221 0 0
3 2 222 0 0
3 2 223 0 0
3 2 224 0 0
3 2 225 0 0
3 2 226 0 0
3 2 227 0 0
3 2 228 0 0
3 2 229 0 0
3 2 230 0 0
3 2 231 0 0
3 2 232 0 0
3 2 233 0 0
3 2 234 0 0
3 2 235 0 0
3 2 236 0 0
3 2 237 0 0
3 2 238 0 0
3 2 239 0 0
3 2 240 0 0
3 2 241 0 0
3 2 242 0 0
3 2 243 0 0
3 2 244 0 0
3 2 245 0 0
3 2 246 0 0
3 2 247 0 0
3 2 248 0 0
3 2 249 0 0
3 2 250 0 0
3 2 251 0 0
3 2 252 0 0
3 2 253 0 0
3 2 254 0 0
3 2 255 0 32
3 3 0 0 72
3 3 1 0 8
3 3 2 0 8
3 3 3 0 8
3 3 4 0 8
3 3 5 0 8
3 3 6 0 8
3 3 7 0 8
3 3 8 0 8
3 3 9 0 8
3 3 10 0 8
3 3 11 0 8
3 3 12 0 8
3 3 13 0 8
3 3 14 0 8
3 3 15 0 8
3 3 16 0 8
3 3 17 0 8
3 3 18 0 8
3 3 19 0 8
3 3 20 0 8
3 3 21 0 8
3 3 22 0 8
3 3 23 0 8
3 3 24 0 8
3 3 25 0 8
3 3 26 0 8
3 3 27 0 8
3 3 28 0 8
3 3 29 0 8
3 3 30 0 8
3 3 31 0 8
3 3 32 0 8
3 3 33 0 8
3 3 34 0 8
3 3 35 0 8
3 3 36 0 8
3 3 37 0 8
3 3 38 0 8
3 3 39 0 8
3 3 40 0 8
3 3 41 0 8
3 3 42 0 8
3 3 43 0 8
3 3 44 0 8
3 3 45 0 8
3 3 46 0 8
3 3 47 0 8
3 3 48 0 8
3 3 49 0 8
3 3 50 0 8
3 3 51 0 8
3 3 52 0 8
3 3 53 0 8
3 3 54 0 8
3 3 55 0 8
3 3 56 0 8
3 3 57 0 8
3 3 58 0 8
3 3 59 0 8
3 3 60 0 8
3 3 61 0 8
3 3 62 0 8
3 3 63 0 8
3 3 64 0 8
3 3 65 0 8
3 3 66 0 8
3 3 67 0 8
3 3 68 0 8
3 3 69 0 8
3 3 70 0 8
3 3 71 0 8
3 3 72 0 8
3 3 73 0 8
3 3 74 0 8
3 3 75 0 8
3 3 76 0 8
3 3 77 0 8
3 3 78 0 8
3 3 79 0 8
3 3 80 0 8
3 3 81 0 8
3 3 82 0 8
3 3 83 0 8
3 3 84 0 8
3 3 85 0 8
3 3 86 0 8
3 3 87 0 8
3 3 88 0 8
3 3 89 0 8
3 3 90 0 8
3 3 91 0 8
3 3 92 0 8
3 3 93 0 8
3 3 94 0 8
3 3 95 0 8
3 3 96 0 8
3 3 97 0 8
3 3 98 0 8
3 3 99 0 8
3 3 100 0 8
3 3 101 0 8
3 3 102 0 8
3 3 103 0 8
3 3 104 0 8
3 3 105 0 8
3 3 106 0 8
3 3 107 0 8
3 3 108 0 8
3 3 109 0 8
3 3 110 0 8
3 3 111 0 8
3 3 112 0 8
3 3 113 0 8
3 3 114 0 8
3 3 115 0 8
3 3 116 0 8
3 3 117 0 8
3 3 118 0 8
3 3 119 0 8
3 3 120 0 8
3 3 121 0 8
3 3 122 0 8
3 3 123 0 8
3 3 124 0 8
3 3 125 0 8
3 3 126 0 8
3 3 127 0 8
3 3 128 0 8
3 3 129 0 8
3 3 130 0 8
3 3 131 0 8
3 3 132 0 8
3 3 133 0 8
3 3 134 0 8
3 3 135 0 8
3 3 136 0 8
3 3 137 0 8
3 3 138 0 8
3 3 139 0 8
3 3 140 0 8
3 3 141 0 8
3 3 142 0 8
3 3 143 0 8
3 3 144 0 8
3 3 145 0 8
3 3 146 0 8
3 3 147 0 8
3 3 148 0 8
3 3 149 0 8
3 3 150 0 8
3 3 151 0 8
3 3 152 0 8
3 3 153 0 8
3 3 154 0 8
3 3 155 0 8
3 3 156 0 8
3 3 157 0 8
3 3 158 0 8
3 3 159 0 8
3 3 160 0 8
3 3 161 0 8
3 3 162 0 8
3 3 163 0 8
3 3 164 0 8
3 3 165 0 8
3 3 166 0 8
3 3 167 0 8
3 3 168 0 8
3 3 169 0 8
3 3 170 0 8
3 3 171 0 8
3 3 172 0 8
3 3 173 0 8
3 3 174 0 8
3 3 175 0 8
3 3 176 0 8
3 3 177 0 8
3 3 178 0 8
3 3 179 0 8
3 3 180 0 8
3 3 181 0 8
3 3 182 0 8
3 3 183 0 8
3 3 184 0 8
3 3 185 0 8
3 3 186 0 8
3 3 187 0 8
3 3 188 0 8
3 3 189 0 8
3 3 190 0 8
3 3 191 0 8
3 3 192 0 8
3 3 193 0 8
3 3 194 0 8
3 3 195 0 8
3 3 196 0 8
3 3 197 0 8
3 3 198 0 8
3 3 199 0 8
3 3 200 0 8
3 3 201 0 8
3 3 202 0 8
3 3 203 0 8
3 3 204 0 8
3 3 205 0 8
3 3 206 0 8
3 3 207 0 8
3 3 208 0 8
3 3 209 0 8
3 3 210 0 8
3 3 211 0 8
3 3 212 0 8
3 3 213 0 8
3 3 214 0 8
3 3 215 0 8
3 3 216 0 8
3 3 217 0 8
3 3 218 0 8
3 3 219 0 8
3 3 220 0 8
3 3 221 0 8
3 3 222 0 8
3 3 223 0 8
3 3 224 0 8
3 3 225 0 8
3 3 226 0 8
3 3 227 0 8
3 3 228 0 8
3 3 229 0 8
3 3 230 0 8
3 3 231 0 8
3 3 232 0 8
3 3 233 0 8
3 3 234 0 8
3 3 235 0 8
3 3 236 0 8
3 3 237 0 8
3 3 238 0 8
3 3 239 0 8
3 3 240 0 8
3 3 241 0 8
3 3 242 0 8
3 3 243 0 8
3 3 244 0 8
3 3 245 0 8
3 3 246 0 8
3 3 247 0 8
3 3 248 0 8
3 3 249 0 8
3 3 250 0 8
3 3 251 0 8
3 3 252 0 8
3 3 253 0 8
3 3 254 0 8
3 3 255 0 40
4 0 0 0 80
4 0 1 0 16
4 0 2 0 16
4 0 3 0 16
4 0 4 0 16
4 0 5 0 16
4 0 6 0 16
4 0 7 0 16
4 0 8 0 16
4 0 9 0 16
4 0 10 0 16
4 0 11 0 16
4 0 12 0 16
4 0 13 0 16
4 0 14 0 16
4 0 15 0 16
4 0 16 0 16
4 0 17 0 16
4 0 18 0 16
4 0 19 0 16
4 0 20 0 16
4 0 21 0 16
4 0 22 0 16
4 0 23 0 16
4 0 24 0 16
4 0 25 0 16
4 0 26 0 16
4 0 27 0 16
4 0 28 0 16
4 0 29 0 16
4 0 30 0 16
4 0 31 0 16
4 0 32 0 16
4 0 33 0 16
4 0 34 0 16
4 0 35 0 16
4 0 36 0 16
4 0 37 0 16
4 0 38 0 16
4 0 39 0 16
4 0 40 0 16
4 0 41 0 16
4 0 42 0 16
4 0 43 0 16
4 0 44 0 16
4 0 45 0 16
4 0 46 0 16
4 0 47 0 16
4 0 48 0 16
4 0 49 0 16
4 0 50 0 16
4 0 51 0 16
4 0 52 0 16
4 0 53 0 16
4 0 54 0 16
4 0 55 0 16
4 0 56 0 16
4 0 57 0 16
4 0 58 0 16
4 0 59 0 16
4 0 60 0 16
4 0 61 0 16
4 0 62 0 16
4 0 63 0 16
4 0 64 0 16
4 0 65 0 16
4 0 66 0 16
4 0 67 0 16
4 0 68 0 16
4 0 69 0 16
4 0 70 0 16
4 0 71 0 16
4 0 72 0 16
4 0 73 0 16
4 0 74 0 16
4 0 75 0 16
4 0 76 0 16
4 0 77 0 16
4 0 78 0 16
4 0 79 0 16
4 0 80 0 16
4 0 81 0 16
4 0 82 0 16
4 0 83 0 16
4 0 84 0 16
4 0 85 0 16
4 0 86 0 16
4 0 87 0 16
4 0 88 0 16
4 0 89 0 16
4 0 90 0 16
4 0 91 0 16
4 0 92 0 16
4 0 93 0 16
4 0 94 0 16
4 0 95 0 16
4 0 96 0 16
4 0 97 0 16
4 0 98 0 16
4 0 99 0 16
4 0 100 0 16
4 0 101 0 16
4 0 102 0 16
4 0 103 0 16
4 0 104 0 16
4 0 105 0 16
4 0 106 0 16
4 0 107 0 16
4 0 108 0 16
4 0 109 0 16
4 0 110 0 16
4 0 111 0 16
4 0 112 0 16
4 0 113 0 16
4 0 114 0 16
4 0 115 0 16
4 0 116 0 16
4 0 117 0 16
4 0 118 0 16
4 0 119 0 16
4 0 120 0 16
4 0 121 0 16
4 0 122 0 16
4 0 123 0 16
4 0 124 0 16
4 0 125 0 16
4 0 126 0 16
4 0 127 0 16
4 0 128 0 16
4 0 129 0 16
4 0 130 0 16
4 0 131 0 16
4 0 132 0 16
4 0 133 0 16
4 0 134 0 16
4 0 135 0 16
4 0 136 0 16
4 0 137 0 16
4 0 138 0 16
4 0 139 0 16
4 0 140 0 16
4 0 141 0 16
4 0 142 0 16
4 0 143 0 16
4 0 144 0 16
4 0 145 0 16
4 0 146 0 16
4 0 147 0 16
4 0 148 0 16
4 0 149 0 16
4 0 150 0 16
4 0 151 0 16
4 0 152 0 16
4 0 153 0 16
4 0 154 0 16
4 0 155 0 16
4 0 156 0 16
4 0 157 0 16
4 0 158 0 16
4 0 159 0 16
4 0 160 0 16
4 0 161 0 16
4 0 162 0 16
4 0 163 0 16
4 0 164 0 16
4 0 165 0 16
4 0 166 0 16
4 0 167 0 16
4 0 168 0 16
4 0 169 0 16
4 0 170 0 16
4 0 171 0 16
4 0 172 0 16
4 0 173 0 16
4 0 174 0 16
4 0 175 0 16
4 0 176 0 16
4 0 177 0 16
4 0 178 0 16
4 0 179 0 16
4 0 180 0 16
4 0 181 0 16
4 0 182 0 16
4 0 183 0 16
4 0 184 0 16
4 0 185 0 16
4 0 186 0 16
4 0 187 0 16
4 0 188 0 16
4 0 189 0 16
4 0 190 0 16
4 0 191 0 16
4 0 192 0 16
4 0 193 0 16
4 0 194 0 16
4 0 195 0 16
4 0 196 0 16
4 0 197 0 16
4 0 198 0 16
4 0 199 0 16
4 0 200 0 16
4 0 201 0 16
4 0 202 0 16
4 0 203 0 16
4 0 204 0 16
4 0 205 0 16
4 0 206 0 16
4 0 207 0 16
4 0 208 0 16
4 0 209 0 16
4 0 210 0 16
4 0 211 0 16
4 0 212 0 16
4 0 213 0 16
4 0 214 0 16
4 0 215 0 16
4 0 216 0 16
4 0 217 0 16
4 0 218 0 16
4 0 219 0 16
4 0 220 0 16
4 0 221 0 16
4 0 222 0 16
4 0 223 0 16
4 0 224 0 16
4 0 225 0 16
4 0 226 0 16
4 0 227 0 16
4 0 228 0 16
4 0 229 0 16
4 0 230 0 16
4 0 231 0 16
4 0 232 0 16
4 0 233 0 16
4 0 234 0 16
4 0 235 0 16
4 0 236 0 16
4 0 237 0 16
4 0 238 0 16
4 0 239 0 16
4 0 240 0 16
4 0 241 0 16
4 0 242 0 16
4 0 243 0 16
4 0 244 0 16
4 0 245 0 16
4 0 246 0 16
4 0 247 0 16
4 0 248 0 16
4 0 249 0 16
4 0 250 0 16
4 0 251 0 16
4 0 252 0 16
4 0 253 0 16
4 0 254 0 16
4 0 255 0 48
4 1 0 0 64
4 1 1 0 0
4 1 2 0 0
4 1 3 0 0
4 1 4 0 0
4 1 5 0 0
4 1 6 0 0
4 1 7 0 0
4 1 8 0 0
4 1 9 0 0
4 1 10 0 0
4 1 11 0 0
4 1 12 0 0
4 1 13 0 0
4 1 14 0 0
4 1 15 0 0
4 1 16 0 0
4 1 17 0 0
4 1 18 0 0
4 1 19 0 0
4 1 20 0 0
4 1 21 0 0
4 1 22 0 0
4 1 23 0 0
4 1 24 0 0
4 1 25 0 0
4 1 26 0 0
4 1 27 0 0
4 1 28 0 0
4 1 29 0 0
4 1 30 0 0
4 1 31 0 0
4 1 32 0 0
4 1 33 0 0
4 1 34 0 0
4 1 35 0 0
4 1 36 0 0
4 1 37 0 0
4 1 38 0 0
4 1 39 0 0
4 1 40 0 0
4 1 41 0 0
4 1 42 0 0
4 1 43 0 0
4 1 44 0 0
4 1 45 0 0
4 1 46 0 0
4 1 47 0 0
4 1 48 0 0
4 1 49 0 0
4 1 50 0 0
4 1 51 0 0
4 1 52 0 0
4 1 53 0 0
4 1 54 0 0
4 1 55 0 0
4 1 56 0 0
4 1 57 0 0
4 1 58 0 0
4 1 59 0 0
4 1 60 0 0
4 1 61 0 0
4 1 62 0 0
4 1 63 0 0
4 1 64 0 0
4 1 65 0 0
4 1 66 0 0
4 1 67 0 0
4 1 68 0 0
4 1 69 0 0
4 1 70 0 0
4 1 71 0 0
4 1 72 0 0
4 1 73 0 0
4 1 74 0 0
4 1 75 0 0
4 1 76 0 0
4 1 77 0 0
4 1 78 0 0
4 1 79 0 0
4 1 80 0 0
4 1 81 0 0
4 1 82 0 0
4 1 83 0 0
4 1 84 0 0
4 1 85 0 0
4 1 86 0 0
4 1 87 0 0
4 1 88 0 0
4 1 89 0 0
4 1 90 0 0
4 1 91 0 0
4 1 92 0 0
4 1 93 0 0
4 1 94 0 0
4 1 95 0 0
4 1 96 0 0
4 1 97 0 0
4 1 98 0 0
4 1 99 0 0
4 1 100 0 0
4 1 101 0 0
4 1 102 0 0
4 1 103 0 0
4 1 104 0 0
4 1 105 0 0
4 1 106 0 0
4 1 107 0 0
4 1 108 0 0
4 1 109 0 0
4 1 110 0 0
4 1 111 0 0
4 1 112 0 0
4 1 113 0 0
4 1 114 0 0
4 1 115 0 0
4 1 116 0 0
4 1 117 0 0
4 1 118 0 0
4 1 119 0 0
4 1 120 0 0
4 1 121 0 0
4 1 122 0 0
4 1 123 0 0
4 1 124 0 0
4 1 125 0 0
4 1 126 0 0
4 1 127 0 0
4 1 128 0 0
4 1 129 0 0
4 1 130 0 0
4 1 131 0 0
4 1 132 0 0
4 1 133 0 0
4 1 134 0 0
4 1 135 0 0
4 1 136 0 0
4 1 137 0 0
4 1 138 0 0
4 1 139 0 0
4 1 140 0 0
4 1 141 0 0
4 1 142 0 0
4 1 143 0 0
4 1 144 0 0
4 1 145 0 0
4 1 146 0 0
4 1 147 0 0
4 1 148 0 0
4 1 149 0 0
4 1 150 0 0
4 1 151 0 0
4 1 152 0 0
4 1 153 0 0
4 1 154 0 0
4 1 155 0 0
4 1 156 0 0
4 1 157 0 0
4 1 158 0 0
4 1 159 0 0
4 1 160 0 0
4 1 161 0 0
4 1 162 0 0
4 1 163 0 0
4 1 164 0 0
4 1 165 0 0
4 1 166 0 0
4 1 167 0 0
4 1 168 0 0
4 1 169 0 0
4 1 170 0 0
4 1 171 0 0
4 1 172 0 0
4 1 173 0 0
4 1 174 0 0
4 1 175 0 0
4 1 176 0 0
4 1 177 0 0
4 1 178 0 0
4 1 179 0 0
4 1 180 0 0
4 1 181 0 0
4 1 182 0 0
4 1 183 0 0
4 1 184 0 0
4 1 185 0 0
4 1 186 0 0
4 1 187 0 0
4 1 188 0 0
4 1 189 0 0
4 1 190 0 0
4 1 191 0 0
4 1 192 0 0
4 1 193 0 0
4 1 194 0 0
4 1 195 0 0
4 1 196 0 0
4 1 197 0 0
4 1 198 0 0
4 1 199 0 0
4 1 200 0 0
4 1 201 0 0
4 1 202 0 0
4 1 203 0 0
4 1 204 0 0
4 1 205 0 0
4 1 206 0 0
4 1 207 0 0
4 1 208 0 0
4 1 209 0 0
4 1 210 0 0
4 1 211 0 0
4 1 212 0 0
4 1 213 0 0
4 1 214 0 0
4 1 215 0 0
4 1 216 0 0
4 1 217 0 0
4 1 218 0 0
4 1 219 0 0
4 1 220 0 0
4 1 221 0 0
4 1 222 0 0
4 1 223 0 0
4 1 224 0 0
4 1 225 0 0
4 1 226 0 0
4 1 227 0 0
4 1 228 0 0
4 1 229 0 0
4 1 230 0 0
4 1 231 0 0
4 1 232 0 0
4 1 233 0 0
4 1 234 0 0
4 1 235 0 0
4 1 236 0 0
4 1 237 0 0
4 1 238 0 0
4 1 239 0 0
4 1 240 0 0
4 1 241 0 0
4 1 242 0 0
4 1 243 0 0
4 1 244 0 0
4 1 245 0 0
4 1 246 0 0
4 1 247 0 0
4 1 248 0 0
4 1 249 0 0
4 1 250 0 0
4 1 251 0 0
4 1 252 0 0
4 1 253 0 0
4 1 254 0 0
4 1 255 0 32
4 2 0 0 64
4 2 1 0 0
4 2 2 0 0
4 2 3 0 0
4 2 4 0 0
4 2 5 0 0
4 2 6 0 0
4 2 7 0 0
4 2 8 0 0
4 2 9 0 0
4 2 10 0 0
4 2 11 0 0
4 2 12 0 0
4 2 13 0 0
4 2 14 0 0
4 2 15 0 0
4 2 16 0 0
4 2 17 0 0
4 2 18 0 0
4 2 19 0 0
4 2 20 0 0
4 2 21 0 0
4 2 22 0 0
4 2 23 0 0
4 2 24 0 0
4 2 25 0 0
4 2 26 0 0
4 2 27 0 0
4 2 28 0 0
4 2 29 0 0
4 2 30 0 0
4 2 31 0 0
4 2 32 0 0
4 2 33 0 0
4 2 34 0 0
4 2 35 0 0
4 2 36 0 0
4 2 37 0 0
4 2 38 0 0
4 2 39 0 0
4 2 40 0 0
4 2 41 0 0
4 2 42 0 0
4 2 43 0 0
4 2 44 0 0
4 2 45 0 0
4 2 46 0 0
4 2 47 0 0
4 2 48 0 0
4 2 49 0 0
4 2 50 0 0
4 2 51 0 0
4 2 52 0 0
4 2 53 0 0
4 2 54 0 0
4 2 55 0 0
4 2 56 0 0
4 2 57 0 0
4 2 58 0 0
4 2 59 0 0
4 2 60 0 0
4 2 61 0 0
4 2 62 0 0
4 2 63 0 0
4 2 64 0 0
4 2 65 0 0
4 2 66 0 0
4 2 67 0 0
4 2 68 0 0
4 2 69 0 0
4 2 70 0 0
4 2 71 0 0
4 2 72 0 0
4 2 73 0 0
4 2 74 0 0
4 2 75 0 0
4 2 76 0 0
4 2 77 0 0
4 2 78 0 0
4 2 79 0 0
4 2 80 0 0
4 2 81 0 0
4 2 82 0 0
4 2 83 0 0
4 2 84 0 0
4 2 85 0 0
4 2 86 0 0
4 2 87 0 0
4 2 88 0 0
4 2 89 0 0
4 2 90 0 0
4 2 91 0 0
4 2 92 0 0
4 2 93 0 0
4 2 94 0 0
4 2 95 0 0
4 2 96 0 0
4 2 97 0 0
4 2 98 0 0
4 2 99 0 0
4 2 100 0 0
4 2 101 0 0
4 2 102 0 0
4 2 103 0 0
4 2 104 0 0
4 2 105 0 0
4 2 106 0 0
4 2 107 0 0
4 2 108 0 0
4 2 109 0 0
4 2 110 0 0
4 2 111 0 0
4 2 112 0 0
4 2 113 0 0
4 2 114 0 0
4 2 115 0 0
4 2 116 0 0
4 2 117 0 0
4 2 118 0 0
4 2 119 0 0
4 2 120 0 0
4 2 121 0 0
4 2 122 0 0
4 2 123 0 0
4 2 124 0 0
4 2 125 0 0
4 2 126 0 0
4 2 127 0 0
4 2 128 0 0
4 2 129 0 0
4 2 130 0 0
4 2 131 0 0
4 2 132 0 0
4 2 133 0 0
4 2 134 0 0
4 2 135 0 0
4 2 136 0 0
4 2 137 0 0
4 2 138 0 0
4 2 139 0 0
4 2 140 0 0
4 2 141 0 0
4 2 142 0 0
4 2 143 0 0
4 2 144 0 0
4 2 145 0 0
4 2 146 0 0
4 2 147 0 0
4 2 148 0 0
4 2 149 0 0
4 2 150 0 0
4 2 151 0 0
4 2 152 0 0
4 2 153 0 0
4 2 154 0 0
4 2 155 0 0
4 2 156 0 0
4 2 157 0 0
4 2 158 0 0
4 2 159 0 0
4 2 160 0 0
4 2 161 0 0
4 2 162 0 0
4 2 163 0 0
4 2 164 0 0
4 2 165 0 0
4 2 166 0 0
4 2 167 0 0
4 2 168 0 0
4 2 169 0 0
4 2 170 0 0
4 2 171 0 0
4 2 172 0 0
4 2 173 0 0
4 2 174 0 0
4 2 175 0 0
4 2 176 0 0
4 2 177 0 0
4 2 178 0 0
4 2 179 0 0
4 2 180 0 0
4 2 181 0 0
4 2 182 0 0
4 2 183 0 0
4 2 184 0 0
4 2 185 0 0
4 2 186 0 0
4 2 187 0 0
4 2 188 0 0
4 2 189 0 0
4 2 190 0 0
4 2 191 0 0
4 2 192 0 0
4 2 193 0 0
4 2 194 0 0
4 2 195 0 0
4 2 196 0 0
4 2 197 0 0
4 2 198 0 0
4 2 199 0 0
4 2 200 0 0
4 2 201 0 0
4 2 202 0 0
4 2 203 0 0
4 2 204 0 0
4 2 205 0 0
4 2 206 0 0
4 2 207 0 0
4 2 208 0 0
4 2 209 0 0
4 2 210 0 0
4 2 211 0 0
4 2 212 0 0
4 2 213 0 0
4 2 214 0 0
4 2 215 0 0
4 2 216 0 0
4 2 217 0 0
4 2 218 0 0
4 2 219 0 0
4 2 220 0 0
4 2 221 0 0
4 2 222 0 0
4 2 223 0 0
4 2 224 0 0
4 2 225 0 0
4 2 226 0 0
4 2 227 0 0
4 2 228 0 0
4 2 229 0 0
4 2 230 0 0
4 2 231 0 0
4 2 232 0 0
4 2 233 0 0
4 2 234 0 0
4 2 235 0 0
4 2 236 0 0
4 2 237 0 0
4 2 238 0 0
4 2 239 0 0
4 2 240 0 0
4 2 241 0 0
4 2 242 0 0
4 2 243 0 0
4 2 244 0 0
4 2 245 0 0
4 2 246 0 0
4 2 247 0 0
4 2 248 0 0
4 2 249 0 0
4 2 250 0 0
4 2 251 0 0
4 2 252 0 0
4 2 253 0 0
4 2 254 0 0
4 2 255 0 32
4 3 0 0 72
4 3 1 0 8
4 3 2 0 8
4 3 3 0 8
4 3 4 0 8
4 3 5 0 8
4 3 6 0 8
4 3 7 0 8
4 3 8 0 8
4 3 9 0 8
4 3 10 0 8
4 3 11 0 8
4 3 12 0 8
4 3 13 0 8
4 3 14 0 8
4 3 15 0 8
4 3 16 0 8
4 3 17 0 8
4 3 18 0 8
4 3 19 0 8
4 3 20 0 8
4 3 21 0 8
4 3 22 0 8
4 3 23 0 8
4 3 24 0 8
4 3 25 0 8
4 3 26 0 8
4 3 27 0 8
4 3 28 0 8
4 3 29 0 8
4 3 30 0 8
4 3 31 0 8
4 3 32 0 8
4 3 33 0 8
4 3 34 0 8
4 3 35 0 8
4 3 36 0 8
4 3 37 0 8
4 3 38 0 8
4 3 39 0 8
4 3 40 0 8
4 3 41 0 8
4 3 42 0 8
4 3 43 0 8
4 3 44 0 8
4 3 45 0 8
4 3 46 0 8
4 3 47 0 8
4 3 48 0 8
4 3 49 0 8
4 3 50 0 8
4 3 51 0 8
4 3 52 0 8
4 3 53 0 8
4 3 54 0 8
4 3 55 0 8
4 3 56 0 8
4 3 57 0 8
4 3 58 0 8
4 3 59 0 8
4 3 60 0 8
4 3 61 0 8
4 3 62 0 8
4 3 63 0 8
4 3 64 0 8
4 3 65 0 8
4 3 66 0 8
4 3 67 0 8
4 3 68 0 8
4 3 69 0 8
4 3 70 0 8
4 3 71 0 8
4 3 72 0 8
4 3 73 0 8
4 3 74 0 8
4 3 75 0 8
4 3 76 0 8
4 3 77 0 8
4 3 78 0 8
4 3 79 0 8
4 3 80 0 8
4 3 81 0 8
4 3 82 0 8
4 3 83 0 8
4 3 84 0 8
4 3 85 0 8
4 3 86 0 8
4 3 87 0 8
4 3 88 0 8
4 3 89 0 8
4 3 90 0 8
4 3 91 0 8
4 3 92 0 8
4 3 93 0 8
4 3 94 0 8
4 3 95 0 8
4 3 96 0 8
4 3 97 0 8
4 3 98 0 8
4 3 99 0 8
4 3 100 0 8
4 3 101 0 8
4 3 102 0 8
4 3 103 0 8
4 3 104 0 8
4 3 105 0 8
4 3 106 0 8
4 3 107 0 8
4 3 108 0 8
4 3 109 0 8
4 3 110 0 8
4 3 111 0 8
4 3 112 0 8
4 3 113 0 8
4 3 114 0 8
4 3 115 0 8
4 3 116 0 8
4 3 117 0 8
4 3 118 0 8
4 3 119 0 8
4 3 120 0 8
4 3 121 0 8
4 3 122 0 8
4 3 123 0 8
4 3 124 0 8
4 3 125 0 8
4 3 126 0 8
4 3 127 0 8
4 3 128 0 8
4 3 129 0 8
4 3 130 0 8
4 3 131 0 8
4 3 132 0 8
4 3 133 0 8
4 3 134 0 8
4 3 135 0 8
4 3 136 0 8
4 3 137 0 8
4 3 138 0 8
4 3 139 0 8
4 3 140 0 8
4 3 141 0 8
4 3 142 0 8
4 3 143 0 8
4 3 144 0 8
4 3 145 0 8
4 3 146 0 8
4 3 147 0 8
4 3 148 0 8
4 3 149 0 8
4 3 150 0 8
4 3 151 0 8
4 3 152 0 8
4 3 153 0 8
4 3 154 0 8
4 3 155 0 8
4 3 156 0 8
4 3 157 0 8
4 3 158 0 8
4 3 159 0 8
4 3 160 0 8
4 3 161 0 8
4 3 162 0 8
4 3 163 0 8
4 3 164 0 8
4 3 165 0 8
4 3 166 0 8
4 3 167 0 8
4 3 168 0 8
4 3 169 0 8
4 3 170 0 8
4 3 171 0 8
4 3 172 0 8
4 3 173 0 8
4 3 174 0 8
4 3 175 0 8
4 3 176 0 8
4 3 177 0 8
4 3 178 0 8
4 3 179 0 8
4 3 180 0 8
4 3 181 0 8
4 3 182 0 8
4 3 183 0 8
4 3 184 0 8
4 3 185 0 8
4 3 186 0 8
4 3 187 0 8
4 3 188 0 8
4 3 189 0 8
4 3 190 0 8
4 3 191 0 8
4 3 192 0 8
4 3 193 0 8
4 3 194 0 8
4 3 195 0 8
4 3 196 0 8
4 3 197 0 8
4 3 198 0 8
4 3 199 0 8
4 3 200 0 8
4 3 201 0 8
4 3 202 0 8
4 3 203 0 8
4 3 204 0 8
4 3 205 0 8
4 3 206 0 8
4 3 207 0 8
4 3 208 0 8
4 3 209 0 8
4 3 210 0 8
4 3 211 0 8
4 3 212 0 8
4 3 213 0 8
4 3 214 0 8
4 3 215 0 8
4 3 216 0 8
4 3 217 0 8
4 3 218 0 8
4 3 219 0 8
4 3 220 0 8
4 3 221 0 8
4 3 222 0 8
4 3 223 0 8
4 3 224 0 8
4 3 225 0 8
4 3 226 0 8
4 3 227 0 8
4 3 228 0 8
4 3 229 0 8
4 3 230 0 8
4 3 231 0 8
4 3 232 0 8
4 3 233 0 8
4 3 234 0 8
4 3 235 0 8
4 3 236 0 8
4 3 237 0 8
4 3 238 0 8
4 3 239 0 8
4 3 240 0 8
4 3 241 0 8
4 3 242 0 8
4 3 243 0 8
4 3 244 0 8
4 3 245 0 8
4 3 246 0 8
4 3 247 0 8
4 3 248 0 8
4 3 249 0 8
4 3 250 0 8
4 3 251 0 8
4 3 252 0 8
4 3 253 0 8
4 3 254 0 8
4 3 255 0 40
5 0 0 0 80
5 0 1 0 16
5 0 2 0 16
5 0 3 0 16
5 0 4 0 16
5 0 5 0 16
5 0 6 0 16
5 0 7 0 16
5 0 8 0 16
5 0 9 0 16
5 0 10 0 16
5 0 11 0 16
5 0 12 0 16
5 0 13 0 16
5 0 14 0 16
5 0 15 0 16
5 0 16 0 16
5 0 17 0 16
5 0 18 0 16
5 0 19 0 16
5 0 20 0 16
5 0 21 0 16
5 0 22 0 16
5 0 23 0 16
5 0 24 0 16
5 0 25 0 16
5 0 26 0 16
5 0 27 0 16
5 0 28 0 16
5 0 29 0 16
5 0 30 0 16
5 0 31 0 16
5 0 32 0 16
5 0 33 0 16
5 0 34 0 16
5 0 35 0 16
5 0 36 0 16
5 0 37 0 16
5 0 38 0 16
5 0 39 0 16
5 0 40 0 16
5 0 41 0 16
5 0 42 0 16
5 0 43 0 16
5 0 44 0 16
5 0 45 0 16
5 0 46 0 16
5 0 47 0 16
5 0 48 0 16
5 0 49 0 16
5 0 50 0 16
5 0 51 0 16
5 0 52 0 16
5 0 53 0 16
5 0 54 0 16
5 0 55 0 16
5 0 56 0 16
5 0 57 0 16
5 0 58 0 16
5 0 59 0 16
5 0 60 0 16
5 0 61 0 16
5 0 62 0 16
5 0 63 0 16
5 0 64 0 16
5 0 65 0 16
5 0 66 0 16
5 0 67 0 16
5 0 68 0 16
5 0 69 0 16
5 0 70 0 16
5 0 71 0 16
5 0 72 0 16
5 0 73 0 16
5 0 74 0 16
5 0 75 0 16
5 0 76 0 16
5 0 77 0 16
5 0 78 0 16
5 0 79 0 16
5 0 80 0 16
5 0 81 0 16
5 0 82 0 16
5 0 83 0 16
5 0 84 0 16
5 0 85 0 16
5 0 86 0 16
5 0 87 0 16
5 0 88 0 16
5 0 89 0 16
5 0 90 0 16
5 0 91 0 16
5 0 92 0 16
5 0 93 0 16
5 0 94 0 16
5 0 95 0 16
5 0 96 0 16
5 0 97 0 16
5 0 98 0 16
5 0 99 0 16
5 0 100 0 16
5 0 101 0 16
5 0 102 0 16
5 0 103 0 16
5 0 104 0 16
5 0 105 0 16
5 0 106 0 16
5 0 107 0 16
5 0 108 0 16
5 0 109 0 16
5 0 110 0 16
5 0 111 0 16
5 0 112 0 16
5 0 113 0 16
5 0 114 0 16
5 0 115 0 16
5 0 116 0 16
5 0 117 0 16
5 0 118 0 16
5 0 119 0 16
5 0 120 0 16
5 0 121 0 16
5 0 122 0 16
5 0 123 0 16
5 0 124 0 16
5 0 125 0 16
5 0 126 0 16
5 0 127 0 16
5 0 128 0 16
5 0 129 0 16
5 0 130 0 16
5 0 131 0 16
5 0 132 0 16
5 0 133 0 16
5 0 134 0 16
5 0 135 0 16
5 0 136 0 16
5 0 137 0 16
5 0 138 0 16
5 0 139 0 16
5 0 140 0 16
5 0 141 0 16
5 0 142 0 16
5 0 143 0 16
5 0 144 0 16
5 0 145 0 16
5 0 146 0 16
5 0 147 0 16
5 0 148 0 16
5 0 149 0 16
5 0 150 0 16
5 0 151 0 16
5 0 152 0 16
5 0 153 0 16
5 0 154 0 16
5 0 155 0 16
5 0 156 0 16
5 0 157 0 16
5 0 158 0 16
5 0 159 0 16
5 0 160 0 16
5 0 161 0 16
5 0 162 0 16
5 0 163 0 16
5 0 164 0 16
5 0 165 0 16
5 0 166 0 16
5 0 167 0 16
5 0 168 0 16
5 0 169 0 16
5 0 170 0 16
5 0 171 0 16
5 0 172 0 16
5 0 173 0 16
5 0 174 0 16
5 0 175 0 16
5 0 176 0 16
5 0 177 0 16
5 0 178 0 16
5 0 179 0 16
5 0 180 0 16
5 0 181 0 16
5 0 182 0 16
5 0 183 0 16
5 0 184 0 16
5 0 185 0 16
5 0 186 0 16
5 0 187 0 16
5 0 188 0 16
5 0 189 0 16
5 0 190 0 16
5 0 191 0 16
5 0 192 0 16
5 0 193 0 16
5 0 194 0 16
5 0 195 0 16
5 0 196 0 16
5 0 197 0 16
5 0 198 0 16
5 0 199 0 16
5 0 200 0 16
5 0 201 0 16
5 0 202 0 16
5 0 203 0 16
5 0 204 0 16
5 0 205 0 16
5 0 206 0 16
5 0 207 0 16
5 0 208 0 16
5 0 209 0 16
5 0 210 0 16
5 0 211 0 16
5 0 212 0 16
5 0 213 0 16
5 0 214 0 16
5 0 215 0 16
5 0 216 0 16
5 0 217 0 16
5 0 218 0 16
5 0 219 0 16
5 0 220 0 16
5 0 221 0 16
5 0 222 0 16
5 0 223 0 16
5 0 224 0 16
5 0 225 0 16
5 0 226 0 16
5 0 227 0 16
5 0 228 0 16
5 0 229 0 16
5 0 230 0 16
5 0 231 0 16
5 0 232 0 16
5 0 233 0 16
5 0 234 0 16
5 0 235 0 16
5 0 236 0 16
5 0 237 0 16
5 0 238 0 16
5 0 239 0 16
5 0 240 0 16
5 0 241 0 16
5 0 242 0 16
5 0 243 0 16
5 0 244 0 16
5 0 245 0 16
5 0 246 0 16
5 0 247 0 16
5 0 248 0 16
5 0 249 0 16
5 0 250 0 16
5 0 251 0 16
5 0 252 0 16
5 0 253 0 16
5 0 254 0 16
5 0 255 0 48
5 1 0 0 64
5 1 1 0 0
5 1 2 0 0
5 1 3 0 0
5 1 4 0 0
5 1 5 0 0
5 1 6 0 0
5 1 7 0 0
5 1 8 0 0
5 1 9 0 0
5 1 10 0 0
5 1 11 0 0
5 1 12 0 0
5 1 13 0 0
5 1 14 0 0
5 1 15 0 0
5 1 16 0 0
5 1 17 0 0
5 1 18 0 0
5 1 19 0 0
5 1 20 0 0
5 1 21 0 0
5 1 22 0 0
5 1 23 0 0
5 1 24 0 0
5 1 25 0 0
5 1 26 0 0
5 1 27 0 0
5 1 28 0 0
5 1 29 0 0
5 1 30 0 0
5 1 31 0 0
5 1 32 0 0
5 1 33 0 0
5 1 34 0 0
5 1 35 0 0
5 1 36 0 0
5 1 37 0 0
5 1 38 0 0
5 1 39 0 0
5 1 40 0 0
5 1 41 0 0
5 1 42 0 0
5 1 43 0 0
5 1 44 0 0
5 1 45 0 0
5 1 46 0 0
5 1 47 0 0
5 1 48 0 0
5 1 49 0 0
5 1 50 0 0
5 1 51 0 0
5 1 52 0 0
5 1 53 0 0
5 1 54 0 0
5 1 55 0 0
5 1 56 0 0
5 1 57 0 0
5 1 58 0 0
5 1 59 0 0
5 1 60 0 0
5 1 61 0 0
5 1 62 0 0
5 1 63 0 0
5 1 64 0 0
5 1 65 0 0
5 1 66 0 0
5 1 67 0 0
5 1 68 0 0
5 1 69 0 0
5 1 70 0 0
5 1 71 0 0
5 1 72 0 0
5 1 73 0 0
5 1 74 0 0
5 1 75 0 0
5 1 76 0 0
5 1 77 0 0
5 1 78 0 0
5 1 79 0 0
5 1 80 0 0
5 1 81 0 0
5 1 82 0 0
5 1 83 0 0
5 1 84 0 0
5 1 85 0 0
5 1 86 0 0
5 1 87 0 0
5 1 88 0 0
5 1 89 0 0
5 1 90 0 0
5 1 91 0 0
5 1 92 0 0
5 1 93 0 0
5 1 94 0 0
5 1 95 0 0
5 1 96 0 0
5 1 97 0 0
5 1 98 0 0
5 1 99 0 0
5 1 100 0 0
5 1 101 0 0
5 1 102 0 0
5 1 103 0 0
5 1 104 0 0
5 1 105 0 0
5 1 106 0 0
5 1 107 0 0
5 1 108 0 0
5 1 109 0 0
5 1 110 0 0
5 1 111 0 0
5 1 112 0 0
5 1 113 0 0
5 1 114 0 0
5 1 115 0 0
5 1 116 0 0
5 1 117 0 0
5 1 118 0 0
5 1 119 0 0
5 1 120 0 0
5 1 121 0 0
5 1 122 0 0
5 1 123 0 0
5 1 124 0 0
5 1 125 0 0
5 1 126 0 0
5 1 127 0 0
5 1 128 0 0
5 1 129 0 0
5 1 130 0 0
5 1 131 0 0
5 1 132 0 0
5 1 133 0 0
5 1 134 0 0
5 1 135 0 0
5 1 136 0 0
5 1 137 0 0
5 1 138 0 0
5 1 139 0 0
5 1 140 0 0
5 1 141 0 0
5 1 142 0 0
5 1 143 0 0
5 1 144 0 0
5 1 145 0 0
5 1 146 0 0
5 1 147 0 0
5 1 148 0 0
5 1 149 0 0
5 1 150 0 0
5 1 151 0 0
5 1 152 0 0
5 1 153 0 0
5 1 154 0 0
5 1 155 0 0
5 1 156 0 0
5 1 157 0 0
5 1 158 0 0
5 1 159 0 0
5 1 160 0 0
5 1 161 0 0
5 1 162 0 0
5 1 163 0 0
5 1 164 0 0
5 1 165 0 0
5 1 166 0 0
5 1 167 0 0
5 1 168 0 0
5 1 169 0 0
5 1 170 0 0
5 1 171 0 0
5 1 172 0 0
5 1 173 0 0
5 1 174 0 0
5 1 175 0 0
5 1 176 0 0
5 1 177 0 0
5 1 178 0 0
5 1 179 0 0
5 1 180 0 0
5 1 181 0 0
5 1 182 0 0
5 1 183 0 0
5 1 184 0 0
5 1 185 0 0
5 1 186 0 0
5 1 187 0 0
5 1 188 0 0
5 1 189 0 0
5 1 190 0 0
5 1 191 0 0
5 1 192 0 0
5 1 193 0 0
5 1 194 0 0
5 1 195 0 0
5 1 196 0 0
5 1 197 0 0
5 1 198 0 0
5 1 199 0 0
5 1 200 0 0
5 1 201 0 0
5 1 202 0 0
5 1 203 0 0
5 1 204 0 0
5 1 205 0 0
5 1 206 0 0
5 1 207 0 0
5 1 208 0 0
5 1 209 0 0
5 1 210 0 0
5 1 211 0 0
5 1 212 0 0
5 1 213 0 0
5 1 214 0 0
5 1 215 0 0
5 1 216 0 0
5 1 217 0 0
5 1 218 0 0
5 1 219 0 0
5 1 220 0 0
5 1 221 0 0
5 1 222 0 0
5 1 223 0 0
5 1 224 0 0
5 1 225 0 0
5 1 226 0 0
5 1 227 0 0
5 1 228 0 0
5 1 229 0 0
5 1 230 0 0
5 1 231 0 0
5 1 232 0 0
5 1 233 0 0
5 1 234 0 0
5 1 235 0 0
5 1 236 0 0
5 1 237 0 0
5 1 238 0 0
5 1 239 0 0
5 1 240 0 0
5 1 241 0 0
5 1 242 0 0
5 1 243 0 0
5 1 244 0 0
5 1 245 0 0
5 1 246 0 0
5 1 247 0 0
5 1 248 0 0
5 1 249 0 0
5 1 250 0 0
5 1 251 0 0
5 1 252 0 0
5 1 253 0 0
5 1 254 0 0
5 1 255 0 32
5 2 0 0 64
5 2 1 0 0
5 2 2 0 0
5 2 3 0 0
5 2 4 0 0
5 2 5 0 0
5 2 6 0 0
5 2 7 0 0
5 2 8 0 0
5 2 9 0 0
5 2 10 0 0
5 2 11 0 0
5 2 12 0 0
5 2 13 0 0
5 2 14 0 0
5 2 15 0 0
5 2 16 0 0
5 2 17 0 0
5 2 18 0 0
5 2 19 0 0
5 2 20 0 0
5 2 21 0 0
5 2 22 0 0
5 2 23 0 0
5 2 24 0 0
5 2 25 0 0
5 2 26 0 0
5 2 27 0 0
5 2 28 0 0
5 2 29 0 0
5 2 30 0 0
5 2 31 0 0
5 2 32 0 0
5 2 33 0 0
5 2 34 0 0
5 2 35 0 0
5 2 36 0 0
5 2 37 0 0
5 2 38 0 0
5 2 39 0 0
5 2 40 0 0
5 2 41 0 0
5 2 42 0 0
5 2 43 0 0
5 2 44 0 0
5 2 45 0 0
5 2 46 0 0
5 2 47 0 0
5 2 48 0 0
5 2 49 0 0
5 2 50 0 0
5 2 51 0 0
5 2 52 0 0
5 2 53 0 0
5 2 54 0 0
5 2 55 0 0
5 2 56 0 0
5 2 57 0 0
5 2 58 0 0
5 2 59 0 0
5 2 60 0 0
5 2 61 0 0
5 2 62 0 0
5 2 63 0 0
5 2 64 0 0
5 2 65 0 0
5 2 66 0 0
5 2 67 0 0
5 2 68 0 0
5 2 69 0 0
5 2 70 0 0
5 2 71 0 0
5 2 72 0 0
5 2 73 0 0
5 2 74 0 0
5 2 75 0 0
5 2 76 0 0
5 2 77 0 0
5 2 78 0 0
5 2 79 0 0
5 2 80 0 0
5 2 81 0 0
5 2 82 0 0
5 2 83 0 0
5 2 84 0 0
5 2 85 0 0
5 2 86 0 0
5 2 87 0 0
5 2 88 0 0
5 2 89 0 0
5 2 90 0 0
5 2 91 0 0
5 2 92 0 0
5 2 93 0 0
5 2 94 0 0
5 2 95 0 0
5 2 96 0 0
5 2 97 0 0
5 2 98 0 0
5 2 99 0 0
5 2 100 0 0
5 2 101 0 0
5 2 102 0 0
5 2 103 0 0
5 2 104 0 0
5 2 105 0 0
5 2 106 0 0
5 2 107 0 0
5 2 108 0 0
5 2 109 0 0
5 2 110 0 0
5 2 111 0 0
5 2 112 0 0
5 2 113 0 0
5 2 114 0 0
5 2 115 0 0
5 2 116 0 0
5 2 117 0 0
5 2 118 0 0
5 2 119 0 0
5 2 120 0 0
5 2 121 0 0
5 2 122 0 0
5 2 123 0 0
5 2 124 0 0
5 2 125 0 0
5 2 126 0 0
5 2 127 0 0
5 2 128 0 0
5 2 129 0 0
5 2 130 0 0
5 2 131 0 0
5 2 132 0 0
5 2 133 0 0
5 2 134 0 0
5 2 135 0 0
5 2 136 0 0
5 2 137 0 0
5 2 138 0 0
5 2 139 0 0
5 2 140 0 0
5 2 141 0 0
5 2 142 0 0
5 2 143 0 0
5 2 144 0 0
5 2 145 0 0
5 2 146 0 0
5 2 147 0 0
5 2 148 0 0
5 2 149 0 0
5 2 150 0 0
5 2 151 0 0
5 2 152 0 0
5 2 153 0 0
5 2 154 0 0
5 2 155 0 0
5 2 156 0 0
5 2 157 0 0
5 2 158 0 0
5 2 159 0 0
5 2 160 0 0
5 2 161 0 0
5 2 162 0 0
5 2 163 0 0
5 2 164 0 0
5 2 165 0 0
5 2 166 0 0
5 2 167 0 0
5 2 168 0 0
5 2 169 0 0
5 2 170 0 0
5 2 171 0 0
5 2 172 0 0
5 2 173 0 0
5 2 174 0 0
5 2 175 0 0
5 2 176 0 0
5 2 177 0 0
5 2 178 0 0
5 2 179 0 0
5 2 180 0 0
5 2 181 0 0
5 2 182 0 0
5 2 183 0 0
5 2 184 0 0
5 2 185 0 0
5 2 186 0 0
5 2 187 0 0
5 2 188 0 0
5 2 189 0 0
5 2 190 0 0
5 2 191 0 0
5 2 192 0 0
5 2 193 0 0
5 2 194 0 0
5 2 195 0 0
5 2 196 0 0
5 2 197 0 0
5 2 198 0 0
5 2 199 0 0
5 2 200 0 0
5 2 201 0 0
5 2 202 0 0
5 2 203 0 0
5 2 204 0 0
5 2 205 0 0
5 2 206 0 0
5 2 207 0 0
5 2 208 0 0
5 2 209 0 0
5 2 210 0 0
5 2 211 0 0
5 2 212 0 0
5 2 213 0 0
5 2 214 0 0
5 2 215 0 0
5 2 216 0 0
5 2 217 0 0
5 2 218 0 0
5 2 219 0 0
5 2 220 0 0
5 2 221 0 0
5 2 222 0 0
5 2 223 0 0
5 2 224 0 0
5 2 225 0 0
5 2 226 0 0
5 2 227 0 0
5 2 228 0 0
5 2 229 0 0
5 2 230 0 0
5 2 231 0 0
5 2 232 0 0
5 2 233 0 0
5 2 234 0 0
5 2 235 0 0
5 2 236 0 0
5 2 237 0 0
5 2 238 0 0
5 2 239 0 0
5 2 240 0 0
5 2 241 0 0
5 2 242 0 0
5 2 243 0 0
5 2 244 0 0
5 2 245 0 0
5 2 246 0 0
5 2 247 0 0
5 2 248 0 0
5 2 249 0 0
5 2 250 0 0
5 2 251 0 0
5 2 252 0 0
5 2 253 0 0
5 2 254 0 0
5 2 255 0 32
5 3 0 0 72
5 3 1 0 8
5 3 2 0 8
5 3 3 0 8
5 3 4 0 8
5 3 5 0 8
5 3 6 0 8
5 3 7 0 8
5 3 8 0 8
5 3 9 0 8
5 3 10 0 8
5 3 11 0 8
5 3 12 0 8
5 3 13 0 8
5 3 14 0 8
5 3 15 0 8
5 3 16 0 8
5 3 17 0 8
5 3 18 0 8
5 3 19 0 8
5 3 20 0 8
5 3 21 0 8
5 3 22 0 8
5 3 23 0 8
5 3 24 0 8
5 3 25 0 8
5 3 26 0 8
5 3 27 0 8
5 3 28 0 8
5 3 29 0 8
5 3 30 0 8
5 3 31 0 8
5 3 32 0 8
5 3 33 0 8
5 3 34 0 8
5 3 35 0 8
5 3 36 0 8
5 3 37 0 8
5 3 38 0 8
5 3 39 0 8
5 3 40 0 8
5 3 41 0 8
5 3 42 0 8
5 3 43 0 8
5 3 44 0 8
5 3 45 0 8
5 3 46 0 8
5 3 47 0 8
5 3 48 0 8
5 3 49 0 8
5 3 50 0 8
5 3 51 0 8
5 3 52 0 8
5 3 53 0 8
5 3 54 0 8
5 3 55 0 8
5 3 56 0 8
5 3 57 0 8
5 3 58 0 8
5 3 59 0 8
5 3 60 0 8
5 3 61 0 8
5 3 62 0 8
5 3 63 0 8
5 3 64 0 8
5 3 65 0 8
5 3 66 0 8
5 3 67 0 8
5 3 68 0 8
5 3 69 0 8
5 3 70 0 8
5 3 71 0 8
5 3 72 0 8
5 3 73 0 8
5 3 74 0 8
5 3 75 0 8
5 3 76 0 8
5 3 77 0 8
5 3 78 0 8
5 3 79 0 8
5 3 80 0 8
5 3 81 0 8
5 3 82 0 8
5 3 83 0 8
5 3 84 0 8
5 3 85 0 8
5 3 86 0 8
5 3 87 0 8
5 3 88 0 8
5 3 89 0 8
5 3 90 0 8
5 3 91 0 8
5 3 92 0 8
5 3 93 0 8
5 3 94 0 8
5 3 95 0 8
5 3 96 0 8
5 3 97 0 8
5 3 98 0 8
5 3 99 0 8
5 3 100 0 8
5 3 101 0 8
5 3 102 0 8
5 3 103 0 8
5 3 104 0 8
5 3 105 0 8
5 3 106 0 8
5 3 107 0 8
5 3 108 0 8
5 3 109 0 8
5 3 110 0 8
5 3 111 0 8
5 3 112 0 8
5 3 113 0 8
5 3 114 0 8
5 3 115 0 8
5 3 116 0 8
5 3 117 0 8
5 3 118 0 8
5 3 119 0 8
5 3 120 0 8
5 3 121 0 8
5 3 122 0 8
5 3 123 0 8
5 3 124 0 8
5 3 125 0 8
5 3 126 0 8
5 3 127 0 8
5 3 128 0 8
5 3 129 0 8
5 3 130 0 8
5 3 131 0 8
5 3 132 0 8
5 3 133 0 8
5 3 134 0 8
5 3 135 0 8
5 3 136 0 8
5 3 137 0 8
5 3 138 0 8
5 3 139 0 8
5 3 140 0 8
5 3 141 0 8
5 3 142 0 8
5 3 143 0 8
5 3 144 0 8
5 3 145 0 8
5 3 146 0 8
5 3 147 0 8
5 3 148 0 8
5 3 149 0 8
5 3 150 0 8
5 3 151 0 8
5 3 152 0 8
5 3 153 0 8
5 3 154 0 8
5 3 155 0 8
5 3 156 0 8
5 3 157 0 8
5 3 158 0 8
5 3 159 0 8
5 3 160 0 8
5 3 161 0 8
5 3 162 0 8
5 3 163 0 8
5 3 164 0 8
5 3 165 0 8
5 3 166 0 8
5 3 167 0 8
5 3 168 0 8
5 3 169 0 8
5 3 170 0 8
5 3 171 0 8
5 3 172 0 8
5 3 173 0 8
5 3 174 0 8
5 3 175 0 8
5 3 176 0 8
5 3 177 0 8
5 3 178 0 8
5 3 179 0 8
5 3 180 0 8
5 3 181 0 8
5 3 182 0 8
5 3 183 0 8
5 3 184 0 8
5 3 185 0 8
5 3 186 0 8
5 3 187 0 8
5 3 188 0 8
5 3 189 0 8
5 3 190 0 8
5 3 191 0 8
5 3 192 0 8
5 3 193 0 8
5 3 194 0 8
5 3 195 0 8
5 3 196 0 8
5 3 197 0 8
5 3 198 0 8
5 3 199 0 8
5 3 200 0 8
5 3 201 0 8
5 3 202 0 8
5 3 203 0 8
5 3 204 0 8
5 3 205 0 8
5 3 206 0 8
5 3 207 0 8
5 3 208 0 8
5 3 209 0 8
5 3 210 0 8
5 3 211 0 8
5 3 212 0 8
5 3 213 0 8
5 3 214 0 8
5 3 215 0 8
5 3 216 0 8
5 3 217 0 8
5 3 218 0 8
5 3 219 0 8
5 3 220 0 8
5 3 221 0 8
5 3 222 0 8
5 3 223 0 8
5 3 224 0 8
5 3 225 0 8
5 3 226 0 8
5 3 227 0 8
5 3 228 0 8
5 3 229 0 8
5 3 230 0 8
5 3 231 0 8
5 3 232 0 8
5 3 233 0 8
5 3 234 0 8
5 3 235 0 8
5 3 236 0 8
5 3 237 0 8
5 3 238 0 8
5 3 239 0 8
5 3 240 0 8
5 3 241 0 8
5 3 242 0 8
5 3 243 0 8
5 3 244 0 8
5 3 245 0 8
5 3 246 0 8
5 3 247 0 8
5 3 248 0 8
5 3 249 0 8
5 3 250 0 8
5 3 251 0 8
5 3 252 0 8
5 3 253 0 8
5 3 254 0 8
5 3 255 0 40
6 0 0 0 80
6 0 1 0 16
6 0 2 0 16
6 0 3 0 16
6 0 4 0 16
6 0 5 0 16
6 0 6 0 16
6 0 7 0 16
6 0 8 0 16
6 0 9 0 16
6 0 10 0 16
6 0 11 0 16
6 0 12 0 16
6 0 13 0 16
6 0 14 0 16
6 0 15 0 16
6 0 16 0 16
6 0 17 0 16
6 0 18 0 16
6 0 19 0 16
6 0 20 0 16
6 0 21 0 16
6 0 22 0 16
6 0 23 0 16
6 0 24 0 16
6 0 25 0 16
6 0 26 0 16
6 0 27 0 16
6 0 28 0 16
6 0 29 0 16
6 0 30 0 16
6 0 31 0 16
6 0 32 0 16
6 0 33 0 16
6 0 34 0 16
6 0 35 0 16
6 0 36 0 16
6 0 37 0 16
6 0 38 0 16
6 0 39 0 16
6 0 40 0 16
6 0 41 0 16
6 0 42 0 16
6 0 43 0 16
6 0 44 0 16
6 0 45 0 16
6 0 46 0 16
6 0 47 0 16
6 0 48 0 16
6 0 49 0 16
6 0 50 0 16
6 0 51 0 16
6 0 52 0 16
6 0 53 0 16
6 0 54 0 16
6 0 55 0 16
6 0 56 0 16
6 0 57 0 16
6 0 58 0 16
6 0 59 0 16
6 0 60 0 16
6 0 61 0 16
6 0 62 0 16
6 0 63 0 16
6 0 64 0 16
6 0 65 0 16
6 0 66 0 16
6 0 67 0 16
6 0 68 0 16
6 0 69 0 16
6 0 70 0 16
6 0 71 0 16
6 0 72 0 16
6 0 73 0 16
6 0 74 0 16
6 0 75 0 16
6 0 76 0 16
6 0 77 0 16
6 0 78 0 16
6 0 79 0 16
6 0 80 0 16
6 0 81 0 16
6 0 82 0 16
6 0 83 0 16
6 0 84 0 16
6 0 85 0 16
6 0 86 0 16
6 0 87 0 16
6 0 88 0 16
6 0 89 0 16
6 0 90 0 16
6 0 91 0 16
6 0 92 0 16
6 0 93 0 16
6 0 94 0 16
6 0 95 0 16
6 0 96 0 16
6 0 97 0 16
6 0 98 0 16
6 0 99 0 16
6 0 100 0 16
6 0 101 0 16
6 0 102 0 16
6 0 103 0 16
6 0 104 0 16
6 0 105 0 16
6 0 106 0 16
6 0 107 0 16
6 0 108 0 16
6 0 109 0 16
6 0 110 0 16
6 0 111 0 16
6 0 112 0 16
6 0 113 0 16
6 0 114 0 16
6 0 115 0 16
6 0 116 0 16
6 0 117 0 16
6 0 118 0 16
6 0 119 0 16
6 0 120 0 16
6 0 121 0 16
6 0 122 0 16
6 0 123 0 16
6 0 124 0 16
6 0 125 0 16
6 0 126 0 16
6 0 127 0 16
6 0 128 0 16
6 0 129 0 16
6 0 130 0 16
6 0 131 0 16
6 0 132 0 16
6 0 133 0 16
6 0 134 0 16
6 0 135 0 16
6 0 136 0 16
6 0 137 0 16
6 0 138 0 16
6 0 139 0 16
6 0 140 0 16
6 0 141 0 16
6 0 142 0 16
6 0 143 0 16
6 0 144 0 16
6 0 145 0 16
6 0 146 0 16
6 0 147 0 16
6 0 148 0 16
6 0 149 0 16
6 0 150 0 16
6 0 151 0 16
6 0 152 0 16
6 0 153 0 16
6 0 154 0 16
6 0 155 0 16
6 0 156 0 16
6 0 157 0 16
6 0 158 0 16
6 0 159 0 16
6 0 160 0 16
6 0 161 0 16
6 0 162 0 16
6 0 163 0 16
6 0 164 0 16
6 0 165 0 16
6 0 166 0 16
6 0 167 0 16
6 0 168 0 16
6 0 169 0 16
6 0 170 0 16
6 0 171 0 16
6 0 172 0 16
6 0 173 0 16
6 0 174 0 16
6 0 175 0 16
6 0 176 0 16
6 0 177 0 16
6 0 178 0 16
6 0 179 0 16
6 0 180 0 16
6 0 181 0 16
6 0 182 0 16
6 0 183 0 16
6 0 184 0 16
6 0 185 0 16
6 0 186 0 16
6 0 187 0 16
6 0 188 0 16
6 0 189 0 16
6 0 190 0 16
6 0 191 0 16
6 0 192 0 16
6 0 193 0 16
6 0 194 0 16
6 0 195 0 16
6 0 196 0 16
6 0 197 0 16
6 0 198 0 16
6 0 199 0 16
6 0 200 0 16
6 0 201 0 16
6 0 202 0 16
6 0 203 0 16
6 0 204 0 16
6 0 205 0 16
6 0 206 0 16
6 0 207 0 16
6 0 208 0 16
6 0 209 0 16
6 0 210 0 16
6 0 211 0 16
6 0 212 0 16
6 0 213 0 16
6 0 214 0 16
6 0 215 0 16
6 0 216 0 16
6 0 217 0 16
6 0 218 0 16
6 0 219 0 16
6 0 220 0 16
6 0 221 0 16
6 0 222 0 16
6 0 223 0 16
6 0 224 0 16
6 0 225 0 16
6 0 226 0 16
6 0 227 0 16
6 0 228 0 16
6 0 229 0 16
6 0 230 0 16
6 0 231 0 16
6 0 232 0 16
6 0 233 0 16
6 0 234 0 16
6 0 235 0 16
6 0 236 0 16
6 0 237 0 16
6 0 238 0 16
6 0 239 0 16
6 0 240 0 16
6 0 241 0 16
6 0 242 0 16
6 0 243 0 16
6 0 244 0 16
6 0 245 0 16
6 0 246 0 16
6 0 247 0 16
6 0 248 0 16
6 0 249 0 16
6 0 250 0 16
6 0 251 0 16
6 0 252 0 16
6 0 253 0 16
6 0 254 0 16
6 0 255 0 48
6 1 0 0 64
6 1 1 0 0
6 1 2 0 0
6 1 3 0 0
6 1 4 0 0
6 1 5 0 0
6 1 6 0 0
6 1 7 0 0
6 1 8 0 0
6 1 9 0 0
6 1 10 0 0
6 1 11 0 0
6 1 12 0 0
6 1 13 0 0
6 1 14 0 0
6 1 15 0 0
6 1 16 0 0
6 1 17 0 0
6 1 18 0 0
6 1 19 0 0
6 1 20 0 0
6 1 21 0 0
6 1 22 0 0
6 1 23 0 0
6 1 24 0 0
6 1 25 0 0
6 1 26 0 0
6 1 27 0 0
6 1 28 0 0
6 1 29 0 0
6 1 30 0 0
6 1 31 0 0
6 1 32 0 0
6 1 33 0 0
6 1 34 0 0
6 1 35 0 0
6 1 36 0 0
6 1 37 0 0
6 1 38 0 0
6 1 39 0 0
6 1 40 0 0
6 1 41 0 0
6 1 42 0 0
6 1 43 0 0
6 1 44 0 0
6 1 45 0 0
6 1 46 0 0
6 1 47 0 0
6 1 48 0 0
6 1 49 0 0
6 1 50 0 0
6 1 51 0 0
6 1 52 0 0
6 1 53 0 0
6 1 54 0 0
6 1 55 0 0
6 1 56 0 0
6 1 57 0 0
6 1 58 0 0
6 1 59 0 0
6 1 60 0 0
6 1 61 0 0
6 1 62 0 0
6 1 63 0 0
6 1 64 0 0
6 1 65 0 0
6 1 66 0 0
6 1 67 0 0
6 1 68 0 0
6 1 69 0 0
6 1 70 0 0
6 1 71 0 0
6 1 72 0 0
6 1 73 0 0
6 1 74 0 0
6 1 75 0 0
6 1 76 0 0
6 1 77 0 0
6 1 78 0 0
6 1 79 0 0
6 1 80 0 0
6 1 81 0 0
6 1 82 0 0
6 1 83 0 0
6 1 84 0 0
6 1 85 0 0
6 1 86 0 0
6 1 87 0 0
6 1 88 0 0
6 1 89 0 0
6 1 90 0 0
6 1 91 0 0
6 1 92 0 0
6 1 93 0 0
6 1 94 0 0
6 1 95 0 0
6 1 96 0 0
6 1 97 0 0
6 1 98 0 0
6 1 99 0 0
6 1 100 0 0
6 1 101 0 0
6 1 102 0 0
6 1 103 0 0
6 1 104 0 0
6 1 105 0 0
6 1 106 0 0
6 1 107 0 0
6 1 108 0 0
6 1 109 0 0
6 1 110 0 0
6 1 111 0 0
6 1 112 0 0
6 1 113 0 0
6 1 114 0 0
6 1 115 0 0
6 1 116 0 0
6 1 117 0 0
6 1 118 0 0
6 1 119 0 0
6 1 120 0 0
6 1 121 0 0
6 1 122 0 0
6 1 123 0 0
6 1 124 0 0
6 1 125 0 0
6 1 126 0 0
6 1 127 0 0
6 1 128 0 0
6 1 129 0 0
6 1 130 0 0
6 1 131 0 0
6 1 132 0 0
6 1 133 0 0
6 1 134 0 0
6 1 135 0 0
6 1 136 0 0
6 1 137 0 0
6 1 138 0 0
6 1 139 0 0
6 1 140 0 0
6 1 141 0 0
6 1 142 0 0
6 1 143 0 0
6 1 144 0 0
6 1 145 0 0
6 1 146 0 0
6 1 147 0 0
6 1 148 0 0
6 1 149 0 0
6 1 150 0 0
6 1 151 0 0
6 1 152 0 0
6 1 153 0 0
6 1 154 0 0
6 1 155 0 0
6 1 156 0 0
6 1 157 0 0
6 1 158 0 0
6 1 159 0 0
6 1 160 0 0
6 1 161 0 0
6 1 162 0 0
6 1 163 0 0
6 1 164 0 0
6 1 165 0 0
6 1 166 0 0
6 1 167 0 0
6 1 168 0 0
6 1 169 0 0
6 1 170 0 0
6 1 171 0 0
6 1 172 0 0
6 1 173 0 0
6 1 174 0 0
6 1 175 0 0
6 1 176 0 0
6 1 177 0 0
6 1 178 0 0
6 1 179 0 0
6 1 180 0 0
6 1 181 0 0
6 1 182 0 0
6 1 183 0 0
6 1 184 0 0
6 1 185 0 0
6 1 186 0 0
6 1 187 0 0
6 1 188 0 0
6 1 189 0 0
6 1 190 0 0
6 1 191 0 0
6 1 192 0 0
6 1 193 0 0
6 1 194 0 0
6 1 195 0 0
6 1 196 0 0
6 1 197 0 0
6 1 198 0 0
6 1 199 0 0
6 1 200 0 0
6 1 201 0 0
6 1 202 0 0
6 1 203 0 0
6 1 204 0 0
6 1 205 0 0
6 1 206 0 0
6 1 207 0 0
6 1 208 0 0
6 1 209 0 0
6 1 210 0 0
6 1 211 0 0
6 1 212 0 0
6 1 213 0 0
6 1 214 0 0
6 1 215 0 0
6 1 216 0 0
6 1 217 0 0
6 1 218 0 0
6 1 219 0 0
6 1 220 0 0
6 1 221 0 0
6 1 222 0 0
6 1 223 0 0
6 1 224 0 0
6 1 225 0 0
6 1 226 0 0
6 1 227 0 0
6 1 228 0 0
6 1 229 0 0
6 1 230 0 0
6 1 231 0 0
6 1 232 0 0
6 1 233 0 0
6 1 234 0 0
6 1 235 0 0
6 1 236 0 0
6 1 237 0 0
6 1 238 0 0
6 1 239 0 0
6 1 240 0 0
6 1 241 0 0
6 1 242 0 0
6 1 243 0 0
6 1 244 0 0
6 1 245 0 0
6 1 246 0 0
6 1 247 0 0
6 1 248 0 0
6 1 249 0 0
6 1 250 0 0
6 1 251 0 0
6 1 252 0 0
6 1 253 0 0
6 1 254 0 0
6 1 255 0 32
6 2 0 0 64
6 2 1 0 0
6 2 2 0 0
6 2 3 0 0
6 2 4 0 0
6 2 5 0 0
6 2 6 0 0
6 2 7 0 0
6 2 8 0 0
6 2 9 0 0
6 2 10 0 0
6 2 11 0 0
6 2 12 0 0
6 2 13 0 0
6 2 14 0 0
6 2 15 0 0
6 2 16 0 0
6 2 17 0 0
6 2 18 0 0
6 2 19 0 0
6 2 20 0 0
6 2 21 0 0
6 2 22 0 0
6 2 23 0 0
6 2 24 0 0
6 2 25 0 0
6 2 26 0 0
6 2 27 0 0
6 2 28 0 0
6 2 29 0 0
6 2 30 0 0
6 2 31 0 0
6 2 32 0 0
6 2 33 0 0
6 2 34 0 0
6 2 35 0 0
6 2 36 0 0
6 2 37 0 0
6 2 38 0 0
6 2 39 0 0
6 2 40 0 0
6 2 41 0 0
6 2 42 0 0
6 2 43 0 0
6 2 44 0 0
6 2 45 0 0
6 2 46 0 0
6 2 47 0 0
6 2 48 0 0
6 2 49 0 0
6 2 50 0 0
6 2 51 0 0
6 2 52 0 0
6 2 53 0 0
6 2 54 0 0
6 2 55 0 0
6 2 56 0 0
6 2 57 0 0
6 2 58 0 0
6 2 59 0 0
6 2 60 0 0
6 2 61 0 0
6 2 62 0 0
6 2 63 0 0
6 2 64 0 0
6 2 65 0 0
6 2 66 0 0
6 2 67 0 0
6 2 68 0 0
6 2 69 0 0
6 2 70 0 0
6 2 71 0 0
6 2 72 0 0
6 2 73 0 0
6 2 74 0 0
6 2 75 0 0
6 2 76 0 0
6 2 77 0 0
6 2 78 0 0
6 2 79 0 0
6 2 80 0 0
6 2 81 0 0
6 2 82 0 0
6 2 83 0 0
6 2 84 0 0
6 2 85 0 0
6 2 86 0 0
6 2 87 0 0
6 2 88 0 0
6 2 89 0 0
6 2 90 0 0
6 2 91 0 0
6 2 92 0 0
6 2 93 0 0
6 2 94 0 0
6 2 95 0 0
6 2 96 0 0
6 2 97 0 0
6 2 98 0 0
6 2 99 0 0
6 2 100 0 0
6 2 101 0 0
6 2 102 0 0
6 2 103 0 0
6 2 104 0 0
6 2 105 0 0
6 2 106 0 0
6 2 107 0 0
6 2 108 0 0
6 2 109 0 0
6 2 110 0 0
6 2 111 0 0
6 2 112 0 0
6 2 113 0 0
6 2 114 0 0
6 2 115 0 0
6 2 116 0 0
6 2 117 0 0
6 2 118 0 0
6 2 119 0 0
6 2 120 0 0
6 2 121 0 0
6 2 122 0 0
6 2 123 0 0
6 2 124 0 0
6 2 125 0 0
6 2 126 0 0
6 2 127 0 0
6 2 128 0 0
6 2 129 0 0
6 2 130 0 0
6 2 131 0 0
6 2 132 0 0
6 2 133 0 0
6 2 134 0 0
6 2 135 0 0
6 2 136 0 0
6 2 137 0 0
6 2 138 0 0
6 2 139 0 0
6 2 140 0 0
6 2 141 0 0
6 2 142 0 0
6 2 143 0 0
6 2 144 0 0
6 2 145 0 0
6 2 146 0 0
6 2 147 0 0
6 2 148 0 0
6 2 149 0 0
6 2 150 0 0
6 2 151 0 0
6 2 152 0 0
6 2 153 0 0
6 2 154 0 0
6 2 155 0 0
6 2 156 0 0
6 2 157 0 0
6 2 158 0 0
6 2 159 0 0
6 2 160 0 0
6 2 161 0 0
6 2 162 0 0
6 2 163 0 0
6 2 164 0 0
6 2 165 0 0
6 2 166 0 0
6 2 167 0 0
6 2 168 0 0
6 2 169 0 0
6 2 170 0 0
6 2 171 0 0
6 2 172 0 0
6 2 173 0 0
6 2 174 0 0
6 2 175 0 0
6 2 176 0 0
6 2 177 0 0
6 2 178 0 0
6 2 179 0 0
6 2 180 0 0
6 2 181 0 0
6 2 182 0 0
6 2 183 0 0
6 2 184 0 0
6 2 185 0 0
6 2 186 0 0
6 2 187 0 0
6 2 188 0 0
6 2 189 0 0
6 2 190 0 0
6 2 191 0 0
6 2 192 0 0
6 2 193 0 0
6 2 194 0 0
6 2 195 0 0
6 2 196 0 0
6 2 197 0 0
6 2 198 0 0
6 2 199 0 0
6 2 200 0 0
6 2 201 0 0
6 2 202 0 0
6 2 203 0 0
6 2 204 0 0
6 2 205 0 0
6 2 206 0 0
6 2 207 0 0
6 2 208 0 0
6 2 209 0 0
6 2 210 0 0
6 2 211 0 0
6 2 212 0 0
6 2 213 0 0
6 2 214 0 0
6 2 215 0 0
6 2 216 0 0
6 2 217 0 0
6 2 218 0 0
6 2 219 0 0
6 2 220 0 0
6 2 221 0 0
6 2 222 0 0
6 2 223 0 0
6 2 224 0 0
6 2 225 0 0
6 2 226 0 0
6 2 227 0 0
6 2 228 0 0
6 2 229 0 0
6 2 230 0 0
6 2 231 0 0
6 2 232 0 0
6 2 233 0 0
6 2 234 0 0
6 2 235 0 0
6 2 236 0 0
6 2 237 0 0
6 2 238 0 0
6 2 239 0 0
6 2 240 0 0
6 2 241 0 0
6 2 242 0 0
6 2 243 0 0
6 2 244 0 0
6 2 245 0 0
6 2 246 0 0
6 2 247 0 0
6 2 248 0 0
6 2 249 0 0
6 2 250 0 0
6 2 251 0 0
6 2 252 0 0
6 2 253 0 0
6 2 254 0 0
6 2 255 0 32
6 3 0 0 72
6 3 1 0 8
6 3 2 0 8
6 3 3 0 8
6 3 4 0 8
6 3 5 0 8
6 3 6 0 8
6 3 7 0 8
6 3 8 0 8
6 3 9 0 8
6 3 10 0 8
6 3 11 0 8
6 3 12 0 8
6 3 13 0 8
6 3 14 0 8
6 3 15 0 8
6 3 16 0 8
6 3 17 0 8
6 3 18 0 8
6 3 19 0 8
6 3 20 0 8
6 3 21 0 8
6 3 22 0 8
6 3 23 0 8
6 3 24 0 8
6 3 25 0 8
6 3 26 0 8
6 3 27 0 8
6 3 28 0 8
6 3 29 0 8
6 3 30 0 8
6 3 31 0 8
6 3 32 0 8
6 3 33 0 8
6 3 34 0 8
6 3 35 0 8
6 3 36 0 8
6 3 37 0 8
6 3 38 0 8
6 3 39 0 8
6 3 40 0 8
6 3 41 0 8
6 3 42 0 8
6 3 43 0 8
6 3 44 0 8
6 3 45 0 8
6 3 46 0 8
6 3 47 0 8
6 3 48 0 8
6 3 49 0 8
6 3 50 0 8
6 3 51 0 8
6 3 52 0 8
6 3 53 0 8
6 3 54 0 8
6 3 55 0 8
6 3 56 0 8
6 3 57 0 8
6 3 58 0 8
6 3 59 0 8
6 3 60 0 8
6 3 61 0 8
6 3 62 0 8
6 3 63 0 8
6 3 64 0 8
6 3 65 0 8
6 3 66 0 8
6 3 67 0 8
6 3 68 0 8
6 3 69 0 8
6 3 70 0 8
6 3 71 0 8
6 3 72 0 8
6 3 73 0 8
6 3 74 0 8
6 3 75 0 8
6 3 76 0 8
6 3 77 0 8
6 3 78 0 8
6 3 79 0 8
6 3 80 0 8
6 3 81 0 8
6 3 82 0 8
6 3 83 0 8
6 3 84 0 8
6 3 85 0 8
6 3 86 0 8
6 3 87 0 8
6 3 88 0 8
6 3 89 0 8
6 3 90 0 8
6 3 91 0 8
6 3 92 0 8
6 3 93 0 8
6 3 94 0 8
6 3 95 0 8
6 3 96 0 8
6 3 97 0 8
6 3 98 0 8
6 3 99 0 8
6 3 100 0 8
6 3 101 0 8
6 3 102 0 8
6 3 103 0 8
6 3 104 0 8
6 3 105 0 8
6 3 106 0 8
6 3 107 0 8
6 3 108 0 8
6 3 109 0 8
6 3 110 0 8
6 3 111 0 8
6 3 112 0 8
6 3 113 0 8
6 3 114 0 8
6 3 115 0 8
6 3 116 0 8
6 3 117 0 8
6 3 118 0 8
6 3 119 0 8
6 3 120 0 8
6 3 121 0 8
6 3 122 0 8
6 3 123 0 8
6 3 124 0 8
6 3 125 0 8
6 3 126 0 8
6 3 127 0 8
6 3 128 0 8
6 3 129 0 8
6 3 130 0 8
6 3 131 0 8
6 3 132 0 8
6 3 133 0 8
6 3 134 0 8
6 3 135 0 8
6 3 136 0 8
6 3 137 0 8
6 3 138 0 8
6 3 139 0 8
6 3 140 0 8
6 3 141 0 8
6 3 142 0 8
6 3 143 0 8
6 3 144 0 8
6 3 145 0 8
6 3 146 0 8
6 3 147 0 8
6 3 148 0 8
6 3 149 0 8
6 3 150 0 8
6 3 151 0 8
6 3 152 0 8
6 3 153 0 8
6 3 154 0 8
6 3 155 0 8
6 3 156 0 8
6 3 157 0 8
6 3 158 0 8
6 3 159 0 8
6 3 160 0 8
6 3 161 0 8
6 3 162 0 8
6 3 163 0 8
6 3 164 0 8
6 3 165 0 8
6 3 166 0 8
6 3 167 0 8
6 3 168 0 8
6 3 169 0 8
6 3 170 0 8
6 3 171 0 8
6 3 172 0 8
6 3 173 0 8
6 3 174 0 8
6 3 175 0 8
6 3 176 0 8
6 3 177 0 8
6 3 178 0 8
6 3 179 0 8
6 3 180 0 8
6 3 181 0 8
6 3 182 0 8
6 3 183 0 8
6 3 184 0 8
6 3 185 0 8
6 3 186 0 8
6 3 187 0 8
6 3 188 0 8
6 3 189 0 8
6 3 190 0 8
6 3 191 0 8
6 3 192 0 8
6 3 193 0 8
6 3 194 0 8
6 3 195 0 8
6 3 196 0 8
6 3 197 0 8
6 3 198 0 8
6 3 199 0 8
6 3 200 0 8
6 3 201 0 8
6 3 202 0 8
6 3 203 0 8
6 3 204 0 8
6 3 205 0 8
6 3 206 0 8
6 3 207 0 8
6 3 208 0 8
6 3 209 0 8
6 3 210 0 8
6 3 211 0 8
6 3 212 0 8
6 3 213 0 8
6 3 214 0 8
6 3 215 0 8
6 3 216 0 8
6 3 217 0 8
6 3 218 0 8
6 3 219 0 8
6 3 220 0 8
6 3 221 0 8
6 3 222 0 8
6 3 223 0 8
6 3 224 0 8
6 3 225 0 8
6 3 226 0 8
6 3 227 0 8
6 3 228 0 8
6 3 229 0 8
6 3 230 0 8
6 3 231 0 8
6 3 232 0 8
6 3 233 0 8
6 3 234 0 8
6 3 235 0 8
6 3 236 0 8
6 3 237 0 8
6 3 238 0 8
6 3 239 0 8
6 3 240 0 8
6 3 241 0 8
6 3 242 0 8
6 3 243 0 8
6 3 244 0 8
6 3 245 0 8
6 3 246 0 8
6 3 247 0 8
6 3 248 0 8
6 3 249 0 8
6 3 250 0 8
6 3 251 0 8
6 3 252 0 8
6 3 253 0 8
6 3 254 0 8
6 3 255 0 40
7 0 0 0 80
7 0 1 0 16
7 0 2 0 16
7 0 3 0 16
7 0 4 0 16
7 0 5 0 16
7 0 6 0 16
7 0 7 0 16
7 0 8 0 16
7 0 9 0 16
7 0 10 0 16
7 0 11 0 16
7 0 12 0 16
7 0 13 0 16
7 0 14 0 16
7 0 15 0 16
7 0 16 0 16
7 0 17 0 16
7 0 18 0 16
7 0 19 0 16
7 0 20 0 16
7 0 21 0 16
7 0 22 0 16
7 0 23 0 16
7 0 24 0 16
7 0 25 0 16
7 0 26 0 16
7 0 27 0 16
7 0 28 0 16
7 0 29 0 16
7 0 30 0 16
7 0 31 0 16
7 0 32 0 16
7 0 33 0 16
7 0 34 0 16
7 0 35 0 16
7 0 36 0 16
7 0 37 0 16
7 0 38 0 16
7 0 39 0 16
7 0 40 0 16
7 0 41 0 16
7 0 42 0 16
7 0 43 0 16
7 0 44 0 16
7 0 45 0 16
7 0 46 0 16
7 0 47 0 16
7 0 48 0 16
7 0 49 0 16
7 0 50 0 16
7 0 51 0 16
7 0 52 0 16
7 0 53 0 16
7 0 54 0 16
7 0 55 0 16
7 0 56 0 16
7 0 57 0 16
7 0 58 0 16
7 0 59 0 16
7 0 60 0 16
7 0 61 0 16
7 0 62 0 16
7 0 63 0 16
7 0 64 0 16
7 0 65 0 16
7 0 66 0 16
7 0 67 0 16
7 0 68 0 16
7 0 69 0 16
7 0 70 0 16
7 0 71 0 16
7 0 72 0 16
7 0 73 0 16
7 0 74 0 16
7 0 75 0 16
7 0 76 0 16
7 0 77 0 16
7 0 78 0 16
7 0 79 0 16
7 0 80 0 16
7 0 81 0 16
7 0 82 0 16
7 0 83 0 16
7 0 84 0 16
7 0 85 0 16
7 0 86 0 16
7 0 87 0 16
7 0 88 0 16
7 0 89 0 16
7 0 90 0 16
7 0 91 0 16
7 0 92 0 16
7 0 93 0 16
7 0 94 0 16
7 0 95 0 16
7 0 96 0 16
7 0 97 0 16
7 0 98 0 16
7 0 99 0 16
7 0 100 0 16
7 0 101 0 16
7 0 102 0 16
7 0 103 0 16
7 0 104 0 16
7 0 105 0 16
7 0 106 0 16
7 0 107 0 16
7 0 108 0 16
7 0 109 0 16
7 0 110 0 16
7 0 111 0 16
7 0 112 0 16
7 0 113 0 16
7 0 114 0 16
7 0 115 0 16
7 0 116 0 16
7 0 117 0 16
7 0 118 0 16
7 0 119 0 16
7 0 120 0 16
7 0 121 0 16
7 0 122 0 16
7 0 123 0 16
7 0 124 0 16
7 0 125 0 16
7 0 126 0 16
7 0 127 0 16
7 0 128 0 16
7 0 129 0 16
7 0 130 0 16
7 0 131 0 16
7 0 132 0 16
7 0 133 0 16
7 0 134 0 16
7 0 135 0 16
7 0 136 0 16
7 0 137 0 16
7 0 138 0 16
7 0 139 0 16
7 0 140 0 16
7 0 141 0 16
7 0 142 0 16
7 0 143 0 16
7 0 144 0 16
7 0 145 0 16
7 0 146 0 16
7 0 147 0 16
7 0 148 0 16
7 0 149 0 16
7 0 150 0 16
7 0 151 0 16
7 0 152 0 16
7 0 153 0 16
7 0 154 0 16
7 0 155 0 16
7 0 156 0 16
7 0 157 0 16
7 0 158 0 16
7 0 159 0 16
7 0 160 0 16
7 0 161 0 16
7 0 162 0 16
7 0 163 0 16
7 0 164 0 16
7 0 165 0 16
7 0 166 0 16
7 0 167 0 16
7 0 168 0 16
7 0 169 0 16
7 0 170 0 16
7 0 171 0 16
7 0 172 0 16
7 0 173 0 16
7 0 174 0 16
7 0 175 0 16
7 0 176 0 16
7 0 177 0 16
7 0 178 0 16
7 0 179 0 16
7 0 180 0 16
7 0 181 0 16
7 0 182 0 16
7 0 183 0 16
7 0 184 0 16
7 0 185 0 16
7 0 186 0 16
7 0 187 0 16
7 0 188 0 16
7 0 189 0 16
7 0 190 0 16
7 0 191 0 16
7 0 192 0 16
7 0 193 0 16
7 0 194 0 16
7 0 195 0 16
7 0 196 0 16
7 0 197 0 16
7 0 198 0 16
7 0 199 0 16
7 0 200 0 16
7 0 201 0 16
7 0 202 0 16
7 0 203 0 16
7 0 204 0 16
7 0 205 0 16
7 0 206 0 16
7 0 207 0 16
7 0 208 0 16
7 0 209 0 16
7 0 210 0 16
7 0 211 0 16
7 0 212 0 16
7 0 213 0 16
7 0 214 0 16
7 0 215 0 16
7 0 216 0 16
7 0 217 0 16
7 0 218 0 16
7 0 219 0 16
7 0 220 0 16
7 0 221 0 16
7 0 222 0 16
7 0 223 0 16
7 0 224 0 16
7 0 225 0 16
7 0 226 0 16
7 0 227 0 16
7 0 228 0 16
7 0 229 0 16
7 0 230 0 16
7 0 231 0 16
7 0 232 0 16
7 0 233 0 16
7 0 234 0 16
7 0 235 0 16
7 0 236 0 16
7 0 237 0 16
7 0 238 0 16
7 0 239 0 16
7 0 240 0 16
7 0 241 0 16
7 0 242 0 16
7 0 243 0 16
7 0 244 0 16
7 0 245 0 16
7 0 246 0 16
7 0 247 0 16
7 0 248 0 16
7 0 249 0 16
7 0 250 0 16
7 0 251 0 16
7 0 252 0 16
7 0 253 0 16
7 0 254 0 16
7 0 255 0 48
7 1 0 0 64
7 1 1 0 0
7 1 2 0 0
7 1 3 0 0
7 1 4 0 0
7 1 5 0 0
7 1 6 0 0
7 1 7 0 0
7 1 8 0 0
7 1 9 0 0
7 1 10 0 0
7 1 11 0 0
7 1 12 0 0
7 1 13 0 0
7 1 14 0 0
7 1 15 0 0
7 1 16 0 0
7 1 17 0 0
7 1 18 0 0
7 1 19 0 0
7 1 20 0 0
7 1 21 0 0
7 1 22 0 0
7 1 23 0 0
7 1 24 0 0
7 1 25 0 0
7 1 26 0 0
7 1 27 0 0
7 1 28 0 0
7 1 29 0 0
7 1 30 0 0
7 1 31 0 0
7 1 32 0 0
7 1 33 0 0
7 1 34 0 0
7 1 35 0 0
7 1 36 0 0
7 1 37 0 0
7 1 38 0 0
7 1 39 0 0
7 1 40 0 0
7 1 41 0 0
7 1 42 0 0
7 1 43 0 0
7 1 44 0 0
7 1 45 0 0
7 1 46 0 0
7 1 47 0 0
7 1 48 0 0
7 1 49 0 0
7 1 50 0 0
7 1 51 0 0
7 1 52 0 0
7 1 53 0 0
7 1 54 0 0
7 1 55 0 0
7 1 56 0 0
7 1 57 0 0
7 1 58 0 0
7 1 59 0 0
7 1 60 0 0
7 1 61 0 0
7 1 62 0 0
7 1 63 0 0
7 1 64 0 0
7 1 65 0 0
7 1 66 0 0
7 1 67 0 0
7 1 68 0 0
7 1 69 0 0
7 1 70 0 0
7 1 71 0 0
7 1 72 0 0
7 1 73 0 0
7 1 74 0 0
7 1 75 0 0
7 1 76 0 0
7 1 77 0 0
7 1 78 0 0
7 1 79 0 0
7 1 80 0 0
7 1 81 0 0
7 1 82 0 0
7 1 83 0 0
7 1 84 0 0
7 1 85 0 0
7 1 86 0 0
7 1 87 0 0
7 1 88 0 0
7 1 89 0 0
7 1 90 0 0
7 1 91 0 0
7 1 92 0 0
7 1 93 0 0
7 1 94 0 0
7 1 95 0 0
7 1 96 0 0
7 1 97 0 0
7 1 98 0 0
7 1 99 0 0
7 1 100 0 0
7 1 101 0 0
7 1 102 0 0
7 1 103 0 0
7 1 104 0 0
7 1 105 0 0
7 1 106 0 0
7 1 107 0 0
7 1 108 0 0
7 1 109 0 0
7 1 110 0 0
7 1 111 0 0
7 1 112 0 0
7 1 113 0 0
7 1 114 0 0
7 1 115 0 0
7 1 116 0 0
7 1 117 0 0
7 1 118 0 0
7 1 119 0 0
7 1 120 0 0
7 1 121 0 0
7 1 122 0 0
7 1 123 0 0
7 1 124 0 0
7 1 125 0 0
7 1 126 0 0
7 1 127 0 0
7 1 128 0 0
7 1 129 0 0
7 1 130 0 0
7 1 131 0 0
7 1 132 0 0
7 1 133 0 0
7 1 134 0 0
7 1 135 0 0
7 1 136 0 0
7 1 137 0 0
7 1 138 0 0
7 1 139 0 0
7 1 140 0 0
7 1 141 0 0
7 1 142 0 0
7 1 143 0 0
7 1 144 0 0
7 1 145 0 0
7 1 146 0 0
7 1 147 0 0
7 1 148 0 0
7 1 149 0 0
7 1 150 0 0
7 1 151 0 0
7 1 152 0 0
7 1 153 0 0
7 1 154 0 0
7 1 155 0 0
7 1 156 0 0
7 1 157 0 0
7 1 158 0 0
7 1 159 0 0
7 1 160 0 0
7 1 161 0 0
7 1 162 0 0
7 1 163 0 0
7 1 164 0 0
7 1 165 0 0
7 1 166 0 0
7 1 167 0 0
7 1 168 0 0
7 1 169 0 0
7 1 170 0 0
7 1 171 0 0
7 1 172 0 0
7 1 173 0 0
7 1 174 0 0
7 1 175 0 0
7 1 176 0 0
7 1 177 0 0
7 1 178 0 0
7 1 179 0 0
7 1 180 0 0
7 1 181 0 0
7 1 182 0 0
7 1 183 0 0
7 1 184 0 0
7 1 185 0 0
7 1 186 0 0
7 1 187 0 0
7 1 188 0 0
7 1 189 0 0
7 1 190 0 0
7 1 191 0 0
7 1 192 0 0
7 1 193 0 0
7 1 194 0 0
7 1 195 0 0
7 1 196 0 0
7 1 197 0 0
7 1 198 0 0
7 1 199 0 0
7 1 200 0 0
7 1 201 0 0
7 1 202 0 0
7 1 203 0 0
7 1 204 0 0
7 1 205 0 0
7 1 206 0 0
7 1 207 0 0
7 1 208 0 0
7 1 209 0 0
7 1 210 0 0
7 1 211 0 0
7 1 212 0 0
7 1 213 0 0
7 1 214 0 0
7 1 215 0 0
7 1 216 0 0
7 1 217 0 0
7 1 218 0 0
7 1 219 0 0
7 1 220 0 0
7 1 221 0 0
7 1 222 0 0
7 1 223 0 0
7 1 224 0 0
7 1 225 0 0
7 1 226 0 0
7 1 227 0 0
7 1 228 0 0
7 1 229 0 0
7 1 230 0 0
7 1 231 0 0
7 1 232 0 0
7 1 233 0 0
7 1 234 0 0
7 1 235 0 0
7 1 236 0 0
7 1 237 0 0
7 1 238 0 0
7 1 239 0 0
7 1 240 0 0
7 1 241 0 0
7 1 242 0 0
7 1 243 0 0
7 1 244 0 0
7 1 245 0 0
7 1 246 0 0
7 1 247 0 0
7 1 248 0 0
7 1 249 0 0
7 1 250 0 0
7 1 251 0 0
7 1 252 0 0
7 1 253 0 0
7 1 254 0 0
7 1 255 0 32
7 2 0 0 64
7 2 1 0 0
7 2 2 0 0
7 2 3 0 0
7 2 4 0 0
7 2 5 0 0
7 2 6 0 0
7 2 7 0 0
7 2 8 0 0
7 2 9 0 0
7 2 10 0 0
7 2 11 0 0
7 2 12 0 0
7 2 13 0 0
7 2 14 0 0
7 2 15 0 0
7 2 16 0 0
7 2 17 0 0
7 2 18 0 0
7 2 19 0 0
7 2 20 0 0
7 2 21 0 0
7 2 22 0 0
7 2 23 0 0
7 2 24 0 0
7 2 25 0 0
7 2 26 0 0
7 2 27 0 0
7 2 28 0 0
7 2 29 0 0
7 2 30 0 0
7 2 31 0 0
7 2 32 0 0
7 2 33 0 0
7 2 34 0 0
7 2 35 0 0
7 2 36 0 0
7 2 37 0 0
7 2 38 0 0
7 2 39 0 0
7 2 40 0 0
7 2 41 0 0
7 2 42 0 0
7 2 43 0 0
7 2 44 0 0
7 2 45 0 0
7 2 46 0 0
7 2 47 0 0
7 2 48 0 0
7 2 49 0 0
7 2 50 0 0
7 2 51 0 0
7 2 52 0 0
7 2 53 0 0
7 2 54 0 0
7 2 55 0 0
7 2 56 0 0
7 2 57 0 0
7 2 58 0 0
7 2 59 0 0
7 2 60 0 0
7 2 61 0 0
7 2 62 0 0
7 2 63 0 0
7 2 64 0 0
7 2 65 0 0
7 2 66 0 0
7 2 67 0 0
7 2 68 0 0
7 2 69 0 0
7 2 70 0 0
7 2 71 0 0
7 2 72 0 0
7 2 73 0 0
7 2 74 0 0
7 2 75 0 0
7 2 76 0 0
7 2 77 0 0
7 2 78 0 0
7 2 79 0 0
7 2 80 0 0
7 2 81 0 0
7 2 82 0 0
7 2 83 0 0
7 2 84 0 0
7 2 85 0 0
7 2 86 0 0
7 2 87 0 0
7 2 88 0 0
7 2 89 0 0
7 2 90 0 0
7 2 91 0 0
7 2 92 0 0
7 2 93 0 0
7 2 94 0 0
7 2 95 0 0
7 2 96 0 0
7 2 97 0 0
7 2 98 0 0
7 2 99 0 0
7 2 100 0 0
7 2 101 0 0
7 2 102 0 0
7 2 103 0 0
7 2 104 0 0
7 2 105 0 0
7 2 106 0 0
7 2 107 0 0
7 2 108 0 0
7 2 109 0 0
7 2 110 0 0
7 2 111 0 0
7 2 112 0 0
7 2 113 0 0
7 2 114 0 0
7 2 115 0 0
7 2 116 0 0
7 2 117 0 0
7 2 118 0 0
7 2 119 0 0
7 2 120 0 0
7 2 121 0 0
7 2 122 0 0
7 2 123 0 0
7 2 124 0 0
7 2 125 0 0
7 2 126 0 0
7 2 127 0 0
7 2 128 0 0
7 2 129 0 0
7 2 130 0 0
7 2 131 0 0
7 2 132 0 0
7 2 133 0 0
7 2 134 0 0
7 2 135 0 0
7 2 136 0 0
7 2 137 0 0
7 2 138 0 0
7 2 139 0 0
7 2 140 0 0
7 2 141 0 0
7 2 142 0 0
7 2 143 0 0
7 2 144 0 0
7 2 145 0 0
7 2 146 0 0
7 2 147 0 0
7 2 148 0 0
7 2 149 0 0
7 2 150 0 0
7 2 151 0 0
7 2 152 0 0
7 2 153 0 0
7 2 154 0 0
7 2 155 0 0
7 2 156 0 0
7 2 157 0 0
7 2 158 0 0
7 2 159 0 0
7 2 160 0 0
7 2 161 0 0
7 2 162 0 0
7 2 163 0 0
7 2 164 0 0
7 2 165 0 0
7 2 166 0 0
7 2 167 0 0
7 2 168 0 0
7 2 169 0 0
7 2 170 0 0
7 2 171 0 0
7 2 172 0 0
7 2 173 0 0
7 2 174 0 0
7 2 175 0 0
7 2 176 0 0
7 2 177 0 0
7 2 178 0 0
7 2 179 0 0
7 2 180 0 0
7 2 181 0 0
7 2 182 0 0
7 2 183 0 0
7 2 184 0 0
7 2 185 0 0
7 2 186 0 0
7 2 187 0 0
7 2 188 0 0
7 2 189 0 0
7 2 190 0 0
7 2 191 0 0
7 2 192 0 0
7 2 193 0 0
7 2 194 0 0
7 2 195 0 0
7 2 196 0 0
7 2 197 0 0
7 2 198 0 0
7 2 199 0 0
7 2 200 0 0
7 2 201 0 0
7 2 202 0 0
7 2 203 0 0
7 2 204 0 0
7 2 205 0 0
7 2 206 0 0
7 2 207 0 0
7 2 208 0 0
7 2 209 0 0
7 2 210 0 0
7 2 211 0 0
7 2 212 0 0
7 2 213 0 0
7 2 214 0 0
7 2 215 0 0
7 2 216 0 0
7 2 217 0 0
7 2 218 0 0
7 2 219 0 0
7 2 220 0 0
7 2 221 0 0
7 2 222 0 0
7 2 223 0 0
7 2 224 0 0
7 2 225 0 0
7 2 226 0 0
7 2 227 0 0
7 2 228 0 0
7 2 229 0 0
7 2 230 0 0
7 2 231 0 0
7 2 232 0 0
7 2 233 0 0
7 2 234 0 0
7 2 235 0 0
7 2 236 0 0
7 2 237 0 0
7 2 238 0 0
7 2 239 0 0
7 2 240 0 0
7 2 241 0 0
7 2 242 0 0
7 2 243 0 0
7 2 244 0 0
7 2 245 0 0
7 2 246 0 0
7 2 247 0 0
7 2 248 0 0
7 2 249 0 0
7 2 250 0 0
7 2 251 0 0
7 2 252 0 0
7 2 253 0 0
7 2 254 0 0
7 2 255 0 32
7 3 0 0 72
7 3 1 0 8
7 3 2 0 8
7 3 3 0 8
7 3 4 0 8
7 3 5 0 8
7 3 6 0 8
7 3 7 0 8
7 3 8 0 8
7 3 9 0 8
7 3 10 0 8
7 3 11 0 8
7 3 12 0 8
7 3 13 0 8
7 3 14 0 8
7 3 15 0 8
7 3 16 0 8
7 3 17 0 8
7 3 18 0 8
7 3 19 0 8
7 3 20 0 8
7 3 21 0 8
7 3 22 0 8
7 3 23 0 8
7 3 24 0 8
7 3 25 0 8
7 3 26 0 8
7 3 27 0 8
7 3 28 0 8
7 3 29 0 8
7 3 30 0 8
7 3 31 0 8
7 3 32 0 8
7 3 33 0 8
7 3 34 0 8
7 3 35 0 8
7 3 36 0 8
7 3 37 0 8
7 3 38 0 8
7 3 39 0 8
7 3 40 0 8
7 3 41 0 8
7 3 42 0 8
7 3 43 0 8
7 3 44 0 8
7 3 45 0 8
7 3 46 0 8
7 3 47 0 8
7 3 48 0 8
7 3 49 0 8
7 3 50 0 8
7 3 51 0 8
7 3 52 0 8
7 3 53 0 8
7 3 54 0 8
7 3 55 0 8
7 3 56 0 8
7 3 57 0 8
7 3 58 0 8
7 3 59 0 8
7 3 60 0 8
7 3 61 0 8
7 3 62 0 8
7 3 63 0 8
7 3 64 0 8
7 3 65 0 8
7 3 66 0 8
7 3 67 0 8
7 3 68 0 8
7 3 69 0 8
7 3 70 0 8
7 3 71 0 8
7 3 72 0 8
7 3 73 0 8
7 3 74 0 8
7 3 75 0 8
7 3 76 0 8
7 3 77 0 8
7 3 78 0 8
7 3 79 0 8
7 3 80 0 8
7 3 81 0 8
7 3 82 0 8
7 3 83 0 8
7 3 84 0 8
7 3 85 0 8
7 3 86 0 8
7 3 87 0 8
7 3 88 0 8
7 3 89 0 8
7 3 90 0 8
7 3 91 0 8
7 3 92 0 8
7 3 93 0 8
7 3 94 0 8
7 3 95 0 8
7 3 96 0 8
7 3 97 0 8
7 3 98 0 8
7 3 99 0 8
7 3 100 0 8
7 3 101 0 8
7 3 102 0 8
7 3 103 0 8
7 3 104 0 8
7 3 105 0 8
7 3 106 0 8
7 3 107 0 8
7 3 108 0 8
7 3 109 0 8
7 3 110 0 8
7 3 111 0 8
7 3 112 0 8
7 3 113 0 8
7 3 114 0 8
7 3 115 0 8
7 3 116 0 8
7 3 117 0 8
7 3 118 0 8
7 3 119 0 8
7 3 120 0 8
7 3 121 0 8
7 3 122 0 8
7 3 123 0 8
7 3 124 0 8
7 3 125 0 8
7 3 126 0 8
7 3 127 0 8
7 3 128 0 8
7 3 129 0 8
7 3 130 0 8
7 3 131 0 8
7 3 132 0 8
7 3 133 0 8
7 3 134 0 8
7 3 135 0 8
7 3 136 0 8
7 3 137 0 8
7 3 138 0 8
7 3 139 0 8
7 3 140 0 8
7 3 141 0 8
7 3 142 0 8
7 3 143 0 8
7 3 144 0 8
7 3 145 0 8
7 3 146 0 8
7 3 147 0 8
7 3 148 0 8
7 3 149 0 8
7 3 150 0 8
7 3 151 0 8
7 3 152 0 8
7 3 153 0 8
7 3 154 0 8
7 3 155 0 8
7 3 156 0 8
7 3 157 0 8
7 3 158 0 8
7 3 159 0 8
7 3 160 0 8
7 3 161 0 8
7 3 162 0 8
7 3 163 0 8
7 3 164 0 8
7 3 165 0 8
7 3 166 0 8
7 3 167 0 8
7 3 168 0 8
7 3 169 0 8
7 3 170 0 8
7 3 171 0 8
7 3 172 0 8
7 3 173 0 8
7 3 174 0 8
7 3 175 0 8
7 3 176 0 8
7 3 177 0 8
7 3 178 0 8
7 3 179 0 8
7 3 180 0 8
7 3 181 0 8
7 3 182 0 8
7 3 183 0 8
7 3 184 0 8
7 3 185 0 8
7 3 186 0 8
7 3 187 0 8
7 3 188 0 8
7 3 189 0 8
7 3 190 0 8
7 3 191 0 8
7 3 192 0 8
7 3 193 0 8
7 3 194 0 8
7 3 195 0 8
7 3 196 0 8
7 3 197 0 8
7 3 198 0 8
7 3 199 0 8
7 3 200 0 8
7 3 201 0 8
7 3 202 0 8
7 3 203 0 8
7 3 204 0 8
7 3 205 0 8
7 3 206 0 8
7 3 207 0 8
7 3 208 0 8
7 3 209 0 8
7 3 210 0 8
7 3 211 0 8
7 3 212 0 8
7 3 213 0 8
7 3 214 0 8
7 3 215 0 8
7 3 216 0 8
7 3 217 0 8
7 3 218 0 8
7 3 219 0 8
7 3 220 0 8
7 3 221 0 8
7 3 222 0 8
7 3 223 0 8
7 3 224 0 8
7 3 225 0 8
7 3 226 0 8
7 3 227 0 8
7 3 228 0 8
7 3 229 0 8
7 3 230 0 8
7 3 231 0 8
7 3 232 0 8
7 3 233 0 8
7 3 234 0 8
7 3 235 0 8
7 3 236 0 8
7 3 237 0 8
7 3 238 0 8
7 3 239 0 8
7 3 240 0 8
7 3 241 0 8
7 3 242 0 8
7 3 243 0 8
7 3 244 0 8
7 3 245 0 8
7 3 246 0 8
7 3 247 0 8
7 3 248 0 8
7 3 249 0 8
7 3 250 0 8
7 3 251 0 8
7 3 252 0 8
7 3 253 0 8
7 3 254 0 8
7 3 255 0 40
8 0 0 0 80
8 0 1 0 16
8 0 2 0 16
8 0 3 0 16
8 0 4 0 16
8 0 5 0 16
8 0 6 0 16
8 0 7 0 16
8 0 8 0 16
8 0 9 0 16
8 0 10 0 16
8 0 11 0 16
8 0 12 0 16
8 0 13 0 16
8 0 14 0 16
8 0 15 0 16
8 0 16 0 16
8 0 17 0 16
8 0 18 0 16
8 0 19 0 16
8 0 20 0 16
8 0 21 0 16
8 0 22 0 16
8 0 23 0 16
8 0 24 0 16
8 0 25 0 16
8 0 26 0 16
8 0 27 0 16
8 0 28 0 16
8 0 29 0 16
8 0 30 0 16
8 0 31 0 16
8 0 32 0 16
8 0 33 0 16
8 0 34 0 16
8 0 35 0 16
8 0 36 0 16
8 0 37 0 16
8 0 38 0 16
8 0 39 0 16
8 0 40 0 16
8 0 41 0 16
8 0 42 0 16
8 0 43 0 16
8 0 44 0 16
8 0 45 0 16
8 0 46 0 16
8 0 47 0 16
8 0 48 0 16
8 0 49 0 16
8 0 50 0 16
8 0 51 0 16
8 0 52 0 16
8 0 53 0 16
8 0 54 0 16
8 0 55 0 16
8 0 56 0 16
8 0 57 0 16
8 0 58 0 16
8 0 59 0 16
8 0 60 0 16
8 0 61 0 16
8 0 62 0 16
8 0 63 0 16
8 0 64 0 16
8 0 65 0 16
8 0 66 0 16
8 0 67 0 16
8 0 68 0 16
8 0 69 0 16
8 0 70 0 16
8 0 71 0 16
8 0 72 0 16
8 0 73 0 16
8 0 74 0 16
8 0 75 0 16
8 0 76 0 16
8 0 77 0 16
8 0 78 0 16
8 0 79 0 16
8 0 80 0 16
8 0 81 0 16
8 0 82 0 16
8 0 83 0 16
8 0 84 0 16
8 0 85 0 16
8 0 86 0 16
8 0 87 0 16
8 0 88 0 16
8 0 89 0 16
8 0 90 0 16
8 0 91 0 16
8 0 92 0 16
8 0 93 0 16
8 0 94 0 16
8 0 95 0 16
8 0 96 0 16
8 0 97 0 16
8 0 98 0 16
8 0 99 0 16
8 0 100 0 16
8 0 101 0 16
8 0 102 0 16
8 0 103 0 16
8 0 104 0 16
8 0 105 0 16
8 0 106 0 16
8 0 107 0 16
8 0 108 0 16
8 0 109 0 16
8 0 110 0 16
8 0 111 0 16
8 0 112 0 16
8 0 113 0 16
8 0 114 0 16
8 0 115 0 16
8 0 116 0 16
8 0 117 0 16
8 0 118 0 16
8 0 119 0 16
8 0 120 0 16
8 0 121 0 16
8 0 122 0 16
8 0 123 0 16
8 0 124 0 16
8 0 125 0 16
8 0 126 0 16
8 0 127 0 16
8 0 128 0 16
8 0 129 0 16
8 0 130 0 16
8 0 131 0 16
8 0 132 0 16
8 0 133 0 16
8 0 134 0 16
8 0 135 0 16
8 0 136 0 16
8 0 137 0 16
8 0 138 0 16
8 0 139 0 16
8 0 140 0 16
8 0 141 0 16
8 0 142 0 16
8 0 143 0 16
8 0 144 0 16
8 0 145 0 16
8 0 146 0 16
8 0 147 0 16
8 0 148 0 16
8 0 149 0 16
8 0 150 0 16
8 0 151 0 16
8 0 152 0 16
8 0 153 0 16
8 0 154 0 16
8 0 155 0 16
8 0 156 0 16
8 0 157 0 16
8 0 158 0 16
8 0 159 0 16
8 0 160 0 16
8 0 161 0 16
8 0 162 0 16
8 0 163 0 16
8 0 164 0 16
8 0 165 0 16
8 0 166 0 16
8 0 167 0 16
8 0 168 0 16
8 0 169 0 16
8 0 170 0 16
8 0 171 0 16
8 0 172 0 16
8 0 173 0 16
8 0 174 0 16
8 0 175 0 16
8 0 176 0 16
8 0 177 0 16
8 0 178 0 16
8 0 179 0 16
8 0 180 0 16
8 0 181 0 16
8 0 182 0 16
8 0 183 0 16
8 0 184 0 16
8 0 185 0 16
8 0 186 0 16
8 0 187 0 16
8 0 188 0 16
8 0 189 0 16
8 0 190 0 16
8 0 191 0 16
8 0 192 0 16
8 0 193 0 16
8 0 194 0 16
8 0 195 0 16
8 0 196 0 16
8 0 197 0 16
8 0 198 0 16
8 0 199 0 16
8 0 200 0 16
8 0 201 0 16
8 0 202 0 16
8 0 203 0 16
8 0 204 0 16
8 0 205 0 16
8 0 206 0 16
8 0 207 0 16
8 0 208 0 16
8 0 209 0 16
8 0 210 0 16
8 0 211 0 16
8 0 212 0 16
8 0 213 0 16
8 0 214 0 16
8 0 215 0 16
8 0 216 0 16
8 0 217 0 16
8 0 218 0 16
8 0 219 0 16
8 0 220 0 16
