Qubicle Exchange Format
Version 0.2
www.minddesk.com
19 33 10
6
0.682353 0.407843 0.301961
0.705882 0.309804 0.309804
0.858824 0.470588 0.470588
0.909804 0.764706 0.603922
1.000000 0.882353 0.752941
1.000000 1.000000 1.000000
0 10 3 3 84
0 10 4 3 20
0 10 5 3 20
0 10 6 3 20
0 10 7 3 20
0 10 8 0 52
0 11 3 3 68
0 11 4 3 4
0 11 5 3 4
0 11 6 3 4
0 11 7 3 4
0 11 8 0 36
0 12 3 3 68
0 12 4 3 4
0 12 5 3 4
0 12 6 3 12
0 12 7 3 12
0 12 8 0 36
0 13 3 3 68
0 13 4 3 4
0 13 5 3 36
0 13 8 0 108
0 14 3 3 76
0 14 4 3 12
0 14 5 3 44
1 10 3 3 80
1 10 4 3 16
1 10 5 3 16
1 10 6 3 16
1 10 7 3 16
1 10 8 0 48
1 11 3 3 64
1 11 4 3 0
1 11 5 3 0
1 11 6 3 0
1 11 7 3 0
1 11 8 0 32
1 12 3 3 64
1 12 4 3 0
1 12 5 3 0
1 12 6 3 8
1 12 7 3 8
1 12 8 0 32
1 13 3 3 64
1 13 4 3 0
1 13 5 3 32
1 13 8 0 104
1 14 3 3 72
1 14 4 3 8
1 14 5 3 40
2 10 3 3 82
2 10 4 3 18
2 10 5 3 18
2 10 6 3 18
2 10 7 3 18
2 10 8 0 50
2 11 3 3 66
2 11 4 3 2
2 11 5 3 2
2 11 6 3 2
2 11 7 3 2
2 11 8 0 34
2 12 3 3 64
2 12 4 3 0
2 12 5 3 0
2 12 6 3 10
2 12 7 3 10
2 12 8 0 34
2 13 3 3 64
2 13 4 3 0
2 13 5 3 32
2 13 8 0 106
2 14 3 3 72
2 14 4 3 8
2 14 5 3 40
3 12 3 3 80
3 12 4 3 16
3 12 5 3 48
3 13 3 3 64
3 13 4 3 0
3 13 5 3 32
3 14 3 3 72
3 14 4 3 8
3 14 5 3 40
4 0 4 0 84
4 0 5 0 20
4 0 6 0 20
4 0 7 0 60
4 1 4 0 68
4 1 5 0 4
4 1 6 0 36
4 2 4 3 68
4 2 5 3 4
4 2 6 3 36
4 3 3 4 84
4 3 4 4 4
4 3 5 4 4
4 3 6 4 4
4 3 7 4 20
4 3 8 4 52
4 4 3 4 68
4 4 4 4 4
4 4 5 4 4
4 4 6 4 4
4 4 7 4 4
4 4 8 4 36
4 5 3 4 68
4 5 4 4 4
4 5 5 4 4
4 5 6 4 4
4 5 7 4 4
4 5 8 4 36
4 6 3 4 68
4 6 4 4 4
4 6 5 4 4
4 6 6 4 4
4 6 7 4 4
4 6 8 4 36
4 7 3 4 68
4 7 4 4 4
4 7 5 4 4
4 7 6 4 4
4 7 7 4 4
4 7 8 4 36
4 8 2 4 84
4 8 3 4 4
4 8 4 4 4
4 8 5 4 4
4 8 6 4 4
4 8 7 4 4
4 8 8 4 36
4 9 2 4 68
4 9 3 4 4
4 9 4 4 4
4 9 5 4 4
4 9 6 4 4
4 9 7 4 4
4 9 8 4 36
4 10 2 4 68
4 10 3 4 4
4 10 4 4 4
4 10 5 4 4
4 10 6 4 4
4 10 7 4 4
4 10 8 4 36
4 11 2 4 68
4 11 3 4 4
4 11 4 4 4
4 11 5 4 4
4 11 6 4 4
4 11 7 4 12
4 11 8 4 44
4 12 2 4 68
4 12 3 4 0
4 12 4 4 0
4 12 5 4 0
4 12 6 4 36
4 13 2 4 68
4 13 3 4 0
4 13 4 4 0
4 13 5 4 0
4 13 6 4 36
4 14 2 4 68
4 14 3 4 0
4 14 4 4 0
4 14 5 4 0
4 14 6 4 36
4 15 2 4 68
4 15 3 4 4
4 15 4 4 4
4 15 5 4 4
4 15 6 4 36
4 16 2 4 76
4 16 3 4 4
4 16 4 4 4
4 16 5 4 4
4 16 6 4 4
4 16 7 4 52
4 17 3 4 68
4 17 4 4 4
4 17 5 4 4
4 17 6 4 4
4 17 7 4 36
4 18 3 4 68
4 18 4 4 4
4 18 5 4 4
4 18 6 4 4
4 18 7 4 36
4 19 3 4 68
4 19 4 4 4
4 19 5 4 4
4 19 6 4 4
4 19 7 4 36
4 20 3 4 68
4 20 4 4 4
4 20 5 4 4
4 20 6 4 4
4 20 7 4 36
4 21 3 4 68
4 21 4 4 4
4 21 5 4 4
4 21 6 4 4
4 21 7 4 36
4 22 3 4 68
4 22 4 4 4
4 22 5 4 4
4 22 6 4 4
4 22 7 4 36
4 23 3 4 68
4 23 4 4 4
4 23 5 4 4
4 23 6 4 4
4 23 7 4 36
4 24 3 4 68
4 24 4 4 4
4 24 5 4 4
4 24 6 4 4
4 24 7 4 36
4 25 3 4 76
4 25 4 4 4
4 25 5 4 4
4 25 6 4 4
4 25 7 4 44
4 26 4 0 68
4 26 5 0 4
4 26 6 0 38
4 27 4 0 68
4 27 5 0 4
4 27 6 0 38
4 28 4 0 68
4 28 5 0 4
4 28 6 0 38
4 29 4 0 68
4 29 5 0 4
4 29 6 0 38
4 30 4 0 68
4 30 5 0 4
4 30 6 0 38
4 31 4 0 68
4 31 5 0 4
4 31 6 0 38
4 32 4 0 76
4 32 5 0 12
4 32 6 0 44
5 0 4 0 80
5 0 5 0 16
5 0 6 0 16
5 0 7 0 56
5 1 4 0 64
5 1 5 0 0
5 1 6 0 32
5 2 4 3 64
5 2 5 3 0
5 2 6 3 32
5 3 3 4 80
5 3 4 4 0
5 3 5 4 0
5 3 6 4 0
5 3 7 4 16
5 3 8 4 48
5 4 3 4 64
5 4 4 4 0
5 4 5 4 0
5 4 6 4 0
5 4 7 4 0
5 4 8 4 32
5 5 3 4 64
5 5 4 4 0
5 5 5 4 0
5 5 6 4 0
5 5 7 4 0
5 5 8 4 32
5 6 3 4 64
5 6 4 4 0
5 6 5 4 0
5 6 6 4 0
5 6 7 4 0
5 6 8 4 32
5 7 3 4 64
5 7 4 4 0
5 7 5 4 0
5 7 6 4 0
5 7 7 4 0
5 7 8 4 32
5 8 2 4 80
5 8 3 4 0
5 8 4 4 0
5 8 5 4 0
5 8 6 4 0
5 8 7 4 0
5 8 8 4 32
5 9 2 4 64
5 9 3 4 0
5 9 4 4 0
5 9 5 4 0
5 9 6 4 0
5 9 7 4 0
5 9 8 4 32
5 10 2 4 64
5 10 3 4 0
5 10 4 4 0
5 10 5 4 0
5 10 6 4 0
5 10 7 4 0
5 10 8 4 32
5 11 2 4 64
5 11 3 4 0
5 11 4 4 0
5 11 5 4 0
5 11 6 4 0
5 11 7 4 8
5 11 8 4 40
5 12 2 4 64
5 12 3 4 0
5 12 4 4 0
5 12 5 4 0
5 12 6 4 32
5 13 2 4 64
5 13 3 4 0
5 13 4 4 0
5 13 5 4 0
5 13 6 4 32
5 14 2 4 64
5 14 3 4 0
5 14 4 4 0
5 14 5 4 0
5 14 6 4 32
5 15 2 4 64
5 15 3 4 0
5 15 4 4 0
5 15 5 4 0
5 15 6 4 32
5 16 2 4 72
5 16 3 4 0
5 16 4 4 0
5 16 5 3 0
5 16 6 3 0
5 16 7 3 16
5 16 8 3 52
5 17 3 4 64
5 17 4 4 0
5 17 5 3 0
5 17 6 3 0
5 17 7 3 0
5 17 8 3 38
5 18 3 4 64
5 18 4 4 0
5 18 5 3 0
5 18 6 3 0
5 18 7 3 0
5 18 8 3 38
5 19 3 4 64
5 19 4 4 0
5 19 5 3 0
5 19 6 3 0
5 19 7 3 0
5 19 8 3 38
5 20 3 4 64
5 20 4 4 0
5 20 5 3 0
5 20 6 3 0
5 20 7 3 0
5 20 8 3 36
5 21 3 4 64
5 21 4 4 0
5 21 5 4 0
5 21 6 4 0
5 21 7 4 0
5 21 8 4 36
5 22 3 4 64
5 22 4 4 0
5 22 5 5 0
5 22 6 5 0
5 22 7 5 0
5 22 8 5 36
5 23 3 4 64
5 23 4 4 0
5 23 5 5 0
5 23 6 5 0
5 23 7 5 0
5 23 8 1 36
5 24 3 4 64
5 24 4 4 0
5 24 5 5 0
5 24 6 5 0
5 24 7 5 0
5 24 8 5 44
5 25 3 4 72
5 25 4 4 0
5 25 5 4 0
5 25 6 4 8
5 25 7 4 40
5 26 4 0 64
5 26 5 3 32
5 27 4 0 64
5 27 5 3 32
5 28 4 0 64
5 28 5 3 32
5 29 4 0 64
5 29 5 3 32
5 30 4 0 64
5 30 5 3 32
5 31 4 0 64
5 31 5 3 32
5 32 4 0 72
5 32 5 0 8
5 32 6 0 56
6 0 4 0 82
6 0 5 0 18
6 0 6 0 18
6 0 7 0 58
6 1 4 0 66
6 1 5 0 2
6 1 6 0 34
6 2 4 3 66
6 2 5 3 2
6 2 6 3 34
6 3 3 4 80
6 3 4 4 0
6 3 5 4 0
6 3 6 4 0
6 3 7 4 16
6 3 8 4 48
6 4 3 4 64
6 4 4 4 0
6 4 5 4 0
6 4 6 4 0
6 4 7 4 0
6 4 8 4 32
6 5 3 4 64
6 5 4 4 0
6 5 5 4 0
6 5 6 4 0
6 5 7 4 0
6 5 8 4 32
6 6 3 4 64
6 6 4 4 0
6 6 5 4 0
6 6 6 4 0
6 6 7 4 0
6 6 8 4 32
6 7 3 4 64
6 7 4 4 0
6 7 5 4 0
6 7 6 4 0
6 7 7 4 0
6 7 8 4 32
6 8 2 4 80
6 8 3 4 0
6 8 4 4 0
6 8 5 4 0
6 8 6 4 0
6 8 7 4 0
6 8 8 4 32
6 9 2 4 64
6 9 3 4 0
6 9 4 4 0
6 9 5 4 0
6 9 6 4 0
6 9 7 4 0
6 9 8 4 32
6 10 2 4 64
6 10 3 4 0
6 10 4 4 0
6 10 5 4 0
6 10 6 4 0
6 10 7 4 0
6 10 8 4 32
6 11 2 4 64
6 11 3 4 0
6 11 4 4 0
6 11 5 4 0
6 11 6 4 0
6 11 7 4 8
6 11 8 4 40
6 12 2 4 64
6 12 3 4 0
6 12 4 4 0
6 12 5 4 0
6 12 6 4 32
6 13 2 4 64
6 13 3 4 0
6 13 4 4 0
6 13 5 4 0
6 13 6 4 32
6 14 2 4 64
6 14 3 4 0
6 14 4 4 0
6 14 5 4 0
6 14 6 4 32
6 15 2 4 64
6 15 3 4 0
6 15 4 4 0
6 15 5 4 0
6 15 6 4 32
6 16 2 4 72
6 16 3 4 0
6 16 4 4 0
6 16 5 3 0
6 16 6 3 0
6 16 7 3 16
6 16 8 3 56
6 17 3 4 64
6 17 4 4 0
6 17 5 1 0
6 17 6 1 0
6 17 7 1 32
6 18 3 4 64
6 18 4 4 0
6 18 5 1 0
6 18 6 1 0
6 18 7 1 32
6 19 3 4 64
6 19 4 4 0
6 19 5 1 0
6 19 6 1 0
6 19 7 1 32
6 20 3 4 64
6 20 4 4 0
6 20 5 3 0
6 20 6 3 0
6 20 7 3 0
6 20 8 3 48
6 21 3 4 64
6 21 4 4 0
6 21 5 4 0
6 21 6 4 0
6 21 7 4 0
6 21 8 4 32
6 22 3 4 64
6 22 4 4 0
6 22 5 0 0
6 22 6 0 0
6 22 7 0 0
6 22 8 5 32
6 23 3 4 64
6 23 4 4 0
6 23 5 0 0
6 23 6 0 0
6 23 7 0 0
6 23 8 5 32
6 24 3 4 64
6 24 4 4 0
6 24 5 5 0
6 24 6 5 0
6 24 7 5 0
6 24 8 5 40
6 25 3 4 72
6 25 4 4 0
6 25 5 4 0
6 25 6 4 8
6 25 7 4 40
6 26 4 0 64
6 26 5 3 32
6 27 4 0 64
6 27 5 3 32
6 28 4 0 64
6 28 5 3 32
6 29 4 0 64
6 29 5 3 32
6 30 4 0 64
6 30 5 3 32
6 31 4 0 64
6 31 5 3 32
6 32 4 0 72
6 32 5 0 8
6 32 6 0 56
7 2 0 5 84
7 2 1 5 20
7 2 2 5 52
7 3 0 5 68
7 3 1 5 4
7 3 2 5 4
7 3 3 4 16
7 3 4 4 16
7 3 5 4 16
7 3 6 4 16
7 3 7 4 16
7 3 8 4 48
7 4 0 5 68
7 4 1 5 4
7 4 2 5 4
7 4 3 4 0
7 4 4 4 0
7 4 5 4 0
7 4 6 4 0
7 4 7 4 0
7 4 8 4 32
7 5 0 5 68
7 5 1 5 4
7 5 2 5 4
7 5 3 4 0
7 5 4 4 0
7 5 5 4 0
7 5 6 4 0
7 5 7 4 0
7 5 8 4 32
7 6 0 5 76
7 6 1 5 12
7 6 2 5 12
7 6 3 4 0
7 6 4 4 0
7 6 5 4 0
7 6 6 4 0
7 6 7 4 0
7 6 8 4 32
7 7 3 4 64
7 7 4 4 0
7 7 5 4 0
7 7 6 4 0
7 7 7 4 0
7 7 8 4 32
7 8 2 4 80
7 8 3 4 0
7 8 4 4 0
7 8 5 4 0
7 8 6 4 0
7 8 7 4 0
7 8 8 4 32
7 9 2 4 64
7 9 3 4 0
7 9 4 4 0
7 9 5 4 0
7 9 6 4 0
7 9 7 4 0
7 9 8 4 32
7 10 2 4 64
7 10 3 4 0
7 10 4 4 0
7 10 5 4 0
7 10 6 4 0
7 10 7 4 0
7 10 8 4 32
7 11 2 4 64
7 11 3 4 0
7 11 4 4 0
7 11 5 4 0
7 11 6 4 0
7 11 7 4 8
7 11 8 4 40
7 12 2 4 64
7 12 3 4 0
7 12 4 4 0
7 12 5 4 0
7 12 6 4 32
7 13 2 4 64
7 13 3 4 0
7 13 4 4 0
7 13 5 4 0
7 13 6 4 32
7 14 2 4 64
7 14 3 4 0
7 14 4 4 0
7 14 5 4 0
7 14 6 4 32
7 15 2 4 64
7 15 3 4 0
7 15 4 4 0
7 15 5 4 0
7 15 6 4 32
7 16 2 4 72
7 16 3 4 0
7 16 4 4 0
7 16 5 3 0
7 16 6 3 0
7 16 7 3 16
7 16 8 3 48
7 17 3 4 64
7 17 4 4 0
7 17 5 2 0
7 17 6 2 0
7 17 7 2 0
7 17 8 2 44
7 18 3 4 64
7 18 4 4 0
7 18 5 1 0
7 18 6 1 0
7 18 7 1 32
7 19 3 4 64
7 19 4 4 0
7 19 5 1 0
7 19 6 1 0
7 19 7 1 32
7 20 3 4 64
7 20 4 4 0
7 20 5 3 0
7 20 6 3 0
7 20 7 3 0
7 20 8 3 48
7 21 3 4 64
7 21 4 4 0
7 21 5 4 0
7 21 6 4 0
7 21 7 4 0
7 21 8 4 32
7 22 3 4 64
7 22 4 4 0
7 22 5 5 0
7 22 6 5 0
7 22 7 5 0
7 22 8 5 32
7 23 3 4 64
7 23 4 4 0
7 23 5 5 0
7 23 6 5 0
7 23 7 5 0
7 23 8 5 32
7 24 3 4 64
7 24 4 4 0
7 24 5 5 0
7 24 6 5 0
7 24 7 5 0
7 24 8 5 40
7 25 3 4 72
7 25 4 4 0
7 25 5 4 0
7 25 6 4 0
7 25 7 4 40
7 26 4 0 66
7 26 5 0 2
7 26 6 0 38
7 27 4 0 66
7 27 5 0 2
7 27 6 0 38
7 28 4 0 66
7 28 5 0 2
7 28 6 0 38
7 29 4 0 66
7 29 5 0 2
7 29 6 0 38
7 30 4 0 66
7 30 5 0 2
7 30 6 0 38
7 31 4 0 66
7 31 5 0 2
7 31 6 0 38
7 32 4 0 74
7 32 5 0 10
7 32 6 0 42
8 2 0 5 80
8 2 1 5 16
8 2 2 5 48
8 3 0 5 64
8 3 1 5 0
8 3 2 5 0
8 3 3 4 16
8 3 4 4 16
8 3 5 4 16
8 3 6 4 16
8 3 7 4 16
8 3 8 4 48
8 4 0 5 64
8 4 1 5 0
8 4 2 5 0
8 4 3 4 0
8 4 4 4 0
8 4 5 4 0
8 4 6 4 0
8 4 7 4 0
8 4 8 4 32
8 5 0 5 64
8 5 1 5 0
8 5 2 5 0
8 5 3 4 0
8 5 4 4 0
8 5 5 4 0
8 5 6 4 0
8 5 7 4 0
8 5 8 4 32
8 6 0 5 72
8 6 1 5 8
8 6 2 5 8
8 6 3 4 0
8 6 4 4 0
8 6 5 4 0
8 6 6 4 0
8 6 7 4 0
8 6 8 4 32
8 7 3 4 64
8 7 4 4 0
8 7 5 4 0
8 7 6 4 0
8 7 7 4 0
8 7 8 4 32
8 8 2 4 80
8 8 3 4 0
8 8 4 4 0
8 8 5 4 0
8 8 6 4 0
8 8 7 4 0
8 8 8 4 32
8 9 2 4 64
8 9 3 4 0
8 9 4 4 0
8 9 5 4 0
8 9 6 4 0
8 9 7 4 0
8 9 8 4 32
8 10 2 4 64
8 10 3 4 0
8 10 4 4 0
8 10 5 4 0
8 10 6 4 0
8 10 7 4 0
8 10 8 4 32
8 11 2 4 64
8 11 3 4 0
8 11 4 4 0
8 11 5 4 0
8 11 6 4 0
8 11 7 4 8
8 11 8 4 40
8 12 2 4 64
8 12 3 4 0
8 12 4 4 0
8 12 5 4 0
8 12 6 4 32
8 13 2 4 64
8 13 3 4 0
8 13 4 4 0
8 13 5 4 0
8 13 6 4 32
8 14 2 4 64
8 14 3 4 0
8 14 4 4 0
8 14 5 4 0
8 14 6 4 32
8 15 2 4 64
8 15 3 4 0
8 15 4 4 0
8 15 5 4 0
8 15 6 4 32
8 16 2 4 72
8 16 3 4 0
8 16 4 4 0
8 16 5 3 0
8 16 6 3 0
8 16 7 3 16
8 16 8 3 48
8 17 3 4 64
8 17 4 4 0
8 17 5 2 0
8 17 6 2 0
8 17 7 2 0
8 17 8 2 40
8 18 3 4 64
8 18 4 4 0
8 18 5 1 0
8 18 6 1 0
8 18 7 1 32
8 19 3 4 64
8 19 4 4 0
8 19 5 5 0
8 19 6 5 0
8 19 7 5 0
8 19 8 5 52
8 20 3 4 64
8 20 4 4 0
8 20 5 3 0
8 20 6 3 0
8 20 7 3 0
8 20 8 3 32
8 21 3 4 64
8 21 4 4 0
8 21 5 0 0
8 21 6 0 0
8 21 7 0 0
8 21 8 0 0
8 21 9 0 60
8 22 3 4 64
8 22 4 4 0
8 22 5 3 0
8 22 6 3 0
8 22 7 3 0
8 22 8 3 32
8 23 3 4 64
8 23 4 4 0
8 23 5 3 0
8 23 6 3 0
8 23 7 3 0
8 23 8 3 32
8 24 3 4 64
8 24 4 4 0
8 24 5 3 0
8 24 6 3 0
8 24 7 3 0
8 24 8 3 40
8 25 3 4 72
8 25 4 4 8
8 25 5 4 8
8 25 6 4 8
8 25 7 4 40
9 2 0 5 80
9 2 1 5 16
9 2 2 5 48
9 3 0 5 64
9 3 1 5 0
9 3 2 5 0
9 3 3 4 16
9 3 4 4 16
9 3 5 4 16
9 3 6 4 16
9 3 7 4 16
9 3 8 4 48
9 4 0 5 64
9 4 1 5 0
9 4 2 5 0
9 4 3 4 0
9 4 4 4 0
9 4 5 4 0
9 4 6 4 0
9 4 7 4 0
9 4 8 4 32
9 5 0 5 64
9 5 1 5 0
9 5 2 5 0
9 5 3 4 0
9 5 4 4 0
9 5 5 4 0
9 5 6 4 0
9 5 7 4 0
9 5 8 4 32
9 6 0 5 72
9 6 1 5 8
9 6 2 5 8
9 6 3 4 0
9 6 4 4 0
9 6 5 4 0
9 6 6 4 0
9 6 7 4 0
9 6 8 4 32
9 7 3 4 64
9 7 4 4 0
9 7 5 4 0
9 7 6 4 0
9 7 7 3 0
9 7 8 3 32
9 8 2 4 80
9 8 3 4 0
9 8 4 4 0
9 8 5 3 0
9 8 6 3 0
9 8 7 3 0
9 8 8 3 32
9 9 2 4 64
9 9 3 4 0
9 9 4 4 0
9 9 5 3 0
9 9 6 3 0
9 9 7 4 0
9 9 8 4 32
9 10 2 4 64
9 10 3 4 0
9 10 4 4 0
9 10 5 4 0
9 10 6 4 0
9 10 7 4 0
9 10 8 4 32
9 11 2 4 64
9 11 3 4 0
9 11 4 4 0
9 11 5 4 0
9 11 6 4 0
9 11 7 4 8
9 11 8 4 40
9 12 2 4 64
9 12 3 4 0
9 12 4 4 0
9 12 5 4 0
9 12 6 4 32
9 13 2 4 64
9 13 3 4 0
9 13 4 4 0
9 13 5 4 0
9 13 6 4 32
9 14 2 4 64
9 14 3 4 0
9 14 4 4 0
9 14 5 4 0
9 14 6 4 32
9 15 2 4 64
9 15 3 4 0
9 15 4 4 0
9 15 5 4 0
9 15 6 4 32
9 16 2 4 72
9 16 3 4 0
9 16 4 4 0
9 16 5 3 0
9 16 6 3 0
9 16 7 3 16
9 16 8 3 48
9 17 3 4 64
9 17 4 4 0
9 17 5 2 0
9 17 6 2 0
9 17 7 2 0
9 17 8 2 40
9 18 3 4 64
9 18 4 4 0
9 18 5 1 0
9 18 6 1 0
9 18 7 1 32
9 19 3 4 64
9 19 4 4 0
9 19 5 5 0
9 19 6 5 0
9 19 7 5 0
9 19 8 5 48
9 20 3 4 64
9 20 4 4 0
9 20 5 3 0
9 20 6 3 0
9 20 7 3 0
9 20 8 3 32
9 21 3 4 64
9 21 4 4 0
9 21 5 0 0
9 21 6 0 0
9 21 7 0 0
9 21 8 0 0
9 21 9 0 56
9 22 3 4 64
9 22 4 4 0
9 22 5 3 0
9 22 6 3 0
9 22 7 3 0
9 22 8 3 32
9 23 3 4 64
9 23 4 4 0
9 23 5 3 0
9 23 6 3 0
9 23 7 3 0
9 23 8 3 32
9 24 3 4 64
9 24 4 4 0
9 24 5 3 0
9 24 6 3 0
9 24 7 3 0
9 24 8 3 40
9 25 3 4 72
9 25 4 4 8
9 25 5 4 8
9 25 6 4 8
9 25 7 4 40
10 2 0 5 80
10 2 1 5 16
10 2 2 5 48
10 3 0 5 64
10 3 1 5 0
10 3 2 5 0
10 3 3 4 16
10 3 4 4 16
10 3 5 4 16
10 3 6 4 16
10 3 7 4 16
10 3 8 4 48
10 4 0 5 64
10 4 1 5 0
10 4 2 5 0
10 4 3 4 0
10 4 4 4 0
10 4 5 4 0
10 4 6 4 0
10 4 7 4 0
10 4 8 4 32
10 5 0 5 64
10 5 1 5 0
10 5 2 5 0
10 5 3 4 0
10 5 4 4 0
10 5 5 4 0
10 5 6 4 0
10 5 7 4 0
10 5 8 4 32
10 6 0 5 72
10 6 1 5 8
10 6 2 5 8
10 6 3 4 0
10 6 4 4 0
10 6 5 4 0
10 6 6 4 0
10 6 7 4 0
10 6 8 4 32
10 7 3 4 64
10 7 4 4 0
10 7 5 4 0
10 7 6 4 0
10 7 7 4 0
10 7 8 4 32
10 8 2 4 80
10 8 3 4 0
10 8 4 4 0
10 8 5 4 0
10 8 6 4 0
10 8 7 4 0
10 8 8 4 32
10 9 2 4 64
10 9 3 4 0
10 9 4 4 0
10 9 5 4 0
10 9 6 4 0
10 9 7 4 0
10 9 8 4 32
10 10 2 4 64
10 10 3 4 0
10 10 4 4 0
10 10 5 4 0
10 10 6 4 0
10 10 7 4 0
10 10 8 4 32
10 11 2 4 64
10 11 3 4 0
10 11 4 4 0
10 11 5 4 0
10 11 6 4 0
10 11 7 4 8
10 11 8 4 40
10 12 2 4 64
10 12 3 4 0
10 12 4 4 0
10 12 5 4 0
10 12 6 4 32
10 13 2 4 64
10 13 3 4 0
10 13 4 4 0
10 13 5 4 0
10 13 6 4 32
10 14 2 4 64
10 14 3 4 0
10 14 4 4 0
10 14 5 4 0
10 14 6 4 32
10 15 2 4 64
10 15 3 4 0
10 15 4 4 0
10 15 5 4 0
10 15 6 4 32
10 16 2 4 72
10 16 3 4 0
10 16 4 4 0
10 16 5 3 0
10 16 6 3 0
10 16 7 3 16
10 16 8 3 48
10 17 3 4 64
10 17 4 4 0
10 17 5 2 0
10 17 6 2 0
10 17 7 2 0
10 17 8 2 40
10 18 3 4 64
10 18 4 4 0
10 18 5 1 0
10 18 6 1 0
10 18 7 1 32
10 19 3 4 64
10 19 4 4 0
10 19 5 5 0
10 19 6 5 0
10 19 7 5 0
10 19 8 5 50
10 20 3 4 64
10 20 4 4 0
10 20 5 3 0
10 20 6 3 0
10 20 7 3 0
10 20 8 3 32
10 21 3 4 64
10 21 4 4 0
10 21 5 0 0
10 21 6 0 0
10 21 7 0 0
10 21 8 0 0
10 21 9 0 58
10 22 3 4 64
10 22 4 4 0
10 22 5 3 0
10 22 6 3 0
10 22 7 3 0
10 22 8 3 32
10 23 3 4 64
10 23 4 4 0
10 23 5 3 0
10 23 6 3 0
10 23 7 3 0
10 23 8 3 32
10 24 3 4 64
10 24 4 4 0
10 24 5 3 0
10 24 6 3 0
10 24 7 3 0
10 24 8 3 40
10 25 3 4 72
10 25 4 4 8
10 25 5 4 8
10 25 6 4 8
10 25 7 4 40
11 2 0 5 82
11 2 1 5 18
11 2 2 5 50
11 3 0 5 66
11 3 1 5 2
11 3 2 5 2
11 3 3 4 16
11 3 4 4 16
11 3 5 4 16
11 3 6 4 16
11 3 7 4 16
11 3 8 4 48
11 4 0 5 66
11 4 1 5 2
11 4 2 5 2
11 4 3 4 0
11 4 4 4 0
11 4 5 4 0
11 4 6 4 0
11 4 7 4 0
11 4 8 4 32
11 5 0 5 66
11 5 1 5 2
11 5 2 5 2
11 5 3 4 0
11 5 4 4 0
11 5 5 4 0
11 5 6 4 0
11 5 7 4 0
11 5 8 4 32
11 6 0 5 74
11 6 1 5 10
11 6 2 5 10
11 6 3 4 0
11 6 4 4 0
11 6 5 4 0
11 6 6 4 0
11 6 7 4 0
11 6 8 4 32
11 7 3 4 64
11 7 4 4 0
11 7 5 4 0
11 7 6 4 0
11 7 7 4 0
11 7 8 4 32
11 8 2 4 80
11 8 3 4 0
11 8 4 4 0
11 8 5 4 0
11 8 6 4 0
11 8 7 4 0
11 8 8 4 32
11 9 2 4 64
11 9 3 4 0
11 9 4 4 0
11 9 5 4 0
11 9 6 4 0
11 9 7 4 0
11 9 8 4 32
11 10 2 4 64
11 10 3 4 0
11 10 4 4 0
11 10 5 4 0
11 10 6 4 0
11 10 7 4 0
11 10 8 4 32
11 11 2 4 64
11 11 3 4 0
11 11 4 4 0
11 11 5 4 0
11 11 6 4 0
11 11 7 4 8
11 11 8 4 40
11 12 2 4 64
11 12 3 4 0
11 12 4 4 0
11 12 5 4 0
11 12 6 4 32
11 13 2 4 64
11 13 3 4 0
11 13 4 4 0
11 13 5 4 0
11 13 6 4 32
11 14 2 4 64
11 14 3 4 0
11 14 4 4 0
11 14 5 4 0
11 14 6 4 32
11 15 2 4 64
11 15 3 4 0
11 15 4 4 0
11 15 5 4 0
11 15 6 4 32
11 16 2 4 72
11 16 3 4 0
11 16 4 4 0
11 16 5 3 0
11 16 6 3 0
11 16 7 3 16
11 16 8 3 48
11 17 3 4 64
11 17 4 4 0
11 17 5 2 0
11 17 6 2 0
11 17 7 2 0
11 17 8 2 42
11 18 3 4 64
11 18 4 4 0
11 18 5 1 0
11 18 6 1 0
11 18 7 1 32
11 19 3 4 64
11 19 4 4 0
11 19 5 1 0
11 19 6 1 0
11 19 7 1 32
11 20 3 4 64
11 20 4 4 0
11 20 5 3 0
11 20 6 3 0
11 20 7 3 0
11 20 8 3 48
11 21 3 4 64
11 21 4 4 0
11 21 5 4 0
11 21 6 4 0
11 21 7 4 0
11 21 8 4 32
11 22 3 4 64
11 22 4 4 0
11 22 5 5 0
11 22 6 5 0
11 22 7 5 0
11 22 8 5 32
11 23 3 4 64
11 23 4 4 0
11 23 5 5 0
11 23 6 5 0
11 23 7 5 0
11 23 8 5 32
11 24 3 4 64
11 24 4 4 0
11 24 5 5 0
11 24 6 5 0
11 24 7 5 0
11 24 8 5 40
11 25 3 4 72
11 25 4 4 0
11 25 5 4 0
11 25 6 4 0
11 25 7 4 40
11 26 4 0 68
11 26 5 0 4
11 26 6 0 38
11 27 4 0 68
11 27 5 0 4
11 27 6 0 38
11 28 4 0 68
11 28 5 0 4
11 28 6 0 38
11 29 4 0 68
11 29 5 0 4
11 29 6 0 6
11 29 7 0 22
11 29 8 0 22
11 29 9 0 52
11 30 4 0 76
11 30 5 0 4
11 30 6 0 4
11 30 7 0 4
11 30 8 0 4
11 30 9 0 36
11 31 5 0 76
11 31 6 0 12
11 31 7 0 12
11 31 8 0 12
11 31 9 0 44
12 0 4 0 84
12 0 5 0 20
12 0 6 0 20
12 0 7 0 60
12 1 4 0 68
12 1 5 0 4
12 1 6 0 36
12 2 4 3 68
12 2 5 3 4
12 2 6 3 36
12 3 3 4 80
12 3 4 4 0
12 3 5 4 0
12 3 6 4 0
12 3 7 4 16
12 3 8 4 48
12 4 3 4 64
12 4 4 4 0
12 4 5 4 0
12 4 6 4 0
12 4 7 4 0
12 4 8 4 32
12 5 3 4 64
12 5 4 4 0
12 5 5 4 0
12 5 6 4 0
12 5 7 4 0
12 5 8 4 32
12 6 3 4 64
12 6 4 4 0
12 6 5 4 0
12 6 6 4 0
12 6 7 4 0
12 6 8 4 32
12 7 3 4 64
12 7 4 4 0
12 7 5 4 0
12 7 6 4 0
12 7 7 4 0
12 7 8 4 32
12 8 2 4 80
12 8 3 4 0
12 8 4 4 0
12 8 5 4 0
12 8 6 4 0
12 8 7 4 0
12 8 8 4 32
12 9 2 4 64
12 9 3 4 0
12 9 4 4 0
12 9 5 4 0
12 9 6 4 0
12 9 7 4 0
12 9 8 4 32
12 10 2 4 64
12 10 3 4 0
12 10 4 4 0
12 10 5 4 0
12 10 6 4 0
12 10 7 4 0
12 10 8 4 32
12 11 2 4 64
12 11 3 4 0
12 11 4 4 0
12 11 5 4 0
12 11 6 4 0
12 11 7 4 8
12 11 8 4 40
12 12 2 4 64
12 12 3 4 0
12 12 4 4 0
12 12 5 4 0
12 12 6 4 32
12 13 2 4 64
12 13 3 4 0
12 13 4 4 0
12 13 5 4 0
12 13 6 4 32
12 14 2 4 64
12 14 3 4 0
12 14 4 4 0
12 14 5 4 0
12 14 6 4 32
12 15 2 4 64
12 15 3 4 0
12 15 4 4 0
12 15 5 4 0
12 15 6 4 32
12 16 2 4 72
12 16 3 4 0
12 16 4 4 0
12 16 5 3 0
12 16 6 3 0
12 16 7 3 16
12 16 8 3 56
12 17 3 4 64
12 17 4 4 0
12 17 5 1 0
12 17 6 1 0
12 17 7 1 32
12 18 3 4 64
12 18 4 4 0
12 18 5 1 0
12 18 6 1 0
12 18 7 1 32
12 19 3 4 64
12 19 4 4 0
12 19 5 1 0
12 19 6 1 0
12 19 7 1 32
12 20 3 4 64
12 20 4 4 0
12 20 5 3 0
12 20 6 3 0
12 20 7 3 0
12 20 8 3 48
12 21 3 4 64
12 21 4 4 0
12 21 5 4 0
12 21 6 4 0
12 21 7 4 0
12 21 8 4 32
12 22 3 4 64
12 22 4 4 0
12 22 5 0 0
12 22 6 0 0
12 22 7 0 0
12 22 8 5 32
12 23 3 4 64
12 23 4 4 0
12 23 5 0 0
12 23 6 0 0
12 23 7 0 0
12 23 8 1 32
12 24 3 4 64
12 24 4 4 0
12 24 5 5 0
12 24 6 5 0
12 24 7 5 0
12 24 8 5 40
12 25 3 4 72
12 25 4 4 0
12 25 5 4 0
12 25 6 4 8
12 25 7 4 40
12 26 4 0 64
12 26 5 3 32
12 27 4 0 64
12 27 5 3 32
12 28 4 0 64
12 28 5 3 32
12 29 4 0 64
12 29 5 3 32
12 29 9 0 112
12 30 4 0 72
12 30 5 3 0
12 30 6 3 16
12 30 7 3 16
12 30 8 3 16
12 30 9 0 32
12 31 5 0 72
12 31 6 0 8
12 31 7 0 8
12 31 8 0 8
12 31 9 0 40
13 0 4 0 80
13 0 5 0 16
13 0 6 0 16
13 0 7 0 56
13 1 4 0 64
13 1 5 0 0
13 1 6 0 32
13 2 4 3 64
13 2 5 3 0
13 2 6 3 32
13 3 3 4 80
13 3 4 4 0
13 3 5 4 0
13 3 6 4 0
13 3 7 4 16
13 3 8 4 48
13 4 3 4 64
13 4 4 4 0
13 4 5 4 0
13 4 6 4 0
13 4 7 4 0
13 4 8 4 32
13 5 3 4 64
13 5 4 4 0
13 5 5 4 0
13 5 6 4 0
13 5 7 4 0
13 5 8 4 32
13 6 3 4 64
13 6 4 4 0
13 6 5 4 0
13 6 6 4 0
13 6 7 4 0
13 6 8 4 32
13 7 3 4 64
13 7 4 4 0
13 7 5 4 0
13 7 6 4 0
13 7 7 4 0
13 7 8 4 32
13 8 2 4 80
13 8 3 4 0
13 8 4 4 0
13 8 5 4 0
13 8 6 4 0
13 8 7 4 0
13 8 8 4 32
13 9 2 4 64
13 9 3 4 0
13 9 4 4 0
13 9 5 4 0
13 9 6 4 0
13 9 7 4 0
13 9 8 4 32
13 10 2 4 64
13 10 3 4 0
13 10 4 4 0
13 10 5 4 0
13 10 6 4 0
13 10 7 4 0
13 10 8 4 32
13 11 2 4 64
13 11 3 4 0
13 11 4 4 0
13 11 5 4 0
13 11 6 4 0
13 11 7 4 8
13 11 8 4 40
13 12 2 4 64
13 12 3 4 0
13 12 4 4 0
13 12 5 4 0
13 12 6 4 32
13 13 2 4 64
13 13 3 4 0
13 13 4 4 0
13 13 5 4 0
13 13 6 4 32
13 14 2 4 64
13 14 3 4 0
13 14 4 4 0
13 14 5 4 0
13 14 6 4 32
13 15 2 4 64
13 15 3 4 0
13 15 4 4 0
13 15 5 4 0
13 15 6 4 32
13 16 2 4 72
13 16 3 4 0
13 16 4 4 0
13 16 5 3 0
13 16 6 3 0
13 16 7 3 16
13 16 8 3 50
13 17 3 4 64
13 17 4 4 0
13 17 5 3 0
13 17 6 3 0
13 17 7 3 0
13 17 8 3 38
13 18 3 4 64
13 18 4 4 0
13 18 5 3 0
13 18 6 3 0
13 18 7 3 0
13 18 8 3 38
13 19 3 4 64
13 19 4 4 0
13 19 5 3 0
13 19 6 3 0
13 19 7 3 0
13 19 8 3 38
13 20 3 4 64
13 20 4 4 0
13 20 5 3 0
13 20 6 3 0
13 20 7 3 0
13 20 8 3 34
13 21 3 4 64
13 21 4 4 0
13 21 5 4 0
13 21 6 4 0
13 21 7 4 0
13 21 8 4 34
13 22 3 4 64
13 22 4 4 0
13 22 5 5 0
13 22 6 5 0
13 22 7 5 0
13 22 8 5 34
13 23 3 4 64
13 23 4 4 0
13 23 5 5 0
13 23 6 5 0
13 23 7 5 0
13 23 8 5 34
13 24 3 4 64
13 24 4 4 0
13 24 5 5 0
13 24 6 5 0
13 24 7 5 0
13 24 8 5 42
13 25 3 4 72
13 25 4 4 0
13 25 5 4 0
13 25 6 4 8
13 25 7 4 40
13 26 4 0 64
13 26 5 3 32
13 27 4 0 64
13 27 5 3 32
13 28 4 0 64
13 28 5 3 32
13 29 4 0 64
13 29 5 3 32
13 29 9 0 112
13 30 4 0 72
13 30 5 3 0
13 30 6 3 16
13 30 7 3 16
13 30 8 3 16
13 30 9 0 32
13 31 5 0 72
13 31 6 0 8
13 31 7 0 8
13 31 8 0 8
13 31 9 0 40
14 0 4 0 82
14 0 5 0 18
14 0 6 0 18
14 0 7 0 58
14 1 4 0 66
14 1 5 0 2
14 1 6 0 34
14 2 4 3 66
14 2 5 3 2
14 2 6 3 34
14 3 3 4 82
14 3 4 4 2
14 3 5 4 2
14 3 6 4 2
14 3 7 4 18
14 3 8 4 50
14 4 3 4 66
14 4 4 4 2
14 4 5 4 2
14 4 6 4 2
14 4 7 4 2
14 4 8 4 34
14 5 3 4 66
14 5 4 4 2
14 5 5 4 2
14 5 6 4 2
14 5 7 4 2
14 5 8 4 34
14 6 3 4 66
14 6 4 4 2
14 6 5 4 2
14 6 6 4 2
14 6 7 4 2
14 6 8 4 34
14 7 3 4 66
14 7 4 4 2
14 7 5 4 2
14 7 6 4 2
14 7 7 4 2
14 7 8 4 34
14 8 2 4 82
14 8 3 4 2
14 8 4 4 2
14 8 5 4 2
14 8 6 4 2
14 8 7 4 2
14 8 8 4 34
14 9 2 4 66
14 9 3 4 2
14 9 4 4 2
14 9 5 4 2
14 9 6 4 2
14 9 7 4 2
14 9 8 4 34
14 10 2 4 66
14 10 3 4 2
14 10 4 4 2
14 10 5 4 2
14 10 6 4 2
14 10 7 4 2
14 10 8 4 34
14 11 2 4 66
14 11 3 4 2
14 11 4 4 2
14 11 5 4 2
14 11 6 4 2
14 11 7 4 10
14 11 8 4 42
14 12 2 4 66
14 12 3 4 0
14 12 4 4 0
14 12 5 4 0
14 12 6 4 34
14 13 2 4 66
14 13 3 4 0
14 13 4 4 0
14 13 5 4 0
14 13 6 4 34
14 14 2 4 66
14 14 3 4 0
14 14 4 4 0
14 14 5 4 0
14 14 6 4 34
14 15 2 4 66
14 15 3 4 2
14 15 4 4 2
14 15 5 4 2
14 15 6 4 34
14 16 2 4 74
14 16 3 4 2
14 16 4 4 2
14 16 5 4 2
14 16 6 4 2
14 16 7 4 50
14 17 3 4 66
14 17 4 4 2
14 17 5 4 2
14 17 6 4 2
14 17 7 4 34
14 18 3 4 66
14 18 4 4 2
14 18 5 4 2
14 18 6 4 2
14 18 7 4 34
14 19 3 4 66
14 19 4 4 2
14 19 5 4 2
14 19 6 4 2
14 19 7 4 34
14 20 3 4 66
14 20 4 4 2
14 20 5 4 2
14 20 6 4 2
14 20 7 4 34
14 21 3 4 66
14 21 4 4 2
14 21 5 4 2
14 21 6 4 2
14 21 7 4 34
14 22 3 4 66
14 22 4 4 2
14 22 5 4 2
14 22 6 4 2
14 22 7 4 34
14 23 3 4 66
14 23 4 4 2
14 23 5 4 2
14 23 6 4 2
14 23 7 4 34
14 24 3 4 66
14 24 4 4 2
14 24 5 4 2
14 24 6 4 2
14 24 7 4 34
14 25 3 4 74
14 25 4 4 2
14 25 5 4 2
14 25 6 4 2
14 25 7 4 42
14 26 4 0 66
14 26 5 0 2
14 26 6 0 38
14 27 4 0 66
14 27 5 0 2
14 27 6 0 38
14 28 4 0 66
14 28 5 0 2
14 28 6 0 38
14 29 4 0 66
14 29 5 0 2
14 29 6 0 6
14 29 7 0 22
14 29 8 0 22
14 29 9 0 50
14 30 4 0 74
14 30 5 0 2
14 30 6 0 2
14 30 7 0 2
14 30 8 0 2
14 30 9 0 34
14 31 5 0 74
14 31 6 0 10
14 31 7 0 10
14 31 8 0 10
14 31 9 0 42
15 12 3 3 80
15 12 4 3 16
15 12 5 3 48
15 13 3 3 64
15 13 4 3 0
15 13 5 3 32
15 14 3 3 72
15 14 4 3 8
15 14 5 3 40
16 9 8 0 116
16 10 3 3 84
16 10 4 3 20
16 10 5 3 20
16 10 6 3 20
16 10 7 3 20
16 10 8 0 36
16 11 3 3 68
16 11 4 3 4
16 11 5 3 4
16 11 6 3 4
16 11 7 3 4
16 11 8 0 36
16 12 3 3 64
16 12 4 3 0
16 12 5 3 0
16 12 6 3 12
16 12 7 3 12
16 12 8 0 44
16 13 3 3 64
16 13 4 3 0
16 13 5 3 32
16 14 3 3 72
16 14 4 3 8
16 14 5 3 40
17 9 8 0 112
17 10 3 3 80
17 10 4 3 16
17 10 5 3 16
17 10 6 3 16
17 10 7 3 16
17 10 8 0 32
17 11 3 3 64
17 11 4 3 0
17 11 5 3 0
17 11 6 3 0
17 11 7 3 0
17 11 8 0 32
17 12 3 3 64
17 12 4 3 0
17 12 5 3 0
17 12 6 3 8
17 12 7 3 8
17 12 8 0 40
17 13 3 3 64
17 13 4 3 0
17 13 5 3 32
17 14 3 3 72
17 14 4 3 8
17 14 5 3 40
18 9 8 0 114
18 10 3 3 82
18 10 4 3 18
18 10 5 3 18
18 10 6 3 18
18 10 7 3 18
18 10 8 0 34
18 11 3 3 66
18 11 4 3 2
18 11 5 3 2
18 11 6 3 2
18 11 7 3 2
18 11 8 0 34
18 12 3 3 66
18 12 4 3 2
18 12 5 3 2
18 12 6 3 10
18 12 7 3 10
18 12 8 0 42
18 13 3 3 66
18 13 4 3 2
18 13 5 3 34
18 14 3 3 74
18 14 4 3 10
18 14 5 3 42
