Qubicle Exchange Format
Version 0.2
www.minddesk.com
16 16 16
2
0.000000 0.439216 0.925490
1.000000 1.000000 1.000000
0 0 0 1 84
0 0 1 1 20
0 0 2 1 20
0 0 3 1 20
0 0 4 1 20
0 0 5 1 20
0 0 6 1 20
0 0 7 1 20
0 0 8 1 20
0 0 9 1 20
0 0 10 1 20
0 0 11 1 20
0 0 12 1 20
0 0 13 1 20
0 0 14 1 20
0 0 15 1 52
0 1 0 0 68
0 1 1 0 6
0 1 2 0 6
0 1 3 0 6
0 1 4 0 6
0 1 5 0 6
0 1 6 0 6
0 1 7 0 6
0 1 8 0 6
0 1 9 0 6
0 1 10 0 6
0 1 11 0 6
0 1 12 0 6
0 1 13 0 6
0 1 14 0 6
0 1 15 0 36
0 2 0 1 68
0 2 1 1 6
0 2 2 1 6
0 2 3 1 6
0 2 4 1 6
0 2 5 1 6
0 2 6 1 6
0 2 7 1 6
0 2 8 1 6
0 2 9 1 6
0 2 10 1 6
0 2 11 1 6
0 2 12 1 6
0 2 13 1 6
0 2 14 1 6
0 2 15 1 36
0 3 0 0 68
0 3 1 0 6
0 3 2 0 6
0 3 3 0 6
0 3 4 0 6
0 3 5 0 6
0 3 6 0 6
0 3 7 0 6
0 3 8 0 6
0 3 9 0 6
0 3 10 0 6
0 3 11 0 6
0 3 12 0 6
0 3 13 0 6
0 3 14 0 6
0 3 15 0 36
0 4 0 1 68
0 4 1 1 6
0 4 2 1 6
0 4 3 1 6
0 4 4 1 6
0 4 5 1 6
0 4 6 1 6
0 4 7 1 6
0 4 8 1 6
0 4 9 1 6
0 4 10 1 6
0 4 11 1 6
0 4 12 1 6
0 4 13 1 6
0 4 14 1 6
0 4 15 1 36
0 5 0 0 68
0 5 1 0 6
0 5 2 0 6
0 5 3 0 6
0 5 4 0 6
0 5 5 0 6
0 5 6 0 6
0 5 7 0 6
0 5 8 0 6
0 5 9 0 6
0 5 10 0 6
0 5 11 0 6
0 5 12 0 6
0 5 13 0 6
0 5 14 0 6
0 5 15 0 36
0 6 0 1 68
0 6 1 1 6
0 6 2 1 6
0 6 3 1 6
0 6 4 1 6
0 6 5 1 6
0 6 6 1 6
0 6 7 1 6
0 6 8 1 6
0 6 9 1 6
0 6 10 1 6
0 6 11 1 6
0 6 12 1 6
0 6 13 1 6
0 6 14 1 6
0 6 15 1 36
0 7 0 0 68
0 7 1 0 6
0 7 2 0 6
0 7 3 0 6
0 7 4 0 6
0 7 5 0 6
0 7 6 0 6
0 7 7 0 6
0 7 8 0 6
0 7 9 0 6
0 7 10 0 6
0 7 11 0 6
0 7 12 0 6
0 7 13 0 6
0 7 14 0 6
0 7 15 0 36
0 8 0 1 68
0 8 1 1 6
0 8 2 1 6
0 8 3 1 6
0 8 4 1 6
0 8 5 1 6
0 8 6 1 6
0 8 7 1 6
0 8 8 1 6
0 8 9 1 6
0 8 10 1 6
0 8 11 1 6
0 8 12 1 6
0 8 13 1 6
0 8 14 1 6
0 8 15 1 36
0 9 0 0 68
0 9 1 0 6
0 9 2 0 6
0 9 3 0 6
0 9 4 0 6
0 9 5 0 6
0 9 6 0 6
0 9 7 0 6
0 9 8 0 6
0 9 9 0 6
0 9 10 0 6
0 9 11 0 6
0 9 12 0 6
0 9 13 0 6
0 9 14 0 6
0 9 15 0 36
0 10 0 1 68
0 10 1 1 6
0 10 2 1 6
0 10 3 1 6
0 10 4 1 6
0 10 5 1 6
0 10 6 1 6
0 10 7 1 6
0 10 8 1 6
0 10 9 1 6
0 10 10 1 6
0 10 11 1 6
0 10 12 1 6
0 10 13 1 6
0 10 14 1 6
0 10 15 1 36
0 11 0 0 68
0 11 1 0 6
0 11 2 0 6
0 11 3 0 6
0 11 4 0 6
0 11 5 0 6
0 11 6 0 6
0 11 7 0 6
0 11 8 0 6
0 11 9 0 6
0 11 10 0 6
0 11 11 0 6
0 11 12 0 6
0 11 13 0 6
0 11 14 0 6
0 11 15 0 36
0 12 0 1 68
0 12 1 1 6
0 12 2 1 6
0 12 3 1 6
0 12 4 1 6
0 12 5 1 6
0 12 6 1 6
0 12 7 1 6
0 12 8 1 6
0 12 9 1 6
0 12 10 1 6
0 12 11 1 6
0 12 12 1 6
0 12 13 1 6
0 12 14 1 6
0 12 15 1 36
0 13 0 0 68
0 13 1 0 6
0 13 2 0 6
0 13 3 0 6
0 13 4 0 6
0 13 5 0 6
0 13 6 0 6
0 13 7 0 6
0 13 8 0 6
0 13 9 0 6
0 13 10 0 6
0 13 11 0 6
0 13 12 0 6
0 13 13 0 6
0 13 14 0 6
0 13 15 0 36
0 14 0 1 68
0 14 1 1 6
0 14 2 1 6
0 14 3 1 6
0 14 4 1 6
0 14 5 1 6
0 14 6 1 6
0 14 7 1 6
0 14 8 1 6
0 14 9 1 6
0 14 10 1 6
0 14 11 1 6
0 14 12 1 6
0 14 13 1 6
0 14 14 1 6
0 14 15 1 36
0 15 0 0 76
0 15 1 0 12
0 15 2 0 12
0 15 3 0 12
0 15 4 0 12
0 15 5 0 12
0 15 6 0 12
0 15 7 0 12
0 15 8 0 12
0 15 9 0 12
0 15 10 0 12
0 15 11 0 12
0 15 12 0 12
0 15 13 0 12
0 15 14 0 12
0 15 15 0 44
1 0 0 1 80
1 0 1 1 24
1 0 2 1 24
1 0 3 1 24
1 0 4 1 24
1 0 5 1 24
1 0 6 1 24
1 0 7 1 24
1 0 8 1 24
1 0 9 1 24
1 0 10 1 24
1 0 11 1 24
1 0 12 1 24
1 0 13 1 24
1 0 14 1 24
1 0 15 1 48
1 1 0 0 96
1 1 15 0 96
1 2 0 1 96
1 2 15 1 96
1 3 0 0 96
1 3 15 0 96
1 4 0 1 96
1 4 15 1 96
1 5 0 0 96
1 5 15 0 96
1 6 0 1 96
1 6 15 1 96
1 7 0 0 96
1 7 15 0 96
1 8 0 1 96
1 8 15 1 96
1 9 0 0 96
1 9 15 0 96
1 10 0 1 96
1 10 15 1 96
1 11 0 0 96
1 11 15 0 96
1 12 0 1 96
1 12 15 1 96
1 13 0 0 96
1 13 15 0 96
1 14 0 1 96
1 14 15 1 96
1 15 0 0 72
1 15 1 0 24
1 15 2 0 24
1 15 3 0 24
1 15 4 0 24
1 15 5 0 24
1 15 6 0 24
1 15 7 0 24
1 15 8 0 24
1 15 9 0 24
1 15 10 0 24
1 15 11 0 24
1 15 12 0 24
1 15 13 0 24
1 15 14 0 24
1 15 15 0 40
2 0 0 1 80
2 0 1 1 24
2 0 2 1 24
2 0 3 1 24
2 0 4 1 24
2 0 5 1 24
2 0 6 1 24
2 0 7 1 24
2 0 8 1 24
2 0 9 1 24
2 0 10 1 24
2 0 11 1 24
2 0 12 1 24
2 0 13 1 24
2 0 14 1 24
2 0 15 1 48
2 1 0 0 96
2 1 15 0 96
2 2 0 1 96
2 2 15 1 96
2 3 0 0 96
2 3 15 0 96
2 4 0 1 96
2 4 15 1 96
2 5 0 0 96
2 5 15 0 96
2 6 0 1 96
2 6 15 1 96
2 7 0 0 96
2 7 15 0 96
2 8 0 1 96
2 8 15 1 96
2 9 0 0 96
2 9 15 0 96
2 10 0 1 96
2 10 15 1 96
2 11 0 0 96
2 11 15 0 96
2 12 0 1 96
2 12 15 1 96
2 13 0 0 96
2 13 15 0 96
2 14 0 1 96
2 14 15 1 96
2 15 0 0 72
2 15 1 0 24
2 15 2 0 24
2 15 3 0 24
2 15 4 0 24
2 15 5 0 24
2 15 6 0 24
2 15 7 0 24
2 15 8 0 24
2 15 9 0 24
2 15 10 0 24
2 15 11 0 24
2 15 12 0 24
2 15 13 0 24
2 15 14 0 24
2 15 15 0 40
3 0 0 1 80
3 0 1 1 24
3 0 2 1 24
3 0 3 1 24
3 0 4 1 24
3 0 5 1 24
3 0 6 1 24
3 0 7 1 24
3 0 8 1 24
3 0 9 1 24
3 0 10 1 24
3 0 11 1 24
3 0 12 1 24
3 0 13 1 24
3 0 14 1 24
3 0 15 1 48
3 1 0 0 96
3 1 15 0 96
3 2 0 1 96
3 2 15 1 96
3 3 0 0 96
3 3 15 0 96
3 4 0 1 96
3 4 15 1 96
3 5 0 0 96
3 5 15 0 96
3 6 0 1 96
3 6 15 1 96
3 7 0 0 96
3 7 15 0 96
3 8 0 1 96
3 8 15 1 96
3 9 0 0 96
3 9 15 0 96
3 10 0 1 96
3 10 15 1 96
3 11 0 0 96
3 11 15 0 96
3 12 0 1 96
3 12 15 1 96
3 13 0 0 96
3 13 15 0 96
3 14 0 1 96
3 14 15 1 96
3 15 0 0 72
3 15 1 0 24
3 15 2 0 24
3 15 3 0 24
3 15 4 0 24
3 15 5 0 24
3 15 6 0 24
3 15 7 0 24
3 15 8 0 24
3 15 9 0 24
3 15 10 0 24
3 15 11 0 24
3 15 12 0 24
3 15 13 0 24
3 15 14 0 24
3 15 15 0 40
4 0 0 1 80
4 0 1 1 24
4 0 2 1 24
4 0 3 1 24
4 0 4 1 24
4 0 5 1 24
4 0 6 1 24
4 0 7 1 24
4 0 8 1 24
4 0 9 1 24
4 0 10 1 24
4 0 11 1 24
4 0 12 1 24
4 0 13 1 24
4 0 14 1 24
4 0 15 1 48
4 1 0 0 96
4 1 15 0 96
4 2 0 1 96
4 2 15 1 96
4 3 0 0 96
4 3 15 0 96
4 4 0 1 96
4 4 15 1 96
4 5 0 0 96
4 5 15 0 96
4 6 0 1 96
4 6 15 1 96
4 7 0 0 96
4 7 15 0 96
4 8 0 1 96
4 8 15 1 96
4 9 0 0 96
4 9 15 0 96
4 10 0 1 96
4 10 15 1 96
4 11 0 0 96
4 11 15 0 96
4 12 0 1 96
4 12 15 1 96
4 13 0 0 96
4 13 15 0 96
4 14 0 1 96
4 14 15 1 96
4 15 0 0 72
4 15 1 0 24
4 15 2 0 24
4 15 3 0 24
4 15 4 0 24
4 15 5 0 24
4 15 6 0 24
4 15 7 0 24
4 15 8 0 24
4 15 9 0 24
4 15 10 0 24
4 15 11 0 24
4 15 12 0 24
4 15 13 0 24
4 15 14 0 24
4 15 15 0 40
5 0 0 1 80
5 0 1 1 24
5 0 2 1 24
5 0 3 1 24
5 0 4 1 24
5 0 5 1 24
5 0 6 1 24
5 0 7 1 24
5 0 8 1 24
5 0 9 1 24
5 0 10 1 24
5 0 11 1 24
5 0 12 1 24
5 0 13 1 24
5 0 14 1 24
5 0 15 1 48
5 1 0 0 96
5 1 15 0 96
5 2 0 1 96
5 2 15 1 96
5 3 0 0 96
5 3 15 0 96
5 4 0 1 96
5 4 15 1 96
5 5 0 0 96
5 5 15 0 96
5 6 0 1 96
5 6 15 1 96
5 7 0 0 96
5 7 15 0 96
5 8 0 1 96
5 8 15 1 96
5 9 0 0 96
5 9 15 0 96
5 10 0 1 96
5 10 15 1 96
5 11 0 0 96
5 11 15 0 96
5 12 0 1 96
5 12 15 1 96
5 13 0 0 96
5 13 15 0 96
5 14 0 1 96
5 14 15 1 96
5 15 0 0 72
5 15 1 0 24
5 15 2 0 24
5 15 3 0 24
5 15 4 0 24
5 15 5 0 24
5 15 6 0 24
5 15 7 0 24
5 15 8 0 24
5 15 9 0 24
5 15 10 0 24
5 15 11 0 24
5 15 12 0 24
5 15 13 0 24
5 15 14 0 24
5 15 15 0 40
6 0 0 1 80
6 0 1 1 24
6 0 2 1 24
6 0 3 1 24
6 0 4 1 24
6 0 5 1 24
6 0 6 1 24
6 0 7 1 24
6 0 8 1 24
6 0 9 1 24
6 0 10 1 24
6 0 11 1 24
6 0 12 1 24
6 0 13 1 24
6 0 14 1 24
6 0 15 1 48
6 1 0 0 96
6 1 15 0 96
6 2 0 1 96
6 2 15 1 96
6 3 0 0 96
6 3 15 0 96
6 4 0 1 96
6 4 15 1 96
6 5 0 0 96
6 5 15 0 96
6 6 0 1 96
6 6 15 1 96
6 7 0 0 96
6 7 15 0 96
6 8 0 1 96
6 8 15 1 96
6 9 0 0 96
6 9 15 0 96
6 10 0 1 96
6 10 15 1 96
6 11 0 0 96
6 11 15 0 96
6 12 0 1 96
6 12 15 1 96
6 13 0 0 96
6 13 15 0 96
6 14 0 1 96
6 14 15 1 96
6 15 0 0 72
6 15 1 0 24
6 15 2 0 24
6 15 3 0 24
6 15 4 0 24
6 15 5 0 24
6 15 6 0 24
6 15 7 0 24
6 15 8 0 24
6 15 9 0 24
6 15 10 0 24
6 15 11 0 24
6 15 12 0 24
6 15 13 0 24
6 15 14 0 24
6 15 15 0 40
7 0 0 1 80
7 0 1 1 24
7 0 2 1 24
7 0 3 1 24
7 0 4 1 24
7 0 5 1 24
7 0 6 1 24
7 0 7 1 24
7 0 8 1 24
7 0 9 1 24
7 0 10 1 24
7 0 11 1 24
7 0 12 1 24
7 0 13 1 24
7 0 14 1 24
7 0 15 1 48
7 1 0 0 96
7 1 15 0 96
7 2 0 1 96
7 2 15 1 96
7 3 0 0 96
7 3 15 0 96
7 4 0 1 96
7 4 15 1 96
7 5 0 0 96
7 5 15 0 96
7 6 0 1 96
7 6 15 1 96
7 7 0 0 96
7 7 15 0 96
7 8 0 1 96
7 8 15 1 96
7 9 0 0 96
7 9 15 0 96
7 10 0 1 96
7 10 15 1 96
7 11 0 0 96
7 11 15 0 96
7 12 0 1 96
7 12 15 1 96
7 13 0 0 96
7 13 15 0 96
7 14 0 1 96
7 14 15 1 96
7 15 0 0 72
7 15 1 0 24
7 15 2 0 24
7 15 3 0 24
7 15 4 0 24
7 15 5 0 24
7 15 6 0 24
7 15 7 0 24
7 15 8 0 24
7 15 9 0 24
7 15 10 0 24
7 15 11 0 24
7 15 12 0 24
7 15 13 0 24
7 15 14 0 24
7 15 15 0 40
8 0 0 1 80
8 0 1 1 24
8 0 2 1 24
8 0 3 1 24
8 0 4 1 24
8 0 5 1 24
8 0 6 1 24
8 0 7 1 24
8 0 8 1 24
8 0 9 1 24
8 0 10 1 24
8 0 11 1 24
8 0 12 1 24
8 0 13 1 24
8 0 14 1 24
8 0 15 1 48
8 1 0 0 96
8 1 15 0 96
8 2 0 1 96
8 2 15 1 96
8 3 0 0 96
8 3 15 0 96
8 4 0 1 96
8 4 15 1 96
8 5 0 0 96
8 5 15 0 96
8 6 0 1 96
8 6 15 1 96
8 7 0 0 96
8 7 15 0 96
8 8 0 1 96
8 8 15 1 96
8 9 0 0 96
8 9 15 0 96
8 10 0 1 96
8 10 15 1 96
8 11 0 0 96
8 11 15 0 96
8 12 0 1 96
8 12 15 1 96
8 13 0 0 96
8 13 15 0 96
8 14 0 1 96
8 14 15 1 96
8 15 0 0 72
8 15 1 0 24
8 15 2 0 24
8 15 3 0 24
8 15 4 0 24
8 15 5 0 24
8 15 6 0 24
8 15 7 0 24
8 15 8 0 24
8 15 9 0 24
8 15 10 0 24
8 15 11 0 24
8 15 12 0 24
8 15 13 0 24
8 15 14 0 24
8 15 15 0 40
9 0 0 1 80
9 0 1 1 24
9 0 2 1 24
9 0 3 1 24
9 0 4 1 24
9 0 5 1 24
9 0 6 1 24
9 0 7 1 24
9 0 8 1 24
9 0 9 1 24
9 0 10 1 24
9 0 11 1 24
9 0 12 1 24
9 0 13 1 24
9 0 14 1 24
9 0 15 1 48
9 1 0 0 96
9 1 15 0 96
9 2 0 1 96
9 2 15 1 96
9 3 0 0 96
9 3 15 0 96
9 4 0 1 96
9 4 15 1 96
9 5 0 0 96
9 5 15 0 96
9 6 0 1 96
9 6 15 1 96
9 7 0 0 96
9 7 15 0 96
9 8 0 1 96
9 8 15 1 96
9 9 0 0 96
9 9 15 0 96
9 10 0 1 96
9 10 15 1 96
9 11 0 0 96
9 11 15 0 96
9 12 0 1 96
9 12 15 1 96
9 13 0 0 96
9 13 15 0 96
9 14 0 1 96
9 14 15 1 96
9 15 0 0 72
9 15 1 0 24
9 15 2 0 24
9 15 3 0 24
9 15 4 0 24
9 15 5 0 24
9 15 6 0 24
9 15 7 0 24
9 15 8 0 24
9 15 9 0 24
9 15 10 0 24
9 15 11 0 24
9 15 12 0 24
9 15 13 0 24
9 15 14 0 24
9 15 15 0 40
10 0 0 1 80
10 0 1 1 24
10 0 2 1 24
10 0 3 1 24
10 0 4 1 24
10 0 5 1 24
10 0 6 1 24
10 0 7 1 24
10 0 8 1 24
10 0 9 1 24
10 0 10 1 24
10 0 11 1 24
10 0 12 1 24
10 0 13 1 24
10 0 14 1 24
10 0 15 1 48
10 1 0 0 96
10 1 15 0 96
10 2 0 1 96
10 2 15 1 96
10 3 0 0 96
10 3 15 0 96
10 4 0 1 96
10 4 15 1 96
10 5 0 0 96
10 5 15 0 96
10 6 0 1 96
10 6 15 1 96
10 7 0 0 96
10 7 15 0 96
10 8 0 1 96
10 8 15 1 96
10 9 0 0 96
10 9 15 0 96
10 10 0 1 96
10 10 15 1 96
10 11 0 0 96
10 11 15 0 96
10 12 0 1 96
10 12 15 1 96
10 13 0 0 96
10 13 15 0 96
10 14 0 1 96
10 14 15 1 96
10 15 0 0 72
10 15 1 0 24
10 15 2 0 24
10 15 3 0 24
10 15 4 0 24
10 15 5 0 24
10 15 6 0 24
10 15 7 0 24
10 15 8 0 24
10 15 9 0 24
10 15 10 0 24
10 15 11 0 24
10 15 12 0 24
10 15 13 0 24
10 15 14 0 24
10 15 15 0 40
11 0 0 1 80
11 0 1 1 24
11 0 2 1 24
11 0 3 1 24
11 0 4 1 24
11 0 5 1 24
11 0 6 1 24
11 0 7 1 24
11 0 8 1 24
11 0 9 1 24
11 0 10 1 24
11 0 11 1 24
11 0 12 1 24
11 0 13 1 24
11 0 14 1 24
11 0 15 1 48
11 1 0 0 96
11 1 15 0 96
11 2 0 1 96
11 2 15 1 96
11 3 0 0 96
11 3 15 0 96
11 4 0 1 96
11 4 15 1 96
11 5 0 0 96
11 5 15 0 96
11 6 0 1 96
11 6 15 1 96
11 7 0 0 96
11 7 15 0 96
11 8 0 1 96
11 8 15 1 96
11 9 0 0 96
11 9 15 0 96
11 10 0 1 96
11 10 15 1 96
11 11 0 0 96
11 11 15 0 96
11 12 0 1 96
11 12 15 1 96
11 13 0 0 96
11 13 15 0 96
11 14 0 1 96
11 14 15 1 96
11 15 0 0 72
11 15 1 0 24
11 15 2 0 24
11 15 3 0 24
11 15 4 0 24
11 15 5 0 24
11 15 6 0 24
11 15 7 0 24
11 15 8 0 24
11 15 9 0 24
11 15 10 0 24
11 15 11 0 24
11 15 12 0 24
11 15 13 0 24
11 15 14 0 24
11 15 15 0 40
12 0 0 1 80
12 0 1 1 24
12 0 2 1 24
12 0 3 1 24
12 0 4 1 24
12 0 5 1 24
12 0 6 1 24
12 0 7 1 24
12 0 8 1 24
12 0 9 1 24
12 0 10 1 24
12 0 11 1 24
12 0 12 1 24
12 0 13 1 24
12 0 14 1 24
12 0 15 1 48
12 1 0 0 96
12 1 15 0 96
12 2 0 1 96
12 2 15 1 96
12 3 0 0 96
12 3 15 0 96
12 4 0 1 96
12 4 15 1 96
12 5 0 0 96
12 5 15 0 96
12 6 0 1 96
12 6 15 1 96
12 7 0 0 96
12 7 15 0 96
12 8 0 1 96
12 8 15 1 96
12 9 0 0 96
12 9 15 0 96
12 10 0 1 96
12 10 15 1 96
12 11 0 0 96
12 11 15 0 96
12 12 0 1 96
12 12 15 1 96
12 13 0 0 96
12 13 15 0 96
12 14 0 1 96
12 14 15 1 96
12 15 0 0 72
12 15 1 0 24
12 15 2 0 24
12 15 3 0 24
12 15 4 0 24
12 15 5 0 24
12 15 6 0 24
12 15 7 0 24
12 15 8 0 24
12 15 9 0 24
12 15 10 0 24
12 15 11 0 24
12 15 12 0 24
12 15 13 0 24
12 15 14 0 24
12 15 15 0 40
13 0 0 1 80
13 0 1 1 24
13 0 2 1 24
13 0 3 1 24
13 0 4 1 24
13 0 5 1 24
13 0 6 1 24
13 0 7 1 24
13 0 8 1 24
13 0 9 1 24
13 0 10 1 24
13 0 11 1 24
13 0 12 1 24
13 0 13 1 24
13 0 14 1 24
13 0 15 1 48
13 1 0 0 96
13 1 15 0 96
13 2 0 1 96
13 2 15 1 96
13 3 0 0 96
13 3 15 0 96
13 4 0 1 96
13 4 15 1 96
13 5 0 0 96
13 5 15 0 96
13 6 0 1 96
13 6 15 1 96
13 7 0 0 96
13 7 15 0 96
13 8 0 1 96
13 8 15 1 96
13 9 0 0 96
13 9 15 0 96
13 10 0 1 96
13 10 15 1 96
13 11 0 0 96
13 11 15 0 96
13 12 0 1 96
13 12 15 1 96
13 13 0 0 96
13 13 15 0 96
13 14 0 1 96
13 14 15 1 96
13 15 0 0 72
13 15 1 0 24
13 15 2 0 24
13 15 3 0 24
13 15 4 0 24
13 15 5 0 24
13 15 6 0 24
13 15 7 0 24
13 15 8 0 24
13 15 9 0 24
13 15 10 0 24
13 15 11 0 24
13 15 12 0 24
13 15 13 0 24
13 15 14 0 24
13 15 15 0 40
14 0 0 1 80
14 0 1 1 24
14 0 2 1 24
14 0 3 1 24
14 0 4 1 24
14 0 5 1 24
14 0 6 1 24
14 0 7 1 24
14 0 8 1 24
14 0 9 1 24
14 0 10 1 24
14 0 11 1 24
14 0 12 1 24
14 0 13 1 24
14 0 14 1 24
14 0 15 1 48
14 1 0 0 96
14 1 15 0 96
14 2 0 1 96
14 2 15 1 96
14 3 0 0 96
14 3 15 0 96
14 4 0 1 96
14 4 15 1 96
14 5 0 0 96
14 5 15 0 96
14 6 0 1 96
14 6 15 1 96
14 7 0 0 96
14 7 15 0 96
14 8 0 1 96
14 8 15 1 96
14 9 0 0 96
14 9 15 0 96
14 10 0 1 96
14 10 15 1 96
14 11 0 0 96
14 11 15 0 96
14 12 0 1 96
14 12 15 1 96
14 13 0 0 96
14 13 15 0 96
14 14 0 1 96
14 14 15 1 96
14 15 0 0 72
14 15 1 0 24
14 15 2 0 24
14 15 3 0 24
14 15 4 0 24
14 15 5 0 24
14 15 6 0 24
14 15 7 0 24
14 15 8 0 24
14 15 9 0 24
14 15 10 0 24
14 15 11 0 24
14 15 12 0 24
14 15 13 0 24
14 15 14 0 24
14 15 15 0 40
15 0 0 1 82
15 0 1 1 18
15 0 2 1 18
15 0 3 1 18
15 0 4 1 18
15 0 5 1 18
15 0 6 1 18
15 0 7 1 18
15 0 8 1 18
15 0 9 1 18
15 0 10 1 18
15 0 11 1 18
15 0 12 1 18
15 0 13 1 18
15 0 14 1 18
15 0 15 1 50
15 1 0 0 66
15 1 1 0 6
15 1 2 0 6
15 1 3 0 6
15 1 4 0 6
15 1 5 0 6
15 1 6 0 6
15 1 7 0 6
15 1 8 0 6
15 1 9 0 6
15 1 10 0 6
15 1 11 0 6
15 1 12 0 6
15 1 13 0 6
15 1 14 0 6
15 1 15 0 34
15 2 0 1 66
15 2 1 1 6
15 2 2 1 6
15 2 3 1 6
15 2 4 1 6
15 2 5 1 6
15 2 6 1 6
15 2 7 1 6
15 2 8 1 6
15 2 9 1 6
15 2 10 1 6
15 2 11 1 6
15 2 12 1 6
15 2 13 1 6
15 2 14 1 6
15 2 15 1 34
15 3 0 0 66
15 3 1 0 6
15 3 2 0 6
15 3 3 0 6
15 3 4 0 6
15 3 5 0 6
15 3 6 0 6
15 3 7 0 6
15 3 8 0 6
15 3 9 0 6
15 3 10 0 6
15 3 11 0 6
15 3 12 0 6
15 3 13 0 6
15 3 14 0 6
15 3 15 0 34
15 4 0 1 66
15 4 1 1 6
15 4 2 1 6
15 4 3 1 6
15 4 4 1 6
15 4 5 1 6
15 4 6 1 6
15 4 7 1 6
15 4 8 1 6
15 4 9 1 6
15 4 10 1 6
15 4 11 1 6
15 4 12 1 6
15 4 13 1 6
15 4 14 1 6
15 4 15 1 34
15 5 0 0 66
15 5 1 0 6
15 5 2 0 6
15 5 3 0 6
15 5 4 0 6
15 5 5 0 6
15 5 6 0 6
15 5 7 0 6
15 5 8 0 6
15 5 9 0 6
15 5 10 0 6
15 5 11 0 6
15 5 12 0 6
15 5 13 0 6
15 5 14 0 6
15 5 15 0 34
15 6 0 1 66
15 6 1 1 6
15 6 2 1 6
15 6 3 1 6
15 6 4 1 6
15 6 5 1 6
15 6 6 1 6
15 6 7 1 6
15 6 8 1 6
15 6 9 1 6
15 6 10 1 6
15 6 11 1 6
15 6 12 1 6
15 6 13 1 6
15 6 14 1 6
15 6 15 1 34
15 7 0 0 66
15 7 1 0 6
15 7 2 0 6
15 7 3 0 6
15 7 4 0 6
15 7 5 0 6
15 7 6 0 6
15 7 7 0 6
15 7 8 0 6
15 7 9 0 6
15 7 10 0 6
15 7 11 0 6
15 7 12 0 6
15 7 13 0 6
15 7 14 0 6
15 7 15 0 34
15 8 0 1 66
15 8 1 1 6
15 8 2 1 6
15 8 3 1 6
15 8 4 1 6
15 8 5 1 6
15 8 6 1 6
15 8 7 1 6
15 8 8 1 6
15 8 9 1 6
15 8 10 1 6
15 8 11 1 6
15 8 12 1 6
15 8 13 1 6
15 8 14 1 6
15 8 15 1 34
15 9 0 0 66
15 9 1 0 6
15 9 2 0 6
15 9 3 0 6
15 9 4 0 6
15 9 5 0 6
15 9 6 0 6
15 9 7 0 6
15 9 8 0 6
15 9 9 0 6
15 9 10 0 6
15 9 11 0 6
15 9 12 0 6
15 9 13 0 6
15 9 14 0 6
15 9 15 0 34
15 10 0 1 66
15 10 1 1 6
15 10 2 1 6
15 10 3 1 6
15 10 4 1 6
15 10 5 1 6
15 10 6 1 6
15 10 7 1 6
15 10 8 1 6
15 10 9 1 6
15 10 10 1 6
15 10 11 1 6
15 10 12 1 6
15 10 13 1 6
15 10 14 1 6
15 10 15 1 34
15 11 0 0 66
15 11 1 0 6
15 11 2 0 6
15 11 3 0 6
15 11 4 0 6
15 11 5 0 6
15 11 6 0 6
15 11 7 0 6
15 11 8 0 6
15 11 9 0 6
15 11 10 0 6
15 11 11 0 6
15 11 12 0 6
15 11 13 0 6
15 11 14 0 6
15 11 15 0 34
15 12 0 1 66
15 12 1 1 6
15 12 2 1 6
15 12 3 1 6
15 12 4 1 6
15 12 5 1 6
15 12 6 1 6
15 12 7 1 6
15 12 8 1 6
15 12 9 1 6
15 12 10 1 6
15 12 11 1 6
15 12 12 1 6
15 12 13 1 6
15 12 14 1 6
15 12 15 1 34
15 13 0 0 66
15 13 1 0 6
15 13 2 0 6
15 13 3 0 6
15 13 4 0 6
15 13 5 0 6
15 13 6 0 6
15 13 7 0 6
15 13 8 0 6
15 13 9 0 6
15 13 10 0 6
15 13 11 0 6
15 13 12 0 6
15 13 13 0 6
15 13 14 0 6
15 13 15 0 34
15 14 0 1 66
15 14 1 1 6
15 14 2 1 6
15 14 3 1 6
15 14 4 1 6
15 14 5 1 6
15 14 6 1 6
15 14 7 1 6
15 14 8 1 6
15 14 9 1 6
15 14 10 1 6
15 14 11 1 6
15 14 12 1 6
15 14 13 1 6
15 14 14 1 6
15 14 15 1 34
15 15 0 0 74
15 15 1 0 10
15 15 2 0 10
15 15 3 0 10
15 15 4 0 10
15 15 5 0 10
15 15 6 0 10
15 15 7 0 10
15 15 8 0 10
15 15 9 0 10
15 15 10 0 10
15 15 11 0 10
15 15 12 0 10
15 15 13 0 10
15 15 14 0 10
15 15 15 0 42
