Qubicle Exchange Format
Version 0.2
www.minddesk.com
32 8 8
69
0.223529 0.152941 0.000000
0.227451 0.152941 0.000000
0.227451 0.156863 0.000000
0.231373 0.156863 0.000000
0.231373 0.160784 0.000000
0.235294 0.160784 0.000000
0.239216 0.160784 0.000000
0.239216 0.164706 0.000000
0.243137 0.164706 0.000000
0.243137 0.168627 0.000000
0.247059 0.168627 0.000000
0.250980 0.172549 0.000000
0.254902 0.176471 0.003922
0.254902 0.180392 0.007843
0.258824 0.184314 0.011765
0.262745 0.184314 0.015686
0.266667 0.188235 0.019608
0.266667 0.192157 0.023529
0.270588 0.196078 0.027451
0.274510 0.200000 0.031373
0.278431 0.203922 0.035294
0.278431 0.203922 0.039216
0.282353 0.207843 0.043137
0.286275 0.211765 0.047059
0.290196 0.215686 0.050980
0.290196 0.219608 0.054902
0.294118 0.223529 0.058824
0.298039 0.223529 0.062745
0.301961 0.227451 0.066667
0.301961 0.231373 0.070588
0.305882 0.235294 0.074510
0.309804 0.239216 0.078431
0.313726 0.239216 0.082353
0.313726 0.243137 0.086275
0.317647 0.247059 0.090196
0.792157 0.890196 0.564706
0.796078 0.894118 0.568627
0.796078 0.898039 0.568627
0.800000 0.901961 0.572549
0.803922 0.905882 0.572549
0.807843 0.909804 0.576471
0.811765 0.913725 0.580392
0.815686 0.917647 0.580392
0.819608 0.921569 0.584314
0.823529 0.925490 0.588235
0.823529 0.929412 0.588235
0.827451 0.933333 0.592157
0.831373 0.937255 0.592157
0.835294 0.941176 0.596078
0.839216 0.945098 0.600000
0.843137 0.949020 0.600000
0.847059 0.952941 0.603922
0.850980 0.956863 0.607843
0.850980 0.960784 0.607843
0.854902 0.964706 0.611765
0.858824 0.968627 0.611765
0.862745 0.972549 0.615686
0.866667 0.976471 0.619608
0.870588 0.980392 0.619608
0.874510 0.984314 0.623529
0.874510 0.984314 0.627451
0.874510 0.984314 0.631373
0.878431 0.984314 0.635294
0.878431 0.984314 0.639216
0.878431 0.984314 0.643137
0.882353 0.984314 0.647059
0.882353 0.984314 0.650980
0.882353 0.984314 0.654902
0.886275 0.984314 0.658824
0 0 2 3 84
0 0 3 12 20
0 0 4 11 20
0 0 5 10 52
0 1 1 17 84
0 1 2 30 4
0 1 3 18 4
0 1 4 32 4
0 1 5 5 4
0 1 6 0 52
0 2 0 15 84
0 2 1 10 4
0 2 2 62 4
0 2 3 54 4
0 2 4 62 4
0 2 5 61 4
0 2 6 2 4
0 2 7 8 52
0 3 0 8 68
0 3 1 18 4
0 3 2 63 4
0 3 3 59 4
0 3 4 40 4
0 3 5 49 4
0 3 6 13 4
0 3 7 12 36
0 4 0 3 68
0 4 1 25 4
0 4 2 52 4
0 4 3 63 4
0 4 4 55 4
0 4 5 66 4
0 4 6 16 4
0 4 7 23 36
0 5 0 28 76
0 5 1 10 4
0 5 2 58 4
0 5 3 58 4
0 5 4 67 4
0 5 5 59 4
0 5 6 10 4
0 5 7 10 44
0 6 1 30 76
0 6 2 5 4
0 6 3 18 4
0 6 4 12 4
0 6 5 31 4
0 6 6 13 44
0 7 2 5 76
0 7 3 28 12
0 7 4 10 12
0 7 5 5 44
1 0 2 10 80
1 0 3 11 16
1 0 4 32 16
1 0 5 10 48
1 1 1 33 80
1 1 2 9 0
1 1 3 3 0
1 1 4 33 0
1 1 5 28 0
1 1 6 20 48
1 2 0 29 80
1 2 1 10 0
1 2 2 59 0
1 2 3 64 0
1 2 4 67 0
1 2 5 37 0
1 2 6 7 0
1 2 7 8 48
1 3 0 16 64
1 3 1 19 0
1 3 2 64 0
1 3 3 61 0
1 3 4 66 0
1 3 5 61 0
1 3 6 31 0
1 3 7 8 32
1 4 0 2 64
1 4 1 28 0
1 4 2 59 0
1 4 3 51 0
1 4 4 60 0
1 4 5 51 0
1 4 6 5 0
1 4 7 3 32
1 5 0 5 72
1 5 1 1 0
1 5 2 66 0
1 5 3 65 0
1 5 4 47 0
1 5 5 64 0
1 5 6 10 0
1 5 7 27 40
1 6 1 31 72
1 6 2 0 0
1 6 3 12 0
1 6 4 5 0
1 6 5 6 0
1 6 6 20 40
1 7 2 19 72
1 7 3 4 8
1 7 4 26 8
1 7 5 8 40
2 0 2 5 80
2 0 3 2 16
2 0 4 25 16
2 0 5 34 48
2 1 1 8 80
2 1 2 10 0
2 1 3 28 0
2 1 4 4 0
2 1 5 10 0
2 1 6 33 48
2 2 0 32 80
2 2 1 5 0
2 2 2 67 0
2 2 3 61 0
2 2 4 42 0
2 2 5 64 0
2 2 6 14 0
2 2 7 10 48
2 3 0 2 64
2 3 1 5 0
2 3 2 58 0
2 3 3 61 0
2 3 4 63 0
2 3 5 62 0
2 3 6 16 0
2 3 7 4 32
2 4 0 5 64
2 4 1 10 0
2 4 2 46 0
2 4 3 56 0
2 4 4 61 0
2 4 5 45 0
2 4 6 13 0
2 4 7 0 32
2 5 0 5 72
2 5 1 2 0
2 5 2 68 0
2 5 3 38 0
2 5 4 45 0
2 5 5 63 0
2 5 6 10 0
2 5 7 12 40
2 6 1 29 72
2 6 2 12 0
2 6 3 3 0
2 6 4 7 0
2 6 5 22 0
2 6 6 6 40
2 7 2 20 72
2 7 3 2 8
2 7 4 6 8
2 7 5 17 40
3 0 2 5 80
3 0 3 29 16
3 0 4 7 16
3 0 5 9 48
3 1 1 2 80
3 1 2 8 0
3 1 3 5 0
3 1 4 24 0
3 1 5 1 0
3 1 6 0 48
3 2 0 5 80
3 2 1 5 0
3 2 2 60 0
3 2 3 55 0
3 2 4 62 0
3 2 5 61 0
3 2 6 31 0
3 2 7 2 48
3 3 0 18 64
3 3 1 5 0
3 3 2 64 0
3 3 3 40 0
3 3 4 41 0
3 3 5 61 0
3 3 6 34 0
3 3 7 6 32
3 4 0 14 64
3 4 1 2 0
3 4 2 59 0
3 4 3 59 0
3 4 4 67 0
3 4 5 60 0
3 4 6 29 0
3 4 7 3 32
3 5 0 25 72
3 5 1 10 0
3 5 2 59 0
3 5 3 35 0
3 5 4 40 0
3 5 5 65 0
3 5 6 4 0
3 5 7 10 40
3 6 1 19 72
3 6 2 9 0
3 6 3 11 0
3 6 4 2 0
3 6 5 20 0
3 6 6 8 40
3 7 2 3 72
3 7 3 1 8
3 7 4 5 8
3 7 5 5 40
4 0 2 3 80
4 0 3 9 16
4 0 4 14 16
4 0 5 10 48
4 1 1 27 80
4 1 2 7 0
4 1 3 0 0
4 1 4 2 0
4 1 5 26 0
4 1 6 2 48
4 2 0 22 80
4 2 1 7 0
4 2 2 49 0
4 2 3 63 0
4 2 4 60 0
4 2 5 47 0
4 2 6 33 0
4 2 7 23 48
4 3 0 5 64
4 3 1 10 0
4 3 2 61 0
4 3 3 61 0
4 3 4 60 0
4 3 5 40 0
4 3 6 24 0
4 3 7 10 32
4 4 0 5 64
4 4 1 6 0
4 4 2 45 0
4 4 3 63 0
4 4 4 66 0
4 4 5 39 0
4 4 6 2 0
4 4 7 1 32
4 5 0 31 72
4 5 1 27 0
4 5 2 66 0
4 5 3 46 0
4 5 4 38 0
4 5 5 43 0
4 5 6 10 0
4 5 7 22 40
4 6 1 6 72
4 6 2 18 0
4 6 3 12 0
4 6 4 10 0
4 6 5 2 0
4 6 6 6 40
4 7 2 12 72
4 7 3 10 8
4 7 4 34 8
4 7 5 7 40
5 0 2 15 80
5 0 3 18 16
5 0 4 20 16
5 0 5 8 48
5 1 1 27 80
5 1 2 21 0
5 1 3 32 0
5 1 4 14 0
5 1 5 5 0
5 1 6 2 48
5 2 0 8 80
5 2 1 7 0
5 2 2 61 0
5 2 3 53 0
5 2 4 66 0
5 2 5 50 0
5 2 6 1 0
5 2 7 23 48
5 3 0 2 64
5 3 1 32 0
5 3 2 63 0
5 3 3 45 0
5 3 4 62 0
5 3 5 44 0
5 3 6 17 0
5 3 7 13 32
5 4 0 28 64
5 4 1 13 0
5 4 2 67 0
5 4 3 57 0
5 4 4 61 0
5 4 5 60 0
5 4 6 33 0
5 4 7 3 32
5 5 0 12 72
5 5 1 5 0
5 5 2 64 0
5 5 3 35 0
5 5 4 42 0
5 5 5 48 0
5 5 6 2 0
5 5 7 10 40
5 6 1 3 72
5 6 2 8 0
5 6 3 33 0
5 6 4 12 0
5 6 5 13 0
5 6 6 31 40
5 7 2 21 72
5 7 3 27 8
5 7 4 14 8
5 7 5 17 40
6 0 2 25 80
6 0 3 8 16
6 0 4 3 16
6 0 5 18 48
6 1 1 24 80
6 1 2 17 0
6 1 3 32 0
6 1 4 30 0
6 1 5 3 0
6 1 6 2 48
6 2 0 10 80
6 2 1 19 0
6 2 2 52 0
6 2 3 38 0
6 2 4 64 0
6 2 5 53 0
6 2 6 5 0
6 2 7 10 48
6 3 0 15 64
6 3 1 12 0
6 3 2 59 0
6 3 3 65 0
6 3 4 61 0
6 3 5 56 0
6 3 6 10 0
6 3 7 25 32
6 4 0 6 64
6 4 1 6 0
6 4 2 66 0
6 4 3 68 0
6 4 4 65 0
6 4 5 40 0
6 4 6 3 0
6 4 7 26 32
6 5 0 5 72
6 5 1 12 0
6 5 2 63 0
6 5 3 42 0
6 5 4 65 0
6 5 5 66 0
6 5 6 3 0
6 5 7 8 40
6 6 1 26 72
6 6 2 34 0
6 6 3 29 0
6 6 4 21 0
6 6 5 2 0
6 6 6 3 40
6 7 2 31 72
6 7 3 8 8
6 7 4 6 8
6 7 5 19 40
7 0 2 32 80
7 0 3 13 16
7 0 4 3 16
7 0 5 9 48
7 1 1 17 80
7 1 2 5 0
7 1 3 30 0
7 1 4 20 0
7 1 5 1 0
7 1 6 7 48
7 2 0 14 80
7 2 1 26 0
7 2 2 64 0
7 2 3 52 0
7 2 4 58 0
7 2 5 55 0
7 2 6 19 0
7 2 7 21 48
7 3 0 7 64
7 3 1 1 0
7 3 2 66 0
7 3 3 61 0
7 3 4 66 0
7 3 5 68 0
7 3 6 9 0
7 3 7 18 32
7 4 0 16 64
7 4 1 7 0
7 4 2 67 0
7 4 3 58 0
7 4 4 60 0
7 4 5 36 0
7 4 6 34 0
7 4 7 2 32
7 5 0 19 72
7 5 1 9 0
7 5 2 51 0
7 5 3 52 0
7 5 4 61 0
7 5 5 54 0
7 5 6 5 0
7 5 7 10 40
7 6 1 8 72
7 6 2 21 0
7 6 3 3 0
7 6 4 7 0
7 6 5 10 0
7 6 6 10 40
7 7 2 17 72
7 7 3 3 8
7 7 4 10 8
7 7 5 15 40
8 0 2 3 80
8 0 3 13 16
8 0 4 2 16
8 0 5 7 48
8 1 1 5 80
8 1 2 33 0
8 1 3 2 0
8 1 4 2 0
8 1 5 5 0
8 1 6 8 48
8 2 0 1 80
8 2 1 31 0
8 2 2 49 0
8 2 3 47 0
8 2 4 68 0
8 2 5 63 0
8 2 6 23 0
8 2 7 10 48
8 3 0 10 64
8 3 1 3 0
8 3 2 56 0
8 3 3 61 0
8 3 4 56 0
8 3 5 60 0
8 3 6 14 0
8 3 7 9 32
8 4 0 17 64
8 4 1 8 0
8 4 2 63 0
8 4 3 67 0
8 4 4 67 0
8 4 5 64 0
8 4 6 30 0
8 4 7 14 32
8 5 0 28 72
8 5 1 21 0
8 5 2 63 0
8 5 3 68 0
8 5 4 67 0
8 5 5 66 0
8 5 6 15 0
8 5 7 7 40
8 6 1 32 72
8 6 2 29 0
8 6 3 8 0
8 6 4 3 0
8 6 5 18 0
8 6 6 34 40
8 7 2 7 72
8 7 3 19 8
8 7 4 1 8
8 7 5 5 40
9 0 2 10 80
9 0 3 32 16
9 0 4 3 16
9 0 5 27 48
9 1 1 19 80
9 1 2 19 0
9 1 3 16 0
9 1 4 10 0
9 1 5 14 0
9 1 6 7 48
9 2 0 10 80
9 2 1 28 0
9 2 2 47 0
9 2 3 51 0
9 2 4 57 0
9 2 5 59 0
9 2 6 2 0
9 2 7 7 48
9 3 0 21 64
9 3 1 17 0
9 3 2 62 0
9 3 3 36 0
9 3 4 42 0
9 3 5 42 0
9 3 6 21 0
9 3 7 32 32
9 4 0 6 64
9 4 1 28 0
9 4 2 63 0
9 4 3 35 0
9 4 4 41 0
9 4 5 60 0
9 4 6 26 0
9 4 7 26 32
9 5 0 7 72
9 5 1 5 0
9 5 2 62 0
9 5 3 41 0
9 5 4 47 0
9 5 5 59 0
9 5 6 5 0
9 5 7 17 40
9 6 1 8 72
9 6 2 11 0
9 6 3 18 0
9 6 4 30 0
9 6 5 14 0
9 6 6 7 40
9 7 2 11 72
9 7 3 9 8
9 7 4 28 8
9 7 5 5 40
10 0 2 30 80
10 0 3 19 16
10 0 4 23 16
10 0 5 12 48
10 1 1 17 80
10 1 2 22 0
10 1 3 4 0
10 1 4 2 0
10 1 5 33 0
10 1 6 10 48
10 2 0 8 80
10 2 1 8 0
10 2 2 59 0
10 2 3 59 0
10 2 4 45 0
10 2 5 63 0
10 2 6 18 0
10 2 7 12 48
10 3 0 7 64
10 3 1 3 0
10 3 2 41 0
10 3 3 60 0
10 3 4 64 0
10 3 5 64 0
10 3 6 9 0
10 3 7 1 32
10 4 0 30 64
10 4 1 19 0
10 4 2 56 0
10 4 3 65 0
10 4 4 59 0
10 4 5 59 0
10 4 6 6 0
10 4 7 2 32
10 5 0 2 72
10 5 1 2 0
10 5 2 67 0
10 5 3 67 0
10 5 4 59 0
10 5 5 59 0
10 5 6 28 0
10 5 7 0 42
10 6 1 29 72
10 6 2 25 0
10 6 3 18 0
10 6 4 8 0
10 6 5 15 0
10 6 6 11 40
10 7 2 10 72
10 7 3 22 8
10 7 4 17 8
10 7 5 8 40
11 0 2 1 80
11 0 3 22 16
11 0 4 3 16
11 0 5 29 48
11 1 1 6 80
11 1 2 22 0
11 1 3 10 0
11 1 4 28 0
11 1 5 18 0
11 1 6 33 48
11 2 0 28 80
11 2 1 18 0
11 2 2 52 0
11 2 3 60 0
11 2 4 59 0
11 2 5 54 0
11 2 6 16 0
11 2 7 9 48
11 3 0 22 64
11 3 1 23 0
11 3 2 47 0
11 3 3 48 0
11 3 4 62 0
11 3 5 48 0
11 3 6 3 0
11 3 7 8 32
11 4 0 8 64
11 4 1 34 0
11 4 2 43 0
11 4 3 63 0
11 4 4 43 0
11 4 5 36 0
11 4 6 25 2
11 4 7 19 40
11 5 0 29 72
11 5 1 12 0
11 5 2 40 0
11 5 3 64 0
11 5 4 37 0
11 5 5 61 0
11 5 6 33 34
11 6 1 16 72
11 6 2 32 0
11 6 3 30 0
11 6 4 10 0
11 6 5 2 0
11 6 6 5 42
11 7 2 29 72
11 7 3 7 8
11 7 4 5 8
11 7 5 26 40
12 0 2 7 82
12 0 3 6 16
12 0 4 9 16
12 0 5 10 48
12 1 1 6 80
12 1 2 3 2
12 1 3 3 0
12 1 4 13 0
12 1 5 10 0
12 1 6 12 48
12 2 0 24 80
12 2 1 3 0
12 2 2 60 0
12 2 3 45 0
12 2 4 63 0
12 2 5 62 0
12 2 6 19 0
12 2 7 8 48
12 3 0 31 64
12 3 1 3 0
12 3 2 56 0
12 3 3 37 0
12 3 4 62 0
12 3 5 63 0
12 3 6 17 8
12 3 7 17 32
12 4 0 1 64
12 4 1 4 0
12 4 2 46 0
12 4 3 41 0
12 4 4 59 0
12 4 5 58 32
12 4 7 7 104
12 5 0 24 72
12 5 1 8 0
12 5 2 63 0
12 5 3 59 0
12 5 4 42 0
12 5 5 56 32
12 6 1 4 72
12 6 2 17 0
12 6 3 2 0
12 6 4 10 0
12 6 5 29 34
12 7 2 25 72
12 7 3 10 8
12 7 4 22 8
12 7 5 5 40
13 0 3 3 80
13 0 4 25 16
13 0 5 13 48
13 1 1 34 112
13 1 3 5 64
13 1 4 31 0
13 1 5 27 0
13 1 6 10 48
13 2 0 7 80
13 2 1 20 0
13 2 2 52 16
13 2 3 58 0
13 2 4 44 0
13 2 5 62 0
13 2 6 7 0
13 2 7 25 48
13 3 0 23 64
13 3 1 2 0
13 3 2 67 0
13 3 3 68 0
13 3 4 63 0
13 3 5 60 0
13 3 6 2 8
13 3 7 11 32
13 4 0 17 64
13 4 1 34 0
13 4 2 59 0
13 4 3 63 0
13 4 4 39 0
13 4 5 66 32
13 4 7 32 104
13 5 0 34 72
13 5 1 20 0
13 5 2 38 0
13 5 3 59 0
13 5 4 66 0
13 5 5 57 40
13 6 1 12 72
13 6 2 22 0
13 6 3 1 0
13 6 4 16 32
13 7 2 7 72
13 7 3 30 8
13 7 4 2 8
13 7 5 0 56
14 0 3 14 80
14 0 4 19 16
14 0 5 14 48
14 1 1 24 112
14 1 3 7 64
14 1 4 31 0
14 1 5 28 0
14 1 6 24 48
14 2 0 1 80
14 2 1 18 0
14 2 2 35 16
14 2 3 64 0
14 2 4 64 0
14 2 5 63 0
14 2 6 0 0
14 2 7 20 48
14 3 0 20 64
14 3 1 24 0
14 3 2 47 0
14 3 3 60 0
14 3 4 68 0
14 3 5 59 0
14 3 6 21 8
14 3 7 6 32
14 4 0 10 64
14 4 1 2 0
14 4 2 41 0
14 4 3 56 0
14 4 4 61 0
14 4 5 45 32
14 4 7 21 104
14 5 0 18 72
14 5 1 2 0
14 5 2 40 0
14 5 3 60 0
14 5 4 51 0
14 5 5 36 32
14 6 1 20 72
14 6 2 24 0
14 6 3 2 0
14 6 4 25 0
14 6 5 8 36
14 7 2 28 72
14 7 3 10 8
14 7 4 1 8
14 7 5 34 40
15 0 3 2 80
15 0 4 34 16
15 0 5 13 48
15 1 1 25 112
15 1 3 18 64
15 1 4 33 0
15 1 5 14 0
15 1 6 5 48
15 2 0 8 80
15 2 1 4 0
15 2 2 40 16
15 2 3 41 0
15 2 4 67 0
15 2 5 63 0
15 2 6 31 0
15 2 7 1 48
15 3 0 28 64
15 3 1 10 0
15 3 2 45 0
15 3 3 67 0
15 3 4 61 0
15 3 5 43 0
15 3 6 27 8
15 3 7 5 32
15 4 0 23 64
15 4 1 8 0
15 4 2 43 0
15 4 3 63 0
15 4 4 64 0
15 4 5 50 32
15 4 7 8 104
15 5 0 0 72
15 5 1 2 0
15 5 2 43 0
15 5 3 66 0
15 5 4 47 0
15 5 5 37 32
15 6 1 17 72
15 6 2 2 0
15 6 3 33 0
15 6 4 10 0
15 6 5 19 32
15 7 2 30 72
15 7 3 28 8
15 7 4 34 8
15 7 5 10 40
16 0 3 30 80
16 0 4 12 16
16 0 5 11 48
16 1 1 7 112
16 1 3 10 66
16 1 4 0 0
16 1 5 26 0
16 1 6 3 48
16 2 0 3 80
16 2 1 7 0
16 2 2 67 16
16 2 3 37 0
16 2 4 42 0
16 2 5 64 0
16 2 6 33 0
16 2 7 5 48
16 3 0 8 64
16 3 1 12 0
16 3 2 50 0
16 3 3 43 0
16 3 4 64 0
16 3 5 47 0
16 3 6 3 8
16 3 7 28 32
16 4 0 34 64
16 4 1 4 0
16 4 2 59 0
16 4 3 67 0
16 4 4 61 0
16 4 5 65 32
16 4 7 15 104
16 5 0 32 72
16 5 1 8 0
16 5 2 44 0
16 5 3 59 0
16 5 4 45 0
16 5 5 66 32
16 6 1 2 72
16 6 2 18 0
16 6 3 10 0
16 6 4 30 0
16 6 5 5 32
16 7 2 2 72
16 7 3 9 8
16 7 4 1 8
16 7 5 27 40
17 0 3 16 88
17 0 4 8 16
17 0 5 4 48
17 1 1 31 112
17 1 4 28 64
17 1 5 10 0
17 1 6 4 48
17 2 0 27 80
17 2 1 27 0
17 2 2 39 18
17 2 3 41 16
17 2 4 43 0
17 2 5 63 0
17 2 6 7 0
17 2 7 10 48
17 3 0 10 64
17 3 1 13 0
17 3 2 61 0
17 3 3 60 0
17 3 4 65 0
17 3 5 66 0
17 3 6 10 0
17 3 7 8 32
17 4 0 23 64
17 4 1 8 0
17 4 2 66 0
17 4 3 67 0
17 4 4 42 0
17 4 5 60 0
17 4 6 19 4
17 4 7 24 40
17 5 0 9 72
17 5 1 5 0
17 5 2 55 0
17 5 3 66 0
17 5 4 37 0
17 5 5 59 0
17 5 6 5 36
17 6 1 3 72
17 6 2 24 0
17 6 3 10 0
17 6 4 2 0
17 6 5 15 0
17 6 6 4 44
17 7 2 2 72
17 7 3 33 8
17 7 4 17 8
17 7 5 4 40
18 0 3 21 90
18 0 4 7 16
18 0 5 3 48
18 1 1 33 112
18 1 4 10 64
18 1 5 5 0
18 1 6 31 48
18 2 0 18 80
18 2 1 4 32
18 2 3 64 80
18 2 4 42 0
18 2 5 42 0
18 2 6 7 0
18 2 7 7 48
18 3 0 28 64
18 3 1 2 0
18 3 2 38 16
18 3 3 57 0
18 3 4 63 0
18 3 5 38 0
18 3 6 31 0
18 3 7 5 32
18 4 0 10 64
18 4 1 7 0
18 4 2 47 0
18 4 3 56 0
18 4 4 48 0
18 4 5 66 0
18 4 6 33 0
18 4 7 7 32
18 5 0 10 72
18 5 1 31 0
18 5 2 46 0
18 5 3 55 0
18 5 4 65 0
18 5 5 67 0
18 5 6 21 0
18 5 7 31 44
18 6 1 5 72
18 6 2 14 0
18 6 3 9 0
18 6 4 24 0
18 6 5 5 0
18 6 6 27 40
18 7 2 21 72
18 7 3 2 8
18 7 4 31 8
18 7 5 5 40
19 0 4 28 80
19 0 5 3 48
19 1 1 8 112
19 1 3 0 84
19 1 4 5 0
19 1 5 10 0
19 1 6 16 48
19 2 0 28 80
19 2 1 6 0
19 2 2 59 20
19 2 3 35 0
19 2 4 48 0
19 2 5 57 0
19 2 6 3 0
19 2 7 7 48
19 3 0 16 64
19 3 1 24 0
19 3 2 58 0
19 3 3 60 0
19 3 4 67 0
19 3 5 38 0
19 3 6 21 0
19 3 7 18 32
19 4 0 5 64
19 4 1 7 0
19 4 2 54 0
19 4 3 54 0
19 4 4 50 0
19 4 5 64 0
19 4 6 1 0
19 4 7 21 32
19 5 0 0 72
19 5 1 16 0
19 5 2 64 0
19 5 3 63 0
19 5 4 66 0
19 5 5 61 0
19 5 6 3 0
19 5 7 30 40
19 6 1 19 72
19 6 2 8 0
19 6 3 7 0
19 6 4 26 0
19 6 5 12 0
19 6 6 19 40
19 7 2 24 72
19 7 3 34 8
19 7 4 8 8
19 7 5 2 40
20 0 3 20 84
20 0 4 7 16
20 0 5 8 48
20 1 1 31 112
20 1 3 20 64
20 1 4 19 0
20 1 5 30 0
20 1 6 26 48
20 2 0 14 80
20 2 1 5 0
20 2 2 60 16
20 2 3 68 0
20 2 4 62 0
20 2 5 63 0
20 2 6 28 0
20 2 7 5 48
20 3 0 0 64
20 3 1 28 0
20 3 2 38 0
20 3 3 55 0
20 3 4 60 0
20 3 5 62 0
20 3 6 10 0
20 3 7 13 32
20 4 0 10 64
20 4 1 3 0
20 4 2 61 0
20 4 3 67 0
20 4 4 45 0
20 4 5 52 0
20 4 6 30 0
20 4 7 1 32
20 5 0 28 72
20 5 1 31 0
20 5 2 43 0
20 5 3 52 0
20 5 4 59 0
20 5 5 53 0
20 5 6 26 0
20 5 7 26 40
20 6 1 7 72
20 6 2 15 0
20 6 3 3 0
20 6 4 10 0
20 6 5 10 0
20 6 6 3 40
20 7 2 18 72
20 7 3 8 8
20 7 4 6 8
20 7 5 2 40
21 0 2 5 84
21 0 3 8 16
21 0 4 9 16
21 0 5 26 48
21 1 1 6 80
21 1 2 22 4
21 1 3 2 0
21 1 4 5 0
21 1 5 12 0
21 1 6 5 48
21 2 0 27 80
21 2 1 2 0
21 2 2 59 0
21 2 3 47 0
21 2 4 52 0
21 2 5 45 0
21 2 6 1 0
21 2 7 25 48
21 3 0 10 64
21 3 1 9 0
21 3 2 57 0
21 3 3 67 0
21 3 4 45 0
21 3 5 40 0
21 3 6 3 0
21 3 7 10 32
21 4 0 5 64
21 4 1 10 0
21 4 2 60 0
21 4 3 38 0
21 4 4 58 0
21 4 5 59 0
21 4 6 9 0
21 4 7 4 32
21 5 0 23 72
21 5 1 13 0
21 5 2 59 0
21 5 3 59 0
21 5 4 64 0
21 5 5 62 0
21 5 6 7 0
21 5 7 24 40
21 6 1 6 72
21 6 2 11 0
21 6 3 8 0
21 6 4 32 0
21 6 5 2 0
21 6 6 16 40
21 7 2 8 72
21 7 3 8 8
21 7 4 5 8
21 7 5 31 40
22 0 2 8 80
22 0 3 29 16
22 0 4 12 16
22 0 5 26 48
22 1 1 7 80
22 1 2 10 0
22 1 3 32 0
22 1 4 19 0
22 1 5 3 0
22 1 6 9 48
22 2 0 11 80
22 2 1 5 0
22 2 2 59 0
22 2 3 57 0
22 2 4 66 0
22 2 5 46 0
22 2 6 19 0
22 2 7 20 48
22 3 0 21 64
22 3 1 28 0
22 3 2 59 0
22 3 3 54 0
22 3 4 42 0
22 3 5 43 0
22 3 6 3 0
22 3 7 7 32
22 4 0 18 64
22 4 1 17 0
22 4 2 45 0
22 4 3 36 0
22 4 4 64 0
22 4 5 48 0
22 4 6 32 0
22 4 7 7 32
22 5 0 29 72
22 5 1 13 0
22 5 2 47 0
22 5 3 51 0
22 5 4 57 0
22 5 5 41 0
22 5 6 11 0
22 5 7 29 40
22 6 1 17 72
22 6 2 2 0
22 6 3 31 0
22 6 4 3 0
22 6 5 11 0
22 6 6 4 40
22 7 2 34 72
22 7 3 10 8
22 7 4 8 8
22 7 5 14 40
23 0 2 5 80
23 0 3 12 16
23 0 4 23 16
23 0 5 8 48
23 1 1 10 80
23 1 2 6 0
23 1 3 13 0
23 1 4 8 0
23 1 5 10 0
23 1 6 7 48
23 2 0 2 80
23 2 1 16 0
23 2 2 44 0
23 2 3 67 0
23 2 4 59 0
23 2 5 51 0
23 2 6 8 0
23 2 7 3 48
23 3 0 22 64
23 3 1 22 0
23 3 2 60 0
23 3 3 57 0
23 3 4 45 0
23 3 5 43 0
23 3 6 11 0
23 3 7 16 32
23 4 0 17 64
23 4 1 1 0
23 4 2 62 0
23 4 3 48 0
23 4 4 36 0
23 4 5 56 0
23 4 6 28 0
23 4 7 0 32
23 5 0 5 72
23 5 1 17 0
23 5 2 65 0
23 5 3 54 0
23 5 4 59 0
23 5 5 52 0
23 5 6 8 0
23 5 7 7 40
23 6 1 10 72
23 6 2 4 0
23 6 3 10 0
23 6 4 10 0
23 6 5 5 0
23 6 6 8 40
23 7 2 3 72
23 7 3 5 8
23 7 4 7 8
23 7 5 2 40
24 0 2 28 80
24 0 3 16 16
24 0 4 32 16
24 0 5 5 48
24 1 1 29 80
24 1 2 7 0
24 1 3 9 0
24 1 4 22 0
24 1 5 16 0
24 1 6 16 48
24 2 0 29 80
24 2 1 3 0
24 2 2 60 0
24 2 3 63 0
24 2 4 62 0
24 2 5 64 0
24 2 6 3 0
24 2 7 25 48
24 3 0 31 64
24 3 1 21 0
24 3 2 55 0
24 3 3 35 0
24 3 4 41 0
24 3 5 66 0
24 3 6 5 0
24 3 7 4 32
24 4 0 7 64
24 4 1 1 0
24 4 2 43 0
24 4 3 61 0
24 4 4 47 0
24 4 5 49 0
24 4 6 12 0
24 4 7 27 32
24 5 0 10 72
24 5 1 34 0
24 5 2 63 0
24 5 3 60 0
24 5 4 57 0
24 5 5 64 0
24 5 6 2 0
24 5 7 2 40
24 6 1 10 72
24 6 2 2 0
24 6 3 0 0
24 6 4 9 0
24 6 5 10 0
24 6 6 25 40
24 7 2 22 72
24 7 3 6 8
24 7 4 17 8
24 7 5 4 40
25 0 2 3 80
25 0 3 27 16
25 0 4 34 16
25 0 5 11 48
25 1 1 12 80
25 1 2 25 0
25 1 3 28 0
25 1 4 15 0
25 1 5 10 0
25 1 6 2 48
25 2 0 24 80
25 2 1 34 0
25 2 2 64 0
25 2 3 55 0
25 2 4 63 0
25 2 5 63 0
25 2 6 5 0
25 2 7 25 48
25 3 0 1 64
25 3 1 32 0
25 3 2 54 0
25 3 3 62 0
25 3 4 39 0
25 3 5 54 0
25 3 6 2 0
25 3 7 4 32
25 4 0 7 64
25 4 1 3 0
25 4 2 64 0
25 4 3 61 0
25 4 4 66 0
25 4 5 47 0
25 4 6 5 0
25 4 7 26 32
25 5 0 7 72
25 5 1 26 0
25 5 2 38 0
25 5 3 51 0
25 5 4 61 0
25 5 5 59 0
25 5 6 3 0
25 5 7 8 40
25 6 1 12 72
25 6 2 30 0
25 6 3 20 0
25 6 4 17 0
25 6 5 8 0
25 6 6 27 40
25 7 2 8 72
25 7 3 8 8
25 7 4 30 8
25 7 5 10 40
26 0 2 13 80
26 0 3 3 16
26 0 4 18 16
26 0 5 2 48
26 1 1 26 80
26 1 2 8 0
26 1 3 28 0
26 1 4 10 0
26 1 5 26 0
26 1 6 11 48
26 2 0 10 80
26 2 1 2 0
26 2 2 55 0
26 2 3 55 0
26 2 4 66 0
26 2 5 67 0
26 2 6 11 0
26 2 7 1 48
26 3 0 10 64
26 3 1 34 0
26 3 2 66 0
26 3 3 48 0
26 3 4 59 0
26 3 5 61 0
26 3 6 2 0
26 3 7 2 32
26 4 0 8 64
26 4 1 10 0
26 4 2 63 0
26 4 3 50 0
26 4 4 52 0
26 4 5 64 0
26 4 6 32 0
26 4 7 2 32
26 5 0 30 72
26 5 1 7 0
26 5 2 66 0
26 5 3 60 0
26 5 4 65 0
26 5 5 61 0
26 5 6 10 0
26 5 7 10 40
26 6 1 4 72
26 6 2 15 0
26 6 3 27 0
26 6 4 2 0
26 6 5 21 0
26 6 6 19 40
26 7 2 10 72
26 7 3 19 8
26 7 4 29 8
26 7 5 7 40
27 0 2 7 80
27 0 3 12 16
27 0 4 18 16
27 0 5 23 48
27 1 1 16 80
27 1 2 13 0
27 1 3 20 0
27 1 4 7 0
27 1 5 30 0
27 1 6 2 48
27 2 0 10 80
27 2 1 8 0
27 2 2 65 0
27 2 3 59 0
27 2 4 57 0
27 2 5 55 0
27 2 6 27 0
27 2 7 27 48
27 3 0 32 64
27 3 1 10 0
27 3 2 60 0
27 3 3 68 0
27 3 4 64 0
27 3 5 39 0
27 3 6 9 0
27 3 7 21 32
27 4 0 24 64
27 4 1 4 0
27 4 2 64 0
27 4 3 63 0
27 4 4 53 0
27 4 5 53 0
27 4 6 5 0
27 4 7 22 32
27 5 0 14 72
27 5 1 3 0
27 5 2 64 0
27 5 3 47 0
27 5 4 45 0
27 5 5 64 0
27 5 6 7 0
27 5 7 13 40
27 6 1 9 72
27 6 2 11 0
27 6 3 10 0
27 6 4 0 0
27 6 5 30 0
27 6 6 9 40
27 7 2 5 72
27 7 3 8 8
27 7 4 30 8
27 7 5 5 40
28 0 2 10 80
28 0 3 20 16
28 0 4 5 16
28 0 5 11 48
28 1 1 9 82
28 1 2 29 0
28 1 3 0 0
28 1 4 9 0
28 1 5 20 0
28 1 6 19 48
28 2 0 2 80
28 2 1 8 0
28 2 2 35 0
28 2 3 59 0
28 2 4 66 0
28 2 5 48 0
28 2 6 5 0
28 2 7 27 48
28 3 0 10 64
28 3 1 10 2
28 3 2 42 0
28 3 3 67 0
28 3 4 42 0
28 3 5 68 0
28 3 6 6 0
28 3 7 2 32
28 4 0 10 64
28 4 1 8 2
28 4 2 45 0
28 4 3 43 0
28 4 4 59 0
28 4 5 59 0
28 4 6 34 0
28 4 7 2 32
28 5 0 2 72
28 5 1 25 2
28 5 2 62 0
28 5 3 59 0
28 5 4 59 0
28 5 5 67 0
28 5 6 4 0
28 5 7 7 42
28 6 1 25 72
28 6 2 32 0
28 6 3 24 0
28 6 4 20 0
28 6 5 25 0
28 6 6 33 40
28 7 2 7 72
28 7 3 21 8
28 7 4 2 8
28 7 5 11 40
29 0 2 1 82
29 0 3 7 16
29 0 4 7 16
29 0 5 20 48
29 1 2 10 64
29 1 3 2 0
29 1 4 22 0
29 1 5 15 0
29 1 6 7 48
29 2 0 23 82
29 2 1 7 26
29 2 2 47 0
29 2 3 55 0
29 2 4 59 0
29 2 5 51 0
29 2 6 26 0
29 2 7 24 50
29 3 0 25 98
29 3 2 58 64
29 3 3 57 0
29 3 4 48 0
29 3 5 44 0
29 3 6 7 0
29 3 7 13 32
29 4 0 10 98
29 4 2 61 64
29 4 3 42 0
29 4 4 47 0
29 4 5 59 0
29 4 6 25 0
29 4 7 2 42
29 5 0 22 106
29 5 2 56 64
29 5 3 66 0
29 5 4 61 0
29 5 5 52 0
29 5 6 18 32
29 6 1 19 90
29 6 2 7 0
29 6 3 9 0
29 6 4 32 0
29 6 5 10 2
29 6 6 5 42
29 7 2 10 74
29 7 3 14 10
29 7 4 2 10
29 7 5 11 42
30 0 3 2 82
30 0 4 10 18
30 0 5 22 50
30 1 2 23 82
30 1 3 11 2
30 1 4 32 2
30 1 5 17 2
30 1 6 10 50
30 2 2 60 66
30 2 3 66 2
30 2 4 56 2
30 2 5 61 2
30 2 6 8 34
30 3 2 65 66
30 3 3 67 2
30 3 4 62 2
30 3 5 66 2
30 3 6 3 2
30 3 7 27 58
30 4 2 62 66
30 4 3 66 2
30 4 4 60 2
30 4 5 67 2
30 4 6 32 34
30 5 2 66 66
30 5 3 41 2
30 5 4 60 2
30 5 5 60 10
30 5 6 28 42
30 6 2 32 74
30 6 3 8 10
30 6 4 24 42
