Qubicle Exchange Format
Version 0.2
www.minddesk.com
16 32 16
25
0.239216 0.239216 0.239216
0.243137 0.243137 0.243137
0.247059 0.247059 0.247059
0.250980 0.250980 0.250980
0.254902 0.254902 0.254902
0.258824 0.258824 0.258824
0.262745 0.262745 0.262745
0.266667 0.266667 0.266667
0.270588 0.270588 0.270588
0.274510 0.274510 0.274510
0.278431 0.278431 0.278431
0.282353 0.282353 0.282353
0.286275 0.286275 0.286275
0.290196 0.290196 0.290196
0.294118 0.294118 0.294118
0.298039 0.298039 0.298039
0.301961 0.301961 0.301961
0.305882 0.305882 0.305882
0.309804 0.309804 0.309804
0.313726 0.313726 0.313726
0.317647 0.317647 0.317647
0.321569 0.321569 0.321569
0.325490 0.325490 0.325490
0.329412 0.329412 0.329412
0.333333 0.333333 0.333333
2 0 4 23 84
2 0 5 4 20
2 0 6 19 20
2 0 7 3 20
2 0 8 9 20
2 0 9 3 20
2 0 10 11 20
2 0 11 3 52
2 1 4 1 68
2 1 5 22 4
2 1 6 11 4
2 1 7 1 4
2 1 8 21 4
2 1 9 15 4
2 1 10 2 4
2 1 11 24 36
2 2 4 15 68
2 2 5 1 4
2 2 6 7 4
2 2 7 9 4
2 2 8 24 4
2 2 9 24 4
2 2 10 5 4
2 2 11 0 36
2 3 4 4 68
2 3 5 6 4
2 3 6 21 4
2 3 7 19 4
2 3 8 4 4
2 3 9 0 4
2 3 10 2 4
2 3 11 0 36
2 4 4 21 68
2 4 5 1 4
2 4 6 5 4
2 4 7 2 4
2 4 8 6 4
2 4 9 20 4
2 4 10 3 4
2 4 11 21 36
2 5 4 4 68
2 5 5 9 4
2 5 6 22 4
2 5 7 9 4
2 5 8 1 4
2 5 9 6 4
2 5 10 21 4
2 5 11 6 36
2 6 4 16 68
2 6 5 0 4
2 6 6 17 4
2 6 7 5 4
2 6 8 18 4
2 6 9 5 4
2 6 10 0 4
2 6 11 2 36
2 7 4 23 68
2 7 5 7 4
2 7 6 9 4
2 7 7 3 4
2 7 8 22 4
2 7 9 0 4
2 7 10 14 4
2 7 11 22 36
2 8 4 21 68
2 8 5 12 4
2 8 6 3 4
2 8 7 4 4
2 8 8 6 4
2 8 9 3 4
2 8 10 3 4
2 8 11 13 36
2 9 4 8 68
2 9 5 15 4
2 9 6 0 4
2 9 7 5 4
2 9 8 1 4
2 9 9 4 4
2 9 10 21 12
2 9 11 6 36
2 10 4 3 68
2 10 5 21 4
2 10 6 3 4
2 10 7 17 4
2 10 8 6 4
2 10 9 19 44
2 10 11 18 110
2 11 4 15 68
2 11 5 12 4
2 11 6 14 4
2 11 7 11 12
2 11 8 15 44
2 12 4 12 76
2 12 5 6 12
2 12 6 16 44
3 0 3 20 84
3 0 4 9 16
3 0 5 4 16
3 0 6 4 16
3 0 7 3 16
3 0 8 3 16
3 0 9 19 16
3 0 10 11 16
3 0 11 5 48
3 1 3 6 68
3 1 4 14 0
3 1 5 13 0
3 1 6 9 0
3 1 7 23 0
3 1 8 3 0
3 1 9 1 0
3 1 10 6 0
3 1 11 12 32
3 2 3 3 68
3 2 4 8 0
3 2 5 15 0
3 2 6 3 0
3 2 7 18 0
3 2 8 19 0
3 2 9 23 0
3 2 10 14 0
3 2 11 6 32
3 3 3 23 68
3 3 4 23 0
3 3 5 14 0
3 3 6 1 0
3 3 7 5 0
3 3 8 4 0
3 3 9 11 0
3 3 10 16 0
3 3 11 8 32
3 4 3 4 68
3 4 4 1 0
3 4 5 6 0
3 4 6 14 0
3 4 7 3 0
3 4 8 12 0
3 4 9 6 0
3 4 10 10 0
3 4 11 24 32
3 5 3 24 68
3 5 4 4 0
3 5 5 21 0
3 5 6 9 0
3 5 7 15 0
3 5 8 18 0
3 5 9 12 0
3 5 10 8 0
3 5 11 14 32
3 6 3 6 68
3 6 4 4 0
3 6 5 11 0
3 6 6 3 0
3 6 7 13 0
3 6 8 22 0
3 6 9 14 0
3 6 10 0 0
3 6 11 11 32
3 7 3 2 68
3 7 4 1 0
3 7 5 23 0
3 7 6 1 0
3 7 7 5 0
3 7 8 2 0
3 7 9 6 0
3 7 10 4 0
3 7 11 10 32
3 8 3 9 68
3 8 4 1 0
3 8 5 10 0
3 8 6 10 0
3 8 7 2 0
3 8 8 6 0
3 8 9 4 0
3 8 10 2 0
3 8 11 4 32
3 9 3 5 68
3 9 4 5 0
3 9 5 4 0
3 9 6 5 0
3 9 7 1 0
3 9 8 1 0
3 9 9 2 0
3 9 10 3 0
3 9 11 0 40
3 10 3 5 68
3 10 4 14 0
3 10 5 16 0
3 10 6 22 0
3 10 7 1 0
3 10 8 4 0
3 10 9 8 0
3 10 10 3 44
3 11 3 8 68
3 11 4 2 0
3 11 5 6 0
3 11 6 22 0
3 11 7 8 0
3 11 8 18 0
3 11 9 4 44
3 12 3 6 68
3 12 4 3 0
3 12 5 2 0
3 12 6 4 8
3 12 7 16 12
3 12 8 2 44
3 13 3 16 76
3 13 4 1 12
3 13 5 0 44
4 0 3 12 80
4 0 4 22 16
4 0 5 1 16
4 0 6 8 16
4 0 7 5 16
4 0 8 22 16
4 0 9 24 16
4 0 10 3 16
4 0 11 3 48
4 1 3 12 64
4 1 4 8 0
4 1 5 5 0
4 1 6 2 0
4 1 7 8 0
4 1 8 8 0
4 1 9 7 0
4 1 10 16 0
4 1 11 3 32
4 2 3 5 64
4 2 4 10 0
4 2 5 1 0
4 2 6 5 0
4 2 7 18 0
4 2 8 0 0
4 2 9 12 0
4 2 10 23 0
4 2 11 8 32
4 3 3 4 64
4 3 4 0 0
4 3 5 8 0
4 3 6 8 0
4 3 7 22 0
4 3 8 19 0
4 3 9 3 0
4 3 10 23 0
4 3 11 2 32
4 4 3 11 64
4 4 4 0 0
4 4 5 0 0
4 4 6 15 0
4 4 7 15 0
4 4 8 14 0
4 4 9 4 0
4 4 10 7 0
4 4 11 16 32
4 5 2 16 86
4 5 3 4 0
4 5 4 13 0
4 5 5 5 0
4 5 6 22 0
4 5 7 16 0
4 5 8 5 0
4 5 9 0 0
4 5 10 6 0
4 5 11 5 32
4 6 2 3 70
4 6 3 4 0
4 6 4 4 0
4 6 5 14 0
4 6 6 6 0
4 6 7 3 0
4 6 8 18 0
4 6 9 2 0
4 6 10 16 0
4 6 11 6 32
4 7 2 0 70
4 7 3 18 0
4 7 4 3 0
4 7 5 0 0
4 7 6 3 0
4 7 7 22 0
4 7 8 2 0
4 7 9 11 0
4 7 10 18 0
4 7 11 1 32
4 8 2 1 70
4 8 3 0 0
4 8 4 24 0
4 8 5 1 0
4 8 6 22 0
4 8 7 5 0
4 8 8 14 0
4 8 9 19 0
4 8 10 5 0
4 8 11 4 32
4 9 2 5 70
4 9 3 10 0
4 9 4 9 0
4 9 5 14 0
4 9 6 4 0
4 9 7 0 0
4 9 8 8 0
4 9 9 3 0
4 9 10 3 0
4 9 11 13 32
4 10 2 1 70
4 10 3 3 0
4 10 4 3 0
4 10 5 6 0
4 10 6 2 0
4 10 7 18 0
4 10 8 2 0
4 10 9 19 0
4 10 10 5 0
4 10 11 11 44
4 11 2 1 70
4 11 3 11 0
4 11 4 14 0
4 11 5 5 0
4 11 6 20 0
4 11 7 20 0
4 11 8 5 0
4 11 9 1 8
4 11 10 14 44
4 12 2 19 70
4 12 3 4 0
4 12 4 7 0
4 12 5 11 0
4 12 6 2 8
4 12 7 11 8
4 12 8 1 40
4 13 2 15 78
4 13 3 0 8
4 13 4 12 8
4 13 5 22 40
5 0 2 22 84
5 0 3 5 16
5 0 4 24 16
5 0 5 22 16
5 0 6 15 16
5 0 7 16 16
5 0 8 0 16
5 0 9 3 16
5 0 10 2 16
5 0 11 24 48
5 1 2 4 68
5 1 3 0 0
5 1 4 14 0
5 1 5 4 0
5 1 6 6 0
5 1 7 2 0
5 1 8 11 0
5 1 9 6 0
5 1 10 8 0
5 1 11 22 32
5 2 2 5 68
5 2 3 3 0
5 2 4 5 0
5 2 5 5 0
5 2 6 1 0
5 2 7 1 0
5 2 8 3 0
5 2 9 6 0
5 2 10 1 0
5 2 11 7 32
5 3 2 1 76
5 3 3 5 0
5 3 4 15 0
5 3 5 5 0
5 3 6 16 0
5 3 7 6 0
5 3 8 11 0
5 3 9 10 0
5 3 10 0 0
5 3 11 2 32
5 4 3 4 64
5 4 4 2 0
5 4 5 3 0
5 4 6 1 0
5 4 7 3 0
5 4 8 4 0
5 4 9 4 0
5 4 10 14 0
5 4 11 6 32
5 5 3 0 64
5 5 4 6 0
5 5 5 12 0
5 5 6 23 0
5 5 7 0 0
5 5 8 20 0
5 5 9 6 0
5 5 10 11 0
5 5 11 5 32
5 6 3 20 64
5 6 4 2 0
5 6 5 5 0
5 6 6 4 0
5 6 7 13 0
5 6 8 3 0
5 6 9 1 0
5 6 10 21 0
5 6 11 3 32
5 7 3 14 64
5 7 4 22 0
5 7 5 11 0
5 7 6 0 0
5 7 7 0 0
5 7 8 19 0
5 7 9 21 0
5 7 10 4 0
5 7 11 1 32
5 8 3 4 64
5 8 4 6 0
5 8 5 0 0
5 8 6 3 0
5 8 7 14 0
5 8 8 6 0
5 8 9 5 0
5 8 10 21 0
5 8 11 9 32
5 9 3 2 64
5 9 4 8 0
5 9 5 4 0
5 9 6 0 0
5 9 7 24 0
5 9 8 1 0
5 9 9 24 0
5 9 10 8 0
5 9 11 4 32
5 10 3 11 64
5 10 4 4 0
5 10 5 10 0
5 10 6 1 0
5 10 7 16 0
5 10 8 6 0
5 10 9 24 0
5 10 10 1 0
5 10 11 0 40
5 11 3 6 64
5 11 4 5 0
5 11 5 5 0
5 11 6 9 0
5 11 7 8 0
5 11 8 17 0
5 11 9 22 0
5 11 10 0 32
5 12 3 16 64
5 12 4 1 0
5 12 5 1 0
5 12 6 4 0
5 12 7 24 0
5 12 8 4 0
5 12 9 3 4
5 12 10 0 36
5 13 3 3 64
5 13 4 14 0
5 13 5 2 0
5 13 6 14 4
5 13 7 2 4
5 13 8 19 4
5 13 9 1 4
5 13 10 1 36
5 14 3 22 76
5 14 4 3 4
5 14 5 0 4
5 14 6 23 4
5 14 7 11 4
5 14 8 6 4
5 14 9 0 4
5 14 10 13 44
5 15 4 23 68
5 15 5 7 4
5 15 6 0 4
5 15 7 6 4
5 15 8 14 4
5 15 9 19 36
5 16 4 22 68
5 16 5 4 4
5 16 6 4 4
5 16 7 12 4
5 16 8 3 4
5 16 9 10 4
5 16 10 21 52
5 17 4 0 68
5 17 5 2 4
5 17 6 12 4
5 17 7 3 4
5 17 8 2 4
5 17 9 22 4
5 17 10 5 36
5 18 4 1 76
5 18 5 17 12
5 18 6 4 12
5 18 7 13 12
5 18 8 8 12
5 18 9 18 12
5 18 10 4 44
6 0 2 11 80
6 0 3 4 16
6 0 4 16 16
6 0 5 1 16
6 0 6 24 16
6 0 7 13 16
6 0 8 2 16
6 0 9 20 16
6 0 10 20 16
6 0 11 22 48
6 1 2 19 64
6 1 3 2 0
6 1 4 5 0
6 1 5 3 0
6 1 6 6 0
6 1 7 4 0
6 1 8 22 0
6 1 9 4 0
6 1 10 1 0
6 1 11 23 32
6 2 2 10 64
6 2 3 7 0
6 2 4 2 0
6 2 5 8 0
6 2 6 22 0
6 2 7 14 0
6 2 8 1 0
6 2 9 19 0
6 2 10 4 0
6 2 11 18 0
6 2 12 16 52
6 3 2 3 64
6 3 3 4 0
6 3 4 24 0
6 3 5 3 0
6 3 6 21 0
6 3 7 1 0
6 3 8 3 0
6 3 9 4 0
6 3 10 0 0
6 3 11 22 0
6 3 12 8 36
6 4 2 16 68
6 4 3 22 0
6 4 4 2 0
6 4 5 0 0
6 4 6 4 0
6 4 7 14 0
6 4 8 11 0
6 4 9 5 0
6 4 10 5 0
6 4 11 0 0
6 4 12 3 36
6 5 2 18 68
6 5 3 11 0
6 5 4 8 0
6 5 5 1 0
6 5 6 1 0
6 5 7 4 0
6 5 8 16 0
6 5 9 1 0
6 5 10 11 0
6 5 11 22 0
6 5 12 3 44
6 6 2 11 68
6 6 3 11 0
6 6 4 3 0
6 6 5 13 0
6 6 6 0 0
6 6 7 22 0
6 6 8 4 0
6 6 9 0 0
6 6 10 5 0
6 6 11 3 32
6 7 2 13 68
6 7 3 1 0
6 7 4 8 0
6 7 5 22 0
6 7 6 19 0
6 7 7 16 0
6 7 8 15 0
6 7 9 2 0
6 7 10 2 0
6 7 11 14 32
6 8 2 15 76
6 8 3 19 0
6 8 4 13 0
6 8 5 3 0
6 8 6 3 0
6 8 7 5 0
6 8 8 9 0
6 8 9 4 0
6 8 10 4 0
6 8 11 0 32
6 9 3 4 64
6 9 4 16 0
6 9 5 5 0
6 9 6 6 0
6 9 7 6 0
6 9 8 19 0
6 9 9 11 0
6 9 10 6 0
6 9 11 6 32
6 10 3 2 64
6 10 4 5 0
6 10 5 24 0
6 10 6 1 0
6 10 7 23 0
6 10 8 6 0
6 10 9 0 0
6 10 10 0 0
6 10 11 1 40
6 11 3 2 64
6 11 4 2 0
6 11 5 2 0
6 11 6 6 0
6 11 7 8 0
6 11 8 8 0
6 11 9 0 0
6 11 10 0 32
6 12 3 6 64
6 12 4 4 0
6 12 5 6 0
6 12 6 14 0
6 12 7 6 0
6 12 8 6 0
6 12 9 1 0
6 12 10 6 32
6 13 2 9 86
6 13 3 22 0
6 13 4 17 0
6 13 5 5 0
6 13 6 11 0
6 13 7 21 0
6 13 8 6 0
6 13 9 0 0
6 13 10 0 32
6 14 2 5 70
6 14 3 8 0
6 14 4 2 0
6 14 5 2 0
6 14 6 11 0
6 14 7 16 0
6 14 8 2 0
6 14 9 3 0
6 14 10 1 32
6 15 2 2 78
6 15 3 6 6
6 15 4 23 0
6 15 5 20 0
6 15 6 5 0
6 15 7 4 0
6 15 8 13 0
6 15 9 11 0
6 15 10 4 36
6 16 3 4 70
6 16 4 6 0
6 16 5 3 0
6 16 6 20 0
6 16 7 2 0
6 16 8 16 0
6 16 9 22 0
6 16 10 7 32
6 17 3 0 68
6 17 4 16 0
6 17 5 6 0
6 17 6 1 0
6 17 7 9 0
6 17 8 12 0
6 17 9 6 0
6 17 10 16 32
6 18 3 9 76
6 18 4 1 0
6 18 5 8 0
6 18 6 2 0
6 18 7 22 0
6 18 8 1 8
6 18 9 3 8
6 18 10 2 40
6 19 4 6 76
6 19 5 6 12
6 19 6 23 12
6 19 7 19 44
7 0 2 0 80
7 0 3 19 16
7 0 4 0 16
7 0 5 16 16
7 0 6 3 16
7 0 7 6 16
7 0 8 4 16
7 0 9 11 16
7 0 10 24 16
7 0 11 5 48
7 1 2 24 64
7 1 3 1 0
7 1 4 18 0
7 1 5 5 0
7 1 6 2 0
7 1 7 21 0
7 1 8 6 0
7 1 9 16 0
7 1 10 13 0
7 1 11 4 0
7 1 12 2 52
7 2 2 5 64
7 2 3 7 0
7 2 4 4 0
7 2 5 5 0
7 2 6 22 0
7 2 7 14 0
7 2 8 6 0
7 2 9 13 0
7 2 10 13 0
7 2 11 22 0
7 2 12 12 32
7 3 2 1 64
7 3 3 8 0
7 3 4 4 0
7 3 5 22 0
7 3 6 6 0
7 3 7 21 0
7 3 8 6 0
7 3 9 0 0
7 3 10 9 0
7 3 11 1 0
7 3 12 12 32
7 4 2 7 64
7 4 3 0 0
7 4 4 15 0
7 4 5 0 0
7 4 6 14 0
7 4 7 8 0
7 4 8 16 0
7 4 9 14 0
7 4 10 17 0
7 4 11 1 0
7 4 12 3 32
7 5 2 6 64
7 5 3 6 0
7 5 4 0 0
7 5 5 16 0
7 5 6 2 0
7 5 7 2 0
7 5 8 1 0
7 5 9 5 0
7 5 10 8 0
7 5 11 4 0
7 5 12 15 32
7 6 2 16 64
7 6 3 5 0
7 6 4 8 0
7 6 5 1 0
7 6 6 11 0
7 6 7 14 0
7 6 8 5 0
7 6 9 5 0
7 6 10 1 0
7 6 11 1 0
7 6 12 11 36
7 7 2 21 64
7 7 3 3 0
7 7 4 21 0
7 7 5 11 0
7 7 6 4 0
7 7 7 4 0
7 7 8 0 0
7 7 9 8 0
7 7 10 2 0
7 7 11 5 0
7 7 12 16 36
7 8 2 22 64
7 8 3 1 0
7 8 4 5 0
7 8 5 9 0
7 8 6 14 0
7 8 7 10 0
7 8 8 1 0
7 8 9 6 0
7 8 10 1 0
7 8 11 4 0
7 8 12 4 36
7 9 2 7 68
7 9 3 1 0
7 9 4 12 0
7 9 5 6 0
7 9 6 14 0
7 9 7 16 0
7 9 8 22 0
7 9 9 21 0
7 9 10 20 0
7 9 11 3 0
7 9 12 1 44
7 10 2 2 76
7 10 3 21 0
7 10 4 0 0
7 10 5 5 0
7 10 6 17 0
7 10 7 22 0
7 10 8 5 0
7 10 9 0 0
7 10 10 6 0
7 10 11 7 32
7 11 3 20 64
7 11 4 14 0
7 11 5 3 0
7 11 6 0 0
7 11 7 16 0
7 11 8 2 0
7 11 9 5 0
7 11 10 8 0
7 11 11 1 36
7 12 3 4 64
7 12 4 8 0
7 12 5 16 0
7 12 6 6 0
7 12 7 13 0
7 12 8 11 0
7 12 9 16 0
7 12 10 2 0
7 12 11 7 36
7 13 3 6 64
7 13 4 1 0
7 13 5 4 0
7 13 6 13 0
7 13 7 2 0
7 13 8 14 0
7 13 9 7 0
7 13 10 4 0
7 13 11 15 36
7 14 3 14 72
7 14 4 4 0
7 14 5 24 0
7 14 6 24 0
7 14 7 13 0
7 14 8 3 0
7 14 9 24 0
7 14 10 1 0
7 14 11 15 36
7 15 4 14 64
7 15 5 3 0
7 15 6 19 0
7 15 7 17 0
7 15 8 0 0
7 15 9 12 0
7 15 10 2 0
7 15 11 1 36
7 16 4 3 64
7 16 5 22 0
7 16 6 2 0
7 16 7 4 0
7 16 8 11 0
7 16 9 19 0
7 16 10 24 0
7 16 11 8 36
7 17 3 5 80
7 17 4 2 0
7 17 5 6 0
7 17 6 8 0
7 17 7 19 0
7 17 8 3 0
7 17 9 22 0
7 17 10 14 0
7 17 11 20 36
7 18 3 6 64
7 18 4 10 0
7 18 5 0 0
7 18 6 14 0
7 18 7 1 0
7 18 8 0 8
7 18 9 7 0
7 18 10 4 8
7 18 11 2 44
7 19 3 5 76
7 19 4 23 0
7 19 5 14 0
7 19 6 6 0
7 19 7 24 32
7 19 9 24 108
7 20 4 18 76
7 20 5 6 4
7 20 6 17 12
7 20 7 22 44
7 21 5 6 108
8 0 2 2 80
8 0 3 2 16
8 0 4 8 16
8 0 5 2 16
8 0 6 24 16
8 0 7 12 16
8 0 8 8 16
8 0 9 11 16
8 0 10 5 16
8 0 11 24 16
8 0 12 6 52
8 1 2 2 64
8 1 3 22 0
8 1 4 4 0
8 1 5 3 0
8 1 6 10 0
8 1 7 8 0
8 1 8 3 0
8 1 9 7 0
8 1 10 0 0
8 1 11 6 0
8 1 12 10 32
8 2 2 6 64
8 2 3 23 0
8 2 4 5 0
8 2 5 12 0
8 2 6 8 0
8 2 7 19 0
8 2 8 1 0
8 2 9 0 0
8 2 10 2 0
8 2 11 7 0
8 2 12 3 32
8 3 2 3 64
8 3 3 1 0
8 3 4 3 0
8 3 5 19 0
8 3 6 3 0
8 3 7 5 0
8 3 8 21 0
8 3 9 17 0
8 3 10 11 0
8 3 11 8 0
8 3 12 3 32
8 4 2 3 64
8 4 3 15 0
8 4 4 22 0
8 4 5 2 0
8 4 6 16 0
8 4 7 1 0
8 4 8 1 0
8 4 9 10 0
8 4 10 14 0
8 4 11 1 0
8 4 12 8 32
8 5 2 22 64
8 5 3 16 0
8 5 4 24 0
8 5 5 5 0
8 5 6 22 0
8 5 7 5 0
8 5 8 17 0
8 5 9 5 0
8 5 10 23 0
8 5 11 15 0
8 5 12 17 32
8 6 2 14 64
8 6 3 5 0
8 6 4 22 0
8 6 5 11 0
8 6 6 17 0
8 6 7 1 0
8 6 8 1 0
8 6 9 2 0
8 6 10 14 0
8 6 11 19 0
8 6 12 8 32
8 7 2 13 64
8 7 3 1 0
8 7 4 10 0
8 7 5 24 0
8 7 6 24 0
8 7 7 14 0
8 7 8 8 0
8 7 9 2 0
8 7 10 19 0
8 7 11 0 0
8 7 12 2 32
8 8 2 5 64
8 8 3 4 0
8 8 4 7 0
8 8 5 2 0
8 8 6 13 0
8 8 7 7 0
8 8 8 1 0
8 8 9 20 0
8 8 10 16 0
8 8 11 23 0
8 8 12 21 32
8 9 2 13 64
8 9 3 16 0
8 9 4 4 0
8 9 5 9 0
8 9 6 0 0
8 9 7 17 0
8 9 8 18 0
8 9 9 22 0
8 9 10 9 0
8 9 11 18 0
8 9 12 4 32
8 10 2 6 72
8 10 3 6 0
8 10 4 22 0
8 10 5 2 0
8 10 6 10 0
8 10 7 6 0
8 10 8 21 0
8 10 9 5 0
8 10 10 3 0
8 10 11 5 0
8 10 12 15 36
8 11 3 14 64
8 11 4 17 0
8 11 5 5 0
8 11 6 6 0
8 11 7 19 0
8 11 8 6 0
8 11 9 2 0
8 11 10 14 0
8 11 11 2 0
8 11 12 3 44
8 12 3 8 64
8 12 4 4 0
8 12 5 4 0
8 12 6 10 0
8 12 7 2 0
8 12 8 4 0
8 12 9 23 0
8 12 10 4 0
8 12 11 4 32
8 13 3 1 64
8 13 4 2 0
8 13 5 3 0
8 13 6 23 0
8 13 7 3 0
8 13 8 4 0
8 13 9 22 0
8 13 10 19 0
8 13 11 6 0
8 13 12 1 52
8 14 3 6 64
8 14 4 3 0
8 14 5 2 0
8 14 6 3 0
8 14 7 7 0
8 14 8 2 0
8 14 9 14 0
8 14 10 17 0
8 14 11 3 0
8 14 12 6 36
8 15 3 5 68
8 15 4 1 0
8 15 5 5 0
8 15 6 1 0
8 15 7 5 0
8 15 8 5 0
8 15 9 14 0
8 15 10 2 0
8 15 11 12 0
8 15 12 3 36
8 16 3 23 68
8 16 4 4 0
8 16 5 13 0
8 16 6 6 0
8 16 7 20 0
8 16 8 6 0
8 16 9 24 0
8 16 10 5 0
8 16 11 21 0
8 16 12 6 36
8 17 3 4 64
8 17 4 6 0
8 17 5 12 0
8 17 6 5 0
8 17 7 6 0
8 17 8 9 0
8 17 9 0 0
8 17 10 3 0
8 17 11 5 0
8 17 12 3 36
8 18 3 3 64
8 18 4 6 0
8 18 5 2 0
8 18 6 21 0
8 18 7 0 0
8 18 8 1 0
8 18 9 3 0
8 18 10 8 0
8 18 11 8 8
8 18 12 22 44
8 19 3 4 72
8 19 4 22 0
8 19 5 16 0
8 19 6 5 0
8 19 7 0 0
8 19 8 1 4
8 19 9 3 8
8 19 10 16 44
8 20 4 24 64
8 20 5 22 0
8 20 6 17 0
8 20 7 2 0
8 20 8 16 36
8 21 4 19 76
8 21 5 24 0
8 21 6 18 4
8 21 7 16 4
8 21 8 6 36
8 22 5 6 68
8 22 6 16 4
8 22 7 6 4
8 22 8 11 36
8 23 4 16 84
8 23 5 5 4
8 23 6 9 4
8 23 7 0 4
8 23 8 8 36
8 24 4 4 78
8 24 5 10 12
8 24 6 1 12
8 24 7 19 12
8 24 8 20 44
9 0 2 2 80
9 0 3 15 16
9 0 4 15 16
9 0 5 2 16
9 0 6 1 16
9 0 7 6 16
9 0 8 0 16
9 0 9 13 16
9 0 10 6 16
9 0 11 18 16
9 0 12 5 50
9 1 2 0 64
9 1 3 6 0
9 1 4 14 0
9 1 5 11 0
9 1 6 4 0
9 1 7 20 0
9 1 8 3 0
9 1 9 20 0
9 1 10 23 0
9 1 11 20 0
9 1 12 0 32
9 2 2 3 64
9 2 3 16 0
9 2 4 10 0
9 2 5 5 0
9 2 6 11 0
9 2 7 15 0
9 2 8 19 0
9 2 9 15 0
9 2 10 0 0
9 2 11 5 0
9 2 12 23 32
9 3 2 9 64
9 3 3 6 0
9 3 4 0 0
9 3 5 0 0
9 3 6 4 0
9 3 7 6 0
9 3 8 9 0
9 3 9 0 0
9 3 10 8 0
9 3 11 22 0
9 3 12 5 32
9 4 2 4 64
9 4 3 0 0
9 4 4 16 0
9 4 5 16 0
9 4 6 17 0
9 4 7 10 0
9 4 8 3 0
9 4 9 11 0
9 4 10 4 0
9 4 11 4 0
9 4 12 19 32
9 5 2 0 64
9 5 3 3 0
9 5 4 2 0
9 5 5 5 0
9 5 6 3 0
9 5 7 0 0
9 5 8 5 0
9 5 9 3 0
9 5 10 17 0
9 5 11 1 0
9 5 12 1 32
9 6 2 5 64
9 6 3 5 0
9 6 4 5 0
9 6 5 19 0
9 6 6 14 0
9 6 7 4 0
9 6 8 24 0
9 6 9 23 0
9 6 10 2 0
9 6 11 19 0
9 6 12 5 32
9 7 2 0 64
9 7 3 5 0
9 7 4 3 0
9 7 5 22 0
9 7 6 22 0
9 7 7 10 0
9 7 8 5 0
9 7 9 2 0
9 7 10 2 0
9 7 11 14 0
9 7 12 17 32
9 8 2 24 64
9 8 3 1 0
9 8 4 0 0
9 8 5 1 0
9 8 6 4 0
9 8 7 2 0
9 8 8 2 0
9 8 9 21 0
9 8 10 2 0
9 8 11 19 0
9 8 12 6 32
9 9 2 4 64
9 9 3 1 0
9 9 4 21 0
9 9 5 10 0
9 9 6 4 0
9 9 7 8 0
9 9 8 10 0
9 9 9 6 0
9 9 10 19 0
9 9 11 7 0
9 9 12 11 32
9 10 2 16 72
9 10 3 5 0
9 10 4 16 0
9 10 5 21 0
9 10 6 5 0
9 10 7 6 0
9 10 8 8 0
9 10 9 0 0
9 10 10 0 0
9 10 11 15 0
9 10 12 21 32
9 11 3 3 64
9 11 4 14 0
9 11 5 20 0
9 11 6 4 0
9 11 7 6 0
9 11 8 6 0
9 11 9 8 0
9 11 10 3 0
9 11 11 6 0
9 11 12 1 32
9 12 3 11 64
9 12 4 22 0
9 12 5 10 0
9 12 6 22 0
9 12 7 6 0
9 12 8 3 0
9 12 9 6 0
9 12 10 6 0
9 12 11 24 0
9 12 12 8 36
9 13 3 4 64
9 13 4 12 0
9 13 5 2 0
9 13 6 18 0
9 13 7 6 0
9 13 8 20 0
9 13 9 6 0
9 13 10 5 0
9 13 11 5 0
9 13 12 8 32
9 14 3 5 64
9 14 4 17 0
9 14 5 21 0
9 14 6 15 0
9 14 7 15 0
9 14 8 20 0
9 14 9 3 0
9 14 10 1 0
9 14 11 19 0
9 14 12 14 32
9 15 3 6 64
9 15 4 8 0
9 15 5 3 0
9 15 6 16 0
9 15 7 2 0
9 15 8 5 0
9 15 9 3 0
9 15 10 5 0
9 15 11 16 0
9 15 12 3 32
9 16 3 14 64
9 16 4 0 0
9 16 5 8 0
9 16 6 4 0
9 16 7 22 0
9 16 8 22 0
9 16 9 18 0
9 16 10 3 0
9 16 11 0 0
9 16 12 19 32
9 17 3 0 64
9 17 4 5 0
9 17 5 6 0
9 17 6 7 0
9 17 7 1 0
9 17 8 19 0
9 17 9 4 0
9 17 10 14 0
9 17 11 22 0
9 17 12 8 32
9 18 3 22 64
9 18 4 1 0
9 18 5 10 0
9 18 6 16 0
9 18 7 19 0
9 18 8 1 0
9 18 9 18 0
9 18 10 0 0
9 18 11 4 0
9 18 12 16 32
9 19 3 5 72
9 19 4 11 0
9 19 5 24 0
9 19 6 5 0
9 19 7 12 0
9 19 8 22 0
9 19 9 6 0
9 19 10 15 0
9 19 11 13 12
9 19 12 3 44
9 20 4 24 66
9 20 5 19 0
9 20 6 15 0
9 20 7 14 0
9 20 8 22 0
9 20 9 1 4
9 20 10 16 36
9 21 4 3 64
9 21 5 0 0
9 21 6 5 0
9 21 7 20 0
9 21 8 6 0
9 21 9 20 4
9 21 10 22 36
9 22 4 0 68
9 22 5 3 0
9 22 6 18 0
9 22 7 6 0
9 22 8 15 0
9 22 9 5 4
9 22 10 4 36
9 23 4 14 72
9 23 5 11 0
9 23 6 5 0
9 23 7 8 0
9 23 8 16 0
9 23 9 14 4
9 23 10 1 36
9 24 5 1 64
9 24 6 15 0
9 24 7 6 0
9 24 8 14 0
9 24 9 10 4
9 24 10 10 36
9 25 5 5 76
9 25 6 6 4
9 25 7 14 4
9 25 8 23 4
9 25 9 18 12
9 25 10 1 46
9 26 6 1 78
9 26 7 24 12
9 26 8 7 44
10 0 2 10 82
10 0 3 14 16
10 0 4 23 16
10 0 5 2 16
10 0 6 11 16
10 0 7 20 16
10 0 8 4 16
10 0 9 4 16
10 0 10 16 16
10 0 11 6 48
10 1 2 23 66
10 1 3 4 0
10 1 4 23 0
10 1 5 14 0
10 1 6 24 0
10 1 7 3 0
10 1 8 23 0
10 1 9 19 0
10 1 10 3 0
10 1 11 5 0
10 1 12 4 48
10 2 2 8 66
10 2 3 20 0
10 2 4 4 0
10 2 5 6 0
10 2 6 13 0
10 2 7 0 0
10 2 8 18 0
10 2 9 1 0
10 2 10 5 0
10 2 11 5 0
10 2 12 0 32
10 3 2 8 66
10 3 3 13 0
10 3 4 7 0
10 3 5 9 0
10 3 6 10 0
10 3 7 7 0
10 3 8 4 0
10 3 9 1 0
10 3 10 0 0
10 3 11 4 0
10 3 12 16 32
10 4 2 3 66
10 4 3 6 0
10 4 4 0 0
10 4 5 16 0
10 4 6 5 0
10 4 7 1 0
10 4 8 21 0
10 4 9 2 0
10 4 10 23 0
10 4 11 18 0
10 4 12 5 32
10 5 2 0 66
10 5 3 1 0
10 5 4 2 0
10 5 5 16 0
10 5 6 15 0
10 5 7 6 0
10 5 8 12 0
10 5 9 3 0
10 5 10 10 0
10 5 11 6 0
10 5 12 24 32
10 6 2 6 66
10 6 3 4 0
10 6 4 5 0
10 6 5 15 0
10 6 6 0 0
10 6 7 14 0
10 6 8 19 0
10 6 9 5 0
10 6 10 0 0
10 6 11 11 0
10 6 12 16 32
10 7 2 19 66
10 7 3 22 0
10 7 4 15 0
10 7 5 8 0
10 7 6 17 0
10 7 7 6 0
10 7 8 24 0
10 7 9 2 0
10 7 10 2 0
10 7 11 0 0
10 7 12 16 32
10 8 2 17 66
10 8 3 4 0
10 8 4 3 0
10 8 5 11 0
10 8 6 3 0
10 8 7 7 0
10 8 8 5 0
10 8 9 6 0
10 8 10 1 0
10 8 11 2 0
10 8 12 8 32
10 9 2 6 66
10 9 3 2 0
10 9 4 18 0
10 9 5 3 0
10 9 6 0 0
10 9 7 5 0
10 9 8 4 0
10 9 9 0 0
10 9 10 21 0
10 9 11 1 0
10 9 12 0 32
10 10 2 6 66
10 10 3 0 0
10 10 4 6 0
10 10 5 4 0
10 10 6 19 0
10 10 7 16 0
10 10 8 20 0
10 10 9 8 0
10 10 10 23 0
10 10 11 23 0
10 10 12 3 32
10 11 2 20 78
10 11 3 18 0
10 11 4 0 0
10 11 5 3 0
10 11 6 20 0
10 11 7 4 0
10 11 8 16 0
10 11 9 9 0
10 11 10 11 0
10 11 11 12 0
10 11 12 11 32
10 12 3 3 64
10 12 4 6 0
10 12 5 9 0
10 12 6 21 0
10 12 7 7 0
10 12 8 0 0
10 12 9 15 0
10 12 10 5 0
10 12 11 2 0
10 12 12 4 32
10 13 3 5 66
10 13 4 24 0
10 13 5 23 0
10 13 6 11 0
10 13 7 6 0
10 13 8 4 0
10 13 9 1 0
10 13 10 1 0
10 13 11 0 0
10 13 12 20 32
10 14 3 6 64
10 14 4 2 0
10 14 5 2 0
10 14 6 8 0
10 14 7 1 0
10 14 8 14 0
10 14 9 22 0
10 14 10 0 0
10 14 11 19 0
10 14 12 22 32
10 15 3 20 64
10 15 4 2 0
10 15 5 8 0
10 15 6 22 0
10 15 7 6 0
10 15 8 8 0
10 15 9 1 0
10 15 10 21 0
10 15 11 5 0
10 15 12 1 32
10 16 3 15 66
10 16 4 13 0
10 16 5 3 0
10 16 6 5 0
10 16 7 13 0
10 16 8 4 0
10 16 9 6 0
10 16 10 2 0
10 16 11 8 0
10 16 12 11 32
10 17 3 5 66
10 17 4 1 0
10 17 5 3 0
10 17 6 6 0
10 17 7 8 0
10 17 8 12 0
10 17 9 6 0
10 17 10 14 0
10 17 11 3 0
10 17 12 6 32
10 18 3 6 64
10 18 4 8 0
10 18 5 2 0
10 18 6 16 0
10 18 7 16 0
10 18 8 23 0
10 18 9 1 0
10 18 10 6 0
10 18 11 6 0
10 18 12 4 32
10 19 3 5 72
10 19 4 1 8
10 19 5 24 0
10 19 6 11 0
10 19 7 17 0
10 19 8 5 0
10 19 9 6 0
10 19 10 11 0
10 19 11 11 8
10 19 12 4 40
10 20 5 22 64
10 20 6 6 0
10 20 7 1 0
10 20 8 3 0
10 20 9 17 0
10 20 10 19 34
10 21 4 22 80
10 21 5 1 0
10 21 6 20 0
10 21 7 5 0
10 21 8 1 0
10 21 9 6 0
10 21 10 10 32
10 22 4 22 64
10 22 5 13 0
10 22 6 3 0
10 22 7 3 0
10 22 8 22 0
10 22 9 14 0
10 22 10 17 32
10 23 4 13 72
10 23 5 19 0
10 23 6 5 0
10 23 7 15 0
10 23 8 1 0
10 23 9 6 0
10 23 10 14 32
10 24 5 14 64
10 24 6 14 0
10 24 7 0 0
10 24 8 11 0
10 24 9 24 0
10 24 10 5 40
10 25 5 16 64
10 25 6 19 8
10 25 7 0 0
10 25 8 5 0
10 25 9 11 32
10 26 5 13 110
10 26 7 12 72
10 26 8 4 8
10 26 9 1 46
11 0 3 6 80
11 0 4 2 16
11 0 5 5 16
11 0 6 11 16
11 0 7 19 16
11 0 8 3 16
11 0 9 19 16
11 0 10 16 16
11 0 11 6 48
11 1 3 20 64
11 1 4 21 0
11 1 5 13 0
11 1 6 19 0
11 1 7 22 0
11 1 8 6 0
11 1 9 20 0
11 1 10 14 0
11 1 11 1 0
11 1 12 16 48
11 2 3 15 64
11 2 4 5 0
11 2 5 8 0
11 2 6 14 0
11 2 7 3 0
11 2 8 4 0
11 2 9 1 0
11 2 10 7 0
11 2 11 2 0
11 2 12 2 32
11 3 3 16 64
11 3 4 22 0
11 3 5 21 0
11 3 6 17 0
11 3 7 11 0
11 3 8 4 0
11 3 9 16 0
11 3 10 22 0
11 3 11 21 0
11 3 12 2 32
11 4 3 14 64
11 4 4 8 0
11 4 5 24 0
11 4 6 10 0
11 4 7 4 0
11 4 8 6 0
11 4 9 0 0
11 4 10 5 0
11 4 11 1 0
11 4 12 5 32
11 5 3 17 64
11 5 4 1 0
11 5 5 22 0
11 5 6 19 0
11 5 7 7 0
11 5 8 1 0
11 5 9 4 0
11 5 10 3 0
11 5 11 5 0
11 5 12 4 32
11 6 3 4 64
11 6 4 1 0
11 6 5 7 0
11 6 6 9 0
11 6 7 23 0
11 6 8 22 0
11 6 9 1 0
11 6 10 23 0
11 6 11 19 0
11 6 12 16 32
11 7 3 9 64
11 7 4 4 0
11 7 5 5 0
11 7 6 5 0
11 7 7 1 0
11 7 8 4 0
11 7 9 17 0
11 7 10 5 0
11 7 11 19 0
11 7 12 6 32
11 8 3 1 64
11 8 4 11 0
11 8 5 22 0
11 8 6 4 0
11 8 7 6 0
11 8 8 10 0
11 8 9 19 0
11 8 10 1 0
11 8 11 4 0
11 8 12 3 32
11 9 3 22 64
11 9 4 5 0
11 9 5 2 0
11 9 6 13 0
11 9 7 4 0
11 9 8 3 0
11 9 9 6 0
11 9 10 20 0
11 9 11 1 0
11 9 12 3 32
11 10 3 3 64
11 10 4 19 0
11 10 5 4 0
11 10 6 16 0
11 10 7 15 0
11 10 8 12 0
11 10 9 15 0
11 10 10 1 0
11 10 11 13 0
11 10 12 13 32
11 11 3 23 64
11 11 4 5 0
11 11 5 8 0
11 11 6 1 0
11 11 7 22 0
11 11 8 5 0
11 11 9 5 0
11 11 10 14 0
11 11 11 5 0
11 11 12 6 32
11 12 3 4 72
11 12 4 5 0
11 12 5 3 0
11 12 6 3 0
11 12 7 12 0
11 12 8 4 0
11 12 9 23 0
11 12 10 14 0
11 12 11 6 0
11 12 12 16 32
11 13 4 2 64
11 13 5 15 0
11 13 6 3 0
11 13 7 3 0
11 13 8 7 0
11 13 9 14 0
11 13 10 8 0
11 13 11 13 0
11 13 12 22 32
11 14 3 17 80
11 14 4 1 0
11 14 5 9 0
11 14 6 21 0
11 14 7 4 0
11 14 8 9 0
11 14 9 3 0
11 14 10 3 0
11 14 11 18 0
11 14 12 2 32
11 15 3 13 72
11 15 4 4 0
11 15 5 4 0
11 15 6 22 0
11 15 7 6 0
11 15 8 22 0
11 15 9 8 0
11 15 10 0 0
11 15 11 3 0
11 15 12 16 32
11 16 4 11 64
11 16 5 22 0
11 16 6 6 0
11 16 7 4 0
11 16 8 2 0
11 16 9 0 0
11 16 10 18 0
11 16 11 11 0
11 16 12 11 32
11 17 4 5 64
11 17 5 2 0
11 17 6 4 0
11 17 7 2 0
11 17 8 0 0
11 17 9 16 0
11 17 10 1 0
11 17 11 5 0
11 17 12 16 32
11 18 3 19 80
11 18 4 5 0
11 18 5 6 0
11 18 6 5 0
11 18 7 5 0
11 18 8 3 0
11 18 9 16 0
11 18 10 0 0
11 18 11 8 0
11 18 12 19 32
11 19 3 21 72
11 19 4 11 0
11 19 5 3 0
11 19 6 13 0
11 19 7 0 0
11 19 8 3 0
11 19 9 13 0
11 19 10 22 8
11 19 11 1 8
11 19 12 6 42
11 20 4 9 68
11 20 5 20 0
11 20 6 0 0
11 20 7 10 0
11 20 8 17 0
11 20 9 9 32
11 21 4 4 64
11 21 5 22 0
11 21 6 24 0
11 21 7 6 0
11 21 8 21 0
11 21 9 17 0
11 21 10 4 48
11 22 4 16 64
11 22 5 5 0
11 22 6 14 0
11 22 7 3 0
11 22 8 2 0
11 22 9 8 0
11 22 10 8 32
11 23 4 14 72
11 23 5 6 0
11 23 6 14 0
11 23 7 16 0
11 23 8 11 0
11 23 9 1 0
11 23 10 1 32
11 24 5 6 64
11 24 6 2 0
11 24 7 19 0
11 24 8 21 0
11 24 9 11 0
11 24 10 20 40
11 25 4 1 94
11 25 5 1 10
11 25 6 3 10
11 25 7 2 2
11 25 8 19 2
11 25 9 4 42
11 26 7 4 74
11 26 8 12 42
12 0 3 4 80
12 0 4 1 16
12 0 5 3 16
12 0 6 14 16
12 0 7 2 16
12 0 8 20 16
12 0 9 2 16
12 0 10 7 16
12 0 11 11 16
12 0 12 3 52
12 1 3 2 64
12 1 4 11 0
12 1 5 1 0
12 1 6 0 0
12 1 7 1 0
12 1 8 22 0
12 1 9 3 0
12 1 10 18 0
12 1 11 2 0
12 1 12 10 32
12 2 3 1 64
12 2 4 7 0
12 2 5 19 0
12 2 6 16 0
12 2 7 1 0
12 2 8 11 0
12 2 9 2 0
12 2 10 7 0
12 2 11 24 0
12 2 12 1 32
12 3 3 6 64
12 3 4 21 0
12 3 5 3 0
12 3 6 4 0
12 3 7 2 0
12 3 8 1 0
12 3 9 4 0
12 3 10 20 0
12 3 11 4 0
12 3 12 22 32
12 4 3 1 64
12 4 4 20 0
12 4 5 14 0
12 4 6 2 0
12 4 7 2 0
12 4 8 11 0
12 4 9 6 0
12 4 10 3 0
12 4 11 22 0
12 4 12 8 32
12 5 3 15 64
12 5 4 6 0
12 5 5 12 0
12 5 6 4 0
12 5 7 6 0
12 5 8 19 0
12 5 9 2 0
12 5 10 1 0
12 5 11 20 0
12 5 12 2 32
12 6 3 7 64
12 6 4 0 0
12 6 5 5 2
12 6 6 22 0
12 6 7 5 0
12 6 8 2 0
12 6 9 1 0
12 6 10 2 0
12 6 11 2 0
12 6 12 7 32
12 7 3 16 64
12 7 4 15 0
12 7 5 5 2
12 7 6 5 0
12 7 7 2 0
12 7 8 17 0
12 7 9 2 0
12 7 10 6 2
12 7 11 24 0
12 7 12 1 32
12 8 3 5 66
12 8 4 3 0
12 8 5 2 2
12 8 6 18 0
12 8 7 9 0
12 8 8 3 0
12 8 9 22 2
12 8 10 1 2
12 8 11 5 0
12 8 12 4 32
12 9 3 21 66
12 9 4 1 0
12 9 5 2 2
12 9 6 22 0
12 9 7 1 0
12 9 8 7 0
12 9 9 11 2
12 9 10 16 2
12 9 11 18 0
12 9 12 5 32
12 10 3 6 66
12 10 4 2 0
12 10 5 0 2
12 10 6 0 0
12 10 7 5 0
12 10 8 5 2
12 10 9 9 2
12 10 10 3 2
12 10 11 19 0
12 10 12 11 32
12 11 3 15 66
12 11 4 3 0
12 11 5 16 2
12 11 6 4 0
12 11 7 22 0
12 11 8 5 2
12 11 9 4 2
12 11 10 22 2
12 11 11 4 0
12 11 12 1 32
12 12 3 3 66
12 12 4 11 0
12 12 5 2 2
12 12 6 16 0
12 12 7 8 0
12 12 8 4 2
12 12 9 2 2
12 12 10 22 2
12 12 11 16 0
12 12 12 5 32
12 13 3 5 70
12 13 4 18 0
12 13 5 5 2
12 13 6 8 0
12 13 7 12 0
12 13 8 1 2
12 13 9 9 0
12 13 10 2 2
12 13 11 18 2
12 13 12 2 32
12 14 3 14 66
12 14 4 0 0
12 14 5 14 2
12 14 6 2 0
12 14 7 0 0
12 14 8 18 2
12 14 9 1 0
12 14 10 8 2
12 14 11 6 2
12 14 12 19 32
12 15 3 16 66
12 15 4 4 0
12 15 5 7 0
12 15 6 17 0
12 15 7 2 2
12 15 8 22 2
12 15 9 2 0
12 15 10 5 2
12 15 11 0 2
12 15 12 0 32
12 16 3 20 70
12 16 4 4 0
12 16 5 19 0
12 16 6 24 0
12 16 7 6 2
12 16 8 6 0
12 16 9 11 0
12 16 10 22 2
12 16 11 5 2
12 16 12 6 32
12 17 3 2 70
12 17 4 4 0
12 17 5 15 0
12 17 6 23 2
12 17 7 16 2
12 17 8 14 0
12 17 9 3 0
12 17 10 3 2
12 17 11 3 2
12 17 12 4 34
12 18 3 3 66
12 18 4 22 0
12 18 5 19 0
12 18 6 13 0
12 18 7 11 0
12 18 8 16 0
12 18 9 17 2
12 18 10 6 2
12 18 11 8 0
12 18 12 4 42
12 19 3 4 74
12 19 4 17 0
12 19 5 17 0
12 19 6 6 0
12 19 7 10 0
12 19 8 4 0
12 19 9 7 2
12 19 10 3 0
12 19 11 9 32
12 20 4 3 64
12 20 5 7 0
12 20 6 11 0
12 20 7 22 0
12 20 8 1 0
12 20 9 8 0
12 20 10 14 6
12 20 11 8 14
12 20 12 5 62
12 21 4 3 66
12 21 5 3 2
12 21 6 4 2
12 21 7 4 2
12 21 8 2 2
12 21 9 2 2
12 21 10 1 34
12 22 4 2 66
12 22 5 18 2
12 22 6 23 2
12 22 7 3 2
12 22 8 5 2
12 22 9 6 2
12 22 10 15 34
12 23 4 16 66
12 23 5 4 2
12 23 6 8 2
12 23 7 0 2
12 23 8 3 2
12 23 9 4 2
12 23 10 24 34
12 24 4 11 78
12 24 5 15 10
12 24 6 5 10
12 24 7 5 10
12 24 8 5 10
12 24 9 5 10
12 24 10 11 42
13 0 3 19 82
13 0 4 3 18
13 0 5 0 18
13 0 6 14 18
13 0 7 4 18
13 0 8 6 18
13 0 9 21 18
13 0 10 6 18
13 0 11 17 18
13 0 12 4 50
13 1 3 5 66
13 1 4 8 2
13 1 5 6 2
13 1 6 5 2
13 1 7 18 2
13 1 8 15 2
13 1 9 0 2
13 1 10 19 2
13 1 11 6 2
13 1 12 0 34
13 2 3 3 66
13 2 4 3 2
13 2 5 5 2
13 2 6 17 2
13 2 7 19 2
13 2 8 1 2
13 2 9 17 2
13 2 10 15 2
13 2 11 2 2
13 2 12 6 34
13 3 3 6 66
13 3 4 22 2
13 3 5 3 2
13 3 6 24 2
13 3 7 16 2
13 3 8 14 2
13 3 9 10 2
13 3 10 17 2
13 3 11 5 2
13 3 12 11 34
13 4 3 15 66
13 4 4 16 2
13 4 5 5 2
13 4 6 1 2
13 4 7 6 2
13 4 8 6 2
13 4 9 0 2
13 4 10 11 2
13 4 11 3 2
13 4 12 3 34
13 5 3 6 66
13 5 4 14 2
13 5 5 14 10
13 5 6 11 2
13 5 7 12 2
13 5 8 0 2
13 5 9 8 2
13 5 10 0 2
13 5 11 23 2
13 5 12 12 34
13 6 3 21 66
13 6 4 10 34
13 6 6 13 66
13 6 7 9 2
13 6 8 1 2
13 6 9 22 2
13 6 10 22 10
13 6 11 3 2
13 6 12 16 34
13 7 3 3 74
13 7 4 18 34
13 7 6 11 66
13 7 7 14 2
13 7 8 15 2
13 7 9 3 42
13 7 11 4 66
13 7 12 5 34
13 8 4 1 98
13 8 6 7 66
13 8 7 16 2
13 8 8 11 34
13 8 11 5 66
13 8 12 4 34
13 9 4 8 98
13 9 6 5 66
13 9 7 1 2
13 9 8 2 42
13 9 11 5 66
13 9 12 2 34
13 10 4 10 98
13 10 6 21 66
13 10 7 4 34
13 10 11 12 66
13 10 12 8 34
13 11 4 3 98
13 11 6 3 66
13 11 7 11 34
13 11 11 6 66
13 11 12 3 34
13 12 4 5 98
13 12 6 6 66
13 12 7 1 34
13 12 11 20 74
13 12 12 16 34
13 13 4 6 98
13 13 6 14 66
13 13 7 2 34
13 13 9 0 114
13 13 12 2 98
13 14 4 3 98
13 14 6 15 66
13 14 7 3 42
13 14 9 1 98
13 14 12 4 98
13 15 4 5 66
13 15 5 4 18
13 15 6 6 34
13 15 9 13 98
13 15 12 3 98
13 16 4 22 66
13 16 5 6 2
13 16 6 14 42
13 16 8 8 82
13 16 9 14 34
13 16 12 14 106
13 17 4 16 66
13 17 5 24 34
13 17 8 4 66
13 17 9 2 42
13 18 4 2 66
13 18 5 3 2
13 18 6 19 18
13 18 7 7 18
13 18 8 5 34
13 18 11 16 114
13 19 4 1 66
13 19 5 16 2
13 19 6 14 2
13 19 7 15 2
13 19 8 24 34
13 19 10 10 90
13 19 11 8 42
13 20 4 20 74
13 20 5 0 10
13 20 6 24 10
13 20 7 14 10
13 20 8 6 10
13 20 9 0 58
