Qubicle Exchange Format
Version 0.2
www.minddesk.com
8 8 8
56
0.000000 0.000000 0.000000
0.000000 0.541176 0.211765
0.000000 0.552941 0.211765
0.003922 0.215686 0.074510
0.074510 0.270588 0.145098
0.082353 0.286275 0.149020
0.094118 0.278431 0.152941
0.145098 0.345098 0.211765
0.152941 0.341176 0.219608
0.239216 0.164706 0.000000
0.243137 0.164706 0.000000
0.247059 0.168627 0.000000
0.254902 0.176471 0.003922
0.258824 0.184314 0.011765
0.262745 0.184314 0.015686
0.266667 0.192157 0.023529
0.270588 0.196078 0.027451
0.274510 0.200000 0.031373
0.333333 0.333333 0.333333
0.843137 0.505882 0.184314
0.858824 0.513726 0.184314
0.862745 0.643137 0.603922
0.866667 0.541176 0.227451
0.866667 0.866667 0.866667
0.870588 0.525490 0.196078
0.870588 0.529412 0.207843
0.874510 0.525490 0.188235
0.886275 0.556863 0.243137
0.890196 0.560784 0.247059
0.890196 0.564706 0.254902
0.894118 0.686275 0.647059
0.898039 0.576471 0.270588
0.917647 0.556863 0.207843
0.921569 0.556863 0.207843
0.921569 0.564706 0.223529
0.921569 0.572549 0.247059
0.929412 0.552941 0.200000
0.929412 0.698039 0.650980
0.945098 0.572549 0.215686
0.945098 0.580392 0.239216
0.945098 0.611765 0.294118
0.949020 0.568627 0.207843
0.949020 0.600000 0.258824
0.949020 0.603922 0.266667
0.956863 0.741176 0.698039
0.964706 0.584314 0.227451
0.964706 0.611765 0.274510
0.964706 0.733333 0.690196
0.968627 0.611765 0.270588
0.976471 0.631373 0.290196
0.976471 0.631373 0.301961
0.976471 0.635294 0.313726
0.976471 0.647059 0.333333
0.976471 0.749020 0.709804
0.988235 0.988235 0.988235
1.000000 1.000000 1.000000
0 4 2 18 126
0 4 3 18 126
0 4 4 18 126
0 5 2 18 126
0 5 3 18 126
0 5 4 18 126
0 6 2 18 126
0 6 3 18 126
0 6 4 18 126
0 7 2 18 126
0 7 3 18 126
0 7 4 18 126
1 2 3 55 126
1 2 4 55 126
1 2 5 18 126
1 2 6 18 126
1 4 1 18 126
1 4 2 18 126
1 4 3 18 126
1 4 4 18 126
1 4 5 18 126
1 4 6 18 126
1 5 1 18 126
1 5 2 13 0
1 5 3 14 0
1 5 4 13 0
1 5 5 18 126
1 5 6 18 126
1 6 1 18 126
1 6 2 16 0
1 6 3 15 0
1 6 4 11 0
1 6 5 18 126
1 6 6 18 126
1 7 2 18 126
1 7 3 18 126
1 7 4 18 126
2 0 3 18 126
2 0 4 18 126
2 1 3 18 126
2 1 4 18 126
2 2 2 55 126
2 2 3 54 0
2 2 4 23 0
2 2 5 55 126
2 3 2 55 126
2 3 3 55 126
2 3 4 55 126
2 3 5 55 126
2 4 1 18 126
2 4 2 45 0
2 4 3 32 0
2 4 4 50 0
2 4 5 40 0
2 4 6 18 126
2 5 1 18 126
2 5 2 46 0
2 5 3 19 0
2 5 4 49 0
2 5 5 42 0
2 5 6 2 32
2 6 1 18 126
2 6 2 12 0
2 6 3 41 0
2 6 4 38 0
2 6 5 18 126
2 6 6 18 126
2 7 2 18 126
2 7 3 18 126
2 7 4 18 126
3 2 2 55 126
3 2 3 55 126
3 2 4 55 126
3 2 5 55 126
3 3 2 55 126
3 3 3 52 0
3 3 4 28 0
3 3 5 55 126
3 4 1 18 126
3 4 2 29 0
3 4 3 33 0
3 4 4 48 0
3 4 5 34 0
3 4 6 0 48
3 5 1 18 126
3 5 2 20 0
3 5 3 35 0
3 5 4 31 0
3 5 5 36 0
3 5 6 18 126
3 6 1 18 126
3 6 2 18 126
3 6 3 18 126
3 6 4 18 126
3 6 5 18 126
3 6 6 18 126
4 2 2 55 126
4 2 3 55 126
4 2 4 55 126
4 2 5 55 126
4 3 2 55 126
4 3 3 47 0
4 3 4 30 0
4 3 5 55 126
4 4 1 18 126
4 4 2 8 0
4 4 3 6 0
4 4 4 21 0
4 4 5 24 0
4 4 6 0 48
4 5 1 18 126
4 5 2 50 0
4 5 3 26 0
4 5 4 39 0
4 5 5 51 0
4 5 6 18 126
4 6 1 18 126
4 6 2 18 126
4 6 3 18 126
4 6 4 18 126
4 6 5 18 126
4 6 6 18 126
5 0 3 18 126
5 0 4 18 126
5 1 3 18 126
5 1 4 18 126
5 2 2 55 126
5 2 3 37 0
5 2 4 44 0
5 2 5 55 126
5 3 2 55 126
5 3 3 55 126
5 3 4 55 126
5 3 5 55 126
5 4 1 18 126
5 4 2 3 0
5 4 3 7 0
5 4 4 53 0
5 4 5 30 0
5 4 6 18 126
5 5 1 18 126
5 5 2 5 0
5 5 3 4 0
5 5 4 25 0
5 5 5 22 0
5 5 6 1 32
5 6 1 18 126
5 6 2 11 0
5 6 3 43 0
5 6 4 27 0
5 6 5 18 126
5 6 6 18 126
5 7 2 18 126
5 7 3 18 126
5 7 4 18 126
6 2 3 55 126
6 2 4 55 126
6 2 5 18 126
6 2 6 18 126
6 4 1 18 126
6 4 2 18 126
6 4 3 18 126
6 4 4 18 126
6 4 5 18 126
6 4 6 18 126
6 5 1 18 126
6 5 2 9 0
6 5 3 13 0
6 5 4 15 0
6 5 5 18 126
6 5 6 18 126
6 6 1 18 126
6 6 2 11 0
6 6 3 17 0
6 6 4 10 0
6 6 5 18 126
6 6 6 18 126
6 7 2 18 126
6 7 3 18 126
6 7 4 18 126
7 4 2 18 126
7 4 3 18 126
7 4 4 18 126
7 5 2 18 126
7 5 3 18 126
7 5 4 18 126
7 6 2 18 126
7 6 3 18 126
7 6 4 18 126
7 7 2 18 126
7 7 3 18 126
7 7 4 18 126
