Qubicle Exchange Format
Version 0.2
www.minddesk.com
16 16 16
57
0.000000 0.000000 0.000000
0.000000 0.541176 0.211765
0.000000 0.552941 0.211765
0.003922 0.215686 0.074510
0.074510 0.270588 0.145098
0.082353 0.286275 0.149020
0.094118 0.278431 0.152941
0.145098 0.345098 0.211765
0.152941 0.341176 0.219608
0.239216 0.164706 0.000000
0.243137 0.164706 0.000000
0.247059 0.168627 0.000000
0.254902 0.176471 0.003922
0.258824 0.184314 0.011765
0.262745 0.184314 0.015686
0.266667 0.192157 0.023529
0.270588 0.196078 0.027451
0.274510 0.200000 0.031373
0.333333 0.333333 0.333333
0.600000 0.600000 0.600000
0.843137 0.505882 0.184314
0.858824 0.513726 0.184314
0.862745 0.643137 0.603922
0.866667 0.541176 0.227451
0.866667 0.866667 0.866667
0.870588 0.525490 0.196078
0.870588 0.529412 0.207843
0.874510 0.525490 0.188235
0.886275 0.556863 0.243137
0.890196 0.560784 0.247059
0.890196 0.564706 0.254902
0.894118 0.686275 0.647059
0.898039 0.576471 0.270588
0.917647 0.556863 0.207843
0.921569 0.556863 0.207843
0.921569 0.564706 0.223529
0.921569 0.572549 0.247059
0.929412 0.552941 0.200000
0.929412 0.698039 0.650980
0.945098 0.572549 0.215686
0.945098 0.580392 0.239216
0.945098 0.611765 0.294118
0.949020 0.568627 0.207843
0.949020 0.600000 0.258824
0.949020 0.603922 0.266667
0.956863 0.741176 0.698039
0.964706 0.584314 0.227451
0.964706 0.611765 0.274510
0.964706 0.733333 0.690196
0.968627 0.611765 0.270588
0.976471 0.631373 0.290196
0.976471 0.631373 0.301961
0.976471 0.635294 0.313726
0.976471 0.647059 0.333333
0.976471 0.749020 0.709804
0.988235 0.988235 0.988235
1.000000 1.000000 1.000000
0 0 0 19 126
0 0 1 19 126
0 0 2 19 126
0 0 3 19 126
0 0 4 19 126
0 0 5 19 126
0 0 6 19 126
0 0 7 19 126
0 0 8 19 126
0 0 9 19 126
0 0 10 19 126
0 0 11 19 126
0 0 12 19 126
0 0 13 19 126
0 0 14 19 126
0 0 15 19 126
0 1 0 19 126
0 1 15 19 126
0 2 0 19 126
0 2 15 19 126
0 3 0 19 126
0 3 15 19 126
0 4 0 19 126
0 4 15 19 126
0 5 0 19 126
0 5 15 19 126
0 6 0 19 126
0 6 15 19 126
0 7 0 19 126
0 7 15 19 126
0 8 0 19 126
0 8 6 18 84
0 8 7 18 20
0 8 8 18 20
0 8 9 18 20
0 8 10 18 20
0 8 11 18 52
0 8 15 19 126
0 9 0 19 126
0 9 6 18 68
0 9 7 18 4
0 9 8 18 4
0 9 9 18 4
0 9 10 18 4
0 9 11 18 36
0 9 15 19 126
0 10 0 19 126
0 10 6 18 68
0 10 7 18 4
0 10 8 18 4
0 10 9 18 4
0 10 10 18 4
0 10 11 18 36
0 10 15 19 126
0 11 0 19 126
0 11 6 18 68
0 11 7 18 4
0 11 8 18 4
0 11 9 18 4
0 11 10 18 4
0 11 11 18 36
0 11 15 19 126
0 12 0 19 126
0 12 6 18 68
0 12 7 18 4
0 12 8 18 4
0 12 9 18 4
0 12 10 18 4
0 12 11 18 36
0 12 15 19 126
0 13 0 19 126
0 13 6 18 68
0 13 7 18 4
0 13 8 18 4
0 13 9 18 4
0 13 10 18 4
0 13 11 18 36
0 13 15 19 126
0 14 0 19 126
0 14 6 18 68
0 14 7 18 4
0 14 8 18 4
0 14 9 18 4
0 14 10 18 4
0 14 11 18 36
0 14 15 19 126
0 15 0 19 126
0 15 1 19 126
0 15 2 19 126
0 15 3 19 126
0 15 4 19 126
0 15 5 19 126
0 15 6 19 126
0 15 7 19 126
0 15 8 19 126
0 15 9 19 126
0 15 10 19 126
0 15 11 19 126
0 15 12 19 126
0 15 13 19 126
0 15 14 19 126
0 15 15 19 126
1 0 0 19 126
1 0 15 19 126
1 8 6 18 80
1 8 7 18 16
1 8 8 18 16
1 8 9 18 16
1 8 10 18 16
1 8 11 18 48
1 9 6 18 64
1 9 7 18 0
1 9 8 18 0
1 9 9 18 0
1 9 10 18 0
1 9 11 18 32
1 10 6 18 64
1 10 7 18 0
1 10 8 18 0
1 10 9 18 0
1 10 10 18 0
1 10 11 18 32
1 11 6 18 64
1 11 7 18 0
1 11 8 18 0
1 11 9 18 0
1 11 10 18 0
1 11 11 18 32
1 12 6 18 64
1 12 7 18 0
1 12 8 18 0
1 12 9 18 0
1 12 10 18 0
1 12 11 18 32
1 13 6 18 64
1 13 7 18 0
1 13 8 18 0
1 13 9 18 0
1 13 10 18 0
1 13 11 18 32
1 14 6 18 64
1 14 7 18 0
1 14 8 18 0
1 14 9 18 0
1 14 10 18 0
1 14 11 18 32
1 15 0 19 126
1 15 6 18 72
1 15 7 18 8
1 15 8 18 8
1 15 9 18 8
1 15 10 18 8
1 15 11 18 40
1 15 15 19 126
2 0 0 19 126
2 0 15 19 126
2 4 2 18 84
2 4 3 18 20
2 4 4 18 20
2 4 5 18 20
2 4 6 56 20
2 4 7 56 20
2 4 8 56 20
2 4 9 56 52
2 5 2 18 76
2 5 3 18 12
2 5 4 18 12
2 5 5 18 12
2 5 6 56 12
2 5 7 56 12
2 5 8 56 12
2 5 9 56 44
2 8 2 18 84
2 8 3 18 20
2 8 4 18 20
2 8 5 18 20
2 8 6 18 16
2 8 7 18 16
2 8 8 18 16
2 8 9 18 16
2 8 10 18 16
2 8 11 18 16
2 8 12 18 20
2 8 13 18 52
2 9 2 18 68
2 9 3 18 4
2 9 4 18 4
2 9 5 18 4
2 9 6 18 0
2 9 7 18 0
2 9 8 18 0
2 9 9 18 0
2 9 10 18 0
2 9 11 18 0
2 9 12 18 4
2 9 13 18 36
2 10 2 18 68
2 10 3 18 4
2 10 4 18 4
2 10 5 18 4
2 10 6 13 0
2 10 7 13 0
2 10 8 14 0
2 10 9 14 0
2 10 10 13 0
2 10 11 13 0
2 10 12 18 4
2 10 13 18 36
2 11 2 18 68
2 11 3 18 4
2 11 4 18 4
2 11 5 18 4
2 11 6 13 0
2 11 7 13 0
2 11 8 14 0
2 11 9 14 0
2 11 10 13 0
2 11 11 13 0
2 11 12 18 4
2 11 13 18 36
2 12 2 18 68
2 12 3 18 4
2 12 4 18 4
2 12 5 18 4
2 12 6 11 0
2 12 7 11 0
2 12 8 15 0
2 12 9 15 0
2 12 10 16 0
2 12 11 16 0
2 12 12 18 4
2 12 13 18 36
2 13 2 18 76
2 13 3 18 12
2 13 4 18 12
2 13 5 18 12
2 13 6 11 0
2 13 7 11 0
2 13 8 15 0
2 13 9 15 0
2 13 10 16 0
2 13 11 16 0
2 13 12 18 12
2 13 13 18 44
2 14 6 18 64
2 14 7 18 0
2 14 8 18 0
2 14 9 18 0
2 14 10 18 0
2 14 11 18 32
2 15 0 19 126
2 15 6 18 72
2 15 7 18 8
2 15 8 18 8
2 15 9 18 8
2 15 10 18 8
2 15 11 18 40
2 15 15 19 126
3 0 0 19 126
3 0 15 19 126
3 4 2 18 82
3 4 3 18 18
3 4 4 18 16
3 4 5 18 16
3 4 6 56 16
3 4 7 56 16
3 4 8 56 16
3 4 9 56 48
3 5 2 18 74
3 5 3 18 10
3 5 4 18 8
3 5 5 18 8
3 5 6 56 8
3 5 7 56 8
3 5 8 56 8
3 5 9 56 40
3 8 2 18 80
3 8 3 18 16
3 8 4 18 16
3 8 5 18 16
3 8 6 18 16
3 8 7 18 16
3 8 8 18 16
3 8 9 18 16
3 8 10 18 16
3 8 11 18 16
3 8 12 18 16
3 8 13 18 48
3 9 2 18 64
3 9 3 18 0
3 9 4 18 0
3 9 5 18 0
3 9 6 18 0
3 9 7 18 0
3 9 8 18 0
3 9 9 18 0
3 9 10 18 0
3 9 11 18 0
3 9 12 18 0
3 9 13 18 32
3 10 2 18 64
3 10 3 18 0
3 10 4 18 0
3 10 5 18 0
3 10 6 13 0
3 10 7 13 0
3 10 8 14 0
3 10 9 14 0
3 10 10 13 0
3 10 11 13 0
3 10 12 18 0
3 10 13 18 32
3 11 2 18 64
3 11 3 18 0
3 11 4 18 0
3 11 5 18 0
3 11 6 13 0
3 11 7 13 0
3 11 8 14 0
3 11 9 14 0
3 11 10 13 0
3 11 11 13 0
3 11 12 18 0
3 11 13 18 32
3 12 2 18 64
3 12 3 18 0
3 12 4 18 0
3 12 5 18 0
3 12 6 11 0
3 12 7 11 0
3 12 8 15 0
3 12 9 15 0
3 12 10 16 0
3 12 11 16 0
3 12 12 18 0
3 12 13 18 32
3 13 2 18 72
3 13 3 18 8
3 13 4 18 8
3 13 5 18 8
3 13 6 11 0
3 13 7 11 0
3 13 8 15 0
3 13 9 15 0
3 13 10 16 0
3 13 11 16 0
3 13 12 18 8
3 13 13 18 40
3 14 6 18 64
3 14 7 18 0
3 14 8 18 0
3 14 9 18 0
3 14 10 18 0
3 14 11 18 32
3 15 0 19 126
3 15 6 18 72
3 15 7 18 8
3 15 8 18 8
3 15 9 18 8
3 15 10 18 8
3 15 11 18 40
3 15 15 19 126
4 0 0 19 126
4 0 6 18 84
4 0 7 18 20
4 0 8 18 20
4 0 9 18 52
4 0 15 19 126
4 1 6 18 68
4 1 7 18 4
4 1 8 18 4
4 1 9 18 36
4 2 6 18 68
4 2 7 18 4
4 2 8 18 4
4 2 9 18 36
4 3 6 18 68
4 3 7 18 4
4 3 8 18 4
4 3 9 18 36
4 4 4 56 80
4 4 5 56 16
4 4 6 24 0
4 4 7 24 0
4 4 8 55 0
4 4 9 55 0
4 4 10 56 20
4 4 11 56 52
4 5 4 56 64
4 5 5 56 0
4 5 6 24 0
4 5 7 24 0
4 5 8 55 0
4 5 9 55 0
4 5 10 56 4
4 5 11 56 36
4 6 4 56 68
4 6 5 56 4
4 6 6 56 4
4 6 7 56 4
4 6 8 56 4
4 6 9 56 4
4 6 10 56 4
4 6 11 56 36
4 7 4 56 68
4 7 5 56 4
4 7 6 56 4
4 7 7 56 4
4 7 8 56 4
4 7 9 56 4
4 7 10 56 4
4 7 11 56 36
4 8 2 18 80
4 8 3 18 16
4 8 4 41 0
4 8 5 41 0
4 8 6 51 0
4 8 7 51 0
4 8 8 33 0
4 8 9 33 0
4 8 10 46 0
4 8 11 46 0
4 8 12 18 16
4 8 13 18 48
4 9 2 18 64
4 9 3 18 0
4 9 4 41 0
4 9 5 41 0
4 9 6 51 0
4 9 7 51 0
4 9 8 33 0
4 9 9 33 0
4 9 10 46 0
4 9 11 46 0
4 9 12 18 0
4 9 13 18 32
4 10 2 2 64
4 10 3 2 0
4 10 4 43 0
4 10 5 43 0
4 10 6 50 0
4 10 7 50 0
4 10 8 20 0
4 10 9 20 0
4 10 10 47 0
4 10 11 47 0
4 10 12 18 0
4 10 13 18 32
4 11 2 2 64
4 11 3 2 0
4 11 4 43 0
4 11 5 43 0
4 11 6 50 0
4 11 7 50 0
4 11 8 20 0
4 11 9 20 0
4 11 10 47 0
4 11 11 47 0
4 11 12 18 0
4 11 13 18 32
4 12 2 18 64
4 12 3 18 0
4 12 4 18 0
4 12 5 18 0
4 12 6 39 0
4 12 7 39 0
4 12 8 42 0
4 12 9 42 0
4 12 10 12 0
4 12 11 12 0
4 12 12 18 0
4 12 13 18 32
4 13 2 18 72
4 13 3 18 8
4 13 4 18 8
4 13 5 18 8
4 13 6 39 0
4 13 7 39 0
4 13 8 42 0
4 13 9 42 0
4 13 10 12 0
4 13 11 12 0
4 13 12 18 8
4 13 13 18 40
4 14 6 18 64
4 14 7 18 0
4 14 8 18 0
4 14 9 18 0
4 14 10 18 0
4 14 11 18 32
4 15 0 19 126
4 15 6 18 72
4 15 7 18 8
4 15 8 18 8
4 15 9 18 8
4 15 10 18 8
4 15 11 18 40
4 15 15 19 126
5 0 0 19 126
5 0 6 18 82
5 0 7 18 18
5 0 8 18 18
5 0 9 18 50
5 0 15 19 126
5 1 6 18 66
5 1 7 18 2
5 1 8 18 2
5 1 9 18 34
5 2 6 18 66
5 2 7 18 2
5 2 8 18 2
5 2 9 18 34
5 3 6 18 66
5 3 7 18 2
5 3 8 18 2
5 3 9 18 34
5 4 4 56 80
5 4 5 56 16
5 4 6 24 0
5 4 7 24 0
5 4 8 55 0
5 4 9 55 0
5 4 10 56 16
5 4 11 56 48
5 5 4 56 64
5 5 5 56 0
5 5 6 24 0
5 5 7 24 0
5 5 8 55 0
5 5 9 55 0
5 5 10 56 0
5 5 11 56 32
5 6 4 56 64
5 6 5 56 0
5 6 6 56 0
5 6 7 56 0
5 6 8 56 0
5 6 9 56 0
5 6 10 56 0
5 6 11 56 32
5 7 4 56 64
5 7 5 56 0
5 7 6 56 0
5 7 7 56 0
5 7 8 56 0
5 7 9 56 0
5 7 10 56 0
5 7 11 56 32
5 8 2 18 80
5 8 3 18 16
5 8 4 41 0
5 8 5 41 0
5 8 6 51 0
5 8 7 51 0
5 8 8 33 0
5 8 9 33 0
5 8 10 46 0
5 8 11 46 0
5 8 12 18 16
5 8 13 18 48
5 9 2 18 64
5 9 3 18 0
5 9 4 41 0
5 9 5 41 0
5 9 6 51 0
5 9 7 51 0
5 9 8 33 0
5 9 9 33 0
5 9 10 46 0
5 9 11 46 0
5 9 12 18 0
5 9 13 18 32
5 10 2 2 64
5 10 3 2 0
5 10 4 43 0
5 10 5 43 0
5 10 6 50 0
5 10 7 50 0
5 10 8 20 0
5 10 9 20 0
5 10 10 47 0
5 10 11 47 0
5 10 12 18 0
5 10 13 18 32
5 11 2 2 64
5 11 3 2 0
5 11 4 43 0
5 11 5 43 0
5 11 6 50 0
5 11 7 50 0
5 11 8 20 0
5 11 9 20 0
5 11 10 47 0
5 11 11 47 0
5 11 12 18 0
5 11 13 18 32
5 12 2 18 64
5 12 3 18 0
5 12 4 18 0
5 12 5 18 0
5 12 6 39 0
5 12 7 39 0
5 12 8 42 0
5 12 9 42 0
5 12 10 12 0
5 12 11 12 0
5 12 12 18 0
5 12 13 18 32
5 13 2 18 72
5 13 3 18 8
5 13 4 18 8
5 13 5 18 8
5 13 6 39 0
5 13 7 39 0
5 13 8 42 0
5 13 9 42 0
5 13 10 12 0
5 13 11 12 0
5 13 12 18 8
5 13 13 18 40
5 14 6 18 66
5 14 7 18 2
5 14 8 18 2
5 14 9 18 2
5 14 10 18 2
5 14 11 18 34
5 15 0 19 126
5 15 6 18 74
5 15 7 18 10
5 15 8 18 10
5 15 9 18 10
5 15 10 18 10
5 15 11 18 42
5 15 15 19 126
6 0 0 19 126
6 0 15 19 126
6 4 4 56 80
6 4 5 56 16
6 4 6 56 16
6 4 7 56 16
6 4 8 56 16
6 4 9 56 16
6 4 10 56 16
6 4 11 56 48
6 5 4 56 64
6 5 5 56 0
6 5 6 56 0
6 5 7 56 0
6 5 8 56 0
6 5 9 56 0
6 5 10 56 0
6 5 11 56 32
6 6 4 56 64
6 6 5 56 0
6 6 6 29 0
6 6 7 29 0
6 6 8 53 0
6 6 9 53 0
6 6 10 56 0
6 6 11 56 32
6 7 4 56 64
6 7 5 56 0
6 7 6 29 0
6 7 7 29 0
6 7 8 53 0
6 7 9 53 0
6 7 10 56 0
6 7 11 56 32
6 8 2 0 80
6 8 3 0 16
6 8 4 35 0
6 8 5 35 0
6 8 6 49 0
6 8 7 49 0
6 8 8 34 0
6 8 9 34 0
6 8 10 30 0
6 8 11 30 0
6 8 12 18 16
6 8 13 18 48
6 9 2 0 64
6 9 3 0 0
6 9 4 35 0
6 9 5 35 0
6 9 6 49 0
6 9 7 49 0
6 9 8 34 0
6 9 9 34 0
6 9 10 30 0
6 9 11 30 0
6 9 12 18 0
6 9 13 18 32
6 10 2 18 64
6 10 3 18 0
6 10 4 37 0
6 10 5 37 0
6 10 6 32 0
6 10 7 32 0
6 10 8 36 0
6 10 9 36 0
6 10 10 21 0
6 10 11 21 0
6 10 12 18 0
6 10 13 18 32
6 11 2 18 64
6 11 3 18 0
6 11 4 37 0
6 11 5 37 0
6 11 6 32 0
6 11 7 32 0
6 11 8 36 0
6 11 9 36 0
6 11 10 21 0
6 11 11 21 0
6 11 12 18 0
6 11 13 18 32
6 12 2 18 64
6 12 3 18 0
6 12 4 18 0
6 12 5 18 0
6 12 6 18 0
6 12 7 18 0
6 12 8 18 0
6 12 9 18 0
6 12 10 18 0
6 12 11 18 0
6 12 12 18 0
6 12 13 18 32
6 13 2 18 72
6 13 3 18 8
6 13 4 18 8
6 13 5 18 8
6 13 6 18 8
6 13 7 18 8
6 13 8 18 8
6 13 9 18 8
6 13 10 18 8
6 13 11 18 8
6 13 12 18 8
6 13 13 18 40
6 15 0 19 126
6 15 15 19 126
7 0 0 19 126
7 0 15 19 126
7 4 4 56 80
7 4 5 56 16
7 4 6 56 16
7 4 7 56 16
7 4 8 56 16
7 4 9 56 16
7 4 10 56 16
7 4 11 56 48
7 5 4 56 64
7 5 5 56 0
7 5 6 56 0
7 5 7 56 0
7 5 8 56 0
7 5 9 56 0
7 5 10 56 0
7 5 11 56 32
7 6 4 56 64
7 6 5 56 0
7 6 6 29 0
7 6 7 29 0
7 6 8 53 0
7 6 9 53 0
7 6 10 56 0
7 6 11 56 32
7 7 4 56 64
7 7 5 56 0
7 7 6 29 0
7 7 7 29 0
7 7 8 53 0
7 7 9 53 0
7 7 10 56 0
7 7 11 56 32
7 8 2 0 80
7 8 3 0 16
7 8 4 35 0
7 8 5 35 0
7 8 6 49 0
7 8 7 49 0
7 8 8 34 0
7 8 9 34 0
7 8 10 30 0
7 8 11 30 0
7 8 12 18 16
7 8 13 18 48
7 9 2 0 64
7 9 3 0 0
7 9 4 35 0
7 9 5 35 0
7 9 6 49 0
7 9 7 49 0
7 9 8 34 0
7 9 9 34 0
7 9 10 30 0
7 9 11 30 0
7 9 12 18 0
7 9 13 18 32
7 10 2 18 64
7 10 3 18 0
7 10 4 37 0
7 10 5 37 0
7 10 6 32 0
7 10 7 32 0
7 10 8 36 0
7 10 9 36 0
7 10 10 21 0
7 10 11 21 0
7 10 12 18 0
7 10 13 18 32
7 11 2 18 64
7 11 3 18 0
7 11 4 37 0
7 11 5 37 0
7 11 6 32 0
7 11 7 32 0
7 11 8 36 0
7 11 9 36 0
7 11 10 21 0
7 11 11 21 0
7 11 12 18 0
7 11 13 18 32
7 12 2 18 64
7 12 3 18 0
7 12 4 18 0
7 12 5 18 0
7 12 6 18 0
7 12 7 18 0
7 12 8 18 0
7 12 9 18 0
7 12 10 18 0
7 12 11 18 0
7 12 12 18 0
7 12 13 18 32
7 13 2 18 72
7 13 3 18 8
7 13 4 18 8
7 13 5 18 8
7 13 6 18 8
7 13 7 18 8
7 13 8 18 8
7 13 9 18 8
7 13 10 18 8
7 13 11 18 8
7 13 12 18 8
7 13 13 18 40
7 15 0 19 126
7 15 15 19 126
8 0 0 19 126
8 0 15 19 126
8 4 4 56 80
8 4 5 56 16
8 4 6 56 16
8 4 7 56 16
8 4 8 56 16
8 4 9 56 16
8 4 10 56 16
8 4 11 56 48
8 5 4 56 64
8 5 5 56 0
8 5 6 56 0
8 5 7 56 0
8 5 8 56 0
8 5 9 56 0
8 5 10 56 0
8 5 11 56 32
8 6 4 56 64
8 6 5 56 0
8 6 6 31 0
8 6 7 31 0
8 6 8 48 0
8 6 9 48 0
8 6 10 56 0
8 6 11 56 32
8 7 4 56 64
8 7 5 56 0
8 7 6 31 0
8 7 7 31 0
8 7 8 48 0
8 7 9 48 0
8 7 10 56 0
8 7 11 56 32
8 8 2 0 80
8 8 3 0 16
8 8 4 25 0
8 8 5 25 0
8 8 6 22 0
8 8 7 22 0
8 8 8 6 0
8 8 9 6 0
8 8 10 8 0
8 8 11 8 0
8 8 12 18 16
8 8 13 18 48
8 9 2 0 64
8 9 3 0 0
8 9 4 25 0
8 9 5 25 0
8 9 6 22 0
8 9 7 22 0
8 9 8 6 0
8 9 9 6 0
8 9 10 8 0
8 9 11 8 0
8 9 12 18 0
8 9 13 18 32
8 10 2 18 64
8 10 3 18 0
8 10 4 52 0
8 10 5 52 0
8 10 6 40 0
8 10 7 40 0
8 10 8 27 0
8 10 9 27 0
8 10 10 51 0
8 10 11 51 0
8 10 12 18 0
8 10 13 18 32
8 11 2 18 64
8 11 3 18 0
8 11 4 52 0
8 11 5 52 0
8 11 6 40 0
8 11 7 40 0
8 11 8 27 0
8 11 9 27 0
8 11 10 51 0
8 11 11 51 0
8 11 12 18 0
8 11 13 18 32
8 12 2 18 64
8 12 3 18 0
8 12 4 18 0
8 12 5 18 0
8 12 6 18 0
8 12 7 18 0
8 12 8 18 0
8 12 9 18 0
8 12 10 18 0
8 12 11 18 0
8 12 12 18 0
8 12 13 18 32
8 13 2 18 72
8 13 3 18 8
8 13 4 18 8
8 13 5 18 8
8 13 6 18 8
8 13 7 18 8
8 13 8 18 8
8 13 9 18 8
8 13 10 18 8
8 13 11 18 8
8 13 12 18 8
8 13 13 18 40
8 15 0 19 126
8 15 15 19 126
9 0 0 19 126
9 0 15 19 126
9 4 4 56 80
9 4 5 56 16
9 4 6 56 16
9 4 7 56 16
9 4 8 56 16
9 4 9 56 16
9 4 10 56 16
9 4 11 56 48
9 5 4 56 64
9 5 5 56 0
9 5 6 56 0
9 5 7 56 0
9 5 8 56 0
9 5 9 56 0
9 5 10 56 0
9 5 11 56 32
9 6 4 56 64
9 6 5 56 0
9 6 6 31 0
9 6 7 31 0
9 6 8 48 0
9 6 9 48 0
9 6 10 56 0
9 6 11 56 32
9 7 4 56 64
9 7 5 56 0
9 7 6 31 0
9 7 7 31 0
9 7 8 48 0
9 7 9 48 0
9 7 10 56 0
9 7 11 56 32
9 8 2 0 80
9 8 3 0 16
9 8 4 25 0
9 8 5 25 0
9 8 6 22 0
9 8 7 22 0
9 8 8 6 0
9 8 9 6 0
9 8 10 8 0
9 8 11 8 0
9 8 12 18 16
9 8 13 18 48
9 9 2 0 64
9 9 3 0 0
9 9 4 25 0
9 9 5 25 0
9 9 6 22 0
9 9 7 22 0
9 9 8 6 0
9 9 9 6 0
9 9 10 8 0
9 9 11 8 0
9 9 12 18 0
9 9 13 18 32
9 10 2 18 64
9 10 3 18 0
9 10 4 52 0
9 10 5 52 0
9 10 6 40 0
9 10 7 40 0
9 10 8 27 0
9 10 9 27 0
9 10 10 51 0
9 10 11 51 0
9 10 12 18 0
9 10 13 18 32
9 11 2 18 64
9 11 3 18 0
9 11 4 52 0
9 11 5 52 0
9 11 6 40 0
9 11 7 40 0
9 11 8 27 0
9 11 9 27 0
9 11 10 51 0
9 11 11 51 0
9 11 12 18 0
9 11 13 18 32
9 12 2 18 64
9 12 3 18 0
9 12 4 18 0
9 12 5 18 0
9 12 6 18 0
9 12 7 18 0
9 12 8 18 0
9 12 9 18 0
9 12 10 18 0
9 12 11 18 0
9 12 12 18 0
9 12 13 18 32
9 13 2 18 72
9 13 3 18 8
9 13 4 18 8
9 13 5 18 8
9 13 6 18 8
9 13 7 18 8
9 13 8 18 8
9 13 9 18 8
9 13 10 18 8
9 13 11 18 8
9 13 12 18 8
9 13 13 18 40
9 15 0 19 126
9 15 15 19 126
10 0 0 19 126
10 0 6 18 84
10 0 7 18 20
10 0 8 18 20
10 0 9 18 52
10 0 15 19 126
10 1 6 18 68
10 1 7 18 4
10 1 8 18 4
10 1 9 18 36
10 2 6 18 68
10 2 7 18 4
10 2 8 18 4
10 2 9 18 36
10 3 6 18 68
10 3 7 18 4
10 3 8 18 4
10 3 9 18 36
10 4 4 56 80
10 4 5 56 16
10 4 6 45 0
10 4 7 45 0
10 4 8 38 0
10 4 9 38 0
10 4 10 56 16
10 4 11 56 48
10 5 4 56 64
10 5 5 56 0
10 5 6 45 0
10 5 7 45 0
10 5 8 38 0
10 5 9 38 0
10 5 10 56 0
10 5 11 56 32
10 6 4 56 64
10 6 5 56 0
10 6 6 56 0
10 6 7 56 0
10 6 8 56 0
10 6 9 56 0
10 6 10 56 0
10 6 11 56 32
10 7 4 56 64
10 7 5 56 0
10 7 6 56 0
10 7 7 56 0
10 7 8 56 0
10 7 9 56 0
10 7 10 56 0
10 7 11 56 32
10 8 2 18 80
10 8 3 18 16
10 8 4 31 0
10 8 5 31 0
10 8 6 54 0
10 8 7 54 0
10 8 8 7 0
10 8 9 7 0
10 8 10 3 0
10 8 11 3 0
10 8 12 18 16
10 8 13 18 48
10 9 2 18 64
10 9 3 18 0
10 9 4 31 0
10 9 5 31 0
10 9 6 54 0
10 9 7 54 0
10 9 8 7 0
10 9 9 7 0
10 9 10 3 0
10 9 11 3 0
10 9 12 18 0
10 9 13 18 32
10 10 2 1 64
10 10 3 1 0
10 10 4 23 0
10 10 5 23 0
10 10 6 26 0
10 10 7 26 0
10 10 8 4 0
10 10 9 4 0
10 10 10 5 0
10 10 11 5 0
10 10 12 18 0
10 10 13 18 32
10 11 2 1 64
10 11 3 1 0
10 11 4 23 0
10 11 5 23 0
10 11 6 26 0
10 11 7 26 0
10 11 8 4 0
10 11 9 4 0
10 11 10 5 0
10 11 11 5 0
10 11 12 18 0
10 11 13 18 32
10 12 2 18 64
10 12 3 18 0
10 12 4 18 0
10 12 5 18 0
10 12 6 28 0
10 12 7 28 0
10 12 8 44 0
10 12 9 44 0
10 12 10 11 0
10 12 11 11 0
10 12 12 18 0
10 12 13 18 32
10 13 2 18 72
10 13 3 18 8
10 13 4 18 8
10 13 5 18 8
10 13 6 28 0
10 13 7 28 0
10 13 8 44 0
10 13 9 44 0
10 13 10 11 0
10 13 11 11 0
10 13 12 18 8
10 13 13 18 40
10 14 6 18 68
10 14 7 18 4
10 14 8 18 4
10 14 9 18 4
10 14 10 18 4
10 14 11 18 36
10 15 0 19 126
10 15 6 18 76
10 15 7 18 12
10 15 8 18 12
10 15 9 18 12
10 15 10 18 12
10 15 11 18 44
10 15 15 19 126
11 0 0 19 126
11 0 6 18 82
11 0 7 18 18
11 0 8 18 18
11 0 9 18 50
11 0 15 19 126
11 1 6 18 66
11 1 7 18 2
11 1 8 18 2
11 1 9 18 34
11 2 6 18 66
11 2 7 18 2
11 2 8 18 2
11 2 9 18 34
11 3 6 18 66
11 3 7 18 2
11 3 8 18 2
11 3 9 18 34
11 4 4 56 80
11 4 5 56 16
11 4 6 45 0
11 4 7 45 0
11 4 8 38 0
11 4 9 38 0
11 4 10 56 18
11 4 11 56 50
11 5 4 56 64
11 5 5 56 0
11 5 6 45 0
11 5 7 45 0
11 5 8 38 0
11 5 9 38 0
11 5 10 56 2
11 5 11 56 34
11 6 4 56 66
11 6 5 56 2
11 6 6 56 2
11 6 7 56 2
11 6 8 56 2
11 6 9 56 2
11 6 10 56 2
11 6 11 56 34
11 7 4 56 66
11 7 5 56 2
11 7 6 56 2
11 7 7 56 2
11 7 8 56 2
11 7 9 56 2
11 7 10 56 2
11 7 11 56 34
11 8 2 18 80
11 8 3 18 16
11 8 4 31 0
11 8 5 31 0
11 8 6 54 0
11 8 7 54 0
11 8 8 7 0
11 8 9 7 0
11 8 10 3 0
11 8 11 3 0
11 8 12 18 16
11 8 13 18 48
11 9 2 18 64
11 9 3 18 0
11 9 4 31 0
11 9 5 31 0
11 9 6 54 0
11 9 7 54 0
11 9 8 7 0
11 9 9 7 0
11 9 10 3 0
11 9 11 3 0
11 9 12 18 0
11 9 13 18 32
11 10 2 1 64
11 10 3 1 0
11 10 4 23 0
11 10 5 23 0
11 10 6 26 0
11 10 7 26 0
11 10 8 4 0
11 10 9 4 0
11 10 10 5 0
11 10 11 5 0
11 10 12 18 0
11 10 13 18 32
11 11 2 1 64
11 11 3 1 0
11 11 4 23 0
11 11 5 23 0
11 11 6 26 0
11 11 7 26 0
11 11 8 4 0
11 11 9 4 0
11 11 10 5 0
11 11 11 5 0
11 11 12 18 0
11 11 13 18 32
11 12 2 18 64
11 12 3 18 0
11 12 4 18 0
11 12 5 18 0
11 12 6 28 0
11 12 7 28 0
11 12 8 44 0
11 12 9 44 0
11 12 10 11 0
11 12 11 11 0
11 12 12 18 0
11 12 13 18 32
11 13 2 18 72
11 13 3 18 8
11 13 4 18 8
11 13 5 18 8
11 13 6 28 0
11 13 7 28 0
11 13 8 44 0
11 13 9 44 0
11 13 10 11 0
11 13 11 11 0
11 13 12 18 8
11 13 13 18 40
11 14 6 18 64
11 14 7 18 0
11 14 8 18 0
11 14 9 18 0
11 14 10 18 0
11 14 11 18 32
11 15 0 19 126
11 15 6 18 72
11 15 7 18 8
11 15 8 18 8
11 15 9 18 8
11 15 10 18 8
11 15 11 18 40
11 15 15 19 126
12 0 0 19 126
12 0 15 19 126
12 4 2 18 84
12 4 3 18 20
12 4 4 18 16
12 4 5 18 16
12 4 6 56 16
12 4 7 56 16
12 4 8 56 16
12 4 9 56 48
12 5 2 18 76
12 5 3 18 12
12 5 4 18 8
12 5 5 18 8
12 5 6 56 8
12 5 7 56 8
12 5 8 56 8
12 5 9 56 40
12 8 2 18 80
12 8 3 18 16
12 8 4 18 16
12 8 5 18 16
12 8 6 18 16
12 8 7 18 16
12 8 8 18 16
12 8 9 18 16
12 8 10 18 16
12 8 11 18 16
12 8 12 18 16
12 8 13 18 48
12 9 2 18 64
12 9 3 18 0
12 9 4 18 0
12 9 5 18 0
12 9 6 18 0
12 9 7 18 0
12 9 8 18 0
12 9 9 18 0
12 9 10 18 0
12 9 11 18 0
12 9 12 18 0
12 9 13 18 32
12 10 2 18 64
12 10 3 18 0
12 10 4 18 0
12 10 5 18 0
12 10 6 15 0
12 10 7 15 0
12 10 8 13 0
12 10 9 13 0
12 10 10 9 0
12 10 11 9 0
12 10 12 18 0
12 10 13 18 32
12 11 2 18 64
12 11 3 18 0
12 11 4 18 0
12 11 5 18 0
12 11 6 15 0
12 11 7 15 0
12 11 8 13 0
12 11 9 13 0
12 11 10 9 0
12 11 11 9 0
12 11 12 18 0
12 11 13 18 32
12 12 2 18 64
12 12 3 18 0
12 12 4 18 0
12 12 5 18 0
12 12 6 10 0
12 12 7 10 0
12 12 8 17 0
12 12 9 17 0
12 12 10 11 0
12 12 11 11 0
12 12 12 18 0
12 12 13 18 32
12 13 2 18 72
12 13 3 18 8
12 13 4 18 8
12 13 5 18 8
12 13 6 10 0
12 13 7 10 0
12 13 8 17 0
12 13 9 17 0
12 13 10 11 0
12 13 11 11 0
12 13 12 18 8
12 13 13 18 40
12 14 6 18 64
12 14 7 18 0
12 14 8 18 0
12 14 9 18 0
12 14 10 18 0
12 14 11 18 32
12 15 0 19 126
12 15 6 18 72
12 15 7 18 8
12 15 8 18 8
12 15 9 18 8
12 15 10 18 8
12 15 11 18 40
12 15 15 19 126
13 0 0 19 126
13 0 15 19 126
13 4 2 18 82
13 4 3 18 18
13 4 4 18 18
13 4 5 18 18
13 4 6 56 18
13 4 7 56 18
13 4 8 56 18
13 4 9 56 50
13 5 2 18 74
13 5 3 18 10
13 5 4 18 10
13 5 5 18 10
13 5 6 56 10
13 5 7 56 10
13 5 8 56 10
13 5 9 56 42
13 8 2 18 82
13 8 3 18 18
13 8 4 18 18
13 8 5 18 18
13 8 6 18 16
13 8 7 18 16
13 8 8 18 16
13 8 9 18 16
13 8 10 18 16
13 8 11 18 16
13 8 12 18 18
13 8 13 18 50
13 9 2 18 66
13 9 3 18 2
13 9 4 18 2
13 9 5 18 2
13 9 6 18 0
13 9 7 18 0
13 9 8 18 0
13 9 9 18 0
13 9 10 18 0
13 9 11 18 0
13 9 12 18 2
13 9 13 18 34
13 10 2 18 66
13 10 3 18 2
13 10 4 18 2
13 10 5 18 2
13 10 6 15 0
13 10 7 15 0
13 10 8 13 0
13 10 9 13 0
13 10 10 9 0
13 10 11 9 0
13 10 12 18 2
13 10 13 18 34
13 11 2 18 66
13 11 3 18 2
13 11 4 18 2
13 11 5 18 2
13 11 6 15 0
13 11 7 15 0
13 11 8 13 0
13 11 9 13 0
13 11 10 9 0
13 11 11 9 0
13 11 12 18 2
13 11 13 18 34
13 12 2 18 66
13 12 3 18 2
13 12 4 18 2
13 12 5 18 2
13 12 6 10 0
13 12 7 10 0
13 12 8 17 0
13 12 9 17 0
13 12 10 11 0
13 12 11 11 0
13 12 12 18 2
13 12 13 18 34
13 13 2 18 74
13 13 3 18 10
13 13 4 18 10
13 13 5 18 10
13 13 6 10 0
13 13 7 10 0
13 13 8 17 0
13 13 9 17 0
13 13 10 11 0
13 13 11 11 0
13 13 12 18 10
13 13 13 18 42
13 14 6 18 64
13 14 7 18 0
13 14 8 18 0
13 14 9 18 0
13 14 10 18 0
13 14 11 18 32
13 15 0 19 126
13 15 6 18 72
13 15 7 18 8
13 15 8 18 8
13 15 9 18 8
13 15 10 18 8
13 15 11 18 40
13 15 15 19 126
14 0 0 19 126
14 0 15 19 126
14 8 6 18 80
14 8 7 18 16
14 8 8 18 16
14 8 9 18 16
14 8 10 18 16
14 8 11 18 48
14 9 6 18 64
14 9 7 18 0
14 9 8 18 0
14 9 9 18 0
14 9 10 18 0
14 9 11 18 32
14 10 6 18 64
14 10 7 18 0
14 10 8 18 0
14 10 9 18 0
14 10 10 18 0
14 10 11 18 32
14 11 6 18 64
14 11 7 18 0
14 11 8 18 0
14 11 9 18 0
14 11 10 18 0
14 11 11 18 32
14 12 6 18 64
14 12 7 18 0
14 12 8 18 0
14 12 9 18 0
14 12 10 18 0
14 12 11 18 32
14 13 6 18 64
14 13 7 18 0
14 13 8 18 0
14 13 9 18 0
14 13 10 18 0
14 13 11 18 32
14 14 6 18 64
14 14 7 18 0
14 14 8 18 0
14 14 9 18 0
14 14 10 18 0
14 14 11 18 32
14 15 0 19 126
14 15 6 18 72
14 15 7 18 8
14 15 8 18 8
14 15 9 18 8
14 15 10 18 8
14 15 11 18 40
14 15 15 19 126
15 0 0 19 126
15 0 1 19 126
15 0 2 19 126
15 0 3 19 126
15 0 4 19 126
15 0 5 19 126
15 0 6 19 126
15 0 7 19 126
15 0 8 19 126
15 0 9 19 126
15 0 10 19 126
15 0 11 19 126
15 0 12 19 126
15 0 13 19 126
15 0 14 19 126
15 0 15 19 126
15 1 0 19 126
15 1 15 19 126
15 2 0 19 126
15 2 15 19 126
15 3 0 19 126
15 3 15 19 126
15 4 0 19 126
15 4 15 19 126
15 5 0 19 126
15 5 15 19 126
15 6 0 19 126
15 6 15 19 126
15 7 0 19 126
15 7 15 19 126
15 8 0 19 126
15 8 6 18 82
15 8 7 18 18
15 8 8 18 18
15 8 9 18 18
15 8 10 18 18
15 8 11 18 50
15 8 15 19 126
15 9 0 19 126
15 9 6 18 66
15 9 7 18 2
15 9 8 18 2
15 9 9 18 2
15 9 10 18 2
15 9 11 18 34
15 9 15 19 126
15 10 0 19 126
15 10 6 18 66
15 10 7 18 2
15 10 8 18 2
15 10 9 18 2
15 10 10 18 2
15 10 11 18 34
15 10 15 19 126
15 11 0 19 126
15 11 6 18 66
15 11 7 18 2
15 11 8 18 2
15 11 9 18 2
15 11 10 18 2
15 11 11 18 34
15 11 15 19 126
15 12 0 19 126
15 12 6 18 66
15 12 7 18 2
15 12 8 18 2
15 12 9 18 2
15 12 10 18 2
15 12 11 18 34
15 12 15 19 126
15 13 0 19 126
15 13 6 18 66
15 13 7 18 2
15 13 8 18 2
15 13 9 18 2
15 13 10 18 2
15 13 11 18 34
15 13 15 19 126
15 14 0 19 126
15 14 6 18 66
15 14 7 18 2
15 14 8 18 2
15 14 9 18 2
15 14 10 18 2
15 14 11 18 34
15 14 15 19 126
15 15 0 19 126
15 15 1 19 126
15 15 2 19 126
15 15 3 19 126
15 15 4 19 126
15 15 5 19 126
15 15 6 19 126
15 15 7 19 126
15 15 8 19 126
15 15 9 19 126
15 15 10 19 126
15 15 11 19 126
15 15 12 19 126
15 15 13 19 126
15 15 14 19 126
15 15 15 19 126
