Qubicle Exchange Format
Version 0.2
www.minddesk.com
8 8 8
55
0.000000 0.000000 0.000000
0.000000 0.541176 0.211765
0.000000 0.552941 0.211765
0.003922 0.215686 0.074510
0.074510 0.270588 0.145098
0.082353 0.286275 0.149020
0.094118 0.278431 0.152941
0.145098 0.345098 0.211765
0.152941 0.341176 0.219608
0.239216 0.164706 0.000000
0.243137 0.164706 0.000000
0.247059 0.168627 0.000000
0.254902 0.176471 0.003922
0.258824 0.184314 0.011765
0.262745 0.184314 0.015686
0.266667 0.192157 0.023529
0.270588 0.196078 0.027451
0.274510 0.200000 0.031373
0.333333 0.333333 0.333333
0.843137 0.505882 0.184314
0.858824 0.513726 0.184314
0.862745 0.643137 0.603922
0.866667 0.541176 0.227451
0.866667 0.866667 0.866667
0.870588 0.525490 0.196078
0.870588 0.529412 0.207843
0.874510 0.525490 0.188235
0.886275 0.556863 0.243137
0.890196 0.560784 0.247059
0.890196 0.564706 0.254902
0.894118 0.686275 0.647059
0.898039 0.576471 0.270588
0.917647 0.556863 0.207843
0.921569 0.556863 0.207843
0.921569 0.564706 0.223529
0.921569 0.572549 0.247059
0.929412 0.552941 0.200000
0.945098 0.572549 0.215686
0.945098 0.580392 0.239216
0.945098 0.611765 0.294118
0.949020 0.568627 0.207843
0.949020 0.600000 0.258824
0.949020 0.603922 0.266667
0.956863 0.741176 0.698039
0.964706 0.584314 0.227451
0.964706 0.611765 0.274510
0.964706 0.733333 0.690196
0.968627 0.611765 0.270588
0.976471 0.631373 0.290196
0.976471 0.631373 0.301961
0.976471 0.635294 0.313726
0.976471 0.647059 0.333333
0.976471 0.749020 0.709804
0.988235 0.988235 0.988235
1.000000 1.000000 1.000000
0 2 6 18 124
1 2 1 18 124
1 2 6 18 120
1 4 1 18 84
1 4 2 18 20
1 4 3 0 20
1 4 4 0 20
1 4 5 18 20
1 4 6 18 52
1 5 1 18 68
1 5 2 2 4
1 5 3 18 4
1 5 4 18 4
1 5 5 1 4
1 5 6 18 36
1 6 1 18 76
1 6 2 18 12
1 6 3 18 12
1 6 4 18 12
1 6 5 18 12
1 6 6 18 44
2 0 5 18 124
2 2 1 18 88
2 2 2 54 20
2 2 3 54 20
2 2 4 54 20
2 2 5 54 20
2 2 6 54 56
2 3 2 54 68
2 3 3 54 4
2 3 4 54 4
2 3 5 54 36
2 4 1 18 80
2 4 2 39 0
2 4 3 34 0
2 4 4 24 0
2 4 5 30 0
2 4 6 18 48
2 5 1 18 64
2 5 2 41 0
2 5 3 36 0
2 5 4 50 0
2 5 5 22 0
2 5 6 18 32
2 6 1 18 72
2 6 2 18 8
2 6 3 18 8
2 6 4 18 8
2 6 5 18 8
2 6 6 18 40
3 0 2 18 116
3 0 5 18 114
3 1 2 18 100
3 1 5 18 100
3 2 1 54 88
3 2 2 23 0
3 2 3 54 16
3 2 4 54 16
3 2 5 43 0
3 2 6 54 58
3 3 2 54 64
3 3 3 28 0
3 3 4 30 0
3 3 5 54 32
3 4 0 18 84
3 4 1 18 16
3 4 2 49 0
3 4 3 47 0
3 4 4 21 0
3 4 5 52 0
3 4 6 18 16
3 4 7 18 52
3 5 0 18 68
3 5 1 13 0
3 5 2 48 0
3 5 3 31 0
3 5 4 38 0
3 5 5 25 0
3 5 6 15 0
3 5 7 18 36
3 6 0 18 68
3 6 1 11 0
3 6 2 37 0
3 6 3 18 8
3 6 4 18 8
3 6 5 27 0
3 6 6 10 0
3 6 7 18 36
3 7 0 18 76
3 7 1 18 12
3 7 2 18 44
3 7 5 18 76
3 7 6 18 12
3 7 7 18 44
4 0 2 18 114
4 1 2 18 98
4 1 5 18 114
4 2 1 54 90
4 2 2 53 0
4 2 3 54 16
4 2 4 54 16
4 2 5 54 126
4 3 2 54 64
4 3 3 51 0
4 3 4 46 0
4 3 5 54 32
4 4 0 18 80
4 4 1 18 16
4 4 2 32 0
4 4 3 33 0
4 4 4 6 0
4 4 5 7 0
4 4 6 18 16
4 4 7 18 48
4 5 0 18 64
4 5 1 14 0
4 5 2 19 0
4 5 3 35 0
4 5 4 26 0
4 5 5 4 0
4 5 6 13 0
4 5 7 18 32
4 6 0 18 64
4 6 1 15 0
4 6 2 40 0
4 6 3 18 8
4 6 4 18 8
4 6 5 42 0
4 6 6 17 0
4 6 7 18 32
4 7 0 18 72
4 7 1 18 8
4 7 2 18 40
4 7 5 18 72
4 7 6 18 8
4 7 7 18 40
5 2 2 54 82
5 2 3 54 18
5 2 4 54 18
5 2 5 54 50
5 3 2 54 66
5 3 3 54 2
5 3 4 54 2
5 3 5 54 34
5 4 0 18 82
5 4 1 18 16
5 4 2 44 0
5 4 3 29 0
5 4 4 8 0
5 4 5 3 0
5 4 6 18 16
5 4 7 18 50
5 5 0 18 66
5 5 1 13 0
5 5 2 45 0
5 5 3 20 0
5 5 4 49 0
5 5 5 5 0
5 5 6 9 0
5 5 7 18 34
5 6 0 18 66
5 6 1 16 0
5 6 2 12 0
5 6 3 18 8
5 6 4 18 8
5 6 5 11 0
5 6 6 11 0
5 6 7 18 34
5 7 0 18 74
5 7 1 18 10
5 7 2 18 42
5 7 5 18 74
5 7 6 18 10
5 7 7 18 42
6 4 1 18 82
6 4 2 18 18
6 4 3 18 18
6 4 4 18 18
6 4 5 18 18
6 4 6 18 50
6 5 1 18 66
6 5 2 18 2
6 5 3 18 2
6 5 4 18 2
6 5 5 18 2
6 5 6 18 34
6 6 1 18 74
6 6 2 18 10
6 6 3 18 10
6 6 4 18 10
6 6 5 18 10
6 6 6 18 42
