Qubicle Exchange Format
Version 0.2
www.minddesk.com
8 8 8
5
0.000000 0.000000 0.000000
0.266667 0.266667 0.266667
0.733333 0.000000 0.000000
0.866667 0.866667 0.866667
0.941176 0.737255 0.235294
0 0 0 1 92
0 0 1 1 60
0 0 6 1 92
0 0 7 1 60
0 2 3 0 84
0 2 4 0 20
0 2 5 0 20
0 2 6 0 28
0 2 7 0 62
0 3 3 0 76
0 3 4 0 12
0 3 5 0 44
1 0 0 1 90
1 0 1 1 50
1 0 6 1 82
1 0 7 1 58
1 1 1 1 102
1 1 6 1 102
1 2 1 1 68
1 2 2 1 20
1 2 3 1 16
1 2 4 1 16
1 2 5 1 16
1 2 6 1 32
1 3 1 1 76
1 3 2 1 12
1 3 3 1 8
1 3 4 1 8
1 3 5 1 8
1 3 6 1 44
2 2 1 1 80
2 2 2 1 16
2 2 3 1 16
2 2 4 1 16
2 2 5 1 16
2 2 6 1 48
2 3 1 1 72
2 3 2 1 0
2 3 3 1 0
2 3 4 1 0
2 3 5 1 0
2 3 6 1 40
2 4 2 1 76
2 4 3 1 12
2 4 4 1 12
2 4 5 1 44
3 2 1 1 80
3 2 2 1 16
3 2 3 1 16
3 2 4 1 16
3 2 5 1 16
3 2 6 1 48
3 3 1 1 72
3 3 2 1 0
3 3 3 2 0
3 3 4 2 0
3 3 5 1 0
3 3 6 1 40
3 4 2 1 72
3 4 3 2 0
3 4 4 2 0
3 4 5 1 40
3 5 3 2 76
3 5 4 2 44
4 2 1 1 80
4 2 2 1 16
4 2 3 1 16
4 2 4 1 16
4 2 5 1 16
4 2 6 1 48
4 3 1 1 72
4 3 2 1 0
4 3 3 2 0
4 3 4 2 0
4 3 5 1 0
4 3 6 1 40
4 4 2 1 72
4 4 3 2 0
4 4 4 2 0
4 4 5 1 40
4 5 3 2 74
4 5 4 2 42
5 2 1 1 80
5 2 2 1 16
5 2 3 1 16
5 2 4 1 16
5 2 5 1 16
5 2 6 1 48
5 3 1 1 72
5 3 2 1 0
5 3 3 1 0
5 3 4 1 0
5 3 5 1 0
5 3 6 1 40
5 4 2 1 74
5 4 3 1 10
5 4 4 1 10
5 4 5 1 42
6 0 0 1 92
6 0 1 1 52
6 0 6 1 84
6 0 7 1 60
6 1 1 1 102
6 1 6 1 102
6 2 1 1 66
6 2 2 1 18
6 2 3 1 16
6 2 4 1 16
6 2 5 1 16
6 2 6 1 32
6 3 1 3 66
6 3 2 1 10
6 3 3 1 8
6 3 4 1 8
6 3 5 1 8
6 3 6 1 42
6 4 1 3 102
6 5 1 3 102
6 6 1 4 126
7 0 0 1 90
7 0 1 1 58
7 0 6 1 90
7 0 7 1 58
7 2 3 0 82
7 2 4 0 18
7 2 5 0 18
7 2 6 0 26
7 2 7 0 62
7 3 3 0 74
7 3 4 0 10
7 3 5 0 42
