Qubicle Exchange Format
Version 0.2
www.minddesk.com
240 20 240
43
0.000000 0.670588 0.000000
0.000000 0.674510 0.000000
0.000000 0.678431 0.000000
0.000000 0.682353 0.000000
0.000000 0.686275 0.000000
0.000000 0.690196 0.000000
0.000000 0.694118 0.000000
0.000000 0.698039 0.000000
0.000000 0.701961 0.000000
0.000000 0.705882 0.000000
0.000000 0.709804 0.000000
0.000000 0.713726 0.000000
0.000000 0.717647 0.000000
0.000000 0.721569 0.000000
0.000000 0.725490 0.000000
0.000000 0.729412 0.000000
0.000000 0.733333 0.000000
0.000000 0.737255 0.000000
0.000000 0.741176 0.000000
0.003922 0.741176 0.003922
0.007843 0.741176 0.007843
0.011765 0.745098 0.011765
0.015686 0.745098 0.015686
0.019608 0.745098 0.019608
0.023529 0.745098 0.023529
0.027451 0.749020 0.027451
0.031373 0.749020 0.031373
0.035294 0.749020 0.035294
0.039216 0.749020 0.039216
0.043137 0.752941 0.043137
0.047059 0.752941 0.047059
0.050980 0.752941 0.050980
0.054902 0.752941 0.054902
0.058824 0.756863 0.058824
0.062745 0.756863 0.062745
0.066667 0.756863 0.066667
0.070588 0.756863 0.070588
0.074510 0.760784 0.074510
0.078431 0.760784 0.078431
0.082353 0.760784 0.082353
0.086275 0.760784 0.086275
0.090196 0.764706 0.090196
0.094118 0.764706 0.094118
38 0 25 31 92
38 0 26 14 28
38 0 27 38 28
38 0 28 33 28
38 0 29 18 60
39 0 23 4 92
39 0 24 6 28
39 0 25 38 24
39 0 26 15 24
39 0 27 4 24
39 0 28 11 24
39 0 29 7 24
39 0 30 14 28
39 0 31 1 60
40 0 22 29 92
40 0 23 37 24
40 0 24 4 24
40 0 25 7 16
40 0 26 7 16
40 0 27 7 16
40 0 28 21 16
40 0 29 28 16
40 0 30 0 24
40 0 31 3 24
40 0 32 14 60
40 1 25 12 76
40 1 26 37 12
40 1 27 3 12
40 1 28 5 12
40 1 29 10 44
41 0 22 18 88
41 0 23 41 16
41 0 24 10 16
41 0 25 39 16
41 0 26 33 16
41 0 27 13 16
41 0 28 20 16
41 0 29 35 16
41 0 30 23 16
41 0 31 2 16
41 0 32 16 56
41 1 23 10 76
41 1 24 21 12
41 1 25 21 8
41 1 26 39 8
41 1 27 10 8
41 1 28 28 8
41 1 29 1 8
41 1 30 2 12
41 1 31 17 44
42 0 21 41 92
42 0 22 31 16
42 0 23 4 16
42 0 24 19 16
42 0 25 16 16
42 0 26 10 16
42 0 27 38 16
42 0 28 25 16
42 0 29 35 16
42 0 30 33 16
42 0 31 31 16
42 0 32 40 16
42 0 33 40 60
42 1 22 5 76
42 1 23 1 8
42 1 24 7 8
42 1 25 36 0
42 1 26 29 0
42 1 27 22 0
42 1 28 19 0
42 1 29 30 0
42 1 30 22 8
42 1 31 12 8
42 1 32 12 44
42 2 25 36 76
42 2 26 31 12
42 2 27 14 12
42 2 28 12 12
42 2 29 4 44
43 0 20 4 92
43 0 21 28 24
43 0 22 0 16
43 0 23 40 16
43 0 24 21 16
43 0 25 4 16
43 0 26 2 16
43 0 27 42 16
43 0 28 4 16
43 0 29 5 16
43 0 30 10 16
43 0 31 15 16
43 0 32 11 16
43 0 33 20 24
43 0 34 24 60
43 1 22 8 72
43 1 23 35 8
43 1 24 22 0
43 1 25 13 0
43 1 26 11 0
43 1 27 21 0
43 1 28 36 0
43 1 29 32 0
43 1 30 27 0
43 1 31 35 8
43 1 32 27 40
43 2 24 13 76
43 2 25 4 8
43 2 26 24 8
43 2 27 12 8
43 2 28 5 8
43 2 29 42 8
43 2 30 4 44
44 0 20 8 88
44 0 21 31 16
44 0 22 25 16
44 0 23 10 16
44 0 24 3 16
44 0 25 8 16
44 0 26 39 16
44 0 27 32 16
44 0 28 31 16
44 0 29 40 16
44 0 30 19 16
44 0 31 34 16
44 0 32 24 16
44 0 33 13 16
44 0 34 0 56
44 1 21 36 76
44 1 22 42 8
44 1 23 16 0
44 1 24 34 0
44 1 25 41 0
44 1 26 1 0
44 1 27 21 0
44 1 28 19 0
44 1 29 9 0
44 1 30 20 0
44 1 31 22 0
44 1 32 30 8
44 1 33 6 44
44 2 23 13 76
44 2 24 22 8
44 2 25 39 8
44 2 26 33 8
44 2 27 7 8
44 2 28 19 8
44 2 29 18 8
44 2 30 34 8
44 2 31 7 44
45 0 19 33 92
45 0 20 32 16
45 0 21 3 16
45 0 22 2 16
45 0 23 36 16
45 0 24 16 16
45 0 25 36 16
45 0 26 0 16
45 0 27 16 16
45 0 28 16 16
45 0 29 21 16
45 0 30 30 16
45 0 31 39 16
45 0 32 33 16
45 0 33 17 16
45 0 34 34 16
45 0 35 19 60
45 1 20 35 76
45 1 21 32 8
45 1 22 25 0
45 1 23 22 0
45 1 24 27 0
45 1 25 11 0
45 1 26 16 0
45 1 27 28 0
45 1 28 3 0
45 1 29 12 0
45 1 30 41 0
45 1 31 37 0
45 1 32 18 0
45 1 33 13 8
45 1 34 28 44
45 2 22 7 76
45 2 23 28 8
45 2 24 11 8
45 2 25 22 0
45 2 26 23 0
45 2 27 38 0
45 2 28 35 0
45 2 29 36 0
45 2 30 28 8
45 2 31 21 8
45 2 32 20 44
45 3 25 34 76
45 3 26 13 12
45 3 27 23 12
45 3 28 25 12
45 3 29 7 44
46 0 19 15 88
46 0 20 0 16
46 0 21 33 16
46 0 22 7 16
46 0 23 29 16
46 0 24 0 16
46 0 25 32 16
46 0 26 31 16
46 0 27 4 16
46 0 28 10 16
46 0 29 30 16
46 0 30 8 16
46 0 31 11 16
46 0 32 41 16
46 0 33 39 16
46 0 34 6 16
46 0 35 31 56
46 1 20 35 72
46 1 21 1 0
46 1 22 30 0
46 1 23 11 0
46 1 24 21 0
46 1 25 4 0
46 1 26 0 0
46 1 27 6 0
46 1 28 16 0
46 1 29 10 0
46 1 30 31 0
46 1 31 25 0
46 1 32 13 0
46 1 33 17 0
46 1 34 42 40
46 2 21 1 76
46 2 22 5 8
46 2 23 32 0
46 2 24 17 0
46 2 25 7 0
46 2 26 8 0
46 2 27 18 0
46 2 28 7 0
46 2 29 30 0
46 2 30 18 0
46 2 31 22 0
46 2 32 26 8
46 2 33 18 44
46 3 23 13 76
46 3 24 13 12
46 3 25 1 8
46 3 26 9 8
46 3 27 10 8
46 3 28 34 8
46 3 29 41 8
46 3 30 12 12
46 3 31 7 44
47 0 18 16 92
47 0 19 17 16
47 0 20 17 16
47 0 21 37 16
47 0 22 35 16
47 0 23 7 16
47 0 24 28 16
47 0 25 41 16
47 0 26 9 16
47 0 27 40 16
47 0 28 21 16
47 0 29 25 16
47 0 30 1 16
47 0 31 16 16
47 0 32 21 16
47 0 33 2 16
47 0 34 1 16
47 0 35 21 16
47 0 36 11 60
47 1 19 8 76
47 1 20 22 8
47 1 21 12 0
47 1 22 11 0
47 1 23 7 0
47 1 24 12 0
47 1 25 8 0
47 1 26 31 0
47 1 27 41 0
47 1 28 25 0
47 1 29 2 0
47 1 30 26 0
47 1 31 30 0
47 1 32 37 0
47 1 33 11 0
47 1 34 11 8
47 1 35 19 44
47 2 21 13 72
47 2 22 12 0
47 2 23 11 0
47 2 24 15 0
47 2 25 12 0
47 2 26 28 0
47 2 27 38 0
47 2 28 39 0
47 2 29 23 0
47 2 30 16 0
47 2 31 41 0
47 2 32 35 0
47 2 33 17 40
47 3 22 1 76
47 3 23 1 8
47 3 24 38 8
47 3 25 41 8
47 3 26 2 8
47 3 27 4 0
47 3 28 2 8
47 3 29 16 8
47 3 30 15 8
47 3 31 4 8
47 3 32 4 44
47 4 27 7 108
48 0 18 36 88
48 0 19 40 16
48 0 20 15 16
48 0 21 15 16
48 0 22 1 16
48 0 23 39 16
48 0 24 1 16
48 0 25 42 16
48 0 26 32 16
48 0 27 32 16
48 0 28 28 16
48 0 29 37 16
48 0 30 21 16
48 0 31 24 16
48 0 32 25 16
48 0 33 18 16
48 0 34 39 16
48 0 35 41 16
48 0 36 7 56
48 1 19 22 72
48 1 20 7 0
48 1 21 15 0
48 1 22 12 0
48 1 23 11 0
48 1 24 40 0
48 1 25 11 0
48 1 26 1 0
48 1 27 30 0
48 1 28 42 0
48 1 29 16 0
48 1 30 6 0
48 1 31 25 0
48 1 32 28 0
48 1 33 22 0
48 1 34 13 0
48 1 35 36 40
48 2 20 29 76
48 2 21 41 8
48 2 22 7 0
48 2 23 16 0
48 2 24 26 0
48 2 25 13 0
48 2 26 38 0
48 2 27 1 0
48 2 28 31 0
48 2 29 4 0
48 2 30 3 0
48 2 31 38 0
48 2 32 19 0
48 2 33 42 8
48 2 34 1 44
48 3 22 17 72
48 3 23 26 8
48 3 24 24 8
48 3 25 10 0
48 3 26 27 0
48 3 27 13 0
48 3 28 2 0
48 3 29 39 0
48 3 30 10 8
48 3 31 1 8
48 3 32 0 40
48 4 25 37 76
48 4 26 18 12
48 4 27 37 8
48 4 28 14 12
48 4 29 9 44
49 0 17 35 92
49 0 18 38 16
49 0 19 10 16
49 0 20 0 16
49 0 21 32 16
49 0 22 29 16
49 0 23 23 16
49 0 24 7 16
49 0 25 34 16
49 0 26 13 16
49 0 27 42 16
49 0 28 29 16
49 0 29 28 16
49 0 30 14 16
49 0 31 35 16
49 0 32 17 16
49 0 33 26 16
49 0 34 33 16
49 0 35 11 16
49 0 36 13 16
49 0 37 34 60
49 1 18 20 76
49 1 19 42 0
49 1 20 22 0
49 1 21 18 0
49 1 22 22 0
49 1 23 2 0
49 1 24 14 0
49 1 25 16 0
49 1 26 12 0
49 1 27 13 0
49 1 28 14 0
49 1 29 0 0
49 1 30 19 0
49 1 31 25 0
49 1 32 35 0
49 1 33 17 0
49 1 34 23 0
49 1 35 21 0
49 1 36 4 44
49 2 19 2 76
49 2 20 12 8
49 2 21 20 0
49 2 22 37 0
49 2 23 23 0
49 2 24 7 0
49 2 25 19 0
49 2 26 26 0
49 2 27 9 0
49 2 28 12 0
49 2 29 19 0
49 2 30 31 0
49 2 31 24 0
49 2 32 27 0
49 2 33 30 0
49 2 34 19 8
49 2 35 6 44
49 3 21 9 76
49 3 22 0 8
49 3 23 13 0
49 3 24 11 0
49 3 25 34 0
49 3 26 41 0
49 3 27 26 0
49 3 28 26 0
49 3 29 30 0
49 3 30 23 0
49 3 31 22 0
49 3 32 5 8
49 3 33 4 44
49 4 23 8 76
49 4 24 10 12
49 4 25 19 8
49 4 26 34 8
49 4 27 3 8
49 4 28 27 8
49 4 29 23 8
49 4 30 13 12
49 4 31 18 44
50 0 17 28 88
50 0 18 19 16
50 0 19 6 16
50 0 20 18 16
50 0 21 37 16
50 0 22 13 16
50 0 23 21 16
50 0 24 4 16
50 0 25 6 16
50 0 26 37 16
50 0 27 16 16
50 0 28 35 16
50 0 29 38 16
50 0 30 40 16
50 0 31 30 16
50 0 32 5 16
50 0 33 42 16
50 0 34 13 16
50 0 35 40 16
50 0 36 36 16
50 0 37 16 56
50 1 18 22 72
50 1 19 31 0
50 1 20 1 0
50 1 21 1 0
50 1 22 6 0
50 1 23 15 0
50 1 24 0 0
50 1 25 26 0
50 1 26 28 0
50 1 27 41 0
50 1 28 10 0
50 1 29 23 0
50 1 30 2 0
50 1 31 34 0
50 1 32 13 0
50 1 33 22 0
50 1 34 30 0
50 1 35 18 0
50 1 36 41 40
50 2 19 2 72
50 2 20 13 0
50 2 21 28 0
50 2 22 1 0
50 2 23 22 0
50 2 24 12 0
50 2 25 38 0
50 2 26 35 0
50 2 27 12 0
50 2 28 34 0
50 2 29 42 0
50 2 30 4 0
50 2 31 41 0
50 2 32 22 0
50 2 33 5 0
50 2 34 17 0
50 2 35 29 40
50 3 20 33 76
50 3 21 16 8
50 3 22 4 0
50 3 23 38 0
50 3 24 8 0
50 3 25 24 0
50 3 26 17 0
50 3 27 1 0
50 3 28 11 0
50 3 29 18 0
50 3 30 41 0
50 3 31 1 0
50 3 32 16 0
50 3 33 19 8
50 3 34 40 44
50 4 22 40 76
50 4 23 13 8
50 4 24 1 8
50 4 25 11 8
50 4 26 20 8
50 4 27 2 8
50 4 28 25 8
50 4 29 35 8
50 4 30 0 8
50 4 31 41 8
50 4 32 10 44
51 0 16 13 92
51 0 17 28 16
51 0 18 18 16
51 0 19 41 16
51 0 20 2 16
51 0 21 6 16
51 0 22 36 16
51 0 23 7 16
51 0 24 6 16
51 0 25 37 16
51 0 26 14 16
51 0 27 31 16
51 0 28 31 16
51 0 29 24 16
51 0 30 11 16
51 0 31 37 16
51 0 32 13 16
51 0 33 29 16
51 0 34 8 16
51 0 35 33 16
51 0 36 25 16
51 0 37 5 16
51 0 38 7 60
51 1 17 12 76
51 1 18 18 0
51 1 19 1 0
51 1 20 1 0
51 1 21 24 0
51 1 22 1 0
51 1 23 14 0
51 1 24 13 0
51 1 25 30 0
51 1 26 1 0
51 1 27 28 0
51 1 28 14 0
51 1 29 36 0
51 1 30 18 0
51 1 31 10 0
51 1 32 34 0
51 1 33 24 0
51 1 34 5 0
51 1 35 24 0
51 1 36 14 0
51 1 37 26 44
51 2 18 13 76
51 2 19 18 8
51 2 20 6 0
51 2 21 19 0
51 2 22 10 0
51 2 23 4 0
51 2 24 26 0
51 2 25 8 0
51 2 26 10 0
51 2 27 14 0
51 2 28 16 0
51 2 29 1 0
51 2 30 10 0
51 2 31 13 0
51 2 32 4 0
51 2 33 3 0
51 2 34 24 0
51 2 35 19 8
51 2 36 20 44
51 3 20 12 72
51 3 21 10 8
51 3 22 34 0
51 3 23 21 0
51 3 24 4 0
51 3 25 10 0
51 3 26 35 0
51 3 27 14 0
51 3 28 42 0
51 3 29 0 0
51 3 30 5 0
51 3 31 13 0
51 3 32 42 0
51 3 33 11 8
51 3 34 12 40
51 4 22 7 72
51 4 23 13 8
51 4 24 28 8
51 4 25 38 0
51 4 26 4 0
51 4 27 22 0
51 4 28 35 0
51 4 29 33 0
51 4 30 19 8
51 4 31 18 8
51 4 32 10 40
51 5 25 24 76
51 5 26 37 12
51 5 27 1 12
51 5 28 42 12
51 5 29 27 44
52 0 16 41 88
52 0 17 14 16
52 0 18 33 16
52 0 19 9 16
52 0 20 13 16
52 0 21 19 16
52 0 22 25 16
52 0 23 16 16
52 0 24 39 16
52 0 25 15 16
52 0 26 22 16
52 0 27 8 16
52 0 28 2 16
52 0 29 33 16
52 0 30 7 16
52 0 31 28 16
52 0 32 18 16
52 0 33 24 16
52 0 34 4 16
52 0 35 41 16
52 0 36 14 16
52 0 37 33 16
52 0 38 42 56
52 1 17 32 72
52 1 18 2 0
52 1 19 18 0
52 1 20 10 0
52 1 21 30 0
52 1 22 8 0
52 1 23 37 0
52 1 24 5 0
52 1 25 24 0
52 1 26 30 0
52 1 27 17 0
52 1 28 15 0
52 1 29 13 0
52 1 30 21 0
52 1 31 30 0
52 1 32 11 0
52 1 33 1 0
52 1 34 6 0
52 1 35 39 0
52 1 36 34 0
52 1 37 12 40
52 2 18 36 72
52 2 19 42 0
52 2 20 26 0
52 2 21 6 0
52 2 22 28 0
52 2 23 4 0
52 2 24 4 0
52 2 25 27 0
52 2 26 0 0
52 2 27 16 0
52 2 28 13 0
52 2 29 7 0
52 2 30 9 0
52 2 31 7 0
52 2 32 18 0
52 2 33 9 0
52 2 34 7 0
52 2 35 25 0
52 2 36 18 40
52 3 19 33 76
52 3 20 18 8
52 3 21 14 0
52 3 22 16 0
52 3 23 30 0
52 3 24 39 0
52 3 25 6 0
52 3 26 28 0
52 3 27 17 0
52 3 28 28 0
52 3 29 20 0
52 3 30 35 0
52 3 31 24 0
52 3 32 3 0
52 3 33 3 0
52 3 34 12 8
52 3 35 10 44
52 4 21 30 76
52 4 22 11 8
52 4 23 7 8
52 4 24 9 0
52 4 25 26 0
52 4 26 17 0
52 4 27 22 0
52 4 28 40 0
52 4 29 42 0
52 4 30 0 0
52 4 31 29 8
52 4 32 24 8
52 4 33 0 44
52 5 24 8 76
52 5 25 25 8
52 5 26 4 8
52 5 27 12 8
52 5 28 39 8
52 5 29 1 8
52 5 30 0 44
53 0 16 1 88
53 0 17 19 16
53 0 18 5 16
53 0 19 17 16
53 0 20 37 16
53 0 21 37 16
53 0 22 26 16
53 0 23 19 16
53 0 24 14 16
53 0 25 26 16
53 0 26 23 16
53 0 27 21 16
53 0 28 28 16
53 0 29 12 16
53 0 30 36 16
53 0 31 29 16
53 0 32 29 16
53 0 33 16 16
53 0 34 38 16
53 0 35 41 16
53 0 36 9 16
53 0 37 26 16
53 0 38 40 56
53 1 17 34 72
53 1 18 16 0
53 1 19 11 0
53 1 20 3 0
53 1 21 4 0
53 1 22 13 0
53 1 23 19 0
53 1 24 40 0
53 1 25 5 0
53 1 26 34 0
53 1 27 22 0
53 1 28 7 0
53 1 29 7 0
53 1 30 40 0
53 1 31 17 0
53 1 32 1 0
53 1 33 35 0
53 1 34 2 0
53 1 35 1 0
53 1 36 7 0
53 1 37 42 40
53 2 18 2 72
53 2 19 28 0
53 2 20 12 0
53 2 21 28 0
53 2 22 6 0
53 2 23 11 0
53 2 24 11 0
53 2 25 10 0
53 2 26 13 0
53 2 27 16 0
53 2 28 28 0
53 2 29 15 0
53 2 30 7 0
53 2 31 19 0
53 2 32 24 0
53 2 33 17 0
53 2 34 7 0
53 2 35 28 0
53 2 36 11 40
53 3 19 6 72
53 3 20 39 0
53 3 21 14 0
53 3 22 39 0
53 3 23 28 0
53 3 24 25 0
53 3 25 14 0
53 3 26 13 0
53 3 27 10 0
53 3 28 38 0
53 3 29 1 0
53 3 30 13 0
53 3 31 4 0
53 3 32 9 0
53 3 33 7 0
53 3 34 21 0
53 3 35 23 40
53 4 20 14 76
53 4 21 18 8
53 4 22 14 8
53 4 23 35 0
53 4 24 3 0
53 4 25 33 0
53 4 26 37 0
53 4 27 15 0
53 4 28 42 0
53 4 29 18 0
53 4 30 30 0
53 4 31 20 0
53 4 32 16 8
53 4 33 10 8
53 4 34 12 44
53 5 23 26 76
53 5 24 40 8
53 5 25 18 8
53 5 26 26 8
53 5 27 18 8
53 5 28 8 8
53 5 29 8 8
53 5 30 22 8
53 5 31 4 44
54 0 15 27 92
54 0 16 9 16
54 0 17 7 16
54 0 18 27 16
54 0 19 27 16
54 0 20 13 16
54 0 21 33 16
54 0 22 15 16
54 0 23 27 16
54 0 24 17 16
54 0 25 16 16
54 0 26 24 16
54 0 27 37 16
54 0 28 13 16
54 0 29 14 16
54 0 30 25 16
54 0 31 36 16
54 0 32 11 16
54 0 33 42 16
54 0 34 4 16
54 0 35 7 16
54 0 36 20 16
54 0 37 20 16
54 0 38 18 16
54 0 39 40 60
54 1 16 31 76
54 1 17 8 0
54 1 18 15 0
54 1 19 13 0
54 1 20 4 0
54 1 21 21 0
54 1 22 8 0
54 1 23 0 0
54 1 24 2 0
54 1 25 18 0
54 1 26 7 0
54 1 27 22 0
54 1 28 8 0
54 1 29 18 0
54 1 30 3 0
54 1 31 23 0
54 1 32 6 0
54 1 33 4 0
54 1 34 21 0
54 1 35 18 0
54 1 36 14 0
54 1 37 14 0
54 1 38 15 44
54 2 17 13 76
54 2 18 17 0
54 2 19 38 0
54 2 20 38 0
54 2 21 6 0
54 2 22 12 0
54 2 23 16 0
54 2 24 27 0
54 2 25 19 0
54 2 26 42 0
54 2 27 36 0
54 2 28 1 0
54 2 29 3 0
54 2 30 7 0
54 2 31 28 0
54 2 32 2 0
54 2 33 28 0
54 2 34 39 0
54 2 35 34 0
54 2 36 31 0
54 2 37 22 44
54 3 18 23 76
54 3 19 37 8
54 3 20 7 0
54 3 21 14 0
54 3 22 2 0
54 3 23 13 0
54 3 24 27 0
54 3 25 33 0
54 3 26 33 0
54 3 27 34 0
54 3 28 35 0
54 3 29 2 0
54 3 30 15 0
54 3 31 10 0
54 3 32 16 0
54 3 33 6 0
54 3 34 17 0
54 3 35 16 8
54 3 36 2 44
54 4 20 41 72
54 4 21 1 8
54 4 22 39 0
54 4 23 14 0
54 4 24 34 0
54 4 25 11 0
54 4 26 36 0
54 4 27 21 0
54 4 28 15 0
54 4 29 11 0
54 4 30 7 0
54 4 31 33 0
54 4 32 11 0
54 4 33 3 8
54 4 34 41 40
54 5 22 4 76
54 5 23 23 8
54 5 24 7 8
54 5 25 9 8
54 5 26 32 0
54 5 27 16 0
54 5 28 36 0
54 5 29 11 8
54 5 30 10 8
54 5 31 1 8
54 5 32 21 44
54 6 26 4 76
54 6 27 16 12
54 6 28 34 44
55 0 15 10 88
55 0 16 8 16
55 0 17 21 16
55 0 18 4 16
55 0 19 1 16
55 0 20 32 16
55 0 21 2 16
55 0 22 28 16
55 0 23 16 16
55 0 24 36 16
55 0 25 13 16
55 0 26 6 16
55 0 27 35 16
55 0 28 14 16
55 0 29 9 16
55 0 30 17 16
55 0 31 7 16
55 0 32 26 16
55 0 33 18 16
55 0 34 29 16
55 0 35 5 16
55 0 36 15 16
55 0 37 19 16
55 0 38 18 16
55 0 39 36 56
55 1 16 2 72
55 1 17 15 0
55 1 18 24 0
55 1 19 26 0
55 1 20 15 0
55 1 21 12 0
55 1 22 39 0
55 1 23 31 0
55 1 24 0 0
55 1 25 34 0
55 1 26 30 0
55 1 27 26 0
55 1 28 15 0
55 1 29 35 0
55 1 30 20 0
55 1 31 19 0
55 1 32 42 0
55 1 33 3 0
55 1 34 6 0
55 1 35 37 0
55 1 36 40 0
55 1 37 12 0
55 1 38 21 40
55 2 17 3 72
55 2 18 16 0
55 2 19 18 0
55 2 20 42 0
55 2 21 5 0
55 2 22 9 0
55 2 23 32 0
55 2 24 5 0
55 2 25 40 0
55 2 26 33 0
55 2 27 8 0
55 2 28 4 0
55 2 29 42 0
55 2 30 11 0
55 2 31 5 0
55 2 32 41 0
55 2 33 40 0
55 2 34 12 0
55 2 35 39 0
55 2 36 27 0
55 2 37 33 40
55 3 18 19 72
55 3 19 31 0
55 3 20 2 0
55 3 21 6 0
55 3 22 16 0
55 3 23 25 0
55 3 24 5 0
55 3 25 4 0
55 3 26 38 0
55 3 27 14 0
55 3 28 19 0
55 3 29 22 0
55 3 30 32 0
55 3 31 1 0
55 3 32 23 0
55 3 33 23 0
55 3 34 20 0
55 3 35 21 0
55 3 36 19 40
55 4 19 7 76
55 4 20 36 8
55 4 21 23 0
55 4 22 24 0
55 4 23 23 0
55 4 24 29 0
55 4 25 13 0
55 4 26 1 0
55 4 27 12 0
55 4 28 40 0
55 4 29 17 0
55 4 30 42 0
55 4 31 30 0
55 4 32 2 0
55 4 33 30 0
55 4 34 13 8
55 4 35 10 44
55 5 21 39 76
55 5 22 16 8
55 5 23 0 8
55 5 24 13 0
55 5 25 14 0
55 5 26 3 0
55 5 27 40 0
55 5 28 17 0
55 5 29 18 0
55 5 30 23 0
55 5 31 6 8
55 5 32 35 8
55 5 33 27 44
55 6 24 2 76
55 6 25 39 12
55 6 26 20 8
55 6 27 21 8
55 6 28 40 8
55 6 29 20 12
55 6 30 36 44
56 0 15 17 88
56 0 16 32 16
56 0 17 1 16
56 0 18 25 16
56 0 19 33 16
56 0 20 1 16
56 0 21 22 16
56 0 22 6 16
56 0 23 12 16
56 0 24 42 16
56 0 25 13 16
56 0 26 13 16
56 0 27 9 16
56 0 28 9 16
56 0 29 16 16
56 0 30 42 16
56 0 31 17 16
56 0 32 15 16
56 0 33 19 16
56 0 34 5 16
56 0 35 0 16
56 0 36 40 16
56 0 37 19 16
56 0 38 38 16
56 0 39 33 56
56 1 16 6 72
56 1 17 28 0
56 1 18 36 0
56 1 19 40 0
56 1 20 27 0
56 1 21 31 0
56 1 22 6 0
56 1 23 10 0
56 1 24 41 0
56 1 25 24 0
56 1 26 3 0
56 1 27 32 0
56 1 28 17 0
56 1 29 6 0
56 1 30 28 0
56 1 31 29 0
56 1 32 6 0
56 1 33 11 0
56 1 34 37 0
56 1 35 34 0
56 1 36 4 0
56 1 37 20 0
56 1 38 25 40
56 2 17 17 72
56 2 18 10 0
56 2 19 41 0
56 2 20 2 0
56 2 21 25 0
56 2 22 18 0
56 2 23 30 0
56 2 24 24 0
56 2 25 13 0
56 2 26 33 0
56 2 27 42 0
56 2 28 30 0
56 2 29 34 0
56 2 30 35 0
56 2 31 22 0
56 2 32 32 0
56 2 33 40 0
56 2 34 16 0
56 2 35 1 0
56 2 36 0 0
56 2 37 19 40
56 3 18 2 72
56 3 19 9 0
56 3 20 38 0
56 3 21 40 0
56 3 22 5 0
56 3 23 40 0
56 3 24 1 0
56 3 25 17 0
56 3 26 37 0
56 3 27 16 0
56 3 28 26 0
56 3 29 40 0
56 3 30 0 0
56 3 31 29 0
56 3 32 9 0
56 3 33 14 0
56 3 34 32 0
56 3 35 10 0
56 3 36 3 40
56 4 19 12 72
56 4 20 41 8
56 4 21 20 0
56 4 22 38 0
56 4 23 4 0
56 4 24 7 0
56 4 25 24 0
56 4 26 36 0
56 4 27 16 0
56 4 28 27 0
56 4 29 37 0
56 4 30 11 0
56 4 31 19 0
56 4 32 22 0
56 4 33 22 0
56 4 34 16 8
56 4 35 5 40
56 5 21 40 72
56 5 22 42 8
56 5 23 3 0
56 5 24 10 0
56 5 25 10 0
56 5 26 16 0
56 5 27 15 0
56 5 28 1 0
56 5 29 0 0
56 5 30 2 0
56 5 31 27 0
56 5 32 1 8
56 5 33 11 40
56 6 23 36 76
56 6 24 34 8
56 6 25 12 8
56 6 26 14 8
56 6 27 33 8
56 6 28 18 8
56 6 29 19 8
56 6 30 40 8
56 6 31 24 44
57 0 15 13 80
57 0 16 37 16
57 0 17 0 16
57 0 18 35 16
57 0 19 18 16
57 0 20 25 16
57 0 21 23 16
57 0 22 7 16
57 0 23 24 16
57 0 24 26 16
57 0 25 31 16
57 0 26 26 16
57 0 27 13 16
57 0 28 9 16
57 0 29 4 16
57 0 30 4 16
57 0 31 5 16
57 0 32 12 16
57 0 33 23 16
57 0 34 27 16
57 0 35 14 16
57 0 36 7 16
57 0 37 40 16
57 0 38 33 16
57 0 39 34 48
57 1 15 11 76
57 1 16 2 0
57 1 17 33 0
57 1 18 37 0
57 1 19 31 0
57 1 20 7 0
57 1 21 21 0
57 1 22 23 0
57 1 23 31 0
57 1 24 41 0
57 1 25 2 0
57 1 26 13 0
57 1 27 27 0
57 1 28 36 0
57 1 29 19 0
57 1 30 16 0
57 1 31 41 0
57 1 32 30 0
57 1 33 40 0
57 1 34 0 0
57 1 35 3 0
57 1 36 40 0
57 1 37 27 0
57 1 38 5 0
57 1 39 9 44
57 2 16 34 76
57 2 17 12 0
57 2 18 2 0
57 2 19 4 0
57 2 20 29 0
57 2 21 3 0
57 2 22 18 0
57 2 23 1 0
57 2 24 7 0
57 2 25 18 0
57 2 26 11 0
57 2 27 19 0
57 2 28 30 0
57 2 29 7 0
57 2 30 16 0
57 2 31 16 0
57 2 32 10 0
57 2 33 22 0
57 2 34 37 0
57 2 35 37 0
57 2 36 2 0
57 2 37 36 0
57 2 38 11 44
57 3 17 2 76
57 3 18 32 8
57 3 19 16 0
57 3 20 12 0
57 3 21 13 0
57 3 22 1 0
57 3 23 3 0
57 3 24 34 0
57 3 25 10 0
57 3 26 39 0
57 3 27 12 0
57 3 28 39 0
57 3 29 32 0
57 3 30 27 0
57 3 31 14 0
57 3 32 23 0
57 3 33 36 0
57 3 34 4 0
57 3 35 1 0
57 3 36 17 8
57 3 37 41 44
57 4 19 33 72
57 4 20 16 0
57 4 21 42 0
57 4 22 22 0
57 4 23 5 0
57 4 24 29 0
57 4 25 1 0
57 4 26 39 0
57 4 27 41 0
57 4 28 13 0
57 4 29 20 0
57 4 30 12 0
57 4 31 7 0
57 4 32 0 0
57 4 33 1 0
57 4 34 16 0
57 4 35 4 40
57 5 20 21 76
57 5 21 22 8
57 5 22 6 0
57 5 23 12 0
57 5 24 38 0
57 5 25 25 0
57 5 26 9 0
57 5 27 8 0
57 5 28 13 0
57 5 29 16 0
57 5 30 19 0
57 5 31 15 0
57 5 32 31 0
57 5 33 42 8
57 5 34 18 44
57 6 22 42 76
57 6 23 20 8
57 6 24 26 8
57 6 25 29 8
57 6 26 0 8
57 6 27 16 8
57 6 28 18 8
57 6 29 16 8
57 6 30 5 8
57 6 31 32 8
57 6 32 16 44
58 0 14 20 92
58 0 15 30 16
58 0 16 16 16
58 0 17 21 16
58 0 18 30 16
58 0 19 3 16
58 0 20 2 16
58 0 21 18 16
58 0 22 35 16
58 0 23 28 16
58 0 24 33 16
58 0 25 1 16
58 0 26 21 16
58 0 27 2 16
58 0 28 2 16
58 0 29 18 16
58 0 30 34 16
58 0 31 10 16
58 0 32 7 16
58 0 33 4 16
58 0 34 40 16
58 0 35 18 16
58 0 36 41 16
58 0 37 39 16
58 0 38 3 16
58 0 39 5 16
58 0 40 32 60
58 1 15 10 72
58 1 16 3 0
58 1 17 7 0
58 1 18 35 0
58 1 19 38 0
58 1 20 18 0
58 1 21 23 0
58 1 22 0 0
58 1 23 15 0
58 1 24 37 0
58 1 25 5 0
58 1 26 13 0
58 1 27 18 0
58 1 28 10 0
58 1 29 29 0
58 1 30 19 0
58 1 31 2 0
58 1 32 36 0
58 1 33 5 0
58 1 34 10 0
58 1 35 25 0
58 1 36 36 0
58 1 37 14 0
58 1 38 32 0
58 1 39 31 40
58 2 16 42 72
58 2 17 33 0
58 2 18 0 0
58 2 19 28 0
58 2 20 10 0
58 2 21 30 0
58 2 22 41 0
58 2 23 29 0
58 2 24 1 0
58 2 25 38 0
58 2 26 1 0
58 2 27 11 0
58 2 28 1 0
58 2 29 8 0
58 2 30 5 0
58 2 31 19 0
58 2 32 4 0
58 2 33 7 0
58 2 34 32 0
58 2 35 37 0
58 2 36 27 0
58 2 37 3 0
58 2 38 30 40
58 3 17 4 72
58 3 18 9 0
58 3 19 3 0
58 3 20 31 0
58 3 21 4 0
58 3 22 40 0
58 3 23 13 0
58 3 24 13 0
58 3 25 12 0
58 3 26 16 0
58 3 27 27 0
58 3 28 8 0
58 3 29 36 0
58 3 30 41 0
58 3 31 9 0
58 3 32 3 0
58 3 33 0 0
58 3 34 26 0
58 3 35 7 0
58 3 36 35 0
58 3 37 12 40
58 4 18 4 76
58 4 19 16 8
58 4 20 26 0
58 4 21 24 0
58 4 22 37 0
58 4 23 18 0
58 4 24 38 0
58 4 25 4 0
58 4 26 2 0
58 4 27 22 0
58 4 28 7 0
58 4 29 33 0
58 4 30 42 0
58 4 31 35 0
58 4 32 6 0
58 4 33 13 0
58 4 34 25 0
58 4 35 19 8
58 4 36 4 44
58 5 20 11 72
58 5 21 33 8
58 5 22 22 0
58 5 23 37 0
58 5 24 12 0
58 5 25 20 0
58 5 26 14 0
58 5 27 36 0
58 5 28 27 0
58 5 29 35 0
58 5 30 26 0
58 5 31 31 0
58 5 32 18 0
58 5 33 34 8
58 5 34 4 40
58 6 22 4 72
58 6 23 4 8
58 6 24 13 8
58 6 25 10 8
58 6 26 33 0
58 6 27 9 0
58 6 28 35 0
58 6 29 33 8
58 6 30 21 8
58 6 31 39 8
58 6 32 12 40
58 7 26 34 76
58 7 27 15 12
58 7 28 36 44
59 0 14 34 88
59 0 15 32 16
59 0 16 18 16
59 0 17 41 16
59 0 18 19 16
59 0 19 26 16
59 0 20 26 16
59 0 21 3 16
59 0 22 22 16
59 0 23 13 16
59 0 24 37 16
59 0 25 22 16
59 0 26 21 16
59 0 27 20 16
59 0 28 18 16
59 0 29 40 16
59 0 30 13 16
59 0 31 11 16
59 0 32 18 16
59 0 33 12 16
59 0 34 7 16
59 0 35 34 16
59 0 36 1 16
59 0 37 23 16
59 0 38 30 16
59 0 39 0 16
59 0 40 24 56
59 1 15 39 72
59 1 16 28 0
59 1 17 9 0
59 1 18 7 0
59 1 19 11 0
59 1 20 16 0
59 1 21 18 0
59 1 22 17 0
59 1 23 21 0
59 1 24 16 0
59 1 25 28 0
59 1 26 10 0
59 1 27 20 0
59 1 28 19 0
59 1 29 30 0
59 1 30 24 0
59 1 31 31 0
59 1 32 17 0
59 1 33 42 0
59 1 34 41 0
59 1 35 27 0
59 1 36 22 0
59 1 37 41 0
59 1 38 26 0
59 1 39 17 40
59 2 16 1 72
59 2 17 18 0
59 2 18 0 0
59 2 19 19 0
59 2 20 18 0
59 2 21 18 0
59 2 22 15 0
59 2 23 32 0
59 2 24 1 0
59 2 25 21 0
59 2 26 30 0
59 2 27 18 0
59 2 28 7 0
59 2 29 24 0
59 2 30 39 0
59 2 31 11 0
59 2 32 17 0
59 2 33 5 0
59 2 34 29 0
59 2 35 22 0
59 2 36 20 0
59 2 37 22 0
59 2 38 17 40
59 3 17 0 72
59 3 18 11 0
59 3 19 41 0
59 3 20 40 0
59 3 21 12 0
59 3 22 35 0
59 3 23 21 0
59 3 24 38 0
59 3 25 39 0
59 3 26 9 0
59 3 27 20 0
59 3 28 32 0
59 3 29 25 0
59 3 30 19 0
59 3 31 1 0
59 3 32 13 0
59 3 33 39 0
59 3 34 18 0
59 3 35 16 0
59 3 36 17 0
59 3 37 8 40
59 4 18 23 72
59 4 19 13 0
59 4 20 27 0
59 4 21 2 0
59 4 22 19 0
59 4 23 32 0
59 4 24 5 0
59 4 25 4 0
59 4 26 10 0
59 4 27 18 0
59 4 28 1 0
59 4 29 14 0
59 4 30 27 0
59 4 31 12 0
59 4 32 28 0
59 4 33 19 0
59 4 34 25 0
59 4 35 3 0
59 4 36 25 40
59 5 19 26 76
59 5 20 3 8
59 5 21 31 0
59 5 22 8 0
59 5 23 15 0
59 5 24 2 0
59 5 25 11 0
59 5 26 1 0
59 5 27 2 0
59 5 28 13 0
59 5 29 3 0
59 5 30 33 0
59 5 31 13 0
59 5 32 21 0
59 5 33 19 0
59 5 34 4 8
59 5 35 11 44
59 6 21 7 76
59 6 22 4 8
59 6 23 16 8
59 6 24 18 0
59 6 25 7 0
59 6 26 42 0
59 6 27 42 0
59 6 28 10 0
59 6 29 7 0
59 6 30 7 0
59 6 31 17 8
59 6 32 2 8
59 6 33 12 44
59 7 24 3 76
59 7 25 21 12
59 7 26 7 8
59 7 27 40 8
59 7 28 35 8
59 7 29 8 12
59 7 30 39 44
60 0 14 11 80
60 0 15 6 16
60 0 16 13 16
60 0 17 20 16
60 0 18 0 16
60 0 19 3 16
60 0 20 21 16
60 0 21 27 16
60 0 22 7 16
60 0 23 24 16
60 0 24 3 16
60 0 25 19 16
60 0 26 11 16
60 0 27 5 16
60 0 28 11 16
60 0 29 15 16
60 0 30 15 16
60 0 31 37 16
60 0 32 8 16
60 0 33 12 16
60 0 34 17 16
60 0 35 2 16
60 0 36 9 16
60 0 37 12 16
60 0 38 24 16
60 0 39 35 16
60 0 40 22 48
60 1 14 1 76
60 1 15 15 0
60 1 16 7 0
60 1 17 3 0
60 1 18 21 0
60 1 19 27 0
60 1 20 17 0
60 1 21 18 0
60 1 22 37 0
60 1 23 38 0
60 1 24 3 0
60 1 25 30 0
60 1 26 13 0
60 1 27 7 0
60 1 28 18 0
60 1 29 18 0
60 1 30 10 0
60 1 31 10 0
60 1 32 35 0
60 1 33 16 0
60 1 34 4 0
60 1 35 20 0
60 1 36 8 0
60 1 37 1 0
60 1 38 7 0
60 1 39 13 0
60 1 40 18 44
60 2 15 23 76
60 2 16 7 0
60 2 17 29 0
60 2 18 18 0
60 2 19 31 0
60 2 20 34 0
60 2 21 8 0
60 2 22 29 0
60 2 23 38 0
60 2 24 6 0
60 2 25 10 0
60 2 26 24 0
60 2 27 20 0
60 2 28 4 0
60 2 29 37 0
60 2 30 11 0
60 2 31 10 0
60 2 32 12 0
60 2 33 16 0
60 2 34 11 0
60 2 35 31 0
60 2 36 31 0
60 2 37 1 0
60 2 38 16 0
60 2 39 41 44
60 3 16 1 76
60 3 17 16 0
60 3 18 1 0
60 3 19 11 0
60 3 20 26 0
60 3 21 11 0
60 3 22 30 0
60 3 23 30 0
60 3 24 18 0
60 3 25 1 0
60 3 26 7 0
60 3 27 14 0
60 3 28 29 0
60 3 29 6 0
60 3 30 28 0
60 3 31 41 0
60 3 32 31 0
60 3 33 18 0
60 3 34 35 0
60 3 35 27 0
60 3 36 17 0
60 3 37 16 0
60 3 38 22 44
60 4 17 20 76
60 4 18 6 8
60 4 19 30 0
60 4 20 10 0
60 4 21 20 0
60 4 22 39 0
60 4 23 26 0
60 4 24 2 0
60 4 25 32 0
60 4 26 31 0
60 4 27 25 0
60 4 28 4 0
60 4 29 13 0
60 4 30 10 0
60 4 31 16 0
60 4 32 12 0
60 4 33 19 0
60 4 34 38 0
60 4 35 17 0
60 4 36 17 8
60 4 37 35 44
60 5 19 41 72
60 5 20 22 8
60 5 21 21 0
60 5 22 41 0
60 5 23 23 0
60 5 24 1 0
60 5 25 37 0
60 5 26 16 0
60 5 27 6 0
60 5 28 10 0
60 5 29 35 0
60 5 30 0 0
60 5 31 2 0
60 5 32 19 0
60 5 33 15 0
60 5 34 12 8
60 5 35 1 40
60 6 21 9 72
60 6 22 29 8
60 6 23 7 0
60 6 24 42 0
60 6 25 10 0
60 6 26 4 0
60 6 27 15 0
60 6 28 19 0
60 6 29 19 0
60 6 30 1 0
60 6 31 33 0
60 6 32 18 8
60 6 33 23 40
60 7 23 2 76
60 7 24 20 8
60 7 25 37 8
60 7 26 6 8
60 7 27 16 8
60 7 28 32 8
60 7 29 41 8
60 7 30 16 8
60 7 31 14 44
61 0 13 5 92
61 0 14 2 16
61 0 15 36 16
61 0 16 0 16
61 0 17 9 16
61 0 18 13 16
61 0 19 15 16
61 0 20 4 16
61 0 21 41 16
61 0 22 16 16
61 0 23 8 16
61 0 24 35 16
61 0 25 16 16
61 0 26 0 16
61 0 27 9 16
61 0 28 19 16
61 0 29 1 16
61 0 30 30 16
61 0 31 4 16
61 0 32 1 16
61 0 33 3 16
61 0 34 22 16
61 0 35 18 16
61 0 36 1 16
61 0 37 30 16
61 0 38 34 16
61 0 39 20 16
61 0 40 15 16
61 0 41 19 60
61 1 14 31 72
61 1 15 12 0
61 1 16 31 0
61 1 17 27 0
61 1 18 35 0
61 1 19 37 0
61 1 20 11 0
61 1 21 12 0
61 1 22 7 0
61 1 23 10 0
61 1 24 12 0
61 1 25 9 0
61 1 26 4 0
61 1 27 17 0
61 1 28 13 0
61 1 29 27 0
61 1 30 16 0
61 1 31 24 0
61 1 32 16 0
61 1 33 8 0
61 1 34 10 0
61 1 35 38 0
61 1 36 30 0
61 1 37 11 0
61 1 38 1 0
61 1 39 31 0
61 1 40 34 40
61 2 15 29 72
61 2 16 25 0
61 2 17 30 0
61 2 18 16 0
61 2 19 28 0
61 2 20 35 0
61 2 21 35 0
61 2 22 38 0
61 2 23 3 0
61 2 24 28 0
61 2 25 4 0
61 2 26 18 0
61 2 27 39 0
61 2 28 34 0
61 2 29 16 0
61 2 30 8 0
61 2 31 27 0
61 2 32 33 0
61 2 33 18 0
61 2 34 23 0
61 2 35 1 0
61 2 36 27 0
61 2 37 11 0
61 2 38 31 0
61 2 39 21 40
61 3 16 18 72
61 3 17 12 0
61 3 18 41 0
61 3 19 17 0
61 3 20 27 0
61 3 21 9 0
61 3 22 25 0
61 3 23 28 0
61 3 24 7 0
61 3 25 12 0
61 3 26 6 0
61 3 27 0 0
61 3 28 6 0
61 3 29 12 0
61 3 30 8 0
61 3 31 38 0
61 3 32 7 0
61 3 33 11 0
61 3 34 6 0
61 3 35 39 0
61 3 36 37 0
61 3 37 10 0
61 3 38 17 40
61 4 17 13 72
61 4 18 31 0
61 4 19 41 0
61 4 20 36 0
61 4 21 14 0
61 4 22 16 0
61 4 23 42 0
61 4 24 11 0
61 4 25 11 0
61 4 26 27 0
61 4 27 16 0
61 4 28 6 0
61 4 29 14 0
61 4 30 24 0
61 4 31 14 0
61 4 32 37 0
61 4 33 19 0
61 4 34 42 0
61 4 35 9 0
61 4 36 4 0
61 4 37 10 40
61 5 18 3 76
61 5 19 16 8
61 5 20 4 0
61 5 21 30 0
61 5 22 8 0
61 5 23 4 0
61 5 24 7 0
61 5 25 25 0
61 5 26 13 0
61 5 27 29 0
61 5 28 24 0
61 5 29 31 0
61 5 30 33 0
61 5 31 0 0
61 5 32 9 0
61 5 33 12 0
61 5 34 24 0
61 5 35 37 8
61 5 36 25 44
61 6 20 18 76
61 6 21 3 8
61 6 22 30 8
61 6 23 36 0
61 6 24 21 0
61 6 25 14 0
61 6 26 19 0
61 6 27 2 0
61 6 28 11 0
61 6 29 25 0
61 6 30 4 0
61 6 31 33 0
61 6 32 20 8
61 6 33 21 8
61 6 34 31 44
61 7 23 18 72
61 7 24 7 8
61 7 25 19 8
61 7 26 32 8
61 7 27 10 8
61 7 28 18 8
61 7 29 37 8
61 7 30 16 8
61 7 31 27 40
62 0 13 25 88
62 0 14 18 16
62 0 15 40 16
62 0 16 4 16
62 0 17 3 16
62 0 18 4 16
62 0 19 26 16
62 0 20 19 16
62 0 21 7 16
62 0 22 28 16
62 0 23 19 16
62 0 24 17 16
62 0 25 13 16
62 0 26 13 16
62 0 27 6 16
62 0 28 31 16
62 0 29 37 16
62 0 30 37 16
62 0 31 30 16
62 0 32 10 16
62 0 33 27 16
62 0 34 1 16
62 0 35 39 16
62 0 36 0 16
62 0 37 23 16
62 0 38 0 16
62 0 39 4 16
62 0 40 3 16
62 0 41 32 56
62 1 14 8 72
62 1 15 15 0
62 1 16 16 0
62 1 17 27 0
62 1 18 10 0
62 1 19 33 0
62 1 20 13 0
62 1 21 37 0
62 1 22 10 0
62 1 23 29 0
62 1 24 35 0
62 1 25 41 0
62 1 26 1 0
62 1 27 22 0
62 1 28 18 0
62 1 29 12 0
62 1 30 36 0
62 1 31 25 0
62 1 32 4 0
62 1 33 42 0
62 1 34 31 0
62 1 35 22 0
62 1 36 10 0
62 1 37 30 0
62 1 38 42 0
62 1 39 29 0
62 1 40 10 40
62 2 15 37 72
62 2 16 29 0
62 2 17 30 0
62 2 18 16 0
62 2 19 33 0
62 2 20 22 0
62 2 21 26 0
62 2 22 8 0
62 2 23 8 0
62 2 24 17 0
62 2 25 9 0
62 2 26 20 0
62 2 27 17 0
62 2 28 11 0
62 2 29 2 0
62 2 30 41 0
62 2 31 4 0
62 2 32 18 0
62 2 33 1 0
62 2 34 32 0
62 2 35 26 0
62 2 36 10 0
62 2 37 1 0
62 2 38 12 0
62 2 39 37 40
62 3 16 31 72
62 3 17 0 0
62 3 18 21 0
62 3 19 4 0
62 3 20 1 0
62 3 21 25 0
62 3 22 40 0
62 3 23 22 0
62 3 24 9 0
62 3 25 9 0
62 3 26 36 0
62 3 27 17 0
62 3 28 42 0
62 3 29 13 0
62 3 30 13 0
62 3 31 13 0
62 3 32 21 0
62 3 33 6 0
62 3 34 22 0
62 3 35 16 0
62 3 36 17 0
62 3 37 2 0
62 3 38 17 40
62 4 17 12 72
62 4 18 22 0
62 4 19 11 0
62 4 20 42 0
62 4 21 15 0
62 4 22 13 0
62 4 23 40 0
62 4 24 35 0
62 4 25 12 0
62 4 26 42 0
62 4 27 41 0
62 4 28 6 0
62 4 29 39 0
62 4 30 24 0
62 4 31 9 0
62 4 32 24 0
62 4 33 16 0
62 4 34 1 0
62 4 35 38 0
62 4 36 7 0
62 4 37 22 40
62 5 18 2 72
62 5 19 22 8
62 5 20 22 0
62 5 21 15 0
62 5 22 7 0
62 5 23 4 0
62 5 24 13 0
62 5 25 20 0
62 5 26 18 0
62 5 27 23 0
62 5 28 10 0
62 5 29 6 0
62 5 30 11 0
62 5 31 24 0
62 5 32 24 0
62 5 33 25 0
62 5 34 25 0
62 5 35 3 8
62 5 36 35 40
62 6 20 21 72
62 6 21 31 8
62 6 22 36 0
62 6 23 12 0
62 6 24 4 0
62 6 25 8 0
62 6 26 28 0
62 6 27 39 0
62 6 28 20 0
62 6 29 22 0
62 6 30 36 0
62 6 31 16 0
62 6 32 22 0
62 6 33 21 8
62 6 34 5 40
62 7 22 41 76
62 7 23 14 8
62 7 24 29 8
62 7 25 25 8
62 7 26 30 8
62 7 27 12 8
62 7 28 18 8
62 7 29 22 8
62 7 30 16 8
62 7 31 6 8
62 7 32 16 44
63 0 13 28 88
63 0 14 23 16
63 0 15 14 16
63 0 16 15 16
63 0 17 21 16
63 0 18 18 16
63 0 19 17 16
63 0 20 22 16
63 0 21 4 16
63 0 22 31 16
63 0 23 23 16
63 0 24 18 16
63 0 25 19 16
63 0 26 20 16
63 0 27 11 16
63 0 28 4 16
63 0 29 37 16
63 0 30 28 16
63 0 31 6 16
63 0 32 7 16
63 0 33 23 16
63 0 34 41 16
63 0 35 11 16
63 0 36 8 16
63 0 37 0 16
63 0 38 36 16
63 0 39 4 16
63 0 40 5 16
63 0 41 28 56
63 1 14 29 64
63 1 15 15 0
63 1 16 6 0
63 1 17 31 0
63 1 18 15 0
63 1 19 38 0
63 1 20 31 0
63 1 21 7 0
63 1 22 11 0
63 1 23 13 0
63 1 24 3 0
63 1 25 1 0
63 1 26 25 0
63 1 27 3 0
63 1 28 36 0
63 1 29 11 0
63 1 30 7 0
63 1 31 13 0
63 1 32 16 0
63 1 33 31 0
63 1 34 2 0
63 1 35 7 0
63 1 36 14 0
63 1 37 24 0
63 1 38 29 0
63 1 39 42 0
63 1 40 22 32
63 2 14 34 76
63 2 15 21 0
63 2 16 20 0
63 2 17 20 0
63 2 18 34 0
63 2 19 17 0
63 2 20 5 0
63 2 21 13 0
63 2 22 18 0
63 2 23 42 0
63 2 24 12 0
63 2 25 27 0
63 2 26 34 0
63 2 27 21 0
63 2 28 34 0
63 2 29 15 0
63 2 30 7 0
63 2 31 8 0
63 2 32 5 0
63 2 33 26 0
63 2 34 34 0
63 2 35 1 0
63 2 36 14 0
63 2 37 29 0
63 2 38 8 0
63 2 39 14 0
63 2 40 14 44
63 3 15 25 76
63 3 16 1 0
63 3 17 18 0
63 3 18 5 0
63 3 19 35 0
63 3 20 1 0
63 3 21 18 0
63 3 22 34 0
63 3 23 17 0
63 3 24 9 0
63 3 25 39 0
63 3 26 19 0
63 3 27 0 0
63 3 28 13 0
63 3 29 39 0
63 3 30 40 0
63 3 31 7 0
63 3 32 17 0
63 3 33 26 0
63 3 34 4 0
63 3 35 39 0
63 3 36 14 0
63 3 37 38 0
63 3 38 30 0
63 3 39 0 44
63 4 16 34 76
63 4 17 30 8
63 4 18 28 0
63 4 19 42 0
63 4 20 16 0
63 4 21 7 0
63 4 22 36 0
63 4 23 23 0
63 4 24 9 0
63 4 25 16 0
63 4 26 6 0
63 4 27 34 0
63 4 28 12 0
63 4 29 10 0
63 4 30 23 0
63 4 31 31 0
63 4 32 1 0
63 4 33 11 0
63 4 34 4 0
63 4 35 12 0
63 4 36 16 0
63 4 37 24 8
63 4 38 35 44
63 5 18 38 72
63 5 19 38 0
63 5 20 28 0
63 5 21 14 0
63 5 22 17 0
63 5 23 38 0
63 5 24 35 0
63 5 25 40 0
63 5 26 30 0
63 5 27 29 0
63 5 28 13 0
63 5 29 19 0
63 5 30 32 0
63 5 31 14 0
63 5 32 14 0
63 5 33 10 0
63 5 34 25 0
63 5 35 3 0
63 5 36 20 40
63 6 19 42 76
63 6 20 27 8
63 6 21 1 0
63 6 22 14 0
63 6 23 16 0
63 6 24 16 0
63 6 25 7 0
63 6 26 4 0
63 6 27 24 0
63 6 28 18 0
63 6 29 4 0
63 6 30 10 0
63 6 31 1 0
63 6 32 18 0
63 6 33 32 0
63 6 34 29 8
63 6 35 31 44
63 7 21 20 76
63 7 22 8 8
63 7 23 0 8
63 7 24 27 8
63 7 25 13 0
63 7 26 32 0
63 7 27 24 0
63 7 28 2 0
63 7 29 37 0
63 7 30 17 8
63 7 31 25 8
63 7 32 3 8
63 7 33 15 44
63 8 25 31 76
63 8 26 16 12
63 8 27 32 12
63 8 28 11 12
63 8 29 32 44
64 0 13 38 80
64 0 14 4 16
64 0 15 40 16
64 0 16 36 16
64 0 17 4 16
64 0 18 13 16
64 0 19 13 16
64 0 20 21 16
64 0 21 16 16
64 0 22 39 16
64 0 23 5 16
64 0 24 38 16
64 0 25 37 16
64 0 26 4 16
64 0 27 27 16
64 0 28 33 16
64 0 29 42 16
64 0 30 4 16
64 0 31 17 16
64 0 32 18 16
64 0 33 34 16
64 0 34 3 16
64 0 35 34 16
64 0 36 9 16
64 0 37 6 16
64 0 38 25 16
64 0 39 7 16
64 0 40 33 16
64 0 41 33 48
64 1 13 4 76
64 1 14 4 0
64 1 15 7 0
64 1 16 7 0
64 1 17 18 0
64 1 18 7 0
64 1 19 3 0
64 1 20 12 0
64 1 21 12 0
64 1 22 16 0
64 1 23 40 0
64 1 24 35 0
64 1 25 18 0
64 1 26 4 0
64 1 27 10 0
64 1 28 4 0
64 1 29 33 0
64 1 30 31 0
64 1 31 19 0
64 1 32 18 0
64 1 33 16 0
64 1 34 22 0
64 1 35 35 0
64 1 36 1 0
64 1 37 21 0
64 1 38 10 0
64 1 39 19 0
64 1 40 18 0
64 1 41 7 44
64 2 14 25 72
64 2 15 41 0
64 2 16 26 0
64 2 17 6 0
64 2 18 0 0
64 2 19 37 0
64 2 20 13 0
64 2 21 17 0
64 2 22 32 0
64 2 23 6 0
64 2 24 38 0
64 2 25 4 0
64 2 26 2 0
64 2 27 18 0
64 2 28 21 0
64 2 29 6 0
64 2 30 35 0
64 2 31 27 0
64 2 32 12 0
64 2 33 42 0
64 2 34 29 0
64 2 35 39 0
64 2 36 1 0
64 2 37 29 0
64 2 38 39 0
64 2 39 40 0
64 2 40 2 40
64 3 15 8 72
64 3 16 31 0
64 3 17 31 0
64 3 18 22 0
64 3 19 23 0
64 3 20 42 0
64 3 21 10 0
64 3 22 16 0
64 3 23 30 0
64 3 24 16 0
64 3 25 24 0
64 3 26 18 0
64 3 27 19 0
64 3 28 11 0
64 3 29 13 0
64 3 30 23 0
64 3 31 6 0
64 3 32 18 0
64 3 33 10 0
64 3 34 21 0
64 3 35 19 0
64 3 36 20 0
64 3 37 13 0
64 3 38 10 0
64 3 39 39 40
64 4 16 27 72
64 4 17 7 0
64 4 18 11 0
64 4 19 24 0
64 4 20 42 0
64 4 21 16 0
64 4 22 40 0
64 4 23 15 0
64 4 24 15 0
64 4 25 22 0
64 4 26 39 0
64 4 27 16 0
64 4 28 7 0
64 4 29 16 0
64 4 30 17 0
64 4 31 1 0
64 4 32 9 0
64 4 33 22 0
64 4 34 7 0
64 4 35 22 0
64 4 36 23 0
64 4 37 24 0
64 4 38 26 40
64 5 17 17 76
64 5 18 26 8
64 5 19 16 0
64 5 20 4 0
64 5 21 13 0
64 5 22 28 0
64 5 23 13 0
64 5 24 31 0
64 5 25 2 0
64 5 26 11 0
64 5 27 27 0
64 5 28 18 0
64 5 29 18 0
64 5 30 21 0
64 5 31 19 0
64 5 32 23 0
64 5 33 18 0
64 5 34 16 0
64 5 35 30 0
64 5 36 11 8
64 5 37 14 44
64 6 19 10 72
64 6 20 22 8
64 6 21 18 0
64 6 22 36 0
64 6 23 4 0
64 6 24 15 0
64 6 25 19 0
64 6 26 14 0
64 6 27 1 0
64 6 28 12 0
64 6 29 18 0
64 6 30 10 0
64 6 31 23 0
64 6 32 6 0
64 6 33 13 0
64 6 34 10 8
64 6 35 34 40
64 7 21 37 72
64 7 22 5 8
64 7 23 3 8
64 7 24 24 0
64 7 25 30 0
64 7 26 29 0
64 7 27 1 0
64 7 28 2 0
64 7 29 1 0
64 7 30 11 0
64 7 31 20 8
64 7 32 3 8
64 7 33 18 40
64 8 24 31 76
64 8 25 37 8
64 8 26 0 8
64 8 27 24 8
64 8 28 34 8
64 8 29 38 8
64 8 30 10 44
65 0 13 29 80
65 0 14 16 16
65 0 15 36 16
65 0 16 16 16
65 0 17 41 16
65 0 18 2 16
65 0 19 21 16
65 0 20 18 16
65 0 21 3 16
65 0 22 19 16
65 0 23 38 16
65 0 24 29 16
65 0 25 19 16
65 0 26 32 16
65 0 27 5 16
65 0 28 7 16
65 0 29 38 16
65 0 30 12 16
65 0 31 4 16
65 0 32 16 16
65 0 33 13 16
65 0 34 28 16
65 0 35 38 16
65 0 36 18 16
65 0 37 36 16
65 0 38 7 16
65 0 39 28 16
65 0 40 33 16
65 0 41 20 48
65 1 13 21 72
65 1 14 41 0
65 1 15 33 0
65 1 16 11 0
65 1 17 20 0
65 1 18 34 0
65 1 19 7 0
65 1 20 5 0
65 1 21 11 0
65 1 22 10 0
65 1 23 7 0
65 1 24 19 0
65 1 25 13 0
65 1 26 18 0
65 1 27 24 0
65 1 28 16 0
65 1 29 12 0
65 1 30 42 0
65 1 31 1 0
65 1 32 18 0
65 1 33 15 0
65 1 34 18 0
65 1 35 18 0
65 1 36 14 0
65 1 37 1 0
65 1 38 31 0
65 1 39 32 0
65 1 40 4 0
65 1 41 7 40
65 2 14 5 72
65 2 15 29 0
65 2 16 1 0
65 2 17 20 0
65 2 18 17 0
65 2 19 16 0
65 2 20 30 0
65 2 21 38 0
65 2 22 23 0
65 2 23 16 0
65 2 24 22 0
65 2 25 13 0
65 2 26 22 0
65 2 27 10 0
65 2 28 34 0
65 2 29 37 0
65 2 30 22 0
65 2 31 9 0
65 2 32 15 0
65 2 33 34 0
65 2 34 31 0
65 2 35 1 0
65 2 36 29 0
65 2 37 29 0
65 2 38 37 0
65 2 39 15 0
65 2 40 10 40
65 3 15 18 72
65 3 16 32 0
65 3 17 17 0
65 3 18 9 0
65 3 19 32 0
65 3 20 42 0
65 3 21 2 0
65 3 22 26 0
65 3 23 4 0
65 3 24 11 0
65 3 25 16 0
65 3 26 5 0
65 3 27 41 0
65 3 28 37 0
65 3 29 40 0
65 3 30 32 0
65 3 31 21 0
65 3 32 36 0
65 3 33 40 0
65 3 34 1 0
65 3 35 6 0
65 3 36 5 0
65 3 37 38 0
65 3 38 25 0
65 3 39 30 40
65 4 16 37 72
65 4 17 9 0
65 4 18 26 0
65 4 19 7 0
65 4 20 4 0
65 4 21 39 0
65 4 22 37 0
65 4 23 23 0
65 4 24 23 0
65 4 25 5 0
65 4 26 0 0
65 4 27 25 0
65 4 28 7 0
65 4 29 5 0
65 4 30 31 0
65 4 31 13 0
65 4 32 9 0
65 4 33 22 0
65 4 34 24 0
65 4 35 32 0
65 4 36 15 0
65 4 37 36 0
65 4 38 35 40
65 5 17 10 72
65 5 18 11 0
65 5 19 18 0
65 5 20 19 0
65 5 21 30 0
65 5 22 21 0
65 5 23 1 0
65 5 24 18 0
65 5 25 17 0
65 5 26 2 0
65 5 27 27 0
65 5 28 11 0
65 5 29 9 0
65 5 30 26 0
65 5 31 12 0
65 5 32 38 0
65 5 33 4 0
65 5 34 26 0
65 5 35 10 0
65 5 36 7 0
65 5 37 2 40
65 6 18 13 76
65 6 19 9 8
65 6 20 8 0
65 6 21 40 0
65 6 22 18 0
65 6 23 25 0
65 6 24 1 0
65 6 25 4 0
65 6 26 16 0
65 6 27 38 0
65 6 28 25 0
65 6 29 5 0
65 6 30 6 0
65 6 31 39 0
65 6 32 6 0
65 6 33 18 0
65 6 34 37 0
65 6 35 0 8
65 6 36 11 44
65 7 20 4 76
65 7 21 12 8
65 7 22 10 8
65 7 23 4 0
65 7 24 37 0
65 7 25 9 0
65 7 26 10 0
65 7 27 10 0
65 7 28 27 0
65 7 29 30 0
65 7 30 41 0
65 7 31 30 0
65 7 32 12 8
65 7 33 20 8
65 7 34 24 44
65 8 23 29 76
65 8 24 38 8
65 8 25 26 8
65 8 26 3 8
65 8 27 13 8
65 8 28 4 8
65 8 29 13 8
65 8 30 28 8
65 8 31 31 44
66 0 12 7 92
66 0 13 1 16
66 0 14 11 16
66 0 15 1 16
66 0 16 7 16
66 0 17 41 16
66 0 18 1 16
66 0 19 33 16
66 0 20 26 16
66 0 21 40 16
66 0 22 5 16
66 0 23 9 16
66 0 24 6 16
66 0 25 21 16
66 0 26 17 16
66 0 27 27 16
66 0 28 26 16
66 0 29 19 16
66 0 30 10 16
66 0 31 29 16
66 0 32 10 16
66 0 33 13 16
66 0 34 34 16
66 0 35 12 16
66 0 36 12 16
66 0 37 7 16
66 0 38 21 16
66 0 39 9 16
66 0 40 4 16
66 0 41 27 16
66 0 42 29 60
66 1 13 2 72
66 1 14 19 0
66 1 15 10 0
66 1 16 34 0
66 1 17 4 0
66 1 18 15 0
66 1 19 26 0
66 1 20 3 0
66 1 21 15 0
66 1 22 40 0
66 1 23 18 0
66 1 24 33 0
66 1 25 23 0
66 1 26 34 0
66 1 27 0 0
66 1 28 37 0
66 1 29 31 0
66 1 30 15 0
66 1 31 41 0
66 1 32 6 0
66 1 33 8 0
66 1 34 31 0
66 1 35 20 0
66 1 36 29 0
66 1 37 26 0
66 1 38 23 0
66 1 39 14 0
66 1 40 31 0
66 1 41 10 40
66 2 14 9 72
66 2 15 37 0
66 2 16 9 0
66 2 17 24 0
66 2 18 7 0
66 2 19 2 0
66 2 20 10 0
66 2 21 42 0
66 2 22 34 0
66 2 23 35 0
66 2 24 9 0
66 2 25 37 0
66 2 26 27 0
66 2 27 7 0
66 2 28 32 0
66 2 29 38 0
66 2 30 2 0
66 2 31 12 0
66 2 32 9 0
66 2 33 37 0
66 2 34 20 0
66 2 35 2 0
66 2 36 7 0
66 2 37 1 0
66 2 38 11 0
66 2 39 16 0
66 2 40 23 40
66 3 15 7 72
66 3 16 30 0
66 3 17 11 0
66 3 18 35 0
66 3 19 5 0
66 3 20 32 0
66 3 21 41 0
66 3 22 25 0
66 3 23 41 0
66 3 24 10 0
66 3 25 40 0
66 3 26 21 0
66 3 27 8 0
66 3 28 13 0
66 3 29 18 0
66 3 30 9 0
66 3 31 16 0
66 3 32 7 0
66 3 33 42 0
66 3 34 23 0
66 3 35 19 0
66 3 36 4 0
66 3 37 6 0
66 3 38 11 0
66 3 39 7 40
66 4 16 32 72
66 4 17 14 0
66 4 18 11 0
66 4 19 13 0
66 4 20 17 0
66 4 21 16 0
66 4 22 6 0
66 4 23 26 0
66 4 24 17 0
66 4 25 39 0
66 4 26 32 0
66 4 27 24 0
66 4 28 13 0
66 4 29 13 0
66 4 30 19 0
66 4 31 31 0
66 4 32 10 0
66 4 33 1 0
66 4 34 7 0
66 4 35 15 0
66 4 36 10 0
66 4 37 4 0
66 4 38 14 40
66 5 17 6 72
66 5 18 19 0
66 5 19 5 0
66 5 20 8 0
66 5 21 1 0
66 5 22 14 0
66 5 23 0 0
66 5 24 19 0
66 5 25 18 0
66 5 26 20 0
66 5 27 17 0
66 5 28 18 0
66 5 29 27 0
66 5 30 13 0
66 5 31 13 0
66 5 32 7 0
66 5 33 8 0
66 5 34 40 0
66 5 35 39 0
66 5 36 11 0
66 5 37 5 40
66 6 18 41 72
66 6 19 40 8
66 6 20 28 0
66 6 21 41 0
66 6 22 40 0
66 6 23 36 0
66 6 24 33 0
66 6 25 18 0
66 6 26 0 0
66 6 27 39 0
66 6 28 14 0
66 6 29 38 0
66 6 30 21 0
66 6 31 23 0
66 6 32 39 0
66 6 33 38 0
66 6 34 28 0
66 6 35 5 8
66 6 36 3 40
66 7 20 28 72
66 7 21 10 8
66 7 22 2 0
66 7 23 25 0
66 7 24 23 0
66 7 25 25 0
66 7 26 14 0
66 7 27 13 0
66 7 28 0 0
66 7 29 5 0
66 7 30 0 0
66 7 31 1 0
66 7 32 23 0
66 7 33 32 8
66 7 34 36 40
66 8 22 5 76
66 8 23 34 8
66 8 24 4 8
66 8 25 5 8
66 8 26 12 8
66 8 27 16 8
66 8 28 8 8
66 8 29 13 8
66 8 30 30 8
66 8 31 27 8
66 8 32 22 44
67 0 12 12 88
67 0 13 6 16
67 0 14 16 16
67 0 15 32 16
67 0 16 18 16
67 0 17 28 16
67 0 18 18 16
67 0 19 4 16
67 0 20 13 16
67 0 21 21 16
67 0 22 7 16
67 0 23 39 16
67 0 24 42 16
67 0 25 31 16
67 0 26 0 16
67 0 27 10 16
67 0 28 18 16
67 0 29 37 16
67 0 30 1 16
67 0 31 19 16
67 0 32 9 16
67 0 33 31 16
67 0 34 36 16
67 0 35 10 16
67 0 36 7 16
67 0 37 2 16
67 0 38 2 16
67 0 39 20 16
67 0 40 35 16
67 0 41 15 16
67 0 42 3 56
67 1 13 1 64
67 1 14 42 0
67 1 15 9 0
67 1 16 20 0
67 1 17 33 0
67 1 18 14 0
67 1 19 19 0
67 1 20 10 0
67 1 21 17 0
67 1 22 9 0
67 1 23 1 0
67 1 24 7 0
67 1 25 8 0
67 1 26 4 0
67 1 27 31 0
67 1 28 14 0
67 1 29 23 0
67 1 30 13 0
67 1 31 40 0
67 1 32 4 0
67 1 33 10 0
67 1 34 18 0
67 1 35 16 0
67 1 36 29 0
67 1 37 36 0
67 1 38 9 0
67 1 39 37 0
67 1 40 4 0
67 1 41 34 32
67 2 13 6 76
67 2 14 11 0
67 2 15 7 0
67 2 16 28 0
67 2 17 39 0
67 2 18 29 0
67 2 19 1 0
67 2 20 10 0
67 2 21 24 0
67 2 22 2 0
67 2 23 33 0
67 2 24 41 0
67 2 25 33 0
67 2 26 0 0
67 2 27 3 0
67 2 28 14 0
67 2 29 3 0
67 2 30 23 0
67 2 31 42 0
67 2 32 5 0
67 2 33 23 0
67 2 34 10 0
67 2 35 39 0
67 2 36 12 0
67 2 37 7 0
67 2 38 16 0
67 2 39 26 0
67 2 40 21 0
67 2 41 4 44
67 3 14 42 76
67 3 15 27 0
67 3 16 10 0
67 3 17 2 0
67 3 18 28 0
67 3 19 0 0
67 3 20 27 0
67 3 21 4 0
67 3 22 18 0
67 3 23 22 0
67 3 24 13 0
67 3 25 3 0
67 3 26 16 0
67 3 27 34 0
67 3 28 10 0
67 3 29 7 0
67 3 30 1 0
67 3 31 4 0
67 3 32 34 0
67 3 33 16 0
67 3 34 14 0
67 3 35 24 0
67 3 36 25 0
67 3 37 6 0
67 3 38 22 0
67 3 39 33 0
67 3 40 36 44
67 4 15 27 76
67 4 16 18 0
67 4 17 25 0
67 4 18 14 0
67 4 19 9 0
67 4 20 9 0
67 4 21 19 0
67 4 22 9 0
67 4 23 36 0
67 4 24 37 0
67 4 25 3 0
67 4 26 5 0
67 4 27 22 0
67 4 28 1 0
67 4 29 19 0
67 4 30 18 0
67 4 31 14 0
67 4 32 0 0
67 4 33 28 0
67 4 34 40 0
67 4 35 28 0
67 4 36 16 0
67 4 37 18 0
67 4 38 19 0
67 4 39 16 44
67 5 16 21 76
67 5 17 20 8
67 5 18 34 0
67 5 19 18 0
67 5 20 27 0
67 5 21 32 0
67 5 22 1 0
67 5 23 28 0
67 5 24 0 0
67 5 25 12 0
67 5 26 41 0
67 5 27 16 0
67 5 28 42 0
67 5 29 6 0
67 5 30 35 0
67 5 31 7 0
67 5 32 7 0
67 5 33 42 0
67 5 34 11 0
67 5 35 17 0
67 5 36 35 0
67 5 37 4 8
67 5 38 6 44
67 6 18 19 72
67 6 19 39 0
67 6 20 31 0
67 6 21 3 0
67 6 22 9 0
67 6 23 41 0
67 6 24 41 0
67 6 25 4 0
67 6 26 15 0
67 6 27 25 0
67 6 28 24 0
67 6 29 13 0
67 6 30 21 0
67 6 31 37 0
67 6 32 8 0
67 6 33 25 0
67 6 34 34 0
67 6 35 38 0
67 6 36 28 40
67 7 19 17 76
67 7 20 10 8
67 7 21 20 8
67 7 22 8 0
67 7 23 42 0
67 7 24 39 0
67 7 25 13 0
67 7 26 37 0
67 7 27 10 0
67 7 28 27 0
67 7 29 26 0
67 7 30 14 0
67 7 31 33 0
67 7 32 2 0
67 7 33 2 8
67 7 34 5 8
67 7 35 28 44
67 8 22 9 72
67 8 23 6 8
67 8 24 35 8
67 8 25 29 8
67 8 26 13 8
67 8 27 42 8
67 8 28 8 8
67 8 29 15 8
67 8 30 26 8
67 8 31 1 8
67 8 32 0 40
68 0 12 6 88
68 0 13 31 16
68 0 14 10 16
68 0 15 3 16
68 0 16 38 16
68 0 17 27 16
68 0 18 11 16
68 0 19 16 16
68 0 20 27 16
68 0 21 37 16
68 0 22 13 16
68 0 23 15 16
68 0 24 22 16
68 0 25 28 16
68 0 26 27 16
68 0 27 3 16
68 0 28 18 16
68 0 29 32 16
68 0 30 11 16
68 0 31 8 16
68 0 32 6 16
68 0 33 31 16
68 0 34 7 16
68 0 35 16 16
68 0 36 40 16
68 0 37 29 16
68 0 38 29 16
68 0 39 22 16
68 0 40 8 16
68 0 41 39 16
68 0 42 22 56
68 1 13 35 64
68 1 14 10 0
68 1 15 5 0
68 1 16 34 0
68 1 17 21 0
68 1 18 14 0
68 1 19 22 0
68 1 20 25 0
68 1 21 26 0
68 1 22 20 0
68 1 23 22 0
68 1 24 27 0
68 1 25 35 0
68 1 26 9 0
68 1 27 10 0
68 1 28 19 0
68 1 29 32 0
68 1 30 9 0
68 1 31 6 0
68 1 32 16 0
68 1 33 42 0
68 1 34 31 0
68 1 35 9 0
68 1 36 1 0
68 1 37 1 0
68 1 38 0 0
68 1 39 23 0
68 1 40 37 0
68 1 41 30 32
68 2 13 1 72
68 2 14 13 0
68 2 15 2 0
68 2 16 25 0
68 2 17 19 0
68 2 18 10 0
68 2 19 7 0
68 2 20 7 0
68 2 21 1 0
68 2 22 7 0
68 2 23 34 0
68 2 24 9 0
68 2 25 4 0
68 2 26 32 0
68 2 27 20 0
68 2 28 41 0
68 2 29 10 0
68 2 30 13 0
68 2 31 10 0
68 2 32 33 0
68 2 33 7 0
68 2 34 20 0
68 2 35 1 0
68 2 36 3 0
68 2 37 19 0
68 2 38 3 0
68 2 39 36 0
68 2 40 9 0
68 2 41 4 40
68 3 14 42 72
68 3 15 16 0
68 3 16 10 0
68 3 17 38 0
68 3 18 2 0
68 3 19 40 0
68 3 20 7 0
68 3 21 28 0
68 3 22 24 0
68 3 23 42 0
68 3 24 4 0
68 3 25 42 0
68 3 26 34 0
68 3 27 18 0
68 3 28 11 0
68 3 29 20 0
68 3 30 29 0
68 3 31 32 0
68 3 32 12 0
68 3 33 1 0
68 3 34 27 0
68 3 35 9 0
68 3 36 32 0
68 3 37 40 0
68 3 38 14 0
68 3 39 23 0
68 3 40 18 40
68 4 15 25 72
68 4 16 23 0
68 4 17 42 0
68 4 18 35 0
68 4 19 6 0
68 4 20 11 0
68 4 21 34 0
68 4 22 38 0
68 4 23 15 0
68 4 24 9 0
68 4 25 13 0
68 4 26 41 0
68 4 27 36 0
68 4 28 7 0
68 4 29 16 0
68 4 30 1 0
68 4 31 7 0
68 4 32 19 0
68 4 33 14 0
68 4 34 29 0
68 4 35 31 0
68 4 36 23 0
68 4 37 11 0
68 4 38 26 0
68 4 39 6 40
68 5 16 37 72
68 5 17 42 0
68 5 18 21 0
68 5 19 27 0
68 5 20 40 0
68 5 21 28 0
68 5 22 18 0
68 5 23 10 0
68 5 24 25 0
68 5 25 5 0
68 5 26 16 0
68 5 27 19 0
68 5 28 10 0
68 5 29 39 0
68 5 30 12 0
68 5 31 16 0
68 5 32 39 0
68 5 33 10 0
68 5 34 36 0
68 5 35 37 0
68 5 36 1 0
68 5 37 12 0
68 5 38 32 40
68 6 17 27 76
68 6 18 23 8
68 6 19 27 0
68 6 20 41 0
68 6 21 28 0
68 6 22 40 0
68 6 23 6 0
68 6 24 22 0
68 6 25 42 0
68 6 26 3 0
68 6 27 41 0
68 6 28 18 0
68 6 29 25 0
68 6 30 3 0
68 6 31 13 0
68 6 32 29 0
68 6 33 3 0
68 6 34 39 0
68 6 35 16 0
68 6 36 6 8
68 6 37 20 44
68 7 19 22 72
68 7 20 42 8
68 7 21 3 0
68 7 22 31 0
68 7 23 39 0
68 7 24 6 0
68 7 25 7 0
68 7 26 7 0
68 7 27 1 0
68 7 28 3 0
68 7 29 37 0
68 7 30 25 0
68 7 31 3 0
68 7 32 19 0
68 7 33 3 0
68 7 34 4 8
68 7 35 20 40
68 8 21 2 76
68 8 22 31 8
68 8 23 0 8
68 8 24 28 8
68 8 25 4 0
68 8 26 41 0
68 8 27 7 0
68 8 28 4 0
68 8 29 1 0
68 8 30 34 8
68 8 31 8 8
68 8 32 12 8
68 8 33 11 44
68 9 25 8 76
68 9 26 30 12
68 9 27 10 12
68 9 28 11 12
68 9 29 18 44
69 0 12 0 80
69 0 13 16 16
69 0 14 4 16
69 0 15 30 16
69 0 16 25 16
69 0 17 40 16
69 0 18 1 16
69 0 19 13 16
69 0 20 18 16
69 0 21 4 16
69 0 22 16 16
69 0 23 10 16
69 0 24 10 16
69 0 25 15 16
69 0 26 37 16
69 0 27 2 16
69 0 28 3 16
69 0 29 25 16
69 0 30 16 16
69 0 31 23 16
69 0 32 37 16
69 0 33 33 16
69 0 34 15 16
69 0 35 27 16
69 0 36 22 16
69 0 37 36 16
69 0 38 28 16
69 0 39 37 16
69 0 40 33 16
69 0 41 11 16
69 0 42 40 48
69 1 12 3 76
69 1 13 7 0
69 1 14 8 0
69 1 15 17 0
69 1 16 14 0
69 1 17 20 0
69 1 18 3 0
69 1 19 3 0
69 1 20 1 0
69 1 21 6 0
69 1 22 42 0
69 1 23 10 0
69 1 24 29 0
69 1 25 10 0
69 1 26 21 0
69 1 27 10 0
69 1 28 29 0
69 1 29 10 0
69 1 30 35 0
69 1 31 42 0
69 1 32 32 0
69 1 33 16 0
69 1 34 13 0
69 1 35 5 0
69 1 36 41 0
69 1 37 6 0
69 1 38 35 0
69 1 39 38 0
69 1 40 16 0
69 1 41 2 0
69 1 42 13 44
69 2 13 9 72
69 2 14 23 0
69 2 15 32 0
69 2 16 11 0
69 2 17 1 0
69 2 18 16 0
69 2 19 40 0
69 2 20 27 0
69 2 21 17 0
69 2 22 5 0
69 2 23 27 0
69 2 24 1 0
69 2 25 32 0
69 2 26 30 0
69 2 27 25 0
69 2 28 35 0
69 2 29 7 0
69 2 30 14 0
69 2 31 16 0
69 2 32 10 0
69 2 33 35 0
69 2 34 36 0
69 2 35 4 0
69 2 36 19 0
69 2 37 4 0
69 2 38 10 0
69 2 39 16 0
69 2 40 16 0
69 2 41 1 40
69 3 14 21 72
69 3 15 24 0
69 3 16 7 0
69 3 17 33 0
69 3 18 13 0
69 3 19 6 0
69 3 20 22 0
69 3 21 18 0
69 3 22 17 0
69 3 23 14 0
69 3 24 18 0
69 3 25 26 0
69 3 26 34 0
69 3 27 32 0
69 3 28 13 0
69 3 29 30 0
69 3 30 1 0
69 3 31 22 0
69 3 32 20 0
69 3 33 6 0
69 3 34 14 0
69 3 35 6 0
69 3 36 1 0
69 3 37 23 0
69 3 38 2 0
69 3 39 37 0
69 3 40 37 40
69 4 15 28 72
69 4 16 29 0
69 4 17 35 0
69 4 18 10 0
69 4 19 18 0
69 4 20 7 0
69 4 21 25 0
69 4 22 36 0
69 4 23 35 0
69 4 24 10 0
69 4 25 35 0
69 4 26 9 0
69 4 27 0 0
69 4 28 40 0
69 4 29 32 0
69 4 30 41 0
69 4 31 26 0
69 4 32 9 0
69 4 33 42 0
69 4 34 17 0
69 4 35 15 0
69 4 36 7 0
69 4 37 10 0
69 4 38 41 0
69 4 39 6 40
69 5 16 3 72
69 5 17 23 0
69 5 18 8 0
69 5 19 28 0
69 5 20 3 0
69 5 21 8 0
69 5 22 1 0
69 5 23 26 0
69 5 24 5 0
69 5 25 4 0
69 5 26 26 0
69 5 27 31 0
69 5 28 0 0
69 5 29 29 0
69 5 30 19 0
69 5 31 7 0
69 5 32 3 0
69 5 33 22 0
69 5 34 38 0
69 5 35 12 0
69 5 36 1 0
69 5 37 28 0
69 5 38 0 40
69 6 17 3 72
69 6 18 15 8
69 6 19 1 0
69 6 20 15 0
69 6 21 16 0
69 6 22 24 0
69 6 23 13 0
69 6 24 25 0
69 6 25 0 0
69 6 26 31 0
69 6 27 11 0
69 6 28 42 0
69 6 29 32 0
69 6 30 4 0
69 6 31 34 0
69 6 32 35 0
69 6 33 18 0
69 6 34 1 0
69 6 35 22 0
69 6 36 13 8
69 6 37 13 40
69 7 19 25 72
69 7 20 21 8
69 7 21 21 0
69 7 22 2 0
69 7 23 24 0
69 7 24 21 0
69 7 25 34 0
69 7 26 21 0
69 7 27 29 0
69 7 28 19 0
69 7 29 38 0
69 7 30 36 0
69 7 31 0 0
69 7 32 7 0
69 7 33 29 0
69 7 34 35 8
69 7 35 40 40
69 8 21 28 72
69 8 22 23 8
69 8 23 40 8
69 8 24 4 0
69 8 25 10 0
69 8 26 4 0
69 8 27 10 0
69 8 28 15 0
69 8 29 8 0
69 8 30 39 0
69 8 31 32 8
69 8 32 40 8
69 8 33 3 40
69 9 24 2 76
69 9 25 7 8
69 9 26 42 8
69 9 27 37 8
69 9 28 16 8
69 9 29 20 8
69 9 30 6 44
70 0 11 7 92
70 0 12 30 16
70 0 13 25 16
70 0 14 16 16
70 0 15 6 16
70 0 16 40 16
70 0 17 42 16
70 0 18 9 16
70 0 19 27 16
70 0 20 9 16
70 0 21 20 16
70 0 22 13 16
70 0 23 33 16
70 0 24 30 16
70 0 25 2 16
70 0 26 37 16
70 0 27 1 16
70 0 28 2 16
70 0 29 16 16
70 0 30 2 16
70 0 31 10 16
70 0 32 18 16
70 0 33 14 16
70 0 34 23 16
70 0 35 18 16
70 0 36 12 16
70 0 37 38 16
70 0 38 15 16
70 0 39 41 16
70 0 40 36 16
70 0 41 14 16
70 0 42 42 16
70 0 43 26 60
70 1 12 29 72
70 1 13 21 0
70 1 14 8 0
70 1 15 15 0
70 1 16 19 0
70 1 17 3 0
70 1 18 36 0
70 1 19 12 0
70 1 20 37 0
70 1 21 18 0
70 1 22 22 0
70 1 23 17 0
70 1 24 18 0
70 1 25 16 0
70 1 26 13 0
70 1 27 25 0
70 1 28 37 0
70 1 29 24 0
70 1 30 42 0
70 1 31 16 0
70 1 32 10 0
70 1 33 16 0
70 1 34 23 0
70 1 35 23 0
70 1 36 30 0
70 1 37 20 0
70 1 38 9 0
70 1 39 9 0
70 1 40 30 0
70 1 41 38 0
70 1 42 14 40
70 2 13 10 72
70 2 14 12 0
70 2 15 29 0
70 2 16 40 0
70 2 17 21 0
70 2 18 8 0
70 2 19 8 0
70 2 20 36 0
70 2 21 32 0
70 2 22 13 0
70 2 23 28 0
70 2 24 30 0
70 2 25 35 0
70 2 26 42 0
70 2 27 19 0
70 2 28 0 0
70 2 29 1 0
70 2 30 17 0
70 2 31 16 0
70 2 32 24 0
70 2 33 2 0
70 2 34 27 0
70 2 35 7 0
70 2 36 1 0
70 2 37 27 0
70 2 38 3 0
70 2 39 21 0
70 2 40 40 0
70 2 41 17 40
70 3 14 7 72
70 3 15 7 0
70 3 16 20 0
70 3 17 9 0
70 3 18 36 0
70 3 19 27 0
70 3 20 14 0
70 3 21 3 0
70 3 22 18 0
70 3 23 28 0
70 3 24 20 0
70 3 25 28 0
70 3 26 19 0
70 3 27 8 0
70 3 28 39 0
70 3 29 4 0
70 3 30 4 0
70 3 31 36 0
70 3 32 15 0
70 3 33 27 0
70 3 34 29 0
70 3 35 15 0
70 3 36 9 0
70 3 37 4 0
70 3 38 3 0
70 3 39 5 0
70 3 40 12 40
70 4 15 33 72
70 4 16 17 0
70 4 17 14 0
70 4 18 18 0
70 4 19 1 0
70 4 20 18 0
70 4 21 7 0
70 4 22 2 0
70 4 23 16 0
70 4 24 16 0
70 4 25 4 0
70 4 26 33 0
70 4 27 8 0
70 4 28 13 0
70 4 29 28 0
70 4 30 13 0
70 4 31 34 0
70 4 32 31 0
70 4 33 23 0
70 4 34 38 0
70 4 35 3 0
70 4 36 0 0
70 4 37 37 0
70 4 38 10 0
70 4 39 32 40
70 5 16 22 72
70 5 17 19 0
70 5 18 9 0
70 5 19 17 0
70 5 20 42 0
70 5 21 35 0
70 5 22 17 0
70 5 23 33 0
70 5 24 32 0
70 5 25 4 0
70 5 26 5 0
70 5 27 33 0
70 5 28 4 0
70 5 29 7 0
70 5 30 10 0
70 5 31 16 0
70 5 32 32 0
70 5 33 18 0
70 5 34 21 0
70 5 35 15 0
70 5 36 0 0
70 5 37 10 0
70 5 38 4 40
70 6 17 19 72
70 6 18 34 0
70 6 19 10 0
70 6 20 32 0
70 6 21 41 0
70 6 22 19 0
70 6 23 6 0
70 6 24 8 0
70 6 25 10 0
70 6 26 40 0
70 6 27 29 0
70 6 28 4 0
70 6 29 42 0
70 6 30 10 0
70 6 31 34 0
70 6 32 20 0
70 6 33 21 0
70 6 34 7 0
70 6 35 35 0
70 6 36 5 0
70 6 37 6 40
70 7 18 7 76
70 7 19 14 8
70 7 20 30 0
70 7 21 15 0
70 7 22 10 0
70 7 23 20 0
70 7 24 13 0
70 7 25 16 0
70 7 26 24 0
70 7 27 19 0
70 7 28 1 0
70 7 29 29 0
70 7 30 26 0
70 7 31 17 0
70 7 32 31 0
70 7 33 12 0
70 7 34 0 0
70 7 35 5 8
70 7 36 4 44
70 8 20 16 76
70 8 21 3 8
70 8 22 20 8
70 8 23 3 0
70 8 24 21 0
70 8 25 42 0
70 8 26 18 0
70 8 27 3 0
70 8 28 9 0
70 8 29 4 0
70 8 30 7 0
70 8 31 0 0
70 8 32 2 8
70 8 33 22 8
70 8 34 28 44
70 9 23 41 76
70 9 24 7 8
70 9 25 30 8
70 9 26 24 8
70 9 27 30 8
70 9 28 10 8
70 9 29 18 8
70 9 30 26 8
70 9 31 32 44
71 0 11 23 88
71 0 12 27 16
71 0 13 33 16
71 0 14 8 16
71 0 15 7 16
71 0 16 13 16
71 0 17 28 16
71 0 18 9 16
71 0 19 1 16
71 0 20 16 16
71 0 21 16 16
71 0 22 40 16
71 0 23 11 16
71 0 24 23 16
71 0 25 29 16
71 0 26 16 16
71 0 27 2 16
71 0 28 40 16
71 0 29 24 16
71 0 30 15 16
71 0 31 25 16
71 0 32 7 16
71 0 33 16 16
71 0 34 15 16
71 0 35 16 16
71 0 36 25 16
71 0 37 0 16
71 0 38 37 16
71 0 39 1 16
71 0 40 16 16
71 0 41 5 16
71 0 42 15 16
71 0 43 32 56
71 1 12 0 72
71 1 13 11 0
71 1 14 0 0
71 1 15 13 0
71 1 16 42 0
71 1 17 22 0
71 1 18 1 0
71 1 19 10 0
71 1 20 15 0
71 1 21 7 0
71 1 22 42 0
71 1 23 35 0
71 1 24 13 0
71 1 25 40 0
71 1 26 29 0
71 1 27 34 0
71 1 28 4 0
71 1 29 16 0
71 1 30 18 0
71 1 31 24 0
71 1 32 36 0
71 1 33 25 0
71 1 34 10 0
71 1 35 42 0
71 1 36 4 0
71 1 37 20 0
71 1 38 8 0
71 1 39 13 0
71 1 40 18 0
71 1 41 1 0
71 1 42 5 40
71 2 13 37 64
71 2 14 16 0
71 2 15 18 0
71 2 16 36 0
71 2 17 16 0
71 2 18 22 0
71 2 19 16 0
71 2 20 22 0
71 2 21 39 0
71 2 22 13 0
71 2 23 25 0
71 2 24 30 0
71 2 25 11 0
71 2 26 1 0
71 2 27 1 0
71 2 28 11 0
71 2 29 40 0
71 2 30 13 0
71 2 31 21 0
71 2 32 10 0
71 2 33 10 0
71 2 34 10 0
71 2 35 33 0
71 2 36 36 0
71 2 37 14 0
71 2 38 38 0
71 2 39 5 0
71 2 40 16 0
71 2 41 0 32
71 3 13 1 76
71 3 14 1 0
71 3 15 15 0
71 3 16 32 0
71 3 17 13 0
71 3 18 23 0
71 3 19 12 0
71 3 20 2 0
71 3 21 40 0
71 3 22 41 0
71 3 23 9 0
71 3 24 29 0
71 3 25 14 0
71 3 26 13 0
71 3 27 41 0
71 3 28 25 0
71 3 29 33 0
71 3 30 37 0
71 3 31 28 0
71 3 32 38 0
71 3 33 30 0
71 3 34 33 0
71 3 35 6 0
71 3 36 21 0
71 3 37 41 0
71 3 38 20 0
71 3 39 14 0
71 3 40 6 0
71 3 41 6 44
71 4 14 3 76
71 4 15 8 0
71 4 16 16 0
71 4 17 1 0
71 4 18 42 0
71 4 19 18 0
71 4 20 23 0
71 4 21 37 0
71 4 22 22 0
71 4 23 10 0
71 4 24 18 0
71 4 25 0 0
71 4 26 19 0
71 4 27 18 0
71 4 28 32 0
71 4 29 1 0
71 4 30 9 0
71 4 31 27 0
71 4 32 15 0
71 4 33 36 0
71 4 34 3 0
71 4 35 16 0
71 4 36 10 0
71 4 37 32 0
71 4 38 16 0
71 4 39 22 0
71 4 40 32 44
71 5 15 11 76
71 5 16 11 8
71 5 17 10 0
71 5 18 20 0
71 5 19 15 0
71 5 20 1 0
71 5 21 32 0
71 5 22 9 0
71 5 23 30 0
71 5 24 35 0
71 5 25 14 0
71 5 26 22 0
71 5 27 5 0
71 5 28 20 0
71 5 29 16 0
71 5 30 13 0
71 5 31 13 0
71 5 32 35 0
71 5 33 10 0
71 5 34 18 0
71 5 35 4 0
71 5 36 15 0
71 5 37 5 0
71 5 38 26 8
71 5 39 10 44
71 6 17 14 72
71 6 18 28 0
71 6 19 22 0
71 6 20 11 0
71 6 21 40 0
71 6 22 7 0
71 6 23 7 0
71 6 24 21 0
71 6 25 18 0
71 6 26 17 0
71 6 27 10 0
71 6 28 14 0
71 6 29 1 0
71 6 30 42 0
71 6 31 16 0
71 6 32 38 0
71 6 33 14 0
71 6 34 20 0
71 6 35 34 0
71 6 36 38 0
71 6 37 10 40
71 7 18 33 72
71 7 19 3 8
71 7 20 6 0
71 7 21 23 0
71 7 22 16 0
71 7 23 42 0
71 7 24 42 0
71 7 25 34 0
71 7 26 1 0
71 7 27 0 0
71 7 28 38 0
71 7 29 31 0
71 7 30 30 0
71 7 31 36 0
71 7 32 23 0
71 7 33 4 0
71 7 34 0 0
71 7 35 29 8
71 7 36 38 40
71 8 20 11 72
71 8 21 1 8
71 8 22 10 8
71 8 23 36 0
71 8 24 6 0
71 8 25 1 0
71 8 26 16 0
71 8 27 1 0
71 8 28 5 0
71 8 29 28 0
71 8 30 18 0
71 8 31 1 0
71 8 32 34 8
71 8 33 24 8
71 8 34 28 40
71 9 23 30 72
71 9 24 13 8
71 9 25 8 8
71 9 26 31 8
71 9 27 1 8
71 9 28 30 8
71 9 29 14 8
71 9 30 42 8
71 9 31 25 40
72 0 11 13 88
72 0 12 12 16
72 0 13 7 16
72 0 14 13 16
72 0 15 33 16
72 0 16 23 16
72 0 17 19 16
72 0 18 12 16
72 0 19 7 16
72 0 20 23 16
72 0 21 3 16
72 0 22 23 16
72 0 23 42 16
72 0 24 15 16
72 0 25 4 16
72 0 26 37 16
72 0 27 33 16
72 0 28 31 16
72 0 29 21 16
72 0 30 22 16
72 0 31 6 16
72 0 32 27 16
72 0 33 35 16
72 0 34 27 16
72 0 35 20 16
72 0 36 40 16
72 0 37 41 16
72 0 38 21 16
72 0 39 26 16
72 0 40 33 16
72 0 41 10 16
72 0 42 18 16
72 0 43 1 56
72 1 12 14 64
72 1 13 37 0
72 1 14 4 0
72 1 15 0 0
72 1 16 12 0
72 1 17 0 0
72 1 18 13 0
72 1 19 36 0
72 1 20 25 0
72 1 21 8 0
72 1 22 27 0
72 1 23 21 0
72 1 24 17 0
72 1 25 33 0
72 1 26 7 0
72 1 27 17 0
72 1 28 26 0
72 1 29 32 0
72 1 30 25 0
72 1 31 33 0
72 1 32 39 0
72 1 33 14 0
72 1 34 18 0
72 1 35 6 0
72 1 36 15 0
72 1 37 31 0
72 1 38 30 0
72 1 39 18 0
72 1 40 9 0
72 1 41 1 0
72 1 42 25 32
72 2 12 11 76
72 2 13 33 0
72 2 14 11 0
72 2 15 32 0
72 2 16 42 0
72 2 17 10 0
72 2 18 13 0
72 2 19 25 0
72 2 20 17 0
72 2 21 38 0
72 2 22 17 0
72 2 23 17 0
72 2 24 35 0
72 2 25 3 0
72 2 26 21 0
72 2 27 6 0
72 2 28 16 0
72 2 29 23 0
72 2 30 30 0
72 2 31 11 0
72 2 32 21 0
72 2 33 32 0
72 2 34 13 0
72 2 35 23 0
72 2 36 13 0
72 2 37 38 0
72 2 38 18 0
72 2 39 16 0
72 2 40 35 0
72 2 41 13 0
72 2 42 38 44
72 3 13 24 72
72 3 14 4 0
72 3 15 35 0
72 3 16 22 0
72 3 17 41 0
72 3 18 34 0
72 3 19 18 0
72 3 20 8 0
72 3 21 9 0
72 3 22 32 0
72 3 23 17 0
72 3 24 21 0
72 3 25 10 0
72 3 26 22 0
72 3 27 11 0
72 3 28 19 0
72 3 29 3 0
72 3 30 35 0
72 3 31 10 0
72 3 32 10 0
72 3 33 1 0
72 3 34 25 0
72 3 35 12 0
72 3 36 37 0
72 3 37 17 0
72 3 38 29 0
72 3 39 24 0
72 3 40 0 0
72 3 41 10 40
72 4 14 16 72
72 4 15 24 0
72 4 16 32 0
72 4 17 7 0
72 4 18 3 0
72 4 19 30 0
72 4 20 14 0
72 4 21 4 0
72 4 22 38 0
72 4 23 24 0
72 4 24 32 0
72 4 25 15 0
72 4 26 39 0
72 4 27 32 0
72 4 28 1 0
72 4 29 10 0
72 4 30 10 0
72 4 31 1 0
72 4 32 6 0
72 4 33 20 0
72 4 34 13 0
72 4 35 10 0
72 4 36 12 0
72 4 37 13 0
72 4 38 12 0
72 4 39 34 0
72 4 40 21 40
72 5 15 17 72
72 5 16 26 0
72 5 17 37 0
72 5 18 42 0
72 5 19 37 0
72 5 20 8 0
72 5 21 40 0
72 5 22 7 0
72 5 23 6 0
72 5 24 11 0
72 5 25 10 0
72 5 26 7 0
72 5 27 22 0
72 5 28 36 0
72 5 29 14 0
72 5 30 0 0
72 5 31 1 0
72 5 32 22 0
72 5 33 4 0
72 5 34 1 0
72 5 35 39 0
72 5 36 3 0
72 5 37 13 0
72 5 38 41 0
72 5 39 12 40
72 6 16 22 76
72 6 17 24 8
72 6 18 5 0
72 6 19 25 0
72 6 20 12 0
72 6 21 35 0
72 6 22 6 0
72 6 23 9 0
72 6 24 40 0
72 6 25 18 0
72 6 26 2 0
72 6 27 29 0
72 6 28 1 0
72 6 29 39 0
72 6 30 19 0
72 6 31 31 0
72 6 32 9 0
72 6 33 8 0
72 6 34 1 0
72 6 35 26 0
72 6 36 16 0
72 6 37 22 8
72 6 38 5 44
72 7 18 14 72
72 7 19 22 8
72 7 20 10 0
72 7 21 17 0
72 7 22 6 0
72 7 23 23 0
72 7 24 40 0
72 7 25 30 0
72 7 26 26 0
72 7 27 39 0
72 7 28 37 0
72 7 29 15 0
72 7 30 27 0
72 7 31 12 0
72 7 32 4 0
72 7 33 7 0
72 7 34 14 0
72 7 35 7 8
72 7 36 40 40
72 8 20 13 72
72 8 21 20 8
72 8 22 32 0
72 8 23 22 0
72 8 24 38 0
72 8 25 37 0
72 8 26 14 0
72 8 27 10 0
72 8 28 1 0
72 8 29 5 0
72 8 30 35 0
72 8 31 9 0
72 8 32 10 0
72 8 33 34 8
72 8 34 40 40
72 9 22 13 76
72 9 23 21 8
72 9 24 7 8
72 9 25 21 8
72 9 26 16 8
72 9 27 27 8
72 9 28 27 8
72 9 29 34 8
72 9 30 28 8
72 9 31 15 8
72 9 32 32 44
73 0 11 1 88
73 0 12 28 16
73 0 13 25 16
73 0 14 30 16
73 0 15 3 16
73 0 16 10 16
73 0 17 9 16
73 0 18 25 16
73 0 19 4 16
73 0 20 5 16
73 0 21 8 16
73 0 22 9 16
73 0 23 37 16
73 0 24 25 16
73 0 25 13 16
73 0 26 18 16
73 0 27 6 16
73 0 28 39 16
73 0 29 4 16
73 0 30 32 16
73 0 31 10 16
73 0 32 30 16
73 0 33 15 16
73 0 34 42 16
73 0 35 22 16
73 0 36 3 16
73 0 37 10 16
73 0 38 38 16
73 0 39 21 16
73 0 40 23 16
73 0 41 8 16
73 0 42 13 16
73 0 43 37 56
73 1 12 4 64
73 1 13 33 0
73 1 14 28 0
73 1 15 31 0
73 1 16 24 0
73 1 17 18 0
73 1 18 8 0
73 1 19 39 0
73 1 20 36 0
73 1 21 14 0
73 1 22 4 0
73 1 23 21 0
73 1 24 0 0
73 1 25 0 0
73 1 26 26 0
73 1 27 33 0
73 1 28 13 0
73 1 29 37 0
73 1 30 8 0
73 1 31 10 0
73 1 32 16 0
73 1 33 2 0
73 1 34 16 0
73 1 35 1 0
73 1 36 4 0
73 1 37 26 0
73 1 38 13 0
73 1 39 5 0
73 1 40 33 0
73 1 41 17 0
73 1 42 21 32
73 2 12 42 72
73 2 13 37 0
73 2 14 18 0
73 2 15 9 0
73 2 16 24 0
73 2 17 5 0
73 2 18 15 0
73 2 19 0 0
73 2 20 9 0
73 2 21 41 0
73 2 22 33 0
73 2 23 16 0
73 2 24 13 0
73 2 25 15 0
73 2 26 34 0
73 2 27 18 0
73 2 28 21 0
73 2 29 4 0
73 2 30 37 0
73 2 31 29 0
73 2 32 32 0
73 2 33 15 0
73 2 34 12 0
73 2 35 4 0
73 2 36 38 0
73 2 37 0 0
73 2 38 10 0
73 2 39 16 0
73 2 40 26 0
73 2 41 28 0
73 2 42 39 40
73 3 13 12 72
73 3 14 10 0
73 3 15 20 0
73 3 16 42 0
73 3 17 18 0
73 3 18 14 0
73 3 19 30 0
73 3 20 21 0
73 3 21 37 0
73 3 22 17 0
73 3 23 0 0
73 3 24 32 0
73 3 25 6 0
73 3 26 12 0
73 3 27 16 0
73 3 28 22 0
73 3 29 33 0
73 3 30 13 0
73 3 31 2 0
73 3 32 35 0
73 3 33 35 0
73 3 34 18 0
73 3 35 15 0
73 3 36 16 0
73 3 37 7 0
73 3 38 33 0
73 3 39 26 0
73 3 40 28 0
73 3 41 27 40
73 4 14 15 72
73 4 15 6 0
73 4 16 4 0
73 4 17 13 0
73 4 18 4 0
73 4 19 40 0
73 4 20 28 0
73 4 21 16 0
73 4 22 19 0
73 4 23 6 0
73 4 24 19 0
73 4 25 39 0
73 4 26 10 0
73 4 27 32 0
73 4 28 12 0
73 4 29 34 0
73 4 30 21 0
73 4 31 26 0
73 4 32 29 0
73 4 33 19 0
73 4 34 41 0
73 4 35 14 0
73 4 36 10 0
73 4 37 35 0
73 4 38 28 0
73 4 39 36 0
73 4 40 37 40
73 5 15 27 72
73 5 16 1 0
73 5 17 10 0
73 5 18 21 0
73 5 19 13 0
73 5 20 4 0
73 5 21 11 0
73 5 22 24 0
73 5 23 39 0
73 5 24 6 0
73 5 25 18 0
73 5 26 26 0
73 5 27 1 0
73 5 28 6 0
73 5 29 35 0
73 5 30 2 0
73 5 31 2 0
73 5 32 14 0
73 5 33 7 0
73 5 34 32 0
73 5 35 34 0
73 5 36 4 0
73 5 37 14 0
73 5 38 34 0
73 5 39 14 40
73 6 16 4 72
73 6 17 18 0
73 6 18 36 0
73 6 19 13 0
73 6 20 33 0
73 6 21 24 0
73 6 22 7 0
73 6 23 0 0
73 6 24 27 0
73 6 25 32 0
73 6 26 32 0
73 6 27 42 0
73 6 28 19 0
73 6 29 13 0
73 6 30 30 0
73 6 31 21 0
73 6 32 40 0
73 6 33 12 0
73 6 34 41 0
73 6 35 28 0
73 6 36 33 0
73 6 37 24 0
73 6 38 20 40
73 7 17 39 76
73 7 18 5 8
73 7 19 12 0
73 7 20 21 0
73 7 21 40 0
73 7 22 1 0
73 7 23 22 0
73 7 24 6 0
73 7 25 10 0
73 7 26 4 0
73 7 27 30 0
73 7 28 10 0
73 7 29 25 0
73 7 30 15 0
73 7 31 22 0
73 7 32 10 0
73 7 33 4 0
73 7 34 4 0
73 7 35 7 0
73 7 36 17 8
73 7 37 31 44
73 8 19 18 76
73 8 20 27 8
73 8 21 36 8
73 8 22 29 0
73 8 23 0 0
73 8 24 10 0
73 8 25 7 0
73 8 26 34 0
73 8 27 41 0
73 8 28 7 0
73 8 29 16 0
73 8 30 5 0
73 8 31 4 0
73 8 32 4 0
73 8 33 9 8
73 8 34 38 8
73 8 35 14 44
73 9 22 3 72
73 9 23 10 8
73 9 24 31 8
73 9 25 17 8
73 9 26 14 8
73 9 27 10 8
73 9 28 33 8
73 9 29 1 8
73 9 30 2 8
73 9 31 28 8
73 9 32 28 40
74 0 11 16 80
74 0 12 36 16
74 0 13 25 16
74 0 14 26 16
74 0 15 4 16
74 0 16 16 16
74 0 17 8 16
74 0 18 4 16
74 0 19 14 16
74 0 20 7 16
74 0 21 32 16
74 0 22 3 16
74 0 23 15 16
74 0 24 12 16
74 0 25 18 16
74 0 26 1 16
74 0 27 10 16
74 0 28 26 16
74 0 29 21 16
74 0 30 22 16
74 0 31 35 16
74 0 32 29 16
74 0 33 37 16
74 0 34 42 16
74 0 35 4 16
74 0 36 4 16
74 0 37 8 16
74 0 38 14 16
74 0 39 6 16
74 0 40 22 16
74 0 41 14 16
74 0 42 31 16
74 0 43 30 48
74 1 11 41 76
74 1 12 32 0
74 1 13 11 0
74 1 14 11 0
74 1 15 18 0
74 1 16 10 0
74 1 17 23 0
74 1 18 33 0
74 1 19 42 0
74 1 20 13 0
74 1 21 19 0
74 1 22 10 0
74 1 23 26 0
74 1 24 18 0
74 1 25 26 0
74 1 26 13 0
74 1 27 39 0
74 1 28 39 0
74 1 29 23 0
74 1 30 29 0
74 1 31 13 0
74 1 32 24 0
74 1 33 16 0
74 1 34 20 0
74 1 35 15 0
74 1 36 14 0
74 1 37 10 0
74 1 38 19 0
74 1 39 42 0
74 1 40 20 0
74 1 41 13 0
74 1 42 12 0
74 1 43 4 44
74 2 12 12 72
74 2 13 37 0
74 2 14 32 0
74 2 15 35 0
74 2 16 24 0
74 2 17 30 0
74 2 18 16 0
74 2 19 23 0
74 2 20 4 0
74 2 21 0 0
74 2 22 18 0
74 2 23 38 0
74 2 24 1 0
74 2 25 18 0
74 2 26 30 0
74 2 27 8 0
74 2 28 11 0
74 2 29 28 0
74 2 30 40 0
74 2 31 15 0
74 2 32 1 0
74 2 33 32 0
74 2 34 18 0
74 2 35 9 0
74 2 36 10 0
74 2 37 36 0
74 2 38 35 0
74 2 39 16 0
74 2 40 8 0
74 2 41 10 0
74 2 42 1 40
74 3 13 7 72
74 3 14 42 0
74 3 15 26 0
74 3 16 4 0
74 3 17 23 0
74 3 18 12 0
74 3 19 7 0
74 3 20 1 0
74 3 21 35 0
74 3 22 36 0
74 3 23 0 0
74 3 24 14 0
74 3 25 37 0
74 3 26 13 0
74 3 27 4 0
74 3 28 27 0
74 3 29 18 0
74 3 30 21 0
74 3 31 15 0
74 3 32 8 0
74 3 33 21 0
74 3 34 31 0
74 3 35 20 0
74 3 36 29 0
74 3 37 27 0
74 3 38 19 0
74 3 39 7 0
74 3 40 4 0
74 3 41 22 40
74 4 14 20 72
74 4 15 18 0
74 4 16 29 0
74 4 17 37 0
74 4 18 8 0
74 4 19 18 0
74 4 20 35 0
74 4 21 16 0
74 4 22 32 0
74 4 23 1 0
74 4 24 25 0
74 4 25 34 0
74 4 26 12 0
74 4 27 1 0
74 4 28 16 0
74 4 29 23 0
74 4 30 39 0
74 4 31 7 0
74 4 32 7 0
74 4 33 23 0
74 4 34 29 0
74 4 35 10 0
74 4 36 32 0
74 4 37 26 0
74 4 38 15 0
74 4 39 36 0
74 4 40 6 40
74 5 15 0 72
74 5 16 12 0
74 5 17 0 0
74 5 18 30 0
74 5 19 26 0
74 5 20 16 0
74 5 21 7 0
74 5 22 2 0
74 5 23 37 0
74 5 24 37 0
74 5 25 34 0
74 5 26 5 0
74 5 27 39 0
74 5 28 5 0
74 5 29 26 0
74 5 30 9 0
74 5 31 34 0
74 5 32 25 0
74 5 33 34 0
74 5 34 23 0
74 5 35 13 0
74 5 36 35 0
74 5 37 18 0
74 5 38 28 0
74 5 39 13 40
74 6 16 8 72
74 6 17 40 0
74 6 18 4 0
74 6 19 31 0
74 6 20 11 0
74 6 21 23 0
74 6 22 20 0
74 6 23 10 0
74 6 24 28 0
74 6 25 1 0
74 6 26 14 0
74 6 27 20 0
74 6 28 34 0
74 6 29 12 0
74 6 30 27 0
74 6 31 10 0
74 6 32 7 0
74 6 33 18 0
74 6 34 7 0
74 6 35 22 0
74 6 36 42 0
74 6 37 12 0
74 6 38 31 40
74 7 17 15 72
74 7 18 25 8
74 7 19 9 0
74 7 20 21 0
74 7 21 37 0
74 7 22 5 0
74 7 23 33 0
74 7 24 2 0
74 7 25 6 0
74 7 26 1 0
74 7 27 0 0
74 7 28 12 0
74 7 29 13 0
74 7 30 24 0
74 7 31 1 0
74 7 32 34 0
74 7 33 25 0
74 7 34 38 0
74 7 35 1 0
74 7 36 16 8
74 7 37 1 40
74 8 19 42 72
74 8 20 15 8
74 8 21 42 0
74 8 22 41 0
74 8 23 37 0
74 8 24 6 0
74 8 25 30 0
74 8 26 2 0
74 8 27 41 0
74 8 28 19 0
74 8 29 14 0
74 8 30 1 0
74 8 31 38 0
74 8 32 18 0
74 8 33 8 0
74 8 34 35 8
74 8 35 41 40
74 9 21 10 76
74 9 22 31 8
74 9 23 6 8
74 9 24 1 8
74 9 25 21 0
74 9 26 39 0
74 9 27 16 0
74 9 28 35 0
74 9 29 42 0
74 9 30 4 8
74 9 31 12 8
74 9 32 42 8
74 9 33 17 44
74 10 25 36 76
74 10 26 29 12
74 10 27 36 12
74 10 28 15 12
74 10 29 17 44
75 0 11 1 80
75 0 12 19 16
75 0 13 26 16
75 0 14 40 16
75 0 15 28 16
75 0 16 4 16
75 0 17 8 16
75 0 18 4 16
75 0 19 1 16
75 0 20 7 16
75 0 21 10 16
75 0 22 31 16
75 0 23 10 16
75 0 24 24 16
75 0 25 13 16
75 0 26 40 16
75 0 27 0 16
75 0 28 21 16
75 0 29 17 16
75 0 30 18 16
75 0 31 41 16
75 0 32 41 16
75 0 33 18 16
75 0 34 33 16
75 0 35 35 16
75 0 36 4 16
75 0 37 13 16
75 0 38 42 16
75 0 39 19 16
75 0 40 3 16
75 0 41 33 16
75 0 42 29 16
75 0 43 23 48
75 1 11 2 72
75 1 12 22 0
75 1 13 7 0
75 1 14 22 0
75 1 15 16 0
75 1 16 16 0
75 1 17 13 0
75 1 18 19 0
75 1 19 15 0
75 1 20 27 0
75 1 21 27 0
75 1 22 1 0
75 1 23 38 0
75 1 24 18 0
75 1 25 0 0
75 1 26 25 0
75 1 27 5 0
75 1 28 5 0
75 1 29 5 0
75 1 30 18 0
75 1 31 22 0
75 1 32 8 0
75 1 33 42 0
75 1 34 11 0
75 1 35 5 0
75 1 36 28 0
75 1 37 29 0
75 1 38 18 0
75 1 39 12 0
75 1 40 41 0
75 1 41 3 0
75 1 42 18 0
75 1 43 40 40
75 2 12 5 72
75 2 13 6 0
75 2 14 31 0
75 2 15 32 0
75 2 16 26 0
75 2 17 1 0
75 2 18 12 0
75 2 19 36 0
75 2 20 6 0
75 2 21 32 0
75 2 22 26 0
75 2 23 31 0
75 2 24 2 0
75 2 25 33 0
75 2 26 3 0
75 2 27 1 0
75 2 28 29 0
75 2 29 29 0
75 2 30 13 0
75 2 31 1 0
75 2 32 24 0
75 2 33 3 0
75 2 34 24 0
75 2 35 26 0
75 2 36 18 0
75 2 37 37 0
75 2 38 23 0
75 2 39 33 0
75 2 40 39 0
75 2 41 4 0
75 2 42 0 40
75 3 13 11 64
75 3 14 10 0
75 3 15 9 0
75 3 16 7 0
75 3 17 11 0
75 3 18 16 0
75 3 19 18 0
75 3 20 31 0
75 3 21 11 0
75 3 22 7 0
75 3 23 32 0
75 3 24 3 0
75 3 25 6 0
75 3 26 13 0
75 3 27 13 0
75 3 28 16 0
75 3 29 42 0
75 3 30 7 0
75 3 31 3 0
75 3 32 35 0
75 3 33 7 0
75 3 34 35 0
75 3 35 41 0
75 3 36 27 0
75 3 37 7 0
75 3 38 29 0
75 3 39 28 0
75 3 40 30 0
75 3 41 28 32
75 4 13 10 76
75 4 14 30 0
75 4 15 33 0
75 4 16 21 0
75 4 17 10 0
75 4 18 7 0
75 4 19 25 0
75 4 20 9 0
75 4 21 10 0
75 4 22 15 0
75 4 23 12 0
75 4 24 15 0
75 4 25 16 0
75 4 26 8 0
75 4 27 28 0
75 4 28 38 0
75 4 29 22 0
75 4 30 4 0
75 4 31 41 0
75 4 32 34 0
75 4 33 6 0
75 4 34 17 0
75 4 35 16 0
75 4 36 34 0
75 4 37 1 0
75 4 38 42 0
75 4 39 9 0
75 4 40 2 0
75 4 41 15 44
75 5 14 37 76
75 5 15 38 8
75 5 16 6 0
75 5 17 11 0
75 5 18 16 0
75 5 19 6 0
75 5 20 18 0
75 5 21 18 0
75 5 22 1 0
75 5 23 6 0
75 5 24 4 0
75 5 25 20 0
75 5 26 39 0
75 5 27 30 0
75 5 28 40 0
75 5 29 13 0
75 5 30 28 0
75 5 31 20 0
75 5 32 6 0
75 5 33 16 0
75 5 34 4 0
75 5 35 42 0
75 5 36 0 0
75 5 37 41 0
75 5 38 24 0
75 5 39 13 8
75 5 40 2 44
75 6 16 41 72
75 6 17 0 0
75 6 18 22 0
75 6 19 7 0
75 6 20 13 0
75 6 21 16 0
75 6 22 37 0
75 6 23 16 0
75 6 24 8 0
75 6 25 4 0
75 6 26 24 0
75 6 27 33 0
75 6 28 9 0
75 6 29 23 0
75 6 30 7 0
75 6 31 12 0
75 6 32 4 0
75 6 33 20 0
75 6 34 33 0
75 6 35 16 0
75 6 36 23 0
75 6 37 6 0
75 6 38 0 40
75 7 17 17 72
75 7 18 35 8
75 7 19 18 0
75 7 20 16 0
75 7 21 34 0
75 7 22 27 0
75 7 23 12 0
75 7 24 5 0
75 7 25 28 0
75 7 26 19 0
75 7 27 12 0
75 7 28 7 0
75 7 29 34 0
75 7 30 25 0
75 7 31 8 0
75 7 32 28 0
75 7 33 36 0
75 7 34 30 0
75 7 35 4 0
75 7 36 24 8
75 7 37 42 40
75 8 19 31 72
75 8 20 31 8
75 8 21 42 0
75 8 22 28 0
75 8 23 10 0
75 8 24 13 0
75 8 25 10 0
75 8 26 14 0
75 8 27 10 0
75 8 28 36 0
75 8 29 12 0
75 8 30 0 0
75 8 31 38 0
75 8 32 9 0
75 8 33 6 0
75 8 34 29 8
75 8 35 22 40
75 9 21 33 72
75 9 22 18 8
75 9 23 18 8
75 9 24 40 0
75 9 25 9 0
75 9 26 42 0
75 9 27 10 0
75 9 28 40 0
75 9 29 20 0
75 9 30 16 0
75 9 31 6 8
75 9 32 32 8
75 9 33 0 40
75 10 24 20 76
75 10 25 10 8
75 10 26 22 8
75 10 27 37 8
75 10 28 29 8
75 10 29 36 8
75 10 30 10 44
76 0 10 33 92
76 0 11 42 16
76 0 12 9 16
76 0 13 13 16
76 0 14 2 16
76 0 15 0 16
76 0 16 37 16
76 0 17 42 16
76 0 18 10 16
76 0 19 28 16
76 0 20 33 16
76 0 21 36 16
76 0 22 31 16
76 0 23 20 16
76 0 24 17 16
76 0 25 26 16
76 0 26 4 16
76 0 27 36 16
76 0 28 15 16
76 0 29 22 16
76 0 30 6 16
76 0 31 23 16
76 0 32 29 16
76 0 33 33 16
76 0 34 6 16
76 0 35 31 16
76 0 36 7 16
76 0 37 0 16
76 0 38 10 16
76 0 39 6 16
76 0 40 21 16
76 0 41 10 16
76 0 42 38 16
76 0 43 6 16
76 0 44 7 60
76 1 11 12 72
76 1 12 27 0
76 1 13 13 0
76 1 14 42 0
76 1 15 4 0
76 1 16 4 0
76 1 17 7 0
76 1 18 34 0
76 1 19 18 0
76 1 20 13 0
76 1 21 9 0
76 1 22 38 0
76 1 23 18 0
76 1 24 40 0
76 1 25 34 0
76 1 26 1 0
76 1 27 1 0
76 1 28 9 0
76 1 29 0 0
76 1 30 33 0
76 1 31 1 0
76 1 32 9 0
76 1 33 12 0
76 1 34 7 0
76 1 35 15 0
76 1 36 1 0
76 1 37 19 0
76 1 38 24 0
76 1 39 39 0
76 1 40 1 0
76 1 41 6 0
76 1 42 22 0
76 1 43 5 40
76 2 12 30 64
76 2 13 22 0
76 2 14 38 0
76 2 15 17 0
76 2 16 25 0
76 2 17 38 0
76 2 18 34 0
76 2 19 13 0
76 2 20 42 0
76 2 21 35 0
76 2 22 4 0
76 2 23 30 0
76 2 24 30 0
76 2 25 19 0
76 2 26 31 0
76 2 27 21 0
76 2 28 13 0
76 2 29 18 0
76 2 30 34 0
76 2 31 11 0
76 2 32 4 0
76 2 33 10 0
76 2 34 31 0
76 2 35 33 0
76 2 36 14 0
76 2 37 15 0
76 2 38 1 0
76 2 39 15 0
76 2 40 34 0
76 2 41 41 0
76 2 42 35 32
76 3 12 23 76
76 3 13 40 0
76 3 14 1 0
76 3 15 20 0
76 3 16 13 0
76 3 17 34 0
76 3 18 10 0
76 3 19 4 0
76 3 20 38 0
76 3 21 20 0
76 3 22 15 0
76 3 23 17 0
76 3 24 31 0
76 3 25 1 0
76 3 26 7 0
76 3 27 31 0
76 3 28 6 0
76 3 29 28 0
76 3 30 18 0
76 3 31 33 0
76 3 32 41 0
76 3 33 19 0
76 3 34 14 0
76 3 35 1 0
76 3 36 39 0
76 3 37 5 0
76 3 38 5 0
76 3 39 24 0
76 3 40 6 0
76 3 41 8 0
76 3 42 1 44
76 4 13 38 72
76 4 14 35 0
76 4 15 9 0
76 4 16 26 0
76 4 17 27 0
76 4 18 7 0
76 4 19 22 0
76 4 20 35 0
76 4 21 14 0
76 4 22 37 0
76 4 23 18 0
76 4 24 18 0
76 4 25 42 0
76 4 26 5 0
76 4 27 15 0
76 4 28 6 0
76 4 29 15 0
76 4 30 37 0
76 4 31 8 0
76 4 32 32 0
76 4 33 5 0
76 4 34 10 0
76 4 35 8 0
76 4 36 19 0
76 4 37 29 0
76 4 38 15 0
76 4 39 10 0
76 4 40 39 0
76 4 41 21 40
76 5 14 21 72
76 5 15 40 0
76 5 16 19 0
76 5 17 20 0
76 5 18 11 0
76 5 19 34 0
76 5 20 2 0
76 5 21 21 0
76 5 22 13 0
76 5 23 33 0
76 5 24 27 0
76 5 25 14 0
76 5 26 15 0
76 5 27 41 0
76 5 28 21 0
76 5 29 16 0
76 5 30 26 0
76 5 31 1 0
76 5 32 0 0
76 5 33 1 0
76 5 34 38 0
76 5 35 22 0
76 5 36 11 0
76 5 37 14 0
76 5 38 9 0
76 5 39 6 0
76 5 40 20 40
76 6 15 22 76
76 6 16 29 8
76 6 17 28 0
76 6 18 32 0
76 6 19 8 0
76 6 20 26 0
76 6 21 18 0
76 6 22 37 0
76 6 23 42 0
76 6 24 21 0
76 6 25 42 0
76 6 26 0 0
76 6 27 31 0
76 6 28 2 0
76 6 29 0 0
76 6 30 8 0
76 6 31 37 0
76 6 32 38 0
76 6 33 3 0
76 6 34 26 0
76 6 35 33 0
76 6 36 6 0
76 6 37 20 0
76 6 38 14 8
76 6 39 31 44
76 7 17 17 72
76 7 18 42 0
76 7 19 30 0
76 7 20 6 0
76 7 21 35 0
76 7 22 34 0
76 7 23 7 0
76 7 24 6 0
76 7 25 11 0
76 7 26 13 0
76 7 27 33 0
76 7 28 5 0
76 7 29 26 0
76 7 30 40 0
76 7 31 14 0
76 7 32 18 0
76 7 33 27 0
76 7 34 30 0
76 7 35 28 0
76 7 36 13 0
76 7 37 3 40
76 8 18 1 76
76 8 19 18 8
76 8 20 16 0
76 8 21 5 0
76 8 22 38 0
76 8 23 16 0
76 8 24 41 0
76 8 25 29 0
76 8 26 21 0
76 8 27 4 0
76 8 28 5 0
76 8 29 40 0
76 8 30 11 0
76 8 31 32 0
76 8 32 22 0
76 8 33 29 0
76 8 34 13 0
76 8 35 25 8
76 8 36 1 44
76 9 20 27 76
76 9 21 4 8
76 9 22 6 8
76 9 23 5 8
76 9 24 10 0
76 9 25 19 0
76 9 26 10 0
76 9 27 33 0
76 9 28 21 0
76 9 29 3 0
76 9 30 2 0
76 9 31 1 8
76 9 32 6 8
76 9 33 11 8
76 9 34 30 44
76 10 24 24 72
76 10 25 10 8
76 10 26 2 8
76 10 27 4 8
76 10 28 13 8
76 10 29 34 8
76 10 30 32 40
77 0 10 14 88
77 0 11 13 16
77 0 12 9 16
77 0 13 7 16
77 0 14 5 16
77 0 15 0 16
77 0 16 4 16
77 0 17 42 16
77 0 18 30 16
77 0 19 29 16
77 0 20 21 16
77 0 21 5 16
77 0 22 32 16
77 0 23 41 16
77 0 24 39 16
77 0 25 42 16
77 0 26 17 16
77 0 27 39 16
77 0 28 12 16
77 0 29 7 16
77 0 30 10 16
77 0 31 26 16
77 0 32 8 16
77 0 33 3 16
77 0 34 10 16
77 0 35 38 16
77 0 36 4 16
77 0 37 37 16
77 0 38 24 16
77 0 39 41 16
77 0 40 33 16
77 0 41 14 16
77 0 42 36 16
77 0 43 30 16
77 0 44 16 56
77 1 11 38 64
77 1 12 32 0
77 1 13 37 0
77 1 14 24 0
77 1 15 1 0
77 1 16 42 0
77 1 17 40 0
77 1 18 1 0
77 1 19 13 0
77 1 20 13 0
77 1 21 16 0
77 1 22 26 0
77 1 23 41 0
77 1 24 35 0
77 1 25 5 0
77 1 26 3 0
77 1 27 16 0
77 1 28 12 0
77 1 29 15 0
77 1 30 6 0
77 1 31 20 0
77 1 32 10 0
77 1 33 18 0
77 1 34 32 0
77 1 35 23 0
77 1 36 16 0
77 1 37 3 0
77 1 38 2 0
77 1 39 34 0
77 1 40 13 0
77 1 41 3 0
77 1 42 10 0
77 1 43 35 32
77 2 11 1 76
77 2 12 0 0
77 2 13 20 0
77 2 14 41 0
77 2 15 29 0
77 2 16 37 0
77 2 17 5 0
77 2 18 40 0
77 2 19 4 0
77 2 20 33 0
77 2 21 10 0
77 2 22 13 0
77 2 23 25 0
77 2 24 11 0
77 2 25 25 0
77 2 26 13 0
77 2 27 30 0
77 2 28 13 0
77 2 29 18 0
77 2 30 5 0
77 2 31 29 0
77 2 32 25 0
77 2 33 4 0
77 2 34 22 0
77 2 35 11 0
77 2 36 14 0
77 2 37 21 0
77 2 38 13 0
77 2 39 26 0
77 2 40 21 0
77 2 41 2 0
77 2 42 36 0
77 2 43 33 44
77 3 12 25 72
77 3 13 17 0
77 3 14 30 0
77 3 15 23 0
77 3 16 10 0
77 3 17 24 0
77 3 18 31 0
77 3 19 1 0
77 3 20 28 0
77 3 21 25 0
77 3 22 33 0
77 3 23 21 0
77 3 24 34 0
77 3 25 36 0
77 3 26 1 0
77 3 27 16 0
77 3 28 30 0
77 3 29 21 0
77 3 30 1 0
77 3 31 6 0
77 3 32 18 0
77 3 33 23 0
77 3 34 7 0
77 3 35 5 0
77 3 36 1 0
77 3 37 40 0
77 3 38 3 0
77 3 39 20 0
77 3 40 4 0
77 3 41 15 0
77 3 42 2 40
77 4 13 10 72
77 4 14 26 0
77 4 15 0 0
77 4 16 28 0
77 4 17 8 0
77 4 18 40 0
77 4 19 28 0
77 4 20 2 0
77 4 21 16 0
77 4 22 24 0
77 4 23 38 0
77 4 24 15 0
77 4 25 1 0
77 4 26 6 0
77 4 27 18 0
77 4 28 38 0
77 4 29 8 0
77 4 30 39 0
77 4 31 24 0
77 4 32 1 0
77 4 33 0 0
77 4 34 16 0
77 4 35 4 0
77 4 36 37 0
77 4 37 1 0
77 4 38 27 0
77 4 39 41 0
77 4 40 26 0
77 4 41 41 40
77 5 14 28 72
77 5 15 39 0
77 5 16 34 0
77 5 17 13 0
77 5 18 41 0
77 5 19 41 0
77 5 20 14 0
77 5 21 2 0
77 5 22 11 0
77 5 23 10 0
77 5 24 1 0
77 5 25 33 0
77 5 26 14 0
77 5 27 14 0
77 5 28 16 0
77 5 29 16 0
77 5 30 21 0
77 5 31 4 0
77 5 32 19 0
77 5 33 1 0
77 5 34 11 0
77 5 35 13 0
77 5 36 11 0
77 5 37 30 0
77 5 38 21 0
77 5 39 2 0
77 5 40 40 40
77 6 15 16 72
77 6 16 1 0
77 6 17 30 0
77 6 18 34 0
77 6 19 34 0
77 6 20 29 0
77 6 21 14 0
77 6 22 21 0
77 6 23 35 0
77 6 24 16 0
77 6 25 18 0
77 6 26 4 0
77 6 27 30 0
77 6 28 0 0
77 6 29 18 0
77 6 30 24 0
77 6 31 41 0
77 6 32 7 0
77 6 33 14 0
77 6 34 41 0
77 6 35 20 0
77 6 36 1 0
77 6 37 37 0
77 6 38 31 0
77 6 39 37 40
77 7 16 26 76
77 7 17 23 8
77 7 18 41 0
77 7 19 11 0
77 7 20 29 0
77 7 21 2 0
77 7 22 30 0
77 7 23 41 0
77 7 24 39 0
77 7 25 18 0
77 7 26 24 0
77 7 27 36 0
77 7 28 35 0
77 7 29 7 0
77 7 30 7 0
77 7 31 38 0
77 7 32 10 0
77 7 33 35 0
77 7 34 14 0
77 7 35 38 0
77 7 36 3 0
77 7 37 41 8
77 7 38 0 44
77 8 18 10 72
77 8 19 26 8
77 8 20 28 0
77 8 21 31 0
77 8 22 12 0
77 8 23 35 0
77 8 24 3 0
77 8 25 10 0
77 8 26 24 0
77 8 27 37 0
77 8 28 11 0
77 8 29 29 0
77 8 30 18 0
77 8 31 1 0
77 8 32 26 0
77 8 33 24 0
77 8 34 37 0
77 8 35 32 8
77 8 36 14 40
77 9 20 26 72
77 9 21 12 8
77 9 22 26 8
77 9 23 37 0
77 9 24 3 0
77 9 25 10 0
77 9 26 18 0
77 9 27 4 0
77 9 28 13 0
77 9 29 35 0
77 9 30 30 0
77 9 31 8 0
77 9 32 32 8
77 9 33 13 8
77 9 34 14 40
77 10 23 10 76
77 10 24 0 8
77 10 25 9 8
77 10 26 16 8
77 10 27 1 8
77 10 28 13 8
77 10 29 39 8
77 10 30 0 8
77 10 31 7 44
78 0 10 4 88
78 0 11 23 16
78 0 12 25 16
78 0 13 24 16
78 0 14 10 16
78 0 15 10 16
78 0 16 32 16
78 0 17 37 16
78 0 18 1 16
78 0 19 26 16
78 0 20 7 16
78 0 21 2 16
78 0 22 14 16
78 0 23 39 16
78 0 24 31 16
78 0 25 30 16
78 0 26 7 16
78 0 27 23 16
78 0 28 34 16
78 0 29 33 16
78 0 30 2 16
78 0 31 1 16
78 0 32 14 16
78 0 33 1 16
78 0 34 17 16
78 0 35 28 16
78 0 36 19 16
78 0 37 38 16
78 0 38 18 16
78 0 39 13 16
78 0 40 5 16
78 0 41 28 16
78 0 42 42 16
78 0 43 2 16
78 0 44 40 56
78 1 11 22 64
78 1 12 4 0
78 1 13 33 0
78 1 14 29 0
78 1 15 35 0
78 1 16 5 0
78 1 17 32 0
78 1 18 32 0
78 1 19 30 0
78 1 20 2 0
78 1 21 20 0
78 1 22 33 0
78 1 23 13 0
78 1 24 12 0
78 1 25 19 0
78 1 26 17 0
78 1 27 1 0
78 1 28 32 0
78 1 29 19 0
78 1 30 18 0
78 1 31 12 0
78 1 32 40 0
78 1 33 40 0
78 1 34 5 0
78 1 35 31 0
78 1 36 12 0
78 1 37 18 0
78 1 38 2 0
78 1 39 10 0
78 1 40 6 0
78 1 41 4 0
78 1 42 17 0
78 1 43 19 32
78 2 11 20 72
78 2 12 6 0
78 2 13 1 0
78 2 14 0 0
78 2 15 36 0
78 2 16 20 0
78 2 17 39 0
78 2 18 42 0
78 2 19 18 0
78 2 20 4 0
78 2 21 33 0
78 2 22 4 0
78 2 23 0 0
78 2 24 33 0
78 2 25 16 0
78 2 26 38 0
78 2 27 6 0
78 2 28 28 0
78 2 29 35 0
78 2 30 17 0
78 2 31 16 0
78 2 32 40 0
78 2 33 37 0
78 2 34 14 0
78 2 35 32 0
78 2 36 29 0
78 2 37 10 0
78 2 38 41 0
78 2 39 14 0
78 2 40 20 0
78 2 41 35 0
78 2 42 35 0
78 2 43 10 40
78 3 12 9 72
78 3 13 19 0
78 3 14 11 0
78 3 15 21 0
78 3 16 10 0
78 3 17 9 0
78 3 18 36 0
78 3 19 9 0
78 3 20 9 0
78 3 21 30 0
78 3 22 2 0
78 3 23 7 0
78 3 24 13 0
78 3 25 36 0
78 3 26 5 0
78 3 27 36 0
78 3 28 22 0
78 3 29 6 0
78 3 30 10 0
78 3 31 8 0
78 3 32 14 0
78 3 33 42 0
78 3 34 10 0
78 3 35 4 0
78 3 36 13 0
78 3 37 7 0
78 3 38 29 0
78 3 39 13 0
78 3 40 20 0
78 3 41 10 0
78 3 42 41 40
78 4 13 1 72
78 4 14 26 0
78 4 15 13 0
78 4 16 4 0
78 4 17 25 0
78 4 18 27 0
78 4 19 23 0
78 4 20 19 0
78 4 21 4 0
78 4 22 26 0
78 4 23 40 0
78 4 24 40 0
78 4 25 41 0
78 4 26 25 0
78 4 27 33 0
78 4 28 16 0
78 4 29 10 0
78 4 30 11 0
78 4 31 7 0
78 4 32 34 0
78 4 33 16 0
78 4 34 9 0
78 4 35 7 0
78 4 36 9 0
78 4 37 22 0
78 4 38 8 0
78 4 39 18 0
78 4 40 27 0
78 4 41 14 40
78 5 14 39 72
78 5 15 13 0
78 5 16 18 0
78 5 17 10 0
78 5 18 34 0
78 5 19 13 0
78 5 20 18 0
78 5 21 5 0
78 5 22 23 0
78 5 23 15 0
78 5 24 16 0
78 5 25 42 0
78 5 26 1 0
78 5 27 1 0
78 5 28 10 0
78 5 29 8 0
78 5 30 39 0
78 5 31 25 0
78 5 32 1 0
78 5 33 2 0
78 5 34 36 0
78 5 35 16 0
78 5 36 11 0
78 5 37 0 0
78 5 38 9 0
78 5 39 18 0
78 5 40 20 40
78 6 15 16 72
78 6 16 40 0
78 6 17 4 0
78 6 18 13 0
78 6 19 26 0
78 6 20 23 0
78 6 21 42 0
78 6 22 25 0
78 6 23 36 0
78 6 24 28 0
78 6 25 23 0
78 6 26 30 0
78 6 27 17 0
78 6 28 7 0
78 6 29 35 0
78 6 30 28 0
78 6 31 24 0
78 6 32 30 0
78 6 33 12 0
78 6 34 24 0
78 6 35 24 0
78 6 36 20 0
78 6 37 21 0
78 6 38 41 0
78 6 39 4 40
78 7 16 13 72
78 7 17 13 8
78 7 18 5 0
78 7 19 11 0
78 7 20 27 0
78 7 21 30 0
78 7 22 7 0
78 7 23 7 0
78 7 24 3 0
78 7 25 4 0
78 7 26 30 0
78 7 27 29 0
78 7 28 42 0
78 7 29 25 0
78 7 30 13 0
78 7 31 16 0
78 7 32 21 0
78 7 33 16 0
78 7 34 31 0
78 7 35 1 0
78 7 36 0 0
78 7 37 17 8
78 7 38 12 40
78 8 18 16 72
78 8 19 22 8
78 8 20 27 0
78 8 21 16 0
78 8 22 10 0
78 8 23 7 0
78 8 24 42 0
78 8 25 34 0
78 8 26 2 0
78 8 27 26 0
78 8 28 38 0
78 8 29 25 0
78 8 30 10 0
78 8 31 7 0
78 8 32 30 0
78 8 33 6 0
78 8 34 39 0
78 8 35 6 8
78 8 36 16 40
78 9 20 34 72
78 9 21 25 8
78 9 22 39 0
78 9 23 22 0
78 9 24 25 0
78 9 25 10 0
78 9 26 7 0
78 9 27 42 0
78 9 28 41 0
78 9 29 30 0
78 9 30 0 0
78 9 31 3 0
78 9 32 9 0
78 9 33 23 8
78 9 34 42 40
78 10 22 22 76
78 10 23 4 8
78 10 24 18 8
78 10 25 10 8
78 10 26 39 8
78 10 27 0 8
78 10 28 10 8
78 10 29 17 8
78 10 30 27 8
78 10 31 27 8
78 10 32 19 44
79 0 10 9 88
79 0 11 31 16
79 0 12 10 16
79 0 13 36 16
79 0 14 16 16
79 0 15 3 16
79 0 16 25 16
79 0 17 22 16
79 0 18 16 16
79 0 19 20 16
79 0 20 18 16
79 0 21 42 16
79 0 22 15 16
79 0 23 12 16
79 0 24 31 16
79 0 25 11 16
79 0 26 3 16
79 0 27 18 16
79 0 28 22 16
79 0 29 26 16
79 0 30 4 16
79 0 31 12 16
79 0 32 21 16
79 0 33 22 16
79 0 34 32 16
79 0 35 37 16
79 0 36 18 16
79 0 37 31 16
79 0 38 18 16
79 0 39 0 16
79 0 40 28 16
79 0 41 42 16
79 0 42 41 16
79 0 43 5 16
79 0 44 25 56
79 1 11 8 64
79 1 12 27 0
79 1 13 42 0
79 1 14 37 0
79 1 15 14 0
79 1 16 10 0
79 1 17 39 0
79 1 18 42 0
79 1 19 25 0
79 1 20 18 0
79 1 21 4 0
79 1 22 37 0
79 1 23 3 0
79 1 24 9 0
79 1 25 17 0
79 1 26 21 0
79 1 27 15 0
79 1 28 13 0
79 1 29 11 0
79 1 30 14 0
79 1 31 18 0
79 1 32 20 0
79 1 33 29 0
79 1 34 8 0
79 1 35 11 0
79 1 36 0 0
79 1 37 4 0
79 1 38 36 0
79 1 39 39 0
79 1 40 10 0
79 1 41 19 0
79 1 42 24 0
79 1 43 9 32
79 2 11 20 72
79 2 12 4 0
79 2 13 36 0
79 2 14 28 0
79 2 15 28 0
79 2 16 32 0
79 2 17 4 0
79 2 18 24 0
79 2 19 37 0
79 2 20 31 0
79 2 21 32 0
79 2 22 7 0
79 2 23 2 0
79 2 24 18 0
79 2 25 17 0
79 2 26 21 0
79 2 27 16 0
79 2 28 15 0
79 2 29 4 0
79 2 30 5 0
79 2 31 4 0
79 2 32 30 0
79 2 33 7 0
79 2 34 33 0
79 2 35 19 0
79 2 36 34 0
79 2 37 26 0
79 2 38 37 0
79 2 39 18 0
79 2 40 24 0
79 2 41 25 0
79 2 42 12 0
79 2 43 24 40
79 3 12 19 72
79 3 13 4 0
79 3 14 4 0
79 3 15 18 0
79 3 16 12 0
79 3 17 8 0
79 3 18 12 0
79 3 19 34 0
79 3 20 2 0
79 3 21 32 0
79 3 22 6 0
79 3 23 5 0
79 3 24 33 0
79 3 25 7 0
79 3 26 5 0
79 3 27 14 0
79 3 28 30 0
79 3 29 29 0
79 3 30 19 0
79 3 31 42 0
79 3 32 23 0
79 3 33 22 0
79 3 34 29 0
79 3 35 40 0
79 3 36 13 0
79 3 37 9 0
79 3 38 0 0
79 3 39 35 0
79 3 40 16 0
79 3 41 30 0
79 3 42 31 40
79 4 13 11 72
79 4 14 12 0
79 4 15 23 0
79 4 16 23 0
79 4 17 18 0
79 4 18 0 0
79 4 19 25 0
79 4 20 1 0
79 4 21 17 0
79 4 22 17 0
79 4 23 35 0
79 4 24 29 0
79 4 25 18 0
79 4 26 41 0
79 4 27 42 0
79 4 28 41 0
79 4 29 32 0
79 4 30 19 0
79 4 31 24 0
79 4 32 10 0
79 4 33 10 0
79 4 34 28 0
79 4 35 10 0
79 4 36 18 0
79 4 37 13 0
79 4 38 24 0
79 4 39 30 0
79 4 40 23 0
79 4 41 13 40
79 5 14 18 72
79 5 15 14 0
79 5 16 27 0
79 5 17 26 0
79 5 18 41 0
79 5 19 36 0
79 5 20 18 0
79 5 21 28 0
79 5 22 8 0
79 5 23 8 0
79 5 24 16 0
79 5 25 39 0
79 5 26 42 0
79 5 27 18 0
79 5 28 14 0
79 5 29 13 0
79 5 30 26 0
79 5 31 18 0
79 5 32 41 0
79 5 33 14 0
79 5 34 10 0
79 5 35 20 0
79 5 36 29 0
79 5 37 12 0
79 5 38 12 0
79 5 39 5 0
79 5 40 36 40
79 6 15 28 72
79 6 16 29 0
79 6 17 23 0
79 6 18 12 0
79 6 19 1 0
79 6 20 4 0
79 6 21 21 0
79 6 22 33 0
79 6 23 20 0
79 6 24 13 0
79 6 25 41 0
79 6 26 11 0
79 6 27 27 0
79 6 28 18 0
79 6 29 7 0
79 6 30 42 0
79 6 31 7 0
79 6 32 6 0
79 6 33 10 0
79 6 34 21 0
79 6 35 22 0
79 6 36 4 0
79 6 37 18 0
79 6 38 23 0
79 6 39 34 40
79 7 16 7 72
79 7 17 18 0
79 7 18 9 0
79 7 19 38 0
79 7 20 42 0
79 7 21 4 0
79 7 22 28 0
79 7 23 3 0
79 7 24 36 0
79 7 25 13 0
79 7 26 36 0
79 7 27 0 0
79 7 28 37 0
79 7 29 13 0
79 7 30 20 0
79 7 31 17 0
79 7 32 35 0
79 7 33 1 0
79 7 34 36 0
79 7 35 22 0
79 7 36 37 0
79 7 37 13 0
79 7 38 7 40
79 8 17 23 76
79 8 18 29 8
79 8 19 5 0
79 8 20 11 0
79 8 21 28 0
79 8 22 4 0
79 8 23 22 0
79 8 24 25 0
79 8 25 21 0
79 8 26 33 0
79 8 27 35 0
79 8 28 3 0
79 8 29 25 0
79 8 30 25 0
79 8 31 42 0
79 8 32 22 0
79 8 33 27 0
79 8 34 36 0
79 8 35 12 0
79 8 36 16 8
79 8 37 35 44
79 9 19 42 76
79 9 20 0 8
79 9 21 5 8
79 9 22 10 0
79 9 23 25 0
79 9 24 40 0
79 9 25 13 0
79 9 26 18 0
79 9 27 38 0
79 9 28 38 0
79 9 29 29 0
79 9 30 28 0
79 9 31 7 0
79 9 32 29 0
79 9 33 19 8
79 9 34 18 8
79 9 35 13 44
79 10 22 41 72
79 10 23 21 8
79 10 24 1 8
79 10 25 0 8
79 10 26 5 8
79 10 27 14 8
79 10 28 9 8
79 10 29 24 8
79 10 30 38 8
79 10 31 23 8
79 10 32 0 40
80 0 10 1 80
80 0 11 22 16
80 0 12 4 16
80 0 13 22 16
80 0 14 36 16
80 0 15 36 16
80 0 16 35 16
80 0 17 18 16
80 0 18 35 16
80 0 19 38 16
80 0 20 19 16
80 0 21 18 16
80 0 22 31 16
80 0 23 12 16
80 0 24 4 16
80 0 25 2 16
80 0 26 3 16
80 0 27 27 16
80 0 28 42 16
80 0 29 21 16
80 0 30 0 16
80 0 31 4 16
80 0 32 0 16
80 0 33 40 16
80 0 34 14 16
80 0 35 14 16
80 0 36 31 16
80 0 37 10 16
80 0 38 36 16
80 0 39 31 16
80 0 40 27 16
80 0 41 13 16
80 0 42 17 16
80 0 43 3 16
80 0 44 11 48
80 1 10 41 76
80 1 11 30 0
80 1 12 1 0
80 1 13 4 0
80 1 14 39 0
80 1 15 35 0
80 1 16 19 0
80 1 17 31 0
80 1 18 23 0
80 1 19 4 0
80 1 20 30 0
80 1 21 3 0
80 1 22 18 0
80 1 23 15 0
80 1 24 40 0
80 1 25 26 0
80 1 26 15 0
80 1 27 9 0
80 1 28 3 0
80 1 29 17 0
80 1 30 2 0
80 1 31 19 0
80 1 32 10 0
80 1 33 23 0
80 1 34 39 0
80 1 35 22 0
80 1 36 33 0
80 1 37 29 0
80 1 38 42 0
80 1 39 10 0
80 1 40 15 0
80 1 41 2 0
80 1 42 33 0
80 1 43 18 0
80 1 44 5 44
80 2 11 32 72
80 2 12 10 0
80 2 13 27 0
80 2 14 20 0
80 2 15 40 0
80 2 16 38 0
80 2 17 3 0
80 2 18 10 0
80 2 19 33 0
80 2 20 30 0
80 2 21 12 0
80 2 22 41 0
80 2 23 31 0
80 2 24 7 0
80 2 25 4 0
80 2 26 1 0
80 2 27 10 0
80 2 28 14 0
80 2 29 1 0
80 2 30 18 0
80 2 31 40 0
80 2 32 4 0
80 2 33 12 0
80 2 34 16 0
80 2 35 23 0
80 2 36 41 0
80 2 37 41 0
80 2 38 15 0
80 2 39 2 0
80 2 40 38 0
80 2 41 10 0
80 2 42 7 0
80 2 43 7 40
80 3 12 25 72
80 3 13 13 0
80 3 14 18 0
80 3 15 32 0
80 3 16 25 0
80 3 17 13 0
80 3 18 39 0
80 3 19 16 0
80 3 20 30 0
80 3 21 17 0
80 3 22 18 0
80 3 23 20 0
80 3 24 40 0
80 3 25 8 0
80 3 26 33 0
80 3 27 32 0
80 3 28 25 0
80 3 29 40 0
80 3 30 34 0
80 3 31 2 0
80 3 32 4 0
80 3 33 35 0
80 3 34 18 0
80 3 35 21 0
80 3 36 22 0
80 3 37 16 0
80 3 38 1 0
80 3 39 19 0
80 3 40 22 0
80 3 41 24 0
80 3 42 16 40
80 4 13 18 64
80 4 14 30 0
80 4 15 25 0
80 4 16 34 0
80 4 17 1 0
80 4 18 28 0
80 4 19 10 0
80 4 20 19 0
80 4 21 33 0
80 4 22 20 0
80 4 23 3 0
80 4 24 10 0
80 4 25 10 0
80 4 26 39 0
80 4 27 2 0
80 4 28 0 0
80 4 29 28 0
80 4 30 5 0
80 4 31 32 0
80 4 32 33 0
80 4 33 22 0
80 4 34 9 0
80 4 35 21 0
80 4 36 25 0
80 4 37 20 0
80 4 38 37 0
80 4 39 8 0
80 4 40 33 0
80 4 41 31 32
80 5 13 5 76
80 5 14 20 0
80 5 15 22 0
80 5 16 13 0
80 5 17 1 0
80 5 18 16 0
80 5 19 33 0
80 5 20 13 0
80 5 21 10 0
80 5 22 2 0
80 5 23 20 0
80 5 24 4 0
80 5 25 37 0
80 5 26 5 0
80 5 27 0 0
80 5 28 28 0
80 5 29 0 0
80 5 30 9 0
80 5 31 4 0
80 5 32 12 0
80 5 33 36 0
80 5 34 40 0
80 5 35 25 0
80 5 36 11 0
80 5 37 29 0
80 5 38 10 0
80 5 39 13 0
80 5 40 32 0
80 5 41 37 44
80 6 14 7 76
80 6 15 5 8
80 6 16 8 0
80 6 17 6 0
80 6 18 7 0
80 6 19 7 0
80 6 20 24 0
80 6 21 6 0
80 6 22 18 0
80 6 23 25 0
80 6 24 10 0
80 6 25 16 0
80 6 26 6 0
80 6 27 40 0
80 6 28 17 0
80 6 29 8 0
80 6 30 24 0
80 6 31 22 0
80 6 32 17 0
80 6 33 40 0
80 6 34 37 0
80 6 35 6 0
80 6 36 9 0
80 6 37 11 0
80 6 38 25 0
80 6 39 8 8
80 6 40 10 44
80 7 16 15 72
80 7 17 14 0
80 7 18 42 0
80 7 19 40 0
80 7 20 12 0
80 7 21 20 0
80 7 22 30 0
80 7 23 15 0
80 7 24 26 0
80 7 25 38 0
80 7 26 19 0
80 7 27 13 0
80 7 28 26 0
80 7 29 9 0
80 7 30 1 0
80 7 31 3 0
80 7 32 17 0
80 7 33 8 0
80 7 34 12 0
80 7 35 4 0
80 7 36 42 0
80 7 37 11 0
80 7 38 10 40
80 8 17 1 72
80 8 18 39 8
80 8 19 18 0
80 8 20 27 0
80 8 21 41 0
80 8 22 9 0
80 8 23 10 0
80 8 24 26 0
80 8 25 29 0
80 8 26 33 0
80 8 27 3 0
80 8 28 1 0
80 8 29 39 0
80 8 30 16 0
80 8 31 27 0
80 8 32 38 0
80 8 33 31 0
80 8 34 40 0
80 8 35 26 0
80 8 36 31 8
80 8 37 36 40
80 9 19 13 72
80 9 20 18 8
80 9 21 20 0
80 9 22 3 0
80 9 23 28 0
80 9 24 2 0
80 9 25 33 0
80 9 26 29 0
80 9 27 11 0
80 9 28 34 0
80 9 29 41 0
80 9 30 26 0
80 9 31 18 0
80 9 32 8 0
80 9 33 27 0
80 9 34 21 8
80 9 35 19 40
80 10 21 11 76
80 10 22 28 8
80 10 23 24 8
80 10 24 6 8
80 10 25 1 8
80 10 26 16 8
80 10 27 24 8
80 10 28 17 8
80 10 29 38 8
80 10 30 21 8
80 10 31 27 8
80 10 32 4 8
80 10 33 22 44
81 0 10 7 80
81 0 11 33 16
81 0 12 10 16
81 0 13 4 16
81 0 14 18 16
81 0 15 15 16
81 0 16 28 16
81 0 17 1 16
81 0 18 9 16
81 0 19 42 16
81 0 20 1 16
81 0 21 11 16
81 0 22 5 16
81 0 23 1 16
81 0 24 21 16
81 0 25 31 16
81 0 26 34 16
81 0 27 39 16
81 0 28 16 16
81 0 29 4 16
81 0 30 27 16
81 0 31 0 16
81 0 32 18 16
81 0 33 29 16
81 0 34 9 16
81 0 35 6 16
81 0 36 1 16
81 0 37 8 16
81 0 38 27 16
81 0 39 40 16
81 0 40 7 16
81 0 41 27 16
81 0 42 16 16
81 0 43 41 16
81 0 44 31 48
81 1 10 25 72
81 1 11 0 0
81 1 12 13 0
81 1 13 21 0
81 1 14 16 0
81 1 15 41 0
81 1 16 9 0
81 1 17 42 0
81 1 18 3 0
81 1 19 10 0
81 1 20 36 0
81 1 21 7 0
81 1 22 1 0
81 1 23 5 0
81 1 24 1 0
81 1 25 30 0
81 1 26 24 0
81 1 27 27 0
81 1 28 11 0
81 1 29 17 0
81 1 30 17 0
81 1 31 12 0
81 1 32 14 0
81 1 33 14 0
81 1 34 25 0
81 1 35 18 0
81 1 36 33 0
81 1 37 3 0
81 1 38 5 0
81 1 39 4 0
81 1 40 27 0
81 1 41 40 0
81 1 42 42 0
81 1 43 3 0
81 1 44 10 40
81 2 11 0 72
81 2 12 32 0
81 2 13 18 0
81 2 14 17 0
81 2 15 8 0
81 2 16 35 0
81 2 17 34 0
81 2 18 26 0
81 2 19 2 0
81 2 20 24 0
81 2 21 10 0
81 2 22 32 0
81 2 23 11 0
81 2 24 1 0
81 2 25 39 0
81 2 26 16 0
81 2 27 12 0
81 2 28 4 0
81 2 29 5 0
81 2 30 41 0
81 2 31 3 0
81 2 32 33 0
81 2 33 29 0
81 2 34 36 0
81 2 35 17 0
81 2 36 26 0
81 2 37 14 0
81 2 38 21 0
81 2 39 22 0
81 2 40 39 0
81 2 41 10 0
81 2 42 7 0
81 2 43 13 40
81 3 12 20 64
81 3 13 23 0
81 3 14 5 0
81 3 15 35 0
81 3 16 1 0
81 3 17 8 0
81 3 18 6 0
81 3 19 10 0
81 3 20 6 0
81 3 21 18 0
81 3 22 12 0
81 3 23 35 0
81 3 24 11 0
81 3 25 15 0
81 3 26 13 0
81 3 27 17 0
81 3 28 5 0
81 3 29 2 0
81 3 30 17 0
81 3 31 12 0
81 3 32 10 0
81 3 33 12 0
81 3 34 12 0
81 3 35 40 0
81 3 36 22 0
81 3 37 3 0
81 3 38 16 0
81 3 39 36 0
81 3 40 28 0
81 3 41 37 0
81 3 42 10 32
81 4 12 19 76
81 4 13 3 0
81 4 14 10 0
81 4 15 25 0
81 4 16 39 0
81 4 17 12 0
81 4 18 22 0
81 4 19 13 0
81 4 20 25 0
81 4 21 22 0
81 4 22 10 0
81 4 23 7 0
81 4 24 0 0
81 4 25 3 0
81 4 26 37 0
81 4 27 2 0
81 4 28 17 0
81 4 29 10 0
81 4 30 40 0
81 4 31 16 0
81 4 32 22 0
81 4 33 27 0
81 4 34 16 0
81 4 35 14 0
81 4 36 39 0
81 4 37 5 0
81 4 38 41 0
81 4 39 42 0
81 4 40 42 0
81 4 41 24 0
81 4 42 27 44
81 5 13 22 72
81 5 14 25 0
81 5 15 28 0
81 5 16 9 0
81 5 17 41 0
81 5 18 6 0
81 5 19 33 0
81 5 20 27 0
81 5 21 27 0
81 5 22 14 0
81 5 23 20 0
81 5 24 13 0
81 5 25 5 0
81 5 26 27 0
81 5 27 14 0
81 5 28 25 0
81 5 29 2 0
81 5 30 2 0
81 5 31 16 0
81 5 32 29 0
81 5 33 13 0
81 5 34 36 0
81 5 35 7 0
81 5 36 18 0
81 5 37 32 0
81 5 38 16 0
81 5 39 19 0
81 5 40 29 0
81 5 41 13 40
81 6 14 12 72
81 6 15 14 0
81 6 16 10 0
81 6 17 9 0
81 6 18 28 0
81 6 19 31 0
81 6 20 14 0
81 6 21 22 0
81 6 22 16 0
81 6 23 3 0
81 6 24 14 0
81 6 25 0 0
81 6 26 38 0
81 6 27 28 0
81 6 28 16 0
81 6 29 7 0
81 6 30 32 0
81 6 31 11 0
81 6 32 10 0
81 6 33 36 0
81 6 34 13 0
81 6 35 7 0
81 6 36 0 0
81 6 37 21 0
81 6 38 7 0
81 6 39 32 0
81 6 40 31 40
81 7 15 31 76
81 7 16 2 8
81 7 17 18 0
81 7 18 28 0
81 7 19 20 0
81 7 20 38 0
81 7 21 28 0
81 7 22 18 0
81 7 23 1 0
81 7 24 16 0
81 7 25 32 0
81 7 26 26 0
81 7 27 19 0
81 7 28 24 0
81 7 29 6 0
81 7 30 18 0
81 7 31 32 0
81 7 32 16 0
81 7 33 2 0
81 7 34 11 0
81 7 35 17 0
81 7 36 32 0
81 7 37 16 0
81 7 38 20 8
81 7 39 1 44
81 8 17 40 72
81 8 18 36 8
81 8 19 26 0
81 8 20 10 0
81 8 21 17 0
81 8 22 33 0
81 8 23 8 0
81 8 24 20 0
81 8 25 33 0
81 8 26 2 0
81 8 27 13 0
81 8 28 16 0
81 8 29 23 0
81 8 30 13 0
81 8 31 14 0
81 8 32 29 0
81 8 33 23 0
81 8 34 15 0
81 8 35 29 0
81 8 36 33 8
81 8 37 13 40
81 9 19 39 72
81 9 20 2 8
81 9 21 0 0
81 9 22 23 0
81 9 23 11 0
81 9 24 39 0
81 9 25 40 0
81 9 26 8 0
81 9 27 41 0
81 9 28 1 0
81 9 29 1 0
81 9 30 27 0
81 9 31 9 0
81 9 32 31 0
81 9 33 34 0
81 9 34 30 8
81 9 35 13 40
81 10 21 7 72
81 10 22 22 8
81 10 23 32 8
81 10 24 4 8
81 10 25 14 0
81 10 26 28 0
81 10 27 36 0
81 10 28 15 0
81 10 29 37 0
81 10 30 18 8
81 10 31 0 8
81 10 32 22 8
81 10 33 6 40
81 11 25 5 76
81 11 26 2 12
81 11 27 7 12
81 11 28 20 12
81 11 29 8 44
82 0 10 20 80
82 0 11 4 16
82 0 12 32 16
82 0 13 21 16
82 0 14 31 16
82 0 15 12 16
82 0 16 25 16
82 0 17 18 16
82 0 18 7 16
82 0 19 6 16
82 0 20 3 16
82 0 21 41 16
82 0 22 38 16
82 0 23 33 16
82 0 24 1 16
82 0 25 13 16
82 0 26 17 16
82 0 27 27 16
82 0 28 34 16
82 0 29 4 16
82 0 30 41 16
82 0 31 4 16
82 0 32 4 16
82 0 33 21 16
82 0 34 22 16
82 0 35 1 16
82 0 36 4 16
82 0 37 2 16
82 0 38 4 16
82 0 39 3 16
82 0 40 11 16
82 0 41 9 16
82 0 42 0 16
82 0 43 27 16
82 0 44 16 48
82 1 10 4 72
82 1 11 4 0
82 1 12 13 0
82 1 13 32 0
82 1 14 13 0
82 1 15 16 0
82 1 16 33 0
82 1 17 22 0
82 1 18 1 0
82 1 19 31 0
82 1 20 36 0
82 1 21 26 0
82 1 22 19 0
82 1 23 39 0
82 1 24 39 0
82 1 25 18 0
82 1 26 12 0
82 1 27 18 0
82 1 28 34 0
82 1 29 16 0
82 1 30 1 0
82 1 31 27 0
82 1 32 31 0
82 1 33 29 0
82 1 34 41 0
82 1 35 10 0
82 1 36 16 0
82 1 37 24 0
82 1 38 1 0
82 1 39 22 0
82 1 40 18 0
82 1 41 41 0
82 1 42 15 0
82 1 43 2 0
82 1 44 16 40
82 2 11 32 64
82 2 12 20 0
82 2 13 1 0
82 2 14 23 0
82 2 15 16 0
82 2 16 4 0
82 2 17 23 0
82 2 18 16 0
82 2 19 29 0
82 2 20 1 0
82 2 21 24 0
82 2 22 31 0
82 2 23 10 0
82 2 24 21 0
82 2 25 10 0
82 2 26 28 0
82 2 27 7 0
82 2 28 12 0
82 2 29 4 0
82 2 30 42 0
82 2 31 20 0
82 2 32 21 0
82 2 33 1 0
82 2 34 10 0
82 2 35 8 0
82 2 36 11 0
82 2 37 9 0
82 2 38 25 0
82 2 39 7 0
82 2 40 2 0
82 2 41 16 0
82 2 42 27 0
82 2 43 27 32
82 3 11 6 76
82 3 12 7 0
82 3 13 32 0
82 3 14 31 0
82 3 15 11 0
82 3 16 25 0
82 3 17 7 0
82 3 18 14 0
82 3 19 16 0
82 3 20 38 0
82 3 21 0 0
82 3 22 30 0
82 3 23 42 0
82 3 24 37 0
82 3 25 28 0
82 3 26 34 0
82 3 27 24 0
82 3 28 34 0
82 3 29 4 0
82 3 30 21 0
82 3 31 18 0
82 3 32 12 0
82 3 33 27 0
82 3 34 5 0
82 3 35 13 0
82 3 36 39 0
82 3 37 5 0
82 3 38 10 0
82 3 39 10 0
82 3 40 13 0
82 3 41 13 0
82 3 42 22 0
82 3 43 22 44
82 4 12 9 72
82 4 13 39 0
82 4 14 11 0
82 4 15 30 0
82 4 16 14 0
82 4 17 6 0
82 4 18 41 0
82 4 19 8 0
82 4 20 28 0
82 4 21 38 0
82 4 22 35 0
82 4 23 32 0
82 4 24 13 0
82 4 25 23 0
82 4 26 17 0
82 4 27 19 0
82 4 28 18 0
82 4 29 1 0
82 4 30 9 0
82 4 31 16 0
82 4 32 7 0
82 4 33 7 0
82 4 34 11 0
82 4 35 17 0
82 4 36 2 0
82 4 37 28 0
82 4 38 40 0
82 4 39 2 0
82 4 40 1 0
82 4 41 10 0
82 4 42 4 40
82 5 13 40 72
82 5 14 1 0
82 5 15 29 0
82 5 16 24 0
82 5 17 7 0
82 5 18 4 0
82 5 19 13 0
82 5 20 10 0
82 5 21 28 0
82 5 22 27 0
82 5 23 11 0
82 5 24 23 0
82 5 25 13 0
82 5 26 35 0
82 5 27 3 0
82 5 28 30 0
82 5 29 4 0
82 5 30 39 0
82 5 31 18 0
82 5 32 9 0
82 5 33 20 0
82 5 34 28 0
82 5 35 4 0
82 5 36 19 0
82 5 37 27 0
82 5 38 32 0
82 5 39 6 0
82 5 40 24 0
82 5 41 16 40
82 6 14 20 72
82 6 15 35 0
82 6 16 37 0
82 6 17 11 0
82 6 18 19 0
82 6 19 10 0
82 6 20 9 0
82 6 21 17 0
82 6 22 40 0
82 6 23 24 0
82 6 24 28 0
82 6 25 12 0
82 6 26 9 0
82 6 27 11 0
82 6 28 31 0
82 6 29 41 0
82 6 30 23 0
82 6 31 40 0
82 6 32 7 0
82 6 33 11 0
82 6 34 10 0
82 6 35 1 0
82 6 36 11 0
82 6 37 16 0
82 6 38 4 0
82 6 39 8 0
82 6 40 7 40
82 7 15 2 72
82 7 16 30 8
82 7 17 17 0
82 7 18 35 0
82 7 19 17 0
82 7 20 19 0
82 7 21 5 0
82 7 22 9 0
82 7 23 32 0
82 7 24 0 0
82 7 25 26 0
82 7 26 1 0
82 7 27 38 0
82 7 28 41 0
82 7 29 18 0
82 7 30 17 0
82 7 31 27 0
82 7 32 39 0
82 7 33 14 0
82 7 34 37 0
82 7 35 35 0
82 7 36 6 0
82 7 37 25 0
82 7 38 23 8
82 7 39 35 40
82 8 17 6 72
82 8 18 12 0
82 8 19 1 0
82 8 20 22 0
82 8 21 34 0
82 8 22 25 0
82 8 23 42 0
82 8 24 11 0
82 8 25 40 0
82 8 26 7 0
82 8 27 3 0
82 8 28 20 0
82 8 29 29 0
82 8 30 4 0
82 8 31 20 0
82 8 32 26 0
82 8 33 37 0
82 8 34 4 0
82 8 35 18 0
82 8 36 22 0
82 8 37 28 40
82 9 18 8 76
82 9 19 8 8
82 9 20 6 8
82 9 21 38 0
82 9 22 18 0
82 9 23 13 0
82 9 24 7 0
82 9 25 24 0
82 9 26 16 0
82 9 27 3 0
82 9 28 10 0
82 9 29 10 0
82 9 30 8 0
82 9 31 12 0
82 9 32 25 0
82 9 33 10 0
82 9 34 7 8
82 9 35 6 8
82 9 36 4 44
82 10 21 27 72
82 10 22 33 8
82 10 23 30 8
82 10 24 13 0
82 10 25 38 0
82 10 26 11 0
82 10 27 37 0
82 10 28 13 0
82 10 29 12 0
82 10 30 7 0
82 10 31 39 8
82 10 32 17 8
82 10 33 10 40
82 11 24 16 76
82 11 25 12 8
82 11 26 2 8
82 11 27 21 8
82 11 28 7 8
82 11 29 16 8
82 11 30 23 44
83 0 9 27 92
83 0 10 16 16
83 0 11 15 16
83 0 12 32 16
83 0 13 36 16
83 0 14 3 16
83 0 15 27 16
83 0 16 16 16
83 0 17 23 16
83 0 18 10 16
83 0 19 3 16
83 0 20 30 16
83 0 21 33 16
83 0 22 41 16
83 0 23 6 16
83 0 24 40 16
83 0 25 26 16
83 0 26 36 16
83 0 27 5 16
83 0 28 36 16
83 0 29 26 16
83 0 30 38 16
83 0 31 29 16
83 0 32 18 16
83 0 33 16 16
83 0 34 18 16
83 0 35 13 16
83 0 36 22 16
83 0 37 18 16
83 0 38 1 16
83 0 39 19 16
83 0 40 37 16
83 0 41 34 16
83 0 42 7 16
83 0 43 23 16
83 0 44 33 16
83 0 45 7 60
83 1 10 33 72
83 1 11 1 0
83 1 12 3 0
83 1 13 28 0
83 1 14 16 0
83 1 15 32 0
83 1 16 18 0
83 1 17 4 0
83 1 18 7 0
83 1 19 13 0
83 1 20 18 0
83 1 21 31 0
83 1 22 1 0
83 1 23 1 0
83 1 24 30 0
83 1 25 10 0
83 1 26 4 0
83 1 27 3 0
83 1 28 5 0
83 1 29 7 0
83 1 30 25 0
83 1 31 23 0
83 1 32 7 0
83 1 33 14 0
83 1 34 31 0
83 1 35 36 0
83 1 36 8 0
83 1 37 25 0
83 1 38 27 0
83 1 39 29 0
83 1 40 15 0
83 1 41 30 0
83 1 42 38 0
83 1 43 6 0
83 1 44 13 40
83 2 11 4 64
83 2 12 3 0
83 2 13 36 0
83 2 14 19 0
83 2 15 41 0
83 2 16 19 0
83 2 17 18 0
83 2 18 1 0
83 2 19 10 0
83 2 20 35 0
83 2 21 10 0
83 2 22 23 0
83 2 23 28 0
83 2 24 35 0
83 2 25 19 0
83 2 26 19 0
83 2 27 12 0
83 2 28 16 0
83 2 29 36 0
83 2 30 4 0
83 2 31 29 0
83 2 32 4 0
83 2 33 2 0
83 2 34 3 0
83 2 35 8 0
83 2 36 6 0
83 2 37 16 0
83 2 38 42 0
83 2 39 26 0
83 2 40 25 0
83 2 41 10 0
83 2 42 4 0
83 2 43 4 32
83 3 11 21 72
83 3 12 34 0
83 3 13 29 0
83 3 14 16 0
83 3 15 8 0
83 3 16 20 0
83 3 17 1 0
83 3 18 18 0
83 3 19 14 0
83 3 20 5 0
83 3 21 4 0
83 3 22 13 0
83 3 23 11 0
83 3 24 25 0
83 3 25 18 0
83 3 26 2 0
83 3 27 25 0
83 3 28 1 0
83 3 29 7 0
83 3 30 32 0
83 3 31 40 0
83 3 32 11 0
83 3 33 13 0
83 3 34 14 0
83 3 35 21 0
83 3 36 19 0
83 3 37 27 0
83 3 38 14 0
83 3 39 38 0
83 3 40 8 0
83 3 41 29 0
83 3 42 7 0
83 3 43 30 40
83 4 12 29 72
83 4 13 26 0
83 4 14 18 0
83 4 15 10 0
83 4 16 25 0
83 4 17 35 0
83 4 18 14 0
83 4 19 11 0
83 4 20 24 0
83 4 21 31 0
83 4 22 36 0
83 4 23 31 0
83 4 24 4 0
83 4 25 13 0
83 4 26 7 0
83 4 27 9 0
83 4 28 9 0
83 4 29 11 0
83 4 30 0 0
83 4 31 40 0
83 4 32 33 0
83 4 33 35 0
83 4 34 41 0
83 4 35 5 0
83 4 36 16 0
83 4 37 4 0
83 4 38 14 0
83 4 39 19 0
83 4 40 27 0
83 4 41 29 0
83 4 42 16 40
83 5 13 18 72
83 5 14 29 0
83 5 15 6 0
83 5 16 18 0
83 5 17 22 0
83 5 18 30 0
83 5 19 26 0
83 5 20 2 0
83 5 21 26 0
83 5 22 26 0
83 5 23 11 0
83 5 24 26 0
83 5 25 20 0
83 5 26 7 0
83 5 27 38 0
83 5 28 31 0
83 5 29 20 0
83 5 30 18 0
83 5 31 23 0
83 5 32 12 0
83 5 33 14 0
83 5 34 1 0
83 5 35 6 0
83 5 36 1 0
83 5 37 20 0
83 5 38 8 0
83 5 39 16 0
83 5 40 12 0
83 5 41 13 40
83 6 14 31 72
83 6 15 18 0
83 6 16 13 0
83 6 17 32 0
83 6 18 16 0
83 6 19 16 0
83 6 20 26 0
83 6 21 18 0
83 6 22 6 0
83 6 23 18 0
83 6 24 33 0
83 6 25 42 0
83 6 26 5 0
83 6 27 16 0
83 6 28 41 0
83 6 29 18 0
83 6 30 30 0
83 6 31 35 0
83 6 32 10 0
83 6 33 37 0
83 6 34 17 0
83 6 35 30 0
83 6 36 24 0
83 6 37 12 0
83 6 38 18 0
83 6 39 36 0
83 6 40 18 40
83 7 15 28 72
83 7 16 37 0
83 7 17 32 0
83 7 18 3 0
83 7 19 1 0
83 7 20 29 0
83 7 21 32 0
83 7 22 24 0
83 7 23 36 0
83 7 24 33 0
83 7 25 9 0
83 7 26 25 0
83 7 27 29 0
83 7 28 18 0
83 7 29 8 0
83 7 30 38 0
83 7 31 39 0
83 7 32 31 0
83 7 33 35 0
83 7 34 13 0
83 7 35 40 0
83 7 36 1 0
83 7 37 10 0
83 7 38 42 0
83 7 39 10 40
83 8 16 31 76
83 8 17 5 8
83 8 18 35 0
83 8 19 6 0
83 8 20 13 0
83 8 21 12 0
83 8 22 32 0
83 8 23 29 0
83 8 24 12 0
83 8 25 39 0
83 8 26 14 0
83 8 27 20 0
83 8 28 14 0
83 8 29 6 0
83 8 30 16 0
83 8 31 33 0
83 8 32 16 0
83 8 33 30 0
83 8 34 42 0
83 8 35 20 0
83 8 36 29 0
83 8 37 7 8
83 8 38 27 44
83 9 18 10 72
83 9 19 10 8
83 9 20 20 0
83 9 21 13 0
83 9 22 18 0
83 9 23 0 0
83 9 24 30 0
83 9 25 0 0
83 9 26 40 0
83 9 27 7 0
83 9 28 24 0
83 9 29 15 0
83 9 30 6 0
83 9 31 38 0
83 9 32 31 0
83 9 33 13 0
83 9 34 21 0
83 9 35 5 8
83 9 36 29 40
83 10 20 25 76
83 10 21 24 8
83 10 22 42 8
83 10 23 28 8
83 10 24 6 0
83 10 25 24 0
83 10 26 34 0
83 10 27 9 0
83 10 28 34 0
83 10 29 16 0
83 10 30 27 0
83 10 31 33 8
83 10 32 20 8
83 10 33 33 8
83 10 34 28 44
83 11 24 3 72
83 11 25 1 8
83 11 26 24 8
83 11 27 34 8
83 11 28 9 8
83 11 29 10 8
83 11 30 5 40
84 0 9 4 88
84 0 10 14 16
84 0 11 7 16
84 0 12 30 16
84 0 13 13 16
84 0 14 22 16
84 0 15 34 16
84 0 16 2 16
84 0 17 11 16
84 0 18 20 16
84 0 19 33 16
84 0 20 37 16
84 0 21 24 16
84 0 22 6 16
84 0 23 4 16
84 0 24 31 16
84 0 25 3 16
84 0 26 37 16
84 0 27 13 16
84 0 28 32 16
84 0 29 21 16
84 0 30 16 16
84 0 31 4 16
84 0 32 35 16
84 0 33 38 16
84 0 34 16 16
84 0 35 5 16
84 0 36 33 16
84 0 37 9 16
84 0 38 26 16
84 0 39 20 16
84 0 40 10 16
84 0 41 34 16
84 0 42 18 16
84 0 43 21 16
84 0 44 6 16
84 0 45 10 56
84 1 10 30 64
84 1 11 7 0
84 1 12 17 0
84 1 13 2 0
84 1 14 10 0
84 1 15 37 0
84 1 16 17 0
84 1 17 34 0
84 1 18 21 0
84 1 19 26 0
84 1 20 20 0
84 1 21 1 0
84 1 22 30 0
84 1 23 17 0
84 1 24 5 0
84 1 25 10 0
84 1 26 11 0
84 1 27 5 0
84 1 28 26 0
84 1 29 1 0
84 1 30 7 0
84 1 31 16 0
84 1 32 38 0
84 1 33 33 0
84 1 34 13 0
84 1 35 13 0
84 1 36 32 0
84 1 37 30 0
84 1 38 40 0
84 1 39 26 0
84 1 40 33 0
84 1 41 4 0
84 1 42 12 0
84 1 43 9 0
84 1 44 16 32
84 2 10 21 76
84 2 11 7 0
84 2 12 15 0
84 2 13 16 0
84 2 14 5 0
84 2 15 1 0
84 2 16 16 0
84 2 17 30 0
84 2 18 18 0
84 2 19 5 0
84 2 20 37 0
84 2 21 25 0
84 2 22 30 0
84 2 23 19 0
84 2 24 15 0
84 2 25 18 0
84 2 26 6 0
84 2 27 0 0
84 2 28 8 0
84 2 29 19 0
84 2 30 21 0
84 2 31 37 0
84 2 32 10 0
84 2 33 35 0
84 2 34 36 0
84 2 35 30 0
84 2 36 31 0
84 2 37 17 0
84 2 38 18 0
84 2 39 25 0
84 2 40 26 0
84 2 41 40 0
84 2 42 7 0
84 2 43 1 0
84 2 44 18 44
84 3 11 22 72
84 3 12 37 0
84 3 13 19 0
84 3 14 1 0
84 3 15 27 0
84 3 16 42 0
84 3 17 0 0
84 3 18 9 0
84 3 19 16 0
84 3 20 17 0
84 3 21 39 0
84 3 22 28 0
84 3 23 33 0
84 3 24 7 0
84 3 25 2 0
84 3 26 7 0
84 3 27 42 0
84 3 28 24 0
84 3 29 7 0
84 3 30 10 0
84 3 31 1 0
84 3 32 37 0
84 3 33 7 0
84 3 34 33 0
84 3 35 12 0
84 3 36 13 0
84 3 37 1 0
84 3 38 41 0
84 3 39 4 0
84 3 40 13 0
84 3 41 13 0
84 3 42 18 0
84 3 43 29 40
84 4 12 23 72
84 4 13 26 0
84 4 14 11 0
84 4 15 25 0
84 4 16 16 0
84 4 17 37 0
84 4 18 36 0
84 4 19 29 0
84 4 20 29 0
84 4 21 42 0
84 4 22 0 0
84 4 23 38 0
84 4 24 1 0
84 4 25 16 0
84 4 26 29 0
84 4 27 27 0
84 4 28 7 0
84 4 29 23 0
84 4 30 25 0
84 4 31 30 0
84 4 32 5 0
84 4 33 38 0
84 4 34 39 0
84 4 35 33 0
84 4 36 34 0
84 4 37 23 0
84 4 38 17 0
84 4 39 18 0
84 4 40 25 0
84 4 41 40 0
84 4 42 10 40
84 5 13 22 72
84 5 14 27 0
84 5 15 4 0
84 5 16 18 0
84 5 17 32 0
84 5 18 32 0
84 5 19 36 0
84 5 20 1 0
84 5 21 26 0
84 5 22 13 0
84 5 23 31 0
84 5 24 6 0
84 5 25 10 0
84 5 26 23 0
84 5 27 16 0
84 5 28 26 0
84 5 29 1 0
84 5 30 22 0
84 5 31 10 0
84 5 32 39 0
84 5 33 28 0
84 5 34 3 0
84 5 35 37 0
84 5 36 7 0
84 5 37 1 0
84 5 38 32 0
84 5 39 11 0
84 5 40 15 0
84 5 41 4 40
84 6 14 8 72
84 6 15 18 0
84 6 16 35 0
84 6 17 38 0
84 6 18 15 0
84 6 19 36 0
84 6 20 12 0
84 6 21 19 0
