Qubicle Exchange Format
Version 0.2
www.minddesk.com
256 256 256
38
0.000000 0.521569 0.000000
0.000000 0.525490 0.000000
0.000000 0.529412 0.000000
0.000000 0.533333 0.000000
0.000000 0.537255 0.000000
0.000000 0.541176 0.000000
0.000000 0.545098 0.000000
0.000000 0.549020 0.000000
0.000000 0.552941 0.000000
0.000000 0.556863 0.000000
0.000000 0.560784 0.000000
0.000000 0.564706 0.000000
0.000000 0.568627 0.000000
0.000000 0.572549 0.000000
0.000000 0.576471 0.000000
0.003922 0.580392 0.003922
0.007843 0.580392 0.007843
0.011765 0.584314 0.011765
0.015686 0.584314 0.015686
0.019608 0.584314 0.019608
0.023529 0.588235 0.023529
0.027451 0.588235 0.027451
0.031373 0.592157 0.031373
0.035294 0.592157 0.035294
0.039216 0.596078 0.039216
0.043137 0.596078 0.043137
0.047059 0.596078 0.047059
0.050980 0.600000 0.050980
0.054902 0.600000 0.054902
0.058824 0.603922 0.058824
0.062745 0.603922 0.062745
0.066667 0.603922 0.066667
0.070588 0.607843 0.070588
0.074510 0.607843 0.074510
0.078431 0.611765 0.078431
0.082353 0.611765 0.082353
0.086275 0.615686 0.086275
0.090196 0.615686 0.090196
0 0 0 9 84
0 0 1 3 20
0 0 2 9 20
0 0 3 10 20
0 0 4 10 20
0 0 5 5 20
0 0 6 0 20
0 0 7 4 20
0 0 8 27 20
0 0 9 34 20
0 0 10 27 20
0 0 11 35 20
0 0 12 36 20
0 0 13 8 20
0 0 14 6 20
0 0 15 19 20
0 0 16 8 20
0 0 17 37 20
0 0 18 31 20
0 0 19 12 20
0 0 20 31 20
0 0 21 4 20
0 0 22 29 20
0 0 23 27 20
0 0 24 5 20
0 0 25 0 20
0 0 26 37 20
0 0 27 19 20
0 0 28 11 20
0 0 29 15 20
0 0 30 16 20
0 0 31 24 20
0 0 32 5 20
0 0 33 14 20
0 0 34 7 20
0 0 35 26 20
0 0 36 23 20
0 0 37 6 20
0 0 38 22 20
0 0 39 6 20
0 0 40 22 20
0 0 41 34 20
0 0 42 18 20
0 0 43 0 20
0 0 44 2 20
0 0 45 35 20
0 0 46 32 20
0 0 47 6 20
0 0 48 1 20
0 0 49 13 20
0 0 50 7 20
0 0 51 12 20
0 0 52 34 20
0 0 53 4 20
0 0 54 6 20
0 0 55 27 20
0 0 56 17 20
0 0 57 14 20
0 0 58 33 20
0 0 59 27 20
0 0 60 25 20
0 0 61 5 20
0 0 62 7 20
0 0 63 14 20
0 0 64 27 20
0 0 65 23 20
0 0 66 7 20
0 0 67 31 20
0 0 68 18 20
0 0 69 24 20
0 0 70 9 20
0 0 71 14 20
0 0 72 30 20
0 0 73 13 20
0 0 74 9 20
0 0 75 24 20
0 0 76 7 20
0 0 77 26 20
0 0 78 2 20
0 0 79 6 20
0 0 80 13 20
0 0 81 8 20
0 0 82 22 20
0 0 83 35 20
0 0 84 6 20
0 0 85 30 20
0 0 86 17 20
0 0 87 5 20
0 0 88 32 20
0 0 89 30 20
0 0 90 8 20
0 0 91 36 20
0 0 92 14 20
0 0 93 5 20
0 0 94 34 20
0 0 95 8 20
0 0 96 18 20
0 0 97 32 20
0 0 98 14 20
0 0 99 16 20
0 0 100 31 20
0 0 101 1 20
0 0 102 12 20
0 0 103 5 20
0 0 104 29 20
0 0 105 32 20
0 0 106 31 20
0 0 107 12 20
0 0 108 15 20
0 0 109 8 20
0 0 110 15 20
0 0 111 9 20
0 0 112 13 20
0 0 113 14 20
0 0 114 11 20
0 0 115 34 20
0 0 116 17 20
0 0 117 21 20
0 0 118 33 20
0 0 119 6 20
0 0 120 30 20
0 0 121 22 20
0 0 122 2 20
0 0 123 20 20
0 0 124 11 20
0 0 125 20 20
0 0 126 5 20
0 0 127 16 20
0 0 128 1 20
0 0 129 12 20
0 0 130 37 20
0 0 131 20 20
0 0 132 10 20
0 0 133 32 20
0 0 134 10 20
0 0 135 19 20
0 0 136 29 20
0 0 137 5 20
0 0 138 21 20
0 0 139 10 20
0 0 140 1 20
0 0 141 13 20
0 0 142 14 20
0 0 143 10 20
0 0 144 21 20
0 0 145 14 20
0 0 146 12 20
0 0 147 5 20
0 0 148 13 20
0 0 149 28 20
0 0 150 13 20
0 0 151 12 20
0 0 152 23 20
0 0 153 2 20
0 0 154 14 20
0 0 155 36 20
0 0 156 25 20
0 0 157 11 20
0 0 158 8 20
0 0 159 27 20
0 0 160 17 20
0 0 161 2 20
0 0 162 5 20
0 0 163 14 20
0 0 164 25 20
0 0 165 14 20
0 0 166 8 20
0 0 167 14 20
0 0 168 10 20
0 0 169 24 20
0 0 170 7 20
0 0 171 15 20
0 0 172 3 20
0 0 173 1 20
0 0 174 25 20
0 0 175 16 20
0 0 176 6 20
0 0 177 33 20
0 0 178 8 20
0 0 179 20 20
0 0 180 13 20
0 0 181 4 20
0 0 182 35 20
0 0 183 2 20
0 0 184 30 20
0 0 185 13 20
0 0 186 25 20
0 0 187 22 20
0 0 188 28 20
0 0 189 13 20
0 0 190 20 20
0 0 191 6 20
0 0 192 34 20
0 0 193 23 20
0 0 194 25 20
0 0 195 9 20
0 0 196 11 20
0 0 197 13 20
0 0 198 5 20
0 0 199 11 20
0 0 200 8 20
0 0 201 22 20
0 0 202 4 20
0 0 203 20 20
0 0 204 7 20
0 0 205 13 20
0 0 206 26 20
0 0 207 4 20
0 0 208 4 20
0 0 209 13 20
0 0 210 4 20
0 0 211 35 20
0 0 212 14 20
0 0 213 13 20
0 0 214 20 20
0 0 215 0 20
0 0 216 26 20
0 0 217 10 20
0 0 218 1 20
0 0 219 21 20
0 0 220 30 20
0 0 221 1 20
0 0 222 21 20
0 0 223 14 20
0 0 224 13 20
0 0 225 27 20
0 0 226 16 20
0 0 227 28 20
0 0 228 7 20
0 0 229 8 20
0 0 230 13 20
0 0 231 23 20
0 0 232 10 20
0 0 233 31 20
0 0 234 4 20
0 0 235 31 20
0 0 236 10 20
0 0 237 8 20
0 0 238 8 20
0 0 239 11 20
0 0 240 0 20
0 0 241 4 20
0 0 242 32 20
0 0 243 1 20
0 0 244 10 20
0 0 245 22 20
0 0 246 5 20
0 0 247 10 20
0 0 248 11 20
0 0 249 1 20
0 0 250 13 20
0 0 251 3 20
0 0 252 37 20
0 0 253 14 20
0 0 254 14 20
0 0 255 9 52
0 1 0 0 68
0 1 1 16 4
0 1 2 22 4
0 1 3 4 4
0 1 4 9 4
0 1 5 2 4
0 1 6 16 4
0 1 7 1 4
0 1 8 19 4
0 1 9 9 4
0 1 10 6 4
0 1 11 5 4
0 1 12 9 4
0 1 13 10 4
0 1 14 28 4
0 1 15 29 4
0 1 16 2 4
0 1 17 13 4
0 1 18 5 4
0 1 19 10 4
0 1 20 29 4
0 1 21 18 4
0 1 22 4 4
0 1 23 3 4
0 1 24 1 4
0 1 25 13 4
0 1 26 8 4
0 1 27 16 4
0 1 28 21 4
0 1 29 19 4
0 1 30 32 4
0 1 31 24 4
0 1 32 3 4
0 1 33 28 4
0 1 34 7 4
0 1 35 11 4
0 1 36 4 4
0 1 37 2 4
0 1 38 22 4
0 1 39 8 4
0 1 40 13 4
0 1 41 8 4
0 1 42 37 4
0 1 43 0 4
0 1 44 5 4
0 1 45 11 4
0 1 46 25 4
0 1 47 23 4
0 1 48 14 4
0 1 49 37 4
0 1 50 15 4
0 1 51 1 4
0 1 52 26 4
0 1 53 3 4
0 1 54 29 4
0 1 55 12 4
0 1 56 30 4
0 1 57 27 4
0 1 58 12 4
0 1 59 13 4
0 1 60 5 4
0 1 61 14 4
0 1 62 14 4
0 1 63 14 4
0 1 64 3 4
0 1 65 33 4
0 1 66 36 4
0 1 67 14 4
0 1 68 12 4
0 1 69 14 4
0 1 70 31 4
0 1 71 9 4
0 1 72 21 4
0 1 73 21 4
0 1 74 6 4
0 1 75 8 4
0 1 76 29 4
0 1 77 22 4
0 1 78 11 4
0 1 79 5 4
0 1 80 6 4
0 1 81 8 4
0 1 82 36 4
0 1 83 6 4
0 1 84 35 4
0 1 85 28 4
0 1 86 1 4
0 1 87 35 4
0 1 88 18 4
0 1 89 2 4
0 1 90 1 4
0 1 91 23 4
0 1 92 9 4
0 1 93 12 4
0 1 94 37 4
0 1 95 8 4
0 1 96 30 4
0 1 97 6 4
0 1 98 22 4
0 1 99 34 4
0 1 100 13 4
0 1 101 30 4
0 1 102 18 4
0 1 103 26 4
0 1 104 18 4
0 1 105 0 4
0 1 106 25 4
0 1 107 30 4
0 1 108 21 4
0 1 109 12 4
0 1 110 12 4
0 1 111 11 4
0 1 112 15 4
0 1 113 22 4
0 1 114 1 4
0 1 115 10 4
0 1 116 20 4
0 1 117 18 4
0 1 118 6 4
0 1 119 2 4
0 1 120 34 4
0 1 121 36 4
0 1 122 37 4
0 1 123 15 4
0 1 124 27 4
0 1 125 17 4
0 1 126 9 4
0 1 127 5 4
0 1 128 9 4
0 1 129 32 4
0 1 130 30 4
0 1 131 28 4
0 1 132 12 4
0 1 133 23 4
0 1 134 1 4
0 1 135 1 4
0 1 136 11 4
0 1 137 7 4
0 1 138 10 4
0 1 139 33 4
0 1 140 37 4
0 1 141 12 4
0 1 142 17 4
0 1 143 12 4
0 1 144 30 4
0 1 145 0 4
0 1 146 12 4
0 1 147 0 4
0 1 148 6 4
0 1 149 10 4
0 1 150 36 4
0 1 151 37 4
0 1 152 12 4
0 1 153 37 4
0 1 154 1 4
0 1 155 10 4
0 1 156 4 4
0 1 157 35 4
0 1 158 0 4
0 1 159 34 4
0 1 160 36 4
0 1 161 2 4
0 1 162 13 4
0 1 163 27 4
0 1 164 9 4
0 1 165 14 4
0 1 166 20 4
0 1 167 30 4
0 1 168 37 4
0 1 169 18 4
0 1 170 5 4
0 1 171 13 4
0 1 172 14 4
0 1 173 21 4
0 1 174 17 4
0 1 175 4 4
0 1 176 28 4
0 1 177 30 4
0 1 178 3 4
0 1 179 37 4
0 1 180 30 4
0 1 181 32 4
0 1 182 6 4
0 1 183 31 4
0 1 184 1 4
0 1 185 26 4
0 1 186 29 4
0 1 187 11 4
0 1 188 21 4
0 1 189 10 4
0 1 190 0 4
0 1 191 22 4
0 1 192 33 4
0 1 193 9 4
0 1 194 1 4
0 1 195 15 4
0 1 196 3 4
0 1 197 5 4
0 1 198 14 4
0 1 199 9 4
0 1 200 7 4
0 1 201 31 4
0 1 202 26 4
0 1 203 1 4
0 1 204 12 4
0 1 205 3 4
0 1 206 8 4
0 1 207 22 4
0 1 208 9 4
0 1 209 12 4
0 1 210 23 4
0 1 211 36 4
0 1 212 14 4
0 1 213 34 4
0 1 214 17 4
0 1 215 4 4
0 1 216 11 4
0 1 217 10 4
0 1 218 19 4
0 1 219 5 4
0 1 220 20 4
0 1 221 5 4
0 1 222 30 4
0 1 223 1 4
0 1 224 5 4
0 1 225 14 4
0 1 226 2 4
0 1 227 1 4
0 1 228 35 4
0 1 229 27 4
0 1 230 15 4
0 1 231 28 4
0 1 232 37 4
0 1 233 0 4
0 1 234 17 4
0 1 235 17 4
0 1 236 25 4
0 1 237 1 4
0 1 238 25 4
0 1 239 14 4
0 1 240 29 4
0 1 241 10 4
0 1 242 33 4
0 1 243 6 4
0 1 244 13 4
0 1 245 14 4
0 1 246 1 4
0 1 247 4 4
0 1 248 23 4
0 1 249 19 4
0 1 250 14 4
0 1 251 8 4
0 1 252 4 4
0 1 253 7 4
0 1 254 4 4
0 1 255 23 36
0 2 0 2 68
0 2 1 12 4
0 2 2 32 4
0 2 3 35 4
0 2 4 30 4
0 2 5 1 4
0 2 6 1 4
0 2 7 9 4
0 2 8 18 4
0 2 9 0 4
0 2 10 9 4
0 2 11 1 4
0 2 12 19 4
0 2 13 37 4
0 2 14 30 4
0 2 15 11 4
0 2 16 12 4
0 2 17 30 4
0 2 18 23 4
0 2 19 5 4
0 2 20 9 4
0 2 21 6 4
0 2 22 30 4
0 2 23 19 4
0 2 24 10 4
0 2 25 34 4
0 2 26 0 4
0 2 27 35 4
0 2 28 14 4
0 2 29 12 4
0 2 30 0 4
0 2 31 5 4
0 2 32 8 4
0 2 33 2 4
0 2 34 27 4
0 2 35 6 4
0 2 36 32 4
0 2 37 5 4
0 2 38 1 4
0 2 39 6 4
0 2 40 16 4
0 2 41 16 4
0 2 42 18 4
0 2 43 25 4
0 2 44 18 4
0 2 45 27 4
0 2 46 18 4
0 2 47 31 4
0 2 48 6 4
0 2 49 9 4
0 2 50 1 4
0 2 51 20 4
0 2 52 2 4
0 2 53 9 4
0 2 54 8 4
0 2 55 16 4
0 2 56 14 4
0 2 57 3 4
0 2 58 6 4
0 2 59 36 4
0 2 60 4 4
0 2 61 9 4
0 2 62 30 4
0 2 63 28 4
0 2 64 28 4
0 2 65 13 4
0 2 66 13 4
0 2 67 10 4
0 2 68 14 4
0 2 69 18 4
0 2 70 8 4
0 2 71 33 4
0 2 72 16 4
0 2 73 31 4
0 2 74 14 4
0 2 75 16 4
0 2 76 36 4
0 2 77 37 4
0 2 78 0 4
0 2 79 6 4
0 2 80 6 4
0 2 81 22 4
0 2 82 9 4
0 2 83 24 4
0 2 84 17 4
0 2 85 10 4
0 2 86 21 4
0 2 87 3 4
0 2 88 4 4
0 2 89 30 4
0 2 90 5 4
0 2 91 5 4
0 2 92 33 4
0 2 93 8 4
0 2 94 33 4
0 2 95 36 4
0 2 96 9 4
0 2 97 2 4
0 2 98 4 4
0 2 99 8 4
0 2 100 2 4
0 2 101 34 4
0 2 102 33 4
0 2 103 17 4
0 2 104 16 4
0 2 105 21 4
0 2 106 13 4
0 2 107 6 4
0 2 108 33 4
0 2 109 14 4
0 2 110 9 4
0 2 111 9 4
0 2 112 14 4
0 2 113 30 4
0 2 114 14 4
0 2 115 25 4
0 2 116 34 4
0 2 117 4 4
0 2 118 2 4
0 2 119 22 4
0 2 120 27 4
0 2 121 11 4
0 2 122 33 4
0 2 123 2 4
0 2 124 0 4
0 2 125 8 4
0 2 126 2 4
0 2 127 9 4
0 2 128 30 4
0 2 129 9 4
0 2 130 34 4
0 2 131 25 4
0 2 132 34 4
0 2 133 12 4
0 2 134 29 4
0 2 135 34 4
0 2 136 21 4
0 2 137 32 4
0 2 138 13 4
0 2 139 2 4
0 2 140 30 4
0 2 141 32 4
0 2 142 37 4
0 2 143 35 4
0 2 144 9 4
0 2 145 2 4
0 2 146 28 4
0 2 147 14 4
0 2 148 4 4
0 2 149 25 4
0 2 150 30 4
0 2 151 21 4
0 2 152 33 4
0 2 153 21 4
0 2 154 3 4
0 2 155 2 4
0 2 156 14 4
0 2 157 27 4
0 2 158 26 4
0 2 159 2 4
0 2 160 15 4
0 2 161 16 4
0 2 162 23 4
0 2 163 18 4
0 2 164 13 4
0 2 165 2 4
0 2 166 4 4
0 2 167 25 4
0 2 168 19 4
0 2 169 13 4
0 2 170 31 4
0 2 171 22 4
0 2 172 7 4
0 2 173 5 4
0 2 174 4 4
0 2 175 9 4
0 2 176 0 4
0 2 177 10 4
0 2 178 15 4
0 2 179 1 4
0 2 180 34 4
0 2 181 22 4
0 2 182 33 4
0 2 183 20 4
0 2 184 14 4
0 2 185 12 4
0 2 186 24 4
0 2 187 0 4
0 2 188 16 4
0 2 189 20 4
0 2 190 35 4
0 2 191 29 4
0 2 192 17 4
0 2 193 0 4
0 2 194 9 4
0 2 195 6 4
0 2 196 28 4
0 2 197 1 4
0 2 198 12 4
0 2 199 2 4
0 2 200 6 4
0 2 201 27 4
0 2 202 10 4
0 2 203 5 4
0 2 204 25 4
0 2 205 16 4
0 2 206 31 4
0 2 207 16 4
0 2 208 4 4
0 2 209 37 4
0 2 210 27 4
0 2 211 9 4
0 2 212 24 4
0 2 213 6 4
0 2 214 22 4
0 2 215 18 4
0 2 216 16 4
0 2 217 18 4
0 2 218 16 4
0 2 219 13 4
0 2 220 28 4
0 2 221 20 4
0 2 222 17 4
0 2 223 10 4
0 2 224 2 4
0 2 225 2 4
0 2 226 36 4
0 2 227 1 4
0 2 228 36 4
0 2 229 30 4
0 2 230 10 4
0 2 231 1 4
0 2 232 12 4
0 2 233 2 4
0 2 234 36 4
0 2 235 26 4
0 2 236 16 4
0 2 237 12 4
0 2 238 9 4
0 2 239 31 4
0 2 240 28 4
0 2 241 14 4
0 2 242 24 4
0 2 243 4 4
0 2 244 12 4
0 2 245 22 4
0 2 246 33 4
0 2 247 20 4
0 2 248 12 4
0 2 249 15 4
0 2 250 11 4
0 2 251 14 4
0 2 252 13 4
0 2 253 27 4
0 2 254 2 4
0 2 255 9 36
0 3 0 4 68
0 3 1 13 4
0 3 2 25 4
0 3 3 20 4
0 3 4 13 4
0 3 5 8 4
0 3 6 12 4
0 3 7 12 4
0 3 8 36 4
0 3 9 1 4
0 3 10 15 4
0 3 11 5 4
0 3 12 9 4
0 3 13 32 4
0 3 14 8 4
0 3 15 16 4
0 3 16 31 4
0 3 17 12 4
0 3 18 1 4
0 3 19 31 4
0 3 20 34 4
0 3 21 4 4
0 3 22 30 4
0 3 23 13 4
0 3 24 4 4
0 3 25 12 4
0 3 26 14 4
0 3 27 8 4
0 3 28 14 4
0 3 29 6 4
0 3 30 16 4
0 3 31 1 4
0 3 32 4 4
0 3 33 12 4
0 3 34 21 4
0 3 35 8 4
0 3 36 37 4
0 3 37 13 4
0 3 38 3 4
0 3 39 13 4
0 3 40 3 4
0 3 41 32 4
0 3 42 3 4
0 3 43 12 4
0 3 44 2 4
0 3 45 20 4
0 3 46 32 4
0 3 47 37 4
0 3 48 26 4
0 3 49 5 4
0 3 50 6 4
0 3 51 26 4
0 3 52 2 4
0 3 53 17 4
0 3 54 25 4
0 3 55 31 4
0 3 56 9 4
0 3 57 12 4
0 3 58 14 4
0 3 59 21 4
0 3 60 9 4
0 3 61 20 4
0 3 62 2 4
0 3 63 1 4
0 3 64 9 4
0 3 65 10 4
0 3 66 8 4
0 3 67 19 4
0 3 68 5 4
0 3 69 6 4
0 3 70 24 4
0 3 71 17 4
0 3 72 14 4
0 3 73 37 4
0 3 74 6 4
0 3 75 10 4
0 3 76 12 4
0 3 77 31 4
0 3 78 4 4
0 3 79 1 4
0 3 80 2 4
0 3 81 13 4
0 3 82 16 4
0 3 83 4 4
0 3 84 6 4
0 3 85 23 4
0 3 86 14 4
0 3 87 14 4
0 3 88 36 4
0 3 89 13 4
0 3 90 17 4
0 3 91 26 4
0 3 92 23 4
0 3 93 8 4
0 3 94 13 4
0 3 95 5 4
0 3 96 37 4
0 3 97 21 4
0 3 98 2 4
0 3 99 10 4
0 3 100 28 4
0 3 101 32 4
0 3 102 15 4
0 3 103 25 4
0 3 104 6 4
0 3 105 7 4
0 3 106 14 4
0 3 107 6 4
0 3 108 8 4
0 3 109 14 4
0 3 110 29 4
0 3 111 16 4
0 3 112 12 4
0 3 113 6 4
0 3 114 14 4
0 3 115 37 4
0 3 116 33 4
0 3 117 23 4
0 3 118 10 4
0 3 119 12 4
0 3 120 28 4
0 3 121 31 4
0 3 122 11 4
0 3 123 4 4
0 3 124 22 4
0 3 125 14 4
0 3 126 8 4
0 3 127 11 4
0 3 128 12 4
0 3 129 8 4
0 3 130 14 4
0 3 131 18 4
0 3 132 1 4
0 3 133 1 4
0 3 134 2 4
0 3 135 9 4
0 3 136 24 4
0 3 137 7 4
0 3 138 16 4
0 3 139 4 4
0 3 140 11 4
0 3 141 6 4
0 3 142 21 4
0 3 143 0 4
0 3 144 16 4
0 3 145 16 4
0 3 146 6 4
0 3 147 12 4
0 3 148 5 4
0 3 149 6 4
0 3 150 26 4
0 3 151 6 4
0 3 152 29 4
0 3 153 29 4
0 3 154 12 4
0 3 155 1 4
0 3 156 2 4
0 3 157 7 4
0 3 158 31 4
0 3 159 12 4
0 3 160 30 4
0 3 161 0 4
0 3 162 25 4
0 3 163 16 4
0 3 164 6 4
0 3 165 23 4
0 3 166 14 4
0 3 167 18 4
0 3 168 11 4
0 3 169 8 4
0 3 170 14 4
0 3 171 2 4
0 3 172 15 4
0 3 173 5 4
0 3 174 4 4
0 3 175 14 4
0 3 176 4 4
0 3 177 8 4
0 3 178 29 4
0 3 179 23 4
0 3 180 12 4
0 3 181 9 4
0 3 182 21 4
0 3 183 35 4
0 3 184 26 4
0 3 185 20 4
0 3 186 23 4
0 3 187 17 4
0 3 188 29 4
0 3 189 22 4
0 3 190 37 4
0 3 191 21 4
0 3 192 4 4
0 3 193 26 4
0 3 194 12 4
0 3 195 10 4
0 3 196 36 4
0 3 197 1 4
0 3 198 9 4
0 3 199 1 4
0 3 200 23 4
0 3 201 0 4
0 3 202 11 4
0 3 203 9 4
0 3 204 14 4
0 3 205 14 4
0 3 206 1 4
0 3 207 11 4
0 3 208 19 4
0 3 209 10 4
0 3 210 16 4
0 3 211 12 4
0 3 212 14 4
0 3 213 26 4
0 3 214 8 4
0 3 215 15 4
0 3 216 14 4
0 3 217 7 4
0 3 218 24 4
0 3 219 13 4
0 3 220 33 4
0 3 221 6 4
0 3 222 6 4
0 3 223 6 4
0 3 224 6 4
0 3 225 14 4
0 3 226 14 4
0 3 227 19 4
0 3 228 29 4
0 3 229 20 4
0 3 230 29 4
0 3 231 6 4
0 3 232 14 4
0 3 233 13 4
0 3 234 10 4
0 3 235 34 4
0 3 236 19 4
0 3 237 31 4
0 3 238 26 4
0 3 239 28 4
0 3 240 13 4
0 3 241 26 4
0 3 242 20 4
0 3 243 37 4
0 3 244 34 4
0 3 245 12 4
0 3 246 3 4
0 3 247 10 4
0 3 248 20 4
0 3 249 21 4
0 3 250 14 4
0 3 251 20 4
0 3 252 5 4
0 3 253 15 4
0 3 254 13 4
0 3 255 17 36
0 4 0 16 76
0 4 1 2 12
0 4 2 21 12
0 4 3 19 12
0 4 4 6 12
0 4 5 8 12
0 4 6 6 12
0 4 7 1 12
0 4 8 4 12
0 4 9 10 12
0 4 10 0 12
0 4 11 8 12
0 4 12 12 12
0 4 13 19 12
0 4 14 26 12
0 4 15 15 12
0 4 16 25 12
0 4 17 32 12
0 4 18 10 12
0 4 19 10 12
0 4 20 0 12
0 4 21 22 12
0 4 22 37 12
0 4 23 14 12
0 4 24 12 12
0 4 25 36 12
0 4 26 5 12
0 4 27 8 12
0 4 28 5 12
0 4 29 6 12
0 4 30 24 12
0 4 31 4 12
0 4 32 1 12
0 4 33 36 12
0 4 34 31 12
0 4 35 3 12
0 4 36 20 12
0 4 37 9 12
0 4 38 26 12
0 4 39 3 12
0 4 40 5 12
0 4 41 2 12
0 4 42 4 12
0 4 43 8 12
0 4 44 8 12
0 4 45 1 12
0 4 46 17 12
0 4 47 4 12
0 4 48 14 12
0 4 49 5 12
0 4 50 26 12
0 4 51 4 12
0 4 52 8 12
0 4 53 1 12
0 4 54 30 12
0 4 55 14 12
0 4 56 32 12
0 4 57 22 12
0 4 58 5 12
0 4 59 32 12
0 4 60 21 12
0 4 61 33 12
0 4 62 10 12
0 4 63 21 12
0 4 64 14 12
0 4 65 29 12
0 4 66 0 12
0 4 67 22 12
0 4 68 27 12
0 4 69 34 12
0 4 70 3 12
0 4 71 30 12
0 4 72 14 12
0 4 73 7 12
0 4 74 19 12
0 4 75 20 12
0 4 76 8 12
0 4 77 3 12
0 4 78 22 12
0 4 79 28 12
0 4 80 13 12
0 4 81 30 12
0 4 82 35 12
0 4 83 8 12
0 4 84 12 12
0 4 85 12 12
0 4 86 11 12
0 4 87 23 12
0 4 88 4 12
0 4 89 2 12
0 4 90 32 12
0 4 91 13 12
0 4 92 14 12
0 4 93 6 12
0 4 94 12 12
0 4 95 8 12
0 4 96 35 12
0 4 97 34 12
0 4 98 4 12
0 4 99 14 12
0 4 100 2 12
0 4 101 32 12
0 4 102 8 12
0 4 103 1 12
0 4 104 27 12
0 4 105 4 12
0 4 106 12 12
0 4 107 4 12
0 4 108 32 12
0 4 109 14 12
0 4 110 21 12
0 4 111 6 12
0 4 112 17 12
0 4 113 13 12
0 4 114 12 12
0 4 115 27 12
0 4 116 5 12
0 4 117 14 12
0 4 118 34 12
0 4 119 27 12
0 4 120 7 12
0 4 121 13 12
0 4 122 4 12
0 4 123 13 12
0 4 124 24 12
0 4 125 18 12
0 4 126 6 12
0 4 127 32 12
0 4 128 19 12
0 4 129 3 12
0 4 130 30 12
0 4 131 36 12
0 4 132 34 12
0 4 133 13 12
0 4 134 1 12
0 4 135 35 12
0 4 136 36 12
0 4 137 21 12
0 4 138 9 12
0 4 139 23 12
0 4 140 12 12
0 4 141 19 12
0 4 142 7 12
0 4 143 5 12
0 4 144 10 12
0 4 145 12 12
0 4 146 10 12
0 4 147 22 12
0 4 148 1 12
0 4 149 6 12
0 4 150 12 12
0 4 151 15 12
0 4 152 16 12
0 4 153 33 12
0 4 154 6 12
0 4 155 7 12
0 4 156 23 12
0 4 157 25 12
0 4 158 1 12
0 4 159 29 12
0 4 160 13 12
0 4 161 34 12
0 4 162 17 12
0 4 163 26 12
0 4 164 5 12
0 4 165 13 12
0 4 166 35 12
0 4 167 23 12
0 4 168 16 12
0 4 169 21 12
0 4 170 16 12
0 4 171 23 12
0 4 172 32 12
0 4 173 10 12
0 4 174 27 12
0 4 175 17 12
0 4 176 9 12
0 4 177 22 12
0 4 178 8 12
0 4 179 8 12
0 4 180 13 12
0 4 181 19 12
0 4 182 32 12
0 4 183 2 12
0 4 184 31 12
0 4 185 20 12
0 4 186 27 12
0 4 187 5 12
0 4 188 18 12
0 4 189 19 12
0 4 190 11 12
0 4 191 24 12
0 4 192 27 12
0 4 193 32 12
0 4 194 8 12
0 4 195 6 12
0 4 196 8 12
0 4 197 13 12
0 4 198 18 12
0 4 199 23 12
0 4 200 25 12
0 4 201 35 12
0 4 202 33 12
0 4 203 37 12
0 4 204 35 12
0 4 205 16 12
0 4 206 26 12
0 4 207 30 12
0 4 208 1 12
0 4 209 4 12
0 4 210 12 12
0 4 211 30 12
0 4 212 9 12
0 4 213 6 12
0 4 214 2 12
0 4 215 37 12
0 4 216 31 12
0 4 217 35 12
0 4 218 9 12
0 4 219 2 12
0 4 220 19 12
0 4 221 4 12
0 4 222 23 12
0 4 223 1 12
0 4 224 19 12
0 4 225 8 12
0 4 226 16 12
0 4 227 14 12
0 4 228 31 12
0 4 229 36 12
0 4 230 14 12
0 4 231 11 12
0 4 232 26 12
0 4 233 5 12
0 4 234 15 12
0 4 235 4 12
0 4 236 14 12
0 4 237 13 12
0 4 238 27 12
0 4 239 14 12
0 4 240 9 12
0 4 241 15 12
0 4 242 10 12
0 4 243 12 12
0 4 244 28 12
0 4 245 8 12
0 4 246 6 12
0 4 247 2 12
0 4 248 32 12
0 4 249 18 12
0 4 250 28 12
0 4 251 4 12
0 4 252 18 12
0 4 253 10 12
0 4 254 35 12
0 4 255 35 44
1 0 0 14 80
1 0 1 8 16
1 0 2 28 16
1 0 3 21 16
1 0 4 3 16
1 0 5 36 16
1 0 6 10 16
1 0 7 6 16
1 0 8 12 16
1 0 9 12 16
1 0 10 6 16
1 0 11 26 16
1 0 12 8 16
1 0 13 28 16
1 0 14 3 16
1 0 15 14 16
1 0 16 33 16
1 0 17 1 16
1 0 18 31 16
1 0 19 15 16
1 0 20 18 16
1 0 21 28 16
1 0 22 5 16
1 0 23 4 16
1 0 24 17 16
1 0 25 32 16
1 0 26 12 16
1 0 27 37 16
1 0 28 14 16
1 0 29 34 16
1 0 30 1 16
1 0 31 13 16
1 0 32 21 16
1 0 33 10 16
1 0 34 13 16
1 0 35 9 16
1 0 36 26 16
1 0 37 30 16
1 0 38 14 16
1 0 39 27 16
1 0 40 30 16
1 0 41 8 16
1 0 42 6 16
1 0 43 13 16
1 0 44 32 16
1 0 45 15 16
1 0 46 10 16
1 0 47 32 16
1 0 48 34 16
1 0 49 14 16
1 0 50 2 16
1 0 51 10 16
1 0 52 6 16
1 0 53 0 16
1 0 54 13 16
1 0 55 8 16
1 0 56 19 16
1 0 57 2 16
1 0 58 27 16
1 0 59 8 16
1 0 60 27 16
1 0 61 18 16
1 0 62 15 16
1 0 63 2 16
1 0 64 2 16
1 0 65 29 16
1 0 66 14 16
1 0 67 3 16
1 0 68 4 16
1 0 69 14 16
1 0 70 12 16
1 0 71 1 16
1 0 72 3 16
1 0 73 31 16
1 0 74 16 16
1 0 75 35 16
1 0 76 15 16
1 0 77 34 16
1 0 78 15 16
1 0 79 23 16
1 0 80 14 16
1 0 81 2 16
1 0 82 33 16
1 0 83 31 16
1 0 84 21 16
1 0 85 35 16
1 0 86 13 16
1 0 87 13 16
1 0 88 9 16
1 0 89 19 16
1 0 90 14 16
1 0 91 35 16
1 0 92 4 16
1 0 93 16 16
1 0 94 28 16
1 0 95 34 16
1 0 96 6 16
1 0 97 21 16
1 0 98 12 16
1 0 99 34 16
1 0 100 23 16
1 0 101 24 16
1 0 102 13 16
1 0 103 17 16
1 0 104 25 16
1 0 105 8 16
1 0 106 15 16
1 0 107 0 16
1 0 108 6 16
1 0 109 36 16
1 0 110 8 16
1 0 111 14 16
1 0 112 5 16
1 0 113 16 16
1 0 114 9 16
1 0 115 33 16
1 0 116 4 16
1 0 117 14 16
1 0 118 14 16
1 0 119 16 16
1 0 120 33 16
1 0 121 26 16
1 0 122 20 16
1 0 123 9 16
1 0 124 5 16
1 0 125 3 16
1 0 126 1 16
1 0 127 10 16
1 0 128 34 16
1 0 129 9 16
1 0 130 8 16
1 0 131 12 16
1 0 132 35 16
1 0 133 33 16
1 0 134 17 16
1 0 135 16 16
1 0 136 10 16
1 0 137 14 16
1 0 138 24 16
1 0 139 22 16
1 0 140 28 16
1 0 141 2 16
1 0 142 36 16
1 0 143 13 16
1 0 144 13 16
1 0 145 12 16
1 0 146 28 16
1 0 147 18 16
1 0 148 11 16
1 0 149 8 16
1 0 150 25 16
1 0 151 4 16
1 0 152 13 16
1 0 153 24 16
1 0 154 6 16
1 0 155 13 16
1 0 156 0 16
1 0 157 3 16
1 0 158 3 16
1 0 159 27 16
1 0 160 20 16
1 0 161 14 16
1 0 162 14 16
1 0 163 23 16
1 0 164 33 16
1 0 165 19 16
1 0 166 10 16
1 0 167 36 16
1 0 168 3 16
1 0 169 7 16
1 0 170 6 16
1 0 171 24 16
1 0 172 36 16
1 0 173 14 16
1 0 174 9 16
1 0 175 12 16
1 0 176 36 16
1 0 177 21 16
1 0 178 1 16
1 0 179 1 16
1 0 180 26 16
1 0 181 11 16
1 0 182 9 16
1 0 183 14 16
1 0 184 37 16
1 0 185 37 16
1 0 186 19 16
1 0 187 7 16
1 0 188 25 16
1 0 189 3 16
1 0 190 14 16
1 0 191 30 16
1 0 192 28 16
1 0 193 34 16
1 0 194 8 16
1 0 195 33 16
1 0 196 14 16
1 0 197 14 16
1 0 198 11 16
1 0 199 34 16
1 0 200 32 16
1 0 201 2 16
1 0 202 3 16
1 0 203 35 16
1 0 204 8 16
1 0 205 28 16
1 0 206 30 16
1 0 207 10 16
1 0 208 19 16
1 0 209 21 16
1 0 210 33 16
1 0 211 15 16
1 0 212 29 16
1 0 213 2 16
1 0 214 4 16
1 0 215 26 16
1 0 216 24 16
1 0 217 20 16
1 0 218 14 16
1 0 219 22 16
1 0 220 11 16
1 0 221 1 16
1 0 222 33 16
1 0 223 6 16
1 0 224 0 16
1 0 225 30 16
1 0 226 9 16
1 0 227 27 16
1 0 228 6 16
1 0 229 30 16
1 0 230 9 16
1 0 231 26 16
1 0 232 7 16
1 0 233 7 16
1 0 234 37 16
1 0 235 25 16
1 0 236 12 16
1 0 237 27 16
1 0 238 9 16
1 0 239 24 16
1 0 240 18 16
1 0 241 14 16
1 0 242 12 16
1 0 243 12 16
1 0 244 3 16
1 0 245 13 16
1 0 246 14 16
1 0 247 35 16
1 0 248 4 16
1 0 249 1 16
1 0 250 4 16
1 0 251 4 16
1 0 252 9 16
1 0 253 10 16
1 0 254 29 16
1 0 255 23 48
1 1 0 11 64
1 1 1 1 0
1 1 2 30 0
1 1 3 35 0
1 1 4 10 0
1 1 5 22 0
1 1 6 29 0
1 1 7 24 0
1 1 8 2 0
1 1 9 14 0
1 1 10 37 0
1 1 11 4 0
1 1 12 16 0
1 1 13 23 0
1 1 14 14 0
1 1 15 5 0
1 1 16 5 0
1 1 17 21 0
1 1 18 14 0
1 1 19 14 0
1 1 20 27 0
1 1 21 36 0
1 1 22 16 0
1 1 23 36 0
1 1 24 14 0
1 1 25 5 0
1 1 26 27 0
1 1 27 29 0
1 1 28 37 0
1 1 29 6 0
1 1 30 13 0
1 1 31 14 0
1 1 32 3 0
1 1 33 8 0
1 1 34 3 0
1 1 35 9 0
1 1 36 0 0
1 1 37 36 0
1 1 38 16 0
1 1 39 13 0
1 1 40 4 0
1 1 41 12 0
1 1 42 4 0
1 1 43 0 0
1 1 44 5 0
1 1 45 13 0
1 1 46 12 0
1 1 47 6 0
1 1 48 9 0
1 1 49 5 0
1 1 50 20 0
1 1 51 6 0
1 1 52 5 0
1 1 53 28 0
1 1 54 10 0
1 1 55 28 0
1 1 56 0 0
1 1 57 14 0
1 1 58 30 0
1 1 59 31 0
1 1 60 5 0
1 1 61 1 0
1 1 62 4 0
1 1 63 15 0
1 1 64 5 0
1 1 65 0 0
1 1 66 9 0
1 1 67 28 0
1 1 68 14 0
1 1 69 10 0
1 1 70 11 0
1 1 71 37 0
1 1 72 30 0
1 1 73 12 0
1 1 74 20 0
1 1 75 10 0
1 1 76 5 0
1 1 77 17 0
1 1 78 1 0
1 1 79 11 0
1 1 80 26 0
1 1 81 1 0
1 1 82 12 0
1 1 83 31 0
1 1 84 28 0
1 1 85 11 0
1 1 86 19 0
1 1 87 22 0
1 1 88 10 0
1 1 89 13 0
1 1 90 27 0
1 1 91 10 0
1 1 92 6 0
1 1 93 2 0
1 1 94 14 0
1 1 95 21 0
1 1 96 6 0
1 1 97 24 0
1 1 98 17 0
1 1 99 8 0
1 1 100 37 0
1 1 101 3 0
1 1 102 2 0
1 1 103 2 0
1 1 104 34 0
1 1 105 31 0
1 1 106 37 0
1 1 107 25 0
1 1 108 10 0
1 1 109 37 0
1 1 110 14 0
1 1 111 7 0
1 1 112 2 0
1 1 113 14 0
1 1 114 23 0
1 1 115 8 0
1 1 116 35 0
1 1 117 19 0
1 1 118 13 0
1 1 119 16 0
1 1 120 11 0
1 1 121 4 0
1 1 122 8 0
1 1 123 12 0
1 1 124 2 0
1 1 125 31 0
1 1 126 31 0
1 1 127 28 0
1 1 128 10 0
1 1 129 34 0
1 1 130 15 0
1 1 131 30 0
1 1 132 9 0
1 1 133 37 0
1 1 134 16 0
1 1 135 4 0
1 1 136 4 0
1 1 137 13 0
1 1 138 10 0
1 1 139 5 0
1 1 140 6 0
1 1 141 11 0
1 1 142 13 0
1 1 143 22 0
1 1 144 19 0
1 1 145 20 0
1 1 146 14 0
1 1 147 28 0
1 1 148 23 0
1 1 149 21 0
1 1 150 14 0
1 1 151 1 0
1 1 152 23 0
1 1 153 21 0
1 1 154 0 0
1 1 155 26 0
1 1 156 34 0
1 1 157 7 0
1 1 158 29 0
1 1 159 17 0
1 1 160 36 0
1 1 161 7 0
1 1 162 19 0
1 1 163 30 0
1 1 164 11 0
1 1 165 31 0
1 1 166 28 0
1 1 167 31 0
1 1 168 0 0
1 1 169 6 0
1 1 170 3 0
1 1 171 33 0
1 1 172 12 0
1 1 173 4 0
1 1 174 13 0
1 1 175 12 0
1 1 176 15 0
1 1 177 14 0
1 1 178 9 0
1 1 179 4 0
1 1 180 15 0
1 1 181 6 0
1 1 182 4 0
1 1 183 14 0
1 1 184 30 0
1 1 185 10 0
1 1 186 0 0
1 1 187 31 0
1 1 188 18 0
1 1 189 15 0
1 1 190 34 0
1 1 191 21 0
1 1 192 14 0
1 1 193 1 0
1 1 194 15 0
1 1 195 3 0
1 1 196 28 0
1 1 197 16 0
1 1 198 36 0
1 1 199 22 0
1 1 200 26 0
1 1 201 4 0
1 1 202 7 0
1 1 203 4 0
1 1 204 31 0
1 1 205 30 0
1 1 206 21 0
1 1 207 22 0
1 1 208 33 0
1 1 209 35 0
1 1 210 2 0
1 1 211 18 0
1 1 212 21 0
1 1 213 0 0
1 1 214 34 0
1 1 215 17 0
1 1 216 15 0
1 1 217 22 0
1 1 218 6 0
1 1 219 23 0
1 1 220 31 0
1 1 221 3 0
1 1 222 3 0
1 1 223 33 0
1 1 224 12 0
1 1 225 14 0
1 1 226 11 0
1 1 227 29 0
1 1 228 14 0
1 1 229 7 0
1 1 230 14 0
1 1 231 8 0
1 1 232 5 0
1 1 233 8 0
1 1 234 4 0
1 1 235 36 0
1 1 236 19 0
1 1 237 25 0
1 1 238 21 0
1 1 239 33 0
1 1 240 19 0
1 1 241 1 0
1 1 242 10 0
1 1 243 36 0
1 1 244 5 0
1 1 245 12 0
1 1 246 5 0
1 1 247 13 0
1 1 248 0 0
1 1 249 27 0
1 1 250 0 0
1 1 251 25 0
1 1 252 26 0
1 1 253 15 0
1 1 254 14 0
1 1 255 25 32
1 2 0 11 64
1 2 1 1 0
1 2 2 32 0
1 2 3 29 0
1 2 4 4 0
1 2 5 4 0
1 2 6 25 0
1 2 7 14 0
1 2 8 22 0
1 2 9 28 0
1 2 10 21 0
1 2 11 16 0
1 2 12 17 0
1 2 13 32 0
1 2 14 20 0
1 2 15 14 0
1 2 16 2 0
1 2 17 2 0
1 2 18 23 0
1 2 19 6 0
1 2 20 4 0
1 2 21 26 0
1 2 22 2 0
1 2 23 34 0
1 2 24 9 0
1 2 25 2 0
1 2 26 24 0
1 2 27 13 0
1 2 28 24 0
1 2 29 21 0
1 2 30 4 0
1 2 31 1 0
1 2 32 31 0
1 2 33 3 0
1 2 34 5 0
1 2 35 29 0
1 2 36 34 0
1 2 37 2 0
1 2 38 2 0
1 2 39 30 0
1 2 40 6 0
1 2 41 14 0
1 2 42 23 0
1 2 43 4 0
1 2 44 5 0
1 2 45 10 0
1 2 46 21 0
1 2 47 12 0
1 2 48 14 0
1 2 49 36 0
1 2 50 9 0
1 2 51 2 0
1 2 52 19 0
1 2 53 0 0
1 2 54 8 0
1 2 55 28 0
1 2 56 23 0
1 2 57 8 0
1 2 58 33 0
1 2 59 26 0
1 2 60 2 0
1 2 61 14 0
1 2 62 31 0
1 2 63 12 0
1 2 64 0 0
1 2 65 12 0
1 2 66 25 0
1 2 67 2 0
1 2 68 6 0
1 2 69 1 0
1 2 70 12 0
1 2 71 3 0
1 2 72 24 0
1 2 73 10 0
1 2 74 16 0
1 2 75 2 0
1 2 76 4 0
1 2 77 21 0
1 2 78 5 0
1 2 79 24 0
1 2 80 2 0
1 2 81 10 0
1 2 82 24 0
1 2 83 4 0
1 2 84 37 0
1 2 85 32 0
1 2 86 4 0
1 2 87 26 0
1 2 88 16 0
1 2 89 26 0
1 2 90 26 0
1 2 91 10 0
1 2 92 7 0
1 2 93 22 0
1 2 94 12 0
1 2 95 29 0
1 2 96 35 0
1 2 97 14 0
1 2 98 5 0
1 2 99 25 0
1 2 100 18 0
1 2 101 19 0
1 2 102 0 0
1 2 103 20 0
1 2 104 14 0
1 2 105 13 0
1 2 106 36 0
1 2 107 21 0
1 2 108 34 0
1 2 109 31 0
1 2 110 28 0
1 2 111 27 0
1 2 112 9 0
1 2 113 0 0
1 2 114 12 0
1 2 115 27 0
1 2 116 7 0
1 2 117 9 0
1 2 118 12 0
1 2 119 30 0
1 2 120 27 0
1 2 121 4 0
1 2 122 15 0
1 2 123 13 0
1 2 124 15 0
1 2 125 9 0
1 2 126 6 0
1 2 127 15 0
1 2 128 5 0
1 2 129 28 0
1 2 130 4 0
1 2 131 16 0
1 2 132 6 0
1 2 133 7 0
1 2 134 31 0
1 2 135 25 0
1 2 136 8 0
1 2 137 12 0
1 2 138 23 0
1 2 139 21 0
1 2 140 1 0
1 2 141 27 0
1 2 142 2 0
1 2 143 20 0
1 2 144 2 0
1 2 145 9 0
1 2 146 37 0
1 2 147 0 0
1 2 148 27 0
1 2 149 23 0
1 2 150 23 0
1 2 151 6 0
1 2 152 13 0
1 2 153 1 0
1 2 154 12 0
1 2 155 21 0
1 2 156 26 0
1 2 157 12 0
1 2 158 5 0
1 2 159 9 0
1 2 160 7 0
1 2 161 24 0
1 2 162 22 0
1 2 163 6 0
1 2 164 22 0
1 2 165 9 0
1 2 166 10 0
1 2 167 1 0
1 2 168 17 0
1 2 169 6 0
1 2 170 9 0
1 2 171 13 0
1 2 172 32 0
1 2 173 18 0
1 2 174 19 0
1 2 175 31 0
1 2 176 2 0
1 2 177 14 0
1 2 178 0 0
1 2 179 34 0
1 2 180 19 0
1 2 181 33 0
1 2 182 7 0
1 2 183 33 0
1 2 184 10 0
1 2 185 21 0
1 2 186 3 0
1 2 187 21 0
1 2 188 1 0
1 2 189 19 0
1 2 190 9 0
1 2 191 34 0
1 2 192 18 0
1 2 193 19 0
1 2 194 30 0
1 2 195 30 0
1 2 196 14 0
1 2 197 2 0
1 2 198 5 0
1 2 199 8 0
1 2 200 37 0
1 2 201 6 0
1 2 202 35 0
1 2 203 10 0
1 2 204 31 0
1 2 205 11 0
1 2 206 36 0
1 2 207 20 0
1 2 208 14 0
1 2 209 0 0
1 2 210 10 0
1 2 211 22 0
1 2 212 35 0
1 2 213 4 0
1 2 214 6 0
1 2 215 9 0
1 2 216 1 0
1 2 217 8 0
1 2 218 13 0
1 2 219 33 0
1 2 220 27 0
1 2 221 22 0
1 2 222 13 0
1 2 223 1 0
1 2 224 30 0
1 2 225 13 0
1 2 226 14 0
1 2 227 1 0
1 2 228 3 0
1 2 229 11 0
1 2 230 12 0
1 2 231 13 0
1 2 232 32 0
1 2 233 33 0
1 2 234 22 0
1 2 235 27 0
1 2 236 19 0
1 2 237 23 0
1 2 238 19 0
1 2 239 27 0
1 2 240 6 0
1 2 241 18 0
1 2 242 11 0
1 2 243 2 0
1 2 244 14 0
1 2 245 7 0
1 2 246 37 0
1 2 247 20 0
1 2 248 12 0
1 2 249 32 0
1 2 250 28 0
1 2 251 31 0
1 2 252 12 0
1 2 253 24 0
1 2 254 12 0
1 2 255 10 32
1 3 0 32 64
1 3 1 5 0
1 3 2 6 0
1 3 3 30 0
1 3 4 5 0
1 3 5 32 0
1 3 6 16 0
1 3 7 24 0
1 3 8 17 0
1 3 9 14 0
1 3 10 12 0
1 3 11 13 0
1 3 12 15 0
1 3 13 36 0
1 3 14 16 0
1 3 15 6 0
1 3 16 36 0
1 3 17 25 0
1 3 18 6 0
1 3 19 33 0
1 3 20 31 0
1 3 21 6 0
1 3 22 30 0
1 3 23 1 0
1 3 24 23 0
1 3 25 12 0
1 3 26 18 0
1 3 27 32 0
1 3 28 30 0
1 3 29 9 0
1 3 30 10 0
1 3 31 28 0
1 3 32 18 0
1 3 33 28 0
1 3 34 10 0
1 3 35 31 0
1 3 36 36 0
1 3 37 4 0
1 3 38 12 0
1 3 39 13 0
1 3 40 11 0
1 3 41 15 0
1 3 42 14 0
1 3 43 16 0
1 3 44 21 0
1 3 45 16 0
1 3 46 4 0
1 3 47 4 0
1 3 48 32 0
1 3 49 30 0
1 3 50 4 0
1 3 51 2 0
1 3 52 2 0
1 3 53 17 0
1 3 54 4 0
1 3 55 4 0
1 3 56 13 0
1 3 57 8 0
1 3 58 21 0
1 3 59 31 0
1 3 60 33 0
1 3 61 1 0
1 3 62 19 0
1 3 63 5 0
1 3 64 14 0
1 3 65 4 0
1 3 66 12 0
1 3 67 27 0
1 3 68 37 0
1 3 69 31 0
1 3 70 10 0
1 3 71 11 0
1 3 72 2 0
1 3 73 13 0
1 3 74 19 0
1 3 75 9 0
1 3 76 33 0
1 3 77 13 0
1 3 78 8 0
1 3 79 2 0
1 3 80 34 0
1 3 81 2 0
1 3 82 3 0
1 3 83 22 0
1 3 84 30 0
1 3 85 1 0
1 3 86 7 0
1 3 87 7 0
1 3 88 1 0
1 3 89 13 0
1 3 90 35 0
1 3 91 29 0
1 3 92 14 0
1 3 93 5 0
1 3 94 22 0
1 3 95 10 0
1 3 96 26 0
1 3 97 4 0
1 3 98 17 0
1 3 99 4 0
1 3 100 21 0
1 3 101 2 0
1 3 102 25 0
1 3 103 37 0
1 3 104 0 0
1 3 105 34 0
1 3 106 27 0
1 3 107 21 0
1 3 108 2 0
1 3 109 5 0
1 3 110 2 0
1 3 111 12 0
1 3 112 28 0
1 3 113 14 0
1 3 114 35 0
1 3 115 13 0
1 3 116 14 0
1 3 117 29 0
1 3 118 12 0
1 3 119 26 0
1 3 120 13 0
1 3 121 14 0
1 3 122 30 0
1 3 123 17 0
1 3 124 28 0
1 3 125 5 0
1 3 126 12 0
1 3 127 29 0
1 3 128 10 0
1 3 129 33 0
1 3 130 4 0
1 3 131 14 0
1 3 132 36 0
1 3 133 12 0
1 3 134 2 0
1 3 135 5 0
1 3 136 31 0
1 3 137 29 0
1 3 138 35 0
1 3 139 1 0
1 3 140 4 0
1 3 141 12 0
1 3 142 25 0
1 3 143 13 0
1 3 144 33 0
1 3 145 9 0
1 3 146 27 0
1 3 147 1 0
1 3 148 1 0
1 3 149 2 0
1 3 150 34 0
1 3 151 10 0
1 3 152 32 0
1 3 153 33 0
1 3 154 33 0
1 3 155 10 0
1 3 156 17 0
1 3 157 10 0
1 3 158 8 0
1 3 159 9 0
1 3 160 13 0
1 3 161 9 0
1 3 162 8 0
1 3 163 9 0
1 3 164 2 0
1 3 165 14 0
1 3 166 2 0
1 3 167 3 0
1 3 168 25 0
1 3 169 1 0
1 3 170 21 0
1 3 171 17 0
1 3 172 16 0
1 3 173 14 0
1 3 174 24 0
1 3 175 14 0
1 3 176 21 0
1 3 177 25 0
1 3 178 6 0
1 3 179 37 0
1 3 180 7 0
1 3 181 35 0
1 3 182 17 0
1 3 183 19 0
1 3 184 6 0
1 3 185 3 0
1 3 186 24 0
1 3 187 10 0
1 3 188 26 0
1 3 189 13 0
1 3 190 22 0
1 3 191 15 0
1 3 192 13 0
1 3 193 37 0
1 3 194 16 0
1 3 195 12 0
1 3 196 24 0
1 3 197 19 0
1 3 198 0 0
1 3 199 17 0
1 3 200 0 0
1 3 201 22 0
1 3 202 9 0
1 3 203 22 0
1 3 204 12 0
1 3 205 0 0
1 3 206 2 0
1 3 207 14 0
1 3 208 23 0
1 3 209 13 0
1 3 210 32 0
1 3 211 5 0
1 3 212 10 0
1 3 213 29 0
1 3 214 1 0
1 3 215 6 0
1 3 216 17 0
1 3 217 1 0
1 3 218 10 0
1 3 219 8 0
1 3 220 4 0
1 3 221 37 0
1 3 222 12 0
1 3 223 2 0
1 3 224 29 0
1 3 225 6 0
1 3 226 37 0
1 3 227 35 0
1 3 228 22 0
1 3 229 6 0
1 3 230 18 0
1 3 231 2 0
1 3 232 14 0
1 3 233 2 0
1 3 234 28 0
1 3 235 11 0
1 3 236 33 0
1 3 237 14 0
1 3 238 17 0
1 3 239 15 0
1 3 240 27 0
1 3 241 12 0
1 3 242 7 0
1 3 243 26 0
1 3 244 14 0
1 3 245 17 0
1 3 246 36 0
1 3 247 18 0
1 3 248 4 0
1 3 249 12 0
1 3 250 36 0
1 3 251 27 0
1 3 252 14 0
1 3 253 37 0
1 3 254 24 0
1 3 255 34 32
1 4 0 32 72
1 4 1 12 8
1 4 2 15 8
1 4 3 14 8
1 4 4 21 8
1 4 5 28 8
1 4 6 2 8
1 4 7 20 8
1 4 8 15 8
1 4 9 19 8
1 4 10 1 8
1 4 11 19 8
1 4 12 14 8
1 4 13 5 8
1 4 14 12 8
1 4 15 18 8
1 4 16 4 8
1 4 17 37 8
1 4 18 28 8
1 4 19 12 8
1 4 20 26 8
1 4 21 37 8
1 4 22 8 8
1 4 23 14 8
1 4 24 2 8
1 4 25 12 8
1 4 26 25 8
1 4 27 18 8
1 4 28 14 8
1 4 29 28 8
1 4 30 10 8
1 4 31 28 8
1 4 32 17 8
1 4 33 9 8
1 4 34 23 8
1 4 35 12 8
1 4 36 17 8
1 4 37 10 8
1 4 38 13 8
1 4 39 21 8
1 4 40 15 8
1 4 41 33 8
1 4 42 8 8
1 4 43 32 8
1 4 44 0 8
1 4 45 30 8
1 4 46 14 8
1 4 47 6 8
1 4 48 37 8
1 4 49 33 8
1 4 50 26 8
1 4 51 19 8
1 4 52 9 8
1 4 53 24 8
1 4 54 21 8
1 4 55 8 8
1 4 56 36 8
1 4 57 34 8
1 4 58 10 8
1 4 59 25 8
1 4 60 36 8
1 4 61 5 8
1 4 62 20 8
1 4 63 8 8
1 4 64 5 8
1 4 65 28 8
1 4 66 26 8
1 4 67 13 8
1 4 68 26 8
1 4 69 25 8
1 4 70 33 8
1 4 71 8 8
1 4 72 36 8
1 4 73 25 8
1 4 74 15 8
1 4 75 24 8
1 4 76 12 8
1 4 77 18 8
1 4 78 13 8
1 4 79 28 8
1 4 80 25 8
1 4 81 6 8
1 4 82 24 8
1 4 83 8 8
1 4 84 8 8
1 4 85 6 8
1 4 86 12 8
1 4 87 11 8
1 4 88 27 8
1 4 89 29 8
1 4 90 24 8
1 4 91 36 8
1 4 92 20 8
1 4 93 24 8
1 4 94 12 8
1 4 95 11 8
1 4 96 29 8
1 4 97 14 8
1 4 98 37 8
1 4 99 30 8
1 4 100 36 8
1 4 101 37 8
1 4 102 13 8
1 4 103 31 8
1 4 104 15 8
1 4 105 1 8
1 4 106 6 8
1 4 107 2 8
1 4 108 17 8
1 4 109 25 8
1 4 110 24 8
1 4 111 10 8
1 4 112 1 8
1 4 113 12 8
1 4 114 12 8
1 4 115 28 8
1 4 116 9 8
1 4 117 16 8
1 4 118 10 8
1 4 119 30 8
1 4 120 8 8
1 4 121 10 8
1 4 122 35 8
1 4 123 11 8
1 4 124 1 8
1 4 125 6 8
1 4 126 13 8
1 4 127 4 8
1 4 128 36 8
1 4 129 29 8
1 4 130 29 8
1 4 131 20 8
1 4 132 12 8
1 4 133 28 8
1 4 134 9 8
1 4 135 32 8
1 4 136 21 8
1 4 137 4 8
1 4 138 4 8
1 4 139 4 8
1 4 140 2 8
1 4 141 16 8
1 4 142 3 8
1 4 143 8 8
1 4 144 13 8
1 4 145 37 8
1 4 146 5 8
1 4 147 18 8
1 4 148 14 8
1 4 149 11 8
1 4 150 12 8
1 4 151 25 8
1 4 152 9 8
1 4 153 27 8
1 4 154 28 8
1 4 155 10 8
1 4 156 28 8
1 4 157 29 8
1 4 158 29 8
1 4 159 12 8
1 4 160 23 8
1 4 161 15 8
1 4 162 5 8
1 4 163 20 8
1 4 164 15 8
1 4 165 31 8
1 4 166 20 8
1 4 167 10 8
1 4 168 4 8
1 4 169 37 8
1 4 170 33 8
1 4 171 16 8
1 4 172 17 8
1 4 173 2 8
1 4 174 29 8
1 4 175 6 8
1 4 176 37 8
1 4 177 28 8
1 4 178 13 8
1 4 179 33 8
1 4 180 6 8
1 4 181 11 8
1 4 182 26 8
1 4 183 7 8
1 4 184 6 8
1 4 185 5 8
1 4 186 36 8
1 4 187 15 8
1 4 188 5 8
1 4 189 6 8
1 4 190 3 8
1 4 191 13 8
1 4 192 9 8
1 4 193 36 8
1 4 194 22 8
1 4 195 24 8
1 4 196 15 8
1 4 197 33 8
1 4 198 4 8
1 4 199 9 8
1 4 200 6 8
1 4 201 36 8
1 4 202 18 8
1 4 203 9 8
1 4 204 26 8
1 4 205 4 8
1 4 206 14 8
1 4 207 15 8
1 4 208 15 8
1 4 209 35 8
1 4 210 36 8
1 4 211 20 8
1 4 212 22 8
1 4 213 3 8
1 4 214 7 8
1 4 215 2 8
1 4 216 8 8
1 4 217 35 8
1 4 218 22 8
1 4 219 19 8
1 4 220 24 8
1 4 221 24 8
1 4 222 7 8
1 4 223 37 8
1 4 224 10 8
1 4 225 12 8
1 4 226 8 8
1 4 227 31 8
1 4 228 28 8
1 4 229 6 8
1 4 230 31 8
1 4 231 13 8
1 4 232 22 8
1 4 233 16 8
1 4 234 29 8
1 4 235 34 8
1 4 236 8 8
1 4 237 14 8
1 4 238 16 8
1 4 239 35 8
1 4 240 1 8
1 4 241 35 8
1 4 242 14 8
1 4 243 5 8
1 4 244 15 8
1 4 245 29 8
1 4 246 10 8
1 4 247 2 8
1 4 248 6 8
1 4 249 37 8
1 4 250 3 8
1 4 251 21 8
1 4 252 4 8
1 4 253 33 8
1 4 254 12 8
1 4 255 1 40
2 0 0 29 80
2 0 1 6 16
2 0 2 5 16
2 0 3 20 16
2 0 4 1 16
2 0 5 12 16
2 0 6 17 16
2 0 7 33 16
2 0 8 10 16
2 0 9 14 16
2 0 10 17 16
2 0 11 8 16
2 0 12 29 16
2 0 13 21 16
2 0 14 32 16
2 0 15 12 16
2 0 16 11 16
2 0 17 27 16
2 0 18 14 16
2 0 19 4 16
2 0 20 22 16
2 0 21 32 16
2 0 22 3 16
2 0 23 15 16
2 0 24 22 16
2 0 25 6 16
2 0 26 24 16
2 0 27 2 16
2 0 28 6 16
2 0 29 27 16
2 0 30 17 16
2 0 31 2 16
2 0 32 18 16
2 0 33 30 16
2 0 34 29 16
2 0 35 3 16
2 0 36 25 16
2 0 37 9 16
2 0 38 21 16
2 0 39 31 16
2 0 40 4 16
2 0 41 10 16
2 0 42 5 16
2 0 43 14 16
2 0 44 6 16
2 0 45 26 16
2 0 46 2 16
2 0 47 13 16
2 0 48 14 16
2 0 49 8 16
2 0 50 32 16
2 0 51 2 16
2 0 52 17 16
2 0 53 16 16
2 0 54 35 16
2 0 55 9 16
2 0 56 13 16
2 0 57 11 16
2 0 58 4 16
2 0 59 16 16
2 0 60 27 16
2 0 61 23 16
2 0 62 20 16
2 0 63 5 16
2 0 64 24 16
2 0 65 30 16
2 0 66 3 16
2 0 67 15 16
2 0 68 19 16
2 0 69 3 16
2 0 70 1 16
2 0 71 4 16
2 0 72 4 16
2 0 73 9 16
2 0 74 34 16
2 0 75 0 16
2 0 76 4 16
2 0 77 13 16
2 0 78 6 16
2 0 79 14 16
2 0 80 7 16
2 0 81 20 16
2 0 82 37 16
2 0 83 29 16
2 0 84 12 16
2 0 85 4 16
2 0 86 8 16
2 0 87 12 16
2 0 88 36 16
2 0 89 15 16
2 0 90 13 16
2 0 91 8 16
2 0 92 23 16
2 0 93 1 16
2 0 94 17 16
2 0 95 33 16
2 0 96 24 16
2 0 97 9 16
2 0 98 30 16
2 0 99 7 16
2 0 100 10 16
2 0 101 1 16
2 0 102 15 16
2 0 103 10 16
2 0 104 8 16
2 0 105 30 16
2 0 106 27 16
2 0 107 15 16
2 0 108 10 16
2 0 109 13 16
2 0 110 18 16
2 0 111 12 16
2 0 112 34 16
2 0 113 14 16
2 0 114 23 16
2 0 115 27 16
2 0 116 27 16
2 0 117 14 16
2 0 118 35 16
2 0 119 12 16
2 0 120 16 16
2 0 121 30 16
2 0 122 25 16
2 0 123 28 16
2 0 124 22 16
2 0 125 10 16
2 0 126 10 16
2 0 127 5 16
2 0 128 6 16
2 0 129 30 16
2 0 130 23 16
2 0 131 27 16
2 0 132 1 16
2 0 133 26 16
2 0 134 9 16
2 0 135 11 16
2 0 136 18 16
2 0 137 32 16
2 0 138 35 16
2 0 139 7 16
2 0 140 4 16
2 0 141 2 16
2 0 142 8 16
2 0 143 0 16
2 0 144 6 16
2 0 145 33 16
2 0 146 11 16
2 0 147 10 16
2 0 148 33 16
2 0 149 19 16
2 0 150 4 16
2 0 151 9 16
2 0 152 17 16
2 0 153 31 16
2 0 154 14 16
2 0 155 13 16
2 0 156 14 16
2 0 157 37 16
2 0 158 10 16
2 0 159 27 16
2 0 160 10 16
2 0 161 14 16
2 0 162 16 16
2 0 163 17 16
2 0 164 30 16
2 0 165 2 16
2 0 166 25 16
2 0 167 31 16
2 0 168 4 16
2 0 169 26 16
2 0 170 14 16
2 0 171 6 16
2 0 172 30 16
2 0 173 17 16
2 0 174 1 16
2 0 175 13 16
2 0 176 20 16
2 0 177 13 16
2 0 178 29 16
2 0 179 31 16
2 0 180 29 16
2 0 181 8 16
2 0 182 35 16
2 0 183 37 16
2 0 184 33 16
2 0 185 11 16
2 0 186 12 16
2 0 187 16 16
2 0 188 13 16
2 0 189 33 16
2 0 190 13 16
2 0 191 7 16
2 0 192 8 16
2 0 193 34 16
2 0 194 10 16
2 0 195 20 16
2 0 196 6 16
2 0 197 0 16
2 0 198 8 16
2 0 199 15 16
2 0 200 4 16
2 0 201 14 16
2 0 202 25 16
2 0 203 1 16
2 0 204 15 16
2 0 205 34 16
2 0 206 33 16
2 0 207 10 16
2 0 208 0 16
2 0 209 24 16
2 0 210 23 16
2 0 211 13 16
2 0 212 13 16
2 0 213 14 16
2 0 214 24 16
2 0 215 7 16
2 0 216 14 16
2 0 217 21 16
2 0 218 23 16
2 0 219 30 16
2 0 220 27 16
2 0 221 34 16
2 0 222 2 16
2 0 223 22 16
2 0 224 12 16
2 0 225 14 16
2 0 226 6 16
2 0 227 19 16
2 0 228 28 16
2 0 229 30 16
2 0 230 7 16
2 0 231 36 16
2 0 232 25 16
2 0 233 5 16
2 0 234 15 16
2 0 235 9 16
2 0 236 13 16
2 0 237 13 16
2 0 238 9 16
2 0 239 35 16
2 0 240 2 16
2 0 241 34 16
2 0 242 19 16
2 0 243 2 16
2 0 244 20 16
2 0 245 32 16
2 0 246 32 16
2 0 247 28 16
2 0 248 17 16
2 0 249 5 16
2 0 250 2 16
2 0 251 5 16
2 0 252 34 16
2 0 253 10 16
2 0 254 13 16
2 0 255 7 48
2 1 0 12 64
2 1 1 30 0
2 1 2 26 0
2 1 3 10 0
2 1 4 15 0
2 1 5 9 0
2 1 6 14 0
2 1 7 33 0
2 1 8 5 0
2 1 9 35 0
2 1 10 33 0
2 1 11 6 0
2 1 12 37 0
2 1 13 3 0
2 1 14 32 0
2 1 15 6 0
2 1 16 21 0
2 1 17 15 0
2 1 18 3 0
2 1 19 14 0
2 1 20 4 0
2 1 21 31 0
2 1 22 19 0
2 1 23 14 0
2 1 24 1 0
2 1 25 12 0
2 1 26 36 0
2 1 27 14 0
2 1 28 14 0
2 1 29 33 0
2 1 30 8 0
2 1 31 7 0
2 1 32 17 0
2 1 33 21 0
2 1 34 10 0
2 1 35 33 0
2 1 36 3 0
2 1 37 29 0
2 1 38 23 0
2 1 39 32 0
2 1 40 8 0
2 1 41 23 0
2 1 42 26 0
2 1 43 2 0
2 1 44 21 0
2 1 45 24 0
2 1 46 4 0
2 1 47 31 0
2 1 48 23 0
2 1 49 14 0
2 1 50 6 0
2 1 51 29 0
2 1 52 31 0
2 1 53 30 0
2 1 54 21 0
2 1 55 12 0
2 1 56 29 0
2 1 57 7 0
2 1 58 12 0
2 1 59 23 0
2 1 60 31 0
2 1 61 1 0
2 1 62 12 0
2 1 63 9 0
2 1 64 28 0
2 1 65 24 0
2 1 66 30 0
2 1 67 31 0
2 1 68 17 0
2 1 69 9 0
2 1 70 1 0
2 1 71 3 0
2 1 72 4 0
2 1 73 6 0
2 1 74 2 0
2 1 75 10 0
2 1 76 13 0
2 1 77 28 0
2 1 78 9 0
2 1 79 14 0
2 1 80 1 0
2 1 81 9 0
2 1 82 13 0
2 1 83 6 0
2 1 84 1 0
2 1 85 10 0
2 1 86 4 0
2 1 87 12 0
2 1 88 22 0
2 1 89 24 0
2 1 90 34 0
2 1 91 9 0
2 1 92 6 0
2 1 93 4 0
2 1 94 27 0
2 1 95 6 0
2 1 96 13 0
2 1 97 35 0
2 1 98 6 0
2 1 99 4 0
2 1 100 32 0
2 1 101 35 0
2 1 102 9 0
2 1 103 6 0
2 1 104 1 0
2 1 105 20 0
2 1 106 0 0
2 1 107 28 0
2 1 108 19 0
2 1 109 4 0
2 1 110 17 0
2 1 111 11 0
2 1 112 5 0
2 1 113 1 0
2 1 114 10 0
2 1 115 22 0
2 1 116 33 0
2 1 117 34 0
2 1 118 20 0
2 1 119 1 0
2 1 120 21 0
2 1 121 36 0
2 1 122 20 0
2 1 123 28 0
2 1 124 27 0
2 1 125 4 0
2 1 126 10 0
2 1 127 12 0
2 1 128 26 0
2 1 129 29 0
2 1 130 31 0
2 1 131 31 0
2 1 132 17 0
2 1 133 32 0
2 1 134 37 0
2 1 135 13 0
2 1 136 21 0
2 1 137 29 0
2 1 138 21 0
2 1 139 2 0
2 1 140 14 0
2 1 141 10 0
2 1 142 1 0
2 1 143 10 0
2 1 144 6 0
2 1 145 1 0
2 1 146 14 0
2 1 147 21 0
2 1 148 18 0
2 1 149 10 0
2 1 150 27 0
2 1 151 7 0
2 1 152 16 0
2 1 153 19 0
2 1 154 13 0
2 1 155 9 0
2 1 156 17 0
2 1 157 4 0
2 1 158 16 0
2 1 159 11 0
2 1 160 13 0
2 1 161 13 0
2 1 162 8 0
2 1 163 36 0
2 1 164 9 0
2 1 165 34 0
2 1 166 18 0
2 1 167 25 0
2 1 168 4 0
2 1 169 14 0
2 1 170 30 0
2 1 171 19 0
2 1 172 2 0
2 1 173 22 0
2 1 174 30 0
2 1 175 7 0
2 1 176 14 0
2 1 177 34 0
2 1 178 5 0
2 1 179 5 0
2 1 180 12 0
2 1 181 20 0
2 1 182 0 0
2 1 183 12 0
2 1 184 5 0
2 1 185 2 0
2 1 186 14 0
2 1 187 14 0
2 1 188 35 0
2 1 189 30 0
2 1 190 20 0
2 1 191 18 0
2 1 192 14 0
2 1 193 5 0
2 1 194 35 0
2 1 195 31 0
2 1 196 8 0
2 1 197 18 0
2 1 198 3 0
2 1 199 9 0
2 1 200 14 0
2 1 201 14 0
2 1 202 14 0
2 1 203 20 0
2 1 204 8 0
2 1 205 14 0
2 1 206 5 0
2 1 207 8 0
2 1 208 24 0
2 1 209 9 0
2 1 210 30 0
2 1 211 35 0
2 1 212 14 0
2 1 213 20 0
2 1 214 9 0
2 1 215 5 0
2 1 216 33 0
2 1 217 24 0
2 1 218 11 0
2 1 219 12 0
2 1 220 30 0
2 1 221 35 0
2 1 222 13 0
2 1 223 3 0
2 1 224 16 0
2 1 225 19 0
2 1 226 36 0
2 1 227 1 0
2 1 228 35 0
2 1 229 18 0
2 1 230 6 0
2 1 231 23 0
2 1 232 8 0
2 1 233 25 0
2 1 234 25 0
2 1 235 3 0
2 1 236 1 0
2 1 237 30 0
2 1 238 18 0
2 1 239 2 0
2 1 240 5 0
2 1 241 20 0
2 1 242 36 0
2 1 243 1 0
2 1 244 11 0
2 1 245 5 0
2 1 246 33 0
2 1 247 31 0
2 1 248 14 0
2 1 249 13 0
2 1 250 14 0
2 1 251 4 0
2 1 252 27 0
2 1 253 35 0
2 1 254 11 0
2 1 255 33 32
2 2 0 14 64
2 2 1 15 0
2 2 2 3 0
2 2 3 6 0
2 2 4 23 0
2 2 5 13 0
2 2 6 24 0
2 2 7 14 0
2 2 8 4 0
2 2 9 14 0
2 2 10 23 0
2 2 11 12 0
2 2 12 14 0
2 2 13 36 0
2 2 14 2 0
2 2 15 9 0
2 2 16 27 0
2 2 17 16 0
2 2 18 25 0
2 2 19 37 0
2 2 20 9 0
2 2 21 33 0
2 2 22 6 0
2 2 23 12 0
2 2 24 19 0
2 2 25 23 0
2 2 26 15 0
2 2 27 21 0
2 2 28 24 0
2 2 29 31 0
2 2 30 7 0
2 2 31 13 0
2 2 32 28 0
2 2 33 33 0
2 2 34 34 0
2 2 35 27 0
2 2 36 33 0
2 2 37 15 0
2 2 38 10 0
2 2 39 1 0
2 2 40 9 0
2 2 41 9 0
2 2 42 33 0
2 2 43 9 0
2 2 44 17 0
2 2 45 15 0
2 2 46 5 0
2 2 47 2 0
2 2 48 29 0
2 2 49 22 0
2 2 50 13 0
2 2 51 5 0
2 2 52 15 0
2 2 53 5 0
2 2 54 16 0
2 2 55 26 0
2 2 56 2 0
2 2 57 25 0
2 2 58 8 0
2 2 59 37 0
2 2 60 29 0
2 2 61 29 0
2 2 62 14 0
2 2 63 9 0
2 2 64 16 0
2 2 65 14 0
2 2 66 18 0
2 2 67 35 0
2 2 68 16 0
2 2 69 8 0
2 2 70 31 0
2 2 71 25 0
2 2 72 21 0
2 2 73 15 0
2 2 74 30 0
2 2 75 4 0
2 2 76 2 0
2 2 77 24 0
2 2 78 30 0
2 2 79 10 0
2 2 80 26 0
2 2 81 3 0
2 2 82 14 0
2 2 83 35 0
2 2 84 8 0
2 2 85 37 0
2 2 86 0 0
2 2 87 9 0
2 2 88 4 0
2 2 89 23 0
2 2 90 0 0
2 2 91 24 0
2 2 92 13 0
2 2 93 1 0
2 2 94 37 0
2 2 95 5 0
2 2 96 23 0
2 2 97 5 0
2 2 98 17 0
2 2 99 4 0
2 2 100 34 0
2 2 101 11 0
2 2 102 13 0
2 2 103 33 0
2 2 104 29 0
2 2 105 30 0
2 2 106 23 0
2 2 107 0 0
2 2 108 8 0
2 2 109 35 0
2 2 110 23 0
2 2 111 22 0
2 2 112 10 0
2 2 113 7 0
2 2 114 35 0
2 2 115 11 0
2 2 116 36 0
2 2 117 9 0
2 2 118 25 0
2 2 119 32 0
2 2 120 0 0
2 2 121 36 0
2 2 122 13 0
2 2 123 28 0
2 2 124 22 0
2 2 125 6 0
2 2 126 1 0
2 2 127 30 0
2 2 128 5 0
2 2 129 14 0
2 2 130 19 0
2 2 131 4 0
2 2 132 28 0
2 2 133 15 0
2 2 134 36 0
2 2 135 11 0
2 2 136 8 0
2 2 137 14 0
2 2 138 6 0
2 2 139 21 0
2 2 140 34 0
2 2 141 7 0
2 2 142 8 0
2 2 143 1 0
2 2 144 16 0
2 2 145 1 0
2 2 146 12 0
2 2 147 18 0
2 2 148 8 0
2 2 149 23 0
2 2 150 22 0
2 2 151 10 0
2 2 152 36 0
2 2 153 1 0
2 2 154 24 0
2 2 155 4 0
2 2 156 9 0
2 2 157 4 0
2 2 158 7 0
2 2 159 26 0
2 2 160 19 0
2 2 161 6 0
2 2 162 19 0
2 2 163 8 0
2 2 164 21 0
2 2 165 3 0
2 2 166 15 0
2 2 167 11 0
2 2 168 10 0
2 2 169 18 0
2 2 170 37 0
2 2 171 15 0
2 2 172 0 0
2 2 173 5 0
2 2 174 5 0
2 2 175 13 0
2 2 176 28 0
2 2 177 26 0
2 2 178 1 0
2 2 179 32 0
2 2 180 35 0
2 2 181 14 0
2 2 182 27 0
2 2 183 24 0
2 2 184 18 0
2 2 185 27 0
2 2 186 16 0
2 2 187 10 0
2 2 188 11 0
2 2 189 35 0
2 2 190 2 0
2 2 191 9 0
2 2 192 33 0
2 2 193 14 0
2 2 194 18 0
2 2 195 13 0
2 2 196 17 0
2 2 197 9 0
2 2 198 29 0
2 2 199 27 0
2 2 200 4 0
2 2 201 25 0
2 2 202 4 0
2 2 203 3 0
2 2 204 15 0
2 2 205 32 0
2 2 206 17 0
2 2 207 12 0
2 2 208 25 0
2 2 209 22 0
2 2 210 16 0
2 2 211 14 0
2 2 212 4 0
2 2 213 9 0
2 2 214 10 0
2 2 215 10 0
2 2 216 29 0
2 2 217 21 0
2 2 218 21 0
2 2 219 2 0
2 2 220 18 0
2 2 221 3 0
2 2 222 12 0
2 2 223 6 0
2 2 224 19 0
2 2 225 25 0
2 2 226 22 0
2 2 227 2 0
2 2 228 5 0
2 2 229 37 0
2 2 230 2 0
2 2 231 9 0
2 2 232 2 0
2 2 233 23 0
2 2 234 11 0
2 2 235 19 0
2 2 236 5 0
2 2 237 35 0
2 2 238 22 0
2 2 239 31 0
2 2 240 2 0
2 2 241 24 0
2 2 242 22 0
2 2 243 21 0
2 2 244 8 0
2 2 245 4 0
2 2 246 1 0
2 2 247 2 0
2 2 248 19 0
2 2 249 1 0
2 2 250 7 0
2 2 251 8 0
2 2 252 14 0
2 2 253 22 0
2 2 254 1 0
2 2 255 37 32
2 3 0 9 64
2 3 1 18 0
2 3 2 10 0
2 3 3 19 0
2 3 4 26 0
2 3 5 10 0
2 3 6 4 0
2 3 7 17 0
2 3 8 2 0
2 3 9 29 0
2 3 10 14 0
2 3 11 8 0
2 3 12 5 0
2 3 13 22 0
2 3 14 15 0
2 3 15 29 0
2 3 16 8 0
2 3 17 14 0
2 3 18 18 0
2 3 19 5 0
2 3 20 33 0
2 3 21 29 0
2 3 22 5 0
2 3 23 3 0
2 3 24 9 0
2 3 25 2 0
2 3 26 5 0
2 3 27 5 0
2 3 28 14 0
2 3 29 7 0
2 3 30 14 0
2 3 31 6 0
2 3 32 36 0
2 3 33 21 0
2 3 34 28 0
2 3 35 21 0
2 3 36 36 0
2 3 37 4 0
2 3 38 32 0
2 3 39 28 0
2 3 40 3 0
2 3 41 17 0
2 3 42 4 0
2 3 43 16 0
2 3 44 10 0
2 3 45 8 0
2 3 46 28 0
2 3 47 10 0
2 3 48 13 0
2 3 49 13 0
2 3 50 5 0
2 3 51 14 0
2 3 52 32 0
2 3 53 30 0
2 3 54 26 0
2 3 55 2 0
2 3 56 4 0
2 3 57 6 0
2 3 58 25 0
2 3 59 34 0
2 3 60 6 0
2 3 61 13 0
2 3 62 37 0
2 3 63 33 0
2 3 64 6 0
2 3 65 6 0
2 3 66 2 0
2 3 67 9 0
2 3 68 14 0
2 3 69 6 0
2 3 70 13 0
2 3 71 14 0
2 3 72 7 0
2 3 73 15 0
2 3 74 12 0
2 3 75 30 0
2 3 76 29 0
2 3 77 14 0
2 3 78 34 0
2 3 79 34 0
2 3 80 28 0
2 3 81 12 0
2 3 82 3 0
2 3 83 13 0
2 3 84 24 0
2 3 85 14 0
2 3 86 20 0
2 3 87 21 0
2 3 88 6 0
2 3 89 17 0
2 3 90 17 0
2 3 91 5 0
2 3 92 6 0
2 3 93 28 0
2 3 94 5 0
2 3 95 26 0
2 3 96 28 0
2 3 97 4 0
2 3 98 17 0
2 3 99 35 0
2 3 100 7 0
2 3 101 31 0
2 3 102 6 0
2 3 103 8 0
2 3 104 1 0
2 3 105 22 0
2 3 106 13 0
2 3 107 5 0
2 3 108 0 0
2 3 109 14 0
2 3 110 21 0
2 3 111 7 0
2 3 112 6 0
2 3 113 10 0
2 3 114 34 0
2 3 115 7 0
2 3 116 27 0
2 3 117 33 0
2 3 118 0 0
2 3 119 24 0
2 3 120 2 0
2 3 121 29 0
2 3 122 24 0
2 3 123 4 0
2 3 124 7 0
2 3 125 11 0
2 3 126 27 0
2 3 127 1 0
2 3 128 28 0
2 3 129 14 0
2 3 130 2 0
2 3 131 29 0
2 3 132 13 0
2 3 133 21 0
2 3 134 10 0
2 3 135 16 0
2 3 136 12 0
2 3 137 18 0
2 3 138 18 0
2 3 139 33 0
2 3 140 5 0
2 3 141 32 0
2 3 142 30 0
2 3 143 6 0
2 3 144 6 0
2 3 145 27 0
2 3 146 10 0
2 3 147 16 0
2 3 148 12 0
2 3 149 12 0
2 3 150 2 0
2 3 151 5 0
2 3 152 1 0
2 3 153 8 0
2 3 154 9 0
2 3 155 14 0
2 3 156 2 0
2 3 157 17 0
2 3 158 5 0
2 3 159 26 0
2 3 160 24 0
2 3 161 31 0
2 3 162 25 0
2 3 163 4 0
2 3 164 1 0
2 3 165 34 0
2 3 166 29 0
2 3 167 4 0
2 3 168 30 0
2 3 169 14 0
2 3 170 35 0
2 3 171 20 0
2 3 172 23 0
2 3 173 5 0
2 3 174 1 0
2 3 175 28 0
2 3 176 4 0
2 3 177 5 0
2 3 178 2 0
2 3 179 17 0
2 3 180 23 0
2 3 181 31 0
2 3 182 8 0
2 3 183 6 0
2 3 184 20 0
2 3 185 1 0
2 3 186 12 0
2 3 187 3 0
2 3 188 24 0
2 3 189 13 0
2 3 190 33 0
2 3 191 14 0
2 3 192 12 0
2 3 193 5 0
2 3 194 37 0
2 3 195 20 0
2 3 196 25 0
2 3 197 35 0
2 3 198 21 0
2 3 199 36 0
2 3 200 13 0
2 3 201 25 0
2 3 202 8 0
2 3 203 8 0
2 3 204 13 0
2 3 205 9 0
2 3 206 12 0
2 3 207 28 0
2 3 208 13 0
2 3 209 10 0
2 3 210 6 0
2 3 211 36 0
2 3 212 1 0
2 3 213 10 0
2 3 214 8 0
2 3 215 13 0
2 3 216 4 0
2 3 217 13 0
2 3 218 22 0
2 3 219 8 0
2 3 220 9 0
2 3 221 2 0
2 3 222 25 0
2 3 223 25 0
2 3 224 15 0
2 3 225 24 0
2 3 226 23 0
2 3 227 1 0
2 3 228 10 0
2 3 229 8 0
2 3 230 18 0
2 3 231 34 0
2 3 232 10 0
2 3 233 6 0
2 3 234 27 0
2 3 235 2 0
2 3 236 0 0
2 3 237 36 0
2 3 238 1 0
2 3 239 6 0
2 3 240 10 0
2 3 241 21 0
2 3 242 26 0
2 3 243 16 0
2 3 244 10 0
2 3 245 3 0
2 3 246 35 0
2 3 247 24 0
2 3 248 19 0
2 3 249 1 0
2 3 250 34 0
2 3 251 4 0
2 3 252 2 0
2 3 253 6 0
2 3 254 19 0
2 3 255 13 32
2 4 0 33 72
2 4 1 37 8
2 4 2 28 8
2 4 3 21 8
2 4 4 8 8
2 4 5 34 8
2 4 6 2 8
2 4 7 14 8
2 4 8 35 8
2 4 9 21 8
2 4 10 0 8
2 4 11 24 8
2 4 12 3 8
2 4 13 9 8
2 4 14 8 8
2 4 15 13 8
2 4 16 23 8
2 4 17 35 8
2 4 18 22 8
2 4 19 9 8
2 4 20 26 8
2 4 21 14 8
2 4 22 22 8
2 4 23 18 8
2 4 24 37 8
2 4 25 32 8
2 4 26 16 8
2 4 27 10 8
2 4 28 22 8
2 4 29 10 8
2 4 30 10 8
2 4 31 13 8
2 4 32 14 8
2 4 33 33 8
2 4 34 15 8
2 4 35 4 8
2 4 36 26 8
2 4 37 15 8
2 4 38 5 8
2 4 39 36 8
2 4 40 18 8
2 4 41 26 8
2 4 42 8 8
2 4 43 18 8
2 4 44 6 8
2 4 45 23 8
2 4 46 29 8
2 4 47 33 8
2 4 48 28 8
2 4 49 25 8
2 4 50 12 8
2 4 51 2 8
2 4 52 35 8
2 4 53 11 8
2 4 54 5 8
2 4 55 31 8
2 4 56 3 8
2 4 57 23 8
2 4 58 3 8
2 4 59 12 8
2 4 60 5 8
2 4 61 4 8
2 4 62 32 8
2 4 63 2 8
2 4 64 14 8
2 4 65 22 8
2 4 66 10 8
2 4 67 26 8
2 4 68 11 8
2 4 69 29 8
2 4 70 13 8
2 4 71 2 8
2 4 72 28 8
2 4 73 36 8
2 4 74 23 8
2 4 75 9 8
2 4 76 15 8
2 4 77 9 8
2 4 78 30 8
2 4 79 3 8
2 4 80 33 8
2 4 81 7 8
2 4 82 2 8
2 4 83 14 8
2 4 84 7 8
2 4 85 34 8
2 4 86 36 8
2 4 87 6 8
2 4 88 23 8
2 4 89 10 8
2 4 90 10 8
2 4 91 8 8
2 4 92 1 8
2 4 93 23 8
2 4 94 5 8
2 4 95 1 8
2 4 96 9 8
2 4 97 5 8
2 4 98 5 8
2 4 99 34 8
2 4 100 1 8
2 4 101 20 8
2 4 102 12 8
2 4 103 36 8
2 4 104 5 8
2 4 105 16 8
2 4 106 5 8
2 4 107 8 8
2 4 108 14 8
2 4 109 9 8
2 4 110 2 8
2 4 111 31 8
2 4 112 4 8
2 4 113 14 8
2 4 114 12 8
2 4 115 14 8
2 4 116 37 8
2 4 117 32 8
2 4 118 4 8
2 4 119 14 8
2 4 120 24 8
2 4 121 14 8
2 4 122 9 8
2 4 123 4 8
2 4 124 34 8
2 4 125 5 8
2 4 126 9 8
2 4 127 20 8
2 4 128 31 8
2 4 129 31 8
2 4 130 12 8
2 4 131 2 8
2 4 132 23 8
2 4 133 14 8
2 4 134 8 8
2 4 135 4 8
2 4 136 37 8
2 4 137 35 8
2 4 138 35 8
2 4 139 12 8
2 4 140 14 8
2 4 141 14 8
2 4 142 23 8
2 4 143 31 8
2 4 144 13 8
2 4 145 9 8
2 4 146 16 8
2 4 147 12 8
2 4 148 10 8
2 4 149 14 8
2 4 150 9 8
2 4 151 2 8
2 4 152 35 8
2 4 153 25 8
2 4 154 17 8
2 4 155 0 8
2 4 156 25 8
2 4 157 12 8
2 4 158 21 8
2 4 159 14 8
2 4 160 15 8
2 4 161 17 8
2 4 162 1 8
2 4 163 37 8
2 4 164 31 8
2 4 165 14 8
2 4 166 24 8
2 4 167 0 8
2 4 168 31 8
2 4 169 12 8
2 4 170 6 8
2 4 171 30 8
2 4 172 9 8
2 4 173 12 8
2 4 174 10 8
2 4 175 13 8
2 4 176 14 8
2 4 177 15 8
2 4 178 37 8
2 4 179 0 8
2 4 180 24 8
2 4 181 16 8
2 4 182 30 8
2 4 183 3 8
2 4 184 2 8
2 4 185 2 8
2 4 186 1 8
2 4 187 10 8
2 4 188 0 8
2 4 189 35 8
2 4 190 25 8
2 4 191 28 8
2 4 192 30 8
2 4 193 5 8
2 4 194 10 8
2 4 195 37 8
2 4 196 12 8
2 4 197 32 8
2 4 198 13 8
2 4 199 29 8
2 4 200 11 8
2 4 201 18 8
2 4 202 2 8
2 4 203 17 8
2 4 204 12 8
2 4 205 4 8
2 4 206 10 8
2 4 207 9 8
2 4 208 1 8
2 4 209 14 8
2 4 210 10 8
2 4 211 21 8
2 4 212 35 8
2 4 213 6 8
2 4 214 31 8
2 4 215 37 8
2 4 216 4 8
2 4 217 8 8
2 4 218 10 8
2 4 219 16 8
2 4 220 4 8
2 4 221 37 8
2 4 222 1 8
2 4 223 32 8
2 4 224 14 8
2 4 225 13 8
2 4 226 34 8
2 4 227 32 8
2 4 228 13 8
2 4 229 14 8
2 4 230 27 8
2 4 231 14 8
2 4 232 36 8
2 4 233 6 8
2 4 234 5 8
2 4 235 18 8
2 4 236 14 8
2 4 237 13 8
2 4 238 5 8
2 4 239 9 8
2 4 240 9 8
2 4 241 10 8
2 4 242 27 8
2 4 243 21 8
2 4 244 19 8
2 4 245 16 8
2 4 246 31 8
2 4 247 1 8
2 4 248 18 8
2 4 249 14 8
2 4 250 1 8
2 4 251 14 8
2 4 252 25 8
2 4 253 3 8
2 4 254 35 8
2 4 255 23 40
3 0 0 4 80
3 0 1 25 16
3 0 2 1 16
3 0 3 29 16
3 0 4 13 16
3 0 5 31 16
3 0 6 13 16
3 0 7 13 16
3 0 8 22 16
3 0 9 14 16
3 0 10 2 16
3 0 11 12 16
3 0 12 14 16
3 0 13 13 16
3 0 14 15 16
3 0 15 17 16
3 0 16 18 16
3 0 17 6 16
3 0 18 19 16
3 0 19 27 16
3 0 20 3 16
3 0 21 28 16
3 0 22 26 16
3 0 23 19 16
3 0 24 29 16
3 0 25 4 16
3 0 26 23 16
3 0 27 9 16
3 0 28 23 16
3 0 29 29 16
3 0 30 10 16
3 0 31 9 16
3 0 32 4 16
3 0 33 5 16
3 0 34 29 16
3 0 35 10 16
3 0 36 4 16
3 0 37 12 16
3 0 38 36 16
3 0 39 6 16
3 0 40 1 16
3 0 41 35 16
3 0 42 1 16
3 0 43 27 16
3 0 44 5 16
3 0 45 4 16
3 0 46 1 16
3 0 47 1 16
3 0 48 1 16
3 0 49 2 16
3 0 50 31 16
3 0 51 20 16
3 0 52 11 16
3 0 53 31 16
3 0 54 25 16
3 0 55 30 16
3 0 56 10 16
3 0 57 4 16
3 0 58 30 16
3 0 59 12 16
3 0 60 13 16
3 0 61 4 16
3 0 62 6 16
3 0 63 34 16
3 0 64 1 16
3 0 65 14 16
3 0 66 12 16
3 0 67 16 16
3 0 68 10 16
3 0 69 21 16
3 0 70 14 16
3 0 71 32 16
3 0 72 14 16
3 0 73 7 16
3 0 74 37 16
3 0 75 10 16
3 0 76 2 16
3 0 77 30 16
3 0 78 30 16
3 0 79 2 16
3 0 80 2 16
3 0 81 23 16
3 0 82 21 16
3 0 83 12 16
3 0 84 28 16
3 0 85 6 16
3 0 86 2 16
3 0 87 9 16
3 0 88 37 16
3 0 89 31 16
3 0 90 11 16
3 0 91 1 16
3 0 92 33 16
3 0 93 8 16
3 0 94 13 16
3 0 95 2 16
3 0 96 22 16
3 0 97 9 16
3 0 98 14 16
3 0 99 6 16
3 0 100 33 16
3 0 101 32 16
3 0 102 30 16
3 0 103 21 16
3 0 104 1 16
3 0 105 13 16
3 0 106 4 16
3 0 107 13 16
3 0 108 4 16
3 0 109 19 16
3 0 110 1 16
3 0 111 10 16
3 0 112 11 16
3 0 113 10 16
3 0 114 34 16
3 0 115 27 16
3 0 116 12 16
3 0 117 34 16
3 0 118 1 16
3 0 119 0 16
3 0 120 13 16
3 0 121 9 16
3 0 122 35 16
3 0 123 27 16
3 0 124 1 16
3 0 125 16 16
3 0 126 13 16
3 0 127 4 16
3 0 128 24 16
3 0 129 4 16
3 0 130 8 16
3 0 131 12 16
3 0 132 31 16
3 0 133 22 16
3 0 134 22 16
3 0 135 14 16
3 0 136 1 16
3 0 137 9 16
3 0 138 16 16
3 0 139 12 16
3 0 140 4 16
3 0 141 31 16
3 0 142 14 16
3 0 143 25 16
3 0 144 23 16
3 0 145 24 16
3 0 146 9 16
3 0 147 20 16
3 0 148 9 16
3 0 149 6 16
3 0 150 9 16
3 0 151 25 16
3 0 152 14 16
3 0 153 11 16
3 0 154 34 16
3 0 155 23 16
3 0 156 14 16
3 0 157 10 16
3 0 158 8 16
3 0 159 14 16
3 0 160 4 16
3 0 161 22 16
3 0 162 8 16
3 0 163 4 16
3 0 164 5 16
3 0 165 17 16
3 0 166 32 16
3 0 167 1 16
3 0 168 27 16
3 0 169 15 16
3 0 170 26 16
3 0 171 2 16
3 0 172 6 16
3 0 173 3 16
3 0 174 2 16
3 0 175 18 16
3 0 176 12 16
3 0 177 8 16
3 0 178 18 16
3 0 179 17 16
3 0 180 36 16
3 0 181 32 16
3 0 182 37 16
3 0 183 16 16
3 0 184 5 16
3 0 185 9 16
3 0 186 6 16
3 0 187 1 16
3 0 188 33 16
3 0 189 4 16
3 0 190 14 16
3 0 191 8 16
3 0 192 1 16
3 0 193 1 16
3 0 194 25 16
3 0 195 10 16
3 0 196 22 16
3 0 197 8 16
3 0 198 1 16
3 0 199 23 16
3 0 200 2 16
3 0 201 24 16
3 0 202 23 16
3 0 203 2 16
3 0 204 14 16
3 0 205 20 16
3 0 206 23 16
3 0 207 9 16
3 0 208 9 16
3 0 209 36 16
3 0 210 0 16
3 0 211 24 16
3 0 212 2 16
3 0 213 14 16
3 0 214 1 16
3 0 215 8 16
3 0 216 1 16
3 0 217 0 16
3 0 218 28 16
3 0 219 32 16
3 0 220 21 16
3 0 221 21 16
3 0 222 1 16
3 0 223 14 16
3 0 224 17 16
3 0 225 13 16
3 0 226 22 16
3 0 227 16 16
3 0 228 13 16
3 0 229 34 16
3 0 230 37 16
3 0 231 15 16
3 0 232 34 16
3 0 233 31 16
3 0 234 6 16
3 0 235 2 16
3 0 236 8 16
3 0 237 22 16
3 0 238 14 16
3 0 239 0 16
3 0 240 10 16
3 0 241 33 16
3 0 242 24 16
3 0 243 26 16
3 0 244 9 16
3 0 245 14 16
3 0 246 25 16
3 0 247 36 16
3 0 248 13 16
3 0 249 27 16
3 0 250 35 16
3 0 251 13 16
3 0 252 35 16
3 0 253 7 16
3 0 254 5 16
3 0 255 15 48
3 1 0 18 64
3 1 1 35 0
3 1 2 22 0
3 1 3 21 0
3 1 4 10 0
3 1 5 9 0
3 1 6 4 0
3 1 7 26 0
3 1 8 23 0
3 1 9 26 0
3 1 10 6 0
3 1 11 5 0
3 1 12 21 0
3 1 13 37 0
3 1 14 19 0
3 1 15 32 0
3 1 16 28 0
3 1 17 1 0
3 1 18 22 0
3 1 19 3 0
3 1 20 27 0
3 1 21 13 0
3 1 22 6 0
3 1 23 25 0
3 1 24 35 0
3 1 25 1 0
3 1 26 14 0
3 1 27 4 0
3 1 28 37 0
3 1 29 23 0
3 1 30 23 0
3 1 31 7 0
3 1 32 8 0
3 1 33 35 0
3 1 34 23 0
3 1 35 12 0
3 1 36 29 0
3 1 37 26 0
3 1 38 31 0
3 1 39 14 0
3 1 40 28 0
3 1 41 6 0
3 1 42 0 0
3 1 43 17 0
3 1 44 10 0
3 1 45 4 0
3 1 46 30 0
3 1 47 6 0
3 1 48 28 0
3 1 49 29 0
3 1 50 21 0
3 1 51 32 0
3 1 52 18 0
3 1 53 26 0
3 1 54 10 0
3 1 55 10 0
3 1 56 11 0
3 1 57 25 0
3 1 58 16 0
3 1 59 5 0
3 1 60 23 0
3 1 61 7 0
3 1 62 36 0
3 1 63 11 0
3 1 64 13 0
3 1 65 32 0
3 1 66 8 0
3 1 67 0 0
3 1 68 13 0
3 1 69 34 0
3 1 70 19 0
3 1 71 21 0
3 1 72 14 0
3 1 73 12 0
3 1 74 4 0
3 1 75 1 0
3 1 76 7 0
3 1 77 11 0
3 1 78 2 0
3 1 79 5 0
3 1 80 12 0
3 1 81 12 0
3 1 82 10 0
3 1 83 7 0
3 1 84 9 0
3 1 85 19 0
3 1 86 29 0
3 1 87 32 0
3 1 88 14 0
3 1 89 27 0
3 1 90 10 0
3 1 91 13 0
3 1 92 2 0
3 1 93 8 0
3 1 94 13 0
3 1 95 5 0
3 1 96 1 0
3 1 97 21 0
3 1 98 14 0
3 1 99 20 0
3 1 100 14 0
3 1 101 27 0
3 1 102 19 0
3 1 103 16 0
3 1 104 2 0
3 1 105 12 0
3 1 106 1 0
3 1 107 26 0
3 1 108 35 0
3 1 109 4 0
3 1 110 12 0
3 1 111 34 0
3 1 112 14 0
3 1 113 21 0
3 1 114 14 0
3 1 115 30 0
3 1 116 25 0
3 1 117 5 0
3 1 118 2 0
3 1 119 31 0
3 1 120 31 0
3 1 121 13 0
3 1 122 36 0
3 1 123 1 0
3 1 124 10 0
3 1 125 30 0
3 1 126 24 0
3 1 127 30 0
3 1 128 32 0
3 1 129 29 0
3 1 130 16 0
3 1 131 12 0
3 1 132 12 0
3 1 133 10 0
3 1 134 1 0
3 1 135 25 0
3 1 136 26 0
3 1 137 32 0
3 1 138 16 0
3 1 139 15 0
3 1 140 4 0
3 1 141 1 0
3 1 142 22 0
3 1 143 10 0
3 1 144 12 0
3 1 145 21 0
3 1 146 28 0
3 1 147 6 0
3 1 148 6 0
3 1 149 8 0
3 1 150 14 0
3 1 151 19 0
3 1 152 33 0
3 1 153 20 0
3 1 154 29 0
3 1 155 10 0
3 1 156 16 0
3 1 157 14 0
3 1 158 14 0
3 1 159 25 0
3 1 160 2 0
3 1 161 14 0
3 1 162 0 0
3 1 163 3 0
3 1 164 9 0
3 1 165 35 0
3 1 166 6 0
3 1 167 6 0
3 1 168 32 0
3 1 169 11 0
3 1 170 14 0
3 1 171 2 0
3 1 172 7 0
3 1 173 4 0
3 1 174 7 0
3 1 175 15 0
3 1 176 36 0
3 1 177 29 0
3 1 178 19 0
3 1 179 19 0
3 1 180 8 0
3 1 181 5 0
3 1 182 35 0
3 1 183 4 0
3 1 184 12 0
3 1 185 29 0
3 1 186 11 0
3 1 187 6 0
3 1 188 0 0
3 1 189 27 0
3 1 190 32 0
3 1 191 7 0
3 1 192 22 0
3 1 193 1 0
3 1 194 2 0
3 1 195 26 0
3 1 196 2 0
3 1 197 23 0
3 1 198 14 0
3 1 199 33 0
3 1 200 25 0
3 1 201 18 0
3 1 202 6 0
3 1 203 20 0
3 1 204 35 0
3 1 205 10 0
3 1 206 31 0
3 1 207 36 0
3 1 208 4 0
3 1 209 1 0
3 1 210 26 0
3 1 211 7 0
3 1 212 26 0
3 1 213 10 0
3 1 214 17 0
3 1 215 4 0
3 1 216 2 0
3 1 217 0 0
3 1 218 33 0
3 1 219 9 0
3 1 220 5 0
3 1 221 25 0
3 1 222 12 0
3 1 223 21 0
3 1 224 16 0
3 1 225 10 0
3 1 226 7 0
3 1 227 12 0
3 1 228 1 0
3 1 229 11 0
3 1 230 11 0
3 1 231 14 0
3 1 232 1 0
3 1 233 6 0
3 1 234 14 0
3 1 235 16 0
3 1 236 1 0
3 1 237 36 0
3 1 238 29 0
3 1 239 6 0
3 1 240 8 0
3 1 241 13 0
3 1 242 11 0
3 1 243 37 0
3 1 244 22 0
3 1 245 14 0
3 1 246 37 0
3 1 247 13 0
3 1 248 12 0
3 1 249 18 0
3 1 250 30 0
3 1 251 7 0
3 1 252 21 0
3 1 253 9 0
3 1 254 3 0
3 1 255 36 32
3 2 0 4 64
3 2 1 12 0
3 2 2 20 0
3 2 3 16 0
3 2 4 10 0
3 2 5 10 0
3 2 6 9 0
3 2 7 2 0
3 2 8 2 0
3 2 9 33 0
3 2 10 14 0
3 2 11 26 0
3 2 12 8 0
3 2 13 37 0
3 2 14 2 0
3 2 15 4 0
3 2 16 32 0
3 2 17 18 0
3 2 18 18 0
3 2 19 22 0
3 2 20 2 0
3 2 21 35 0
3 2 22 17 0
3 2 23 5 0
3 2 24 8 0
3 2 25 17 0
3 2 26 22 0
3 2 27 20 0
3 2 28 7 0
3 2 29 2 0
3 2 30 2 0
3 2 31 26 0
3 2 32 28 0
3 2 33 23 0
3 2 34 32 0
3 2 35 34 0
3 2 36 16 0
3 2 37 13 0
3 2 38 1 0
3 2 39 5 0
3 2 40 14 0
3 2 41 3 0
3 2 42 0 0
3 2 43 14 0
3 2 44 22 0
3 2 45 8 0
3 2 46 27 0
3 2 47 11 0
3 2 48 0 0
3 2 49 19 0
3 2 50 6 0
3 2 51 14 0
3 2 52 1 0
3 2 53 4 0
3 2 54 14 0
3 2 55 20 0
3 2 56 4 0
3 2 57 9 0
3 2 58 1 0
3 2 59 32 0
3 2 60 32 0
3 2 61 4 0
3 2 62 14 0
3 2 63 6 0
3 2 64 26 0
3 2 65 12 0
3 2 66 2 0
3 2 67 37 0
3 2 68 10 0
3 2 69 10 0
3 2 70 26 0
3 2 71 23 0
3 2 72 9 0
3 2 73 6 0
3 2 74 17 0
3 2 75 19 0
3 2 76 3 0
3 2 77 34 0
3 2 78 27 0
3 2 79 6 0
3 2 80 15 0
3 2 81 8 0
3 2 82 29 0
3 2 83 23 0
3 2 84 14 0
3 2 85 22 0
3 2 86 28 0
3 2 87 31 0
3 2 88 36 0
3 2 89 34 0
3 2 90 22 0
3 2 91 5 0
3 2 92 12 0
3 2 93 28 0
3 2 94 30 0
3 2 95 9 0
3 2 96 23 0
3 2 97 10 0
3 2 98 32 0
3 2 99 31 0
3 2 100 19 0
3 2 101 18 0
3 2 102 30 0
3 2 103 20 0
3 2 104 6 0
3 2 105 30 0
3 2 106 14 0
3 2 107 14 0
3 2 108 14 0
3 2 109 14 0
3 2 110 10 0
3 2 111 20 0
3 2 112 10 0
3 2 113 33 0
3 2 114 2 0
3 2 115 35 0
3 2 116 4 0
3 2 117 19 0
3 2 118 8 0
3 2 119 16 0
3 2 120 18 0
3 2 121 9 0
3 2 122 11 0
3 2 123 34 0
3 2 124 20 0
3 2 125 27 0
3 2 126 9 0
3 2 127 32 0
3 2 128 8 0
3 2 129 14 0
3 2 130 15 0
3 2 131 29 0
3 2 132 28 0
3 2 133 8 0
3 2 134 33 0
3 2 135 6 0
3 2 136 1 0
3 2 137 14 0
3 2 138 14 0
3 2 139 24 0
3 2 140 14 0
3 2 141 14 0
3 2 142 10 0
3 2 143 9 0
3 2 144 5 0
3 2 145 2 0
3 2 146 31 0
3 2 147 17 0
3 2 148 3 0
3 2 149 37 0
3 2 150 13 0
3 2 151 36 0
3 2 152 33 0
3 2 153 33 0
3 2 154 16 0
3 2 155 27 0
3 2 156 14 0
3 2 157 32 0
3 2 158 30 0
3 2 159 32 0
3 2 160 34 0
3 2 161 14 0
3 2 162 5 0
3 2 163 8 0
3 2 164 22 0
3 2 165 5 0
3 2 166 2 0
3 2 167 31 0
3 2 168 37 0
3 2 169 29 0
3 2 170 13 0
3 2 171 33 0
3 2 172 27 0
3 2 173 9 0
3 2 174 7 0
3 2 175 2 0
3 2 176 34 0
3 2 177 17 0
3 2 178 9 0
3 2 179 15 0
3 2 180 19 0
3 2 181 8 0
3 2 182 5 0
3 2 183 4 0
3 2 184 8 0
3 2 185 8 0
3 2 186 13 0
3 2 187 10 0
3 2 188 7 0
3 2 189 4 0
3 2 190 32 0
3 2 191 5 0
3 2 192 8 0
3 2 193 1 0
3 2 194 21 0
3 2 195 11 0
3 2 196 5 0
3 2 197 1 0
3 2 198 29 0
3 2 199 29 0
3 2 200 20 0
3 2 201 34 0
3 2 202 19 0
3 2 203 4 0
3 2 204 13 0
3 2 205 22 0
3 2 206 14 0
3 2 207 16 0
3 2 208 6 0
3 2 209 27 0
3 2 210 3 0
3 2 211 3 0
3 2 212 8 0
3 2 213 2 0
3 2 214 17 0
3 2 215 7 0
3 2 216 3 0
3 2 217 6 0
3 2 218 9 0
3 2 219 29 0
3 2 220 13 0
3 2 221 14 0
3 2 222 2 0
3 2 223 30 0
3 2 224 13 0
3 2 225 5 0
3 2 226 27 0
3 2 227 12 0
3 2 228 1 0
3 2 229 26 0
3 2 230 4 0
3 2 231 9 0
3 2 232 1 0
3 2 233 12 0
3 2 234 1 0
3 2 235 14 0
3 2 236 34 0
3 2 237 13 0
3 2 238 19 0
3 2 239 32 0
3 2 240 34 0
3 2 241 10 0
3 2 242 8 0
3 2 243 28 0
3 2 244 36 0
3 2 245 5 0
3 2 246 17 0
3 2 247 22 0
3 2 248 37 0
3 2 249 37 0
3 2 250 21 0
3 2 251 5 0
3 2 252 20 0
3 2 253 2 0
3 2 254 8 0
3 2 255 33 32
3 3 0 35 64
3 3 1 9 0
3 3 2 12 0
3 3 3 23 0
3 3 4 10 0
3 3 5 6 0
3 3 6 9 0
3 3 7 3 0
3 3 8 8 0
3 3 9 8 0
3 3 10 12 0
3 3 11 11 0
3 3 12 8 0
3 3 13 6 0
3 3 14 1 0
3 3 15 1 0
3 3 16 34 0
3 3 17 18 0
3 3 18 22 0
3 3 19 29 0
3 3 20 28 0
3 3 21 27 0
3 3 22 15 0
3 3 23 15 0
3 3 24 16 0
3 3 25 4 0
3 3 26 5 0
3 3 27 26 0
3 3 28 24 0
3 3 29 25 0
3 3 30 1 0
3 3 31 22 0
3 3 32 21 0
3 3 33 33 0
3 3 34 31 0
3 3 35 31 0
3 3 36 7 0
3 3 37 29 0
3 3 38 11 0
3 3 39 19 0
3 3 40 1 0
3 3 41 27 0
3 3 42 8 0
3 3 43 3 0
3 3 44 11 0
3 3 45 4 0
3 3 46 14 0
3 3 47 10 0
3 3 48 35 0
3 3 49 22 0
3 3 50 3 0
3 3 51 5 0
3 3 52 13 0
3 3 53 11 0
3 3 54 25 0
3 3 55 28 0
3 3 56 35 0
3 3 57 12 0
3 3 58 14 0
3 3 59 17 0
3 3 60 13 0
3 3 61 10 0
3 3 62 7 0
3 3 63 37 0
3 3 64 26 0
3 3 65 21 0
3 3 66 12 0
3 3 67 12 0
3 3 68 9 0
3 3 69 24 0
3 3 70 23 0
3 3 71 15 0
3 3 72 24 0
3 3 73 29 0
3 3 74 33 0
3 3 75 33 0
3 3 76 12 0
3 3 77 12 0
3 3 78 8 0
3 3 79 8 0
3 3 80 6 0
3 3 81 26 0
3 3 82 30 0
3 3 83 23 0
3 3 84 19 0
3 3 85 8 0
3 3 86 36 0
3 3 87 14 0
3 3 88 21 0
3 3 89 2 0
3 3 90 7 0
3 3 91 14 0
3 3 92 29 0
3 3 93 34 0
3 3 94 8 0
3 3 95 0 0
3 3 96 33 0
3 3 97 1 0
3 3 98 22 0
3 3 99 19 0
3 3 100 6 0
3 3 101 2 0
3 3 102 2 0
3 3 103 20 0
3 3 104 2 0
3 3 105 28 0
3 3 106 1 0
3 3 107 1 0
3 3 108 7 0
3 3 109 2 0
3 3 110 30 0
3 3 111 26 0
3 3 112 22 0
3 3 113 30 0
3 3 114 21 0
3 3 115 4 0
3 3 116 2 0
3 3 117 20 0
3 3 118 22 0
3 3 119 23 0
3 3 120 7 0
3 3 121 13 0
3 3 122 1 0
3 3 123 32 0
3 3 124 28 0
3 3 125 12 0
3 3 126 17 0
3 3 127 6 0
3 3 128 3 0
3 3 129 26 0
3 3 130 2 0
3 3 131 30 0
3 3 132 33 0
3 3 133 14 0
3 3 134 27 0
3 3 135 10 0
3 3 136 20 0
3 3 137 5 0
3 3 138 28 0
3 3 139 1 0
3 3 140 30 0
3 3 141 1 0
3 3 142 8 0
3 3 143 37 0
3 3 144 0 0
3 3 145 12 0
3 3 146 10 0
3 3 147 9 0
3 3 148 34 0
3 3 149 13 0
3 3 150 13 0
3 3 151 19 0
3 3 152 28 0
3 3 153 14 0
3 3 154 19 0
3 3 155 24 0
3 3 156 8 0
3 3 157 5 0
3 3 158 28 0
3 3 159 10 0
3 3 160 10 0
3 3 161 5 0
3 3 162 13 0
3 3 163 6 0
3 3 164 9 0
3 3 165 9 0
3 3 166 13 0
3 3 167 24 0
3 3 168 11 0
3 3 169 12 0
3 3 170 12 0
3 3 171 33 0
3 3 172 9 0
3 3 173 1 0
3 3 174 27 0
3 3 175 21 0
3 3 176 22 0
3 3 177 8 0
3 3 178 13 0
3 3 179 6 0
3 3 180 7 0
3 3 181 21 0
3 3 182 6 0
3 3 183 10 0
3 3 184 19 0
3 3 185 10 0
3 3 186 35 0
3 3 187 11 0
3 3 188 1 0
3 3 189 35 0
3 3 190 33 0
3 3 191 3 0
3 3 192 9 0
3 3 193 1 0
3 3 194 14 0
3 3 195 17 0
3 3 196 24 0
3 3 197 8 0
3 3 198 0 0
3 3 199 30 0
3 3 200 10 0
3 3 201 34 0
3 3 202 37 0
3 3 203 14 0
3 3 204 7 0
3 3 205 28 0
3 3 206 9 0
3 3 207 7 0
3 3 208 4 0
3 3 209 17 0
3 3 210 1 0
3 3 211 5 0
3 3 212 10 0
3 3 213 32 0
3 3 214 26 0
3 3 215 10 0
3 3 216 12 0
3 3 217 5 0
3 3 218 10 0
3 3 219 26 0
3 3 220 11 0
3 3 221 31 0
3 3 222 13 0
3 3 223 13 0
3 3 224 8 0
3 3 225 18 0
3 3 226 3 0
3 3 227 1 0
3 3 228 2 0
3 3 229 10 0
3 3 230 13 0
3 3 231 14 0
3 3 232 20 0
3 3 233 30 0
3 3 234 30 0
3 3 235 16 0
3 3 236 10 0
3 3 237 35 0
3 3 238 10 0
3 3 239 6 0
3 3 240 27 0
3 3 241 25 0
3 3 242 1 0
3 3 243 20 0
3 3 244 0 0
3 3 245 26 0
3 3 246 13 0
3 3 247 25 0
3 3 248 9 0
3 3 249 19 0
3 3 250 10 0
3 3 251 16 0
3 3 252 6 0
3 3 253 20 0
3 3 254 14 0
3 3 255 25 32
3 4 0 32 72
3 4 1 29 8
3 4 2 25 8
3 4 3 27 8
3 4 4 9 8
3 4 5 3 8
3 4 6 10 8
3 4 7 6 8
3 4 8 4 8
3 4 9 14 8
3 4 10 4 8
3 4 11 6 8
3 4 12 2 8
3 4 13 33 8
3 4 14 1 8
3 4 15 12 8
3 4 16 12 8
3 4 17 13 8
3 4 18 13 8
3 4 19 9 8
3 4 20 8 8
3 4 21 14 8
3 4 22 10 8
3 4 23 14 8
3 4 24 18 8
3 4 25 9 8
3 4 26 1 8
3 4 27 14 8
3 4 28 12 8
3 4 29 14 8
3 4 30 14 8
3 4 31 29 8
3 4 32 1 8
3 4 33 2 8
3 4 34 20 8
3 4 35 35 8
3 4 36 1 8
3 4 37 18 8
3 4 38 3 8
3 4 39 13 8
3 4 40 25 8
3 4 41 7 8
3 4 42 10 8
3 4 43 19 8
3 4 44 29 8
3 4 45 5 8
3 4 46 29 8
3 4 47 14 8
3 4 48 23 8
3 4 49 15 8
3 4 50 33 8
3 4 51 35 8
3 4 52 24 8
3 4 53 5 8
3 4 54 37 8
3 4 55 21 8
3 4 56 1 8
3 4 57 28 8
3 4 58 29 8
3 4 59 10 8
3 4 60 36 8
3 4 61 30 8
3 4 62 12 8
3 4 63 14 8
3 4 64 29 8
3 4 65 23 8
3 4 66 29 8
3 4 67 23 8
3 4 68 14 8
3 4 69 33 8
3 4 70 14 8
3 4 71 8 8
3 4 72 28 8
3 4 73 22 8
3 4 74 31 8
3 4 75 6 8
3 4 76 32 8
3 4 77 28 8
3 4 78 1 8
3 4 79 26 8
3 4 80 25 8
3 4 81 13 8
3 4 82 8 8
3 4 83 35 8
3 4 84 33 8
3 4 85 8 8
3 4 86 14 8
3 4 87 35 8
3 4 88 5 8
3 4 89 12 8
3 4 90 5 8
3 4 91 14 8
3 4 92 19 8
3 4 93 2 8
3 4 94 9 8
3 4 95 12 8
3 4 96 25 8
3 4 97 17 8
3 4 98 18 8
3 4 99 15 8
3 4 100 10 8
3 4 101 21 8
3 4 102 16 8
3 4 103 14 8
3 4 104 28 8
3 4 105 14 8
3 4 106 34 8
3 4 107 0 8
3 4 108 31 8
3 4 109 14 8
3 4 110 2 8
3 4 111 7 8
3 4 112 14 8
3 4 113 18 8
3 4 114 27 8
3 4 115 9 8
3 4 116 15 8
3 4 117 23 8
3 4 118 28 8
3 4 119 15 8
3 4 120 15 8
3 4 121 4 8
3 4 122 27 8
3 4 123 13 8
3 4 124 33 8
3 4 125 1 8
3 4 126 1 8
3 4 127 37 8
3 4 128 17 8
3 4 129 8 8
3 4 130 31 8
3 4 131 12 8
3 4 132 10 8
3 4 133 32 8
3 4 134 6 8
3 4 135 10 8
3 4 136 10 8
3 4 137 9 8
3 4 138 24 8
3 4 139 10 8
3 4 140 22 8
3 4 141 8 8
3 4 142 0 8
3 4 143 37 8
3 4 144 2 8
3 4 145 31 8
3 4 146 10 8
3 4 147 29 8
3 4 148 12 8
3 4 149 5 8
3 4 150 11 8
3 4 151 6 8
3 4 152 11 8
3 4 153 14 8
3 4 154 29 8
3 4 155 11 8
3 4 156 6 8
3 4 157 28 8
3 4 158 25 8
3 4 159 30 8
3 4 160 28 8
3 4 161 5 8
3 4 162 23 8
3 4 163 13 8
3 4 164 17 8
3 4 165 9 8
3 4 166 2 8
3 4 167 1 8
3 4 168 5 8
3 4 169 21 8
3 4 170 32 8
3 4 171 6 8
3 4 172 32 8
3 4 173 5 8
3 4 174 0 8
3 4 175 20 8
3 4 176 37 8
3 4 177 18 8
3 4 178 33 8
3 4 179 22 8
3 4 180 12 8
3 4 181 8 8
3 4 182 30 8
3 4 183 12 8
3 4 184 13 8
3 4 185 23 8
3 4 186 15 8
3 4 187 30 8
3 4 188 5 8
3 4 189 33 8
3 4 190 1 8
3 4 191 31 8
3 4 192 13 8
3 4 193 22 8
3 4 194 28 8
3 4 195 27 8
3 4 196 15 8
3 4 197 25 8
3 4 198 0 8
3 4 199 36 8
3 4 200 1 8
3 4 201 16 8
3 4 202 19 8
3 4 203 13 8
3 4 204 18 8
3 4 205 5 8
3 4 206 3 8
3 4 207 0 8
3 4 208 33 8
3 4 209 25 8
3 4 210 27 8
3 4 211 9 8
3 4 212 8 8
3 4 213 9 8
3 4 214 14 8
3 4 215 36 8
3 4 216 11 8
3 4 217 13 8
3 4 218 8 8
3 4 219 2 8
3 4 220 27 8
3 4 221 31 8
3 4 222 12 8
3 4 223 3 8
3 4 224 37 8
3 4 225 30 8
3 4 226 35 8
3 4 227 27 8
3 4 228 5 8
3 4 229 37 8
3 4 230 13 8
3 4 231 5 8
3 4 232 3 8
3 4 233 22 8
3 4 234 7 8
3 4 235 21 8
3 4 236 20 8
3 4 237 3 8
3 4 238 28 8
3 4 239 2 8
3 4 240 0 8
3 4 241 29 8
3 4 242 21 8
3 4 243 30 8
3 4 244 29 8
3 4 245 9 8
3 4 246 24 8
3 4 247 9 8
3 4 248 18 8
3 4 249 32 8
3 4 250 27 8
3 4 251 9 8
3 4 252 14 8
3 4 253 31 8
3 4 254 29 8
3 4 255 4 40
4 0 0 2 80
4 0 1 1 16
4 0 2 14 16
4 0 3 34 16
4 0 4 37 16
4 0 5 12 16
4 0 6 25 16
4 0 7 3 16
4 0 8 0 16
4 0 9 6 16
4 0 10 14 16
4 0 11 17 16
4 0 12 14 16
4 0 13 8 16
4 0 14 10 16
4 0 15 27 16
4 0 16 10 16
4 0 17 10 16
4 0 18 3 16
4 0 19 13 16
4 0 20 34 16
4 0 21 30 16
4 0 22 23 16
4 0 23 4 16
4 0 24 26 16
4 0 25 34 16
4 0 26 26 16
4 0 27 37 16
4 0 28 14 16
4 0 29 5 16
4 0 30 1 16
4 0 31 12 16
4 0 32 9 16
4 0 33 32 16
4 0 34 28 16
4 0 35 10 16
4 0 36 4 16
4 0 37 25 16
4 0 38 11 16
4 0 39 6 16
4 0 40 34 16
4 0 41 2 16
4 0 42 14 16
4 0 43 14 16
4 0 44 28 16
4 0 45 15 16
4 0 46 1 16
4 0 47 32 16
4 0 48 15 16
4 0 49 5 16
4 0 50 19 16
4 0 51 15 16
4 0 52 15 16
4 0 53 11 16
4 0 54 24 16
4 0 55 14 16
4 0 56 11 16
4 0 57 34 16
4 0 58 37 16
4 0 59 14 16
4 0 60 24 16
4 0 61 26 16
4 0 62 7 16
4 0 63 36 16
4 0 64 4 16
4 0 65 12 16
4 0 66 28 16
4 0 67 23 16
4 0 68 18 16
4 0 69 15 16
4 0 70 15 16
4 0 71 4 16
4 0 72 20 16
4 0 73 27 16
4 0 74 13 16
4 0 75 12 16
4 0 76 0 16
4 0 77 20 16
4 0 78 15 16
4 0 79 8 16
4 0 80 29 16
4 0 81 4 16
4 0 82 8 16
4 0 83 31 16
4 0 84 15 16
4 0 85 13 16
4 0 86 4 16
4 0 87 20 16
4 0 88 14 16
4 0 89 31 16
4 0 90 2 16
4 0 91 36 16
4 0 92 9 16
4 0 93 10 16
4 0 94 4 16
4 0 95 6 16
4 0 96 33 16
4 0 97 33 16
4 0 98 4 16
4 0 99 6 16
4 0 100 26 16
4 0 101 28 16
4 0 102 23 16
4 0 103 1 16
4 0 104 25 16
4 0 105 18 16
4 0 106 1 16
4 0 107 23 16
4 0 108 22 16
4 0 109 15 16
4 0 110 37 16
4 0 111 3 16
4 0 112 12 16
4 0 113 20 16
4 0 114 10 16
4 0 115 9 16
4 0 116 14 16
4 0 117 1 16
4 0 118 30 16
4 0 119 12 16
4 0 120 18 16
4 0 121 14 16
4 0 122 14 16
4 0 123 4 16
4 0 124 2 16
4 0 125 14 16
4 0 126 35 16
4 0 127 17 16
4 0 128 13 16
4 0 129 35 16
4 0 130 36 16
4 0 131 9 16
4 0 132 37 16
4 0 133 2 16
4 0 134 5 16
4 0 135 0 16
4 0 136 2 16
4 0 137 20 16
4 0 138 30 16
4 0 139 2 16
4 0 140 12 16
4 0 141 35 16
4 0 142 12 16
4 0 143 12 16
4 0 144 14 16
4 0 145 5 16
4 0 146 29 16
4 0 147 4 16
4 0 148 9 16
4 0 149 32 16
4 0 150 2 16
4 0 151 30 16
4 0 152 21 16
4 0 153 9 16
4 0 154 28 16
4 0 155 29 16
4 0 156 26 16
4 0 157 10 16
4 0 158 2 16
4 0 159 8 16
4 0 160 14 16
4 0 161 6 16
4 0 162 9 16
4 0 163 27 16
4 0 164 16 16
4 0 165 33 16
4 0 166 24 16
4 0 167 14 16
4 0 168 1 16
4 0 169 4 16
4 0 170 6 16
4 0 171 1 16
4 0 172 14 16
4 0 173 22 16
4 0 174 8 16
4 0 175 11 16
4 0 176 14 16
4 0 177 14 16
4 0 178 13 16
4 0 179 32 16
4 0 180 1 16
4 0 181 3 16
4 0 182 16 16
4 0 183 13 16
4 0 184 13 16
4 0 185 34 16
4 0 186 13 16
4 0 187 11 16
4 0 188 10 16
4 0 189 36 16
4 0 190 10 16
4 0 191 14 16
4 0 192 24 16
4 0 193 8 16
4 0 194 28 16
4 0 195 11 16
4 0 196 1 16
4 0 197 1 16
4 0 198 1 16
4 0 199 9 16
4 0 200 28 16
4 0 201 6 16
4 0 202 14 16
4 0 203 12 16
4 0 204 33 16
4 0 205 22 16
4 0 206 1 16
4 0 207 35 16
4 0 208 0 16
4 0 209 21 16
4 0 210 14 16
4 0 211 29 16
4 0 212 7 16
4 0 213 22 16
4 0 214 28 16
4 0 215 4 16
4 0 216 7 16
4 0 217 29 16
4 0 218 14 16
4 0 219 13 16
4 0 220 0 16
4 0 221 2 16
4 0 222 6 16
4 0 223 13 16
4 0 224 24 16
4 0 225 21 16
4 0 226 19 16
4 0 227 29 16
4 0 228 8 16
4 0 229 31 16
4 0 230 20 16
4 0 231 25 16
4 0 232 13 16
4 0 233 18 16
4 0 234 1 16
4 0 235 8 16
4 0 236 3 16
4 0 237 14 16
4 0 238 2 16
4 0 239 20 16
4 0 240 15 16
4 0 241 21 16
4 0 242 9 16
4 0 243 32 16
4 0 244 8 16
4 0 245 20 16
4 0 246 29 16
4 0 247 9 16
4 0 248 2 16
4 0 249 10 16
4 0 250 23 16
4 0 251 22 16
4 0 252 37 16
4 0 253 9 16
4 0 254 14 16
4 0 255 31 48
4 1 0 37 64
4 1 1 13 0
4 1 2 31 0
4 1 3 6 0
4 1 4 22 0
4 1 5 2 0
4 1 6 18 0
4 1 7 13 0
4 1 8 24 0
4 1 9 24 0
4 1 10 4 0
4 1 11 24 0
4 1 12 2 0
4 1 13 8 0
4 1 14 37 0
4 1 15 35 0
4 1 16 1 0
4 1 17 9 0
4 1 18 9 0
4 1 19 2 0
4 1 20 4 0
4 1 21 7 0
4 1 22 6 0
4 1 23 36 0
4 1 24 28 0
4 1 25 27 0
4 1 26 24 0
4 1 27 19 0
4 1 28 10 0
4 1 29 2 0
4 1 30 6 0
4 1 31 8 0
4 1 32 14 0
4 1 33 27 0
4 1 34 32 0
4 1 35 1 0
4 1 36 15 0
4 1 37 15 0
4 1 38 6 0
4 1 39 20 0
4 1 40 2 0
4 1 41 12 0
4 1 42 6 0
4 1 43 8 0
4 1 44 14 0
4 1 45 7 0
4 1 46 5 0
4 1 47 22 0
4 1 48 6 0
4 1 49 13 0
4 1 50 16 0
4 1 51 9 0
4 1 52 5 0
4 1 53 5 0
4 1 54 26 0
4 1 55 27 0
4 1 56 12 0
4 1 57 6 0
4 1 58 14 0
4 1 59 34 0
4 1 60 18 0
4 1 61 15 0
4 1 62 7 0
4 1 63 19 0
4 1 64 5 0
4 1 65 23 0
4 1 66 0 0
4 1 67 4 0
4 1 68 19 0
4 1 69 17 0
4 1 70 34 0
4 1 71 14 0
4 1 72 14 0
4 1 73 22 0
4 1 74 21 0
4 1 75 5 0
4 1 76 20 0
4 1 77 8 0
4 1 78 14 0
4 1 79 8 0
4 1 80 34 0
4 1 81 1 0
4 1 82 17 0
4 1 83 15 0
4 1 84 9 0
4 1 85 4 0
4 1 86 29 0
4 1 87 5 0
4 1 88 2 0
4 1 89 35 0
4 1 90 9 0
4 1 91 13 0
4 1 92 1 0
4 1 93 9 0
4 1 94 14 0
4 1 95 13 0
4 1 96 25 0
4 1 97 10 0
4 1 98 14 0
4 1 99 28 0
4 1 100 19 0
4 1 101 20 0
4 1 102 14 0
4 1 103 16 0
4 1 104 19 0
4 1 105 1 0
4 1 106 22 0
4 1 107 3 0
4 1 108 5 0
4 1 109 6 0
4 1 110 24 0
4 1 111 37 0
4 1 112 25 0
4 1 113 34 0
4 1 114 11 0
4 1 115 35 0
4 1 116 7 0
4 1 117 14 0
4 1 118 14 0
4 1 119 14 0
4 1 120 35 0
4 1 121 5 0
4 1 122 1 0
4 1 123 29 0
4 1 124 8 0
4 1 125 13 0
4 1 126 2 0
4 1 127 3 0
4 1 128 24 0
4 1 129 9 0
4 1 130 2 0
4 1 131 27 0
4 1 132 4 0
4 1 133 15 0
4 1 134 22 0
4 1 135 25 0
4 1 136 2 0
4 1 137 34 0
4 1 138 15 0
4 1 139 34 0
4 1 140 10 0
4 1 141 6 0
4 1 142 32 0
4 1 143 1 0
4 1 144 6 0
4 1 145 13 0
4 1 146 19 0
4 1 147 3 0
4 1 148 2 0
4 1 149 8 0
4 1 150 36 0
4 1 151 30 0
4 1 152 0 0
4 1 153 1 0
4 1 154 10 0
4 1 155 32 0
4 1 156 11 0
4 1 157 14 0
4 1 158 4 0
4 1 159 25 0
4 1 160 29 0
4 1 161 34 0
4 1 162 8 0
4 1 163 3 0
4 1 164 29 0
4 1 165 9 0
4 1 166 19 0
4 1 167 22 0
4 1 168 5 0
4 1 169 5 0
4 1 170 18 0
4 1 171 12 0
4 1 172 28 0
4 1 173 20 0
4 1 174 37 0
4 1 175 6 0
4 1 176 10 0
4 1 177 0 0
4 1 178 29 0
4 1 179 16 0
4 1 180 22 0
4 1 181 35 0
4 1 182 1 0
4 1 183 15 0
4 1 184 34 0
4 1 185 20 0
4 1 186 17 0
4 1 187 2 0
4 1 188 34 0
4 1 189 20 0
4 1 190 32 0
4 1 191 4 0
4 1 192 25 0
4 1 193 21 0
4 1 194 23 0
4 1 195 5 0
4 1 196 17 0
4 1 197 11 0
4 1 198 10 0
4 1 199 11 0
4 1 200 23 0
4 1 201 2 0
4 1 202 4 0
4 1 203 16 0
4 1 204 25 0
4 1 205 35 0
4 1 206 10 0
4 1 207 8 0
4 1 208 12 0
4 1 209 11 0
4 1 210 2 0
4 1 211 8 0
4 1 212 23 0
4 1 213 26 0
4 1 214 3 0
4 1 215 2 0
4 1 216 5 0
4 1 217 25 0
4 1 218 3 0
4 1 219 8 0
4 1 220 12 0
4 1 221 13 0
4 1 222 24 0
4 1 223 14 0
4 1 224 5 0
4 1 225 6 0
4 1 226 9 0
4 1 227 35 0
4 1 228 29 0
4 1 229 14 0
4 1 230 6 0
4 1 231 3 0
4 1 232 26 0
4 1 233 10 0
4 1 234 31 0
4 1 235 27 0
4 1 236 32 0
4 1 237 2 0
4 1 238 12 0
4 1 239 8 0
4 1 240 37 0
4 1 241 3 0
4 1 242 5 0
4 1 243 28 0
4 1 244 26 0
4 1 245 34 0
4 1 246 5 0
4 1 247 4 0
4 1 248 4 0
4 1 249 25 0
4 1 250 9 0
4 1 251 7 0
4 1 252 20 0
4 1 253 0 0
4 1 254 20 0
4 1 255 22 32
4 2 0 34 64
4 2 1 6 0
4 2 2 2 0
4 2 3 34 0
4 2 4 2 0
4 2 5 14 0
4 2 6 28 0
4 2 7 14 0
4 2 8 14 0
4 2 9 23 0
4 2 10 4 0
4 2 11 31 0
4 2 12 32 0
4 2 13 8 0
4 2 14 33 0
4 2 15 28 0
4 2 16 0 0
4 2 17 6 0
4 2 18 14 0
4 2 19 10 0
4 2 20 25 0
4 2 21 20 0
4 2 22 21 0
4 2 23 33 0
4 2 24 22 0
4 2 25 27 0
4 2 26 2 0
4 2 27 9 0
4 2 28 12 0
4 2 29 18 0
4 2 30 11 0
4 2 31 36 0
4 2 32 12 0
4 2 33 15 0
4 2 34 1 0
4 2 35 0 0
4 2 36 10 0
4 2 37 17 0
4 2 38 13 0
4 2 39 9 0
4 2 40 16 0
4 2 41 28 0
4 2 42 9 0
4 2 43 12 0
4 2 44 32 0
4 2 45 1 0
4 2 46 5 0
4 2 47 32 0
4 2 48 24 0
4 2 49 14 0
4 2 50 22 0
4 2 51 5 0
4 2 52 17 0
4 2 53 2 0
4 2 54 28 0
4 2 55 24 0
4 2 56 6 0
4 2 57 6 0
4 2 58 4 0
4 2 59 8 0
4 2 60 5 0
4 2 61 5 0
4 2 62 10 0
4 2 63 19 0
4 2 64 31 0
4 2 65 14 0
4 2 66 34 0
4 2 67 6 0
4 2 68 25 0
4 2 69 37 0
4 2 70 17 0
4 2 71 13 0
4 2 72 2 0
4 2 73 12 0
4 2 74 15 0
4 2 75 0 0
4 2 76 13 0
4 2 77 14 0
4 2 78 4 0
4 2 79 5 0
4 2 80 14 0
4 2 81 5 0
4 2 82 4 0
4 2 83 32 0
4 2 84 10 0
4 2 85 24 0
4 2 86 16 0
4 2 87 18 0
4 2 88 21 0
4 2 89 10 0
4 2 90 9 0
4 2 91 23 0
4 2 92 12 0
4 2 93 35 0
4 2 94 2 0
4 2 95 10 0
4 2 96 9 0
4 2 97 10 0
4 2 98 1 0
4 2 99 35 0
4 2 100 2 0
4 2 101 4 0
4 2 102 10 0
4 2 103 12 0
4 2 104 18 0
4 2 105 6 0
4 2 106 17 0
4 2 107 1 0
4 2 108 11 0
4 2 109 5 0
4 2 110 27 0
4 2 111 2 0
4 2 112 32 0
4 2 113 24 0
4 2 114 23 0
4 2 115 17 0
4 2 116 10 0
4 2 117 7 0
4 2 118 8 0
4 2 119 10 0
4 2 120 3 0
4 2 121 7 0
4 2 122 13 0
4 2 123 9 0
4 2 124 10 0
4 2 125 34 0
4 2 126 22 0
4 2 127 3 0
4 2 128 10 0
4 2 129 19 0
4 2 130 4 0
4 2 131 24 0
4 2 132 14 0
4 2 133 36 0
4 2 134 2 0
4 2 135 14 0
4 2 136 22 0
4 2 137 27 0
4 2 138 10 0
4 2 139 15 0
4 2 140 35 0
4 2 141 3 0
4 2 142 3 0
4 2 143 15 0
4 2 144 1 0
4 2 145 2 0
4 2 146 16 0
4 2 147 22 0
4 2 148 12 0
4 2 149 27 0
4 2 150 15 0
4 2 151 14 0
4 2 152 19 0
4 2 153 12 0
4 2 154 30 0
4 2 155 9 0
4 2 156 37 0
4 2 157 33 0
4 2 158 5 0
4 2 159 5 0
4 2 160 3 0
4 2 161 20 0
4 2 162 35 0
4 2 163 14 0
4 2 164 14 0
4 2 165 22 0
4 2 166 33 0
4 2 167 13 0
4 2 168 32 0
4 2 169 21 0
4 2 170 16 0
4 2 171 2 0
4 2 172 15 0
4 2 173 2 0
4 2 174 12 0
4 2 175 28 0
4 2 176 37 0
4 2 177 8 0
4 2 178 2 0
4 2 179 9 0
4 2 180 33 0
4 2 181 29 0
4 2 182 16 0
4 2 183 16 0
4 2 184 21 0
4 2 185 9 0
4 2 186 12 0
4 2 187 35 0
4 2 188 10 0
4 2 189 11 0
4 2 190 30 0
4 2 191 18 0
4 2 192 5 0
4 2 193 11 0
4 2 194 28 0
4 2 195 29 0
4 2 196 37 0
4 2 197 12 0
4 2 198 18 0
4 2 199 10 0
4 2 200 18 0
4 2 201 16 0
4 2 202 36 0
4 2 203 29 0
4 2 204 15 0
4 2 205 8 0
4 2 206 1 0
4 2 207 3 0
4 2 208 31 0
4 2 209 17 0
4 2 210 5 0
4 2 211 12 0
4 2 212 27 0
4 2 213 34 0
4 2 214 30 0
4 2 215 6 0
4 2 216 2 0
4 2 217 27 0
4 2 218 28 0
4 2 219 4 0
4 2 220 6 0
4 2 221 31 0
4 2 222 3 0
4 2 223 34 0
4 2 224 6 0
4 2 225 0 0
4 2 226 15 0
4 2 227 26 0
4 2 228 11 0
4 2 229 23 0
4 2 230 21 0
4 2 231 25 0
4 2 232 26 0
4 2 233 25 0
4 2 234 0 0
4 2 235 23 0
4 2 236 9 0
4 2 237 8 0
4 2 238 8 0
4 2 239 12 0
4 2 240 11 0
4 2 241 15 0
4 2 242 1 0
4 2 243 11 0
4 2 244 14 0
4 2 245 28 0
4 2 246 10 0
4 2 247 24 0
4 2 248 2 0
4 2 249 6 0
4 2 250 29 0
4 2 251 4 0
4 2 252 8 0
4 2 253 9 0
4 2 254 21 0
4 2 255 9 32
4 3 0 0 64
4 3 1 28 0
4 3 2 29 0
4 3 3 30 0
4 3 4 22 0
4 3 5 14 0
4 3 6 29 0
4 3 7 32 0
4 3 8 7 0
4 3 9 34 0
4 3 10 18 0
4 3 11 36 0
4 3 12 14 0
4 3 13 14 0
4 3 14 1 0
4 3 15 1 0
4 3 16 28 0
4 3 17 27 0
4 3 18 26 0
4 3 19 22 0
4 3 20 27 0
4 3 21 2 0
4 3 22 24 0
4 3 23 22 0
4 3 24 16 0
4 3 25 9 0
4 3 26 34 0
4 3 27 1 0
4 3 28 7 0
4 3 29 2 0
4 3 30 8 0
4 3 31 23 0
4 3 32 36 0
4 3 33 6 0
4 3 34 19 0
4 3 35 24 0
4 3 36 13 0
4 3 37 14 0
4 3 38 37 0
4 3 39 24 0
4 3 40 18 0
4 3 41 2 0
4 3 42 31 0
4 3 43 26 0
4 3 44 6 0
4 3 45 8 0
4 3 46 21 0
4 3 47 13 0
4 3 48 32 0
4 3 49 0 0
4 3 50 27 0
4 3 51 15 0
4 3 52 10 0
4 3 53 19 0
4 3 54 12 0
4 3 55 5 0
4 3 56 14 0
4 3 57 6 0
4 3 58 9 0
4 3 59 12 0
4 3 60 34 0
4 3 61 15 0
4 3 62 22 0
4 3 63 5 0
4 3 64 9 0
4 3 65 28 0
4 3 66 23 0
4 3 67 25 0
4 3 68 23 0
4 3 69 37 0
4 3 70 4 0
4 3 71 1 0
4 3 72 11 0
4 3 73 11 0
4 3 74 29 0
4 3 75 19 0
4 3 76 2 0
4 3 77 35 0
4 3 78 4 0
4 3 79 13 0
4 3 80 10 0
4 3 81 8 0
4 3 82 1 0
4 3 83 2 0
4 3 84 5 0
4 3 85 25 0
4 3 86 35 0
4 3 87 14 0
4 3 88 2 0
4 3 89 29 0
4 3 90 22 0
4 3 91 10 0
4 3 92 4 0
4 3 93 32 0
4 3 94 17 0
4 3 95 13 0
4 3 96 27 0
4 3 97 29 0
4 3 98 10 0
4 3 99 10 0
4 3 100 37 0
4 3 101 2 0
4 3 102 31 0
4 3 103 17 0
4 3 104 10 0
4 3 105 14 0
4 3 106 28 0
4 3 107 5 0
4 3 108 2 0
4 3 109 22 0
4 3 110 23 0
4 3 111 2 0
4 3 112 28 0
4 3 113 35 0
4 3 114 1 0
4 3 115 12 0
4 3 116 9 0
4 3 117 30 0
4 3 118 3 0
4 3 119 1 0
4 3 120 7 0
4 3 121 4 0
4 3 122 5 0
4 3 123 36 0
4 3 124 9 0
4 3 125 14 0
4 3 126 8 0
4 3 127 13 0
4 3 128 17 0
4 3 129 35 0
4 3 130 10 0
4 3 131 28 0
4 3 132 5 0
4 3 133 5 0
4 3 134 11 0
4 3 135 7 0
4 3 136 28 0
4 3 137 23 0
4 3 138 28 0
4 3 139 5 0
4 3 140 18 0
4 3 141 14 0
4 3 142 12 0
4 3 143 34 0
4 3 144 24 0
4 3 145 5 0
4 3 146 36 0
4 3 147 0 0
4 3 148 7 0
4 3 149 14 0
4 3 150 37 0
4 3 151 5 0
4 3 152 21 0
4 3 153 13 0
4 3 154 12 0
4 3 155 17 0
4 3 156 21 0
4 3 157 20 0
4 3 158 14 0
4 3 159 14 0
4 3 160 14 0
4 3 161 28 0
4 3 162 2 0
4 3 163 6 0
4 3 164 25 0
4 3 165 36 0
4 3 166 26 0
4 3 167 7 0
4 3 168 29 0
4 3 169 2 0
4 3 170 32 0
4 3 171 12 0
4 3 172 26 0
4 3 173 8 0
4 3 174 0 0
4 3 175 4 0
4 3 176 33 0
4 3 177 19 0
4 3 178 33 0
4 3 179 6 0
4 3 180 17 0
4 3 181 12 0
4 3 182 13 0
4 3 183 2 0
4 3 184 1 0
4 3 185 11 0
4 3 186 10 0
4 3 187 16 0
4 3 188 25 0
4 3 189 14 0
4 3 190 1 0
4 3 191 4 0
4 3 192 11 0
4 3 193 25 0
4 3 194 1 0
4 3 195 20 0
4 3 196 1 0
4 3 197 10 0
4 3 198 10 0
4 3 199 0 0
4 3 200 37 0
4 3 201 37 0
4 3 202 24 0
4 3 203 5 0
4 3 204 3 0
4 3 205 10 0
4 3 206 14 0
4 3 207 19 0
4 3 208 35 0
4 3 209 8 0
4 3 210 8 0
4 3 211 12 0
4 3 212 14 0
4 3 213 32 0
4 3 214 4 0
4 3 215 26 0
4 3 216 37 0
4 3 217 14 0
4 3 218 7 0
4 3 219 20 0
4 3 220 34 0
4 3 221 16 0
4 3 222 23 0
4 3 223 15 0
4 3 224 14 0
4 3 225 9 0
4 3 226 5 0
4 3 227 22 0
4 3 228 6 0
4 3 229 4 0
4 3 230 23 0
4 3 231 1 0
4 3 232 26 0
4 3 233 3 0
4 3 234 23 0
4 3 235 30 0
4 3 236 14 0
4 3 237 24 0
4 3 238 4 0
4 3 239 6 0
4 3 240 12 0
4 3 241 15 0
4 3 242 13 0
4 3 243 8 0
4 3 244 4 0
4 3 245 36 0
4 3 246 14 0
4 3 247 2 0
4 3 248 27 0
4 3 249 5 0
4 3 250 5 0
4 3 251 22 0
4 3 252 30 0
4 3 253 4 0
4 3 254 18 0
4 3 255 24 32
4 4 0 15 72
4 4 1 3 8
4 4 2 12 8
4 4 3 9 8
4 4 4 6 8
4 4 5 32 8
4 4 6 25 8
4 4 7 24 8
4 4 8 35 8
4 4 9 31 8
4 4 10 24 8
4 4 11 13 8
4 4 12 3 8
4 4 13 27 8
4 4 14 36 8
4 4 15 37 8
4 4 16 20 8
4 4 17 14 8
4 4 18 13 8
4 4 19 4 8
4 4 20 5 8
4 4 21 26 8
4 4 22 6 8
4 4 23 14 8
4 4 24 0 8
4 4 25 21 8
4 4 26 24 8
4 4 27 15 8
4 4 28 35 8
4 4 29 7 8
4 4 30 0 8
4 4 31 2 8
4 4 32 22 8
4 4 33 14 8
4 4 34 7 8
4 4 35 10 8
4 4 36 4 8
4 4 37 13 8
4 4 38 35 8
4 4 39 12 8
4 4 40 9 8
4 4 41 19 8
4 4 42 9 8
4 4 43 22 8
4 4 44 33 8
4 4 45 2 8
4 4 46 8 8
4 4 47 28 8
4 4 48 1 8
4 4 49 12 8
4 4 50 15 8
4 4 51 14 8
4 4 52 28 8
4 4 53 17 8
4 4 54 14 8
4 4 55 33 8
4 4 56 4 8
4 4 57 35 8
4 4 58 8 8
4 4 59 10 8
4 4 60 22 8
4 4 61 0 8
4 4 62 36 8
4 4 63 8 8
4 4 64 15 8
4 4 65 11 8
4 4 66 10 8
4 4 67 12 8
4 4 68 26 8
4 4 69 8 8
4 4 70 18 8
4 4 71 3 8
4 4 72 23 8
4 4 73 11 8
4 4 74 6 8
4 4 75 26 8
4 4 76 5 8
4 4 77 26 8
4 4 78 15 8
4 4 79 23 8
4 4 80 14 8
4 4 81 34 8
4 4 82 33 8
4 4 83 23 8
4 4 84 1 8
4 4 85 1 8
4 4 86 1 8
4 4 87 33 8
4 4 88 32 8
4 4 89 35 8
4 4 90 14 8
4 4 91 10 8
4 4 92 36 8
4 4 93 20 8
4 4 94 27 8
4 4 95 9 8
4 4 96 5 8
4 4 97 10 8
4 4 98 12 8
4 4 99 35 8
4 4 100 24 8
4 4 101 27 8
4 4 102 6 8
4 4 103 7 8
4 4 104 5 8
4 4 105 16 8
4 4 106 4 8
4 4 107 37 8
4 4 108 2 8
4 4 109 13 8
4 4 110 13 8
4 4 111 15 8
4 4 112 23 8
4 4 113 11 8
4 4 114 14 8
4 4 115 13 8
4 4 116 16 8
4 4 117 5 8
4 4 118 25 8
4 4 119 22 8
4 4 120 33 8
4 4 121 35 8
4 4 122 14 8
4 4 123 5 8
4 4 124 10 8
4 4 125 1 8
4 4 126 10 8
4 4 127 9 8
4 4 128 3 8
4 4 129 20 8
4 4 130 35 8
4 4 131 4 8
4 4 132 17 8
4 4 133 8 8
4 4 134 10 8
4 4 135 34 8
4 4 136 32 8
4 4 137 4 8
4 4 138 35 8
4 4 139 27 8
4 4 140 20 8
4 4 141 1 8
4 4 142 1 8
4 4 143 4 8
4 4 144 33 8
4 4 145 28 8
4 4 146 29 8
4 4 147 11 8
4 4 148 17 8
4 4 149 23 8
4 4 150 10 8
4 4 151 17 8
4 4 152 2 8
4 4 153 2 8
4 4 154 6 8
4 4 155 8 8
4 4 156 20 8
4 4 157 23 8
4 4 158 5 8
4 4 159 4 8
4 4 160 8 8
4 4 161 1 8
4 4 162 30 8
4 4 163 12 8
4 4 164 33 8
4 4 165 18 8
4 4 166 13 8
4 4 167 6 8
4 4 168 35 8
4 4 169 14 8
4 4 170 15 8
4 4 171 9 8
4 4 172 0 8
4 4 173 2 8
4 4 174 19 8
4 4 175 30 8
4 4 176 21 8
4 4 177 26 8
4 4 178 1 8
4 4 179 26 8
4 4 180 16 8
4 4 181 6 8
4 4 182 13 8
4 4 183 15 8
4 4 184 34 8
4 4 185 2 8
4 4 186 1 8
4 4 187 4 8
4 4 188 11 8
4 4 189 33 8
4 4 190 24 8
4 4 191 1 8
4 4 192 36 8
4 4 193 5 8
4 4 194 34 8
4 4 195 33 8
4 4 196 7 8
4 4 197 24 8
4 4 198 34 8
4 4 199 29 8
4 4 200 19 8
4 4 201 20 8
4 4 202 2 8
4 4 203 26 8
4 4 204 10 8
4 4 205 0 8
4 4 206 13 8
4 4 207 8 8
4 4 208 9 8
4 4 209 34 8
4 4 210 8 8
4 4 211 33 8
4 4 212 24 8
4 4 213 2 8
4 4 214 34 8
4 4 215 17 8
4 4 216 22 8
4 4 217 10 8
4 4 218 7 8
4 4 219 36 8
4 4 220 25 8
4 4 221 10 8
4 4 222 2 8
4 4 223 25 8
4 4 224 5 8
4 4 225 26 8
4 4 226 14 8
4 4 227 4 8
4 4 228 33 8
4 4 229 2 8
4 4 230 30 8
4 4 231 9 8
4 4 232 22 8
4 4 233 13 8
4 4 234 33 8
4 4 235 29 8
4 4 236 30 8
4 4 237 6 8
4 4 238 6 8
4 4 239 1 8
4 4 240 8 8
4 4 241 5 8
4 4 242 33 8
4 4 243 16 8
4 4 244 4 8
4 4 245 1 8
4 4 246 1 8
4 4 247 34 8
4 4 248 14 8
4 4 249 32 8
4 4 250 10 8
4 4 251 30 8
4 4 252 32 8
4 4 253 13 8
4 4 254 14 8
4 4 255 25 40
5 0 0 9 80
5 0 1 19 16
5 0 2 9 16
5 0 3 23 16
5 0 4 36 16
5 0 5 14 16
5 0 6 37 16
5 0 7 8 16
5 0 8 28 16
5 0 9 18 16
5 0 10 20 16
5 0 11 1 16
5 0 12 19 16
5 0 13 2 16
5 0 14 3 16
5 0 15 2 16
5 0 16 1 16
5 0 17 11 16
5 0 18 17 16
5 0 19 2 16
5 0 20 17 16
5 0 21 25 16
5 0 22 35 16
5 0 23 14 16
5 0 24 27 16
5 0 25 8 16
5 0 26 20 16
5 0 27 18 16
5 0 28 34 16
5 0 29 14 16
5 0 30 22 16
5 0 31 5 16
5 0 32 4 16
5 0 33 24 16
5 0 34 37 16
5 0 35 9 16
5 0 36 13 16
5 0 37 1 16
5 0 38 4 16
5 0 39 13 16
5 0 40 37 16
5 0 41 7 16
5 0 42 10 16
5 0 43 14 16
5 0 44 36 16
5 0 45 10 16
5 0 46 26 16
5 0 47 11 16
5 0 48 14 16
5 0 49 23 16
5 0 50 33 16
5 0 51 34 16
5 0 52 8 16
5 0 53 13 16
5 0 54 12 16
5 0 55 1 16
5 0 56 8 16
5 0 57 15 16
5 0 58 12 16
5 0 59 17 16
5 0 60 21 16
5 0 61 7 16
5 0 62 26 16
5 0 63 24 16
5 0 64 21 16
5 0 65 27 16
5 0 66 4 16
5 0 67 8 16
5 0 68 30 16
5 0 69 29 16
5 0 70 6 16
5 0 71 0 16
5 0 72 36 16
5 0 73 15 16
5 0 74 27 16
5 0 75 20 16
5 0 76 30 16
5 0 77 20 16
5 0 78 12 16
5 0 79 20 16
5 0 80 23 16
5 0 81 27 16
5 0 82 33 16
5 0 83 35 16
5 0 84 17 16
5 0 85 5 16
5 0 86 29 16
5 0 87 22 16
5 0 88 6 16
5 0 89 7 16
5 0 90 25 16
5 0 91 37 16
5 0 92 24 16
5 0 93 2 16
5 0 94 29 16
5 0 95 20 16
5 0 96 20 16
5 0 97 10 16
5 0 98 11 16
5 0 99 14 16
5 0 100 1 16
5 0 101 35 16
5 0 102 31 16
5 0 103 6 16
5 0 104 5 16
5 0 105 23 16
5 0 106 32 16
5 0 107 5 16
5 0 108 3 16
5 0 109 14 16
5 0 110 35 16
5 0 111 18 16
5 0 112 19 16
5 0 113 5 16
5 0 114 14 16
5 0 115 24 16
5 0 116 4 16
5 0 117 3 16
5 0 118 28 16
5 0 119 10 16
5 0 120 14 16
5 0 121 16 16
5 0 122 9 16
5 0 123 6 16
5 0 124 6 16
5 0 125 9 16
5 0 126 18 16
5 0 127 23 16
5 0 128 1 16
5 0 129 31 16
5 0 130 23 16
5 0 131 4 16
5 0 132 14 16
5 0 133 8 16
5 0 134 5 16
5 0 135 30 16
5 0 136 26 16
5 0 137 14 16
5 0 138 14 16
5 0 139 15 16
5 0 140 25 16
5 0 141 34 16
5 0 142 9 16
5 0 143 23 16
5 0 144 14 16
5 0 145 3 16
5 0 146 6 16
5 0 147 12 16
5 0 148 9 16
5 0 149 7 16
5 0 150 31 16
5 0 151 24 16
5 0 152 8 16
5 0 153 4 16
5 0 154 3 16
5 0 155 20 16
5 0 156 13 16
5 0 157 8 16
5 0 158 33 16
5 0 159 21 16
5 0 160 31 16
5 0 161 12 16
5 0 162 27 16
5 0 163 11 16
5 0 164 30 16
5 0 165 21 16
5 0 166 12 16
5 0 167 7 16
5 0 168 12 16
5 0 169 34 16
5 0 170 26 16
5 0 171 12 16
5 0 172 26 16
5 0 173 8 16
5 0 174 22 16
5 0 175 25 16
5 0 176 22 16
5 0 177 22 16
5 0 178 4 16
5 0 179 14 16
5 0 180 36 16
5 0 181 36 16
5 0 182 34 16
5 0 183 12 16
5 0 184 6 16
5 0 185 10 16
5 0 186 18 16
5 0 187 6 16
5 0 188 1 16
5 0 189 37 16
5 0 190 24 16
5 0 191 33 16
5 0 192 27 16
5 0 193 13 16
5 0 194 13 16
5 0 195 30 16
5 0 196 4 16
5 0 197 1 16
5 0 198 17 16
5 0 199 20 16
5 0 200 7 16
5 0 201 1 16
5 0 202 33 16
5 0 203 22 16
5 0 204 34 16
5 0 205 29 16
5 0 206 36 16
5 0 207 8 16
5 0 208 11 16
5 0 209 16 16
5 0 210 13 16
5 0 211 17 16
5 0 212 23 16
5 0 213 6 16
5 0 214 14 16
5 0 215 36 16
5 0 216 20 16
5 0 217 36 16
5 0 218 10 16
5 0 219 12 16
5 0 220 37 16
5 0 221 35 16
5 0 222 11 16
5 0 223 35 16
5 0 224 7 16
5 0 225 9 16
5 0 226 4 16
5 0 227 9 16
5 0 228 11 16
5 0 229 3 16
5 0 230 36 16
5 0 231 30 16
5 0 232 26 16
5 0 233 6 16
5 0 234 5 16
5 0 235 28 16
5 0 236 27 16
5 0 237 28 16
5 0 238 9 16
5 0 239 10 16
5 0 240 33 16
5 0 241 1 16
5 0 242 23 16
5 0 243 14 16
5 0 244 14 16
5 0 245 15 16
5 0 246 3 16
5 0 247 24 16
5 0 248 14 16
5 0 249 19 16
5 0 250 36 16
5 0 251 16 16
5 0 252 5 16
5 0 253 25 16
5 0 254 5 16
5 0 255 1 48
5 1 0 1 64
5 1 1 30 0
5 1 2 14 0
5 1 3 7 0
5 1 4 2 0
5 1 5 19 0
5 1 6 13 0
5 1 7 0 0
5 1 8 22 0
5 1 9 16 0
5 1 10 2 0
5 1 11 7 0
5 1 12 33 0
5 1 13 28 0
5 1 14 8 0
5 1 15 23 0
5 1 16 31 0
5 1 17 3 0
5 1 18 12 0
5 1 19 5 0
5 1 20 26 0
5 1 21 7 0
5 1 22 4 0
5 1 23 32 0
5 1 24 6 0
5 1 25 6 0
5 1 26 5 0
5 1 27 15 0
5 1 28 6 0
5 1 29 30 0
5 1 30 18 0
5 1 31 35 0
5 1 32 24 0
5 1 33 36 0
5 1 34 33 0
5 1 35 6 0
5 1 36 29 0
5 1 37 34 0
5 1 38 22 0
5 1 39 13 0
5 1 40 5 0
5 1 41 4 0
5 1 42 4 0
5 1 43 15 0
5 1 44 37 0
5 1 45 19 0
5 1 46 13 0
5 1 47 2 0
5 1 48 30 0
5 1 49 29 0
5 1 50 7 0
5 1 51 2 0
5 1 52 8 0
5 1 53 26 0
5 1 54 30 0
5 1 55 24 0
5 1 56 37 0
5 1 57 12 0
5 1 58 9 0
5 1 59 5 0
5 1 60 6 0
5 1 61 10 0
5 1 62 9 0
5 1 63 14 0
5 1 64 31 0
5 1 65 34 0
5 1 66 1 0
5 1 67 6 0
5 1 68 17 0
5 1 69 2 0
5 1 70 16 0
5 1 71 7 0
5 1 72 10 0
5 1 73 30 0
5 1 74 10 0
5 1 75 1 0
5 1 76 13 0
5 1 77 34 0
5 1 78 10 0
5 1 79 13 0
5 1 80 22 0
5 1 81 15 0
5 1 82 10 0
5 1 83 34 0
5 1 84 24 0
5 1 85 14 0
5 1 86 10 0
5 1 87 9 0
5 1 88 15 0
5 1 89 37 0
5 1 90 5 0
5 1 91 30 0
5 1 92 18 0
5 1 93 37 0
5 1 94 14 0
5 1 95 22 0
5 1 96 19 0
5 1 97 10 0
5 1 98 15 0
5 1 99 18 0
5 1 100 35 0
5 1 101 26 0
5 1 102 10 0
5 1 103 14 0
5 1 104 26 0
5 1 105 1 0
5 1 106 2 0
5 1 107 3 0
5 1 108 14 0
5 1 109 3 0
5 1 110 6 0
5 1 111 14 0
5 1 112 26 0
5 1 113 14 0
5 1 114 20 0
5 1 115 22 0
5 1 116 10 0
5 1 117 27 0
5 1 118 7 0
5 1 119 20 0
5 1 120 10 0
5 1 121 14 0
5 1 122 4 0
5 1 123 10 0
5 1 124 6 0
5 1 125 9 0
5 1 126 34 0
5 1 127 35 0
5 1 128 14 0
5 1 129 10 0
5 1 130 18 0
5 1 131 23 0
5 1 132 8 0
5 1 133 6 0
5 1 134 37 0
5 1 135 5 0
5 1 136 3 0
5 1 137 24 0
5 1 138 4 0
5 1 139 26 0
5 1 140 15 0
5 1 141 31 0
5 1 142 30 0
5 1 143 29 0
5 1 144 17 0
5 1 145 5 0
5 1 146 6 0
5 1 147 6 0
5 1 148 6 0
5 1 149 2 0
5 1 150 4 0
5 1 151 21 0
5 1 152 14 0
5 1 153 29 0
5 1 154 9 0
5 1 155 9 0
5 1 156 37 0
5 1 157 15 0
5 1 158 3 0
5 1 159 31 0
5 1 160 12 0
5 1 161 14 0
5 1 162 8 0
5 1 163 23 0
5 1 164 32 0
5 1 165 4 0
5 1 166 5 0
5 1 167 7 0
5 1 168 31 0
5 1 169 4 0
5 1 170 31 0
5 1 171 27 0
5 1 172 32 0
5 1 173 27 0
5 1 174 5 0
5 1 175 10 0
5 1 176 27 0
5 1 177 10 0
5 1 178 21 0
5 1 179 4 0
5 1 180 8 0
5 1 181 4 0
5 1 182 26 0
5 1 183 2 0
5 1 184 12 0
5 1 185 11 0
5 1 186 20 0
5 1 187 23 0
5 1 188 13 0
5 1 189 20 0
5 1 190 34 0
5 1 191 21 0
5 1 192 36 0
5 1 193 19 0
5 1 194 16 0
5 1 195 27 0
5 1 196 14 0
5 1 197 16 0
5 1 198 14 0
5 1 199 15 0
5 1 200 21 0
5 1 201 19 0
5 1 202 34 0
5 1 203 20 0
5 1 204 3 0
5 1 205 24 0
5 1 206 30 0
5 1 207 25 0
5 1 208 11 0
5 1 209 30 0
5 1 210 16 0
5 1 211 22 0
5 1 212 17 0
5 1 213 8 0
5 1 214 4 0
5 1 215 25 0
5 1 216 2 0
5 1 217 25 0
5 1 218 28 0
5 1 219 14 0
5 1 220 4 0
5 1 221 17 0
5 1 222 24 0
5 1 223 20 0
5 1 224 15 0
5 1 225 29 0
5 1 226 37 0
5 1 227 29 0
5 1 228 5 0
5 1 229 13 0
5 1 230 14 0
5 1 231 17 0
5 1 232 2 0
5 1 233 37 0
5 1 234 18 0
5 1 235 6 0
5 1 236 13 0
5 1 237 4 0
5 1 238 10 0
5 1 239 0 0
5 1 240 35 0
5 1 241 3 0
5 1 242 32 0
5 1 243 9 0
5 1 244 20 0
5 1 245 25 0
5 1 246 20 0
5 1 247 14 0
5 1 248 20 0
5 1 249 24 0
5 1 250 30 0
5 1 251 15 0
5 1 252 37 0
5 1 253 10 0
5 1 254 11 0
5 1 255 6 32
5 2 0 34 64
5 2 1 2 0
5 2 2 34 0
5 2 3 18 0
5 2 4 26 0
5 2 5 4 0
5 2 6 3 0
5 2 7 15 0
5 2 8 14 0
5 2 9 10 0
5 2 10 35 0
5 2 11 11 0
5 2 12 6 0
5 2 13 32 0
5 2 14 10 0
5 2 15 6 0
5 2 16 5 0
5 2 17 6 0
5 2 18 22 0
5 2 19 17 0
5 2 20 1 0
5 2 21 25 0
5 2 22 7 0
5 2 23 11 0
5 2 24 29 0
5 2 25 12 0
5 2 26 35 0
5 2 27 16 0
5 2 28 2 0
5 2 29 20 0
5 2 30 17 0
5 2 31 30 0
5 2 32 2 0
5 2 33 9 0
5 2 34 31 0
5 2 35 8 0
5 2 36 33 0
5 2 37 36 0
5 2 38 9 0
5 2 39 29 0
5 2 40 15 0
5 2 41 25 0
5 2 42 6 0
5 2 43 22 0
5 2 44 33 0
5 2 45 36 0
5 2 46 21 0
5 2 47 15 0
5 2 48 5 0
5 2 49 18 0
5 2 50 36 0
5 2 51 1 0
5 2 52 9 0
5 2 53 25 0
5 2 54 22 0
5 2 55 7 0
5 2 56 1 0
5 2 57 6 0
5 2 58 23 0
5 2 59 8 0
5 2 60 31 0
5 2 61 14 0
5 2 62 19 0
5 2 63 15 0
5 2 64 18 0
5 2 65 16 0
5 2 66 4 0
5 2 67 17 0
5 2 68 19 0
5 2 69 14 0
5 2 70 13 0
5 2 71 1 0
5 2 72 25 0
5 2 73 24 0
5 2 74 1 0
5 2 75 23 0
5 2 76 19 0
5 2 77 23 0
5 2 78 31 0
5 2 79 12 0
5 2 80 34 0
5 2 81 1 0
5 2 82 4 0
5 2 83 26 0
5 2 84 5 0
5 2 85 31 0
5 2 86 14 0
5 2 87 19 0
5 2 88 9 0
5 2 89 18 0
5 2 90 21 0
5 2 91 18 0
5 2 92 6 0
5 2 93 10 0
5 2 94 2 0
5 2 95 14 0
5 2 96 2 0
5 2 97 20 0
5 2 98 17 0
5 2 99 3 0
5 2 100 18 0
5 2 101 10 0
5 2 102 10 0
5 2 103 0 0
5 2 104 12 0
5 2 105 4 0
5 2 106 25 0
5 2 107 18 0
5 2 108 8 0
5 2 109 12 0
5 2 110 36 0
5 2 111 22 0
5 2 112 9 0
5 2 113 2 0
5 2 114 17 0
5 2 115 8 0
5 2 116 19 0
5 2 117 28 0
5 2 118 1 0
5 2 119 29 0
5 2 120 11 0
5 2 121 2 0
5 2 122 12 0
5 2 123 26 0
5 2 124 0 0
5 2 125 37 0
5 2 126 25 0
5 2 127 11 0
5 2 128 2 0
5 2 129 14 0
5 2 130 26 0
5 2 131 4 0
5 2 132 8 0
5 2 133 12 0
5 2 134 6 0
5 2 135 14 0
5 2 136 11 0
5 2 137 12 0
5 2 138 33 0
5 2 139 33 0
5 2 140 14 0
5 2 141 12 0
5 2 142 24 0
5 2 143 6 0
5 2 144 8 0
5 2 145 20 0
5 2 146 35 0
5 2 147 21 0
5 2 148 13 0
5 2 149 3 0
5 2 150 33 0
5 2 151 13 0
5 2 152 4 0
5 2 153 20 0
5 2 154 5 0
5 2 155 7 0
5 2 156 32 0
5 2 157 21 0
5 2 158 36 0
5 2 159 30 0
5 2 160 27 0
5 2 161 35 0
5 2 162 5 0
5 2 163 4 0
5 2 164 33 0
5 2 165 6 0
5 2 166 30 0
5 2 167 31 0
5 2 168 10 0
5 2 169 4 0
5 2 170 31 0
5 2 171 27 0
5 2 172 14 0
5 2 173 31 0
5 2 174 10 0
5 2 175 2 0
5 2 176 6 0
5 2 177 1 0
5 2 178 2 0
5 2 179 14 0
5 2 180 14 0
5 2 181 15 0
5 2 182 26 0
5 2 183 18 0
5 2 184 24 0
5 2 185 2 0
5 2 186 31 0
5 2 187 28 0
5 2 188 15 0
5 2 189 2 0
5 2 190 15 0
5 2 191 28 0
5 2 192 32 0
5 2 193 6 0
5 2 194 7 0
5 2 195 34 0
5 2 196 26 0
5 2 197 23 0
5 2 198 33 0
5 2 199 33 0
5 2 200 35 0
5 2 201 34 0
5 2 202 20 0
5 2 203 14 0
5 2 204 4 0
5 2 205 6 0
5 2 206 23 0
5 2 207 6 0
5 2 208 26 0
5 2 209 5 0
5 2 210 18 0
5 2 211 5 0
5 2 212 27 0
5 2 213 2 0
5 2 214 21 0
5 2 215 0 0
5 2 216 19 0
5 2 217 34 0
5 2 218 29 0
5 2 219 5 0
5 2 220 10 0
5 2 221 11 0
5 2 222 21 0
5 2 223 7 0
5 2 224 20 0
5 2 225 14 0
5 2 226 8 0
5 2 227 21 0
5 2 228 14 0
5 2 229 14 0
5 2 230 12 0
5 2 231 10 0
5 2 232 12 0
5 2 233 0 0
5 2 234 36 0
5 2 235 0 0
5 2 236 27 0
5 2 237 25 0
5 2 238 21 0
5 2 239 21 0
5 2 240 9 0
5 2 241 24 0
5 2 242 21 0
5 2 243 5 0
5 2 244 12 0
5 2 245 18 0
5 2 246 29 0
5 2 247 6 0
5 2 248 11 0
5 2 249 13 0
5 2 250 1 0
5 2 251 21 0
5 2 252 37 0
5 2 253 23 0
5 2 254 13 0
5 2 255 14 32
5 3 0 13 64
5 3 1 8 0
5 3 2 9 0
5 3 3 28 0
5 3 4 20 0
5 3 5 18 0
5 3 6 14 0
5 3 7 5 0
5 3 8 24 0
5 3 9 8 0
5 3 10 26 0
5 3 11 13 0
5 3 12 35 0
5 3 13 19 0
5 3 14 33 0
5 3 15 14 0
5 3 16 18 0
5 3 17 28 0
5 3 18 12 0
5 3 19 21 0
5 3 20 10 0
5 3 21 1 0
5 3 22 10 0
5 3 23 12 0
5 3 24 1 0
5 3 25 18 0
5 3 26 4 0
5 3 27 9 0
5 3 28 29 0
5 3 29 13 0
5 3 30 13 0
5 3 31 10 0
5 3 32 19 0
5 3 33 14 0
5 3 34 27 0
5 3 35 37 0
5 3 36 11 0
5 3 37 20 0
5 3 38 7 0
5 3 39 32 0
5 3 40 16 0
5 3 41 21 0
5 3 42 37 0
5 3 43 1 0
5 3 44 36 0
5 3 45 12 0
5 3 46 17 0
5 3 47 9 0
5 3 48 18 0
5 3 49 24 0
5 3 50 26 0
5 3 51 0 0
5 3 52 35 0
5 3 53 10 0
5 3 54 36 0
5 3 55 10 0
5 3 56 28 0
5 3 57 8 0
5 3 58 16 0
5 3 59 9 0
5 3 60 25 0
5 3 61 36 0
5 3 62 14 0
5 3 63 11 0
5 3 64 27 0
5 3 65 33 0
5 3 66 10 0
5 3 67 3 0
5 3 68 30 0
5 3 69 28 0
5 3 70 25 0
5 3 71 14 0
5 3 72 10 0
5 3 73 20 0
5 3 74 17 0
5 3 75 8 0
5 3 76 13 0
5 3 77 33 0
5 3 78 15 0
5 3 79 10 0
5 3 80 18 0
5 3 81 9 0
5 3 82 13 0
5 3 83 3 0
5 3 84 15 0
5 3 85 3 0
5 3 86 4 0
5 3 87 36 0
5 3 88 23 0
5 3 89 14 0
5 3 90 20 0
5 3 91 35 0
5 3 92 19 0
5 3 93 0 0
5 3 94 8 0
5 3 95 9 0
5 3 96 8 0
5 3 97 27 0
5 3 98 24 0
5 3 99 25 0
5 3 100 9 0
5 3 101 13 0
5 3 102 2 0
5 3 103 8 0
5 3 104 4 0
5 3 105 12 0
5 3 106 32 0
5 3 107 9 0
5 3 108 27 0
5 3 109 10 0
5 3 110 1 0
5 3 111 35 0
5 3 112 32 0
5 3 113 21 0
5 3 114 14 0
5 3 115 22 0
5 3 116 5 0
5 3 117 8 0
5 3 118 30 0
5 3 119 25 0
5 3 120 20 0
5 3 121 16 0
5 3 122 14 0
5 3 123 4 0
5 3 124 20 0
5 3 125 8 0
5 3 126 1 0
5 3 127 35 0
5 3 128 22 0
5 3 129 6 0
5 3 130 6 0
5 3 131 1 0
5 3 132 13 0
5 3 133 3 0
5 3 134 4 0
5 3 135 23 0
5 3 136 29 0
5 3 137 13 0
5 3 138 4 0
5 3 139 7 0
5 3 140 3 0
5 3 141 31 0
5 3 142 25 0
5 3 143 4 0
5 3 144 6 0
5 3 145 28 0
5 3 146 1 0
5 3 147 5 0
5 3 148 6 0
5 3 149 5 0
5 3 150 15 0
5 3 151 19 0
5 3 152 5 0
5 3 153 14 0
5 3 154 8 0
5 3 155 29 0
5 3 156 12 0
5 3 157 6 0
5 3 158 19 0
5 3 159 10 0
5 3 160 19 0
5 3 161 13 0
5 3 162 16 0
5 3 163 14 0
5 3 164 0 0
5 3 165 18 0
5 3 166 26 0
5 3 167 8 0
5 3 168 24 0
5 3 169 27 0
5 3 170 13 0
5 3 171 34 0
5 3 172 23 0
5 3 173 4 0
5 3 174 5 0
5 3 175 17 0
5 3 176 27 0
5 3 177 31 0
5 3 178 23 0
5 3 179 4 0
5 3 180 14 0
5 3 181 31 0
5 3 182 8 0
5 3 183 36 0
5 3 184 2 0
5 3 185 21 0
5 3 186 30 0
5 3 187 14 0
5 3 188 27 0
5 3 189 1 0
5 3 190 6 0
5 3 191 9 0
5 3 192 17 0
5 3 193 31 0
5 3 194 14 0
5 3 195 12 0
5 3 196 9 0
5 3 197 14 0
5 3 198 35 0
5 3 199 19 0
5 3 200 32 0
5 3 201 21 0
5 3 202 23 0
5 3 203 2 0
5 3 204 8 0
5 3 205 33 0
5 3 206 6 0
5 3 207 10 0
5 3 208 14 0
5 3 209 23 0
5 3 210 26 0
5 3 211 37 0
5 3 212 27 0
5 3 213 4 0
5 3 214 6 0
5 3 215 8 0
5 3 216 4 0
5 3 217 2 0
5 3 218 24 0
5 3 219 18 0
5 3 220 4 0
5 3 221 7 0
5 3 222 14 0
5 3 223 14 0
5 3 224 8 0
5 3 225 8 0
5 3 226 8 0
5 3 227 4 0
5 3 228 37 0
5 3 229 15 0
5 3 230 4 0
5 3 231 14 0
5 3 232 26 0
5 3 233 19 0
5 3 234 20 0
5 3 235 37 0
5 3 236 14 0
5 3 237 13 0
5 3 238 3 0
5 3 239 13 0
5 3 240 10 0
5 3 241 4 0
5 3 242 26 0
5 3 243 13 0
5 3 244 36 0
5 3 245 8 0
5 3 246 21 0
5 3 247 0 0
5 3 248 9 0
5 3 249 7 0
5 3 250 7 0
5 3 251 0 0
5 3 252 2 0
5 3 253 9 0
5 3 254 9 0
5 3 255 7 32
5 4 0 21 72
5 4 1 32 8
5 4 2 12 8
5 4 3 14 8
5 4 4 25 8
5 4 5 23 8
5 4 6 13 8
5 4 7 12 8
5 4 8 15 8
5 4 9 14 8
5 4 10 35 8
5 4 11 25 8
5 4 12 13 8
5 4 13 12 8
5 4 14 12 8
5 4 15 14 8
5 4 16 7 8
5 4 17 18 8
5 4 18 13 8
5 4 19 35 8
5 4 20 33 8
5 4 21 37 8
5 4 22 31 8
5 4 23 4 8
5 4 24 33 8
5 4 25 19 8
5 4 26 11 8
5 4 27 35 8
5 4 28 14 8
5 4 29 14 8
5 4 30 4 8
5 4 31 13 8
5 4 32 0 8
5 4 33 2 8
5 4 34 12 8
5 4 35 21 8
5 4 36 26 8
5 4 37 21 8
5 4 38 27 8
5 4 39 3 8
5 4 40 9 8
5 4 41 20 8
5 4 42 10 8
5 4 43 12 8
5 4 44 24 8
5 4 45 25 8
5 4 46 27 8
5 4 47 17 8
5 4 48 26 8
5 4 49 16 8
5 4 50 25 8
5 4 51 5 8
5 4 52 2 8
5 4 53 9 8
5 4 54 12 8
5 4 55 5 8
5 4 56 31 8
5 4 57 2 8
5 4 58 28 8
5 4 59 31 8
5 4 60 24 8
5 4 61 13 8
5 4 62 5 8
5 4 63 4 8
5 4 64 3 8
5 4 65 21 8
5 4 66 27 8
5 4 67 19 8
5 4 68 11 8
5 4 69 13 8
5 4 70 13 8
5 4 71 20 8
5 4 72 6 8
5 4 73 14 8
5 4 74 9 8
5 4 75 3 8
5 4 76 18 8
5 4 77 5 8
5 4 78 2 8
5 4 79 35 8
5 4 80 0 8
5 4 81 18 8
5 4 82 6 8
5 4 83 12 8
5 4 84 10 8
5 4 85 4 8
5 4 86 15 8
5 4 87 4 8
5 4 88 10 8
5 4 89 1 8
5 4 90 13 8
5 4 91 27 8
5 4 92 24 8
5 4 93 19 8
5 4 94 0 8
5 4 95 0 8
5 4 96 11 8
5 4 97 10 8
5 4 98 1 8
5 4 99 31 8
5 4 100 0 8
5 4 101 25 8
5 4 102 33 8
5 4 103 34 8
5 4 104 17 8
5 4 105 2 8
5 4 106 34 8
5 4 107 0 8
5 4 108 35 8
5 4 109 37 8
5 4 110 13 8
5 4 111 0 8
5 4 112 21 8
5 4 113 6 8
5 4 114 1 8
5 4 115 29 8
5 4 116 5 8
5 4 117 34 8
5 4 118 1 8
5 4 119 23 8
5 4 120 12 8
5 4 121 13 8
5 4 122 21 8
5 4 123 15 8
5 4 124 4 8
5 4 125 14 8
5 4 126 0 8
5 4 127 35 8
5 4 128 14 8
5 4 129 34 8
5 4 130 13 8
5 4 131 14 8
5 4 132 29 8
5 4 133 8 8
5 4 134 14 8
5 4 135 14 8
5 4 136 0 8
5 4 137 8 8
5 4 138 5 8
5 4 139 6 8
5 4 140 20 8
5 4 141 36 8
5 4 142 31 8
5 4 143 25 8
5 4 144 26 8
5 4 145 25 8
5 4 146 28 8
5 4 147 22 8
5 4 148 33 8
5 4 149 1 8
5 4 150 14 8
5 4 151 19 8
5 4 152 17 8
5 4 153 19 8
5 4 154 25 8
5 4 155 12 8
5 4 156 19 8
5 4 157 12 8
5 4 158 20 8
5 4 159 27 8
5 4 160 12 8
5 4 161 7 8
5 4 162 17 8
5 4 163 27 8
5 4 164 12 8
5 4 165 12 8
5 4 166 27 8
5 4 167 25 8
5 4 168 14 8
5 4 169 32 8
5 4 170 0 8
5 4 171 23 8
5 4 172 25 8
5 4 173 9 8
5 4 174 27 8
5 4 175 3 8
5 4 176 29 8
5 4 177 27 8
5 4 178 36 8
5 4 179 36 8
5 4 180 37 8
5 4 181 17 8
5 4 182 21 8
5 4 183 16 8
5 4 184 27 8
5 4 185 28 8
5 4 186 2 8
5 4 187 37 8
5 4 188 17 8
5 4 189 8 8
5 4 190 4 8
5 4 191 26 8
5 4 192 33 8
5 4 193 1 8
5 4 194 6 8
5 4 195 16 8
5 4 196 2 8
5 4 197 12 8
5 4 198 12 8
5 4 199 21 8
5 4 200 5 8
5 4 201 17 8
5 4 202 11 8
5 4 203 37 8
5 4 204 3 8
5 4 205 10 8
5 4 206 6 8
5 4 207 21 8
5 4 208 14 8
5 4 209 28 8
5 4 210 21 8
5 4 211 18 8
5 4 212 25 8
5 4 213 9 8
5 4 214 32 8
5 4 215 12 8
5 4 216 4 8
5 4 217 24 8
5 4 218 34 8
5 4 219 35 8
5 4 220 0 8
5 4 221 14 8
5 4 222 20 8
5 4 223 8 8
5 4 224 25 8
5 4 225 15 8
5 4 226 1 8
5 4 227 28 8
5 4 228 13 8
5 4 229 12 8
5 4 230 37 8
5 4 231 4 8
5 4 232 18 8
5 4 233 16 8
5 4 234 13 8
5 4 235 30 8
5 4 236 4 8
5 4 237 36 8
5 4 238 2 8
5 4 239 14 8
5 4 240 10 8
5 4 241 4 8
5 4 242 7 8
5 4 243 19 8
5 4 244 14 8
5 4 245 11 8
5 4 246 28 8
5 4 247 32 8
5 4 248 10 8
5 4 249 7 8
5 4 250 8 8
5 4 251 28 8
5 4 252 10 8
5 4 253 8 8
5 4 254 9 8
5 4 255 12 40
6 0 0 34 80
6 0 1 14 16
6 0 2 23 16
6 0 3 2 16
6 0 4 7 16
6 0 5 31 16
6 0 6 0 16
6 0 7 25 16
6 0 8 3 16
6 0 9 8 16
6 0 10 15 16
6 0 11 14 16
6 0 12 13 16
6 0 13 31 16
6 0 14 16 16
6 0 15 7 16
6 0 16 27 16
6 0 17 1 16
6 0 18 36 16
6 0 19 21 16
6 0 20 12 16
6 0 21 25 16
6 0 22 6 16
6 0 23 5 16
6 0 24 17 16
6 0 25 1 16
6 0 26 11 16
6 0 27 28 16
6 0 28 24 16
6 0 29 10 16
6 0 30 10 16
6 0 31 20 16
6 0 32 12 16
6 0 33 10 16
6 0 34 9 16
6 0 35 36 16
6 0 36 11 16
6 0 37 2 16
6 0 38 37 16
6 0 39 34 16
6 0 40 3 16
6 0 41 8 16
6 0 42 9 16
6 0 43 37 16
6 0 44 15 16
6 0 45 5 16
6 0 46 12 16
6 0 47 4 16
6 0 48 17 16
6 0 49 28 16
6 0 50 35 16
6 0 51 37 16
6 0 52 5 16
6 0 53 1 16
6 0 54 10 16
6 0 55 30 16
6 0 56 7 16
6 0 57 0 16
6 0 58 28 16
6 0 59 16 16
6 0 60 16 16
6 0 61 14 16
6 0 62 12 16
6 0 63 34 16
6 0 64 21 16
6 0 65 32 16
6 0 66 0 16
6 0 67 30 16
6 0 68 12 16
6 0 69 8 16
6 0 70 36 16
6 0 71 14 16
6 0 72 24 16
6 0 73 5 16
6 0 74 14 16
6 0 75 14 16
6 0 76 8 16
6 0 77 11 16
6 0 78 8 16
6 0 79 1 16
6 0 80 6 16
6 0 81 5 16
6 0 82 1 16
6 0 83 12 16
6 0 84 22 16
6 0 85 33 16
6 0 86 14 16
6 0 87 12 16
6 0 88 14 16
6 0 89 5 16
6 0 90 4 16
6 0 91 25 16
6 0 92 31 16
6 0 93 4 16
6 0 94 23 16
6 0 95 28 16
6 0 96 20 16
6 0 97 19 16
6 0 98 14 16
6 0 99 22 16
6 0 100 7 16
6 0 101 15 16
6 0 102 12 16
6 0 103 29 16
6 0 104 1 16
6 0 105 10 16
6 0 106 3 16
6 0 107 12 16
6 0 108 22 16
6 0 109 6 16
6 0 110 10 16
6 0 111 16 16
6 0 112 37 16
6 0 113 34 16
6 0 114 4 16
6 0 115 20 16
6 0 116 27 16
6 0 117 36 16
6 0 118 10 16
6 0 119 29 16
6 0 120 14 16
6 0 121 20 16
6 0 122 9 16
6 0 123 28 16
6 0 124 26 16
6 0 125 6 16
6 0 126 7 16
6 0 127 1 16
6 0 128 24 16
6 0 129 4 16
6 0 130 8 16
6 0 131 5 16
6 0 132 25 16
6 0 133 5 16
6 0 134 14 16
6 0 135 6 16
6 0 136 6 16
6 0 137 17 16
6 0 138 4 16
6 0 139 8 16
6 0 140 18 16
6 0 141 16 16
6 0 142 18 16
6 0 143 33 16
6 0 144 32 16
6 0 145 24 16
6 0 146 26 16
6 0 147 13 16
6 0 148 3 16
6 0 149 12 16
6 0 150 7 16
6 0 151 11 16
6 0 152 36 16
6 0 153 4 16
6 0 154 33 16
6 0 155 33 16
6 0 156 16 16
6 0 157 18 16
6 0 158 14 16
6 0 159 17 16
6 0 160 21 16
6 0 161 27 16
6 0 162 24 16
6 0 163 12 16
6 0 164 33 16
6 0 165 12 16
6 0 166 9 16
6 0 167 2 16
6 0 168 1 16
6 0 169 14 16
6 0 170 14 16
6 0 171 12 16
6 0 172 30 16
6 0 173 25 16
6 0 174 14 16
6 0 175 5 16
6 0 176 4 16
6 0 177 1 16
6 0 178 28 16
6 0 179 23 16
6 0 180 29 16
6 0 181 32 16
6 0 182 28 16
6 0 183 13 16
6 0 184 6 16
6 0 185 0 16
6 0 186 8 16
6 0 187 6 16
6 0 188 18 16
6 0 189 21 16
6 0 190 1 16
6 0 191 19 16
6 0 192 3 16
6 0 193 10 16
6 0 194 7 16
6 0 195 12 16
6 0 196 10 16
6 0 197 35 16
6 0 198 14 16
6 0 199 34 16
6 0 200 14 16
6 0 201 36 16
6 0 202 10 16
6 0 203 14 16
6 0 204 30 16
6 0 205 5 16
6 0 206 34 16
6 0 207 24 16
6 0 208 4 16
6 0 209 32 16
6 0 210 26 16
6 0 211 6 16
6 0 212 18 16
6 0 213 12 16
6 0 214 32 16
6 0 215 28 16
6 0 216 2 16
6 0 217 18 16
6 0 218 2 16
6 0 219 6 16
6 0 220 1 16
6 0 221 36 16
6 0 222 24 16
6 0 223 16 16
6 0 224 2 16
6 0 225 5 16
6 0 226 10 16
6 0 227 32 16
6 0 228 36 16
6 0 229 6 16
6 0 230 8 16
