Qubicle Exchange Format
Version 0.2
www.minddesk.com
8 8 8
3
0.000000 0.000000 0.000000
0.866667 0.866667 0.866667
1.000000 0.403922 0.094118
2 2 3 0 84
2 2 4 0 52
2 3 3 0 76
2 3 4 0 44
2 7 4 2 126
3 1 3 0 84
3 1 4 0 52
3 2 2 0 84
3 2 3 0 0
3 2 4 0 0
3 2 5 0 52
3 3 2 0 76
3 3 3 0 0
3 3 4 0 0
3 3 5 0 44
3 4 3 0 76
3 4 4 0 44
3 5 4 1 126
3 6 4 1 126
4 1 3 0 82
4 1 4 0 50
4 2 2 0 82
4 2 3 0 0
4 2 4 0 0
4 2 5 0 50
4 3 2 0 74
4 3 3 0 0
4 3 4 0 0
4 3 5 0 42
4 4 3 0 74
4 4 4 0 42
5 2 3 0 82
5 2 4 0 50
5 3 3 0 74
5 3 4 0 42
