Qubicle Exchange Format
Version 0.2
www.minddesk.com
16 16 16
27
0.000000 0.000000 0.000000
0.000000 0.211765 0.070588
0.000000 0.215686 0.070588
0.000000 0.219608 0.070588
0.000000 0.223529 0.074510
0.000000 0.227451 0.074510
0.000000 0.231373 0.074510
0.000000 0.235294 0.078431
0.007843 0.243137 0.086275
0.015686 0.247059 0.094118
0.019608 0.250980 0.098039
0.027451 0.254902 0.105882
0.039216 0.266667 0.117647
0.043137 0.266667 0.117647
0.047059 0.270588 0.121569
0.054902 0.278431 0.129412
0.058824 0.278431 0.133333
0.070588 0.290196 0.145098
0.074510 0.294118 0.149020
0.078431 0.294118 0.152941
0.082353 0.298039 0.156863
0.250980 0.172549 0.000000
0.533333 0.439216 0.000000
0.600000 0.600000 0.600000
0.933333 0.933333 0.933333
0.988235 0.737255 0.690196
1.000000 1.000000 1.000000
0 0 0 23 126
0 0 1 23 126
0 0 2 23 126
0 0 3 23 126
0 0 4 23 126
0 0 5 23 126
0 0 6 23 126
0 0 7 23 126
0 0 8 23 126
0 0 9 23 126
0 0 10 23 126
0 0 11 23 126
0 0 12 23 126
0 0 13 23 126
0 0 14 23 126
0 0 15 23 126
0 1 0 23 126
0 1 15 23 126
0 2 0 23 126
0 2 15 23 126
0 3 0 23 126
0 3 15 23 126
0 4 0 23 126
0 4 15 23 126
0 5 0 23 126
0 5 15 23 126
0 6 0 23 126
0 6 15 23 126
0 7 0 23 126
0 7 15 23 126
0 8 0 23 126
0 8 15 23 126
0 9 0 23 126
0 9 15 23 126
0 10 0 23 126
0 10 15 23 126
0 11 0 23 126
0 11 15 23 126
0 12 0 23 126
0 12 15 23 126
0 13 0 23 126
0 13 15 23 126
0 14 0 23 126
0 14 15 23 126
0 15 0 23 126
0 15 1 23 126
0 15 2 23 126
0 15 3 23 126
0 15 4 23 126
0 15 5 23 126
0 15 6 23 126
0 15 7 23 126
0 15 8 23 126
0 15 9 23 126
0 15 10 23 126
0 15 11 23 126
0 15 12 23 126
0 15 13 23 126
0 15 14 23 126
0 15 15 23 126
1 0 0 23 126
1 0 15 23 126
1 15 0 23 126
1 15 15 23 126
2 0 0 23 126
2 0 15 23 126
2 4 2 25 84
2 4 3 25 20
2 4 4 25 20
2 4 5 25 20
2 4 6 26 20
2 4 7 26 20
2 4 8 26 20
2 4 9 26 52
2 5 2 25 76
2 5 3 25 12
2 5 4 25 12
2 5 5 25 12
2 5 6 26 12
2 5 7 26 12
2 5 8 26 12
2 5 9 26 44
2 8 2 25 84
2 8 3 25 20
2 8 4 25 20
2 8 5 25 20
2 8 6 25 20
2 8 7 25 20
2 8 8 25 20
2 8 9 25 20
2 8 10 25 20
2 8 11 25 20
2 8 12 25 20
2 8 13 25 52
2 9 2 25 68
2 9 3 25 4
2 9 4 25 4
2 9 5 25 4
2 9 6 25 4
2 9 7 25 4
2 9 8 25 4
2 9 9 25 4
2 9 10 25 4
2 9 11 25 4
2 9 12 25 4
2 9 13 25 36
2 10 2 0 68
2 10 3 0 4
2 10 4 25 4
2 10 5 25 4
2 10 6 25 4
2 10 7 25 4
2 10 8 25 4
2 10 9 25 4
2 10 10 25 4
2 10 11 25 4
2 10 12 25 4
2 10 13 25 36
2 11 2 0 68
2 11 3 0 4
2 11 4 25 4
2 11 5 25 4
2 11 6 25 4
2 11 7 25 4
2 11 8 25 4
2 11 9 25 4
2 11 10 25 4
2 11 11 25 4
2 11 12 25 4
2 11 13 25 36
2 12 2 0 68
2 12 3 0 4
2 12 4 0 4
2 12 5 0 4
2 12 6 0 4
2 12 7 0 4
2 12 8 0 4
2 12 9 0 4
2 12 10 0 4
2 12 11 0 4
2 12 12 21 4
2 12 13 21 36
2 13 2 0 68
2 13 3 0 4
2 13 4 0 4
2 13 5 0 4
2 13 6 0 4
2 13 7 0 4
2 13 8 0 4
2 13 9 0 4
2 13 10 0 4
2 13 11 0 4
2 13 12 21 4
2 13 13 21 36
2 14 2 0 68
2 14 3 0 4
2 14 4 21 4
2 14 5 21 4
2 14 6 21 4
2 14 7 21 4
2 14 8 21 4
2 14 9 21 4
2 14 10 21 4
2 14 11 21 4
2 14 12 21 4
2 14 13 21 36
2 15 0 23 126
2 15 2 0 76
2 15 3 0 12
2 15 4 21 12
2 15 5 21 12
2 15 6 21 12
2 15 7 21 12
2 15 8 21 12
2 15 9 21 12
2 15 10 21 12
2 15 11 21 12
2 15 12 21 12
2 15 13 21 44
2 15 15 23 126
3 0 0 23 126
3 0 15 23 126
3 4 2 25 82
3 4 3 25 18
3 4 4 25 16
3 4 5 25 16
3 4 6 26 16
3 4 7 26 16
3 4 8 26 16
3 4 9 26 48
3 5 2 25 74
3 5 3 25 10
3 5 4 25 8
3 5 5 25 8
3 5 6 26 8
3 5 7 26 8
3 5 8 26 8
3 5 9 26 40
3 8 2 25 80
3 8 3 25 16
3 8 4 25 16
3 8 5 25 16
3 8 6 25 16
3 8 7 25 16
3 8 8 25 16
3 8 9 25 16
3 8 10 25 16
3 8 11 25 16
3 8 12 25 16
3 8 13 25 48
3 9 2 25 64
3 9 3 25 0
3 9 4 25 0
3 9 5 25 0
3 9 6 25 0
3 9 7 25 0
3 9 8 25 0
3 9 9 25 0
3 9 10 25 0
3 9 11 25 0
3 9 12 25 0
3 9 13 25 32
3 10 2 0 64
3 10 3 0 0
3 10 4 25 0
3 10 5 25 0
3 10 6 25 0
3 10 7 25 0
3 10 8 25 0
3 10 9 25 0
3 10 10 25 0
3 10 11 25 0
3 10 12 25 0
3 10 13 25 32
3 11 2 0 64
3 11 3 0 0
3 11 4 25 0
3 11 5 25 0
3 11 6 25 0
3 11 7 25 0
3 11 8 25 0
3 11 9 25 0
3 11 10 25 0
3 11 11 25 0
3 11 12 25 0
3 11 13 25 32
3 12 2 0 64
3 12 3 0 0
3 12 4 0 0
3 12 5 0 0
3 12 6 0 0
3 12 7 0 0
3 12 8 0 0
3 12 9 0 0
3 12 10 0 0
3 12 11 0 0
3 12 12 21 0
3 12 13 21 32
3 13 2 0 64
3 13 3 0 0
3 13 4 0 0
3 13 5 0 0
3 13 6 0 0
3 13 7 0 0
3 13 8 0 0
3 13 9 0 0
3 13 10 0 0
3 13 11 0 0
3 13 12 21 0
3 13 13 21 32
3 14 2 0 64
3 14 3 0 0
3 14 4 21 0
3 14 5 21 0
3 14 6 21 0
3 14 7 21 0
3 14 8 21 0
3 14 9 21 0
3 14 10 21 0
3 14 11 21 0
3 14 12 21 0
3 14 13 21 32
3 15 0 23 126
3 15 2 0 72
3 15 3 0 8
3 15 4 21 8
3 15 5 21 8
3 15 6 21 8
3 15 7 21 8
3 15 8 21 8
3 15 9 21 8
3 15 10 21 8
3 15 11 21 8
3 15 12 21 8
3 15 13 21 40
3 15 15 23 126
4 0 0 23 126
4 0 6 25 84
4 0 7 25 20
4 0 8 25 20
4 0 9 25 52
4 0 15 23 126
4 1 6 25 68
4 1 7 25 4
4 1 8 25 4
4 1 9 25 36
4 2 6 22 68
4 2 7 22 4
4 2 8 22 4
4 2 9 22 36
4 3 6 22 68
4 3 7 22 4
4 3 8 22 4
4 3 9 22 36
4 4 4 26 80
4 4 5 26 16
4 4 6 26 0
4 4 7 26 0
4 4 8 26 0
4 4 9 26 0
4 4 10 26 20
4 4 11 26 52
4 5 4 26 64
4 5 5 26 0
4 5 6 26 0
4 5 7 26 0
4 5 8 26 0
4 5 9 26 0
4 5 10 26 4
4 5 11 26 36
4 6 4 26 68
4 6 5 26 4
4 6 6 26 4
4 6 7 26 4
4 6 8 26 4
4 6 9 26 4
4 6 10 26 4
4 6 11 26 36
4 7 4 26 68
4 7 5 26 4
4 7 6 26 4
4 7 7 26 4
4 7 8 26 4
4 7 9 26 4
4 7 10 26 4
4 7 11 26 36
4 8 2 25 80
4 8 3 25 16
4 8 4 25 0
4 8 5 25 0
4 8 6 25 0
4 8 7 25 0
4 8 8 25 0
4 8 9 25 0
4 8 10 25 0
4 8 11 25 0
4 8 12 25 16
4 8 13 25 48
4 9 2 25 64
4 9 3 25 0
4 9 4 25 0
4 9 5 25 0
4 9 6 25 0
4 9 7 25 0
4 9 8 25 0
4 9 9 25 0
4 9 10 25 0
4 9 11 25 0
4 9 12 25 0
4 9 13 25 32
4 10 2 0 64
4 10 3 0 0
4 10 4 6 0
4 10 5 6 0
4 10 6 13 0
4 10 7 13 0
4 10 8 25 0
4 10 9 25 0
4 10 10 25 0
4 10 11 25 0
4 10 12 21 0
4 10 13 21 32
4 11 2 0 64
4 11 3 0 0
4 11 4 6 0
4 11 5 6 0
4 11 6 13 0
4 11 7 13 0
4 11 8 25 0
4 11 9 25 0
4 11 10 25 0
4 11 11 25 0
4 11 12 21 0
4 11 13 21 32
4 12 2 24 64
4 12 3 24 0
4 12 4 14 0
4 12 5 14 0
4 12 6 2 0
4 12 7 2 0
4 12 8 14 0
4 12 9 14 0
4 12 10 9 0
4 12 11 9 0
4 12 12 21 0
4 12 13 21 32
4 13 2 24 64
4 13 3 24 0
4 13 4 14 0
4 13 5 14 0
4 13 6 2 0
4 13 7 2 0
4 13 8 14 0
4 13 9 14 0
4 13 10 9 0
4 13 11 9 0
4 13 12 21 0
4 13 13 21 32
4 14 2 0 64
4 14 3 0 0
4 14 4 21 0
4 14 5 21 0
4 14 6 21 0
4 14 7 21 0
4 14 8 21 0
4 14 9 21 0
4 14 10 21 0
4 14 11 21 0
4 14 12 21 0
4 14 13 21 32
4 15 0 23 126
4 15 2 0 72
4 15 3 0 8
4 15 4 21 8
4 15 5 21 8
4 15 6 21 8
4 15 7 21 8
4 15 8 21 8
4 15 9 21 8
4 15 10 21 8
4 15 11 21 8
4 15 12 21 8
4 15 13 21 40
4 15 15 23 126
5 0 0 23 126
5 0 6 25 82
5 0 7 25 18
5 0 8 25 18
5 0 9 25 50
5 0 15 23 126
5 1 6 25 66
5 1 7 25 2
5 1 8 25 2
5 1 9 25 34
5 2 6 22 66
5 2 7 22 2
5 2 8 22 2
5 2 9 22 34
5 3 6 22 66
5 3 7 22 2
5 3 8 22 2
5 3 9 22 34
5 4 4 26 80
5 4 5 26 16
5 4 6 26 0
5 4 7 26 0
5 4 8 26 0
5 4 9 26 0
5 4 10 26 16
5 4 11 26 48
5 5 4 26 64
5 5 5 26 0
5 5 6 26 0
5 5 7 26 0
5 5 8 26 0
5 5 9 26 0
5 5 10 26 0
5 5 11 26 32
5 6 4 26 64
5 6 5 26 0
5 6 6 26 0
5 6 7 26 0
5 6 8 26 0
5 6 9 26 0
5 6 10 26 0
5 6 11 26 32
5 7 4 26 64
5 7 5 26 0
5 7 6 26 0
5 7 7 26 0
5 7 8 26 0
5 7 9 26 0
5 7 10 26 0
5 7 11 26 32
5 8 2 25 80
5 8 3 25 16
5 8 4 25 0
5 8 5 25 0
5 8 6 25 0
5 8 7 25 0
5 8 8 25 0
5 8 9 25 0
5 8 10 25 0
5 8 11 25 0
5 8 12 25 16
5 8 13 25 48
5 9 2 25 64
5 9 3 25 0
5 9 4 25 0
5 9 5 25 0
5 9 6 25 0
5 9 7 25 0
5 9 8 25 0
5 9 9 25 0
5 9 10 25 0
5 9 11 25 0
5 9 12 25 0
5 9 13 25 32
5 10 2 0 64
5 10 3 0 0
5 10 4 6 0
5 10 5 6 0
5 10 6 13 0
5 10 7 13 0
5 10 8 25 0
5 10 9 25 0
5 10 10 25 0
5 10 11 25 0
5 10 12 21 0
5 10 13 21 32
5 11 2 0 64
5 11 3 0 0
5 11 4 6 0
5 11 5 6 0
5 11 6 13 0
5 11 7 13 0
5 11 8 25 0
5 11 9 25 0
5 11 10 25 0
5 11 11 25 0
5 11 12 21 0
5 11 13 21 32
5 12 2 24 64
5 12 3 24 0
5 12 4 14 0
5 12 5 14 0
5 12 6 2 0
5 12 7 2 0
5 12 8 14 0
5 12 9 14 0
5 12 10 9 0
5 12 11 9 0
5 12 12 21 0
5 12 13 21 32
5 13 2 24 64
5 13 3 24 0
5 13 4 14 0
5 13 5 14 0
5 13 6 2 0
5 13 7 2 0
5 13 8 14 0
5 13 9 14 0
5 13 10 9 0
5 13 11 9 0
5 13 12 21 0
5 13 13 21 32
5 14 2 0 64
5 14 3 0 0
5 14 4 21 0
5 14 5 21 0
5 14 6 21 0
5 14 7 21 0
5 14 8 21 0
5 14 9 21 0
5 14 10 21 0
5 14 11 21 0
5 14 12 21 0
5 14 13 21 32
5 15 0 23 126
5 15 2 0 72
5 15 3 0 8
5 15 4 21 8
5 15 5 21 8
5 15 6 21 8
5 15 7 21 8
5 15 8 21 8
5 15 9 21 8
5 15 10 21 8
5 15 11 21 8
5 15 12 21 8
5 15 13 21 40
5 15 15 23 126
6 0 0 23 126
6 0 15 23 126
6 4 4 26 80
6 4 5 26 16
6 4 6 26 16
6 4 7 26 16
6 4 8 26 16
6 4 9 26 16
6 4 10 26 16
6 4 11 26 48
6 5 4 26 64
6 5 5 26 0
6 5 6 26 0
6 5 7 26 0
6 5 8 26 0
6 5 9 26 0
6 5 10 26 0
6 5 11 26 32
6 6 4 26 64
6 6 5 26 0
6 6 6 26 0
6 6 7 26 0
6 6 8 26 0
6 6 9 26 0
6 6 10 26 0
6 6 11 26 32
6 7 4 26 64
6 7 5 26 0
6 7 6 26 0
6 7 7 26 0
6 7 8 26 0
6 7 9 26 0
6 7 10 26 0
6 7 11 26 32
6 8 2 25 80
6 8 3 25 16
6 8 4 25 0
6 8 5 25 0
6 8 6 25 0
6 8 7 25 0
6 8 8 25 0
6 8 9 25 0
6 8 10 8 0
6 8 11 8 0
6 8 12 25 16
6 8 13 25 48
6 9 2 25 64
6 9 3 25 0
6 9 4 25 0
6 9 5 25 0
6 9 6 25 0
6 9 7 25 0
6 9 8 25 0
6 9 9 25 0
6 9 10 8 0
6 9 11 8 0
6 9 12 25 0
6 9 13 25 32
6 10 2 0 64
6 10 3 0 0
6 10 4 12 0
6 10 5 12 0
6 10 6 20 0
6 10 7 20 0
6 10 8 3 0
6 10 9 3 0
6 10 10 3 0
6 10 11 3 0
6 10 12 21 0
6 10 13 21 32
6 11 2 0 64
6 11 3 0 0
6 11 4 12 0
6 11 5 12 0
6 11 6 20 0
6 11 7 20 0
6 11 8 3 0
6 11 9 3 0
6 11 10 3 0
6 11 11 3 0
6 11 12 21 0
6 11 13 21 32
6 12 2 0 64
6 12 3 0 0
6 12 4 6 0
6 12 5 6 0
6 12 6 18 0
6 12 7 18 0
6 12 8 10 0
6 12 9 10 0
6 12 10 17 0
6 12 11 17 0
6 12 12 21 0
6 12 13 21 32
6 13 2 0 64
6 13 3 0 0
6 13 4 6 0
6 13 5 6 0
6 13 6 18 0
6 13 7 18 0
6 13 8 10 0
6 13 9 10 0
6 13 10 17 0
6 13 11 17 0
6 13 12 21 0
6 13 13 21 32
6 14 2 0 64
6 14 3 0 0
6 14 4 21 0
6 14 5 21 0
6 14 6 21 0
6 14 7 21 0
6 14 8 21 0
6 14 9 21 0
6 14 10 21 0
6 14 11 21 0
6 14 12 21 0
6 14 13 21 32
6 15 0 23 126
6 15 2 0 72
6 15 3 0 8
6 15 4 21 8
6 15 5 21 8
6 15 6 21 8
6 15 7 21 8
6 15 8 21 8
6 15 9 21 8
6 15 10 21 8
6 15 11 21 8
6 15 12 21 8
6 15 13 21 40
6 15 15 23 126
7 0 0 23 126
7 0 15 23 126
7 4 4 26 80
7 4 5 26 16
7 4 6 26 16
7 4 7 26 16
7 4 8 26 16
7 4 9 26 16
7 4 10 26 16
7 4 11 26 48
7 5 4 26 64
7 5 5 26 0
7 5 6 26 0
7 5 7 26 0
7 5 8 26 0
7 5 9 26 0
7 5 10 26 0
7 5 11 26 32
7 6 4 26 64
7 6 5 26 0
7 6 6 26 0
7 6 7 26 0
7 6 8 26 0
7 6 9 26 0
7 6 10 26 0
7 6 11 26 32
7 7 4 26 64
7 7 5 26 0
7 7 6 26 0
7 7 7 26 0
7 7 8 26 0
7 7 9 26 0
7 7 10 26 0
7 7 11 26 32
7 8 2 25 80
7 8 3 25 16
7 8 4 25 0
7 8 5 25 0
7 8 6 25 0
7 8 7 25 0
7 8 8 25 0
7 8 9 25 0
7 8 10 8 0
7 8 11 8 0
7 8 12 25 16
7 8 13 25 48
7 9 2 25 64
7 9 3 25 0
7 9 4 25 0
7 9 5 25 0
7 9 6 25 0
7 9 7 25 0
7 9 8 25 0
7 9 9 25 0
7 9 10 8 0
7 9 11 8 0
7 9 12 25 0
7 9 13 25 32
7 10 2 0 64
7 10 3 0 0
7 10 4 12 0
7 10 5 12 0
7 10 6 20 0
7 10 7 20 0
7 10 8 3 0
7 10 9 3 0
7 10 10 3 0
7 10 11 3 0
7 10 12 21 0
7 10 13 21 32
7 11 2 0 64
7 11 3 0 0
7 11 4 12 0
7 11 5 12 0
7 11 6 20 0
7 11 7 20 0
7 11 8 3 0
7 11 9 3 0
7 11 10 3 0
7 11 11 3 0
7 11 12 21 0
7 11 13 21 32
7 12 2 0 64
7 12 3 0 0
7 12 4 6 0
7 12 5 6 0
7 12 6 18 0
7 12 7 18 0
7 12 8 10 0
7 12 9 10 0
7 12 10 17 0
7 12 11 17 0
7 12 12 21 0
7 12 13 21 32
7 13 2 0 64
7 13 3 0 0
7 13 4 6 0
7 13 5 6 0
7 13 6 18 0
7 13 7 18 0
7 13 8 10 0
7 13 9 10 0
7 13 10 17 0
7 13 11 17 0
7 13 12 21 0
7 13 13 21 32
7 14 2 0 64
7 14 3 0 0
7 14 4 21 0
7 14 5 21 0
7 14 6 21 0
7 14 7 21 0
7 14 8 21 0
7 14 9 21 0
7 14 10 21 0
7 14 11 21 0
7 14 12 21 0
7 14 13 21 32
7 15 0 23 126
7 15 2 0 72
7 15 3 0 8
7 15 4 21 8
7 15 5 21 8
7 15 6 21 8
7 15 7 21 8
7 15 8 21 8
7 15 9 21 8
7 15 10 21 8
7 15 11 21 8
7 15 12 21 8
7 15 13 21 40
7 15 15 23 126
8 0 0 23 126
8 0 15 23 126
8 4 4 26 80
8 4 5 26 16
8 4 6 26 16
8 4 7 26 16
8 4 8 26 16
8 4 9 26 16
8 4 10 26 16
8 4 11 26 48
8 5 4 26 64
8 5 5 26 0
8 5 6 26 0
8 5 7 26 0
8 5 8 26 0
8 5 9 26 0
8 5 10 26 0
8 5 11 26 32
8 6 4 26 64
8 6 5 26 0
8 6 6 25 0
8 6 7 25 0
8 6 8 25 0
8 6 9 25 0
8 6 10 26 0
8 6 11 26 32
8 7 4 26 64
8 7 5 26 0
8 7 6 25 0
8 7 7 25 0
8 7 8 25 0
8 7 9 25 0
8 7 10 26 0
8 7 11 26 32
8 8 2 25 80
8 8 3 25 16
8 8 4 25 0
8 8 5 25 0
8 8 6 25 0
8 8 7 25 0
8 8 8 4 0
8 8 9 4 0
8 8 10 19 0
8 8 11 19 0
8 8 12 25 16
8 8 13 25 48
8 9 2 25 64
8 9 3 25 0
8 9 4 25 0
8 9 5 25 0
8 9 6 25 0
8 9 7 25 0
8 9 8 4 0
8 9 9 4 0
8 9 10 19 0
8 9 11 19 0
8 9 12 25 0
8 9 13 25 32
8 10 2 0 64
8 10 3 0 0
8 10 4 1 0
8 10 5 1 0
8 10 6 2 0
8 10 7 2 0
8 10 8 1 0
8 10 9 1 0
8 10 10 5 0
8 10 11 5 0
8 10 12 21 0
8 10 13 21 32
8 11 2 0 64
8 11 3 0 0
8 11 4 1 0
8 11 5 1 0
8 11 6 2 0
8 11 7 2 0
8 11 8 1 0
8 11 9 1 0
8 11 10 5 0
8 11 11 5 0
8 11 12 21 0
8 11 13 21 32
8 12 2 0 64
8 12 3 0 0
8 12 4 15 0
8 12 5 15 0
8 12 6 13 0
8 12 7 13 0
8 12 8 6 0
8 12 9 6 0
8 12 10 6 0
8 12 11 6 0
8 12 12 21 0
8 12 13 21 32
8 13 2 0 64
8 13 3 0 0
8 13 4 15 0
8 13 5 15 0
8 13 6 13 0
8 13 7 13 0
8 13 8 6 0
8 13 9 6 0
8 13 10 6 0
8 13 11 6 0
8 13 12 21 0
8 13 13 21 32
8 14 2 0 64
8 14 3 0 0
8 14 4 21 0
8 14 5 21 0
8 14 6 21 0
8 14 7 21 0
8 14 8 21 0
8 14 9 21 0
8 14 10 21 0
8 14 11 21 0
8 14 12 21 0
8 14 13 21 32
8 15 0 23 126
8 15 2 0 72
8 15 3 0 8
8 15 4 21 8
8 15 5 21 8
8 15 6 21 8
8 15 7 21 8
8 15 8 21 8
8 15 9 21 8
8 15 10 21 8
8 15 11 21 8
8 15 12 21 8
8 15 13 21 40
8 15 15 23 126
9 0 0 23 126
9 0 15 23 126
9 4 4 26 80
9 4 5 26 16
9 4 6 26 16
9 4 7 26 16
9 4 8 26 16
9 4 9 26 16
9 4 10 26 16
9 4 11 26 48
9 5 4 26 64
9 5 5 26 0
9 5 6 26 0
9 5 7 26 0
9 5 8 26 0
9 5 9 26 0
9 5 10 26 0
9 5 11 26 32
9 6 4 26 64
9 6 5 26 0
9 6 6 25 0
9 6 7 25 0
9 6 8 25 0
9 6 9 25 0
9 6 10 26 0
9 6 11 26 32
9 7 4 26 64
9 7 5 26 0
9 7 6 25 0
9 7 7 25 0
9 7 8 25 0
9 7 9 25 0
9 7 10 26 0
9 7 11 26 32
9 8 2 25 80
9 8 3 25 16
9 8 4 25 0
9 8 5 25 0
9 8 6 25 0
9 8 7 25 0
9 8 8 4 0
9 8 9 4 0
9 8 10 19 0
9 8 11 19 0
9 8 12 25 16
9 8 13 25 48
9 9 2 25 64
9 9 3 25 0
9 9 4 25 0
9 9 5 25 0
9 9 6 25 0
9 9 7 25 0
9 9 8 4 0
9 9 9 4 0
9 9 10 19 0
9 9 11 19 0
9 9 12 25 0
9 9 13 25 32
9 10 2 0 64
9 10 3 0 0
9 10 4 1 0
9 10 5 1 0
9 10 6 2 0
9 10 7 2 0
9 10 8 1 0
9 10 9 1 0
9 10 10 5 0
9 10 11 5 0
9 10 12 21 0
9 10 13 21 32
9 11 2 0 64
9 11 3 0 0
9 11 4 1 0
9 11 5 1 0
9 11 6 2 0
9 11 7 2 0
9 11 8 1 0
9 11 9 1 0
9 11 10 5 0
9 11 11 5 0
9 11 12 21 0
9 11 13 21 32
9 12 2 0 64
9 12 3 0 0
9 12 4 15 0
9 12 5 15 0
9 12 6 13 0
9 12 7 13 0
9 12 8 6 0
9 12 9 6 0
9 12 10 6 0
9 12 11 6 0
9 12 12 21 0
9 12 13 21 32
9 13 2 0 64
9 13 3 0 0
9 13 4 15 0
9 13 5 15 0
9 13 6 13 0
9 13 7 13 0
9 13 8 6 0
9 13 9 6 0
9 13 10 6 0
9 13 11 6 0
9 13 12 21 0
9 13 13 21 32
9 14 2 0 64
9 14 3 0 0
9 14 4 21 0
9 14 5 21 0
9 14 6 21 0
9 14 7 21 0
9 14 8 21 0
9 14 9 21 0
9 14 10 21 0
9 14 11 21 0
9 14 12 21 0
9 14 13 21 32
9 15 0 23 126
9 15 2 0 72
9 15 3 0 8
9 15 4 21 8
9 15 5 21 8
9 15 6 21 8
9 15 7 21 8
9 15 8 21 8
9 15 9 21 8
9 15 10 21 8
9 15 11 21 8
9 15 12 21 8
9 15 13 21 40
9 15 15 23 126
10 0 0 23 126
10 0 6 25 84
10 0 7 25 20
10 0 8 25 20
10 0 9 25 52
10 0 15 23 126
10 1 6 25 68
10 1 7 25 4
10 1 8 25 4
10 1 9 25 36
10 2 6 22 68
10 2 7 22 4
10 2 8 22 4
10 2 9 22 36
10 3 6 22 68
10 3 7 22 4
10 3 8 22 4
10 3 9 22 36
10 4 4 26 80
10 4 5 26 16
10 4 6 25 0
10 4 7 25 0
10 4 8 25 0
10 4 9 25 0
10 4 10 26 16
10 4 11 26 48
10 5 4 26 64
10 5 5 26 0
10 5 6 25 0
10 5 7 25 0
10 5 8 25 0
10 5 9 25 0
10 5 10 26 0
10 5 11 26 32
10 6 4 26 64
10 6 5 26 0
10 6 6 26 0
10 6 7 26 0
10 6 8 26 0
10 6 9 26 0
10 6 10 26 0
10 6 11 26 32
10 7 4 26 64
10 7 5 26 0
10 7 6 26 0
10 7 7 26 0
10 7 8 26 0
10 7 9 26 0
10 7 10 26 0
10 7 11 26 32
10 8 2 25 80
10 8 3 25 16
10 8 4 25 0
10 8 5 25 0
10 8 6 25 0
10 8 7 25 0
10 8 8 15 0
10 8 9 15 0
10 8 10 7 0
10 8 11 7 0
10 8 12 25 16
10 8 13 25 48
10 9 2 25 64
10 9 3 25 0
10 9 4 25 0
10 9 5 25 0
10 9 6 25 0
10 9 7 25 0
10 9 8 15 0
10 9 9 15 0
10 9 10 7 0
10 9 11 7 0
10 9 12 25 0
10 9 13 25 32
10 10 2 0 64
10 10 3 0 0
10 10 4 2 0
10 10 5 2 0
10 10 6 10 0
10 10 7 10 0
10 10 8 11 0
10 10 9 11 0
10 10 10 4 0
10 10 11 4 0
10 10 12 21 0
10 10 13 21 32
10 11 2 0 64
10 11 3 0 0
10 11 4 2 0
10 11 5 2 0
10 11 6 10 0
10 11 7 10 0
10 11 8 11 0
10 11 9 11 0
10 11 10 4 0
10 11 11 4 0
10 11 12 21 0
10 11 13 21 32
10 12 2 24 64
10 12 3 24 0
10 12 4 4 0
10 12 5 4 0
10 12 6 3 0
10 12 7 3 0
10 12 8 16 0
10 12 9 16 0
10 12 10 1 0
10 12 11 1 0
10 12 12 21 0
10 12 13 21 32
10 13 2 24 64
10 13 3 24 0
10 13 4 4 0
10 13 5 4 0
10 13 6 3 0
10 13 7 3 0
10 13 8 16 0
10 13 9 16 0
10 13 10 1 0
10 13 11 1 0
10 13 12 21 0
10 13 13 21 32
10 14 2 0 64
10 14 3 0 0
10 14 4 21 0
10 14 5 21 0
10 14 6 21 0
10 14 7 21 0
10 14 8 21 0
10 14 9 21 0
10 14 10 21 0
10 14 11 21 0
10 14 12 21 0
10 14 13 21 32
10 15 0 23 126
10 15 2 0 72
10 15 3 0 8
10 15 4 21 8
10 15 5 21 8
10 15 6 21 8
10 15 7 21 8
10 15 8 21 8
10 15 9 21 8
10 15 10 21 8
10 15 11 21 8
10 15 12 21 8
10 15 13 21 40
10 15 15 23 126
11 0 0 23 126
11 0 6 25 82
11 0 7 25 18
11 0 8 25 18
11 0 9 25 50
11 0 15 23 126
11 1 6 25 66
11 1 7 25 2
11 1 8 25 2
11 1 9 25 34
11 2 6 22 66
11 2 7 22 2
11 2 8 22 2
11 2 9 22 34
11 3 6 22 66
11 3 7 22 2
11 3 8 22 2
11 3 9 22 34
11 4 4 26 80
11 4 5 26 16
11 4 6 25 0
11 4 7 25 0
11 4 8 25 0
11 4 9 25 0
11 4 10 26 18
11 4 11 26 50
11 5 4 26 64
11 5 5 26 0
11 5 6 25 0
11 5 7 25 0
11 5 8 25 0
11 5 9 25 0
11 5 10 26 2
11 5 11 26 34
11 6 4 26 66
11 6 5 26 2
11 6 6 26 2
11 6 7 26 2
11 6 8 26 2
11 6 9 26 2
11 6 10 26 2
11 6 11 26 34
11 7 4 26 66
11 7 5 26 2
11 7 6 26 2
11 7 7 26 2
11 7 8 26 2
11 7 9 26 2
11 7 10 26 2
11 7 11 26 34
11 8 2 25 80
11 8 3 25 16
11 8 4 25 0
11 8 5 25 0
11 8 6 25 0
11 8 7 25 0
11 8 8 15 0
11 8 9 15 0
11 8 10 7 0
11 8 11 7 0
11 8 12 25 16
11 8 13 25 48
11 9 2 25 64
11 9 3 25 0
11 9 4 25 0
11 9 5 25 0
11 9 6 25 0
11 9 7 25 0
11 9 8 15 0
11 9 9 15 0
11 9 10 7 0
11 9 11 7 0
11 9 12 25 0
11 9 13 25 32
11 10 2 0 64
11 10 3 0 0
11 10 4 2 0
11 10 5 2 0
11 10 6 10 0
11 10 7 10 0
11 10 8 11 0
11 10 9 11 0
11 10 10 4 0
11 10 11 4 0
11 10 12 21 0
11 10 13 21 32
11 11 2 0 64
11 11 3 0 0
11 11 4 2 0
11 11 5 2 0
11 11 6 10 0
11 11 7 10 0
11 11 8 11 0
11 11 9 11 0
11 11 10 4 0
11 11 11 4 0
11 11 12 21 0
11 11 13 21 32
11 12 2 24 64
11 12 3 24 0
11 12 4 4 0
11 12 5 4 0
11 12 6 3 0
11 12 7 3 0
11 12 8 16 0
11 12 9 16 0
11 12 10 1 0
11 12 11 1 0
11 12 12 21 0
11 12 13 21 32
11 13 2 24 64
11 13 3 24 0
11 13 4 4 0
11 13 5 4 0
11 13 6 3 0
11 13 7 3 0
11 13 8 16 0
11 13 9 16 0
11 13 10 1 0
11 13 11 1 0
11 13 12 21 0
11 13 13 21 32
11 14 2 0 64
11 14 3 0 0
11 14 4 21 0
11 14 5 21 0
11 14 6 21 0
11 14 7 21 0
11 14 8 21 0
11 14 9 21 0
11 14 10 21 0
11 14 11 21 0
11 14 12 21 0
11 14 13 21 32
11 15 0 23 126
11 15 2 0 72
11 15 3 0 8
11 15 4 21 8
11 15 5 21 8
11 15 6 21 8
11 15 7 21 8
11 15 8 21 8
11 15 9 21 8
11 15 10 21 8
11 15 11 21 8
11 15 12 21 8
11 15 13 21 40
11 15 15 23 126
12 0 0 23 126
12 0 15 23 126
12 4 2 25 84
12 4 3 25 20
12 4 4 25 16
12 4 5 25 16
12 4 6 26 16
12 4 7 26 16
12 4 8 26 16
12 4 9 26 48
12 5 2 25 76
12 5 3 25 12
12 5 4 25 8
12 5 5 25 8
12 5 6 26 8
12 5 7 26 8
12 5 8 26 8
12 5 9 26 40
12 8 2 25 80
12 8 3 25 16
12 8 4 25 16
12 8 5 25 16
12 8 6 25 16
12 8 7 25 16
12 8 8 25 16
12 8 9 25 16
12 8 10 25 16
12 8 11 25 16
12 8 12 25 16
12 8 13 25 48
12 9 2 25 64
12 9 3 25 0
12 9 4 25 0
12 9 5 25 0
12 9 6 25 0
12 9 7 25 0
12 9 8 25 0
12 9 9 25 0
12 9 10 25 0
12 9 11 25 0
12 9 12 25 0
12 9 13 25 32
12 10 2 0 64
12 10 3 0 0
12 10 4 25 0
12 10 5 25 0
12 10 6 25 0
12 10 7 25 0
12 10 8 25 0
12 10 9 25 0
12 10 10 25 0
12 10 11 25 0
12 10 12 25 0
12 10 13 25 32
12 11 2 0 64
12 11 3 0 0
12 11 4 25 0
12 11 5 25 0
12 11 6 25 0
12 11 7 25 0
12 11 8 25 0
12 11 9 25 0
12 11 10 25 0
12 11 11 25 0
12 11 12 25 0
12 11 13 25 32
12 12 2 0 64
12 12 3 0 0
12 12 4 0 0
12 12 5 0 0
12 12 6 0 0
12 12 7 0 0
12 12 8 0 0
12 12 9 0 0
12 12 10 21 0
12 12 11 21 0
12 12 12 21 0
12 12 13 21 32
12 13 2 0 64
12 13 3 0 0
12 13 4 0 0
12 13 5 0 0
12 13 6 0 0
12 13 7 0 0
12 13 8 0 0
12 13 9 0 0
12 13 10 21 0
12 13 11 21 0
12 13 12 21 0
12 13 13 21 32
12 14 2 0 64
12 14 3 0 0
12 14 4 21 0
12 14 5 21 0
12 14 6 21 0
12 14 7 21 0
12 14 8 21 0
12 14 9 21 0
12 14 10 21 0
12 14 11 21 0
12 14 12 21 0
12 14 13 21 32
12 15 0 23 126
12 15 2 0 72
12 15 3 0 8
12 15 4 21 8
12 15 5 21 8
12 15 6 21 8
12 15 7 21 8
12 15 8 21 8
12 15 9 21 8
12 15 10 21 8
12 15 11 21 8
12 15 12 21 8
12 15 13 21 40
12 15 15 23 126
13 0 0 23 126
13 0 15 23 126
13 4 2 25 82
13 4 3 25 18
13 4 4 25 18
13 4 5 25 18
13 4 6 26 18
13 4 7 26 18
13 4 8 26 18
13 4 9 26 50
13 5 2 25 74
13 5 3 25 10
13 5 4 25 10
13 5 5 25 10
13 5 6 26 10
13 5 7 26 10
13 5 8 26 10
13 5 9 26 42
13 8 2 25 82
13 8 3 25 18
13 8 4 25 18
13 8 5 25 18
13 8 6 25 18
13 8 7 25 18
13 8 8 25 18
13 8 9 25 18
13 8 10 25 18
13 8 11 25 18
13 8 12 25 18
13 8 13 25 50
13 9 2 25 66
13 9 3 25 2
13 9 4 25 2
13 9 5 25 2
13 9 6 25 2
13 9 7 25 2
13 9 8 25 2
13 9 9 25 2
13 9 10 25 2
13 9 11 25 2
13 9 12 25 2
13 9 13 25 34
13 10 2 0 66
13 10 3 0 2
13 10 4 25 2
13 10 5 25 2
13 10 6 25 2
13 10 7 25 2
13 10 8 25 2
13 10 9 25 2
13 10 10 25 2
13 10 11 25 2
13 10 12 25 2
13 10 13 25 34
13 11 2 0 66
13 11 3 0 2
13 11 4 25 2
13 11 5 25 2
13 11 6 25 2
13 11 7 25 2
13 11 8 25 2
13 11 9 25 2
13 11 10 25 2
13 11 11 25 2
13 11 12 25 2
13 11 13 25 34
13 12 2 0 66
13 12 3 0 2
13 12 4 0 2
13 12 5 0 2
13 12 6 0 2
13 12 7 0 2
13 12 8 0 2
13 12 9 0 2
13 12 10 21 2
13 12 11 21 2
13 12 12 21 2
13 12 13 21 34
13 13 2 0 66
13 13 3 0 2
13 13 4 0 2
13 13 5 0 2
13 13 6 0 2
13 13 7 0 2
13 13 8 0 2
13 13 9 0 2
13 13 10 21 2
13 13 11 21 2
13 13 12 21 2
13 13 13 21 34
13 14 2 0 66
13 14 3 0 2
13 14 4 21 2
13 14 5 21 2
13 14 6 21 2
13 14 7 21 2
13 14 8 21 2
13 14 9 21 2
13 14 10 21 2
13 14 11 21 2
13 14 12 21 2
13 14 13 21 34
13 15 0 23 126
13 15 2 0 74
13 15 3 0 10
13 15 4 21 10
13 15 5 21 10
13 15 6 21 10
13 15 7 21 10
13 15 8 21 10
13 15 9 21 10
13 15 10 21 10
13 15 11 21 10
13 15 12 21 10
13 15 13 21 42
13 15 15 23 126
14 0 0 23 126
14 0 15 23 126
14 15 0 23 126
14 15 15 23 126
15 0 0 23 126
15 0 1 23 126
15 0 2 23 126
15 0 3 23 126
15 0 4 23 126
15 0 5 23 126
15 0 6 23 126
15 0 7 23 126
15 0 8 23 126
15 0 9 23 126
15 0 10 23 126
15 0 11 23 126
15 0 12 23 126
15 0 13 23 126
15 0 14 23 126
15 0 15 23 126
15 1 0 23 126
15 1 15 23 126
15 2 0 23 126
15 2 15 23 126
15 3 0 23 126
15 3 15 23 126
15 4 0 23 126
15 4 15 23 126
15 5 0 23 126
15 5 15 23 126
15 6 0 23 126
15 6 15 23 126
15 7 0 23 126
15 7 15 23 126
15 8 0 23 126
15 8 15 23 126
15 9 0 23 126
15 9 15 23 126
15 10 0 23 126
15 10 15 23 126
15 11 0 23 126
15 11 15 23 126
15 12 0 23 126
15 12 15 23 126
15 13 0 23 126
15 13 15 23 126
15 14 0 23 126
15 14 15 23 126
15 15 0 23 126
15 15 1 23 126
15 15 2 23 126
15 15 3 23 126
15 15 4 23 126
15 15 5 23 126
15 15 6 23 126
15 15 7 23 126
15 15 8 23 126
15 15 9 23 126
15 15 10 23 126
15 15 11 23 126
15 15 12 23 126
15 15 13 23 126
15 15 14 23 126
15 15 15 23 126
