Qubicle Exchange Format
Version 0.2
www.minddesk.com
8 8 8
6
0.000000 0.000000 0.000000
0.250980 0.172549 0.000000
0.533333 0.439216 0.000000
0.933333 0.933333 0.933333
0.988235 0.737255 0.690196
1.000000 1.000000 1.000000
1 2 1 4 116
1 2 6 4 116
1 3 1 4 68
1 3 2 4 20
1 3 3 4 20
1 3 4 4 20
1 3 5 4 20
1 3 6 4 36
1 4 1 0 68
1 4 2 0 4
1 4 3 0 4
1 4 4 0 4
1 4 5 0 4
1 4 6 0 36
1 5 1 0 68
1 5 2 3 4
1 5 3 0 4
1 5 4 0 4
1 5 5 3 4
1 5 6 0 36
1 6 1 0 76
1 6 2 0 12
1 6 3 0 12
1 6 4 0 12
1 6 5 0 12
1 6 6 0 44
2 2 1 4 80
2 2 2 5 20
2 2 3 5 20
2 2 4 5 20
2 2 5 5 20
2 2 6 4 48
2 3 1 4 64
2 3 2 4 0
2 3 3 4 0
2 3 4 4 0
2 3 5 4 0
2 3 6 4 32
2 4 1 4 64
2 4 2 4 126
2 4 3 4 126
2 4 4 4 126
2 4 5 4 126
2 4 6 4 32
2 5 1 0 64
2 5 2 4 126
2 5 3 4 126
2 5 4 4 126
2 5 5 4 126
2 5 6 0 32
2 6 1 1 72
2 6 2 1 8
2 6 3 1 8
2 6 4 1 8
2 6 5 1 8
2 6 6 1 40
3 0 2 4 116
3 0 5 4 116
3 1 2 2 100
3 1 5 2 100
3 2 1 5 80
3 2 2 5 0
3 2 3 5 16
3 2 4 5 16
3 2 5 4 0
3 2 6 5 48
3 3 1 4 64
3 3 2 4 0
3 3 3 4 0
3 3 4 4 0
3 3 5 4 0
3 3 6 4 32
3 4 1 4 64
3 4 2 4 126
3 4 3 4 126
3 4 4 4 126
3 4 5 4 126
3 4 6 4 32
3 5 1 0 64
3 5 2 4 126
3 5 3 4 126
3 5 4 4 126
3 5 5 4 126
3 5 6 0 32
3 6 1 1 72
3 6 2 1 8
3 6 3 1 8
3 6 4 1 8
3 6 5 1 8
3 6 6 1 40
4 0 2 4 114
4 0 5 4 114
4 1 2 2 98
4 1 5 2 98
4 2 1 5 82
4 2 2 5 0
4 2 3 5 16
4 2 4 5 16
4 2 5 4 0
4 2 6 5 50
4 3 1 4 64
4 3 2 4 0
4 3 3 4 0
4 3 4 4 126
4 3 5 4 126
4 3 6 4 32
4 4 1 4 64
4 4 2 4 0
4 4 3 4 126
4 4 4 4 126
4 4 5 4 126
4 4 6 4 32
4 5 1 0 64
4 5 2 4 126
4 5 3 4 126
4 5 4 4 126
4 5 5 4 126
4 5 6 0 32
4 6 1 1 72
4 6 2 1 8
4 6 3 1 8
4 6 4 1 8
4 6 5 1 8
4 6 6 1 40
5 2 2 5 82
5 2 3 5 18
5 2 4 5 18
5 2 5 5 50
5 3 1 4 80
5 3 2 4 0
5 3 3 4 126
5 3 4 4 126
5 3 5 4 126
5 3 6 4 48
5 4 1 4 64
5 4 2 4 0
5 4 3 4 126
5 4 4 4 126
5 4 5 4 126
5 4 6 4 32
5 5 1 0 64
5 5 2 4 126
5 5 3 4 126
5 5 4 4 126
5 5 5 4 126
5 5 6 1 32
5 6 1 1 72
5 6 2 1 8
5 6 3 1 8
5 6 4 1 8
5 6 5 1 8
5 6 6 1 40
6 3 1 4 82
6 3 2 4 18
6 3 3 4 18
6 3 4 4 18
6 3 5 4 18
6 3 6 4 50
6 4 1 4 66
6 4 2 1 2
6 4 3 1 2
6 4 4 1 2
6 4 5 1 2
6 4 6 4 34
6 5 1 1 66
6 5 2 1 2
6 5 3 1 2
6 5 4 1 2
6 5 5 1 2
6 5 6 1 34
6 6 1 1 74
6 6 2 1 10
6 6 3 1 10
6 6 4 1 10
6 6 5 1 10
6 6 6 1 42
