Qubicle Exchange Format
Version 0.2
www.minddesk.com
8 8 8
3
0.333333 0.333333 0.333333
0.466667 0.466667 0.466667
1.000000 0.070588 0.000000
1 0 6 1 126
1 1 5 1 126
1 1 6 1 126
2 0 1 1 118
2 1 1 1 78
2 1 2 1 30
2 1 3 1 28
2 1 4 1 60
2 4 2 1 84
2 4 3 1 20
2 4 4 1 20
2 4 5 1 52
2 5 2 2 126
2 5 3 1 4
2 5 4 1 4
2 5 5 2 126
2 6 2 1 76
2 6 3 1 12
2 6 4 1 12
2 6 5 1 44
3 0 6 1 126
3 1 3 1 80
3 1 4 1 48
3 1 5 1 126
3 1 6 1 126
3 2 3 0 126
3 2 4 0 126
3 3 3 0 126
3 3 4 0 126
3 4 2 1 80
3 4 3 1 0
3 4 4 1 0
3 4 5 1 48
3 5 2 1 64
3 5 3 1 0
3 5 4 1 0
3 5 5 1 32
3 6 2 1 72
3 6 3 1 8
3 6 4 1 8
3 6 5 1 40
4 0 1 1 126
4 1 1 1 126
4 1 2 1 126
4 1 3 1 80
4 1 4 1 48
4 2 3 0 126
4 2 4 0 126
4 3 3 0 126
4 3 4 0 126
4 4 2 1 80
4 4 3 1 0
4 4 4 1 0
4 4 5 1 48
4 5 2 1 64
4 5 3 1 0
4 5 4 1 0
4 5 5 1 32
4 6 2 1 72
4 6 3 1 8
4 6 4 1 8
4 6 5 1 40
5 0 6 1 126
5 1 3 1 80
5 1 4 1 48
5 1 5 1 126
5 1 6 1 126
5 2 3 0 126
5 2 4 0 126
5 3 3 0 126
5 3 4 0 126
5 4 2 1 80
5 4 3 1 0
5 4 4 1 0
5 4 5 1 48
5 5 2 1 64
5 5 3 1 0
5 5 4 1 0
5 5 5 1 32
5 6 2 1 72
5 6 3 1 8
5 6 4 1 8
5 6 5 1 40
6 0 1 1 126
6 1 1 1 126
6 1 2 1 126
6 1 3 1 90
6 1 4 1 126
6 4 2 1 82
6 4 3 1 18
6 4 4 1 18
6 4 5 1 50
6 5 2 1 66
6 5 3 1 2
6 5 4 1 2
6 5 5 1 34
6 6 2 1 74
6 6 3 1 10
6 6 4 1 10
6 6 5 1 42
