Qubicle Exchange Format
Version 0.2
www.minddesk.com
8 8 8
30
0.000000 0.239216 0.000000
0.000000 0.243137 0.000000
0.000000 0.247059 0.000000
0.000000 0.250980 0.000000
0.000000 0.254902 0.000000
0.000000 0.258824 0.000000
0.000000 0.262745 0.000000
0.000000 0.266667 0.000000
0.003922 0.270588 0.003922
0.007843 0.270588 0.007843
0.011765 0.274510 0.011765
0.015686 0.278431 0.015686
0.019608 0.282353 0.019608
0.023529 0.282353 0.023529
0.027451 0.286275 0.027451
0.031373 0.290196 0.031373
0.035294 0.294118 0.035294
0.039216 0.294118 0.039216
0.043137 0.298039 0.043137
0.050980 0.301961 0.050980
0.054902 0.305882 0.054902
0.058824 0.309804 0.058824
0.066667 0.313726 0.066667
0.070588 0.317647 0.070588
0.078431 0.325490 0.078431
0.082353 0.325490 0.082353
0.086275 0.329412 0.086275
0.090196 0.333333 0.090196
0.913725 0.000000 0.000000
0.992157 0.019608 0.019608
0 3 2 26 92
0 3 3 1 20
0 3 4 5 20
0 3 5 21 60
0 4 3 4 76
0 4 4 17 44
1 3 2 19 80
1 3 3 15 16
1 3 4 26 16
1 3 5 11 48
1 4 2 29 76
1 4 3 18 8
1 4 4 11 8
1 4 5 28 44
2 0 2 22 118
2 0 5 10 118
2 1 2 10 68
2 1 3 23 20
2 1 4 3 20
2 1 5 16 36
2 2 2 9 68
2 2 3 6 4
2 2 4 4 4
2 2 5 4 36
2 3 2 3 64
2 3 3 13 0
2 3 4 1 0
2 3 5 17 32
2 4 2 4 66
2 4 3 25 10
2 4 4 4 10
2 4 5 27 34
2 5 2 1 110
2 5 5 4 110
3 1 2 23 80
3 1 3 6 16
3 1 4 5 16
3 1 5 11 48
3 2 2 6 64
3 2 3 4 0
3 2 4 25 0
3 2 5 25 32
3 3 2 15 72
3 3 3 3 8
3 3 4 18 8
3 3 5 5 40
4 1 2 3 80
4 1 3 4 16
4 1 4 5 16
4 1 5 27 48
4 2 2 23 64
4 2 3 11 0
4 2 4 7 0
4 2 5 1 32
4 3 2 27 72
4 3 3 15 8
4 3 4 6 8
4 3 5 12 40
5 1 2 7 80
5 1 3 26 16
5 1 4 2 16
5 1 5 0 48
5 2 2 8 64
5 2 3 3 0
5 2 4 4 0
5 2 5 11 32
5 3 2 21 72
5 3 3 5 8
5 3 4 0 8
5 3 5 3 40
6 0 2 24 118
6 0 5 3 118
6 1 2 1 66
6 1 3 25 18
6 1 4 3 18
6 1 5 20 34
6 2 2 0 66
6 2 3 2 2
6 2 4 14 2
6 2 5 8 34
6 3 2 6 74
6 3 3 4 8
6 3 4 5 8
6 3 5 1 42
7 3 3 6 90
7 3 4 2 58
