Qubicle Exchange Format
Version 0.2
www.minddesk.com
8 8 8
34
0.000000 0.211765 0.070588
0.000000 0.215686 0.070588
0.000000 0.219608 0.070588
0.000000 0.223529 0.074510
0.000000 0.227451 0.074510
0.000000 0.231373 0.074510
0.000000 0.235294 0.078431
0.003922 0.239216 0.082353
0.007843 0.243137 0.086275
0.011765 0.243137 0.090196
0.015686 0.247059 0.094118
0.019608 0.250980 0.098039
0.023529 0.254902 0.101961
0.027451 0.254902 0.105882
0.031373 0.258824 0.109804
0.039216 0.266667 0.117647
0.043137 0.266667 0.117647
0.047059 0.270588 0.121569
0.050980 0.274510 0.125490
0.054902 0.278431 0.129412
0.058824 0.278431 0.133333
0.062745 0.282353 0.137255
0.066667 0.286275 0.141176
0.070588 0.290196 0.145098
0.074510 0.294118 0.149020
0.078431 0.294118 0.152941
0.082353 0.298039 0.156863
0.086275 0.301961 0.160784
0.090196 0.305882 0.160784
0.458824 0.027451 0.000000
0.486275 0.031373 0.000000
0.525490 0.113725 0.082353
0.658824 0.003922 0.066667
0.674510 0.058824 0.117647
1 2 3 30 126
1 2 4 30 126
1 2 5 4 28
1 2 6 16 62
1 4 1 7 84
1 4 2 23 20
1 4 3 3 20
1 4 4 3 20
1 4 5 3 20
1 4 6 17 52
1 5 1 3 68
1 5 2 29 4
1 5 3 0 4
1 5 4 9 4
1 5 5 4 4
1 5 6 2 36
1 6 1 3 68
1 6 2 15 4
1 6 3 22 4
1 6 4 5 4
1 6 5 21 4
1 6 6 5 36
1 7 1 3 76
1 7 2 1 12
1 7 3 28 12
1 7 4 1 12
1 7 5 22 12
1 7 6 2 44
2 0 3 20 86
2 0 4 25 54
2 1 3 2 70
2 1 4 19 38
2 2 2 30 126
2 2 3 20 0
2 2 4 5 0
2 2 5 30 126
2 3 2 30 126
2 3 3 30 126
2 3 4 30 126
2 3 5 30 126
2 4 1 7 80
2 4 2 4 0
2 4 3 2 0
2 4 4 8 0
2 4 5 3 0
2 4 6 3 48
2 5 1 28 64
2 5 2 0 0
2 5 3 4 0
2 5 4 16 0
2 5 5 5 0
2 5 6 9 32
2 6 1 5 64
2 6 2 10 0
2 6 3 17 0
2 6 4 1 0
2 6 5 17 0
2 6 6 33 32
2 7 1 12 72
2 7 2 5 8
2 7 3 29 8
2 7 4 14 8
2 7 5 0 8
2 7 6 25 40
3 2 2 30 126
3 2 3 3 16
3 2 4 3 16
3 2 5 2 126
3 3 2 30 126
3 3 3 18 0
3 3 4 23 0
3 3 5 30 126
3 4 1 21 80
3 4 2 8 0
3 4 3 22 0
3 4 4 5 0
3 4 5 18 0
3 4 6 0 48
3 5 1 22 64
3 5 2 2 0
3 5 3 2 0
3 5 4 26 0
3 5 5 15 0
3 5 6 0 32
3 6 1 27 64
3 6 2 23 0
3 6 3 11 0
3 6 4 24 0
3 6 5 5 0
3 6 6 4 32
3 7 1 12 72
3 7 2 22 8
3 7 3 2 8
3 7 4 5 8
3 7 5 0 8
3 7 6 1 40
4 2 2 30 126
4 2 3 21 16
4 2 4 22 16
4 2 5 30 126
4 3 2 2 126
4 3 3 4 0
4 3 4 1 0
4 3 5 30 126
4 4 1 2 80
4 4 2 25 0
4 4 3 3 0
4 4 4 15 0
4 4 5 28 0
4 4 6 16 48
4 5 1 9 64
4 5 2 4 0
4 5 3 0 0
4 5 4 1 0
4 5 5 0 0
4 5 6 25 32
4 6 1 4 64
4 6 2 5 0
4 6 3 5 0
4 6 4 16 0
4 6 5 19 0
4 6 6 23 32
4 7 1 7 72
4 7 2 2 8
4 7 3 4 8
4 7 4 17 8
4 7 5 24 8
4 7 6 22 40
5 0 3 20 86
5 0 4 5 54
5 1 3 6 70
5 1 4 2 38
5 2 2 30 126
5 2 3 21 0
5 2 4 10 0
5 2 5 30 126
5 3 2 30 126
5 3 3 30 126
5 3 4 30 126
5 3 5 2 126
5 4 1 15 80
5 4 2 6 0
5 4 3 19 0
5 4 4 22 0
5 4 5 19 0
5 4 6 0 48
5 5 1 20 64
5 5 2 3 0
5 5 3 13 0
5 5 4 11 0
5 5 5 1 0
5 5 6 2 32
5 6 1 5 64
5 6 2 0 0
5 6 3 20 0
5 6 4 2 0
5 6 5 3 0
5 6 6 32 32
5 7 1 9 72
5 7 2 0 8
5 7 3 0 8
5 7 4 5 8
5 7 5 5 8
5 7 6 18 40
6 2 3 30 126
6 2 4 22 26
6 2 5 6 26
6 2 6 4 62
6 4 1 14 82
6 4 2 23 18
6 4 3 0 18
6 4 4 0 18
6 4 5 26 18
6 4 6 1 50
6 5 1 17 66
6 5 2 6 2
6 5 3 2 2
6 5 4 19 2
6 5 5 2 2
6 5 6 2 34
6 6 1 4 66
6 6 2 1 2
6 6 3 4 2
6 6 4 12 2
6 6 5 2 2
6 6 6 4 34
6 7 1 5 74
6 7 2 31 10
6 7 3 12 10
6 7 4 0 10
6 7 5 5 10
6 7 6 3 42
