Qubicle Exchange Format
Version 0.2
www.minddesk.com
8 8 8
67
0.000000 0.211765 0.070588
0.000000 0.439216 0.925490
0.054902 0.266667 0.125490
0.070588 0.262745 0.133333
0.078431 0.278431 0.149020
0.121569 0.329412 0.192157
0.156863 0.349020 0.223529
0.180392 0.180392 0.180392
0.184314 0.184314 0.184314
0.188235 0.188235 0.188235
0.192157 0.192157 0.192157
0.196078 0.196078 0.196078
0.200000 0.200000 0.200000
0.203922 0.203922 0.203922
0.207843 0.207843 0.207843
0.211765 0.211765 0.211765
0.215686 0.215686 0.215686
0.219608 0.219608 0.219608
0.223529 0.223529 0.223529
0.227451 0.227451 0.227451
0.231373 0.231373 0.231373
0.235294 0.235294 0.235294
0.239216 0.239216 0.239216
0.243137 0.243137 0.243137
0.247059 0.247059 0.247059
0.250980 0.250980 0.250980
0.258824 0.258824 0.258824
0.262745 0.262745 0.262745
0.270588 0.270588 0.270588
0.870588 0.521569 0.188235
0.874510 0.525490 0.188235
0.874510 0.525490 0.192157
0.878431 0.529412 0.192157
0.882353 0.533333 0.192157
0.890196 0.556863 0.235294
0.890196 0.560784 0.243137
0.890196 0.890196 0.890196
0.894118 0.564706 0.250980
0.894118 0.666667 0.623529
0.898039 0.686275 0.647059
0.898039 0.690196 0.650980
0.901961 0.576471 0.266667
0.913725 0.576471 0.254902
0.925490 0.556863 0.203922
0.925490 0.576471 0.247059
0.933333 0.933333 0.933333
0.937255 0.560784 0.203922
0.937255 0.568627 0.215686
0.949020 0.568627 0.207843
0.949020 0.572549 0.219608
0.949020 0.713726 0.666667
0.952941 0.572549 0.207843
0.952941 0.603922 0.262745
0.960784 0.737255 0.694118
0.968627 0.603922 0.254902
0.968627 0.737255 0.694118
0.980392 0.596078 0.231373
0.980392 0.619608 0.270588
0.980392 0.619608 0.274510
0.980392 0.623529 0.274510
0.980392 0.631373 0.298039
0.980392 0.635294 0.305882
0.980392 0.635294 0.309804
0.980392 0.643137 0.321569
0.980392 0.749020 0.705882
0.992157 0.992157 0.992157
1.000000 1.000000 1.000000
1 2 3 66 92
1 2 4 66 28
1 2 5 11 28
1 2 6 14 62
1 4 1 11 84
1 4 2 8 20
1 4 3 10 20
1 4 4 8 20
1 4 5 11 20
1 4 6 9 52
1 5 1 16 68
1 5 2 8 4
1 5 3 11 4
1 5 4 28 4
1 5 5 7 4
1 5 6 14 36
1 6 1 7 76
1 6 2 24 12
1 6 3 10 12
1 6 4 22 12
1 6 5 27 12
1 6 6 19 44
2 0 3 8 86
2 0 4 12 54
2 1 3 13 70
2 1 4 24 38
2 2 2 66 84
2 2 3 65 0
2 2 4 36 0
2 2 5 66 48
2 3 2 66 68
2 3 3 66 4
2 3 4 66 4
2 3 5 66 36
2 4 1 9 80
2 4 2 56 0
2 4 3 47 0
2 4 4 60 0
2 4 5 61 0
2 4 6 25 48
2 5 1 18 64
2 5 2 54 0
2 5 3 32 0
2 5 4 59 0
2 5 5 57 0
2 5 6 1 126
2 6 1 8 72
2 6 2 9 8
2 6 3 51 0
2 6 4 48 0
2 6 5 8 8
2 6 6 17 40
2 7 3 23 78
2 7 4 18 46
3 2 2 66 80
3 2 3 66 16
3 2 4 66 16
3 2 5 66 48
3 3 2 66 64
3 3 3 63 0
3 3 4 42 0
3 3 5 66 32
3 4 1 7 80
3 4 2 37 0
3 4 3 43 0
3 4 4 58 0
3 4 5 43 0
3 4 6 45 48
3 5 1 22 64
3 5 2 30 0
3 5 3 44 0
3 5 4 41 0
3 5 5 46 0
3 5 6 10 32
3 6 1 9 72
3 6 2 25 8
3 6 3 9 8
3 6 4 11 8
3 6 5 10 8
3 6 6 28 40
4 2 2 66 80
4 2 3 66 16
4 2 4 66 16
4 2 5 66 48
4 3 2 66 64
4 3 3 55 0
4 3 4 39 0
4 3 5 66 32
4 4 1 26 80
4 4 2 6 0
4 4 3 3 0
4 4 4 38 0
4 4 5 31 0
4 4 6 45 48
4 5 1 7 64
4 5 2 60 0
4 5 3 33 0
4 5 4 49 0
4 5 5 62 0
4 5 6 11 32
4 6 1 11 72
4 6 2 9 8
4 6 3 7 8
4 6 4 8 8
4 6 5 8 8
4 6 6 25 40
5 0 3 15 86
5 0 4 9 54
5 1 3 10 70
5 1 4 7 38
5 2 2 66 82
5 2 3 50 0
5 2 4 53 0
5 2 5 66 48
5 3 2 66 66
5 3 3 66 2
5 3 4 66 2
5 3 5 66 34
5 4 1 10 80
5 4 2 0 0
5 4 3 5 0
5 4 4 64 0
5 4 5 40 0
5 4 6 10 48
5 5 1 9 64
5 5 2 2 0
5 5 3 4 0
5 5 4 29 0
5 5 5 34 0
5 5 6 1 126
5 6 1 7 72
5 6 2 10 8
5 6 3 52 0
5 6 4 35 0
5 6 5 22 8
5 6 6 20 40
5 7 3 22 78
5 7 4 23 46
6 2 3 66 90
6 2 4 66 26
6 2 5 9 26
6 2 6 13 62
6 4 1 7 82
6 4 2 11 18
6 4 3 8 18
6 4 4 11 18
6 4 5 7 18
6 4 6 23 50
6 5 1 13 66
6 5 2 11 2
6 5 3 21 2
6 5 4 26 2
6 5 5 8 2
6 5 6 18 34
6 6 1 14 74
6 6 2 7 10
6 6 3 7 10
6 6 4 26 10
6 6 5 8 10
6 6 6 18 42
