Qubicle Exchange Format
Version 0.2
www.minddesk.com
16 16 16
68
0.000000 0.211765 0.070588
0.000000 0.439216 0.925490
0.054902 0.266667 0.125490
0.070588 0.262745 0.133333
0.078431 0.278431 0.149020
0.121569 0.329412 0.192157
0.156863 0.349020 0.223529
0.180392 0.180392 0.180392
0.184314 0.184314 0.184314
0.188235 0.188235 0.188235
0.192157 0.192157 0.192157
0.196078 0.196078 0.196078
0.200000 0.200000 0.200000
0.203922 0.203922 0.203922
0.207843 0.207843 0.207843
0.211765 0.211765 0.211765
0.215686 0.215686 0.215686
0.219608 0.219608 0.219608
0.223529 0.223529 0.223529
0.227451 0.227451 0.227451
0.231373 0.231373 0.231373
0.235294 0.235294 0.235294
0.239216 0.239216 0.239216
0.243137 0.243137 0.243137
0.247059 0.247059 0.247059
0.250980 0.250980 0.250980
0.258824 0.258824 0.258824
0.262745 0.262745 0.262745
0.270588 0.270588 0.270588
0.600000 0.600000 0.600000
0.870588 0.521569 0.188235
0.874510 0.525490 0.188235
0.874510 0.525490 0.192157
0.878431 0.529412 0.192157
0.882353 0.533333 0.192157
0.890196 0.556863 0.235294
0.890196 0.560784 0.243137
0.890196 0.890196 0.890196
0.894118 0.564706 0.250980
0.894118 0.666667 0.623529
0.898039 0.686275 0.647059
0.898039 0.690196 0.650980
0.901961 0.576471 0.266667
0.913725 0.576471 0.254902
0.925490 0.556863 0.203922
0.925490 0.576471 0.247059
0.933333 0.933333 0.933333
0.937255 0.560784 0.203922
0.937255 0.568627 0.215686
0.949020 0.568627 0.207843
0.949020 0.572549 0.219608
0.949020 0.713726 0.666667
0.952941 0.572549 0.207843
0.952941 0.603922 0.262745
0.960784 0.737255 0.694118
0.968627 0.603922 0.254902
0.968627 0.737255 0.694118
0.980392 0.596078 0.231373
0.980392 0.619608 0.270588
0.980392 0.619608 0.274510
0.980392 0.623529 0.274510
0.980392 0.631373 0.298039
0.980392 0.635294 0.305882
0.980392 0.635294 0.309804
0.980392 0.643137 0.321569
0.980392 0.749020 0.705882
0.992157 0.992157 0.992157
1.000000 1.000000 1.000000
0 0 0 29 84
0 0 1 29 30
0 0 2 29 30
0 0 3 29 30
0 0 4 29 30
0 0 5 29 30
0 0 6 29 30
0 0 7 29 30
0 0 8 29 30
0 0 9 29 30
0 0 10 29 30
0 0 11 29 30
0 0 12 29 30
0 0 13 29 30
0 0 14 29 30
0 0 15 29 52
0 1 0 29 102
0 1 15 29 102
0 2 0 29 102
0 2 15 29 102
0 3 0 29 102
0 3 15 29 102
0 4 0 29 102
0 4 15 29 102
0 5 0 29 102
0 5 15 29 102
0 6 0 29 102
0 6 15 29 102
0 7 0 29 102
0 7 15 29 102
0 8 0 29 102
0 8 15 29 102
0 9 0 29 102
0 9 15 29 102
0 10 0 29 102
0 10 15 29 102
0 11 0 29 102
0 11 15 29 102
0 12 0 29 102
0 12 15 29 102
0 13 0 29 102
0 13 15 29 102
0 14 0 29 102
0 14 15 29 102
0 15 0 29 76
0 15 1 29 30
0 15 2 29 30
0 15 3 29 30
0 15 4 29 30
0 15 5 29 30
0 15 6 29 30
0 15 7 29 30
0 15 8 29 30
0 15 9 29 30
0 15 10 29 30
0 15 11 29 30
0 15 12 29 30
0 15 13 29 30
0 15 14 29 30
0 15 15 29 44
1 0 0 29 120
1 0 15 29 120
1 15 0 29 120
1 15 15 29 120
2 0 0 29 120
2 0 15 29 120
2 4 2 14 84
2 4 3 14 20
2 4 4 11 20
2 4 5 11 20
2 4 6 67 20
2 4 7 67 20
2 4 8 67 20
2 4 9 67 52
2 5 2 14 76
2 5 3 14 12
2 5 4 11 12
2 5 5 11 12
2 5 6 67 12
2 5 7 67 12
2 5 8 67 12
2 5 9 67 44
2 8 2 9 84
2 8 3 9 20
2 8 4 11 20
2 8 5 11 20
2 8 6 8 20
2 8 7 8 20
2 8 8 10 20
2 8 9 10 20
2 8 10 8 20
2 8 11 8 20
2 8 12 11 20
2 8 13 11 52
2 9 2 9 68
2 9 3 9 4
2 9 4 11 4
2 9 5 11 4
2 9 6 8 4
2 9 7 8 4
2 9 8 10 4
2 9 9 10 4
2 9 10 8 4
2 9 11 8 4
2 9 12 11 4
2 9 13 11 36
2 10 2 14 68
2 10 3 14 4
2 10 4 7 4
2 10 5 7 4
2 10 6 28 4
2 10 7 28 4
2 10 8 11 4
2 10 9 11 4
2 10 10 8 4
2 10 11 8 4
2 10 12 16 4
2 10 13 16 36
2 11 2 14 68
2 11 3 14 4
2 11 4 7 4
2 11 5 7 4
2 11 6 28 4
2 11 7 28 4
2 11 8 11 4
2 11 9 11 4
2 11 10 8 4
2 11 11 8 4
2 11 12 16 4
2 11 13 16 36
2 12 2 19 68
2 12 3 19 4
2 12 4 27 4
2 12 5 27 4
2 12 6 22 4
2 12 7 22 4
2 12 8 10 4
2 12 9 10 4
2 12 10 24 4
2 12 11 24 4
2 12 12 7 4
2 12 13 7 36
2 13 2 19 76
2 13 3 19 12
2 13 4 27 12
2 13 5 27 12
2 13 6 22 12
2 13 7 22 12
2 13 8 10 12
2 13 9 10 12
2 13 10 24 12
2 13 11 24 12
2 13 12 7 12
2 13 13 7 44
2 15 0 29 120
2 15 15 29 120
3 0 0 29 120
3 0 15 29 120
3 4 2 14 82
3 4 3 14 18
3 4 4 11 16
3 4 5 11 16
3 4 6 67 16
3 4 7 67 16
3 4 8 67 16
3 4 9 67 48
3 5 2 14 74
3 5 3 14 10
3 5 4 11 8
3 5 5 11 8
3 5 6 67 8
3 5 7 67 8
3 5 8 67 8
3 5 9 67 40
3 8 2 9 80
3 8 3 9 16
3 8 4 11 16
3 8 5 11 16
3 8 6 8 16
3 8 7 8 16
3 8 8 10 16
3 8 9 10 16
3 8 10 8 16
3 8 11 8 16
3 8 12 11 16
3 8 13 11 48
3 9 2 9 64
3 9 3 9 0
3 9 4 11 0
3 9 5 11 0
3 9 6 8 0
3 9 7 8 0
3 9 8 10 0
3 9 9 10 0
3 9 10 8 0
3 9 11 8 0
3 9 12 11 0
3 9 13 11 32
3 10 2 14 64
3 10 3 14 0
3 10 4 7 0
3 10 5 7 0
3 10 6 28 0
3 10 7 28 0
3 10 8 11 0
3 10 9 11 0
3 10 10 8 0
3 10 11 8 0
3 10 12 16 0
3 10 13 16 32
3 11 2 14 64
3 11 3 14 0
3 11 4 7 0
3 11 5 7 0
3 11 6 28 0
3 11 7 28 0
3 11 8 11 0
3 11 9 11 0
3 11 10 8 0
3 11 11 8 0
3 11 12 16 0
3 11 13 16 32
3 12 2 19 64
3 12 3 19 0
3 12 4 27 0
3 12 5 27 0
3 12 6 22 0
3 12 7 22 0
3 12 8 10 0
3 12 9 10 0
3 12 10 24 0
3 12 11 24 0
3 12 12 7 0
3 12 13 7 32
3 13 2 19 72
3 13 3 19 8
3 13 4 27 8
3 13 5 27 8
3 13 6 22 8
3 13 7 22 8
3 13 8 10 8
3 13 9 10 8
3 13 10 24 8
3 13 11 24 8
3 13 12 7 8
3 13 13 7 40
3 15 0 29 120
3 15 15 29 120
4 0 0 29 120
4 0 6 12 84
4 0 7 12 20
4 0 8 8 20
4 0 9 8 52
4 0 15 29 120
4 1 6 12 68
4 1 7 12 4
4 1 8 8 4
4 1 9 8 36
4 2 6 24 68
4 2 7 24 4
4 2 8 13 4
4 2 9 13 36
4 3 6 24 68
4 3 7 24 4
4 3 8 13 4
4 3 9 13 36
4 4 4 67 80
4 4 5 67 16
4 4 6 37 0
4 4 7 37 0
4 4 8 66 0
4 4 9 66 0
4 4 10 67 20
4 4 11 67 52
4 5 4 67 64
4 5 5 67 0
4 5 6 37 0
4 5 7 37 0
4 5 8 66 0
4 5 9 66 0
4 5 10 67 4
4 5 11 67 36
4 6 4 67 68
4 6 5 67 4
4 6 6 67 4
4 6 7 67 4
4 6 8 67 4
4 6 9 67 4
4 6 10 67 4
4 6 11 67 36
4 7 4 67 68
4 7 5 67 4
4 7 6 67 4
4 7 7 67 4
4 7 8 67 4
4 7 9 67 4
4 7 10 67 4
4 7 11 67 36
4 8 2 25 80
4 8 3 25 16
4 8 4 62 0
4 8 5 62 0
4 8 6 61 0
4 8 7 61 0
4 8 8 48 0
4 8 9 48 0
4 8 10 57 0
4 8 11 57 0
4 8 12 9 16
4 8 13 9 48
4 9 2 25 64
4 9 3 25 0
4 9 4 62 0
4 9 5 62 0
4 9 6 61 0
4 9 7 61 0
4 9 8 48 0
4 9 9 48 0
4 9 10 57 0
4 9 11 57 0
4 9 12 9 0
4 9 13 9 32
4 10 2 1 64
4 10 3 1 0
4 10 4 58 0
4 10 5 58 0
4 10 6 60 0
4 10 7 60 0
4 10 8 33 0
4 10 9 33 0
4 10 10 55 0
4 10 11 55 0
4 10 12 18 0
4 10 13 18 32
4 11 2 1 64
4 11 3 1 0
4 11 4 58 0
4 11 5 58 0
4 11 6 60 0
4 11 7 60 0
4 11 8 33 0
4 11 9 33 0
4 11 10 55 0
4 11 11 55 0
4 11 12 18 0
4 11 13 18 32
4 12 2 17 64
4 12 3 17 0
4 12 4 8 0
4 12 5 8 0
4 12 6 49 0
4 12 7 49 0
4 12 8 52 0
4 12 9 52 0
4 12 10 9 0
4 12 11 9 0
4 12 12 8 0
4 12 13 8 32
4 13 2 17 72
4 13 3 17 8
4 13 4 8 8
4 13 5 8 8
4 13 6 49 0
4 13 7 49 0
4 13 8 52 0
4 13 9 52 0
4 13 10 9 8
4 13 11 9 8
4 13 12 8 8
4 13 13 8 40
4 14 6 18 68
4 14 7 18 4
4 14 8 23 4
4 14 9 23 36
4 15 0 29 120
4 15 6 18 76
4 15 7 18 12
4 15 8 23 12
4 15 9 23 44
4 15 15 29 120
5 0 0 29 120
5 0 6 12 82
5 0 7 12 18
5 0 8 8 18
5 0 9 8 50
5 0 15 29 120
5 1 6 12 66
5 1 7 12 2
5 1 8 8 2
5 1 9 8 34
5 2 6 24 66
5 2 7 24 2
5 2 8 13 2
5 2 9 13 34
5 3 6 24 66
5 3 7 24 2
5 3 8 13 2
5 3 9 13 34
5 4 4 67 80
5 4 5 67 16
5 4 6 37 0
5 4 7 37 0
5 4 8 66 0
5 4 9 66 0
5 4 10 67 16
5 4 11 67 48
5 5 4 67 64
5 5 5 67 0
5 5 6 37 0
5 5 7 37 0
5 5 8 66 0
5 5 9 66 0
5 5 10 67 0
5 5 11 67 32
5 6 4 67 64
5 6 5 67 0
5 6 6 67 0
5 6 7 67 0
5 6 8 67 0
5 6 9 67 0
5 6 10 67 0
5 6 11 67 32
5 7 4 67 64
5 7 5 67 0
5 7 6 67 0
5 7 7 67 0
5 7 8 67 0
5 7 9 67 0
5 7 10 67 0
5 7 11 67 32
5 8 2 25 80
5 8 3 25 16
5 8 4 62 0
5 8 5 62 0
5 8 6 61 0
5 8 7 61 0
5 8 8 48 0
5 8 9 48 0
5 8 10 57 0
5 8 11 57 0
5 8 12 9 16
5 8 13 9 48
5 9 2 25 64
5 9 3 25 0
5 9 4 62 0
5 9 5 62 0
5 9 6 61 0
5 9 7 61 0
5 9 8 48 0
5 9 9 48 0
5 9 10 57 0
5 9 11 57 0
5 9 12 9 0
5 9 13 9 32
5 10 2 1 64
5 10 3 1 0
5 10 4 58 0
5 10 5 58 0
5 10 6 60 0
5 10 7 60 0
5 10 8 33 0
5 10 9 33 0
5 10 10 55 0
5 10 11 55 0
5 10 12 18 0
5 10 13 18 32
5 11 2 1 64
5 11 3 1 0
5 11 4 58 0
5 11 5 58 0
5 11 6 60 0
5 11 7 60 0
5 11 8 33 0
5 11 9 33 0
5 11 10 55 0
5 11 11 55 0
5 11 12 18 0
5 11 13 18 32
5 12 2 17 64
5 12 3 17 0
5 12 4 8 0
5 12 5 8 0
5 12 6 49 0
5 12 7 49 0
5 12 8 52 0
5 12 9 52 0
5 12 10 9 0
5 12 11 9 0
5 12 12 8 0
5 12 13 8 32
5 13 2 17 72
5 13 3 17 8
5 13 4 8 8
5 13 5 8 8
5 13 6 49 0
5 13 7 49 0
5 13 8 52 0
5 13 9 52 0
5 13 10 9 8
5 13 11 9 8
5 13 12 8 8
5 13 13 8 40
5 14 6 18 66
5 14 7 18 2
5 14 8 23 2
5 14 9 23 34
5 15 0 29 120
5 15 6 18 74
5 15 7 18 10
5 15 8 23 10
5 15 9 23 42
5 15 15 29 120
6 0 0 29 120
6 0 15 29 120
6 4 4 67 80
6 4 5 67 16
6 4 6 67 16
6 4 7 67 16
6 4 8 67 16
6 4 9 67 16
6 4 10 67 16
6 4 11 67 48
6 5 4 67 64
6 5 5 67 0
6 5 6 67 0
6 5 7 67 0
6 5 8 67 0
6 5 9 67 0
6 5 10 67 0
6 5 11 67 32
6 6 4 67 64
6 6 5 67 0
6 6 6 43 0
6 6 7 43 0
6 6 8 64 0
6 6 9 64 0
6 6 10 67 0
6 6 11 67 32
6 7 4 67 64
6 7 5 67 0
6 7 6 43 0
6 7 7 43 0
6 7 8 64 0
6 7 9 64 0
6 7 10 67 0
6 7 11 67 32
6 8 2 46 80
6 8 3 46 16
6 8 4 44 0
6 8 5 44 0
6 8 6 59 0
6 8 7 59 0
6 8 8 44 0
6 8 9 44 0
6 8 10 38 0
6 8 11 38 0
6 8 12 7 16
6 8 13 7 48
6 9 2 46 64
6 9 3 46 0
6 9 4 44 0
6 9 5 44 0
6 9 6 59 0
6 9 7 59 0
6 9 8 44 0
6 9 9 44 0
6 9 10 38 0
6 9 11 38 0
6 9 12 7 0
6 9 13 7 32
6 10 2 10 64
6 10 3 10 0
6 10 4 47 0
6 10 5 47 0
6 10 6 42 0
6 10 7 42 0
6 10 8 45 0
6 10 9 45 0
6 10 10 31 0
6 10 11 31 0
6 10 12 22 0
6 10 13 22 32
6 11 2 10 64
6 11 3 10 0
6 11 4 47 0
6 11 5 47 0
6 11 6 42 0
6 11 7 42 0
6 11 8 45 0
6 11 9 45 0
6 11 10 31 0
6 11 11 31 0
6 11 12 22 0
6 11 13 22 32
6 12 2 28 64
6 12 3 28 0
6 12 4 10 0
6 12 5 10 0
6 12 6 11 0
6 12 7 11 0
6 12 8 9 0
6 12 9 9 0
6 12 10 25 0
6 12 11 25 0
6 12 12 9 0
6 12 13 9 32
6 13 2 28 72
6 13 3 28 8
6 13 4 10 8
6 13 5 10 8
6 13 6 11 8
6 13 7 11 8
6 13 8 9 8
6 13 9 9 8
6 13 10 25 8
6 13 11 25 8
6 13 12 9 8
6 13 13 9 40
6 15 0 29 120
6 15 15 29 120
7 0 0 29 120
7 0 15 29 120
7 4 4 67 80
7 4 5 67 16
7 4 6 67 16
7 4 7 67 16
7 4 8 67 16
7 4 9 67 16
7 4 10 67 16
7 4 11 67 48
7 5 4 67 64
7 5 5 67 0
7 5 6 67 0
7 5 7 67 0
7 5 8 67 0
7 5 9 67 0
7 5 10 67 0
7 5 11 67 32
7 6 4 67 64
7 6 5 67 0
7 6 6 43 0
7 6 7 43 0
7 6 8 64 0
7 6 9 64 0
7 6 10 67 0
7 6 11 67 32
7 7 4 67 64
7 7 5 67 0
7 7 6 43 0
7 7 7 43 0
7 7 8 64 0
7 7 9 64 0
7 7 10 67 0
7 7 11 67 32
7 8 2 46 80
7 8 3 46 16
7 8 4 44 0
7 8 5 44 0
7 8 6 59 0
7 8 7 59 0
7 8 8 44 0
7 8 9 44 0
7 8 10 38 0
7 8 11 38 0
7 8 12 7 16
7 8 13 7 48
7 9 2 46 64
7 9 3 46 0
7 9 4 44 0
7 9 5 44 0
7 9 6 59 0
7 9 7 59 0
7 9 8 44 0
7 9 9 44 0
7 9 10 38 0
7 9 11 38 0
7 9 12 7 0
7 9 13 7 32
7 10 2 10 64
7 10 3 10 0
7 10 4 47 0
7 10 5 47 0
7 10 6 42 0
7 10 7 42 0
7 10 8 45 0
7 10 9 45 0
7 10 10 31 0
7 10 11 31 0
7 10 12 22 0
7 10 13 22 32
7 11 2 10 64
7 11 3 10 0
7 11 4 47 0
7 11 5 47 0
7 11 6 42 0
7 11 7 42 0
7 11 8 45 0
7 11 9 45 0
7 11 10 31 0
7 11 11 31 0
7 11 12 22 0
7 11 13 22 32
7 12 2 28 64
7 12 3 28 0
7 12 4 10 0
7 12 5 10 0
7 12 6 11 0
7 12 7 11 0
7 12 8 9 0
7 12 9 9 0
7 12 10 25 0
7 12 11 25 0
7 12 12 9 0
7 12 13 9 32
7 13 2 28 72
7 13 3 28 8
7 13 4 10 8
7 13 5 10 8
7 13 6 11 8
7 13 7 11 8
7 13 8 9 8
7 13 9 9 8
7 13 10 25 8
7 13 11 25 8
7 13 12 9 8
7 13 13 9 40
7 15 0 29 120
7 15 15 29 120
8 0 0 29 120
8 0 15 29 120
8 4 4 67 80
8 4 5 67 16
8 4 6 67 16
8 4 7 67 16
8 4 8 67 16
8 4 9 67 16
8 4 10 67 16
8 4 11 67 48
8 5 4 67 64
8 5 5 67 0
8 5 6 67 0
8 5 7 67 0
8 5 8 67 0
8 5 9 67 0
8 5 10 67 0
8 5 11 67 32
8 6 4 67 64
8 6 5 67 0
8 6 6 40 0
8 6 7 40 0
8 6 8 56 0
8 6 9 56 0
8 6 10 67 0
8 6 11 67 32
8 7 4 67 64
8 7 5 67 0
8 7 6 40 0
8 7 7 40 0
8 7 8 56 0
8 7 9 56 0
8 7 10 67 0
8 7 11 67 32
8 8 2 46 80
8 8 3 46 16
8 8 4 32 0
8 8 5 32 0
8 8 6 39 0
8 8 7 39 0
8 8 8 3 0
8 8 9 3 0
8 8 10 6 0
8 8 11 6 0
8 8 12 26 16
8 8 13 26 48
8 9 2 46 64
8 9 3 46 0
8 9 4 32 0
8 9 5 32 0
8 9 6 39 0
8 9 7 39 0
8 9 8 3 0
8 9 9 3 0
8 9 10 6 0
8 9 11 6 0
8 9 12 26 0
8 9 13 26 32
8 10 2 11 64
8 10 3 11 0
8 10 4 63 0
8 10 5 63 0
8 10 6 50 0
8 10 7 50 0
8 10 8 34 0
8 10 9 34 0
8 10 10 61 0
8 10 11 61 0
8 10 12 7 0
8 10 13 7 32
8 11 2 11 64
8 11 3 11 0
8 11 4 63 0
8 11 5 63 0
8 11 6 50 0
8 11 7 50 0
8 11 8 34 0
8 11 9 34 0
8 11 10 61 0
8 11 11 61 0
8 11 12 7 0
8 11 13 7 32
8 12 2 25 64
8 12 3 25 0
8 12 4 8 0
8 12 5 8 0
8 12 6 8 0
8 12 7 8 0
8 12 8 7 0
8 12 9 7 0
8 12 10 9 0
8 12 11 9 0
8 12 12 11 0
8 12 13 11 32
8 13 2 25 72
8 13 3 25 8
8 13 4 8 8
8 13 5 8 8
8 13 6 8 8
8 13 7 8 8
8 13 8 7 8
8 13 9 7 8
8 13 10 9 8
8 13 11 9 8
8 13 12 11 8
8 13 13 11 40
8 15 0 29 120
8 15 15 29 120
9 0 0 29 120
9 0 15 29 120
9 4 4 67 80
9 4 5 67 16
9 4 6 67 16
9 4 7 67 16
9 4 8 67 16
9 4 9 67 16
9 4 10 67 16
9 4 11 67 48
9 5 4 67 64
9 5 5 67 0
9 5 6 67 0
9 5 7 67 0
9 5 8 67 0
9 5 9 67 0
9 5 10 67 0
9 5 11 67 32
9 6 4 67 64
9 6 5 67 0
9 6 6 40 0
9 6 7 40 0
9 6 8 56 0
9 6 9 56 0
9 6 10 67 0
9 6 11 67 32
9 7 4 67 64
9 7 5 67 0
9 7 6 40 0
9 7 7 40 0
9 7 8 56 0
9 7 9 56 0
9 7 10 67 0
9 7 11 67 32
9 8 2 46 80
9 8 3 46 16
9 8 4 32 0
9 8 5 32 0
9 8 6 39 0
9 8 7 39 0
9 8 8 3 0
9 8 9 3 0
9 8 10 6 0
9 8 11 6 0
9 8 12 26 16
9 8 13 26 48
9 9 2 46 64
9 9 3 46 0
9 9 4 32 0
9 9 5 32 0
9 9 6 39 0
9 9 7 39 0
9 9 8 3 0
9 9 9 3 0
9 9 10 6 0
9 9 11 6 0
9 9 12 26 0
9 9 13 26 32
9 10 2 11 64
9 10 3 11 0
9 10 4 63 0
9 10 5 63 0
9 10 6 50 0
9 10 7 50 0
9 10 8 34 0
9 10 9 34 0
9 10 10 61 0
9 10 11 61 0
9 10 12 7 0
9 10 13 7 32
9 11 2 11 64
9 11 3 11 0
9 11 4 63 0
9 11 5 63 0
9 11 6 50 0
9 11 7 50 0
9 11 8 34 0
9 11 9 34 0
9 11 10 61 0
9 11 11 61 0
9 11 12 7 0
9 11 13 7 32
9 12 2 25 64
9 12 3 25 0
9 12 4 8 0
9 12 5 8 0
9 12 6 8 0
9 12 7 8 0
9 12 8 7 0
9 12 9 7 0
9 12 10 9 0
9 12 11 9 0
9 12 12 11 0
9 12 13 11 32
9 13 2 25 72
9 13 3 25 8
9 13 4 8 8
9 13 5 8 8
9 13 6 8 8
9 13 7 8 8
9 13 8 7 8
9 13 9 7 8
9 13 10 9 8
9 13 11 9 8
9 13 12 11 8
9 13 13 11 40
9 15 0 29 120
9 15 15 29 120
10 0 0 29 120
10 0 6 9 84
10 0 7 9 20
10 0 8 15 20
10 0 9 15 52
10 0 15 29 120
10 1 6 9 68
10 1 7 9 4
10 1 8 15 4
10 1 9 15 36
10 2 6 7 68
10 2 7 7 4
10 2 8 10 4
10 2 9 10 36
10 3 6 7 68
10 3 7 7 4
10 3 8 10 4
10 3 9 10 36
10 4 4 67 80
10 4 5 67 16
10 4 6 54 0
10 4 7 54 0
10 4 8 51 0
10 4 9 51 0
10 4 10 67 16
10 4 11 67 48
10 5 4 67 64
10 5 5 67 0
10 5 6 54 0
10 5 7 54 0
10 5 8 51 0
10 5 9 51 0
10 5 10 67 0
10 5 11 67 32
10 6 4 67 64
10 6 5 67 0
10 6 6 67 0
10 6 7 67 0
10 6 8 67 0
10 6 9 67 0
10 6 10 67 0
10 6 11 67 32
10 7 4 67 64
10 7 5 67 0
10 7 6 67 0
10 7 7 67 0
10 7 8 67 0
10 7 9 67 0
10 7 10 67 0
10 7 11 67 32
10 8 2 10 80
10 8 3 10 16
10 8 4 41 0
10 8 5 41 0
10 8 6 65 0
10 8 7 65 0
10 8 8 5 0
10 8 9 5 0
10 8 10 0 0
10 8 11 0 0
10 8 12 10 16
10 8 13 10 48
10 9 2 10 64
10 9 3 10 0
10 9 4 41 0
10 9 5 41 0
10 9 6 65 0
10 9 7 65 0
10 9 8 5 0
10 9 9 5 0
10 9 10 0 0
10 9 11 0 0
10 9 12 10 0
10 9 13 10 32
10 10 2 1 64
10 10 3 1 0
10 10 4 35 0
10 10 5 35 0
10 10 6 30 0
10 10 7 30 0
10 10 8 4 0
10 10 9 4 0
10 10 10 2 0
10 10 11 2 0
10 10 12 9 0
10 10 13 9 32
10 11 2 1 64
10 11 3 1 0
10 11 4 35 0
10 11 5 35 0
10 11 6 30 0
10 11 7 30 0
10 11 8 4 0
10 11 9 4 0
10 11 10 2 0
10 11 11 2 0
10 11 12 9 0
10 11 13 9 32
10 12 2 20 64
10 12 3 20 0
10 12 4 22 0
10 12 5 22 0
10 12 6 36 0
10 12 7 36 0
10 12 8 53 0
10 12 9 53 0
10 12 10 10 0
10 12 11 10 0
10 12 12 7 0
10 12 13 7 32
10 13 2 20 72
10 13 3 20 8
10 13 4 22 8
10 13 5 22 8
10 13 6 36 0
10 13 7 36 0
10 13 8 53 0
10 13 9 53 0
10 13 10 10 8
10 13 11 10 8
10 13 12 7 8
10 13 13 7 40
10 14 6 23 68
10 14 7 23 4
10 14 8 22 4
10 14 9 22 36
10 15 0 29 120
10 15 6 23 76
10 15 7 23 12
10 15 8 22 12
10 15 9 22 44
10 15 15 29 120
11 0 0 29 120
11 0 6 9 82
11 0 7 9 18
11 0 8 15 18
11 0 9 15 50
11 0 15 29 120
11 1 6 9 66
11 1 7 9 2
11 1 8 15 2
11 1 9 15 34
11 2 6 7 66
11 2 7 7 2
11 2 8 10 2
11 2 9 10 34
11 3 6 7 66
11 3 7 7 2
11 3 8 10 2
11 3 9 10 34
11 4 4 67 80
11 4 5 67 16
11 4 6 54 0
11 4 7 54 0
11 4 8 51 0
11 4 9 51 0
11 4 10 67 18
11 4 11 67 50
11 5 4 67 64
11 5 5 67 0
11 5 6 54 0
11 5 7 54 0
11 5 8 51 0
11 5 9 51 0
11 5 10 67 2
11 5 11 67 34
11 6 4 67 66
11 6 5 67 2
11 6 6 67 2
11 6 7 67 2
11 6 8 67 2
11 6 9 67 2
11 6 10 67 2
11 6 11 67 34
11 7 4 67 66
11 7 5 67 2
11 7 6 67 2
11 7 7 67 2
11 7 8 67 2
11 7 9 67 2
11 7 10 67 2
11 7 11 67 34
11 8 2 10 80
11 8 3 10 16
11 8 4 41 0
11 8 5 41 0
11 8 6 65 0
11 8 7 65 0
11 8 8 5 0
11 8 9 5 0
11 8 10 0 0
11 8 11 0 0
11 8 12 10 16
11 8 13 10 48
11 9 2 10 64
11 9 3 10 0
11 9 4 41 0
11 9 5 41 0
11 9 6 65 0
11 9 7 65 0
11 9 8 5 0
11 9 9 5 0
11 9 10 0 0
11 9 11 0 0
11 9 12 10 0
11 9 13 10 32
11 10 2 1 64
11 10 3 1 0
11 10 4 35 0
11 10 5 35 0
11 10 6 30 0
11 10 7 30 0
11 10 8 4 0
11 10 9 4 0
11 10 10 2 0
11 10 11 2 0
11 10 12 9 0
11 10 13 9 32
11 11 2 1 64
11 11 3 1 0
11 11 4 35 0
11 11 5 35 0
11 11 6 30 0
11 11 7 30 0
11 11 8 4 0
11 11 9 4 0
11 11 10 2 0
11 11 11 2 0
11 11 12 9 0
11 11 13 9 32
11 12 2 20 64
11 12 3 20 0
11 12 4 22 0
11 12 5 22 0
11 12 6 36 0
11 12 7 36 0
11 12 8 53 0
11 12 9 53 0
11 12 10 10 0
11 12 11 10 0
11 12 12 7 0
11 12 13 7 32
11 13 2 20 72
11 13 3 20 8
11 13 4 22 8
11 13 5 22 8
11 13 6 36 0
11 13 7 36 0
11 13 8 53 0
11 13 9 53 0
11 13 10 10 8
11 13 11 10 8
11 13 12 7 8
11 13 13 7 40
11 14 6 23 66
11 14 7 23 2
11 14 8 22 2
11 14 9 22 34
11 15 0 29 120
11 15 6 23 74
11 15 7 23 10
11 15 8 22 10
11 15 9 22 42
11 15 15 29 120
12 0 0 29 120
12 0 15 29 120
12 4 2 13 84
12 4 3 13 20
12 4 4 9 16
12 4 5 9 16
12 4 6 67 16
12 4 7 67 16
12 4 8 67 16
12 4 9 67 48
12 5 2 13 76
12 5 3 13 12
12 5 4 9 8
12 5 5 9 8
12 5 6 67 8
12 5 7 67 8
12 5 8 67 8
12 5 9 67 40
12 8 2 23 80
12 8 3 23 16
12 8 4 7 16
12 8 5 7 16
12 8 6 11 16
12 8 7 11 16
12 8 8 8 16
12 8 9 8 16
12 8 10 11 16
12 8 11 11 16
12 8 12 7 16
12 8 13 7 48
12 9 2 23 64
12 9 3 23 0
12 9 4 7 0
12 9 5 7 0
12 9 6 11 0
12 9 7 11 0
12 9 8 8 0
12 9 9 8 0
12 9 10 11 0
12 9 11 11 0
12 9 12 7 0
12 9 13 7 32
12 10 2 18 64
12 10 3 18 0
12 10 4 8 0
12 10 5 8 0
12 10 6 26 0
12 10 7 26 0
12 10 8 21 0
12 10 9 21 0
12 10 10 11 0
12 10 11 11 0
12 10 12 13 0
12 10 13 13 32
12 11 2 18 64
12 11 3 18 0
12 11 4 8 0
12 11 5 8 0
12 11 6 26 0
12 11 7 26 0
12 11 8 21 0
12 11 9 21 0
12 11 10 11 0
12 11 11 11 0
12 11 12 13 0
12 11 13 13 32
12 12 2 18 64
12 12 3 18 0
12 12 4 8 0
12 12 5 8 0
12 12 6 26 0
12 12 7 26 0
12 12 8 7 0
12 12 9 7 0
12 12 10 7 0
12 12 11 7 0
12 12 12 14 0
12 12 13 14 32
12 13 2 18 72
12 13 3 18 8
12 13 4 8 8
12 13 5 8 8
12 13 6 26 8
12 13 7 26 8
12 13 8 7 8
12 13 9 7 8
12 13 10 7 8
12 13 11 7 8
12 13 12 14 8
12 13 13 14 40
12 15 0 29 120
12 15 15 29 120
13 0 0 29 120
13 0 15 29 120
13 4 2 13 82
13 4 3 13 18
13 4 4 9 18
13 4 5 9 18
13 4 6 67 18
13 4 7 67 18
13 4 8 67 18
13 4 9 67 50
13 5 2 13 74
13 5 3 13 10
13 5 4 9 10
13 5 5 9 10
13 5 6 67 10
13 5 7 67 10
13 5 8 67 10
13 5 9 67 42
13 8 2 23 82
13 8 3 23 18
13 8 4 7 18
13 8 5 7 18
13 8 6 11 18
13 8 7 11 18
13 8 8 8 18
13 8 9 8 18
13 8 10 11 18
13 8 11 11 18
13 8 12 7 18
13 8 13 7 50
13 9 2 23 66
13 9 3 23 2
13 9 4 7 2
13 9 5 7 2
13 9 6 11 2
13 9 7 11 2
13 9 8 8 2
13 9 9 8 2
13 9 10 11 2
13 9 11 11 2
13 9 12 7 2
13 9 13 7 34
13 10 2 18 66
13 10 3 18 2
13 10 4 8 2
13 10 5 8 2
13 10 6 26 2
13 10 7 26 2
13 10 8 21 2
13 10 9 21 2
13 10 10 11 2
13 10 11 11 2
13 10 12 13 2
13 10 13 13 34
13 11 2 18 66
13 11 3 18 2
13 11 4 8 2
13 11 5 8 2
13 11 6 26 2
13 11 7 26 2
13 11 8 21 2
13 11 9 21 2
13 11 10 11 2
13 11 11 11 2
13 11 12 13 2
13 11 13 13 34
13 12 2 18 66
13 12 3 18 2
13 12 4 8 2
13 12 5 8 2
13 12 6 26 2
13 12 7 26 2
13 12 8 7 2
13 12 9 7 2
13 12 10 7 2
13 12 11 7 2
13 12 12 14 2
13 12 13 14 34
13 13 2 18 74
13 13 3 18 10
13 13 4 8 10
13 13 5 8 10
13 13 6 26 10
13 13 7 26 10
13 13 8 7 10
13 13 9 7 10
13 13 10 7 10
13 13 11 7 10
13 13 12 14 10
13 13 13 14 42
13 15 0 29 120
13 15 15 29 120
14 0 0 29 120
14 0 15 29 120
14 15 0 29 120
14 15 15 29 120
15 0 0 29 82
15 0 1 29 30
15 0 2 29 30
15 0 3 29 30
15 0 4 29 30
15 0 5 29 30
15 0 6 29 30
15 0 7 29 30
15 0 8 29 30
15 0 9 29 30
15 0 10 29 30
15 0 11 29 30
15 0 12 29 30
15 0 13 29 30
15 0 14 29 30
15 0 15 29 50
15 1 0 29 102
15 1 15 29 102
15 2 0 29 102
15 2 15 29 102
15 3 0 29 102
15 3 15 29 102
15 4 0 29 102
15 4 15 29 102
15 5 0 29 102
15 5 15 29 102
15 6 0 29 102
15 6 15 29 102
15 7 0 29 102
15 7 15 29 102
15 8 0 29 102
15 8 15 29 102
15 9 0 29 102
15 9 15 29 102
15 10 0 29 102
15 10 15 29 102
15 11 0 29 102
15 11 15 29 102
15 12 0 29 102
15 12 15 29 102
15 13 0 29 102
15 13 15 29 102
15 14 0 29 102
15 14 15 29 102
15 15 0 29 74
15 15 1 29 30
15 15 2 29 30
15 15 3 29 30
15 15 4 29 30
15 15 5 29 30
15 15 6 29 30
15 15 7 29 30
15 15 8 29 30
15 15 9 29 30
15 15 10 29 30
15 15 11 29 30
15 15 12 29 30
15 15 13 29 30
15 15 14 29 30
15 15 15 29 42
