Qubicle Exchange Format
Version 0.2
www.minddesk.com
8 8 8
65
0.000000 0.211765 0.070588
0.000000 0.439216 0.925490
0.054902 0.266667 0.125490
0.070588 0.262745 0.133333
0.078431 0.278431 0.149020
0.121569 0.329412 0.192157
0.156863 0.349020 0.223529
0.180392 0.180392 0.180392
0.184314 0.184314 0.184314
0.188235 0.188235 0.188235
0.192157 0.192157 0.192157
0.196078 0.196078 0.196078
0.200000 0.200000 0.200000
0.203922 0.203922 0.203922
0.207843 0.207843 0.207843
0.211765 0.211765 0.211765
0.215686 0.215686 0.215686
0.219608 0.219608 0.219608
0.223529 0.223529 0.223529
0.227451 0.227451 0.227451
0.231373 0.231373 0.231373
0.235294 0.235294 0.235294
0.239216 0.239216 0.239216
0.243137 0.243137 0.243137
0.247059 0.247059 0.247059
0.250980 0.250980 0.250980
0.258824 0.258824 0.258824
0.262745 0.262745 0.262745
0.270588 0.270588 0.270588
0.870588 0.521569 0.188235
0.874510 0.525490 0.188235
0.874510 0.525490 0.192157
0.878431 0.529412 0.192157
0.882353 0.533333 0.192157
0.890196 0.556863 0.235294
0.890196 0.560784 0.243137
0.890196 0.890196 0.890196
0.894118 0.564706 0.250980
0.894118 0.666667 0.623529
0.898039 0.686275 0.647059
0.898039 0.690196 0.650980
0.901961 0.576471 0.266667
0.913725 0.576471 0.254902
0.925490 0.556863 0.203922
0.925490 0.576471 0.247059
0.933333 0.933333 0.933333
0.937255 0.560784 0.203922
0.937255 0.568627 0.215686
0.949020 0.568627 0.207843
0.949020 0.572549 0.219608
0.952941 0.572549 0.207843
0.952941 0.603922 0.262745
0.960784 0.737255 0.694118
0.968627 0.603922 0.254902
0.968627 0.737255 0.694118
0.980392 0.596078 0.231373
0.980392 0.619608 0.270588
0.980392 0.619608 0.274510
0.980392 0.623529 0.274510
0.980392 0.631373 0.298039
0.980392 0.635294 0.305882
0.980392 0.635294 0.309804
0.980392 0.643137 0.321569
0.980392 0.749020 0.705882
1.000000 1.000000 1.000000
0 2 1 14 124
1 2 1 11 120
1 2 6 13 124
1 4 1 9 84
1 4 2 25 20
1 4 3 45 20
1 4 4 45 20
1 4 5 10 20
1 4 6 23 52
1 5 1 14 68
1 5 2 1 4
1 5 3 10 4
1 5 4 11 4
1 5 5 1 4
1 5 6 18 36
1 6 1 19 76
1 6 2 17 12
1 6 3 28 12
1 6 4 25 12
1 6 5 20 12
1 6 6 18 44
2 0 2 12 124
2 2 1 64 88
2 2 2 64 20
2 2 3 64 20
2 2 4 64 20
2 2 5 64 20
2 2 6 9 56
2 3 2 64 68
2 3 3 64 4
2 3 4 64 4
2 3 5 64 36
2 4 1 11 80
2 4 2 60 0
2 4 3 43 0
2 4 4 31 0
2 4 5 40 0
2 4 6 7 48
2 5 1 7 64
2 5 2 56 0
2 5 3 46 0
2 5 4 61 0
2 5 5 34 0
2 5 6 8 32
2 6 1 27 72
2 6 2 8 8
2 6 3 10 8
2 6 4 8 8
2 6 5 22 8
2 6 6 8 40
3 0 2 8 114
3 0 5 9 116
3 1 2 24 100
3 1 5 7 100
3 2 1 64 126
3 2 2 36 0
3 2 3 64 16
3 2 4 64 16
3 2 5 52 0
3 2 6 64 56
3 3 2 64 64
3 3 3 42 0
3 3 4 39 0
3 3 5 64 32
3 4 1 8 80
3 4 2 59 0
3 4 3 57 0
3 4 4 38 0
3 4 5 63 0
3 4 6 11 48
3 5 1 28 64
3 5 2 58 0
3 5 3 41 0
3 5 4 49 0
3 5 5 29 0
3 5 6 26 32
3 6 1 22 72
3 6 2 48 0
3 6 3 11 8
3 6 4 8 8
3 6 5 35 0
3 6 6 26 40
3 7 2 18 108
3 7 5 23 108
4 0 5 15 114
4 1 2 13 114
4 1 5 10 98
4 2 2 64 126
4 2 3 64 16
4 2 4 64 16
4 2 5 64 0
4 2 6 64 58
4 3 2 64 64
4 3 3 62 0
4 3 4 54 0
4 3 5 64 32
4 4 1 10 80
4 4 2 47 0
4 4 3 43 0
4 4 4 3 0
4 4 5 5 0
4 4 6 8 48
4 5 1 11 64
4 5 2 32 0
4 5 3 44 0
4 5 4 33 0
4 5 5 4 0
4 5 6 21 32
4 6 1 10 72
4 6 2 50 0
4 6 3 9 8
4 6 4 7 8
4 6 5 51 0
4 6 6 7 40
4 7 2 23 106
4 7 5 22 106
5 2 2 64 126
5 2 3 64 18
5 2 4 64 18
5 2 5 64 50
5 3 2 64 66
5 3 3 64 2
5 3 4 64 2
5 3 5 64 34
5 4 1 8 80
5 4 2 55 0
5 4 3 37 0
5 4 4 6 0
5 4 5 0 0
5 4 6 11 48
5 5 1 8 64
5 5 2 53 0
5 5 3 30 0
5 5 4 59 0
5 5 5 2 0
5 5 6 11 32
5 6 1 24 72
5 6 2 9 8
5 6 3 25 8
5 6 4 9 8
5 6 5 10 8
5 6 6 7 40
6 4 1 11 82
6 4 2 9 18
6 4 3 7 18
6 4 4 26 18
6 4 5 10 18
6 4 6 7 50
6 5 1 16 66
6 5 2 18 2
6 5 3 22 2
6 5 4 7 2
6 5 5 9 2
6 5 6 13 34
6 6 1 7 74
6 6 2 8 10
6 6 3 9 10
6 6 4 11 10
6 6 5 7 10
6 6 6 14 42
