Qubicle Exchange Format
Version 0.2
www.minddesk.com
8 8 8
7
0.000000 0.000000 0.000000
0.000000 0.000000 0.658824
0.000000 0.658824 0.000000
0.933333 0.933333 0.933333
0.988235 1.000000 0.003922
1.000000 0.000000 0.000000
1.000000 0.270588 0.000000
0 0 1 5 84
0 0 2 5 52
0 1 1 5 68
0 1 2 5 36
0 2 1 6 68
0 2 2 6 36
0 3 1 6 68
0 3 2 6 36
0 4 1 2 68
0 4 2 2 36
0 5 1 2 76
0 5 2 2 44
1 0 1 5 80
1 0 2 5 16
1 0 3 1 20
1 0 4 1 20
1 0 5 2 20
1 0 6 2 52
1 1 1 5 64
1 1 2 5 0
1 1 3 1 4
1 1 4 1 4
1 1 5 2 4
1 1 6 2 36
1 2 1 6 64
1 2 2 6 0
1 2 3 2 4
1 2 4 2 4
1 2 5 4 4
1 2 6 4 36
1 3 1 6 64
1 3 2 6 0
1 3 3 2 4
1 3 4 2 4
1 3 5 4 4
1 3 6 4 36
1 4 1 2 64
1 4 2 2 0
1 4 3 3 4
1 4 4 3 4
1 4 5 6 4
1 4 6 6 36
1 5 1 2 72
1 5 2 2 8
1 5 3 3 12
1 5 4 3 12
1 5 5 6 12
1 5 6 6 44
2 0 1 4 80
2 0 2 4 16
2 0 3 1 16
2 0 4 1 16
2 0 5 2 16
2 0 6 2 48
2 1 1 4 64
2 1 2 4 0
2 1 3 1 0
2 1 4 1 0
2 1 5 2 0
2 1 6 2 32
2 2 1 5 64
2 2 2 5 0
2 2 3 2 0
2 2 4 2 0
2 2 5 4 0
2 2 6 4 32
2 3 1 5 64
2 3 2 5 0
2 3 3 2 0
2 3 4 2 0
2 3 5 4 0
2 3 6 4 32
2 4 1 1 64
2 4 2 1 0
2 4 3 3 0
2 4 4 3 0
2 4 5 6 0
2 4 6 6 32
2 5 1 1 72
2 5 2 1 8
2 5 3 3 8
2 5 4 3 8
2 5 5 6 8
2 5 6 6 40
3 0 1 4 80
3 0 2 4 16
3 0 3 3 16
3 0 4 3 16
3 0 5 3 16
3 0 6 3 48
3 1 1 4 64
3 1 2 4 0
3 1 3 3 0
3 1 4 3 0
3 1 5 3 0
3 1 6 3 32
3 2 1 5 64
3 2 2 5 0
3 2 3 0 0
3 2 4 0 0
3 2 5 6 0
3 2 6 6 32
3 3 1 5 64
3 3 2 5 0
3 3 3 0 0
3 3 4 0 0
3 3 5 6 0
3 3 6 6 32
3 4 1 1 64
3 4 2 1 0
3 4 3 4 0
3 4 4 4 0
3 4 5 1 0
3 4 6 1 32
3 5 1 1 72
3 5 2 1 8
3 5 3 4 8
3 5 4 4 8
3 5 5 1 8
3 5 6 1 40
4 0 1 6 80
4 0 2 6 16
4 0 3 3 16
4 0 4 3 16
4 0 5 3 16
4 0 6 3 48
4 1 1 6 64
4 1 2 6 0
4 1 3 3 0
4 1 4 3 0
4 1 5 3 0
4 1 6 3 32
4 2 1 5 64
4 2 2 5 0
4 2 3 0 0
4 2 4 0 0
4 2 5 6 0
4 2 6 6 32
4 3 1 5 64
4 3 2 5 0
4 3 3 0 0
4 3 4 0 0
4 3 5 6 0
4 3 6 6 32
4 4 1 3 64
4 4 2 3 0
4 4 3 4 0
4 4 4 4 0
4 4 5 1 0
4 4 6 1 32
4 5 1 3 72
4 5 2 3 8
4 5 3 4 8
4 5 4 4 8
4 5 5 1 8
4 5 6 1 40
5 0 1 6 82
5 0 2 6 18
5 0 3 1 16
5 0 4 1 16
5 0 5 4 16
5 0 6 4 48
5 1 1 6 66
5 1 2 6 2
5 1 3 1 0
5 1 4 1 0
5 1 5 4 0
5 1 6 4 32
5 2 1 5 66
5 2 2 5 2
5 2 3 1 0
5 2 4 1 0
5 2 5 3 0
5 2 6 3 32
5 3 1 5 66
5 3 2 5 2
5 3 3 1 0
5 3 4 1 0
5 3 5 3 0
5 3 6 3 32
5 4 1 3 66
5 4 2 3 2
5 4 3 5 0
5 4 4 5 0
5 4 5 2 0
5 4 6 2 32
5 5 1 3 74
5 5 2 3 10
5 5 3 5 8
5 5 4 5 8
5 5 5 2 8
5 5 6 2 40
6 0 3 1 82
6 0 4 1 18
6 0 5 4 18
6 0 6 4 50
6 1 3 1 66
6 1 4 1 2
6 1 5 4 2
6 1 6 4 34
6 2 3 1 66
6 2 4 1 2
6 2 5 3 2
6 2 6 3 34
6 3 3 1 66
6 3 4 1 2
6 3 5 3 2
6 3 6 3 34
6 4 3 5 66
6 4 4 5 2
6 4 5 2 2
6 4 6 2 34
6 5 3 5 74
6 5 4 5 10
6 5 5 2 10
6 5 6 2 42
