Qubicle Exchange Format
Version 0.2
www.minddesk.com
8 8 8
7
0.000000 0.000000 0.000000
0.000000 0.000000 0.658824
0.000000 0.658824 0.000000
0.933333 0.933333 0.933333
0.988235 1.000000 0.003922
1.000000 0.000000 0.000000
1.000000 0.270588 0.000000
1 0 1 5 126
1 0 2 5 126
1 0 3 1 126
1 0 4 1 126
1 0 5 2 126
1 0 6 2 126
1 1 1 5 126
1 1 2 5 126
1 1 3 1 126
1 1 4 1 126
1 1 5 2 126
1 1 6 2 126
1 2 1 6 126
1 2 2 6 126
1 2 3 2 126
1 2 4 2 126
1 2 5 4 126
1 2 6 4 126
1 3 1 6 126
1 3 2 6 126
1 3 3 2 126
1 3 4 2 126
1 3 5 4 126
1 3 6 4 126
1 4 1 2 126
1 4 2 2 126
1 4 3 3 126
1 4 4 3 126
1 4 5 6 126
1 4 6 6 126
1 5 1 2 126
1 5 2 2 126
1 5 3 3 126
1 5 4 3 126
1 5 5 6 126
1 5 6 6 126
2 0 1 5 126
2 0 2 5 126
2 0 3 1 126
2 0 4 1 126
2 0 5 2 126
2 0 6 2 126
2 1 1 5 126
2 1 2 5 126
2 1 3 1 126
2 1 4 1 126
2 1 5 2 126
2 1 6 2 126
2 2 1 6 126
2 2 2 6 126
2 2 3 2 126
2 2 4 2 126
2 2 5 4 126
2 2 6 4 126
2 3 1 6 126
2 3 2 6 126
2 3 3 2 126
2 3 4 2 126
2 3 5 4 126
2 3 6 4 126
2 4 1 2 126
2 4 2 2 126
2 4 3 3 126
2 4 4 3 126
2 4 5 6 126
2 4 6 6 126
2 5 1 2 126
2 5 2 2 126
2 5 3 3 126
2 5 4 3 126
2 5 5 6 126
2 5 6 6 126
3 0 1 4 126
3 0 2 4 126
3 0 3 3 126
3 0 4 3 126
3 0 5 3 126
3 0 6 3 126
3 1 1 4 126
3 1 2 4 126
3 1 3 3 126
3 1 4 3 126
3 1 5 3 126
3 1 6 3 126
3 2 1 5 126
3 2 2 5 126
3 2 3 0 126
3 2 4 0 126
3 2 5 6 126
3 2 6 6 126
3 3 1 5 126
3 3 2 5 126
3 3 3 0 126
3 3 4 0 126
3 3 5 6 126
3 3 6 6 126
3 4 1 1 126
3 4 2 1 126
3 4 3 4 126
3 4 4 4 126
3 4 5 1 126
3 4 6 1 126
3 5 1 1 126
3 5 2 1 126
3 5 3 4 126
3 5 4 4 126
3 5 5 1 126
3 5 6 1 126
4 0 1 4 126
4 0 2 4 126
4 0 3 3 126
4 0 4 3 126
4 0 5 3 126
4 0 6 3 126
4 1 1 4 126
4 1 2 4 126
4 1 3 3 126
4 1 4 3 126
4 1 5 3 126
4 1 6 3 126
4 2 1 5 126
4 2 2 5 126
4 2 3 0 126
4 2 4 0 126
4 2 5 6 126
4 2 6 6 126
4 3 1 5 126
4 3 2 5 126
4 3 3 0 126
4 3 4 0 126
4 3 5 6 126
4 3 6 6 126
4 4 1 1 126
4 4 2 1 126
4 4 3 4 126
4 4 4 4 126
4 4 5 1 126
4 4 6 1 126
4 5 1 1 126
4 5 2 1 126
4 5 3 4 126
4 5 4 4 126
4 5 5 1 126
4 5 6 1 126
5 0 1 6 126
5 0 2 6 126
5 0 3 1 126
5 0 4 1 126
5 0 5 4 126
5 0 6 4 126
5 1 1 6 126
5 1 2 6 126
5 1 3 1 126
5 1 4 1 126
5 1 5 4 126
5 1 6 4 126
5 2 1 5 126
5 2 2 5 126
5 2 3 1 126
5 2 4 1 126
5 2 5 3 126
5 2 6 3 126
5 3 1 5 126
5 3 2 5 126
5 3 3 1 126
5 3 4 1 126
5 3 5 3 126
5 3 6 3 126
5 4 1 3 126
5 4 2 3 126
5 4 3 5 126
5 4 4 5 126
5 4 5 2 126
5 4 6 2 126
5 5 1 3 126
5 5 2 3 126
5 5 3 5 126
5 5 4 5 126
5 5 5 2 126
5 5 6 2 126
6 0 1 6 126
6 0 2 6 126
6 0 3 1 126
6 0 4 1 126
6 0 5 4 126
6 0 6 4 126
6 1 1 6 126
6 1 2 6 126
6 1 3 1 126
6 1 4 1 126
6 1 5 4 126
6 1 6 4 126
6 2 1 5 126
6 2 2 5 126
6 2 3 1 126
6 2 4 1 126
6 2 5 3 126
6 2 6 3 126
6 3 1 5 126
6 3 2 5 126
6 3 3 1 126
6 3 4 1 126
6 3 5 3 126
6 3 6 3 126
6 4 1 3 126
6 4 2 3 126
6 4 3 5 126
6 4 4 5 126
6 4 5 2 126
6 4 6 2 126
6 5 1 3 126
6 5 2 3 126
6 5 3 5 126
6 5 4 5 126
6 5 5 2 126
6 5 6 2 126
