Qubicle Exchange Format
Version 0.2
www.minddesk.com
8 8 8
33
0.000000 0.211765 0.070588
0.000000 0.215686 0.070588
0.000000 0.219608 0.070588
0.000000 0.223529 0.074510
0.000000 0.227451 0.074510
0.000000 0.231373 0.074510
0.000000 0.235294 0.078431
0.003922 0.239216 0.082353
0.007843 0.243137 0.086275
0.011765 0.243137 0.090196
0.015686 0.247059 0.094118
0.019608 0.250980 0.098039
0.023529 0.254902 0.101961
0.027451 0.254902 0.105882
0.031373 0.258824 0.109804
0.039216 0.266667 0.117647
0.043137 0.266667 0.117647
0.047059 0.270588 0.121569
0.050980 0.274510 0.125490
0.054902 0.278431 0.129412
0.058824 0.278431 0.133333
0.062745 0.282353 0.137255
0.066667 0.286275 0.141176
0.070588 0.290196 0.145098
0.074510 0.294118 0.149020
0.078431 0.294118 0.152941
0.082353 0.298039 0.156863
0.086275 0.301961 0.160784
0.090196 0.305882 0.160784
0.458824 0.027451 0.000000
0.525490 0.113725 0.082353
1.000000 0.003922 0.003922
1.000000 1.000000 1.000000
1 2 1 16 124
1 2 6 4 124
1 4 1 17 84
1 4 2 3 20
1 4 3 0 20
1 4 4 16 20
1 4 5 0 20
1 4 6 1 52
1 5 1 2 68
1 5 2 9 4
1 5 3 0 4
1 5 4 25 4
1 5 5 2 4
1 5 6 2 36
1 6 1 5 68
1 6 2 31 4
1 6 3 4 4
1 6 4 23 4
1 6 5 31 4
1 6 6 4 36
1 7 1 2 76
1 7 2 25 12
1 7 3 1 12
1 7 4 22 12
1 7 5 18 12
1 7 6 3 44
2 2 1 4 88
2 2 2 32 126
2 2 3 32 126
2 2 4 32 126
2 2 5 32 126
2 2 6 6 56
2 3 2 32 126
2 3 3 32 126
2 3 4 32 126
2 3 5 32 126
2 4 1 3 80
2 4 2 3 0
2 4 3 18 0
2 4 4 28 0
2 4 5 19 0
2 4 6 26 48
2 5 1 4 64
2 5 2 5 0
2 5 3 15 0
2 5 4 0 0
2 5 5 1 0
2 5 6 2 32
2 6 1 21 64
2 6 2 17 0
2 6 3 5 0
2 6 4 19 0
2 6 5 3 0
2 6 6 2 32
2 7 1 22 72
2 7 2 0 8
2 7 3 0 8
2 7 4 24 8
2 7 5 5 8
2 7 6 5 40
3 0 2 25 116
3 0 5 5 116
3 1 2 19 100
3 1 5 2 100
3 2 1 32 126
3 2 2 32 126
3 2 3 32 126
3 2 4 32 126
3 2 5 10 0
3 2 6 32 126
3 3 2 32 126
3 3 3 32 126
3 3 4 32 126
3 3 5 32 126
3 4 1 3 80
3 4 2 8 0
3 4 3 5 0
3 4 4 15 0
3 4 5 22 0
3 4 6 0 48
3 5 1 9 64
3 5 2 16 0
3 5 3 26 0
3 5 4 1 0
3 5 5 11 0
3 5 6 19 32
3 6 1 5 64
3 6 2 1 0
3 6 3 24 0
3 6 4 16 0
3 6 5 2 0
3 6 6 12 32
3 7 1 1 72
3 7 2 14 8
3 7 3 5 8
3 7 4 17 8
3 7 5 5 8
3 7 6 0 40
4 0 2 20 114
4 0 5 20 114
4 1 2 2 98
4 1 5 6 98
4 2 1 32 126
4 2 2 32 126
4 2 3 32 126
4 2 4 32 126
4 2 5 21 0
4 2 6 32 126
4 3 2 32 126
4 3 3 32 126
4 3 4 32 126
4 3 5 32 126
4 4 1 3 80
4 4 2 2 0
4 4 3 22 0
4 4 4 3 0
4 4 5 19 0
4 4 6 0 48
4 5 1 0 64
4 5 2 4 0
4 5 3 2 0
4 5 4 0 0
4 5 5 13 0
4 5 6 2 32
4 6 1 22 64
4 6 2 17 0
4 6 3 11 0
4 6 4 5 0
4 6 5 20 0
4 6 6 4 32
4 7 1 28 72
4 7 2 29 8
4 7 3 2 8
4 7 4 4 8
4 7 5 0 8
4 7 6 12 40
5 2 2 32 126
5 2 3 32 126
5 2 4 32 126
5 2 5 32 126
5 3 2 32 126
5 3 3 32 126
5 3 4 32 126
5 3 5 32 126
5 4 1 23 80
5 4 2 4 0
5 4 3 8 0
5 4 4 25 0
5 4 5 6 0
5 4 6 23 48
5 5 1 29 64
5 5 2 0 0
5 5 3 2 0
5 5 4 4 0
5 5 5 3 0
5 5 6 6 32
5 6 1 15 64
5 6 2 10 0
5 6 3 23 0
5 6 4 5 0
5 6 5 0 0
5 6 6 1 32
5 7 1 1 72
5 7 2 5 8
5 7 3 22 8
5 7 4 2 8
5 7 5 0 8
5 7 6 30 40
6 4 1 7 82
6 4 2 7 18
6 4 3 21 18
6 4 4 2 18
6 4 5 15 18
6 4 6 14 50
6 5 1 3 66
6 5 2 28 2
6 5 3 22 2
6 5 4 9 2
6 5 5 20 2
6 5 6 17 34
6 6 1 3 66
6 6 2 5 2
6 6 3 27 2
6 6 4 4 2
6 6 5 5 2
6 6 6 4 34
6 7 1 3 74
6 7 2 12 10
6 7 3 12 10
6 7 4 7 10
6 7 5 9 10
6 7 6 5 42
