Qubicle Exchange Format
Version 0.2
www.minddesk.com
8 8 8
3
0.600000 0.600000 0.600000
0.658824 0.000000 0.062745
0.933333 0.933333 0.933333
1 1 1 1 86
1 1 2 1 22
1 1 3 1 22
1 1 4 1 22
1 1 5 1 22
1 1 6 1 54
1 2 1 1 70
1 2 2 1 6
1 2 3 1 6
1 2 4 1 6
1 2 5 1 6
1 2 6 1 38
1 3 1 1 70
1 3 2 1 6
1 3 3 1 6
1 3 4 1 6
1 3 5 1 6
1 3 6 1 38
1 4 1 1 78
1 4 2 1 14
1 4 3 1 14
1 4 4 1 14
1 4 5 1 14
1 4 6 1 46
2 0 1 1 92
2 0 2 1 28
2 0 3 1 28
2 0 4 1 28
2 0 5 1 28
2 0 6 1 60
2 1 0 0 116
2 1 7 0 116
2 2 0 0 100
2 2 7 0 100
2 3 0 0 100
2 3 7 0 100
2 4 0 0 108
2 4 7 0 108
2 5 1 1 92
2 5 2 2 28
2 5 3 2 28
2 5 4 2 28
2 5 5 1 28
2 5 6 1 60
3 0 1 1 88
3 0 2 1 24
3 0 3 1 24
3 0 4 1 24
3 0 5 2 24
3 0 6 2 56
3 1 0 0 112
3 1 7 0 112
3 2 0 0 96
3 2 7 0 96
3 3 0 0 96
3 3 7 0 96
3 4 0 0 104
3 4 7 0 104
3 5 1 2 88
3 5 2 1 24
3 5 3 1 24
3 5 4 2 24
3 5 5 2 24
3 5 6 1 56
4 0 1 2 88
4 0 2 1 24
4 0 3 1 24
4 0 4 2 24
4 0 5 2 24
4 0 6 1 56
4 1 0 0 112
4 1 7 0 112
4 2 0 0 96
4 2 7 0 96
4 3 0 0 96
4 3 7 0 96
4 4 0 0 104
4 4 7 0 104
4 5 1 1 88
4 5 2 1 24
4 5 3 1 24
4 5 4 1 24
4 5 5 2 24
4 5 6 2 56
5 0 1 1 90
5 0 2 2 26
5 0 3 2 26
5 0 4 2 26
5 0 5 1 26
5 0 6 1 58
5 1 0 0 114
5 1 7 0 114
5 2 0 0 98
5 2 7 0 98
5 3 0 0 98
5 3 7 0 98
5 4 0 0 106
5 4 7 0 106
5 5 1 1 90
5 5 2 1 26
5 5 3 1 26
5 5 4 1 26
5 5 5 1 26
5 5 6 1 58
6 1 1 1 86
6 1 2 1 22
6 1 3 1 22
6 1 4 1 22
6 1 5 1 22
6 1 6 1 54
6 2 1 1 70
6 2 2 1 6
6 2 3 1 6
6 2 4 1 6
6 2 5 1 6
6 2 6 1 38
6 3 1 1 70
6 3 2 1 6
6 3 3 1 6
6 3 4 1 6
6 3 5 1 6
6 3 6 1 38
6 4 1 1 78
6 4 2 1 14
6 4 3 1 14
6 4 4 1 14
6 4 5 1 14
6 4 6 1 46
