Qubicle Exchange Format
Version 0.2
www.minddesk.com
16 16 16
698
0.000000 0.000000 0.000000
0.000000 0.168627 0.054902
0.000000 0.172549 0.054902
0.000000 0.176471 0.054902
0.000000 0.176471 0.058824
0.000000 0.180392 0.054902
0.000000 0.180392 0.058824
0.000000 0.184314 0.054902
0.000000 0.184314 0.058824
0.000000 0.188235 0.058824
0.000000 0.188235 0.062745
0.000000 0.192157 0.058824
0.000000 0.192157 0.062745
0.000000 0.196078 0.058824
0.000000 0.196078 0.062745
0.000000 0.200000 0.058824
0.000000 0.200000 0.062745
0.000000 0.200000 0.066667
0.000000 0.203922 0.062745
0.000000 0.203922 0.066667
0.000000 0.203922 0.070588
0.000000 0.207843 0.062745
0.000000 0.207843 0.066667
0.000000 0.207843 0.070588
0.000000 0.211765 0.062745
0.000000 0.211765 0.066667
0.000000 0.211765 0.070588
0.000000 0.215686 0.066667
0.000000 0.215686 0.070588
0.000000 0.219608 0.066667
0.000000 0.219608 0.070588
0.000000 0.219608 0.074510
0.000000 0.223529 0.066667
0.000000 0.223529 0.070588
0.000000 0.223529 0.074510
0.000000 0.227451 0.070588
0.000000 0.227451 0.078431
0.000000 0.231373 0.074510
0.003922 0.200000 0.070588
0.003922 0.203922 0.070588
0.003922 0.207843 0.066667
0.003922 0.207843 0.070588
0.003922 0.211765 0.070588
0.003922 0.211765 0.074510
0.003922 0.215686 0.078431
0.003922 0.219608 0.074510
0.003922 0.219608 0.078431
0.003922 0.223529 0.074510
0.003922 0.223529 0.078431
0.003922 0.223529 0.082353
0.003922 0.227451 0.074510
0.003922 0.227451 0.078431
0.003922 0.231373 0.082353
0.003922 0.235294 0.078431
0.003922 0.235294 0.082353
0.007843 0.196078 0.070588
0.007843 0.207843 0.070588
0.007843 0.211765 0.070588
0.007843 0.211765 0.078431
0.007843 0.215686 0.074510
0.007843 0.215686 0.078431
0.007843 0.219608 0.074510
0.007843 0.219608 0.078431
0.007843 0.219608 0.082353
0.007843 0.223529 0.086275
0.007843 0.227451 0.078431
0.007843 0.227451 0.082353
0.007843 0.227451 0.086275
0.007843 0.231373 0.078431
0.011765 0.200000 0.078431
0.011765 0.203922 0.078431
0.011765 0.207843 0.074510
0.011765 0.207843 0.078431
0.011765 0.211765 0.078431
0.011765 0.219608 0.078431
0.011765 0.219608 0.082353
0.011765 0.223529 0.082353
0.011765 0.227451 0.082353
0.011765 0.231373 0.082353
0.011765 0.231373 0.086275
0.011765 0.235294 0.086275
0.011765 0.243137 0.090196
0.015686 0.207843 0.078431
0.015686 0.215686 0.082353
0.015686 0.215686 0.086275
0.015686 0.219608 0.082353
0.015686 0.219608 0.086275
0.015686 0.223529 0.086275
0.015686 0.223529 0.090196
0.015686 0.227451 0.082353
0.015686 0.227451 0.086275
0.015686 0.227451 0.090196
0.015686 0.231373 0.086275
0.015686 0.231373 0.090196
0.015686 0.239216 0.090196
0.015686 0.239216 0.094118
0.015686 0.243137 0.094118
0.015686 0.247059 0.094118
0.019608 0.215686 0.082353
0.019608 0.215686 0.086275
0.019608 0.223529 0.090196
0.019608 0.227451 0.090196
0.019608 0.231373 0.090196
0.019608 0.235294 0.090196
0.019608 0.235294 0.094118
0.019608 0.243137 0.090196
0.019608 0.243137 0.094118
0.019608 0.247059 0.094118
0.019608 0.247059 0.098039
0.019608 0.250980 0.098039
0.023529 0.211765 0.086275
0.023529 0.215686 0.090196
0.023529 0.219608 0.086275
0.023529 0.219608 0.090196
0.023529 0.219608 0.094118
0.023529 0.227451 0.090196
0.023529 0.231373 0.094118
0.023529 0.235294 0.090196
0.023529 0.235294 0.098039
0.023529 0.239216 0.098039
0.023529 0.243137 0.098039
0.023529 0.247059 0.098039
0.023529 0.250980 0.098039
0.023529 0.250980 0.101961
0.027451 0.215686 0.090196
0.027451 0.219608 0.090196
0.027451 0.223529 0.090196
0.027451 0.227451 0.094118
0.027451 0.231373 0.094118
0.027451 0.231373 0.098039
0.027451 0.235294 0.094118
0.027451 0.235294 0.098039
0.027451 0.243137 0.101961
0.027451 0.258824 0.105882
0.031373 0.215686 0.094118
0.031373 0.223529 0.094118
0.031373 0.223529 0.098039
0.031373 0.227451 0.094118
0.031373 0.227451 0.098039
0.031373 0.227451 0.101961
0.031373 0.231373 0.098039
0.031373 0.235294 0.098039
0.031373 0.235294 0.101961
0.031373 0.239216 0.101961
0.031373 0.243137 0.101961
0.031373 0.243137 0.105882
0.031373 0.247059 0.101961
0.031373 0.247059 0.105882
0.031373 0.250980 0.101961
0.031373 0.250980 0.105882
0.031373 0.254902 0.105882
0.031373 0.254902 0.109804
0.035294 0.219608 0.098039
0.035294 0.223529 0.098039
0.035294 0.227451 0.098039
0.035294 0.227451 0.101961
0.035294 0.231373 0.098039
0.035294 0.231373 0.101961
0.035294 0.235294 0.101961
0.035294 0.239216 0.101961
0.035294 0.243137 0.105882
0.035294 0.247059 0.105882
0.035294 0.247059 0.109804
0.035294 0.250980 0.109804
0.035294 0.254902 0.105882
0.035294 0.254902 0.109804
0.035294 0.262745 0.113725
0.039216 0.223529 0.098039
0.039216 0.231373 0.105882
0.039216 0.235294 0.101961
0.039216 0.235294 0.105882
0.039216 0.239216 0.105882
0.039216 0.243137 0.105882
0.039216 0.243137 0.109804
0.039216 0.247059 0.105882
0.039216 0.247059 0.109804
0.039216 0.250980 0.109804
0.039216 0.254902 0.109804
0.039216 0.254902 0.113725
0.039216 0.258824 0.109804
0.039216 0.258824 0.113725
0.039216 0.258824 0.117647
0.039216 0.262745 0.113725
0.039216 0.262745 0.117647
0.043137 0.223529 0.105882
0.043137 0.227451 0.105882
0.043137 0.227451 0.109804
0.043137 0.231373 0.105882
0.043137 0.231373 0.109804
0.043137 0.235294 0.105882
0.043137 0.235294 0.109804
0.043137 0.239216 0.105882
0.043137 0.239216 0.109804
0.043137 0.243137 0.109804
0.043137 0.247059 0.109804
0.043137 0.247059 0.113725
0.043137 0.250980 0.109804
0.043137 0.250980 0.113725
0.043137 0.254902 0.113725
0.043137 0.254902 0.117647
0.043137 0.258824 0.113725
0.043137 0.262745 0.117647
0.043137 0.262745 0.121569
0.043137 0.266667 0.121569
0.047059 0.231373 0.109804
0.047059 0.239216 0.109804
0.047059 0.243137 0.109804
0.047059 0.243137 0.113725
0.047059 0.247059 0.109804
0.047059 0.247059 0.113725
0.047059 0.247059 0.117647
0.047059 0.250980 0.113725
0.047059 0.250980 0.117647
0.047059 0.254902 0.113725
0.047059 0.254902 0.117647
0.047059 0.254902 0.121569
0.047059 0.258824 0.117647
0.047059 0.262745 0.121569
0.047059 0.266667 0.121569
0.047059 0.270588 0.125490
0.050980 0.239216 0.113725
0.050980 0.243137 0.113725
0.050980 0.247059 0.113725
0.050980 0.247059 0.117647
0.050980 0.250980 0.121569
0.050980 0.254902 0.113725
0.050980 0.254902 0.117647
0.050980 0.254902 0.121569
0.050980 0.258824 0.117647
0.050980 0.258824 0.121569
0.050980 0.266667 0.121569
0.050980 0.266667 0.125490
0.050980 0.270588 0.121569
0.050980 0.270588 0.125490
0.050980 0.274510 0.125490
0.054902 0.239216 0.113725
0.054902 0.239216 0.117647
0.054902 0.243137 0.113725
0.054902 0.243137 0.117647
0.054902 0.247059 0.113725
0.054902 0.247059 0.117647
0.054902 0.247059 0.121569
0.054902 0.250980 0.117647
0.054902 0.250980 0.121569
0.054902 0.254902 0.121569
0.054902 0.254902 0.125490
0.054902 0.262745 0.125490
0.054902 0.266667 0.121569
0.054902 0.266667 0.129412
0.054902 0.270588 0.125490
0.054902 0.270588 0.129412
0.054902 0.274510 0.129412
0.054902 0.274510 0.133333
0.058824 0.243137 0.121569
0.058824 0.247059 0.117647
0.058824 0.247059 0.121569
0.058824 0.250980 0.121569
0.058824 0.258824 0.125490
0.058824 0.258824 0.129412
0.058824 0.262745 0.125490
0.058824 0.262745 0.129412
0.058824 0.266667 0.125490
0.058824 0.266667 0.129412
0.058824 0.270588 0.129412
0.058824 0.274510 0.133333
0.058824 0.278431 0.129412
0.058824 0.278431 0.133333
0.058824 0.278431 0.137255
0.062745 0.243137 0.121569
0.062745 0.243137 0.125490
0.062745 0.247059 0.121569
0.062745 0.247059 0.125490
0.062745 0.247059 0.129412
0.062745 0.250980 0.121569
0.062745 0.250980 0.125490
0.062745 0.254902 0.125490
0.062745 0.258824 0.125490
0.062745 0.258824 0.129412
0.062745 0.262745 0.125490
0.062745 0.262745 0.129412
0.062745 0.262745 0.133333
0.062745 0.266667 0.125490
0.062745 0.266667 0.129412
0.062745 0.266667 0.133333
0.062745 0.270588 0.133333
0.062745 0.274510 0.133333
0.062745 0.274510 0.137255
0.062745 0.278431 0.133333
0.062745 0.278431 0.137255
0.062745 0.282353 0.137255
0.062745 0.286275 0.137255
0.066667 0.247059 0.125490
0.066667 0.254902 0.129412
0.066667 0.258824 0.129412
0.066667 0.258824 0.133333
0.066667 0.262745 0.129412
0.066667 0.262745 0.133333
0.066667 0.262745 0.137255
0.066667 0.266667 0.133333
0.066667 0.266667 0.137255
0.066667 0.270588 0.133333
0.066667 0.270588 0.137255
0.066667 0.278431 0.137255
0.066667 0.282353 0.137255
0.066667 0.282353 0.141176
0.066667 0.286275 0.141176
0.070588 0.247059 0.129412
0.070588 0.250980 0.133333
0.070588 0.254902 0.133333
0.070588 0.258824 0.129412
0.070588 0.262745 0.133333
0.070588 0.262745 0.137255
0.070588 0.266667 0.133333
0.070588 0.266667 0.137255
0.070588 0.270588 0.133333
0.070588 0.270588 0.137255
0.070588 0.270588 0.141176
0.070588 0.274510 0.137255
0.070588 0.274510 0.141176
0.070588 0.278431 0.137255
0.070588 0.278431 0.141176
0.070588 0.282353 0.141176
0.070588 0.286275 0.141176
0.070588 0.286275 0.145098
0.070588 0.290196 0.145098
0.074510 0.250980 0.129412
0.074510 0.254902 0.129412
0.074510 0.258824 0.137255
0.074510 0.262745 0.137255
0.074510 0.266667 0.137255
0.074510 0.266667 0.141176
0.074510 0.270588 0.137255
0.074510 0.270588 0.141176
0.074510 0.270588 0.145098
0.074510 0.274510 0.141176
0.074510 0.278431 0.141176
0.074510 0.278431 0.145098
0.074510 0.282353 0.145098
0.074510 0.282353 0.149020
0.074510 0.290196 0.145098
0.074510 0.290196 0.149020
0.078431 0.254902 0.141176
0.078431 0.258824 0.137255
0.078431 0.266667 0.141176
0.078431 0.270588 0.137255
0.078431 0.270588 0.141176
0.078431 0.270588 0.145098
0.078431 0.274510 0.141176
0.078431 0.274510 0.145098
0.078431 0.278431 0.141176
0.078431 0.278431 0.145098
0.078431 0.278431 0.149020
0.078431 0.282353 0.145098
0.078431 0.286275 0.145098
0.078431 0.286275 0.149020
0.078431 0.290196 0.149020
0.078431 0.290196 0.152941
0.078431 0.294118 0.152941
0.082353 0.258824 0.141176
0.082353 0.258824 0.145098
0.082353 0.262745 0.141176
0.082353 0.266667 0.141176
0.082353 0.266667 0.145098
0.082353 0.270588 0.145098
0.082353 0.270588 0.149020
0.082353 0.274510 0.145098
0.082353 0.274510 0.149020
0.082353 0.278431 0.145098
0.082353 0.278431 0.149020
0.082353 0.282353 0.149020
0.082353 0.286275 0.149020
0.082353 0.286275 0.152941
0.082353 0.290196 0.152941
0.082353 0.294118 0.156863
0.082353 0.298039 0.156863
0.086275 0.266667 0.145098
0.086275 0.270588 0.149020
0.086275 0.274510 0.149020
0.086275 0.278431 0.149020
0.086275 0.278431 0.152941
0.086275 0.282353 0.149020
0.086275 0.282353 0.152941
0.086275 0.282353 0.156863
0.086275 0.286275 0.152941
0.086275 0.286275 0.156863
0.086275 0.290196 0.152941
0.086275 0.290196 0.156863
0.086275 0.294118 0.152941
0.086275 0.294118 0.156863
0.086275 0.298039 0.156863
0.086275 0.301961 0.156863
0.086275 0.301961 0.160784
0.090196 0.270588 0.149020
0.090196 0.274510 0.152941
0.090196 0.282353 0.152941
0.090196 0.282353 0.156863
0.090196 0.286275 0.152941
0.090196 0.286275 0.156863
0.090196 0.290196 0.156863
0.090196 0.290196 0.160784
0.090196 0.294118 0.156863
0.090196 0.294118 0.160784
0.090196 0.298039 0.160784
0.090196 0.298039 0.164706
0.090196 0.301961 0.164706
0.094118 0.286275 0.156863
0.094118 0.286275 0.160784
0.094118 0.290196 0.156863
0.094118 0.290196 0.160784
0.094118 0.294118 0.160784
0.094118 0.298039 0.160784
0.094118 0.301961 0.160784
0.094118 0.301961 0.164706
0.094118 0.305882 0.164706
0.098039 0.286275 0.160784
0.098039 0.286275 0.164706
0.098039 0.294118 0.160784
0.098039 0.294118 0.164706
0.098039 0.298039 0.164706
0.098039 0.301961 0.164706
0.098039 0.305882 0.168627
0.098039 0.305882 0.172549
0.098039 0.309804 0.168627
0.101961 0.290196 0.164706
0.101961 0.294118 0.164706
0.101961 0.298039 0.164706
0.101961 0.298039 0.168627
0.101961 0.301961 0.168627
0.101961 0.301961 0.172549
0.101961 0.305882 0.168627
0.101961 0.305882 0.172549
0.101961 0.309804 0.172549
0.101961 0.313726 0.172549
0.101961 0.313726 0.176471
0.105882 0.294118 0.168627
0.105882 0.298039 0.168627
0.105882 0.298039 0.172549
0.105882 0.301961 0.168627
0.105882 0.301961 0.172549
0.105882 0.305882 0.172549
0.105882 0.305882 0.176471
0.105882 0.309804 0.172549
0.105882 0.309804 0.176471
0.105882 0.313726 0.172549
0.105882 0.313726 0.176471
0.109804 0.294118 0.172549
0.109804 0.294118 0.176471
0.109804 0.298039 0.172549
0.109804 0.301961 0.172549
0.109804 0.301961 0.176471
0.109804 0.305882 0.176471
0.109804 0.309804 0.180392
0.109804 0.313726 0.176471
0.109804 0.313726 0.180392
0.109804 0.317647 0.176471
0.109804 0.317647 0.180392
0.113725 0.298039 0.176471
0.113725 0.298039 0.180392
0.113725 0.301961 0.172549
0.113725 0.301961 0.176471
0.113725 0.305882 0.176471
0.113725 0.305882 0.180392
0.113725 0.309804 0.176471
0.113725 0.309804 0.180392
0.113725 0.313726 0.180392
0.113725 0.313726 0.184314
0.113725 0.317647 0.180392
0.113725 0.317647 0.184314
0.113725 0.321569 0.180392
0.113725 0.321569 0.184314
0.117647 0.298039 0.180392
0.117647 0.301961 0.180392
0.117647 0.305882 0.184314
0.117647 0.309804 0.180392
0.117647 0.309804 0.184314
0.117647 0.313726 0.184314
0.117647 0.317647 0.184314
0.117647 0.321569 0.184314
0.117647 0.321569 0.188235
0.117647 0.325490 0.188235
0.121569 0.305882 0.184314
0.121569 0.309804 0.184314
0.121569 0.313726 0.184314
0.121569 0.313726 0.188235
0.121569 0.317647 0.188235
0.121569 0.321569 0.188235
0.121569 0.321569 0.192157
0.121569 0.325490 0.188235
0.121569 0.325490 0.192157
0.121569 0.329412 0.192157
0.125490 0.305882 0.188235
0.125490 0.309804 0.188235
0.125490 0.313726 0.188235
0.125490 0.317647 0.188235
0.125490 0.317647 0.192157
0.125490 0.321569 0.188235
0.125490 0.321569 0.192157
0.125490 0.325490 0.192157
0.125490 0.325490 0.196078
0.125490 0.329412 0.192157
0.125490 0.329412 0.196078
0.125490 0.333333 0.200000
0.129412 0.309804 0.192157
0.129412 0.317647 0.192157
0.129412 0.317647 0.196078
0.129412 0.321569 0.196078
0.129412 0.325490 0.196078
0.129412 0.325490 0.200000
0.129412 0.329412 0.192157
0.129412 0.329412 0.196078
0.129412 0.329412 0.200000
0.129412 0.333333 0.196078
0.129412 0.333333 0.200000
0.133333 0.313726 0.196078
0.133333 0.317647 0.196078
0.133333 0.321569 0.196078
0.133333 0.321569 0.200000
0.133333 0.325490 0.203922
0.133333 0.329412 0.200000
0.133333 0.333333 0.200000
0.133333 0.333333 0.203922
0.133333 0.337255 0.200000
0.133333 0.337255 0.203922
0.137255 0.325490 0.200000
0.137255 0.325490 0.203922
0.137255 0.337255 0.203922
0.137255 0.337255 0.207843
0.137255 0.341176 0.203922
0.141176 0.321569 0.200000
0.141176 0.325490 0.203922
0.141176 0.329412 0.203922
0.141176 0.333333 0.203922
0.141176 0.333333 0.207843
0.141176 0.341176 0.207843
0.141176 0.345098 0.207843
0.145098 0.325490 0.203922
0.145098 0.329412 0.203922
0.145098 0.329412 0.207843
0.145098 0.333333 0.207843
0.145098 0.341176 0.211765
0.145098 0.345098 0.211765
0.145098 0.345098 0.215686
0.149020 0.329412 0.203922
0.149020 0.329412 0.211765
0.149020 0.333333 0.211765
0.149020 0.337255 0.207843
0.149020 0.345098 0.211765
0.149020 0.345098 0.215686
0.149020 0.345098 0.219608
0.149020 0.349020 0.215686
0.152941 0.333333 0.211765
0.152941 0.349020 0.215686
0.152941 0.349020 0.219608
0.152941 0.349020 0.223529
0.152941 0.352941 0.215686
0.152941 0.352941 0.219608
0.156863 0.345098 0.219608
0.156863 0.349020 0.219608
0.156863 0.349020 0.223529
0.156863 0.352941 0.219608
0.156863 0.352941 0.223529
0.160784 0.337255 0.219608
0.160784 0.337255 0.223529
0.160784 0.341176 0.223529
0.160784 0.345098 0.223529
0.160784 0.352941 0.227451
0.160784 0.356863 0.223529
0.160784 0.356863 0.227451
0.160784 0.356863 0.231373
0.164706 0.356863 0.227451
0.164706 0.356863 0.231373
0.164706 0.360784 0.231373
0.164706 0.360784 0.235294
0.168627 0.356863 0.231373
0.168627 0.360784 0.235294
0.168627 0.364706 0.235294
0.168627 0.364706 0.239216
0.172549 0.364706 0.235294
0.172549 0.364706 0.239216
0.172549 0.368627 0.239216
0.176471 0.368627 0.239216
0.176471 0.368627 0.243137
0.184314 0.372549 0.247059
0.184314 0.372549 0.250980
0.184314 0.376471 0.247059
0.184314 0.376471 0.250980
0.188235 0.376471 0.250980
0.188235 0.376471 0.254902
0.192157 0.380392 0.254902
0.192157 0.384314 0.254902
0.196078 0.380392 0.258824
0.196078 0.384314 0.258824
0.203922 0.388235 0.262745
0.203922 0.388235 0.266667
0.207843 0.392157 0.266667
0.207843 0.392157 0.270588
0.211765 0.392157 0.274510
0.211765 0.396078 0.274510
0.215686 0.396078 0.274510
0.215686 0.396078 0.278431
0.305882 0.215686 0.015686
0.309804 0.215686 0.015686
0.313726 0.219608 0.015686
0.317647 0.219608 0.015686
0.317647 0.223529 0.015686
0.321569 0.223529 0.015686
0.321569 0.227451 0.015686
0.325490 0.227451 0.015686
0.329412 0.231373 0.015686
0.333333 0.231373 0.015686
0.333333 0.235294 0.015686
0.337255 0.235294 0.015686
0.341176 0.239216 0.019608
0.341176 0.243137 0.023529
0.345098 0.247059 0.027451
0.349020 0.247059 0.031373
0.349020 0.250980 0.035294
0.352941 0.254902 0.039216
0.356863 0.258824 0.043137
0.356863 0.258824 0.047059
0.360784 0.262745 0.050980
0.364706 0.266667 0.054902
0.368627 0.270588 0.062745
0.372549 0.274510 0.066667
0.372549 0.278431 0.070588
0.376471 0.282353 0.074510
0.380392 0.019608 0.000000
0.380392 0.282353 0.078431
0.380392 0.286275 0.082353
0.384314 0.290196 0.086275
0.388235 0.294118 0.090196
0.388235 0.294118 0.094118
0.392157 0.298039 0.098039
0.396078 0.301961 0.101961
0.396078 0.305882 0.105882
0.400000 0.305882 0.109804
0.407843 0.023529 0.000000
0.411765 0.019608 0.000000
0.415686 0.027451 0.000000
0.423529 0.019608 0.000000
0.427451 0.019608 0.000000
0.427451 0.023529 0.000000
0.431373 0.023529 0.000000
0.435294 0.031373 0.000000
0.439216 0.023529 0.000000
0.439216 0.078431 0.054902
0.443137 0.023529 0.000000
0.443137 0.058824 0.035294
0.447059 0.019608 0.000000
0.447059 0.023529 0.000000
0.450980 0.023529 0.000000
0.450980 0.043137 0.015686
0.454902 0.023529 0.000000
0.454902 0.058824 0.031373
0.458824 0.023529 0.000000
0.458824 0.035294 0.003922
0.458824 0.070588 0.043137
0.462745 0.043137 0.015686
0.466667 0.023529 0.000000
0.466667 0.082353 0.054902
0.474510 0.082353 0.050980
0.482353 0.043137 0.015686
0.482353 0.058824 0.031373
0.482353 0.098039 0.066667
0.482353 0.109804 0.082353
0.486275 0.066667 0.039216
0.486275 0.094118 0.062745
0.490196 0.043137 0.011765
0.490196 0.047059 0.015686
0.494118 0.070588 0.039216
0.498039 0.058824 0.027451
0.498039 0.109804 0.082353
0.501961 0.062745 0.031373
0.501961 0.078431 0.047059
0.501961 0.113725 0.086275
0.505882 0.074510 0.043137
0.509804 0.082353 0.050980
0.509804 0.101961 0.074510
0.513726 0.090196 0.058824
0.513726 0.094118 0.062745
0.525490 0.117647 0.086275
0.525490 0.133333 0.101961
0.529412 0.125490 0.094118
0.529412 0.145098 0.113725
0.533333 0.121569 0.094118
0.537255 0.133333 0.105882
0.537255 0.137255 0.109804
0.549020 0.160784 0.137255
0.576471 0.211765 0.188235
0.611765 0.050980 0.105882
0.623529 0.050980 0.105882
0.643137 0.050980 0.105882
0.654902 0.011765 0.074510
0.658824 0.105882 0.156863
0.674510 0.090196 0.149020
0.674510 0.094118 0.149020
0.678431 0.082353 0.141176
1.000000 0.000000 0.000000
0 4 12 25 84
0 4 13 506 52
0 5 12 14 76
0 5 13 18 44
1 4 12 106 80
1 4 13 211 48
1 5 12 29 72
1 5 13 25 40
2 4 3 441 124
2 4 12 35 80
2 4 13 109 48
2 5 12 22 72
2 5 13 522 42
2 8 2 182 84
2 8 3 334 20
2 8 4 293 20
2 8 5 157 20
2 8 6 8 20
2 8 7 224 20
2 8 8 412 20
2 8 9 445 20
2 8 10 111 20
2 8 11 445 20
2 8 12 492 20
2 8 13 6 52
2 9 2 357 68
2 9 3 317 4
2 9 4 14 4
2 9 5 195 4
2 9 6 456 4
2 9 7 528 4
2 9 8 553 4
2 9 9 442 4
2 9 10 236 4
2 9 11 113 4
2 9 12 115 4
2 9 13 543 36
2 10 2 14 68
2 10 3 85 4
2 10 4 396 4
2 10 5 351 4
2 10 6 8 4
2 10 7 55 4
2 10 8 558 4
2 10 9 451 4
2 10 10 11 4
2 10 11 352 4
2 10 12 176 4
2 10 13 24 36
2 11 2 161 68
2 11 3 346 4
2 11 4 304 4
2 11 5 43 4
2 11 6 224 4
2 11 7 83 4
2 11 8 565 4
2 11 9 351 4
2 11 10 83 4
2 11 11 435 4
2 11 12 11 4
2 11 13 529 36
2 12 2 11 68
2 12 3 18 4
2 12 4 697 4
2 12 5 697 4
2 12 6 317 4
2 12 7 83 4
2 12 8 496 4
2 12 9 574 4
2 12 10 697 4
2 12 11 697 4
2 12 12 158 4
2 12 13 25 36
2 13 2 27 76
2 13 3 265 4
2 13 4 697 4
2 13 5 697 4
2 13 6 0 4
2 13 7 25 4
2 13 8 318 4
2 13 9 0 4
2 13 10 697 4
2 13 11 697 4
2 13 12 388 4
2 13 13 150 36
2 14 3 0 76
2 14 4 0 4
2 14 5 0 4
2 14 6 56 4
2 14 7 514 4
2 14 8 436 4
2 14 9 385 4
2 14 10 0 4
2 14 11 0 4
2 14 12 0 4
2 14 13 198 36
2 15 4 568 76
2 15 5 583 12
2 15 6 144 12
2 15 7 313 12
2 15 8 243 12
2 15 9 480 12
2 15 10 560 12
2 15 11 424 12
2 15 12 193 12
2 15 13 14 46
3 4 2 480 92
3 4 3 172 48
3 4 12 81 80
3 4 13 97 56
3 5 3 158 108
3 5 12 51 104
3 8 2 405 80
3 8 3 167 16
3 8 4 284 16
3 8 5 20 16
3 8 6 12 16
3 8 7 193 16
3 8 8 158 16
3 8 9 153 16
3 8 10 190 16
3 8 11 100 16
3 8 12 268 16
3 8 13 394 48
3 9 2 427 64
3 9 3 266 0
3 9 4 327 0
3 9 5 255 0
3 9 6 343 0
3 9 7 296 0
3 9 8 288 0
3 9 9 317 0
3 9 10 125 0
3 9 11 406 0
3 9 12 192 0
3 9 13 73 32
3 10 2 493 64
3 10 3 237 0
3 10 4 49 0
3 10 5 44 0
3 10 6 271 0
3 10 7 41 0
3 10 8 538 0
3 10 9 272 0
3 10 10 18 0
3 10 11 189 0
3 10 12 222 0
3 10 13 159 32
3 11 2 238 64
3 11 3 334 0
3 11 4 44 0
3 11 5 52 0
3 11 6 152 0
3 11 7 9 0
3 11 8 294 0
3 11 9 294 0
3 11 10 407 0
3 11 11 221 0
3 11 12 342 0
3 11 13 171 32
3 12 2 22 64
3 12 3 500 0
3 12 4 689 0
3 12 5 693 0
3 12 6 14 0
3 12 7 350 0
3 12 8 597 0
3 12 9 279 0
3 12 10 694 0
3 12 11 691 0
3 12 12 213 0
3 12 13 25 32
3 13 2 22 72
3 13 3 370 0
3 13 4 695 0
3 13 5 690 0
3 13 6 386 0
3 13 7 355 0
3 13 8 321 0
3 13 9 409 0
3 13 10 692 0
3 13 11 696 0
3 13 12 506 0
3 13 13 9 32
3 14 3 117 72
3 14 4 533 0
3 14 5 472 0
3 14 6 172 0
3 14 7 8 0
3 14 8 374 0
3 14 9 469 0
3 14 10 228 0
3 14 11 567 0
3 14 12 284 0
3 14 13 92 40
3 15 4 555 72
3 15 5 532 8
3 15 6 18 8
3 15 7 59 8
3 15 8 598 8
3 15 9 488 8
3 15 10 378 8
3 15 11 525 8
3 15 12 328 40
4 0 10 77 84
4 0 11 128 52
4 1 10 468 76
4 1 11 16 44
4 4 2 22 80
4 4 3 484 16
4 4 4 629 20
4 4 5 631 20
4 4 6 620 20
4 4 7 610 20
4 4 8 617 20
4 4 9 600 20
4 4 10 601 20
4 4 11 635 20
4 4 12 365 16
4 4 13 590 56
4 5 2 25 76
4 5 3 9 8
4 5 4 611 4
4 5 5 618 4
4 5 6 602 4
4 5 7 600 4
4 5 8 602 4
4 5 9 603 4
4 5 10 602 4
4 5 11 610 4
4 5 12 461 40
4 6 4 617 68
4 6 5 618 4
4 6 6 604 4
4 6 7 601 4
4 6 8 609 4
4 6 9 631 4
4 6 10 634 4
4 6 11 627 36
4 7 4 601 68
4 7 5 615 4
4 7 6 603 4
4 7 7 604 4
4 7 8 629 4
4 7 9 603 4
4 7 10 617 4
4 7 11 604 36
4 8 2 6 80
4 8 3 246 16
4 8 4 192 0
4 8 5 376 0
4 8 6 551 0
4 8 7 465 0
4 8 8 542 0
4 8 9 306 0
4 8 10 339 0
4 8 11 218 0
4 8 12 497 16
4 8 13 421 48
4 9 2 209 64
4 9 3 564 0
4 9 4 31 0
4 9 5 352 0
4 9 6 424 0
4 9 7 477 0
4 9 8 350 0
4 9 9 369 0
4 9 10 374 0
4 9 11 591 0
4 9 12 474 0
4 9 13 517 32
4 10 2 145 64
4 10 3 61 0
4 10 4 25 0
4 10 5 396 0
4 10 6 147 0
4 10 7 248 0
4 10 8 11 0
4 10 9 313 0
4 10 10 254 0
4 10 11 14 0
4 10 12 22 0
4 10 13 112 32
4 11 2 50 64
4 11 3 12 0
4 11 4 287 0
4 11 5 25 0
4 11 6 572 0
4 11 7 136 0
4 11 8 82 0
4 11 9 101 0
4 11 10 140 0
4 11 11 258 0
4 11 12 13 0
4 11 13 18 32
4 12 2 220 64
4 12 3 436 0
4 12 4 486 0
4 12 5 169 0
4 12 6 87 0
4 12 7 247 0
4 12 8 400 0
4 12 9 521 0
4 12 10 364 0
4 12 11 6 0
4 12 12 92 0
4 12 13 11 32
4 13 2 288 72
4 13 3 383 0
4 13 4 154 0
4 13 5 152 0
4 13 6 27 0
4 13 7 389 0
4 13 8 455 0
4 13 9 207 0
4 13 10 115 0
4 13 11 79 0
4 13 12 493 0
4 13 13 42 32
4 14 3 241 72
4 14 4 187 0
4 14 5 14 0
4 14 6 8 0
4 14 7 359 0
4 14 8 283 0
4 14 9 502 0
4 14 10 132 0
4 14 11 68 0
4 14 12 18 0
4 14 13 18 42
4 15 4 341 72
4 15 5 313 8
4 15 6 256 8
4 15 7 256 8
4 15 8 408 8
4 15 9 298 8
4 15 10 9 8
4 15 11 441 8
4 15 12 8 40
5 0 10 380 80
5 0 11 519 48
5 1 10 32 72
5 1 11 27 40
5 4 2 119 80
5 4 3 556 16
5 4 4 609 16
5 4 5 634 16
5 4 6 600 16
5 4 7 628 16
5 4 8 607 16
5 4 9 614 16
5 4 10 614 16
5 4 11 635 16
5 4 12 512 16
5 4 13 279 48
5 5 2 348 72
5 5 3 12 8
5 5 4 636 0
5 5 5 668 0
5 5 6 295 0
5 5 7 352 0
5 5 8 658 0
5 5 9 673 0
5 5 10 663 0
5 5 11 654 0
5 5 12 241 8
5 5 13 488 44
5 6 4 618 64
5 6 5 644 0
5 6 6 684 0
5 6 7 659 0
5 6 8 652 0
5 6 9 678 0
5 6 10 448 0
5 6 11 617 32
5 7 4 634 64
5 7 5 670 0
5 7 6 675 0
5 7 7 649 0
5 7 8 667 0
5 7 9 671 0
5 7 10 71 0
5 7 11 606 32
5 8 2 294 80
5 8 3 332 16
5 8 4 10 0
5 8 5 335 0
5 8 6 484 0
5 8 7 397 0
5 8 8 331 0
5 8 9 325 0
5 8 10 539 0
5 8 11 195 0
5 8 12 311 16
5 8 13 547 48
5 9 2 163 64
5 9 3 6 0
5 9 4 160 0
5 9 5 58 0
5 9 6 494 0
5 9 7 434 0
5 9 8 531 0
5 9 9 586 0
5 9 10 422 0
5 9 11 580 0
5 9 12 595 0
5 9 13 584 32
5 10 2 141 64
5 10 3 231 0
5 10 4 18 0
5 10 5 14 0
5 10 6 143 0
5 10 7 384 0
5 10 8 16 0
5 10 9 12 0
5 10 10 191 0
5 10 11 369 0
5 10 12 256 0
5 10 13 11 32
5 11 2 335 64
5 11 3 16 0
5 11 4 441 0
5 11 5 275 0
5 11 6 366 0
5 11 7 304 0
5 11 8 562 0
5 11 9 9 0
5 11 10 273 0
5 11 11 550 0
5 11 12 57 0
5 11 13 16 32
5 12 2 250 64
5 12 3 394 0
5 12 4 482 0
5 12 5 171 0
5 12 6 148 0
5 12 7 208 0
5 12 8 593 0
5 12 9 579 0
5 12 10 242 0
5 12 11 427 0
5 12 12 228 0
5 12 13 128 32
5 13 2 471 72
5 13 3 539 0
5 13 4 467 0
5 13 5 176 0
5 13 6 300 0
5 13 7 149 0
5 13 8 503 0
5 13 9 412 0
5 13 10 362 0
5 13 11 174 0
5 13 12 8 0
5 13 13 15 42
5 14 3 506 72
5 14 4 11 0
5 14 5 70 0
5 14 6 513 0
5 14 7 14 0
5 14 8 516 0
5 14 9 527 0
5 14 10 164 0
5 14 11 121 0
5 14 12 21 32
5 15 4 6 72
5 15 5 6 8
5 15 6 406 8
5 15 7 245 8
5 15 8 469 8
5 15 9 450 8
5 15 10 411 8
5 15 11 105 8
5 15 12 13 40
6 0 4 297 84
6 0 5 318 52
6 0 10 462 80
6 0 11 221 48
6 1 4 569 68
6 1 5 299 36
6 1 10 388 64
6 1 11 507 32
6 2 4 454 68
6 2 5 390 36
6 2 10 21 68
6 2 11 393 36
6 3 4 566 68
6 3 5 211 36
6 3 10 317 68
6 3 11 112 36
6 4 2 609 80
6 4 3 619 16
6 4 4 11 0
6 4 5 179 0
6 4 6 628 16
6 4 7 623 16
6 4 8 610 16
6 4 9 602 16
6 4 10 62 0
6 4 11 67 0
6 4 12 634 16
6 4 13 601 48
6 5 2 607 72
6 5 3 608 8
6 5 4 198 0
6 5 5 21 0
6 5 6 119 0
6 5 7 439 0
6 5 8 580 0
6 5 9 340 0
6 5 10 64 0
6 5 11 512 0
6 5 12 630 8
6 5 13 601 40
6 6 4 602 64
6 6 5 669 0
6 6 6 257 0
6 6 7 422 0
6 6 8 345 0
6 6 9 360 0
6 6 10 651 0
6 6 11 601 32
6 7 4 608 64
6 7 5 646 0
6 7 6 582 0
6 7 7 431 0
6 7 8 18 0
6 7 9 8 0
6 7 10 674 0
6 7 11 624 32
6 8 2 65 80
6 8 3 66 16
6 8 4 31 0
6 8 5 409 0
6 8 6 21 0
6 8 7 233 0
6 8 8 138 0
6 8 9 379 0
6 8 10 444 0
6 8 11 523 0
6 8 12 84 16
6 8 13 131 48
6 9 2 145 64
6 9 3 22 0
6 9 4 277 0
6 9 5 31 0
6 9 6 94 0
6 9 7 303 0
6 9 8 142 0
6 9 9 548 0
6 9 10 523 0
6 9 11 414 0
6 9 12 17 0
6 9 13 8 32
6 10 2 575 64
6 10 3 533 0
6 10 4 156 0
6 10 5 355 0
6 10 6 528 0
6 10 7 576 0
6 10 8 16 0
6 10 9 21 0
6 10 10 379 0
6 10 11 80 0
6 10 12 549 0
6 10 13 458 32
6 11 2 374 64
6 11 3 60 0
6 11 4 496 0
6 11 5 180 0
6 11 6 596 0
6 11 7 427 0
6 11 8 143 0
6 11 9 563 0
6 11 10 372 0
6 11 11 72 0
6 11 12 194 0
6 11 13 228 32
6 12 2 27 64
6 12 3 22 0
6 12 4 341 0
6 12 5 115 0
6 12 6 283 0
6 12 7 592 0
6 12 8 134 0
6 12 9 289 0
6 12 10 11 0
6 12 11 74 0
6 12 12 389 0
6 12 13 83 40
6 13 2 355 72
6 13 3 37 0
6 13 4 361 0
6 13 5 75 0
6 13 6 271 0
6 13 7 409 0
6 13 8 399 0
6 13 9 389 0
6 13 10 242 0
6 13 11 367 0
6 13 12 228 32
6 14 3 205 72
6 14 4 181 0
6 14 5 123 0
6 14 6 161 0
6 14 7 14 0
6 14 8 357 0
6 14 9 511 0
6 14 10 59 0
6 14 11 18 0
6 14 12 14 32
6 15 4 461 72
6 15 5 114 8
6 15 6 257 8
6 15 7 300 8
6 15 8 412 8
6 15 9 339 8
6 15 10 107 8
6 15 11 61 8
6 15 12 423 40
7 0 4 457 80
7 0 5 318 48
7 0 10 229 82
7 0 11 398 50
7 1 4 436 64
7 1 5 373 32
7 1 10 414 66
7 1 11 506 34
7 2 4 431 64
7 2 5 584 32
7 2 10 239 64
7 2 11 7 32
7 3 4 577 64
7 3 5 374 32
7 3 10 156 64
7 3 11 211 32
7 4 2 630 80
7 4 3 602 16
7 4 4 27 0
7 4 5 35 0
7 4 6 604 16
7 4 7 613 16
7 4 8 624 16
7 4 9 616 16
7 4 10 60 0
7 4 11 266 0
7 4 12 629 18
7 4 13 609 50
7 5 2 634 72
7 5 3 607 8
7 5 4 11 0
7 5 5 47 0
7 5 6 337 0
7 5 7 62 0
7 5 8 243 0
7 5 9 560 0
7 5 10 336 0
7 5 11 226 0
7 5 12 602 10
7 5 13 634 42
7 6 4 632 64
7 6 5 642 0
7 6 6 530 0
7 6 7 260 0
7 6 8 129 0
7 6 9 360 0
7 6 10 652 0
7 6 11 622 32
7 7 4 601 64
7 7 5 677 0
7 7 6 552 0
7 7 7 516 0
7 7 8 11 0
7 7 9 16 0
7 7 10 655 0
7 7 11 633 32
7 8 2 51 80
7 8 3 161 16
7 8 4 422 0
7 8 5 246 0
7 8 6 276 0
7 8 7 230 0
7 8 8 574 0
7 8 9 478 0
7 8 10 570 0
7 8 11 262 0
7 8 12 235 16
7 8 13 8 48
7 9 2 475 64
7 9 3 22 0
7 9 4 389 0
7 9 5 305 0
7 9 6 487 0
7 9 7 53 0
7 9 8 178 0
7 9 9 404 0
7 9 10 348 0
7 9 11 525 0
7 9 12 346 0
7 9 13 184 32
7 10 2 38 64
7 10 3 39 0
7 10 4 508 0
7 10 5 159 0
7 10 6 498 0
7 10 7 433 0
7 10 8 8 0
7 10 9 171 0
7 10 10 80 0
7 10 11 574 0
7 10 12 490 0
7 10 13 208 32
7 11 2 373 64
7 11 3 413 0
7 11 4 339 0
7 11 5 385 0
7 11 6 583 0
7 11 7 291 0
7 11 8 7 0
7 11 9 5 0
7 11 10 338 0
7 11 11 104 0
7 11 12 229 0
7 11 13 211 32
7 12 2 567 64
7 12 3 122 0
7 12 4 11 0
7 12 5 6 0
7 12 6 253 0
7 12 7 534 0
7 12 8 165 0
7 12 9 565 0
7 12 10 448 0
7 12 11 312 0
7 12 12 447 0
7 12 13 468 32
7 13 2 281 64
7 13 3 30 0
7 13 4 221 0
7 13 5 13 0
7 13 6 464 0
7 13 7 381 0
7 13 8 488 0
7 13 9 134 0
7 13 10 16 0
7 13 11 394 0
7 13 12 279 0
7 13 13 512 44
7 14 2 392 68
7 14 3 171 0
7 14 4 418 0
7 14 5 539 0
7 14 6 120 0
7 14 7 337 0
7 14 8 452 0
7 14 9 499 0
7 14 10 32 0
7 14 11 477 0
7 14 12 243 32
7 15 2 193 76
7 15 3 279 12
7 15 4 578 8
7 15 5 118 8
7 15 6 469 8
7 15 7 179 8
7 15 8 212 8
7 15 9 314 8
7 15 10 303 8
7 15 11 159 8
7 15 12 238 40
8 0 4 485 80
8 0 5 408 48
8 1 4 452 64
8 1 5 188 32
8 1 10 27 126
8 1 11 27 126
8 2 4 365 64
8 2 5 189 32
8 2 10 54 80
8 2 11 387 48
8 3 4 9 64
8 3 5 278 32
8 3 10 30 64
8 3 11 402 32
8 4 2 608 80
8 4 3 611 16
8 4 4 430 0
8 4 5 251 0
8 4 6 609 16
8 4 7 627 16
8 4 8 624 16
8 4 9 613 16
8 4 10 369 0
8 4 11 617 32
8 5 2 601 72
8 5 3 628 8
8 5 4 250 0
8 5 5 370 0
8 5 6 16 0
8 5 7 19 0
8 5 8 580 0
8 5 9 431 0
8 5 10 223 0
8 5 11 617 32
8 6 4 605 64
8 6 5 680 0
8 6 6 551 0
8 6 7 388 0
8 6 8 410 0
8 6 9 206 0
8 6 10 676 0
8 6 11 617 32
8 7 4 608 64
8 7 5 665 0
8 7 6 372 0
8 7 7 192 0
8 7 8 429 0
8 7 9 419 0
8 7 10 685 0
8 7 11 608 32
8 8 2 687 80
8 8 3 282 16
8 8 4 5 0
8 8 5 209 0
8 8 6 299 0
8 8 7 264 0
8 8 8 426 0
8 8 9 371 0
8 8 10 547 0
8 8 11 349 0
8 8 12 100 16
8 8 13 292 48
8 9 2 14 64
8 9 3 209 0
8 9 4 18 0
8 9 5 503 0
8 9 6 377 0
8 9 7 489 0
8 9 8 320 0
8 9 9 369 0
8 9 10 481 0
8 9 11 522 0
8 9 12 308 0
8 9 13 8 32
8 10 2 116 64
8 10 3 365 0
8 10 4 452 0
8 10 5 14 0
8 10 6 448 0
8 10 7 14 0
8 10 8 185 0
8 10 9 279 0
8 10 10 311 0
8 10 11 217 0
8 10 12 137 0
8 10 13 98 32
8 11 2 1 64
8 11 3 4 0
8 11 4 18 0
8 11 5 106 0
8 11 6 140 0
8 11 7 315 0
8 11 8 332 0
8 11 9 110 0
8 11 10 199 0
8 11 11 510 0
8 11 12 349 0
8 11 13 127 32
8 12 2 475 64
8 12 3 288 0
8 12 4 446 0
8 12 5 157 0
8 12 6 301 0
8 12 7 334 0
8 12 8 385 0
8 12 9 353 0
8 12 10 420 0
8 12 11 210 0
8 12 12 68 0
8 12 13 476 32
8 13 2 587 64
8 13 3 257 0
8 13 4 395 0
8 13 5 173 0
8 13 6 252 0
8 13 7 469 0
8 13 8 27 0
8 13 9 500 0
8 13 10 280 0
8 13 11 227 0
8 13 12 50 0
8 13 13 353 32
8 14 2 328 64
8 14 3 370 0
8 14 4 645 0
8 14 5 648 0
8 14 6 146 0
8 14 7 365 0
8 14 8 16 0
8 14 9 87 0
8 14 10 10 0
8 14 11 4 0
8 14 12 151 0
8 14 13 90 36
8 15 2 425 72
8 15 3 536 8
8 15 4 319 8
8 15 5 319 8
8 15 6 319 8
8 15 7 361 8
8 15 8 319 8
8 15 9 330 8
8 15 10 39 8
8 15 11 8 8
8 15 12 87 8
8 15 13 408 44
9 0 4 519 82
9 0 5 459 50
9 1 4 464 66
9 1 5 520 34
9 2 4 3 66
9 2 5 3 34
9 2 10 166 82
9 2 11 27 50
9 3 4 416 66
9 3 5 8 34
9 3 10 19 66
9 3 11 25 34
9 4 2 602 82
9 4 3 633 18
9 4 4 266 0
9 4 5 357 0
9 4 6 610 16
9 4 7 604 16
9 4 8 607 16
9 4 9 623 16
9 4 10 244 0
9 4 11 607 32
9 5 2 616 74
9 5 3 608 10
9 5 4 323 0
9 5 5 586 0
9 5 6 438 0
9 5 7 12 0
9 5 8 224 0
9 5 9 316 0
9 5 10 381 0
9 5 11 607 32
9 6 4 615 64
9 6 5 641 0
9 6 6 412 0
9 6 7 365 0
9 6 8 466 0
9 6 9 13 0
9 6 10 679 0
9 6 11 607 32
9 7 4 604 64
9 7 5 666 0
9 7 6 197 0
9 7 7 172 0
9 7 8 87 0
9 7 9 193 0
9 7 10 675 0
9 7 11 630 32
9 8 2 687 80
9 8 3 131 16
9 8 4 270 0
9 8 5 481 0
9 8 6 330 0
9 8 7 264 0
9 8 8 332 0
9 8 9 72 0
9 8 10 504 0
9 8 11 441 0
9 8 12 16 16
9 8 13 124 48
9 9 2 428 64
9 9 3 131 0
9 9 4 378 0
9 9 5 170 0
9 9 6 516 0
9 9 7 599 0
9 9 8 190 0
9 9 9 368 0
9 9 10 581 0
9 9 11 369 0
9 9 12 129 0
9 9 13 269 32
9 10 2 153 64
9 10 3 116 0
9 10 4 14 0
9 10 5 293 0
9 10 6 176 0
9 10 7 11 0
9 10 8 83 0
9 10 9 85 0
9 10 10 386 0
9 10 11 520 0
9 10 12 229 0
9 10 13 259 32
9 11 2 18 64
9 11 3 173 0
9 11 4 28 0
9 11 5 484 0
9 11 6 309 0
9 11 7 225 0
9 11 8 189 0
9 11 9 22 0
9 11 10 99 0
9 11 11 102 0
9 11 12 22 0
9 11 13 102 32
9 12 2 559 64
9 12 3 243 0
9 12 4 345 0
9 12 5 408 0
9 12 6 417 0
9 12 7 262 0
9 12 8 16 0
9 12 9 557 0
9 12 10 378 0
9 12 11 452 0
9 12 12 192 0
9 12 13 368 32
9 13 2 246 64
9 13 3 471 0
9 13 4 160 0
9 13 5 347 0
9 13 6 412 0
9 13 7 151 0
9 13 8 27 0
9 13 9 16 0
9 13 10 523 0
9 13 11 186 0
9 13 12 315 0
9 13 13 25 32
9 14 2 495 64
9 14 3 594 0
9 14 4 640 0
9 14 5 638 0
9 14 6 365 0
9 14 7 209 0
9 14 8 496 0
9 14 9 85 0
9 14 10 71 0
9 14 11 8 0
9 14 12 183 0
9 14 13 95 32
9 15 2 589 72
9 15 3 437 8
9 15 4 319 8
9 15 5 319 8
9 15 6 65 8
9 15 7 189 8
9 15 8 78 8
9 15 9 16 8
9 15 10 75 8
9 15 11 69 8
9 15 12 97 8
9 15 13 178 40
10 4 4 625 80
10 4 5 615 16
10 4 6 603 16
10 4 7 607 16
10 4 8 607 16
10 4 9 600 16
10 4 10 608 16
10 4 11 627 48
10 5 4 600 64
10 5 5 646 0
10 5 6 643 0
10 5 7 660 0
10 5 8 664 0
10 5 9 657 0
10 5 10 662 0
10 5 11 613 32
10 6 4 621 64
10 6 5 650 0
10 6 6 656 0
10 6 7 661 0
10 6 8 83 0
10 6 9 13 0
10 6 10 682 0
10 6 11 615 32
10 7 4 602 64
10 7 5 653 0
10 7 6 686 0
10 7 7 672 0
10 7 8 377 0
10 7 9 155 0
10 7 10 641 0
10 7 11 605 32
10 8 2 687 80
10 8 3 460 16
10 8 4 21 0
10 8 5 102 0
10 8 6 264 0
10 8 7 380 0
10 8 8 294 0
10 8 9 524 0
10 8 10 572 0
10 8 11 547 0
10 8 12 505 16
10 8 13 305 48
10 9 2 488 64
10 9 3 515 0
10 9 4 29 0
10 9 5 198 0
10 9 6 216 0
10 9 7 559 0
10 9 8 524 0
10 9 9 318 0
10 9 10 34 0
10 9 11 48 0
10 9 12 523 0
10 9 13 514 32
10 10 2 319 64
10 10 3 647 0
10 10 4 330 0
10 10 5 168 0
10 10 6 380 0
10 10 7 281 0
10 10 8 430 0
10 10 9 247 0
10 10 10 246 0
10 10 11 193 0
10 10 12 198 0
10 10 13 16 32
10 11 2 319 64
10 11 3 639 0
10 11 4 152 0
10 11 5 4 0
10 11 6 40 0
10 11 7 28 0
10 11 8 484 0
10 11 9 14 0
10 11 10 22 0
10 11 11 25 0
10 11 12 147 0
10 11 13 357 32
10 12 2 319 64
10 12 3 403 0
10 12 4 369 0
10 12 5 202 0
10 12 6 431 0
10 12 7 256 0
10 12 8 89 0
10 12 9 27 0
10 12 10 358 0
10 12 11 236 0
10 12 12 45 0
10 12 13 175 32
10 13 2 415 64
10 13 3 202 0
10 13 4 431 0
10 13 5 525 0
10 13 6 453 0
10 13 7 585 0
10 13 8 161 0
10 13 9 225 0
10 13 10 11 0
10 13 11 184 0
10 13 12 329 0
10 13 13 375 32
10 14 2 220 64
10 14 3 11 0
10 14 4 452 0
10 14 5 276 0
10 14 6 463 0
10 14 7 283 0
10 14 8 11 0
10 14 9 13 0
10 14 10 170 0
10 14 11 82 0
10 14 12 688 0
10 14 13 687 32
10 15 2 687 72
10 15 3 9 8
10 15 4 15 8
10 15 5 193 8
10 15 6 263 8
10 15 7 475 8
10 15 8 5 8
10 15 9 493 8
10 15 10 157 8
10 15 11 319 8
10 15 12 319 8
10 15 13 319 40
11 4 4 602 82
11 4 5 628 18
11 4 6 633 18
11 4 7 610 18
11 4 8 613 18
11 4 9 611 18
11 4 10 612 18
11 4 11 601 50
11 5 4 604 66
11 5 5 620 2
11 5 6 625 2
11 5 7 635 2
11 5 8 618 2
11 5 9 616 2
11 5 10 605 2
11 5 11 617 34
11 6 4 622 66
11 6 5 610 2
11 6 6 627 2
11 6 7 617 2
11 6 8 605 2
11 6 9 629 2
11 6 10 611 2
11 6 11 600 34
11 7 4 634 66
11 7 5 624 2
11 7 6 610 2
11 7 7 610 2
11 7 8 615 2
11 7 9 635 2
11 7 10 615 2
11 7 11 629 34
11 8 2 687 80
11 8 3 388 16
11 8 4 8 0
11 8 5 276 0
11 8 6 36 0
11 8 7 180 0
11 8 8 544 0
11 8 9 340 0
11 8 10 22 0
11 8 11 404 0
11 8 12 519 16
11 8 13 274 48
11 9 2 319 64
11 9 3 537 0
11 9 4 464 0
11 9 5 130 0
11 9 6 133 0
11 9 7 321 0
11 9 8 565 0
11 9 9 318 0
11 9 10 28 0
11 9 11 443 0
11 9 12 260 0
11 9 13 260 34
11 10 2 319 64
11 10 3 626 0
11 10 4 491 0
11 10 5 296 0
11 10 6 19 0
11 10 7 21 0
11 10 8 27 0
11 10 9 285 0
11 10 10 19 0
11 10 11 428 0
11 10 12 172 2
11 10 13 219 34
11 11 2 319 64
11 11 3 637 0
11 11 4 2 0
11 11 5 10 0
11 11 6 483 0
11 11 7 126 0
11 11 8 401 0
11 11 9 313 0
11 11 10 17 0
11 11 11 65 0
11 11 12 554 0
11 11 13 33 34
11 12 2 395 64
11 12 3 567 0
11 12 4 234 0
11 12 5 266 0
11 12 6 535 0
11 12 7 540 0
11 12 8 249 0
11 12 9 16 0
11 12 10 379 0
11 12 11 491 0
11 12 12 407 0
11 12 13 307 34
11 13 2 431 64
11 13 3 436 0
11 13 4 397 0
11 13 5 323 0
11 13 6 584 0
11 13 7 405 0
11 13 8 389 0
11 13 9 18 0
11 13 10 14 0
11 13 11 11 0
11 13 12 397 0
11 13 13 209 32
11 14 2 12 64
11 14 3 58 0
11 14 4 11 0
11 14 5 76 0
11 14 6 546 0
11 14 7 574 0
11 14 8 56 0
11 14 9 235 0
11 14 10 87 0
11 14 11 152 0
11 14 12 681 0
11 14 13 683 32
11 15 2 687 72
11 15 3 687 8
11 15 4 509 8
11 15 5 26 8
11 15 6 479 8
11 15 7 571 8
11 15 8 21 8
11 15 9 196 8
11 15 10 363 8
11 15 11 9 8
11 15 12 319 8
11 15 13 319 40
12 8 2 357 80
12 8 3 132 16
12 8 4 23 16
12 8 5 162 16
12 8 6 244 16
12 8 7 204 16
12 8 8 261 16
12 8 9 256 16
12 8 10 135 16
12 8 11 143 16
12 8 12 305 16
12 8 13 382 56
12 9 2 290 64
12 9 3 143 0
12 9 4 132 0
12 9 5 81 0
12 9 6 519 0
12 9 7 246 0
12 9 8 329 0
12 9 9 9 0
12 9 10 354 0
12 9 11 501 2
12 9 12 267 42
12 10 2 189 64
12 10 3 248 0
12 10 4 432 0
12 10 5 307 0
12 10 6 487 0
12 10 7 449 0
12 10 8 48 0
12 10 9 526 2
12 10 10 514 2
12 10 11 514 32
12 11 2 51 64
12 11 3 213 0
12 11 4 473 0
12 11 5 595 0
12 11 6 262 0
12 11 7 463 0
12 11 8 203 0
12 11 9 244 2
12 11 10 470 2
12 11 11 588 2
12 11 12 519 50
12 12 2 505 64
12 12 3 22 0
12 12 4 140 0
12 12 5 302 0
12 12 6 560 0
12 12 7 561 0
12 12 8 200 0
12 12 9 14 0
12 12 10 282 0
12 12 11 34 0
12 12 12 25 32
12 13 2 262 64
12 13 3 19 0
12 13 4 232 0
12 13 5 194 0
12 13 6 356 0
12 13 7 517 0
12 13 8 25 0
12 13 9 16 0
12 13 10 35 0
12 13 11 322 0
12 13 12 296 0
12 13 13 242 48
12 14 2 397 64
12 14 3 17 0
12 14 4 93 0
12 14 5 215 0
12 14 6 120 0
12 14 7 540 0
12 14 8 96 0
12 14 9 286 0
12 14 10 46 0
12 14 11 227 0
12 14 12 332 0
12 14 13 22 32
12 15 2 209 72
12 15 3 16 8
12 15 4 86 8
12 15 5 86 8
12 15 6 108 8
12 15 7 162 8
12 15 8 17 8
12 15 9 28 8
12 15 10 46 8
12 15 11 218 8
12 15 12 282 8
12 15 13 144 40
13 8 2 216 82
13 8 3 324 18
13 8 4 26 18
13 8 5 26 18
13 8 6 583 18
13 8 7 305 18
13 8 8 261 18
13 8 9 545 18
13 8 10 139 18
13 8 11 320 26
13 8 12 113 26
13 8 13 143 58
13 9 2 31 66
13 9 3 26 2
13 9 4 123 2
13 9 5 323 2
13 9 6 368 2
13 9 7 240 2
13 9 8 154 2
13 9 9 310 10
13 9 10 478 42
13 10 2 63 66
13 10 3 228 2
13 10 4 390 2
13 10 5 348 2
13 10 6 305 2
13 10 7 552 2
13 10 8 333 34
13 10 11 440 90
13 10 12 477 62
13 11 2 381 66
13 11 3 257 2
13 11 4 326 2
13 11 5 344 2
13 11 6 370 2
13 11 7 366 2
13 11 8 76 34
13 12 2 27 66
13 12 3 66 2
13 12 4 103 2
13 12 5 121 2
13 12 6 578 2
13 12 7 478 2
13 12 8 158 2
13 12 9 121 18
13 12 10 369 18
13 12 11 13 18
13 12 12 222 50
13 13 2 22 66
13 13 3 102 2
13 13 4 182 2
13 13 5 16 2
13 13 6 573 2
13 13 7 327 2
13 13 8 518 2
13 13 9 213 2
13 13 10 201 2
13 13 11 179 2
13 13 12 25 2
13 13 13 12 50
13 14 2 308 66
13 14 3 115 2
13 14 4 88 2
13 14 5 541 2
13 14 6 469 2
13 14 7 411 2
13 14 8 337 2
13 14 9 391 2
13 14 10 330 2
13 14 11 386 2
13 14 12 225 2
13 14 13 228 34
13 15 2 155 74
13 15 3 177 10
13 15 4 422 10
13 15 5 85 10
13 15 6 91 10
13 15 7 210 10
13 15 8 214 10
13 15 9 28 10
13 15 10 687 10
13 15 11 687 10
13 15 12 687 10
13 15 13 13 42
