Qubicle Exchange Format
Version 0.2
www.minddesk.com
16 16 16
799
0.000000 0.000000 0.000000
0.000000 0.164706 0.047059
0.000000 0.164706 0.050980
0.000000 0.168627 0.050980
0.000000 0.172549 0.047059
0.000000 0.172549 0.050980
0.000000 0.176471 0.050980
0.000000 0.176471 0.054902
0.000000 0.180392 0.050980
0.000000 0.180392 0.054902
0.000000 0.180392 0.058824
0.000000 0.180392 0.066667
0.000000 0.184314 0.054902
0.000000 0.184314 0.058824
0.000000 0.184314 0.062745
0.000000 0.188235 0.054902
0.000000 0.188235 0.058824
0.000000 0.192157 0.054902
0.000000 0.192157 0.058824
0.000000 0.192157 0.062745
0.000000 0.196078 0.058824
0.000000 0.196078 0.062745
0.000000 0.196078 0.070588
0.000000 0.200000 0.058824
0.000000 0.200000 0.062745
0.000000 0.200000 0.066667
0.000000 0.203922 0.058824
0.000000 0.203922 0.062745
0.000000 0.203922 0.066667
0.000000 0.203922 0.070588
0.000000 0.207843 0.062745
0.000000 0.207843 0.070588
0.000000 0.207843 0.074510
0.000000 0.211765 0.066667
0.000000 0.223529 0.074510
0.003922 0.003922 0.003922
0.003922 0.180392 0.066667
0.003922 0.184314 0.062745
0.003922 0.196078 0.062745
0.003922 0.200000 0.066667
0.003922 0.207843 0.066667
0.003922 0.207843 0.074510
0.003922 0.219608 0.078431
0.003922 0.223529 0.078431
0.003922 0.227451 0.074510
0.007843 0.007843 0.007843
0.007843 0.172549 0.062745
0.007843 0.188235 0.070588
0.007843 0.196078 0.070588
0.007843 0.200000 0.066667
0.007843 0.200000 0.070588
0.007843 0.203922 0.070588
0.007843 0.203922 0.074510
0.007843 0.207843 0.070588
0.007843 0.207843 0.078431
0.007843 0.211765 0.070588
0.007843 0.215686 0.078431
0.007843 0.219608 0.070588
0.011765 0.011765 0.011765
0.011765 0.188235 0.070588
0.011765 0.192157 0.074510
0.011765 0.196078 0.070588
0.011765 0.200000 0.074510
0.011765 0.203922 0.074510
0.011765 0.203922 0.082353
0.011765 0.207843 0.070588
0.011765 0.207843 0.074510
0.011765 0.207843 0.078431
0.011765 0.211765 0.074510
0.011765 0.219608 0.082353
0.011765 0.239216 0.090196
0.015686 0.015686 0.015686
0.015686 0.196078 0.070588
0.015686 0.200000 0.074510
0.015686 0.200000 0.078431
0.015686 0.203922 0.074510
0.015686 0.203922 0.078431
0.015686 0.207843 0.078431
0.015686 0.207843 0.086275
0.015686 0.211765 0.086275
0.015686 0.215686 0.078431
0.015686 0.215686 0.086275
0.015686 0.223529 0.078431
0.015686 0.223529 0.082353
0.015686 0.239216 0.094118
0.019608 0.019608 0.019608
0.019608 0.176471 0.074510
0.019608 0.192157 0.078431
0.019608 0.200000 0.074510
0.019608 0.203922 0.082353
0.019608 0.207843 0.078431
0.019608 0.207843 0.082353
0.019608 0.215686 0.078431
0.019608 0.215686 0.086275
0.019608 0.223529 0.090196
0.019608 0.227451 0.094118
0.019608 0.235294 0.090196
0.019608 0.250980 0.098039
0.023529 0.023529 0.023529
0.023529 0.192157 0.078431
0.023529 0.196078 0.086275
0.023529 0.200000 0.086275
0.023529 0.203922 0.082353
0.023529 0.207843 0.086275
0.023529 0.211765 0.082353
0.023529 0.211765 0.086275
0.023529 0.215686 0.086275
0.023529 0.219608 0.086275
0.023529 0.219608 0.090196
0.023529 0.223529 0.094118
0.023529 0.223529 0.098039
0.023529 0.227451 0.090196
0.023529 0.231373 0.090196
0.023529 0.231373 0.094118
0.023529 0.235294 0.098039
0.023529 0.243137 0.098039
0.027451 0.196078 0.082353
0.027451 0.203922 0.082353
0.027451 0.207843 0.086275
0.027451 0.219608 0.090196
0.027451 0.219608 0.094118
0.027451 0.223529 0.090196
0.027451 0.223529 0.094118
0.027451 0.231373 0.094118
0.027451 0.243137 0.098039
0.031373 0.200000 0.086275
0.031373 0.203922 0.086275
0.031373 0.203922 0.090196
0.031373 0.211765 0.090196
0.031373 0.211765 0.094118
0.031373 0.215686 0.090196
0.031373 0.219608 0.090196
0.031373 0.219608 0.094118
0.031373 0.219608 0.098039
0.031373 0.223529 0.098039
0.031373 0.227451 0.094118
0.031373 0.227451 0.098039
0.031373 0.231373 0.094118
0.031373 0.231373 0.098039
0.031373 0.231373 0.101961
0.031373 0.235294 0.101961
0.031373 0.239216 0.105882
0.031373 0.243137 0.101961
0.031373 0.243137 0.105882
0.035294 0.203922 0.094118
0.035294 0.211765 0.090196
0.035294 0.211765 0.094118
0.035294 0.219608 0.094118
0.035294 0.219608 0.098039
0.035294 0.227451 0.101961
0.035294 0.231373 0.098039
0.035294 0.231373 0.101961
0.035294 0.235294 0.101961
0.035294 0.235294 0.105882
0.035294 0.239216 0.098039
0.035294 0.243137 0.109804
0.035294 0.247059 0.113725
0.035294 0.254902 0.109804
0.039216 0.207843 0.094118
0.039216 0.215686 0.098039
0.039216 0.219608 0.094118
0.039216 0.219608 0.101961
0.039216 0.227451 0.101961
0.039216 0.231373 0.101961
0.039216 0.235294 0.101961
0.039216 0.235294 0.105882
0.039216 0.239216 0.101961
0.039216 0.247059 0.109804
0.039216 0.254902 0.113725
0.043137 0.211765 0.101961
0.043137 0.219608 0.101961
0.043137 0.231373 0.101961
0.043137 0.231373 0.105882
0.043137 0.231373 0.113725
0.043137 0.235294 0.105882
0.043137 0.235294 0.109804
0.043137 0.239216 0.109804
0.043137 0.239216 0.113725
0.043137 0.243137 0.109804
0.043137 0.243137 0.113725
0.043137 0.247059 0.109804
0.043137 0.247059 0.113725
0.043137 0.258824 0.117647
0.043137 0.262745 0.113725
0.047059 0.211765 0.098039
0.047059 0.223529 0.101961
0.047059 0.223529 0.109804
0.047059 0.227451 0.105882
0.047059 0.231373 0.113725
0.047059 0.235294 0.109804
0.047059 0.235294 0.113725
0.047059 0.239216 0.109804
0.047059 0.243137 0.113725
0.047059 0.243137 0.117647
0.047059 0.247059 0.113725
0.047059 0.247059 0.117647
0.047059 0.250980 0.109804
0.047059 0.250980 0.117647
0.047059 0.266667 0.125490
0.050980 0.050980 0.050980
0.050980 0.223529 0.109804
0.050980 0.227451 0.109804
0.050980 0.231373 0.105882
0.050980 0.231373 0.113725
0.050980 0.235294 0.109804
0.050980 0.235294 0.113725
0.050980 0.235294 0.117647
0.050980 0.239216 0.113725
0.050980 0.243137 0.109804
0.050980 0.243137 0.113725
0.050980 0.243137 0.121569
0.050980 0.247059 0.113725
0.050980 0.250980 0.117647
0.050980 0.250980 0.121569
0.050980 0.254902 0.117647
0.050980 0.258824 0.121569
0.054902 0.219608 0.109804
0.054902 0.227451 0.113725
0.054902 0.235294 0.117647
0.054902 0.239216 0.113725
0.054902 0.239216 0.117647
0.054902 0.243137 0.117647
0.054902 0.247059 0.113725
0.054902 0.247059 0.117647
0.054902 0.247059 0.121569
0.054902 0.250980 0.117647
0.054902 0.250980 0.121569
0.054902 0.250980 0.125490
0.054902 0.258824 0.121569
0.054902 0.258824 0.125490
0.054902 0.262745 0.125490
0.054902 0.262745 0.129412
0.054902 0.274510 0.133333
0.058824 0.058824 0.058824
0.058824 0.219608 0.113725
0.058824 0.231373 0.113725
0.058824 0.231373 0.117647
0.058824 0.235294 0.121569
0.058824 0.239216 0.113725
0.058824 0.239216 0.121569
0.058824 0.243137 0.117647
0.058824 0.243137 0.121569
0.058824 0.247059 0.117647
0.058824 0.247059 0.121569
0.058824 0.250980 0.121569
0.058824 0.254902 0.121569
0.058824 0.254902 0.125490
0.058824 0.258824 0.125490
0.058824 0.258824 0.129412
0.058824 0.262745 0.129412
0.058824 0.278431 0.133333
0.062745 0.223529 0.113725
0.062745 0.231373 0.117647
0.062745 0.235294 0.121569
0.062745 0.239216 0.117647
0.062745 0.239216 0.121569
0.062745 0.247059 0.117647
0.062745 0.250980 0.121569
0.062745 0.250980 0.125490
0.062745 0.254902 0.121569
0.062745 0.254902 0.125490
0.062745 0.254902 0.129412
0.062745 0.258824 0.129412
0.062745 0.262745 0.125490
0.062745 0.266667 0.125490
0.062745 0.266667 0.129412
0.062745 0.266667 0.133333
0.062745 0.270588 0.133333
0.062745 0.274510 0.133333
0.062745 0.278431 0.137255
0.062745 0.282353 0.137255
0.066667 0.235294 0.117647
0.066667 0.243137 0.117647
0.066667 0.243137 0.129412
0.066667 0.247059 0.125490
0.066667 0.247059 0.129412
0.066667 0.250980 0.125490
0.066667 0.254902 0.125490
0.066667 0.254902 0.129412
0.066667 0.258824 0.133333
0.066667 0.262745 0.133333
0.066667 0.266667 0.133333
0.066667 0.266667 0.137255
0.066667 0.274510 0.137255
0.070588 0.235294 0.129412
0.070588 0.243137 0.121569
0.070588 0.243137 0.125490
0.070588 0.247059 0.125490
0.070588 0.250980 0.133333
0.070588 0.254902 0.129412
0.070588 0.258824 0.129412
0.070588 0.258824 0.133333
0.070588 0.266667 0.133333
0.070588 0.266667 0.137255
0.070588 0.274510 0.137255
0.070588 0.274510 0.141176
0.070588 0.278431 0.141176
0.074510 0.239216 0.129412
0.074510 0.247059 0.125490
0.074510 0.247059 0.133333
0.074510 0.250980 0.125490
0.074510 0.250980 0.133333
0.074510 0.250980 0.137255
0.074510 0.254902 0.133333
0.074510 0.258824 0.133333
0.074510 0.258824 0.137255
0.074510 0.270588 0.137255
0.074510 0.270588 0.141176
0.074510 0.274510 0.141176
0.074510 0.278431 0.141176
0.074510 0.286275 0.145098
0.078431 0.247059 0.129412
0.078431 0.250980 0.137255
0.078431 0.254902 0.137255
0.078431 0.254902 0.141176
0.078431 0.258824 0.137255
0.078431 0.258824 0.141176
0.078431 0.258824 0.145098
0.078431 0.262745 0.137255
0.078431 0.262745 0.141176
0.078431 0.262745 0.145098
0.078431 0.266667 0.137255
0.078431 0.266667 0.141176
0.078431 0.266667 0.145098
0.078431 0.270588 0.145098
0.078431 0.274510 0.141176
0.078431 0.274510 0.145098
0.078431 0.274510 0.149020
0.078431 0.278431 0.141176
0.078431 0.278431 0.145098
0.078431 0.278431 0.149020
0.078431 0.286275 0.149020
0.078431 0.290196 0.152941
0.082353 0.239216 0.137255
0.082353 0.254902 0.137255
0.082353 0.254902 0.141176
0.082353 0.258824 0.141176
0.082353 0.258824 0.145098
0.082353 0.262745 0.137255
0.082353 0.262745 0.141176
0.082353 0.262745 0.145098
0.082353 0.266667 0.141176
0.082353 0.266667 0.145098
0.082353 0.270588 0.145098
0.082353 0.270588 0.149020
0.082353 0.274510 0.141176
0.082353 0.274510 0.145098
0.082353 0.274510 0.149020
0.082353 0.278431 0.149020
0.082353 0.278431 0.152941
0.082353 0.282353 0.149020
0.082353 0.282353 0.152941
0.082353 0.286275 0.149020
0.082353 0.290196 0.152941
0.082353 0.294118 0.152941
0.086275 0.243137 0.137255
0.086275 0.247059 0.137255
0.086275 0.254902 0.141176
0.086275 0.258824 0.145098
0.086275 0.262745 0.141176
0.086275 0.266667 0.149020
0.086275 0.270588 0.145098
0.086275 0.270588 0.149020
0.086275 0.274510 0.149020
0.086275 0.278431 0.145098
0.086275 0.278431 0.149020
0.086275 0.278431 0.152941
0.086275 0.282353 0.152941
0.086275 0.282353 0.156863
0.086275 0.286275 0.152941
0.086275 0.286275 0.156863
0.086275 0.286275 0.160784
0.086275 0.290196 0.152941
0.086275 0.290196 0.156863
0.086275 0.294118 0.152941
0.086275 0.294118 0.156863
0.086275 0.294118 0.160784
0.090196 0.250980 0.141176
0.090196 0.258824 0.149020
0.090196 0.262745 0.145098
0.090196 0.262745 0.149020
0.090196 0.266667 0.145098
0.090196 0.270588 0.145098
0.090196 0.270588 0.149020
0.090196 0.270588 0.152941
0.090196 0.274510 0.152941
0.090196 0.274510 0.156863
0.090196 0.278431 0.152941
0.090196 0.278431 0.156863
0.090196 0.282353 0.152941
0.090196 0.282353 0.156863
0.090196 0.286275 0.152941
0.090196 0.286275 0.156863
0.090196 0.290196 0.156863
0.090196 0.290196 0.160784
0.090196 0.294118 0.160784
0.090196 0.298039 0.160784
0.090196 0.298039 0.164706
0.094118 0.262745 0.152941
0.094118 0.270588 0.152941
0.094118 0.270588 0.156863
0.094118 0.274510 0.149020
0.094118 0.274510 0.152941
0.094118 0.274510 0.156863
0.094118 0.278431 0.156863
0.094118 0.282353 0.152941
0.094118 0.282353 0.156863
0.094118 0.282353 0.160784
0.094118 0.286275 0.156863
0.094118 0.286275 0.160784
0.094118 0.290196 0.160784
0.094118 0.290196 0.164706
0.094118 0.294118 0.156863
0.094118 0.294118 0.160784
0.094118 0.298039 0.160784
0.094118 0.298039 0.164706
0.094118 0.298039 0.168627
0.094118 0.301961 0.164706
0.098039 0.254902 0.152941
0.098039 0.266667 0.156863
0.098039 0.270588 0.164706
0.098039 0.274510 0.156863
0.098039 0.274510 0.160784
0.098039 0.278431 0.156863
0.098039 0.278431 0.160784
0.098039 0.282353 0.156863
0.098039 0.282353 0.160784
0.098039 0.286275 0.156863
0.098039 0.286275 0.160784
0.098039 0.286275 0.164706
0.098039 0.290196 0.156863
0.098039 0.290196 0.160784
0.098039 0.290196 0.164706
0.098039 0.294118 0.164706
0.098039 0.294118 0.168627
0.098039 0.298039 0.164706
0.098039 0.298039 0.168627
0.098039 0.301961 0.168627
0.098039 0.305882 0.168627
0.101961 0.266667 0.152941
0.101961 0.266667 0.156863
0.101961 0.266667 0.160784
0.101961 0.274510 0.152941
0.101961 0.274510 0.156863
0.101961 0.274510 0.160784
0.101961 0.278431 0.156863
0.101961 0.278431 0.160784
0.101961 0.278431 0.164706
0.101961 0.282353 0.160784
0.101961 0.282353 0.164706
0.101961 0.286275 0.160784
0.101961 0.286275 0.164706
0.101961 0.290196 0.160784
0.101961 0.290196 0.164706
0.101961 0.294118 0.164706
0.101961 0.294118 0.168627
0.101961 0.298039 0.164706
0.101961 0.298039 0.168627
0.101961 0.298039 0.172549
0.101961 0.301961 0.168627
0.101961 0.301961 0.172549
0.101961 0.305882 0.172549
0.101961 0.309804 0.172549
0.105882 0.270588 0.160784
0.105882 0.274510 0.164706
0.105882 0.282353 0.164706
0.105882 0.286275 0.164706
0.105882 0.290196 0.164706
0.105882 0.294118 0.168627
0.105882 0.298039 0.168627
0.105882 0.298039 0.172549
0.105882 0.301961 0.168627
0.105882 0.301961 0.172549
0.105882 0.305882 0.172549
0.105882 0.305882 0.176471
0.105882 0.309804 0.172549
0.105882 0.309804 0.176471
0.105882 0.313726 0.176471
0.109804 0.278431 0.164706
0.109804 0.282353 0.164706
0.109804 0.286275 0.164706
0.109804 0.286275 0.168627
0.109804 0.286275 0.172549
0.109804 0.290196 0.168627
0.109804 0.290196 0.172549
0.109804 0.294118 0.168627
0.109804 0.294118 0.172549
0.109804 0.298039 0.172549
0.109804 0.298039 0.176471
0.109804 0.301961 0.172549
0.109804 0.305882 0.172549
0.109804 0.305882 0.176471
0.109804 0.309804 0.176471
0.109804 0.309804 0.180392
0.109804 0.313726 0.176471
0.109804 0.313726 0.180392
0.109804 0.317647 0.176471
0.109804 0.317647 0.180392
0.113725 0.282353 0.168627
0.113725 0.286275 0.168627
0.113725 0.286275 0.172549
0.113725 0.290196 0.168627
0.113725 0.290196 0.172549
0.113725 0.294118 0.172549
0.113725 0.294118 0.180392
0.113725 0.298039 0.172549
0.113725 0.298039 0.176471
0.113725 0.301961 0.172549
0.113725 0.301961 0.176471
0.113725 0.301961 0.180392
0.113725 0.305882 0.176471
0.113725 0.309804 0.176471
0.113725 0.309804 0.180392
0.113725 0.313726 0.180392
0.113725 0.313726 0.184314
0.113725 0.317647 0.180392
0.113725 0.317647 0.184314
0.117647 0.286275 0.172549
0.117647 0.286275 0.176471
0.117647 0.290196 0.176471
0.117647 0.294118 0.176471
0.117647 0.298039 0.176471
0.117647 0.301961 0.180392
0.117647 0.305882 0.180392
0.117647 0.309804 0.180392
0.117647 0.309804 0.184314
0.117647 0.313726 0.180392
0.117647 0.313726 0.184314
0.117647 0.317647 0.184314
0.117647 0.317647 0.188235
0.121569 0.282353 0.180392
0.121569 0.290196 0.176471
0.121569 0.294118 0.176471
0.121569 0.294118 0.180392
0.121569 0.298039 0.176471
0.121569 0.298039 0.180392
0.121569 0.305882 0.180392
0.121569 0.305882 0.184314
0.121569 0.309804 0.180392
0.121569 0.309804 0.184314
0.121569 0.309804 0.188235
0.121569 0.313726 0.184314
0.121569 0.313726 0.188235
0.121569 0.317647 0.184314
0.121569 0.317647 0.188235
0.121569 0.317647 0.192157
0.121569 0.321569 0.188235
0.121569 0.321569 0.192157
0.121569 0.325490 0.192157
0.125490 0.294118 0.184314
0.125490 0.301961 0.184314
0.125490 0.305882 0.188235
0.125490 0.313726 0.188235
0.125490 0.313726 0.192157
0.125490 0.317647 0.188235
0.125490 0.317647 0.192157
0.125490 0.321569 0.192157
0.125490 0.321569 0.196078
0.125490 0.325490 0.188235
0.125490 0.325490 0.196078
0.125490 0.329412 0.200000
0.129412 0.294118 0.184314
0.129412 0.298039 0.188235
0.129412 0.305882 0.188235
0.129412 0.305882 0.192157
0.129412 0.309804 0.188235
0.129412 0.317647 0.188235
0.129412 0.317647 0.192157
0.129412 0.317647 0.196078
0.129412 0.317647 0.200000
0.129412 0.321569 0.192157
0.129412 0.321569 0.200000
0.129412 0.325490 0.192157
0.129412 0.325490 0.196078
0.129412 0.325490 0.200000
0.129412 0.329412 0.196078
0.129412 0.329412 0.200000
0.133333 0.294118 0.192157
0.133333 0.301961 0.188235
0.133333 0.313726 0.196078
0.133333 0.317647 0.196078
0.133333 0.321569 0.192157
0.133333 0.321569 0.196078
0.133333 0.325490 0.196078
0.133333 0.325490 0.200000
0.133333 0.329412 0.196078
0.133333 0.329412 0.200000
0.133333 0.329412 0.203922
0.133333 0.333333 0.200000
0.133333 0.337255 0.200000
0.137255 0.298039 0.192157
0.137255 0.301961 0.196078
0.137255 0.305882 0.196078
0.137255 0.309804 0.192157
0.137255 0.309804 0.200000
0.137255 0.313726 0.192157
0.137255 0.313726 0.196078
0.137255 0.313726 0.200000
0.137255 0.317647 0.196078
0.137255 0.321569 0.200000
0.137255 0.321569 0.203922
0.137255 0.325490 0.200000
0.137255 0.325490 0.207843
0.137255 0.329412 0.200000
0.137255 0.329412 0.203922
0.137255 0.333333 0.200000
0.137255 0.333333 0.203922
0.137255 0.337255 0.207843
0.141176 0.301961 0.192157
0.141176 0.317647 0.200000
0.141176 0.325490 0.200000
0.141176 0.329412 0.203922
0.141176 0.333333 0.203922
0.141176 0.333333 0.207843
0.141176 0.337255 0.203922
0.141176 0.337255 0.207843
0.141176 0.341176 0.211765
0.145098 0.309804 0.196078
0.145098 0.309804 0.203922
0.145098 0.317647 0.203922
0.145098 0.321569 0.200000
0.145098 0.321569 0.207843
0.145098 0.325490 0.207843
0.145098 0.329412 0.203922
0.145098 0.329412 0.207843
0.145098 0.333333 0.207843
0.145098 0.333333 0.211765
0.145098 0.337255 0.207843
0.145098 0.337255 0.211765
0.145098 0.341176 0.207843
0.145098 0.341176 0.211765
0.145098 0.345098 0.211765
0.149020 0.317647 0.200000
0.149020 0.317647 0.203922
0.149020 0.325490 0.207843
0.149020 0.329412 0.207843
0.149020 0.333333 0.207843
0.149020 0.333333 0.211765
0.149020 0.337255 0.207843
0.149020 0.337255 0.215686
0.149020 0.341176 0.211765
0.149020 0.341176 0.215686
0.149020 0.345098 0.215686
0.152941 0.329412 0.215686
0.152941 0.337255 0.211765
0.152941 0.341176 0.211765
0.152941 0.341176 0.215686
0.152941 0.341176 0.219608
0.152941 0.345098 0.215686
0.152941 0.345098 0.219608
0.156863 0.313726 0.211765
0.156863 0.325490 0.211765
0.156863 0.329412 0.211765
0.156863 0.329412 0.215686
0.156863 0.333333 0.211765
0.156863 0.333333 0.215686
0.156863 0.333333 0.219608
0.156863 0.337255 0.211765
0.156863 0.337255 0.215686
0.156863 0.341176 0.215686
0.156863 0.341176 0.219608
0.156863 0.345098 0.219608
0.156863 0.345098 0.223529
0.156863 0.349020 0.219608
0.156863 0.349020 0.223529
0.160784 0.317647 0.211765
0.160784 0.325490 0.219608
0.160784 0.329412 0.219608
0.160784 0.337255 0.215686
0.160784 0.337255 0.219608
0.160784 0.341176 0.219608
0.160784 0.341176 0.223529
0.160784 0.345098 0.219608
0.160784 0.345098 0.223529
0.160784 0.349020 0.223529
0.160784 0.349020 0.227451
0.160784 0.352941 0.227451
0.160784 0.356863 0.223529
0.160784 0.356863 0.227451
0.164706 0.325490 0.223529
0.164706 0.333333 0.223529
0.164706 0.337255 0.223529
0.164706 0.337255 0.227451
0.164706 0.341176 0.223529
0.164706 0.341176 0.227451
0.164706 0.345098 0.223529
0.164706 0.349020 0.227451
0.164706 0.349020 0.231373
0.164706 0.352941 0.227451
0.164706 0.352941 0.231373
0.164706 0.356863 0.223529
0.164706 0.356863 0.227451
0.164706 0.356863 0.231373
0.168627 0.329412 0.227451
0.168627 0.341176 0.227451
0.168627 0.341176 0.231373
0.168627 0.345098 0.223529
0.168627 0.345098 0.231373
0.168627 0.349020 0.231373
0.168627 0.352941 0.227451
0.168627 0.352941 0.231373
0.168627 0.352941 0.235294
0.168627 0.356863 0.231373
0.168627 0.356863 0.235294
0.168627 0.360784 0.235294
0.172549 0.345098 0.227451
0.172549 0.349020 0.231373
0.172549 0.349020 0.235294
0.172549 0.352941 0.235294
0.172549 0.356863 0.231373
0.172549 0.356863 0.235294
0.172549 0.356863 0.239216
0.172549 0.360784 0.235294
0.172549 0.360784 0.239216
0.176471 0.341176 0.235294
0.176471 0.349020 0.235294
0.176471 0.356863 0.239216
0.176471 0.360784 0.239216
0.176471 0.360784 0.243137
0.176471 0.364706 0.239216
0.176471 0.364706 0.243137
0.180392 0.349020 0.243137
0.180392 0.352941 0.235294
0.180392 0.364706 0.243137
0.180392 0.368627 0.243137
0.180392 0.372549 0.247059
0.184314 0.345098 0.235294
0.184314 0.349020 0.239216
0.184314 0.356863 0.243137
0.184314 0.360784 0.243137
0.184314 0.364706 0.247059
0.184314 0.368627 0.243137
0.184314 0.368627 0.247059
0.184314 0.372549 0.243137
0.184314 0.372549 0.247059
0.188235 0.356863 0.239216
0.188235 0.368627 0.247059
0.188235 0.368627 0.250980
0.188235 0.372549 0.250980
0.192157 0.368627 0.247059
0.192157 0.368627 0.254902
0.192157 0.372549 0.250980
0.192157 0.376471 0.250980
0.192157 0.376471 0.258824
0.196078 0.364706 0.250980
0.196078 0.364706 0.254902
0.196078 0.368627 0.250980
0.196078 0.372549 0.250980
0.196078 0.376471 0.254902
0.196078 0.376471 0.258824
0.200000 0.368627 0.254902
0.200000 0.376471 0.258824
0.200000 0.380392 0.262745
0.203922 0.372549 0.262745
0.203922 0.380392 0.266667
0.203922 0.384314 0.270588
0.203922 0.388235 0.266667
0.207843 0.376471 0.262745
0.207843 0.388235 0.266667
0.207843 0.392157 0.266667
0.211765 0.380392 0.270588
0.211765 0.384314 0.270588
0.211765 0.392157 0.270588
0.211765 0.392157 0.274510
0.215686 0.392157 0.278431
0.215686 0.396078 0.278431
0.219608 0.384314 0.266667
0.219608 0.384314 0.270588
0.219608 0.396078 0.278431
0.223529 0.400000 0.282353
0.227451 0.384314 0.278431
0.227451 0.403922 0.286275
0.231373 0.403922 0.290196
0.231373 0.407843 0.286275
0.239216 0.411765 0.294118
0.243137 0.415686 0.298039
0.247059 0.419608 0.305882
0.254902 0.427451 0.309804
0.266667 0.435294 0.321569
0.282353 0.447059 0.341176
0.403922 0.066667 0.050980
0.411765 0.039216 0.015686
0.411765 0.070588 0.047059
0.431373 0.011765 0.000000
0.431373 0.031373 0.011765
0.431373 0.039216 0.019608
0.439216 0.054902 0.031373
0.454902 0.101961 0.082353
0.529412 0.172549 0.145098
0.537255 0.196078 0.172549
0.592157 0.078431 0.125490
0.611765 0.098039 0.141176
0.619608 0.043137 0.098039
0.619608 0.054902 0.109804
0.647059 0.098039 0.149020
0.647059 0.149020 0.200000
0.678431 0.094118 0.152941
0.694118 0.152941 0.207843
1.000000 0.000000 0.000000
0 0 0 347 84
0 0 1 365 20
0 0 2 343 20
0 0 3 707 20
0 0 4 369 20
0 0 5 541 20
0 0 6 661 20
0 0 7 751 20
0 0 8 748 20
0 0 9 513 20
0 0 10 570 20
0 0 11 434 20
0 0 12 483 20
0 0 13 369 20
0 0 14 346 20
0 0 15 640 52
0 1 0 343 68
0 1 1 575 4
0 1 2 712 4
0 1 3 675 4
0 1 4 748 4
0 1 5 343 4
0 1 6 489 4
0 1 7 686 4
0 1 8 363 4
0 1 9 348 4
0 1 10 698 4
0 1 11 489 4
0 1 12 539 4
0 1 13 686 4
0 1 14 319 4
0 1 15 546 36
0 2 0 375 68
0 2 1 492 4
0 2 2 754 4
0 2 3 367 4
0 2 4 674 4
0 2 5 339 4
0 2 6 556 4
0 2 7 495 4
0 2 8 700 4
0 2 9 316 4
0 2 10 438 4
0 2 11 629 4
0 2 12 461 4
0 2 13 557 4
0 2 14 457 4
0 2 15 512 36
0 3 0 466 68
0 3 1 349 4
0 3 2 343 4
0 3 3 343 4
0 3 4 698 4
0 3 5 754 4
0 3 6 343 4
0 3 7 343 4
0 3 8 369 4
0 3 9 319 4
0 3 10 659 4
0 3 11 506 4
0 3 12 510 4
0 3 13 513 4
0 3 14 574 4
0 3 15 367 36
0 4 0 349 68
0 4 1 522 4
0 4 2 710 4
0 4 3 457 4
0 4 4 437 4
0 4 5 674 4
0 4 6 513 4
0 4 7 661 4
0 4 8 410 4
0 4 9 347 4
0 4 10 587 4
0 4 11 732 4
0 4 12 584 4
0 4 13 558 4
0 4 14 393 4
0 4 15 713 36
0 5 0 367 68
0 5 1 544 4
0 5 2 628 4
0 5 3 407 4
0 5 4 369 4
0 5 5 599 4
0 5 6 544 4
0 5 7 367 4
0 5 8 460 4
0 5 9 369 4
0 5 10 417 4
0 5 11 521 4
0 5 12 646 4
0 5 13 373 4
0 5 14 508 4
0 5 15 392 36
0 6 0 555 68
0 6 1 473 4
0 6 2 508 4
0 6 3 573 4
0 6 4 342 4
0 6 5 489 4
0 6 6 492 4
0 6 7 492 4
0 6 8 375 4
0 6 9 674 4
0 6 10 319 4
0 6 11 586 4
0 6 12 349 4
0 6 13 671 4
0 6 14 701 4
0 6 15 689 36
0 7 0 731 76
0 7 1 692 12
0 7 2 375 12
0 7 3 542 12
0 7 4 704 12
0 7 5 659 12
0 7 6 343 12
0 7 7 572 12
0 7 8 417 12
0 7 9 698 12
0 7 10 348 12
0 7 11 570 12
0 7 12 343 12
0 7 13 369 12
0 7 14 624 12
0 7 15 396 44
1 0 0 604 80
1 0 1 415 16
1 0 2 630 16
1 0 3 513 16
1 0 4 370 16
1 0 5 365 16
1 0 6 429 16
1 0 7 343 16
1 0 8 585 16
1 0 9 431 16
1 0 10 457 16
1 0 11 603 16
1 0 12 664 16
1 0 13 486 16
1 0 14 674 16
1 0 15 546 48
1 1 0 489 64
1 1 1 604 0
1 1 2 692 0
1 1 3 369 0
1 1 4 349 0
1 1 5 366 0
1 1 6 557 0
1 1 7 555 0
1 1 8 369 0
1 1 9 692 0
1 1 10 343 0
1 1 11 584 0
1 1 12 319 0
1 1 13 339 0
1 1 14 717 0
1 1 15 487 32
1 2 0 798 64
1 2 1 688 0
1 2 2 546 0
1 2 3 472 0
1 2 4 349 0
1 2 5 472 0
1 2 6 712 0
1 2 7 369 0
1 2 8 648 0
1 2 9 373 0
1 2 10 512 0
1 2 11 437 0
1 2 12 661 0
1 2 13 627 0
1 2 14 369 0
1 2 15 343 32
1 3 0 798 64
1 3 1 641 0
1 3 2 528 0
1 3 3 438 0
1 3 4 367 0
1 3 5 350 0
1 3 6 604 0
1 3 7 461 0
1 3 8 713 0
1 3 9 547 0
1 3 10 661 0
1 3 11 386 0
1 3 12 586 0
1 3 13 396 0
1 3 14 471 0
1 3 15 362 32
1 4 0 798 64
1 4 1 586 0
1 4 2 470 0
1 4 3 392 0
1 4 4 373 0
1 4 5 673 0
1 4 6 454 0
1 4 7 349 0
1 4 8 341 0
1 4 9 343 0
1 4 10 527 0
1 4 11 724 0
1 4 12 363 0
1 4 13 701 0
1 4 14 348 0
1 4 15 461 32
1 5 0 798 64
1 5 1 515 0
1 5 2 641 0
1 5 3 316 0
1 5 4 730 0
1 5 5 347 0
1 5 6 584 0
1 5 7 385 0
1 5 8 409 0
1 5 9 435 0
1 5 10 553 0
1 5 11 544 0
1 5 12 582 0
1 5 13 407 0
1 5 14 545 0
1 5 15 475 32
1 6 0 0 64
1 6 1 346 0
1 6 2 615 0
1 6 3 347 0
1 6 4 350 0
1 6 5 367 0
1 6 6 375 0
1 6 7 375 0
1 6 8 606 0
1 6 9 615 0
1 6 10 555 0
1 6 11 367 0
1 6 12 544 0
1 6 13 719 0
1 6 14 661 0
1 6 15 582 32
1 7 0 717 72
1 7 1 395 8
1 7 2 559 8
1 7 3 367 8
1 7 4 514 8
1 7 5 698 8
1 7 6 365 8
1 7 7 673 8
1 7 8 367 8
1 7 9 510 8
1 7 10 343 8
1 7 11 708 8
1 7 12 698 8
1 7 13 489 8
1 7 14 613 8
1 7 15 347 40
2 0 0 347 80
2 0 1 375 16
2 0 2 322 16
2 0 3 442 16
2 0 4 371 16
2 0 5 703 16
2 0 6 93 16
2 0 7 3 16
2 0 8 384 16
2 0 9 87 16
2 0 10 548 16
2 0 11 302 16
2 0 12 368 16
2 0 13 109 16
2 0 14 613 16
2 0 15 688 48
2 1 0 529 64
2 1 1 544 0
2 1 2 343 0
2 1 3 278 0
2 1 4 602 0
2 1 5 683 0
2 1 6 9 0
2 1 7 530 0
2 1 8 6 0
2 1 9 679 0
2 1 10 531 0
2 1 11 346 0
2 1 12 712 0
2 1 13 524 0
2 1 14 752 0
2 1 15 367 32
2 2 0 798 64
2 2 1 574 0
2 2 2 469 0
2 2 3 119 0
2 2 4 201 0
2 2 5 4 0
2 2 6 445 0
2 2 7 254 0
2 2 8 63 0
2 2 9 468 0
2 2 10 6 0
2 2 11 436 0
2 2 12 738 0
2 2 13 512 0
2 2 14 542 0
2 2 15 559 32
2 3 0 798 64
2 3 1 641 0
2 3 2 375 0
2 3 3 178 0
2 3 4 361 0
2 3 5 17 0
2 3 6 171 0
2 3 7 306 0
2 3 8 89 0
2 3 9 167 0
2 3 10 559 0
2 3 11 121 0
2 3 12 363 0
2 3 13 413 0
2 3 14 468 0
2 3 15 365 32
2 4 0 798 64
2 4 1 640 0
2 4 2 628 0
2 4 3 166 0
2 4 4 88 0
2 4 5 450 0
2 4 6 62 0
2 4 7 496 0
2 4 8 606 0
2 4 9 465 0
2 4 10 167 0
2 4 11 693 0
2 4 12 640 0
2 4 13 347 0
2 4 14 343 0
2 4 15 461 32
2 5 0 798 64
2 5 1 640 0
2 5 2 491 0
2 5 3 72 0
2 5 4 292 0
2 5 5 208 0
2 5 6 461 0
2 5 7 579 0
2 5 8 427 0
2 5 9 12 0
2 5 10 517 0
2 5 11 551 0
2 5 12 245 0
2 5 13 7 0
2 5 14 375 0
2 5 15 510 32
2 6 0 233 64
2 6 1 323 0
2 6 2 659 0
2 6 3 113 0
2 6 4 15 0
2 6 5 659 0
2 6 6 370 0
2 6 7 708 0
2 6 8 51 0
2 6 9 19 0
2 6 10 135 0
2 6 11 162 0
2 6 12 304 0
2 6 13 16 0
2 6 14 495 0
2 6 15 348 32
2 7 0 365 72
2 7 1 373 8
2 7 2 363 8
2 7 3 369 8
2 7 4 625 8
2 7 5 698 8
2 7 6 611 8
2 7 7 365 8
2 7 8 339 8
2 7 9 342 8
2 7 10 567 8
2 7 11 343 8
2 7 12 319 8
2 7 13 541 8
2 7 14 717 8
2 7 15 344 40
3 0 0 513 80
3 0 1 676 16
3 0 2 407 16
3 0 3 216 16
3 0 4 748 16
3 0 5 317 16
3 0 6 101 16
3 0 7 187 16
3 0 8 188 16
3 0 9 65 16
3 0 10 610 16
3 0 11 596 16
3 0 12 352 16
3 0 13 10 16
3 0 14 570 16
3 0 15 392 48
3 1 0 513 64
3 1 1 473 0
3 1 2 625 0
3 1 3 303 0
3 1 4 488 0
3 1 5 776 0
3 1 6 77 0
3 1 7 651 0
3 1 8 533 0
3 1 9 224 0
3 1 10 623 0
3 1 11 624 0
3 1 12 193 0
3 1 13 395 0
3 1 14 630 0
3 1 15 703 32
3 2 0 798 64
3 2 1 736 0
3 2 2 457 0
3 2 3 304 0
3 2 4 260 0
3 2 5 322 0
3 2 6 769 0
3 2 7 714 0
3 2 8 520 0
3 2 9 248 0
3 2 10 555 0
3 2 11 365 0
3 2 12 373 0
3 2 13 543 0
3 2 14 528 0
3 2 15 348 32
3 3 0 798 64
3 3 1 528 0
3 3 2 710 0
3 3 3 356 0
3 3 4 202 0
3 3 5 38 0
3 3 6 220 0
3 3 7 280 0
3 3 8 292 0
3 3 9 152 0
3 3 10 114 0
3 3 11 629 0
3 3 12 646 0
3 3 13 369 0
3 3 14 340 0
3 3 15 641 32
3 4 0 798 64
3 4 1 692 0
3 4 2 415 0
3 4 3 189 0
3 4 4 56 0
3 4 5 508 0
3 4 6 329 0
3 4 7 598 0
3 4 8 33 0
3 4 9 449 0
3 4 10 326 0
3 4 11 334 0
3 4 12 30 0
3 4 13 505 0
3 4 14 491 0
3 4 15 528 32
3 5 0 798 64
3 5 1 741 0
3 5 2 510 0
3 5 3 647 0
3 5 4 747 0
3 5 5 37 0
3 5 6 293 0
3 5 7 363 0
3 5 8 96 0
3 5 9 552 0
3 5 10 651 0
3 5 11 486 0
3 5 12 362 0
3 5 13 23 0
3 5 14 628 0
3 5 15 703 32
3 6 0 0 64
3 6 1 339 0
3 6 2 347 0
3 6 3 247 0
3 6 4 75 0
3 6 5 17 0
3 6 6 9 0
3 6 7 503 0
3 6 8 198 0
3 6 9 373 0
3 6 10 789 0
3 6 11 788 0
3 6 12 342 0
3 6 13 51 0
3 6 14 367 0
3 6 15 369 32
3 7 0 343 72
3 7 1 556 8
3 7 2 342 8
3 7 3 601 8
3 7 4 346 8
3 7 5 367 8
3 7 6 365 8
3 7 7 582 8
3 7 8 611 8
3 7 9 472 8
3 7 10 369 8
3 7 11 637 8
3 7 12 708 8
3 7 13 570 8
3 7 14 385 8
3 7 15 415 40
4 0 0 343 80
4 0 1 367 16
4 0 2 454 16
4 0 3 210 16
4 0 4 269 16
4 0 5 148 16
4 0 6 760 16
4 0 7 409 16
4 0 8 401 16
4 0 9 408 16
4 0 10 599 16
4 0 11 351 16
4 0 12 446 16
4 0 13 660 16
4 0 14 472 16
4 0 15 732 48
4 1 0 641 64
4 1 1 475 0
4 1 2 324 0
4 1 3 422 0
4 1 4 775 0
4 1 5 708 0
4 1 6 609 0
4 1 7 624 0
4 1 8 752 0
4 1 9 450 0
4 1 10 120 0
4 1 11 468 0
4 1 12 560 0
4 1 13 367 0
4 1 14 676 0
4 1 15 341 32
4 2 0 798 64
4 2 1 365 0
4 2 2 472 0
4 2 3 221 0
4 2 4 73 0
4 2 5 304 0
4 2 6 414 0
4 2 7 703 0
4 2 8 351 0
4 2 9 573 0
4 2 10 176 0
4 2 11 484 0
4 2 12 597 0
4 2 13 407 0
4 2 14 367 0
4 2 15 417 32
4 3 0 798 64
4 3 1 486 0
4 3 2 369 0
4 3 3 258 0
4 3 4 597 0
4 3 5 665 0
4 3 6 60 0
4 3 7 143 0
4 3 8 764 0
4 3 9 134 0
4 3 10 40 0
4 3 11 471 0
4 3 12 778 0
4 3 13 366 0
4 3 14 370 0
4 3 15 542 32
4 4 0 798 64
4 4 1 417 0
4 4 2 675 0
4 4 3 792 0
4 4 4 377 0
4 4 5 483 0
4 4 6 39 0
4 4 7 536 0
4 4 8 227 0
4 4 9 471 0
4 4 10 443 0
4 4 11 595 0
4 4 12 43 0
4 4 13 298 0
4 4 14 342 0
4 4 15 506 32
4 5 0 798 64
4 5 1 324 0
4 5 2 432 0
4 5 3 797 0
4 5 4 42 0
4 5 5 137 0
4 5 6 427 0
4 5 7 341 0
4 5 8 279 0
4 5 9 650 0
4 5 10 577 0
4 5 11 1 0
4 5 12 265 0
4 5 13 309 0
4 5 14 584 0
4 5 15 524 32
4 6 0 199 64
4 6 1 606 0
4 6 2 482 0
4 6 3 772 0
4 6 4 372 0
4 6 5 354 0
4 6 6 92 0
4 6 7 638 0
4 6 8 169 0
4 6 9 99 0
4 6 10 517 0
4 6 11 237 0
4 6 12 273 0
4 6 13 68 0
4 6 14 689 0
4 6 15 646 32
4 7 0 369 72
4 7 1 339 8
4 7 2 662 8
4 7 3 625 8
4 7 4 457 8
4 7 5 472 8
4 7 6 393 8
4 7 7 365 8
4 7 8 339 8
4 7 9 433 8
4 7 10 708 8
4 7 11 393 8
4 7 12 369 8
4 7 13 343 8
4 7 14 555 8
4 7 15 513 40
5 0 0 369 80
5 0 1 663 16
5 0 2 483 16
5 0 3 146 16
5 0 4 515 16
5 0 5 762 16
5 0 6 528 16
5 0 7 682 16
5 0 8 609 16
5 0 9 594 16
5 0 10 687 16
5 0 11 106 16
5 0 12 21 16
5 0 13 173 16
5 0 14 644 16
5 0 15 319 48
5 1 0 692 64
5 1 1 369 0
5 1 2 373 0
5 1 3 562 0
5 1 4 497 0
5 1 5 391 0
5 1 6 696 0
5 1 7 453 0
5 1 8 465 0
5 1 9 685 0
5 1 10 308 0
5 1 11 18 0
5 1 12 331 0
5 1 13 606 0
5 1 14 369 0
5 1 15 491 32
5 2 0 798 64
5 2 1 673 0
5 2 2 489 0
5 2 3 150 0
5 2 4 257 0
5 2 5 532 0
5 2 6 299 0
5 2 7 182 0
5 2 8 261 0
5 2 9 426 0
5 2 10 350 0
5 2 11 13 0
5 2 12 683 0
5 2 13 346 0
5 2 14 339 0
5 2 15 674 32
5 3 0 798 64
5 3 1 644 0
5 3 2 625 0
5 3 3 668 0
5 3 4 224 0
5 3 5 593 0
5 3 6 661 0
5 3 7 409 0
5 3 8 458 0
5 3 9 424 0
5 3 10 55 0
5 3 11 7 0
5 3 12 418 0
5 3 13 425 0
5 3 14 674 0
5 3 15 369 32
5 4 0 798 64
5 4 1 373 0
5 4 2 615 0
5 4 3 790 0
5 4 4 667 0
5 4 5 191 0
5 4 6 160 0
5 4 7 448 0
5 4 8 648 0
5 4 9 722 0
5 4 10 336 0
5 4 11 312 0
5 4 12 346 0
5 4 13 506 0
5 4 14 470 0
5 4 15 630 32
5 5 0 798 64
5 5 1 417 0
5 5 2 606 0
5 5 3 796 0
5 5 4 522 0
5 5 5 403 0
5 5 6 243 0
5 5 7 381 0
5 5 8 368 0
5 5 9 671 0
5 5 10 104 0
5 5 11 207 0
5 5 12 26 0
5 5 13 151 0
5 5 14 472 0
5 5 15 367 32
5 6 0 58 64
5 6 1 348 0
5 6 2 544 0
5 6 3 468 0
5 6 4 140 0
5 6 5 124 0
5 6 6 28 0
5 6 7 15 0
5 6 8 118 0
5 6 9 50 0
5 6 10 619 0
5 6 11 52 0
5 6 12 31 0
5 6 13 174 0
5 6 14 324 0
5 6 15 436 32
5 7 0 472 72
5 7 1 489 8
5 7 2 701 8
5 7 3 335 8
5 7 4 673 8
5 7 5 347 8
5 7 6 555 8
5 7 7 570 8
5 7 8 510 8
5 7 9 570 8
5 7 10 673 8
5 7 11 708 8
5 7 12 343 8
5 7 13 541 8
5 7 14 369 8
5 7 15 489 40
6 0 0 349 80
6 0 1 483 16
6 0 2 601 16
6 0 3 479 16
6 0 4 234 16
6 0 5 608 16
6 0 6 597 16
6 0 7 424 16
6 0 8 567 16
6 0 9 465 16
6 0 10 635 16
6 0 11 607 16
6 0 12 10 16
6 0 13 632 16
6 0 14 395 16
6 0 15 606 48
6 1 0 474 64
6 1 1 461 0
6 1 2 343 0
6 1 3 554 0
6 1 4 565 0
6 1 5 756 0
6 1 6 743 0
6 1 7 527 0
6 1 8 487 0
6 1 9 360 0
6 1 10 282 0
6 1 11 524 0
6 1 12 8 0
6 1 13 315 0
6 1 14 494 0
6 1 15 688 32
6 2 0 407 64
6 2 1 437 0
6 2 2 348 0
6 2 3 400 0
6 2 4 563 0
6 2 5 287 0
6 2 6 90 0
6 2 7 130 0
6 2 8 223 0
6 2 9 47 0
6 2 10 194 0
6 2 11 226 0
6 2 12 537 0
6 2 13 539 0
6 2 14 461 0
6 2 15 348 32
6 3 0 375 64
6 3 1 662 0
6 3 2 460 0
6 3 3 239 0
6 3 4 64 0
6 3 5 3 0
6 3 6 681 0
6 3 7 4 0
6 3 8 74 0
6 3 9 222 0
6 3 10 61 0
6 3 11 453 0
6 3 12 212 0
6 3 13 393 0
6 3 14 473 0
6 3 15 544 32
6 4 0 375 64
6 4 1 686 0
6 4 2 375 0
6 4 3 205 0
6 4 4 567 0
6 4 5 774 0
6 4 6 212 0
6 4 7 763 0
6 4 8 405 0
6 4 9 771 0
6 4 10 82 0
6 4 11 15 0
6 4 12 172 0
6 4 13 157 0
6 4 14 373 0
6 4 15 469 32
6 5 0 0 64
6 5 1 575 0
6 5 2 373 0
6 5 3 455 0
6 5 4 161 0
6 5 5 673 0
6 5 6 702 0
6 5 7 441 0
6 5 8 481 0
6 5 9 277 0
6 5 10 300 0
6 5 11 20 0
6 5 12 421 0
6 5 13 163 0
6 5 14 347 0
6 5 15 675 32
6 6 0 35 64
6 6 1 470 0
6 6 2 432 0
6 6 3 572 0
6 6 4 591 0
6 6 5 572 0
6 6 6 674 0
6 6 7 631 0
6 6 8 52 0
6 6 9 132 0
6 6 10 12 0
6 6 11 286 0
6 6 12 227 0
6 6 13 21 0
6 6 14 512 0
6 6 15 369 32
6 7 0 367 72
6 7 1 542 8
6 7 2 369 8
6 7 3 540 8
6 7 4 343 8
6 7 5 433 8
6 7 6 319 8
6 7 7 601 8
6 7 8 659 8
6 7 9 489 8
6 7 10 342 8
6 7 11 342 8
6 7 12 433 8
6 7 13 582 8
6 7 14 630 8
6 7 15 413 40
7 0 0 754 80
7 0 1 661 16
7 0 2 558 16
7 0 3 291 16
7 0 4 766 16
7 0 5 276 16
7 0 6 151 16
7 0 7 697 16
7 0 8 684 16
7 0 9 253 16
7 0 10 288 16
7 0 11 534 16
7 0 12 66 16
7 0 13 24 16
7 0 14 451 16
7 0 15 615 48
7 1 0 341 64
7 1 1 576 0
7 1 2 365 0
7 1 3 604 0
7 1 4 326 0
7 1 5 620 0
7 1 6 103 0
7 1 7 177 0
7 1 8 266 0
7 1 9 206 0
7 1 10 568 0
7 1 11 713 0
7 1 12 274 0
7 1 13 254 0
7 1 14 343 0
7 1 15 556 32
7 2 0 527 64
7 2 1 348 0
7 2 2 546 0
7 2 3 767 0
7 2 4 6 0
7 2 5 289 0
7 2 6 257 0
7 2 7 158 0
7 2 8 478 0
7 2 9 48 0
7 2 10 362 0
7 2 11 57 0
7 2 12 141 0
7 2 13 695 0
7 2 14 454 0
7 2 15 367 32
7 3 0 661 64
7 3 1 474 0
7 3 2 495 0
7 3 3 241 0
7 3 4 159 0
7 3 5 721 0
7 3 6 108 0
7 3 7 145 0
7 3 8 633 0
7 3 9 200 0
7 3 10 754 0
7 3 11 426 0
7 3 12 153 0
7 3 13 41 0
7 3 14 393 0
7 3 15 388 32
7 4 0 648 64
7 4 1 434 0
7 4 2 648 0
7 4 3 753 0
7 4 4 645 0
7 4 5 779 0
7 4 6 100 0
7 4 7 123 0
7 4 8 350 0
7 4 9 12 0
7 4 10 264 0
7 4 11 526 0
7 4 12 584 0
7 4 13 118 0
7 4 14 407 0
7 4 15 486 32
7 5 0 0 64
7 5 1 346 0
7 5 2 669 0
7 5 3 267 0
7 5 4 407 0
7 5 5 657 0
7 5 6 394 0
7 5 7 548 0
7 5 8 26 0
7 5 9 18 0
7 5 10 181 0
7 5 11 659 0
7 5 12 123 0
7 5 13 522 0
7 5 14 471 0
7 5 15 582 32
7 6 0 432 64
7 6 1 462 0
7 6 2 365 0
7 6 3 295 0
7 6 4 203 0
7 6 5 564 0
7 6 6 584 0
7 6 7 430 0
7 6 8 17 0
7 6 9 484 0
7 6 10 272 0
7 6 11 51 0
7 6 12 70 0
7 6 13 710 0
7 6 14 343 0
7 6 15 567 32
7 7 0 506 72
7 7 1 663 8
7 7 2 661 8
7 7 3 365 8
7 7 4 341 8
7 7 5 339 8
7 7 6 433 8
7 7 7 542 8
7 7 8 365 8
7 7 9 625 8
7 7 10 698 8
7 7 11 316 8
7 7 12 542 8
7 7 13 319 8
7 7 14 515 8
7 7 15 322 40
8 0 0 432 80
8 0 1 737 16
8 0 2 348 16
8 0 3 579 16
8 0 4 449 16
8 0 5 429 16
8 0 6 180 16
8 0 7 296 16
8 0 8 332 16
8 0 9 209 16
8 0 10 634 16
8 0 11 423 16
8 0 12 518 16
8 0 13 106 16
8 0 14 316 16
8 0 15 411 48
8 1 0 346 64
8 1 1 627 0
8 1 2 512 0
8 1 3 218 0
8 1 4 663 0
8 1 5 399 0
8 1 6 588 0
8 1 7 142 0
8 1 8 640 0
8 1 9 765 0
8 1 10 640 0
8 1 11 375 0
8 1 12 280 0
8 1 13 185 0
8 1 14 472 0
8 1 15 674 32
8 2 0 720 64
8 2 1 719 0
8 2 2 701 0
8 2 3 13 0
8 2 4 330 0
8 2 5 698 0
8 2 6 718 0
8 2 7 416 0
8 2 8 204 0
8 2 9 359 0
8 2 10 538 0
8 2 11 12 0
8 2 12 398 0
8 2 13 740 0
8 2 14 741 0
8 2 15 437 32
8 3 0 366 64
8 3 1 336 0
8 3 2 573 0
8 3 3 102 0
8 3 4 149 0
8 3 5 283 0
8 3 6 382 0
8 3 7 236 0
8 3 8 387 0
8 3 9 242 0
8 3 10 27 0
8 3 11 107 0
8 3 12 450 0
8 3 13 380 0
8 3 14 544 0
8 3 15 503 32
8 4 0 546 64
8 4 1 409 0
8 4 2 528 0
8 4 3 658 0
8 4 4 196 0
8 4 5 364 0
8 4 6 739 0
8 4 7 690 0
8 4 8 634 0
8 4 9 246 0
8 4 10 207 0
8 4 11 768 0
8 4 12 770 0
8 4 13 700 0
8 4 14 433 0
8 4 15 606 32
8 5 0 71 64
8 5 1 661 0
8 5 2 640 0
8 5 3 570 0
8 5 4 396 0
8 5 5 331 0
8 5 6 340 0
8 5 7 470 0
8 5 8 725 0
8 5 9 110 0
8 5 10 719 0
8 5 11 652 0
8 5 12 569 0
8 5 13 666 0
8 5 14 343 0
8 5 15 485 32
8 6 0 546 64
8 6 1 513 0
8 6 2 662 0
8 6 3 357 0
8 6 4 419 0
8 6 5 421 0
8 6 6 189 0
8 6 7 508 0
8 6 8 439 0
8 6 9 165 0
8 6 10 275 0
8 6 11 621 0
8 6 12 614 0
8 6 13 672 0
8 6 14 373 0
8 6 15 396 32
8 7 0 319 72
8 7 1 468 8
8 7 2 373 8
8 7 3 413 8
8 7 4 541 8
8 7 5 611 8
8 7 6 431 8
8 7 7 601 8
8 7 8 625 8
8 7 9 555 8
8 7 10 611 8
8 7 11 339 8
8 7 12 342 8
8 7 13 369 8
8 7 14 606 8
8 7 15 342 40
9 0 0 674 80
9 0 1 486 16
9 0 2 482 16
9 0 3 7 16
9 0 4 733 16
9 0 5 656 16
9 0 6 345 16
9 0 7 502 16
9 0 8 317 16
9 0 9 449 16
9 0 10 215 16
9 0 11 290 16
9 0 12 77 16
9 0 13 276 16
9 0 14 348 16
9 0 15 688 48
9 1 0 370 64
9 1 1 392 0
9 1 2 639 0
9 1 3 498 0
9 1 4 535 0
9 1 5 706 0
9 1 6 310 0
9 1 7 674 0
9 1 8 727 0
9 1 9 618 0
9 1 10 197 0
9 1 11 94 0
9 1 12 544 0
9 1 13 431 0
9 1 14 369 0
9 1 15 547 32
9 2 0 437 64
9 2 1 457 0
9 2 2 585 0
9 2 3 500 0
9 2 4 109 0
9 2 5 390 0
9 2 6 578 0
9 2 7 740 0
9 2 8 757 0
9 2 9 230 0
9 2 10 735 0
9 2 11 53 0
9 2 12 515 0
9 2 13 223 0
9 2 14 703 0
9 2 15 457 32
9 3 0 691 64
9 3 1 512 0
9 3 2 489 0
9 3 3 590 0
9 3 4 755 0
9 3 5 682 0
9 3 6 745 0
9 3 7 680 0
9 3 8 105 0
9 3 9 235 0
9 3 10 211 0
9 3 11 481 0
9 3 12 322 0
9 3 13 423 0
9 3 14 546 0
9 3 15 323 32
9 4 0 559 64
9 4 1 470 0
9 4 2 369 0
9 4 3 7 0
9 4 4 113 0
9 4 5 573 0
9 4 6 327 0
9 4 7 314 0
9 4 8 601 0
9 4 9 360 0
9 4 10 390 0
9 4 11 617 0
9 4 12 736 0
9 4 13 720 0
9 4 14 347 0
9 4 15 433 32
9 5 0 45 64
9 5 1 347 0
9 5 2 466 0
9 5 3 326 0
9 5 4 154 0
9 5 5 635 0
9 5 6 337 0
9 5 7 709 0
9 5 8 232 0
9 5 9 637 0
9 5 10 460 0
9 5 11 758 0
9 5 12 474 0
9 5 13 730 0
9 5 14 606 0
9 5 15 489 32
9 6 0 0 64
9 6 1 365 0
9 6 2 673 0
9 6 3 221 0
9 6 4 59 0
9 6 5 549 0
9 6 6 525 0
9 6 7 115 0
9 6 8 107 0
9 6 9 467 0
9 6 10 472 0
9 6 11 768 0
9 6 12 81 0
9 6 13 616 0
9 6 14 730 0
9 6 15 373 32
9 7 0 524 72
9 7 1 688 8
9 7 2 343 8
9 7 3 570 8
9 7 4 305 8
9 7 5 343 8
9 7 6 708 8
9 7 7 365 8
9 7 8 365 8
9 7 9 542 8
9 7 10 343 8
9 7 11 365 8
9 7 12 365 8
9 7 13 365 8
9 7 14 395 8
9 7 15 512 40
10 0 0 347 80
10 0 1 570 16
10 0 2 559 16
10 0 3 14 16
10 0 4 315 16
10 0 5 412 16
10 0 6 554 16
10 0 7 410 16
10 0 8 165 16
10 0 9 728 16
10 0 10 13 16
10 0 11 318 16
10 0 12 21 16
10 0 13 16 16
10 0 14 710 16
10 0 15 628 48
10 1 0 741 64
10 1 1 700 0
10 1 2 702 0
10 1 3 550 0
10 1 4 294 0
10 1 5 11 0
10 1 6 247 0
10 1 7 270 0
10 1 8 592 0
10 1 9 403 0
10 1 10 215 0
10 1 11 112 0
10 1 12 97 0
10 1 13 387 0
10 1 14 494 0
10 1 15 453 32
10 2 0 798 64
10 2 1 742 0
10 2 2 347 0
10 2 3 78 0
10 2 4 379 0
10 2 5 172 0
10 2 6 459 0
10 2 7 451 0
10 2 8 207 0
10 2 9 240 0
10 2 10 239 0
10 2 11 313 0
10 2 12 519 0
10 2 13 348 0
10 2 14 367 0
10 2 15 661 32
10 3 0 798 64
10 3 1 701 0
10 3 2 415 0
10 3 3 34 0
10 3 4 325 0
10 3 5 448 0
10 3 6 268 0
10 3 7 321 0
10 3 8 111 0
10 3 9 622 0
10 3 10 297 0
10 3 11 13 0
10 3 12 753 0
10 3 13 271 0
10 3 14 649 0
10 3 15 555 32
10 4 0 798 64
10 4 1 527 0
10 4 2 436 0
10 4 3 791 0
10 4 4 126 0
10 4 5 133 0
10 4 6 93 0
10 4 7 2 0
10 4 8 122 0
10 4 9 316 0
10 4 10 155 0
10 4 11 214 0
10 4 12 674 0
10 4 13 374 0
10 4 14 604 0
10 4 15 628 32
10 5 0 798 64
10 5 1 674 0
10 5 2 495 0
10 5 3 793 0
10 5 4 186 0
10 5 5 281 0
10 5 6 179 0
10 5 7 256 0
10 5 8 129 0
10 5 9 705 0
10 5 10 646 0
10 5 11 604 0
10 5 12 152 0
10 5 13 119 0
10 5 14 544 0
10 5 15 528 32
10 6 0 0 64
10 6 1 510 0
10 6 2 692 0
10 6 3 509 0
10 6 4 499 0
10 6 5 36 0
10 6 6 250 0
10 6 7 580 0
10 6 8 783 0
10 6 9 781 0
10 6 10 221 0
10 6 11 69 0
10 6 12 195 0
10 6 13 587 0
10 6 14 367 0
10 6 15 528 32
10 7 0 370 72
10 7 1 674 8
10 7 2 710 8
10 7 3 541 8
10 7 4 363 8
10 7 5 339 8
10 7 6 367 8
10 7 7 365 8
10 7 8 670 8
10 7 9 542 8
10 7 10 670 8
10 7 11 625 8
10 7 12 611 8
10 7 13 347 8
10 7 14 669 8
10 7 15 365 40
11 0 0 713 80
11 0 1 390 16
11 0 2 388 16
11 0 3 226 16
11 0 4 186 16
11 0 5 161 16
11 0 6 24 16
11 0 7 642 16
11 0 8 184 16
11 0 9 379 16
11 0 10 80 16
11 0 11 440 16
11 0 12 276 16
11 0 13 27 16
11 0 14 322 16
11 0 15 343 48
11 1 0 611 64
11 1 1 676 0
11 1 2 343 0
11 1 3 519 0
11 1 4 308 0
11 1 5 213 0
11 1 6 619 0
11 1 7 734 0
11 1 8 6 0
11 1 9 501 0
11 1 10 364 0
11 1 11 453 0
11 1 12 151 0
11 1 13 84 0
11 1 14 452 0
11 1 15 736 32
11 2 0 798 64
11 2 1 395 0
11 2 2 367 0
11 2 3 32 0
11 2 4 111 0
11 2 5 17 0
11 2 6 521 0
11 2 7 610 0
11 2 8 566 0
11 2 9 5 0
11 2 10 504 0
11 2 11 653 0
11 2 12 367 0
11 2 13 677 0
11 2 14 388 0
11 2 15 639 32
11 3 0 798 64
11 3 1 723 0
11 3 2 586 0
11 3 3 95 0
11 3 4 228 0
11 3 5 427 0
11 3 6 761 0
11 3 7 678 0
11 3 8 12 0
11 3 9 225 0
11 3 10 378 0
11 3 11 355 0
11 3 12 655 0
11 3 13 251 0
11 3 14 512 0
11 3 15 512 32
11 4 0 798 64
11 4 1 343 0
11 4 2 466 0
11 4 3 795 0
11 4 4 571 0
11 4 5 750 0
11 4 6 333 0
11 4 7 117 0
11 4 8 420 0
11 4 9 402 0
11 4 10 485 0
11 4 11 589 0
11 4 12 190 0
11 4 13 309 0
11 4 14 582 0
11 4 15 741 32
11 5 0 798 64
11 5 1 559 0
11 5 2 615 0
11 5 3 794 0
11 5 4 116 0
11 5 5 509 0
11 5 6 726 0
11 5 7 219 0
11 5 8 463 0
11 5 9 138 0
11 5 10 455 0
11 5 11 744 0
11 5 12 183 0
11 5 13 395 0
11 5 14 373 0
11 5 15 604 32
11 6 0 85 64
11 6 1 547 0
11 6 2 367 0
11 6 3 773 0
11 6 4 144 0
11 6 5 4 0
11 6 6 231 0
11 6 7 603 0
11 6 8 782 0
11 6 9 784 0
11 6 10 566 0
11 6 11 285 0
11 6 12 54 0
11 6 13 79 0
11 6 14 544 0
11 6 15 472 32
11 7 0 363 72
11 7 1 573 8
11 7 2 343 8
11 7 3 611 8
11 7 4 284 8
11 7 5 457 8
11 7 6 552 8
11 7 7 611 8
11 7 8 342 8
11 7 9 698 8
11 7 10 393 8
11 7 11 637 8
11 7 12 611 8
11 7 13 363 8
11 7 14 339 8
11 7 15 584 40
12 0 0 375 80
12 0 1 369 16
12 0 2 741 16
12 0 3 127 16
12 0 4 175 16
12 0 5 252 16
12 0 6 29 16
12 0 7 249 16
12 0 8 636 16
12 0 9 172 16
12 0 10 68 16
12 0 11 102 16
12 0 12 229 16
12 0 13 244 16
12 0 14 348 16
12 0 15 604 48
12 1 0 407 64
12 1 1 613 0
12 1 2 375 0
12 1 3 307 0
12 1 4 634 0
12 1 5 125 0
12 1 6 12 0
12 1 7 24 0
12 1 8 262 0
12 1 9 193 0
12 1 10 715 0
12 1 11 746 0
12 1 12 218 0
12 1 13 21 0
12 1 14 487 0
12 1 15 528 32
12 2 0 798 64
12 2 1 346 0
12 2 2 545 0
12 2 3 338 0
12 2 4 507 0
12 2 5 376 0
12 2 6 641 0
12 2 7 74 0
12 2 8 480 0
12 2 9 76 0
12 2 10 786 0
12 2 11 780 0
12 2 12 261 0
12 2 13 219 0
12 2 14 514 0
12 2 15 699 32
12 3 0 798 64
12 3 1 433 0
12 3 2 342 0
12 3 3 537 0
12 3 4 358 0
12 3 5 341 0
12 3 6 140 0
12 3 7 369 0
12 3 8 86 0
12 3 9 139 0
12 3 10 785 0
12 3 11 787 0
12 3 12 164 0
12 3 13 346 0
12 3 14 425 0
12 3 15 392 32
12 4 0 798 64
12 4 1 323 0
12 4 2 515 0
12 4 3 630 0
12 4 4 600 0
12 4 5 311 0
12 4 6 259 0
12 4 7 168 0
12 4 8 226 0
12 4 9 192 0
12 4 10 641 0
12 4 11 643 0
12 4 12 18 0
12 4 13 22 0
12 4 14 546 0
12 4 15 641 32
12 5 0 798 64
12 5 1 523 0
12 5 2 586 0
12 5 3 291 0
12 5 4 540 0
12 5 5 711 0
12 5 6 369 0
12 5 7 20 0
12 5 8 187 0
12 5 9 464 0
12 5 10 156 0
12 5 11 403 0
12 5 12 383 0
12 5 13 67 0
12 5 14 689 0
12 5 15 675 32
12 6 0 98 64
12 6 1 437 0
12 6 2 528 0
12 6 3 83 0
12 6 4 319 0
12 6 5 209 0
12 6 6 217 0
12 6 7 136 0
12 6 8 581 0
12 6 9 777 0
12 6 10 131 0
12 6 11 177 0
12 6 12 59 0
12 6 13 128 0
12 6 14 510 0
12 6 15 523 32
12 7 0 732 72
12 7 1 365 8
12 7 2 432 8
12 7 3 460 8
12 7 4 673 8
12 7 5 491 8
12 7 6 367 8
12 7 7 433 8
12 7 8 319 8
12 7 9 367 8
12 7 10 342 8
12 7 11 413 8
12 7 12 369 8
12 7 13 457 8
12 7 14 365 8
12 7 15 513 40
13 0 0 692 80
13 0 1 674 16
13 0 2 363 16
13 0 3 694 16
13 0 4 339 16
13 0 5 148 16
13 0 6 16 16
13 0 7 49 16
13 0 8 21 16
13 0 9 19 16
13 0 10 399 16
13 0 11 164 16
13 0 12 397 16
13 0 13 163 16
13 0 14 489 16
13 0 15 556 48
13 1 0 415 64
13 1 1 661 0
13 1 2 487 0
13 1 3 541 0
13 1 4 262 0
13 1 5 13 0
13 1 6 257 0
13 1 7 19 0
13 1 8 480 0
13 1 9 13 0
13 1 10 189 0
13 1 11 24 0
13 1 12 383 0
13 1 13 10 0
13 1 14 428 0
13 1 15 375 32
13 2 0 798 64
13 2 1 436 0
13 2 2 367 0
13 2 3 289 0
13 2 4 77 0
13 2 5 16 0
13 2 6 135 0
13 2 7 21 0
13 2 8 191 0
13 2 9 50 0
13 2 10 308 0
13 2 11 623 0
13 2 12 217 0
13 2 13 32 0
13 2 14 461 0
13 2 15 344 32
13 3 0 798 64
13 3 1 367 0
13 3 2 512 0
13 3 3 592 0
13 3 4 44 0
13 3 5 456 0
13 3 6 477 0
13 3 7 688 0
13 3 8 46 0
13 3 9 238 0
13 3 10 405 0
13 3 11 612 0
13 3 12 25 0
13 3 13 301 0
13 3 14 580 0
13 3 15 523 32
13 4 0 798 64
13 4 1 369 0
13 4 2 524 0
13 4 3 178 0
13 4 4 535 0
13 4 5 353 0
13 4 6 51 0
13 4 7 654 0
13 4 8 584 0
13 4 9 759 0
13 4 10 263 0
13 4 11 314 0
13 4 12 500 0
13 4 13 39 0
13 4 14 436 0
13 4 15 712 32
13 5 0 798 64
13 5 1 455 0
13 5 2 347 0
13 5 3 24 0
13 5 4 77 0
13 5 5 444 0
13 5 6 516 0
13 5 7 328 0
13 5 8 716 0
13 5 9 295 0
13 5 10 447 0
13 5 11 366 0
13 5 12 209 0
13 5 13 119 0
13 5 14 407 0
13 5 15 367 32
13 6 0 233 64
13 6 1 316 0
13 6 2 717 0
13 6 3 344 0
13 6 4 583 0
13 6 5 649 0
13 6 6 387 0
13 6 7 24 0
13 6 8 255 0
13 6 9 729 0
13 6 10 170 0
13 6 11 91 0
13 6 12 400 0
13 6 13 561 0
13 6 14 369 0
13 6 15 323 32
13 7 0 641 72
13 7 1 414 8
13 7 2 742 8
13 7 3 468 8
13 7 4 393 8
13 7 5 732 8
13 7 6 350 8
13 7 7 698 8
13 7 8 341 8
13 7 9 637 8
13 7 10 147 8
13 7 11 346 8
13 7 12 670 8
13 7 13 319 8
13 7 14 601 8
13 7 15 545 40
14 0 0 386 80
14 0 1 468 16
14 0 2 748 16
14 0 3 472 16
14 0 4 486 16
14 0 5 392 16
14 0 6 343 16
14 0 7 732 16
14 0 8 392 16
14 0 9 582 16
14 0 10 626 16
14 0 11 367 16
14 0 12 542 16
14 0 13 394 16
14 0 14 540 16
14 0 15 700 48
14 1 0 454 64
14 1 1 588 0
14 1 2 689 0
14 1 3 741 0
14 1 4 373 0
14 1 5 459 0
14 1 6 676 0
14 1 7 406 0
14 1 8 573 0
14 1 9 502 0
14 1 10 700 0
14 1 11 605 0
14 1 12 604 0
14 1 13 433 0
14 1 14 437 0
14 1 15 350 32
14 2 0 798 64
14 2 1 342 0
14 2 2 319 0
14 2 3 588 0
14 2 4 437 0
14 2 5 584 0
14 2 6 659 0
14 2 7 749 0
14 2 8 369 0
14 2 9 367 0
14 2 10 347 0
14 2 11 508 0
14 2 12 646 0
14 2 13 343 0
14 2 14 314 0
14 2 15 319 32
14 3 0 798 64
14 3 1 510 0
14 3 2 475 0
14 3 3 701 0
14 3 4 688 0
14 3 5 528 0
14 3 6 347 0
14 3 7 417 0
14 3 8 436 0
14 3 9 343 0
14 3 10 322 0
14 3 11 461 0
14 3 12 344 0
14 3 13 701 0
14 3 14 457 0
14 3 15 719 32
14 4 0 798 64
14 4 1 366 0
14 4 2 573 0
14 4 3 320 0
14 4 4 369 0
14 4 5 555 0
14 4 6 406 0
14 4 7 528 0
14 4 8 370 0
14 4 9 719 0
14 4 10 515 0
14 4 11 348 0
14 4 12 373 0
14 4 13 528 0
14 4 14 346 0
14 4 15 556 32
14 5 0 798 64
14 5 1 454 0
14 5 2 370 0
14 5 3 606 0
14 5 4 369 0
14 5 5 476 0
14 5 6 486 0
14 5 7 347 0
14 5 8 461 0
14 5 9 369 0
14 5 10 584 0
14 5 11 435 0
14 5 12 661 0
14 5 13 701 0
14 5 14 528 0
14 5 15 639 32
14 6 0 0 64
14 6 1 396 0
14 6 2 627 0
14 6 3 489 0
14 6 4 692 0
14 6 5 511 0
14 6 6 392 0
14 6 7 541 0
14 6 8 492 0
14 6 9 673 0
14 6 10 492 0
14 6 11 611 0
14 6 12 493 0
14 6 13 385 0
14 6 14 365 0
14 6 15 553 32
14 7 0 369 72
14 7 1 558 8
14 7 2 348 8
14 7 3 615 8
14 7 4 373 8
14 7 5 404 8
14 7 6 456 8
14 7 7 343 8
14 7 8 319 8
14 7 9 472 8
14 7 10 395 8
14 7 11 367 8
14 7 12 365 8
14 7 13 457 8
14 7 14 363 8
14 7 15 346 40
15 0 0 448 82
15 0 1 673 18
15 0 2 339 18
15 0 3 461 18
15 0 4 628 18
15 0 5 686 18
15 0 6 698 18
15 0 7 343 18
15 0 8 370 18
15 0 9 344 18
15 0 10 723 18
15 0 11 702 18
15 0 12 363 18
15 0 13 612 18
15 0 14 351 18
15 0 15 375 50
15 1 0 347 66
15 1 1 547 2
15 1 2 349 2
15 1 3 646 2
15 1 4 490 2
15 1 5 369 2
15 1 6 454 2
15 1 7 640 2
15 1 8 661 2
15 1 9 528 2
15 1 10 508 2
15 1 11 362 2
15 1 12 547 2
15 1 13 573 2
15 1 14 389 2
15 1 15 393 34
15 2 0 460 66
15 2 1 528 2
15 2 2 702 2
15 2 3 513 2
15 2 4 676 2
15 2 5 539 2
15 2 6 601 2
15 2 7 703 2
15 2 8 494 2
15 2 9 710 2
15 2 10 492 2
15 2 11 471 2
15 2 12 625 2
15 2 13 367 2
15 2 14 390 2
15 2 15 456 34
15 3 0 434 66
15 3 1 343 2
15 3 2 319 2
15 3 3 367 2
15 3 4 528 2
15 3 5 366 2
15 3 6 395 2
15 3 7 502 2
15 3 8 363 2
15 3 9 674 2
15 3 10 350 2
15 3 11 641 2
15 3 12 644 2
15 3 13 468 2
15 3 14 712 2
15 3 15 648 34
15 4 0 741 66
15 4 1 410 2
15 4 2 546 2
15 4 3 673 2
15 4 4 448 2
15 4 5 642 2
15 4 6 475 2
15 4 7 648 2
15 4 8 343 2
15 4 9 506 2
15 4 10 347 2
15 4 11 676 2
15 4 12 485 2
15 4 13 573 2
15 4 14 611 2
15 4 15 373 34
15 5 0 369 66
15 5 1 396 2
15 5 2 346 2
15 5 3 448 2
15 5 4 432 2
15 5 5 375 2
15 5 6 457 2
15 5 7 639 2
15 5 8 476 2
15 5 9 640 2
15 5 10 415 2
15 5 11 719 2
15 5 12 367 2
15 5 13 491 2
15 5 14 647 2
15 5 15 369 34
15 6 0 574 66
15 6 1 367 2
15 6 2 508 2
15 6 3 342 2
15 6 4 492 2
15 6 5 347 2
15 6 6 546 2
15 6 7 406 2
15 6 8 323 2
15 6 9 396 2
15 6 10 369 2
15 6 11 712 2
15 6 12 437 2
15 6 13 708 2
15 6 14 641 2
15 6 15 348 34
15 7 0 676 74
15 7 1 626 10
15 7 2 628 10
15 7 3 570 10
15 7 4 686 10
15 7 5 522 10
15 7 6 437 10
15 7 7 369 10
15 7 8 324 10
15 7 9 366 10
15 7 10 611 10
15 7 11 472 10
15 7 12 339 10
15 7 13 472 10
15 7 14 375 10
15 7 15 369 42
